{"topic":"orderbook.200.BTCUSDT","ts":1776816000869,"type":"snapshot","data":{"s":"BTCUSDT","b":[["76358.2","0.523407"],["76354.7","0.033132"],["76353.8","0.102995"],["76352.6","0.079088"],["76352.5","0.05"],["76351.9","0.026194"],["76350.8","0.006545"],["76350.7","0.038843"],["76350.6","0.0132"],["76350.5","0.126"],["76349.6","0.023689"],["76348.9","0.060707"],["76348.8","0.065488"],["76347.2","0.001178"],["76346.9","0.06551"],["76346.2","0.010099"],["76346.1","0.079288"],["76345.7","0.001"],["76345.6","0.001"],["76345.5","0.001"],["76344.1","0.031456"],["76344","0.057257"],["76343.9","0.05"],["76343.4","0.026144"],["76343.2","0.000099"],["76342.8","0.126"],["76340","0.015735"],["76339.7","0.033236"],["76339.6","0.026145"],["76339.4","0.011"],["76338.6","0.05"],["76337.4","0.031456"],["76335.9","0.157949"],["76335.8","0.130981"],["76335.7","0.396985"],["76335.4","0.001178"],["76334.1","0.034003"],["76334","0.031456"],["76333.2","0.051"],["76330.8","0.031456"],["76330.4","0.001"],["76330.3","0.086668"],["76330.2","0.105837"],["76329","0.001"],["76328.4","0.130981"],["76328.2","0.050099"],["76327.8","0.002428"],["76326.6","0.015447"],["76326.5","0.048439"],["76323.6","0.001178"],["76323.5","0.001"],["76323.4","0.001"],["76323","0.000131"],["76322.7","0.031456"],["76322.6","0.163087"],["76321.2","0.391274"],["76320.7","0.000099"],["76320","0.000432"],["76319.7","0.130981"],["76319.3","0.03564"],["76319.2","0.056481"],["76319.1","0.052"],["76317.7","0.031456"],["76315.8","0.126"],["76315","0.087359"],["76314.6","0.031456"],["76313.3","0.130981"],["76313.2","0.000099"],["76312.5","0.015735"],["76312.4","0.05"],["76311.8","0.049617"],["76311.5","0.031456"],["76307.7","0.315626"],["76306.9","0.130981"],["76306.7","0.397038"],["76305.7","0.000099"],["76304.8","0.031456"],["76304.7","0.126"],["76304","0.275862"],["76303.9","0.743081"],["76303.4","0.05"],["76301.2","0.000099"],["76300.7","0.130981"],["76300","0.001178"],["76298.5","0.024344"],["76298.4","0.05"],["76298.2","0.000099"],["76297.8","0.031456"],["76295.7","0.126"],["76294.9","0.284783"],["76294.8","0.74317"],["76294","0.031456"],["76293.8","0.048439"],["76292.7","0.130981"],["76290.7","0.000099"],["76288.6","0.031456"],["76288.2","0.001178"],["76286.9","0.049185"],["76286.8","0.024672"],["76285.8","0.001"],["76285.5","0.126"],["76285.1","0.013102"],["76284.6","0.031456"],["76283.7","0.326235"],["76283.6","0.945455"],["76283.2","0.000099"],["76283","0.003277"],["76282.8","0.130981"],["76282.1","0.013102"],["76281","0.033238"],["76280.9","0.031456"],["76278.1","0.048439"],["76277.5","0.031456"],["76277.1","0.162149"],["76277","0.126"],["76276.9","0.050064"],["76276.7","0.036936"],["76276.4","0.001178"],["76276.1","0.130981"],["76276","0.192558"],["76275.7","0.000656"],["76274.3","0.031456"],["76274.2","0.013103"],["76273.5","0.00515"],["76272.7","0.239702"],["76270.7","0.056566"],["76270.4","0.031456"],["76270.3","0.715001"],["76269.8","0.130981"],["76269.4","0.052898"],["76269.3","0.126"],["76269","0.048439"],["76268.2","0.000099"],["76267.5","0.002675"],["76264.7","0.001178"],["76263.4","0.000099"],["76262.7","0.024174"],["76262.6","0.080986"],["76262.2","0.090671"],["76261.6","0.013107"],["76261.2","0.031456"],["76260.7","0.127099"],["76259.1","0.130981"],["76256.8","0.033171"],["76256.7","0.086452"],["76254.2","0.031456"],["76253.8","0.03564"],["76253.2","0.000099"],["76253","0.126"],["76252.9","0.001178"],["76252.2","0.637801"],["76250.9","0.000854"],["76250.8","0.048439"],["76249.7","0.042135"],["76248.4","0.130981"],["76247.4","0.003168"],["76245.7","0.000099"],["76245.4","0.068147"],["76245.3","0.126"],["76245.1","0.00515"],["76245","0.079895"],["76242.9","0.062625"],["76242.3","0.004007"],["76241.8","0.12"],["76241.1","0.001178"],["76240.4","0.08644"],["76238.2","0.000099"],["76237.6","0.126"],["76236.9","0.130981"],["76234","0.120439"],["76233.9","0.048439"],["76231","0.00162"],["76230.7","0.000099"],["76229.4","0.12"],["76229.3","0.001178"],["76226.4","0.00162"],["76226.2","0.132601"],["76226.1","0.126"],["76226","0.001153"],["76225.7","0.765642"],["76225.6","6.604869"],["76223.6","0.714835"],["76223.2","0.000099"],["76223","0.048439"],["76222.7","0.0001"],["76218.4","0.001"],["76217.6","0.001178"],["76217.2","0.005349"],["76215.5","0.130981"],["76214.6","0.126"],["76214.2","6.180768"],["76208.9","0.025633"],["76208.4","0.065507"],["76208.3","0.648339"],["76205.8","0.001178"],["76205.2","0.126"],["76204.8","0.130981"],["76203.4","0.677626"],["76200","0.007145"],["76199.6","0.17438"]],"a":[["76358.3","0.706848"],["76361.6","0.013787"],["76361.7","0.03"],["76363.1","0.012913"],["76363.2","0.003274"],["76365.1","0.001"],["76365.9","0.0132"],["76367.6","0.037447"],["76368.1","0.110578"],["76368.3","0.002546"],["76368.6","0.001099"],["76369.9","0.006545"],["76370","0.000103"],["76370.6","0.01"],["76370.8","0.001178"],["76372.5","0.001"],["76372.7","0.018905"],["76372.8","0.045735"],["76374.8","0.02962"],["76375.1","0.000614"],["76375.3","0.001"],["76375.4","0.001"],["76375.5","0.001"],["76376.2","0.000099"],["76376.4","0.006545"],["76376.5","0.056035"],["76376.7","0.126"],["76377.9","0.03"],["76378.6","0.001"],["76379.9","0.001"],["76380","0.000103"],["76380.9","0.130981"],["76381.3","0.005462"],["76382.4","0.031456"],["76382.5","0.001178"],["76383.8","0.000099"],["76385.5","0.031456"],["76385.6","0.071926"],["76385.7","0.126"],["76387","0.000099"],["76387.1","0.130981"],["76388.1","0.041341"],["76388.2","0.105837"],["76389.4","0.031456"],["76390","0.000103"],["76390.5","0.001"],["76391.4","0.000099"],["76391.6","0.161622"],["76391.9","0.048439"],["76392.6","0.031456"],["76392.7","0.097927"],["76393.3","0.130981"],["76393.4","0.003825"],["76394.3","0.001178"],["76394.5","0.396313"],["76395","0.015735"],["76395.9","0.03768"],["76396","0.126"],["76399","0.00023"],["76399.5","0.162437"],["76399.6","0.197718"],["76399.7","0.5999"],["76400","0.001005"],["76400.5","0.00515"],["76401.2","0.013104"],["76403.7","0.065752"],["76403.8","0.126"],["76404.3","0.013102"],["76405","0.031456"],["76405.8","0.048439"],["76406.1","0.001178"],["76406.6","0.000099"],["76407.3","0.013102"],["76408.3","0.360379"],["76408.9","0.108199"],["76409","0.199936"],["76410","0.000103"],["76410.2","0.162437"],["76411.3","0.001"],["76413.3","0.04703"],["76413.4","0.126"],["76414","0.031456"],["76414.2","0.000099"],["76417.4","0.048839"],["76417.5","0.162437"],["76417.9","0.001178"],["76418.6","0.005094"],["76419.7","0.048439"],["76420","0.000103"],["76420.4","0.187164"],["76420.5","0.626916"],["76421.8","0.000099"],["76422.5","0.015735"],["76422.9","0.175777"],["76423","0.126"],["76423.5","0.3562"],["76424.8","0.00119"],["76424.9","0.000099"],["76426.2","0.08757"],["76426.3","0.12981"],["76426.7","0.031456"],["76428.3","0.00002"],["76428.6","0.130981"],["76428.7","0.001"],["76429.4","0.000099"],["76429.6","0.001178"],["76430","0.000103"],["76431.7","0.010144"],["76431.8","0.005216"],["76432.2","0.00017"],["76432.4","0.002381"],["76432.6","0.000142"],["76432.9","0.005112"],["76433.5","0.000215"],["76433.8","0.000332"],["76434","0.000411"],["76434.3","0.00011"],["76434.4","0.314468"],["76434.5","1.004092"],["76434.7","0.000092"],["76435","0.000078"],["76435.3","0.000411"],["76435.9","0.031599"],["76436","0.000328"],["76436.1","0.000574"],["76436.4","0.000133"],["76436.5","0.015482"],["76437","0.000099"],["76437.1","0.058913"],["76437.2","0.126"],["76437.3","0.000583"],["76437.5","0.002122"],["76437.9","0.00126"],["76438","0.000277"],["76438.1","0.000635"],["76439.3","0.130981"],["76440","0.000941"],["76440.2","0.00055"],["76440.7","0.048439"],["76440.8","0.074855"],["76440.9","0.086451"],["76441.4","0.001178"],["76441.5","0.130956"],["76441.6","0.000589"],["76442.2","0.00013"],["76442.5","0.000814"],["76442.7","0.014949"],["76442.8","0.000897"],["76442.9","0.00041"],["76443.2","0.00032"],["76443.5","0.000094"],["76443.9","0.000074"],["76444","0.001124"],["76444.2","0.031456"],["76444.6","0.000099"],["76444.8","0.000102"],["76444.9","0.246269"],["76445","0.815025"],["76445.9","0.003961"],["76446.2","0.00282"],["76446.3","0.000356"],["76446.5","0.000108"],["76447.6","0.000423"],["76447.8","0.000116"],["76448","0.001811"],["76448.1","0.000402"],["76448.6","0.001252"],["76449.5","0.086451"],["76449.6","0.000016"],["76450","0.067061"],["76450.5","0.031456"],["76450.6","0.232916"],["76450.7","0.629604"],["76450.9","0.000395"],["76451.2","0.000186"],["76451.3","0.130981"],["76451.6","0.000103"],["76452.2","0.017644"],["76452.4","0.741774"],["76452.7","0.00515"],["76453.1","0.000412"],["76453.2","0.001397"],["76453.3","0.038924"],["76453.4","0.126172"],["76453.6","0.000342"],["76454","0.000859"],["76454.3","0.0001"],["76454.4","0.001373"],["76454.7","0.0001"],["76455","0.000078"],["76455.2","0.00027"],["76455.4","0.000103"],["76456.2","0.016369"],["76456.6","0.000542"],["76456.7","0.031456"],["76456.8","0.402305"],["76456.9","1.206"],["76457","0.001759"],["76457.6","0.130981"],["76458","0.0001"]],"u":28058049,"seq":105954705558},"cts":1776816000866}
{"topic":"orderbook.200.BTCUSDT","ts":1776816000968,"type":"delta","data":{"s":"BTCUSDT","b":[["76358.2","0.573407"],["76351.8","0.025642"],["76351","0.006545"],["76350.8","0"],["76350.7","0.013201"],["76339.6","0"],["76330.2","0.115928"],["76307.7","0.204644"],["76258.1","1.74729"],["76251.5","1.747441"],["76200","0"],["76199.6","0"]],"a":[["76358.3","0.247653"],["76361.7","0"],["76376.4","0"],["76377.8","0.006545"],["76379.2","0.031456"],["76380.8","0.050499"],["76458","0"]],"u":28058050,"seq":105954705653},"cts":1776816000967}
{"topic":"orderbook.200.BTCUSDT","ts":1776816001069,"type":"delta","data":{"s":"BTCUSDT","b":[["76363","0.861962"],["76359.1","0.058802"],["76359","0.131257"],["76358.2","0.065735"],["76356","0.006544"],["76355.9","0.026193"],["76355.4","0.0132"],["76354.9","0.025641"],["76352.6","0.07889"],["76351.9","0"],["76351","0"],["76350.6","0"],["76346.2","0"],["76339.7","0.018209"],["76331.5","0.096955"],["76321.6","0.365306"],["76294.8","0"],["76258.2","0.547372"],["76256.8","0"],["76252.3","0.726709"],["76245.4","0.00515"],["76242.9","0"],["76225.7","0"],["76212.1","0.00464"],["76205.8","0"],["76205.2","0"],["76204.8","0"],["76203.4","0"]],"a":[["76358.3","0"],["76361.6","0"],["76363.1","0.040747"],["76365.9","0"],["76369.9","0"],["76370.6","0"],["76370.7","0.0132"],["76374.7","0.006545"],["76377.8","0"],["76379.2","0"],["76380.8","0"],["76380.9","0"],["76382","0.05931"],["76382.1","0.03766"],["76382.2","0.064959"],["76385.2","0.108964"],["76385.3","0.076503"],["76385.6","0"],["76408.2","0.108199"],["76408.3","0"],["76408.9","0"],["76437.1","0.085592"],["76452.3","0.262122"],["76452.4","0.000135"],["76453.3","0"],["76458","0.0001"],["76458.2","0.00041"],["76458.4","0.00041"],["76458.8","0.000198"]],"u":28058051,"seq":105954705991},"cts":1776816001062}
{"topic":"orderbook.200.BTCUSDT","ts":1776816001169,"type":"delta","data":{"s":"BTCUSDT","b":[["76363","0.625638"],["76356","0"],["76355.5","0.006544"],["76354.9","0"],["76354","0.025641"],["76334.1","0.058597"],["76294.9","0"],["76205.8","0.001178"]],"a":[["76363.1","0.044711"],["76367.2","0.092173"],["76367.3","0.114824"],["76367.5","0.079741"],["76367.6","0"],["76376.4","0.031456"],["76381.2","0.006545"],["76381.9","0.027475"],["76382","0"],["76382.1","0"],["76382.2","0"],["76385.3","0"],["76452.3","0"]],"u":28058052,"seq":105954706066},"cts":1776816001155}
{"topic":"orderbook.200.BTCUSDT","ts":1776816001269,"type":"delta","data":{"s":"BTCUSDT","b":[["76363","0.679738"],["76355.6","0.006544"],["76355.5","0"],["76322.6","0.254884"],["76301.3","0.743107"],["76295.8","0.100557"],["76208.3","0"],["76205.8","0"]],"a":[["76363.1","0.123721"],["76367","0.034096"],["76367.2","0"],["76367.3","0"],["76367.5","0"],["76374.7","0"],["76376.4","0"],["76381.9","0"],["76408.3","0.357539"],["76453.3","0.038625"],["76458.9","0.741809"],["76459.5","0.0061"],["76459.8","0.000107"]],"u":28058053,"seq":105954706190},"cts":1776816001265}
{"topic":"orderbook.200.BTCUSDT","ts":1776816001371,"type":"delta","data":{"s":"BTCUSDT","b":[["76360.8","0.019486"],["76355.6","0"],["76354.1","0.006544"],["76354","0"],["76353.2","0.026256"],["76351.8","0"],["76340.6","0.024186"],["76304","0.462411"],["76252.3","0"],["76211","0.002357"],["76208.4","0"]],"a":[["76363.1","0.11229"],["76379.8","0.006545"],["76380","0.05935"],["76381.2","0"],["76381.3","0.001"],["76382","0.048093"],["76382.1","0.062068"],["76382.3","0.066314"],["76385.1","0.052109"],["76408.2","0.201091"],["76443.8","0.024672"],["76456.8","0.571796"],["76458.4","0"],["76458.8","0"],["76458.9","0"],["76459.5","0"],["76459.8","0"]],"u":28058054,"seq":105954706272},"cts":1776816001362}
{"topic":"orderbook.200.BTCUSDT","ts":1776816001469,"type":"delta","data":{"s":"BTCUSDT","b":[["76354.1","0"],["76353.9","0.006544"],["76340.7","0.030125"],["76339.7","0"],["76330.2","0.105837"],["76252.3","0.384911"],["76208.9","0"]],"a":[["76363.1","0.11502"],["76377.6","0.010106"],["76382","0.028298"],["76382.3","0"],["76385.1","0"],["76408.2","0.108199"],["76408.3","0"],["76458.4","0.00041"],["76458.8","0.000198"]],"u":28058055,"seq":105954706354},"cts":1776816001464}
{"topic":"orderbook.200.BTCUSDT","ts":1776816001569,"type":"delta","data":{"s":"BTCUSDT","b":[["76354.8","0.006544"],["76353.9","0"],["76271.6","0.12"],["76211","0"]],"a":[["76363.1","0.11775"],["76394.2","0.015214"],["76394.3","0.358206"],["76458.8","0"]],"u":28058056,"seq":105954706400},"cts":1776816001561}
{"topic":"orderbook.200.BTCUSDT","ts":1776816001669,"type":"delta","data":{"s":"BTCUSDT","b":[["76334.1","0.034003"],["76331.5","0"],["76276","0"],["76229.4","0"],["76211","0.002357"],["76208.9","0.025633"],["76208.4","0.065507"]],"a":[["76363.1","0.129075"],["76366","0.011304"],["76368.6","0.012117"],["76370","0.01133"],["76377.6","0"],["76391.6","0.307119"],["76392.7","0"],["76393.2","0.015181"],["76394.2","0"],["76448.4","0.12"]],"u":28058057,"seq":105954706464},"cts":1776816001664}
{"topic":"orderbook.200.BTCUSDT","ts":1776816001768,"type":"delta","data":{"s":"BTCUSDT","b":[["76363","0.679857"],["76354.8","0"],["76353.9","0.006544"],["76353.2","0"],["76352.5","0.076256"],["76277.1","0.108582"],["76252.3","0.463072"],["76208.3","0.648339"]],"a":[["76363.1","0.129194"],["76382","0"],["76382.1","0"],["76458.8","0.000198"],["76458.9","0.741809"]],"u":28058058,"seq":105954706494},"cts":1776816001756}
{"topic":"orderbook.200.BTCUSDT","ts":1776816001869,"type":"delta","data":{"s":"BTCUSDT","b":[],"a":[["76392.5","0.015151"],["76393.2","0"]],"u":28058059,"seq":105954706508},"cts":1776816001866}
{"topic":"orderbook.200.BTCUSDT","ts":1776816001969,"type":"delta","data":{"s":"BTCUSDT","b":[["76363","0.099784"],["76360.6","0.058802"],["76360.5","0.131059"],["76359.1","0"],["76359","0.000198"],["76355.4","0.0064"],["76353.9","0"],["76352.7","0.010211"],["76352.5","0.05"],["76351.3","0.026256"],["76350.8","0.006544"],["76208.9","0"],["76208.4","0"],["76208.3","0"]],"a":[["76363.1","0.751722"],["76370.7","0.0064"],["76376.1","0.006545"],["76379.8","0"],["76380","0.000103"],["76381","0.010119"],["76458.9","0"]],"u":28058060,"seq":105954706799},"cts":1776816001967}
{"topic":"orderbook.200.BTCUSDT","ts":1776816002069,"type":"delta","data":{"s":"BTCUSDT","b":[["76363","0.045584"],["76360.9","0.001309"],["76358.2","0.035735"],["76351.3","0"],["76350.8","0"],["76349","0.006545"],["76347","0.023765"],["76344.1","0"],["76340.8","0.031456"],["76301.4","0.031456"],["76245","0.048439"],["76212.1","0"],["76211","0"]],"a":[["76363.1","0.768226"],["76365.8","0.011227"],["76365.9","0.011018"],["76366","0"],["76368.6","0.001099"],["76370","0.000103"],["76374.7","0.006546"],["76376.1","0"],["76377.9","0.078439"],["76379.3","0.031456"],["76458.4","0"],["76458.8","0"]],"u":28058061,"seq":105954707041},"cts":1776816002068}
{"topic":"orderbook.200.BTCUSDT","ts":1776816002171,"type":"delta","data":{"s":"BTCUSDT","b":[["76352.6","0.05843"],["76349.8","0.006545"],["76349.6","0"],["76349","0"],["76348.8","0.091745"],["76294","1.02642"],["76212.1","0.00464"]],"a":[["76363.1","0.779934"],["76365.9","0"],["76369.3","0.015735"],["76370.6","0.01"],["76372.8","0.03"],["76450.6","1.21194"],["76458.2","0"]],"u":28058062,"seq":105954707208},"cts":1776816002167}
{"topic":"orderbook.200.BTCUSDT","ts":1776816002268,"type":"delta","data":{"s":"BTCUSDT","b":[["76360.9","0"],["76360.8","0"],["76360.7","0.001309"],["76360.3","0.021967"],["76349.8","0"],["76349","0.006545"],["76332.3","0.006549"],["76295.8","0.384698"],["76212.1","0"]],"a":[["76374.7","0"],["76375","0.006546"],["76450.5","0.556323"],["76450.6","0.979434"]],"u":28058063,"seq":105954707365},"cts":1776816002264}
{"topic":"orderbook.200.BTCUSDT","ts":1776816002369,"type":"delta","data":{"s":"BTCUSDT","b":[["76360.7","0"],["76360.6","0.001309"],["76350.6","0.006545"],["76349","0"],["76267.5","0"],["76242.3","0"],["76217.2","0.005309"],["76212.1","0.00464"],["76211","0.002357"],["76208.9","0.025633"]],"a":[["76363.1","0.774474"],["76368.3","0"],["76375","0"],["76375.2","0.006546"],["76393.4","0"],["76418.6","0"],["76458.2","0.00041"],["76458.4","0.00041"],["76458.8","0.000198"]],"u":28058064,"seq":105954707467},"cts":1776816002366}
{"topic":"orderbook.200.BTCUSDT","ts":1776816002470,"type":"delta","data":{"s":"BTCUSDT","b":[["76363","0"],["76360.6","0"],["76360.5","0"],["76360.3","0"],["76359","0"],["76358.2","0"],["76355.9","0"],["76355.4","0"],["76354.7","0"],["76354.2","0.193535"],["76353.9","0.055558"],["76352.7","0"],["76352.6","0"],["76352.5","0.02"],["76351.9","0.026194"],["76350.6","0"],["76350.5","0"],["76348.8","0.065488"],["76348","0.0004"],["76347","0"],["76346.6","0.006"],["76345.4","0.015735"],["76343.4","0"],["76340.8","0"],["76340","0"],["76337.4","0"],["76335.3","0.024188"],["76334.1","0.017178"],["76334","0"],["76330.8","0"],["76330.4","0.032456"],["76328.5","0.130981"],["76328.4","0.00515"],["76325.8","0.031456"],["76285","0.015735"],["76267.5","0.002634"],["76242.3","0.003966"],["76208.4","0.065507"],["76208.3","0.648339"],["76205.8","0.001178"],["76205.2","0.126"],["76204.8","0.130981"],["76203.4","0.677626"],["76200","0.007145"],["76199.6","0.17438"]],"a":[["76354.3","0.989564"],["76354.7","0.004196"],["76355","0.011194"],["76356","0.03"],["76360.4","0.011124"],["76361","0.010994"],["76361.7","0.015735"],["76361.9","0.006"],["76363.1","0.100423"],["76363.4","0.0004"],["76364.1","0.112448"],["76365.8","0"],["76368.1","0"],["76368.2","0.006546"],["76368.3","0.002588"],["76368.4","0.126"],["76369.3","0"],["76370.7","0"],["76370.8","0.030748"],["76371.6","0.031456"],["76375.2","0"],["76376.2","0.031555"],["76380.6","0.052188"],["76380.7","0.130981"],["76418.6","0.005136"],["76443.8","0"],["76456.2","0"],["76456.6","0"],["76456.7","0"],["76456.8","0"],["76456.9","0"],["76457","0"],["76457.6","0"],["76458","0"],["76458.2","0"],["76458.4","0"],["76458.8","0"]],"u":28058065,"seq":105954708541},"cts":1776816002468}
{"topic":"orderbook.200.BTCUSDT","ts":1776816002569,"type":"delta","data":{"s":"BTCUSDT","b":[["76354.2","0.251919"],["76348","0"],["76346.6","0.0064"],["76345.3","0.026258"],["76344.4","0.026259"],["76344","0.063803"],["76335.3","0"],["76332.2","0.024189"],["76328.3","0.00515"],["76275.7","0.000099"],["76268.7","0.197629"],["76250.9","0"],["76226","0.001146"],["76200","0"],["76199.6","0"]],"a":[["76354.7","0"],["76356","0.03091"],["76357.4","0.011124"],["76360.4","0.019839"],["76361.9","0.0064"],["76362.9","0.075902"],["76363","0.045584"],["76363.1","0.091023"],["76363.4","0"],["76368.2","0"],["76369.9","0.006546"],["76370.7","0.018568"],["76374.8","0"],["76375.1","0"],["76393.4","0.003868"],["76400","0.000103"],["76424.8","0"]],"u":28058066,"seq":105954708697},"cts":1776816002568}
{"topic":"orderbook.200.BTCUSDT","ts":1776816002669,"type":"delta","data":{"s":"BTCUSDT","b":[["76354.2","0.267639"],["76353.9","0.040655"],["76351.9","0"],["76345.3","0"],["76344.5","0.006546"],["76344","0.057257"],["76339.4","0.039997"],["76277.1","0.35617"],["76275.7","0.00065"],["76273.9","0.849888"],["76269.4","0.105115"],["76252.3","0.078161"],["76250.9","0.000848"],["76203.4","0"]],"a":[["76354.3","0.992804"],["76356","0.03"],["76360.4","0"],["76371.6","0.041876"],["76375.1","0.000621"],["76381","0"],["76388.1","0.288489"],["76388.3","0.845675"],["76424.8","0.001196"],["76431.1","0.00515"],["76455.2","0"],["76455.4","0"]],"u":28058067,"seq":105954708788},"cts":1776816002668}
{"topic":"orderbook.200.BTCUSDT","ts":1776816002769,"type":"delta","data":{"s":"BTCUSDT","b":[["76354.2","0.251919"],["76345.8","0.006546"],["76345.7","0.027258"],["76344.5","0"],["76340.7","0.044691"],["76340.2","0.048439"],["76339.4","0.011"],["76335.9","0.189405"],["76204.8","0"]],"a":[["76354.3","0.997496"],["76356","0"],["76363.1","0.071023"],["76369.9","0"],["76370.5","0.006546"],["76400","0.001012"],["76439.8","0.024672"]],"u":28058068,"seq":105954708904},"cts":1776816002767}
{"topic":"orderbook.200.BTCUSDT","ts":1776816002869,"type":"delta","data":{"s":"BTCUSDT","b":[["76351.9","0.026194"],["76348.7","0.015735"],["76345.8","0"],["76345.6","0.007546"],["76345.4","0"]],"a":[["76354.3","0.9508"]],"u":28058069,"seq":105954708958},"cts":1776816002868}
{"topic":"orderbook.200.BTCUSDT","ts":1776816002971,"type":"delta","data":{"s":"BTCUSDT","b":[["76351.9","0"],["76345.7","0.001"],["76345.6","0.001"],["76345.3","0.026258"],["76344.5","0.006546"],["76340.6","0"],["76339.6","0.028997"],["76321.6","0"]],"a":[["76354.3","0.95353"],["76369.9","0.006546"],["76370.5","0"],["76394.3","0.001178"]],"u":28058070,"seq":105954709045},"cts":1776816002968}
{"topic":"orderbook.200.BTCUSDT","ts":1776816003069,"type":"delta","data":{"s":"BTCUSDT","b":[["76354.2","0.489352"],["76351.9","0.026194"],["76347.3","0.006546"],["76346.4","0.026258"],["76345.3","0"],["76344.5","0"],["76322.6","0.16669"],["76252.3","0.099748"],["76205.2","0"]],"a":[["76354.3","0.488252"],["76357.4","0"],["76360.3","0.011134"],["76369.9","0"],["76372.4","0.006546"],["76391.6","0.161622"]],"u":28058071,"seq":105954709154},"cts":1776816003066}
{"topic":"orderbook.200.BTCUSDT","ts":1776816003169,"type":"delta","data":{"s":"BTCUSDT","b":[["76354.2","0.492082"],["76348.9","0.067253"],["76347.3","0"],["76347.1","0.026258"],["76346.4","0"],["76345.9","0.010481"],["76332.2","0"],["76321.4","0.365513"]],"a":[["76354.3","0.257784"],["76368.3","0.034044"],["76370.6","0"],["76371.6","0.031456"],["76372.4","0"],["76375","0.006546"],["76388.3","1.210491"],["76455.2","0.00027"]],"u":28058072,"seq":105954709245},"cts":1776816003168}
{"topic":"orderbook.200.BTCUSDT","ts":1776816003269,"type":"delta","data":{"s":"BTCUSDT","b":[["76354.2","0.492992"],["76351.7","0.028083"],["76348.9","0.060707"],["76348.8","0.072033"],["76344.4","0"],["76322.6","0.254485"]],"a":[["76354.3","0.257126"],["76391.5","0.014977"],["76392.5","0"]],"u":28058073,"seq":105954709339},"cts":1776816003261}
{"topic":"orderbook.200.BTCUSDT","ts":1776816003369,"type":"delta","data":{"s":"BTCUSDT","b":[["76354.2","0.505072"],["76352","0.015735"],["76349","0.006545"],["76348.8","0.065488"],["76348.7","0"],["76205.8","0"]],"a":[["76355","0"],["76361.7","0"],["76365.4","0.015735"],["76443.1","0.12"]],"u":28058074,"seq":105954709391},"cts":1776816003368}
{"topic":"orderbook.200.BTCUSDT","ts":1776816003469,"type":"delta","data":{"s":"BTCUSDT","b":[["76361.4","0.391704"],["76359.8","0.276102"],["76359.7","0.0275"],["76359.2","0.255348"],["76359.1","0.2628"],["76357.1","0.004373"],["76354.9","0.01749"],["76354.8","0.126"],["76354.3","0.24609"],["76354.2","0.26412"],["76353.8","0.109395"],["76351.7","0"],["76350.8","0.006545"],["76350.7","0.041285"],["76349","0"],["76346.6","0"],["76345.7","0.024378"],["76332.3","0"],["76298.6","0.082001"],["76292.2","0.013101"],["76289.8","0.013101"],["76270.7","0"],["76261.6","0"],["76214.6","0"],["76214.2","0"],["76212.1","0"],["76211","0"],["76208.9","0"],["76208.4","0"],["76208.3","0"]],"a":[["76354.3","0"],["76360.3","0"],["76361","0"],["76361.5","0.468481"],["76361.8","0.126359"],["76361.9","0"],["76363.1","0.041023"],["76364.4","0.011204"],["76365.4","0"],["76368.3","0.002588"],["76368.4","0.011004"],["76369.1","0.0064"],["76371.9","0.011134"],["76375","0"],["76376.1","0.006546"],["76401.2","0"],["76404.3","0"],["76413","0.013101"],["76418","0.013101"],["76440.8","0.106917"]],"u":28058075,"seq":105954709858},"cts":1776816003467}
{"topic":"orderbook.200.BTCUSDT","ts":1776816003569,"type":"delta","data":{"s":"BTCUSDT","b":[["76361.4","0.204426"],["76359.8","0"],["76359.7","0"],["76359.2","0"],["76359.1","0.02"],["76357.1","0"],["76355.4","0.015735"],["76354.9","0"],["76354.3","0"],["76354.2","0.03"],["76353.9","0"],["76352.1","0.026793"],["76352","0"],["76350.7","0.013201"],["76348.1","0.028085"],["76347.1","0"],["76340","0.015735"],["76336.2","0.027177"],["76317","0.097441"],["76298.7","0.048821"],["76298.5","0"],["76285","0"],["76258.2","0.17542"],["76214.6","0.126"],["76214.2","6.180768"],["76212.1","0.00464"],["76211","0.002357"]],"a":[["76361.5","0.676614"],["76361.8","0"],["76361.9","0.022109"],["76365.3","0.011134"],["76367","0"],["76368","0.015735"],["76370.7","0"],["76371.6","0"],["76371.9","0"],["76376.1","0.031456"],["76376.2","0.000099"],["76377.1","0.006546"],["76377.2","0.010203"],["76379.3","0"],["76380.6","0"],["76380.7","0"],["76385.1","0.130981"],["76385.2","0"],["76387.1","0"],["76396.1","0.096196"],["76425.9","0.002279"],["76455.4","0.000103"],["76456.2","0.016369"]],"u":28058076,"seq":105954710162},"cts":1776816003567}
{"topic":"orderbook.200.BTCUSDT","ts":1776816003669,"type":"delta","data":{"s":"BTCUSDT","b":[["76355.4","0"],["76354.8","0"],["76354.3","0.041609"],["76352.6","0.02438"],["76352.1","0"],["76351.8","0.015735"],["76350.8","0"],["76349.3","0.006545"],["76349.2","0.028084"],["76340.3","0.031456"],["76340","0"],["76339.6","0"],["76336.7","0.006549"],["76285","0.015735"],["76225.7","0.239392"],["76214.2","0"],["76212.1","0"],["76211","0"]],"a":[["76361.5","0.710296"],["76361.9","0"],["76364.1","0.123463"],["76364.4","0"],["76365.3","0"],["76368.4","0"],["76375.3","0.007546"],["76377.1","0"],["76456.6","0.000542"],["76456.7","0.031456"],["76456.8","0.571796"],["76456.9","1.206"],["76457","0.001759"]],"u":28058077,"seq":105954710346},"cts":1776816003665}
{"topic":"orderbook.200.BTCUSDT","ts":1776816003771,"type":"delta","data":{"s":"BTCUSDT","b":[["76355.6","0.015735"],["76351.8","0"],["76350.8","0.006545"],["76349.3","0"],["76349.2","0"],["76340","0.015735"],["76285","0"],["76214.2","6.180768"]],"a":[["76361.5","0.7318"],["76369.9","0.011"],["76375.3","0.001"],["76376","0.006546"],["76378.3","0.03"],["76389.9","0.014929"],["76391.5","0"],["76456.8","0"],["76456.9","0"],["76457","0"]],"u":28058078,"seq":105954710426},"cts":1776816003769}
{"topic":"orderbook.200.BTCUSDT","ts":1776816003869,"type":"delta","data":{"s":"BTCUSDT","b":[["76361.4","0.481946"],["76360.1","0.01428"],["76359.4","0.015735"],["76358.6","0.026192"],["76355.7","0.006544"],["76355.6","0"],["76353.7","0.126"],["76351.9","0"],["76351.5","0.028083"],["76350.8","0"],["76346.2","0.031456"],["76345.7","0.001"],["76344","0.084343"],["76342.9","0.130981"],["76303.9","0"],["76254.2","0"],["76215.5","0"],["76214.6","0"],["76214.2","0"]],"a":[["76361.5","0.208591"],["76362.9","0"],["76363.1","0.040825"],["76364.1","0.112448"],["76368","0.000198"],["76368.6","0.012244"],["76369.6","0.011015"],["76372.7","0"],["76376","0"],["76376.1","0"],["76377.2","0"],["76377.9","0.03"],["76381.2","0.006545"],["76382.4","0"],["76383.1","0.031456"],["76385.1","0"],["76385.5","0"],["76386.3","0.031456"],["76388.3","0.845675"],["76389.4","0"],["76392.6","0"],["76394.4","0.031456"],["76395","0"],["76396.1","0"],["76439.8","0"],["76456.8","0.571796"],["76456.9","1.206"],["76457","0.001759"],["76457.5","0.193578"],["76457.6","0.130981"],["76458","0.0001"],["76458.2","0.00041"],["76458.4","0.00041"]],"u":28058079,"seq":105954710697},"cts":1776816003867}
{"topic":"orderbook.200.BTCUSDT","ts":1776816003969,"type":"delta","data":{"s":"BTCUSDT","b":[["76367.9","0.983278"],["76366.1","0.423412"],["76365.1","0.065865"],["76365","0.404062"],["76364.8","0.147652"],["76364.6","0.004534"],["76364","0.058022"],["76363.5","0.479956"],["76363.3","0.002"],["76363.2","0.128452"],["76363.1","0.047556"],["76363","0.103602"],["76362.9","0.061422"],["76361.6","0.000198"],["76361.4","0.03"],["76360.3","0.002"],["76360.1","0"],["76359.4","0"],["76359.2","0.022827"],["76359","0.026192"],["76358.6","0.002102"],["76358.2","0.000099"],["76356.5","0.002"],["76355.7","0"],["76355.3","0.0024"],["76354.8","0.028082"],["76354.3","0.073901"],["76353.8","0.102995"],["76352.5","0.068439"],["76345.9","0"],["76336.7","0"],["76336.2","0"],["76319.2","0.084388"],["76316.2","0.945148"],["76304","0.275862"],["76297.5","0.013099"],["76297","0.0131"],["76292.8","0.0131"],["76283.6","0"],["76282.1","0"],["76274.2","0"],["76269.4","0.052898"],["76262.2","0"],["76258.2","0"],["76252.3","0.021587"],["76249.7","0"],["76226.4","0"],["76226.2","0"],["76226.1","0"],["76226","0"],["76225.7","0"],["76225.6","0"],["76223.6","0"],["76223.2","0"],["76223","0"],["76222.7","0"],["76218.4","0"],["76217.6","0"],["76217.2","0"]],"a":[["76361.5","0"],["76363","0"],["76363.1","0"],["76363.2","0"],["76364.1","0"],["76365.1","0"],["76368","0.179301"],["76368.6","0.001099"],["76369.1","0"],["76369.6","0"],["76369.9","0"],["76370.6","0.0024"],["76370.8","0.001178"],["76371.9","0.002"],["76372.8","0"],["76375.1","0.008152"],["76375.6","0.002"],["76376.5","0"],["76376.7","0"],["76377.9","0"],["76378","0.007461"],["76378.3","0"],["76379.7","0.007331"],["76381.2","0"],["76382.4","0.021522"],["76382.5","0.072003"],["76383.1","0"],["76383.7","0.010249"],["76385.4","0.064702"],["76386.3","0"],["76388","0.031456"],["76393.2","0.006545"],["76407.3","0"],["76413","0"],["76419.2","0.0131"],["76420.7","0.0131"],["76420.8","0.013099"],["76450","0.082796"],["76457.5","0"],["76458.8","0.000198"],["76458.9","0.741809"],["76459.5","0.0061"],["76459.8","0.000107"],["76460","0.000919"],["76460.5","0.000283"],["76461","0.254756"]],"u":28058080,"seq":105954711569},"cts":1776816003967}
{"topic":"orderbook.200.BTCUSDT","ts":1776816004069,"type":"delta","data":{"s":"BTCUSDT","b":[["76370.7","1.491087"],["76368.5","0.461487"],["76368.3","0.162186"],["76368.2","0.397752"],["76368","0.03"],["76367.9","0.045735"],["76367.8","0.001"],["76366.1","0"],["76365.1","0.006543"],["76365","0.2184"],["76364.8","0.02"],["76364","0"],["76363.5","0"],["76363.3","0"],["76363.2","0"],["76363.1","0.0064"],["76363","0.126"],["76362.9","0.003102"],["76361.4","0.03065"],["76360.3","0"],["76359.8","0.013818"],["76359.7","0.026191"],["76359.2","0"],["76359","0"],["76358.6","0"],["76356.5","0"],["76355.3","0"],["76354.5","0.013102"],["76354.4","0.031456"],["76352.6","0.039025"],["76352.5","0.133927"],["76350.7","0.000099"],["76350.6","0.06551"],["76349.6","0.031456"],["76349.4","0.119993"],["76349.3","0.130981"],["76348.9","0"],["76348.8","0"],["76346.9","0"],["76319.2","0.362947"],["76311.1","0.743011"],["76300","0.001244"],["76283.7","0.040106"],["76270.4","0"],["76261.2","0"],["76258.2","0.175877"],["76238.5","0.00652"],["76229.3","0"]],"a":[["76368","0"],["76368.3","0"],["76368.6","0"],["76370","0"],["76370.6","0"],["76370.8","0.252822"],["76371.9","0"],["76375.4","0.008368"],["76375.6","0"],["76376.8","0.013092"],["76377.8","0.030714"],["76378.4","0.0064"],["76378.7","0.065463"],["76380.6","0.065461"],["76381","0.063165"],["76382.4","0"],["76382.5","0.001178"],["76383.7","0"],["76384.5","0.02956"],["76385.4","0.037641"],["76387.9","0.015735"],["76388","0"],["76391.3","0.006544"],["76393.2","0"],["76393.3","0"],["76394.4","0"],["76396.4","0.031456"],["76440","0.000875"],["76461","0.03826"],["76461.1","0.126"],["76461.2","0.000713"],["76462.5","0.000192"]],"u":28058081,"seq":105954712413},"cts":1776816004067}
{"topic":"orderbook.200.BTCUSDT","ts":1776816004169,"type":"delta","data":{"s":"BTCUSDT","b":[["76370.7","1.475075"],["76368.6","0.072814"],["76368.5","0"],["76368.3","0.004534"],["76368.2","0"],["76368","0"],["76365.1","0"],["76364.7","0.006543"],["76363.1","0.081602"],["76362.3","0.113081"],["76361.4","0.03"],["76361","0.0222"],["76360.9","0.026191"],["76359.8","0"],["76359.7","0"],["76358","0.028081"],["76354.3","0.041609"],["76353.8","0"],["76352.6","0.072345"],["76352.5","0.085488"],["76349.4","0.08089"],["76336.4","0.003275"],["76317","0"],["76311.2","0.221789"],["76283","0"],["76269.4","0.101564"],["76261.5","0.5999"],["76258.2","0"],["76229.3","0.001178"]],"a":[["76370.8","0.312846"],["76377.8","0.029405"],["76380.5","0.02022"],["76381","0"],["76385.4","0.070323"],["76386.8","0.12561"],["76388.2","0.137293"],["76391.3","0"],["76391.8","0.006544"],["76400.8","0.37155"],["76405.8","0.147389"],["76416.6","0.003272"],["76461.1","0"],["76461.2","0"],["76462.5","0"]],"u":28058082,"seq":105954712679},"cts":1776816004160}
{"topic":"orderbook.200.BTCUSDT","ts":1776816004269,"type":"delta","data":{"s":"BTCUSDT","b":[["76370.7","1.479609"],["76368.6","0"],["76368.3","0"],["76365.1","0.006544"],["76365","0"],["76364.7","0"],["76363.1","0.054145"],["76362.3","0.139271"],["76360.9","0"],["76358","0"],["76357.9","0.013102"],["76357.3","0.028081"],["76356","0.065488"],["76354.5","0"],["76354.1","0.06551"],["76352.5","0.02"],["76350.6","0"],["76343","0.396886"],["76335.7","0.000099"],["76301.3","0"],["76261.6","0.067201"],["76226.4","0.00162"],["76226.2","0.132601"]],"a":[["76370.8","0.318306"],["76375.1","0.000621"],["76376.8","0"],["76378.2","0.007531"],["76378.6","0.012"],["76378.7","0"],["76380.6","0"],["76382.4","0.006543"],["76384.5","0.042652"],["76386.4","0.065463"],["76388.4","0.065461"],["76389.9","0.021473"],["76390.5","0"],["76391.8","0"],["76393.2","0.130981"],["76394.5","0"],["76407.8","0.396313"],["76409","0"],["76422.3","0.199936"],["76423.5","0"],["76425.9","0"],["76428.7","0"],["76436.8","0.3562"],["76450.9","0.001395"],["76458.9","0.000233"],["76461.1","0.126"],["76461.2","0.000713"]],"u":28058083,"seq":105954712820},"cts":1776816004267}
{"topic":"orderbook.200.BTCUSDT","ts":1776816004369,"type":"delta","data":{"s":"BTCUSDT","b":[["76370.7","0.255996"],["76368","0.01992"],["76367.9","0.015735"],["76365.1","0"],["76364.6","0"],["76364.1","0.004534"],["76363.1","0.0064"],["76363","0"],["76362.9","0.001"],["76362.4","0.068959"],["76362.3","0.113081"],["76361","0"],["76359.2","0.006544"],["76359","0.010417"],["76358.1","0.002102"],["76357.3","0"],["76356.1","0.103441"],["76354.4","0"],["76354.3","0"],["76352.6","0.023772"],["76349.7","0.031456"],["76349.6","0"],["76349.4","0.041792"],["76349.3","0"],["76346.8","0.006548"],["76344","0.199351"],["76343.5","0.027174"],["76335.9","0.070935"],["76321.4","0"],["76307.9","0.743042"],["76304","0.063442"],["76261.6","0.247516"],["76258.2","0.153717"],["76226.4","0"],["76226.2","0"]],"a":[["76370.8","0.739994"],["76371.3","0.007368"],["76373.4","0.007461"],["76373.6","0.007531"],["76375.4","0.001"],["76377.7","0.014438"],["76377.8","0"],["76378","0"],["76378.2","0"],["76378.3","0.006544"],["76380.5","0"],["76382","0.031048"],["76382.1","0.118473"],["76382.4","0"],["76386.2","0.006545"],["76386.8","0"],["76387.5","0.010544"],["76387.9","0"],["76388","0.031456"],["76388.2","0.105837"],["76389.9","0.014929"],["76391.6","0.055063"],["76406.2","0.03"],["76407.7","0.166818"],["76408.2","0"],["76422.2","0.111765"],["76422.9","0.031456"],["76434.9","0.002279"],["76456.8","0.402305"],["76459.8","0"],["76460","0"],["76460.5","0"],["76461","0"],["76461.1","0"],["76461.2","0"]],"u":28058084,"seq":105954713151},"cts":1776816004367}
{"topic":"orderbook.200.BTCUSDT","ts":1776816004469,"type":"delta","data":{"s":"BTCUSDT","b":[["76370.7","0"],["76368","0"],["76367.9","0.111224"],["76363.1","0"],["76360.9","0.004534"],["76360.3","0.0064"],["76359.2","0.013647"],["76356.2","0.006544"],["76322.6","0.16669"],["76311.2","0.415232"],["76300","0.001178"],["76258.2","0.28007"]],"a":[["76368","0.953523"],["76370.7","0.122845"],["76370.8","0.099912"],["76374.8","0.006544"],["76374.9","0.007331"],["76375.6","0.0064"],["76375.7","0.126"],["76377.5","0.11875"],["76377.7","0"],["76378.3","0"],["76378.4","0"],["76379.7","0"],["76382","0"],["76382.1","0"],["76385.6","0.130981"],["76386.2","0"],["76395","0.015735"],["76403.7","0.091926"],["76440","0.000941"],["76450","0.067061"],["76458.9","0"],["76459.5","0"]],"u":28058085,"seq":105954713483},"cts":1776816004467}
{"topic":"orderbook.200.BTCUSDT","ts":1776816004572,"type":"delta","data":{"s":"BTCUSDT","b":[["76367.9","0.103799"],["76360.4","0.015735"],["76358.3","0.006544"],["76356.2","0"],["76355.8","0.028082"],["76348.1","0"],["76229.3","0"]],"a":[["76368","0.871992"],["76370.6","0.068964"],["76370.8","0.089382"],["76373.3","0.015735"],["76374.8","0"],["76375.5","0.042504"],["76377.4","0.045902"],["76383.6","0.006545"],["76458.2","0"],["76458.4","0"],["76458.8","0"]],"u":28058086,"seq":105954713614},"cts":1776816004567}
{"topic":"orderbook.200.BTCUSDT","ts":1776816004669,"type":"delta","data":{"s":"BTCUSDT","b":[["76367.9","0.375122"],["76364.9","0.006544"],["76364.1","0"],["76363.9","0.004534"],["76362.6","0.002085"],["76360.9","0"],["76360.5","0.022208"],["76359.2","0"],["76358.3","0"],["76358.1","0"],["76355.8","0"],["76354.4","0.048439"],["76337.8","0.098941"],["76336.7","0.369302"],["76230.7","0"]],"a":[["76368","0.251315"],["76370.6","0.001309"],["76370.8","0.059382"],["76371.3","0"],["76373.3","0"],["76373.4","0"],["76373.6","0"],["76374.9","0"],["76375.5","0.001"],["76375.7","0"],["76376","0.007374"],["76377.3","0.007467"],["76377.4","0.039358"],["76378.3","0.007537"],["76380.6","0.007337"],["76382.4","0.006544"],["76383.6","0"],["76384.4","0.031456"],["76385.6","0"],["76389.8","0.006545"],["76458.2","0.00041"]],"u":28058087,"seq":105954713795},"cts":1776816004666}
{"topic":"orderbook.200.BTCUSDT","ts":1776816004769,"type":"delta","data":{"s":"BTCUSDT","b":[["76367.9","0.518884"],["76367.3","0.004534"],["76364.9","0"],["76363.9","0"],["76363","0.006544"],["76362.7","0.02619"],["76362.4","0.042769"],["76359.6","0.02808"],["76353.8","0.031456"],["76343.5","0"],["76336.8","0.160083"],["76335.9","0.031456"],["76234","0"],["76233.9","0"],["76231","0"]],"a":[["76368","0.032581"],["76370.6","0.052129"],["76377.3","0"],["76378.5","0.007467"],["76384.4","0"],["76387.9","0.031456"],["76388","0"],["76391.6","0.020662"],["76393.2","0"],["76402.5","0.006837"],["76458.4","0.00041"]],"u":28058088,"seq":105954713981},"cts":1776816004768}
{"topic":"orderbook.200.BTCUSDT","ts":1776816004869,"type":"delta","data":{"s":"BTCUSDT","b":[["76367.9","0.528976"],["76367.3","0"],["76364.2","0.015735"],["76363.9","0.004534"],["76360.5","0.01493"],["76360.4","0"],["76359.6","0"],["76347.1","0.027173"]],"a":[["76368","0.086781"],["76371.9","0.007374"],["76374.2","0.007537"],["76374.6","0.007467"],["76376","0"],["76376.8","0.015735"],["76378.3","0"],["76378.5","0"],["76381.2","0.006544"],["76382.4","0"],["76388.3","0.85222"],["76389.8","0"],["76391.6","0.057118"],["76393.2","0.130981"],["76450.6","1.004106"],["76458.4","0"]],"u":28058089,"seq":105954714075},"cts":1776816004864}
{"topic":"orderbook.200.BTCUSDT","ts":1776816004968,"type":"delta","data":{"s":"BTCUSDT","b":[["76367.9","0.533852"],["76365.4","0.004534"],["76236.9","0"]],"a":[["76368","0.077681"],["76380.5","0.006544"],["76381.2","0"],["76388.1","0.295034"],["76388.3","0.845675"]],"u":28058090,"seq":105954714124},"cts":1776816004953}
{"topic":"orderbook.200.BTCUSDT","ts":1776816005069,"type":"delta","data":{"s":"BTCUSDT","b":[["76367.9","0.53559"],["76365.4","0"],["76363","0"],["76362.8","0.006544"],["76356.7","0.028081"]],"a":[["76368","0.253021"],["76379.8","0.006544"],["76380.5","0"],["76387.4","0.006545"],["76388.1","0.288489"],["76458.2","0"]],"u":28058091,"seq":105954714214},"cts":1776816005059}
{"topic":"orderbook.200.BTCUSDT","ts":1776816005169,"type":"delta","data":{"s":"BTCUSDT","b":[["76362.8","0"],["76362.5","0.006544"],["76284.5","0.12"],["76237.6","0"]],"a":[["76378.6","0.001"]],"u":28058092,"seq":105954714251},"cts":1776816005163}
{"topic":"orderbook.200.BTCUSDT","ts":1776816005268,"type":"delta","data":{"s":"BTCUSDT","b":[["76367.9","0.537838"],["76363","0.006544"],["76362.5","0"],["76357.3","0.028272"],["76356.7","0"],["76284.6","0.106403"],["76283.7","0"],["76237.6","0.126"]],"a":[["76368","0.077681"],["76379.8","0"],["76379.9","0.007544"],["76387.4","0"],["76387.9","0"],["76388","0.006545"],["76458.2","0.00041"],["76458.4","0.00041"]],"u":28058093,"seq":105954714327},"cts":1776816005266}
{"topic":"orderbook.200.BTCUSDT","ts":1776816005371,"type":"delta","data":{"s":"BTCUSDT","b":[["76370.6","0.308335"],["76370.5","0.02"],["76368.4","0.043036"],["76368.3","0.033977"],["76367.9","0.034534"],["76367.7","0.015735"],["76365.9","0.026189"],["76364.2","0"],["76363","0.087761"],["76362.9","0.127"],["76362.7","0.006544"],["76362.4","0"],["76361.6","0"],["76360.3","0"],["76358.2","0.028371"],["76357.3","0"],["76356.1","0.143773"],["76354.9","0.130981"],["76353.2","0.023547"],["76353.1","0.027329"],["76352.6","0"],["76351.5","0"],["76311.1","0"],["76300","0.001244"],["76258.2","0.153717"],["76237.6","0"]],"a":[["76368","0"],["76370.6","0"],["76370.7","0.536855"],["76374.6","0"],["76375.6","0"],["76376.8","0"],["76378.3","0.0064"],["76378.5","0.007467"],["76379.3","0.015735"],["76379.9","0.001"],["76380.4","0.006544"],["76387.4","0.006545"],["76388","0.031456"],["76391.6","0.020662"],["76393.2","0"],["76395.8","0.031456"],["76395.9","0.07196"],["76396.4","0"],["76398.2","0.130981"],["76399.5","0.031456"],["76405","0"],["76406.2","0"],["76440","0.000875"],["76450.6","0.979434"],["76458.8","0.000198"],["76458.9","0.000233"]],"u":28058094,"seq":105954714678},"cts":1776816005368}
{"topic":"orderbook.200.BTCUSDT","ts":1776816005469,"type":"delta","data":{"s":"BTCUSDT","b":[["76370.6","0.110616"],["76368.4","0.030476"],["76367.9","0.004534"],["76367.7","0"],["76364.6","0.015735"],["76362.7","0"],["76361.5","0.006544"],["76358.2","0.000099"],["76357.5","0.028272"],["76311.2","0.221789"],["76258.2","0.19505"],["76238.2","0"]],"a":[["76370.7","0.542315"],["76370.8","0.086654"],["76372.6","0.025115"],["76376","0.007467"],["76377.9","0.024325"],["76378.4","0.006544"],["76378.5","0"],["76380.4","0"],["76386.8","0.006545"],["76387.4","0"],["76388.2","0.236818"],["76458.8","0"],["76458.9","0"]],"u":28058095,"seq":105954714778},"cts":1776816005461}
{"topic":"orderbook.200.BTCUSDT","ts":1776816005568,"type":"delta","data":{"s":"BTCUSDT","b":[["76370.6","0.164816"],["76367.9","0"],["76357.5","0"],["76356.5","0.028273"],["76318.1","0.742943"]],"a":[["76370.7","0.555587"],["76372.5","0.014131"],["76373","0.00015"],["76375.9","0.015735"],["76378.4","0"],["76378.9","0.006544"],["76379","0.023877"],["76379.3","0"],["76386.8","0"],["76386.9","0.006545"],["76458.2","0"],["76458.4","0"]],"u":28058096,"seq":105954714858},"cts":1776816005566}
{"topic":"orderbook.200.BTCUSDT","ts":1776816005668,"type":"delta","data":{"s":"BTCUSDT","b":[["76370.6","0.186816"],["76365.5","0.004534"],["76362.4","0.006544"],["76361.5","0"],["76319.2","0.520016"],["76238.5","0"]],"a":[["76370.7","0.548307"],["76378.9","0"],["76379.8","0.006544"],["76386.9","0"],["76387.3","0.006545"]],"u":28058097,"seq":105954714925},"cts":1776816005665}
{"topic":"orderbook.200.BTCUSDT","ts":1776816005769,"type":"delta","data":{"s":"BTCUSDT","b":[["76370.6","0.187074"],["76362.4","0"],["76361.5","0.006544"]],"a":[["76370.7","0.559485"],["76386.9","0.006545"],["76387.3","0"]],"u":28058098,"seq":105954714972},"cts":1776816005761}
{"topic":"orderbook.200.BTCUSDT","ts":1776816005869,"type":"delta","data":{"s":"BTCUSDT","b":[["76370.6","0.187271"],["76357.9","0.041374"],["76356.5","0"],["76238.5","0.00652"]],"a":[["76370.7","0.561305"],["76405.8","0.048439"],["76453.8","0.024672"],["76458","0"]],"u":28058099,"seq":105954715001},"cts":1776816005856}
{"topic":"orderbook.200.BTCUSDT","ts":1776816005969,"type":"delta","data":{"s":"BTCUSDT","b":[["76362.4","0.006544"],["76361.5","0"],["76337.8","0"],["76335.6","0.098042"]],"a":[["76386.9","0"],["76387.4","0.006545"],["76403.7","0.065752"],["76405.8","0.146079"]],"u":28058100,"seq":105954715032},"cts":1776816005966}
{"topic":"orderbook.200.BTCUSDT","ts":1776816006069,"type":"delta","data":{"s":"BTCUSDT","b":[["76362.7","0.006544"],["76362.4","0"]],"a":[["76370.7","0.548565"],["76375.9","0"],["76379.8","0"],["76379.9","0.007544"],["76387.4","0"],["76387.8","0.006545"],["76395","0"],["76458","0.0001"],["76458.2","0.00041"],["76458.4","0.00041"]],"u":28058101,"seq":105954715114},"cts":1776816006062}
{"topic":"orderbook.200.BTCUSDT","ts":1776816006171,"type":"delta","data":{"s":"BTCUSDT","b":[["76370.6","0.190911"],["76362.7","0"],["76361.5","0.006544"],["76357.9","0.013102"],["76357.7","0.028272"],["76238.5","0"]],"a":[["76370.7","0.537113"],["76377","0.015735"],["76379.8","0.006544"],["76379.9","0.001"],["76387.4","0.006545"],["76387.8","0"],["76395","0.015735"],["76458","0"],["76458.2","0"],["76458.4","0"]],"u":28058102,"seq":105954715194},"cts":1776816006166}
{"topic":"orderbook.200.BTCUSDT","ts":1776816006268,"type":"delta","data":{"s":"BTCUSDT","b":[["76370.6","0.187271"]],"a":[["76370.7","0.55272"],["76379.6","0.006544"],["76379.8","0"],["76395.3","0.03"],["76457.6","0"]],"u":28058103,"seq":105954715259},"cts":1776816006261}
{"topic":"orderbook.200.BTCUSDT","ts":1776816006369,"type":"delta","data":{"s":"BTCUSDT","b":[["76370.6","0.023887"],["76370.5","0"],["76368.4","0.000198"],["76368.3","0"],["76368.2","0.033703"],["76365.9","0"],["76365.5","0"],["76364.6","0"],["76363.9","0"],["76363.1","0.004534"],["76363","0.049408"],["76362.9","0.041"],["76362.6","0"],["76361.5","0"],["76360.1","0.004534"],["76358.3","0.006544"],["76357.9","0.015136"],["76357.7","0"],["76356.1","0.103441"],["76354.9","0"],["76354.8","0"],["76353.8","0"],["76353.1","0"],["76351.8","0.028275"],["76349.7","0"],["76347.2","0.032634"],["76346.2","0"],["76344.1","0.162437"],["76343.2","0.028294"],["76342.9","0"],["76340.3","0"],["76308","0.031456"],["76274.3","0"],["76238.5","0.00652"],["76238.2","0.000099"],["76237.6","0.126"],["76236.9","0.130981"],["76234","0.000439"],["76233.9","0.048439"],["76231","0.00162"],["76230.7","0.000099"],["76229.3","0.001178"],["76226.4","0.00162"],["76226.2","0.132601"]],"a":[["76370.7","0.564865"],["76371.9","0"],["76376","0"],["76376.1","0.007354"],["76376.9","0.006544"],["76379.6","0"],["76380.6","0"],["76384.4","0.006545"],["76387.4","0"],["76457.6","0.130981"],["76458","0.0001"]],"u":28058104,"seq":105954715473},"cts":1776816006366}
{"topic":"orderbook.200.BTCUSDT","ts":1776816006468,"type":"delta","data":{"s":"BTCUSDT","b":[["76370.6","0.078087"],["76368.3","0.024146"],["76365.9","0.026189"],["76362.9","0.001"],["76361.1","0.015735"],["76355.1","0.028273"],["76353.2","0"],["76352.9","0.01444"],["76343.2","0.000099"],["76339.5","0.028197"],["76231","0"],["76230.7","0"],["76229.3","0"],["76226.4","0"],["76226.2","0"]],"a":[["76370.7","0.577605"],["76373.2","0.015735"],["76376","0.006544"],["76376.9","0"],["76377","0"],["76383.7","0.006545"],["76384.4","0"]],"u":28058105,"seq":105954715633},"cts":1776816006466}
{"topic":"orderbook.200.BTCUSDT","ts":1776816006569,"type":"delta","data":{"s":"BTCUSDT","b":[["76357.6","0.028272"],["76339.5","0"]],"a":[["76370.7","0.570121"],["76373.1","0.007484"],["76458","0"]],"u":28058106,"seq":105954715699},"cts":1776816006558}
{"topic":"orderbook.200.BTCUSDT","ts":1776816006669,"type":"delta","data":{"s":"BTCUSDT","b":[["76370.6","0.100087"],["76360.5","0"],["76359.2","0.02402"],["76359.1","0.026544"],["76358.6","0.028272"],["76358.3","0"],["76357.6","0"],["76231","0.00162"]],"a":[["76376","0"],["76377.3","0.006544"],["76383.7","0"],["76384.4","0.006545"]],"u":28058107,"seq":105954715737},"cts":1776816006656}
{"topic":"orderbook.200.BTCUSDT","ts":1776816006768,"type":"delta","data":{"s":"BTCUSDT","b":[["76359.3","0.006544"],["76359.1","0.02"],["76231","0"]],"a":[["76377.2","0.006544"],["76377.3","0"]],"u":28058108,"seq":105954715772},"cts":1776816006767}
{"topic":"orderbook.200.BTCUSDT","ts":1776816006868,"type":"delta","data":{"s":"BTCUSDT","b":[["76370.6","0.045887"],["76359.3","0"],["76231","0.00162"]],"a":[["76377.2","0"],["76377.3","0.006544"],["76384.4","0"],["76385.3","0.006545"]],"u":28058109,"seq":105954715839},"cts":1776816006867}
{"topic":"orderbook.200.BTCUSDT","ts":1776816006971,"type":"delta","data":{"s":"BTCUSDT","b":[["76358","0.006544"],["76231","0"]],"a":[["76370.7","0.585323"],["76373.1","0"],["76374.2","0"],["76376","0.006544"],["76377.3","0"],["76383.7","0.006545"],["76385.3","0"],["76388.8","0.03"],["76458","0.0001"]],"u":28058110,"seq":105954716009},"cts":1776816006958}
{"topic":"orderbook.200.BTCUSDT","ts":1776816007069,"type":"delta","data":{"s":"BTCUSDT","b":[["76362.9","0.041"],["76358.7","0.006544"],["76358","0"]],"a":[["76370.7","0.585061"],["76384.9","0.031456"],["76458","0"]],"u":28058111,"seq":105954716088},"cts":1776816007066}
{"topic":"orderbook.200.BTCUSDT","ts":1776816007169,"type":"delta","data":{"s":"BTCUSDT","b":[["76362.9","0.001"],["76361.1","0"],["76343.5","0.01963"],["76340.7","0.030125"],["76340","0"],["76312.5","0"],["76302.8","0.01963"],["76231","0.00162"]],"a":[["76373.2","0"],["76388.7","0.01963"],["76395","0"],["76422.5","0"],["76440.2","0.02018"],["76458","0.0001"],["76458.2","0.00041"]],"u":28058112,"seq":105954716190},"cts":1776816007165}
{"topic":"orderbook.200.BTCUSDT","ts":1776816007269,"type":"delta","data":{"s":"BTCUSDT","b":[["76368.6","0.023207"],["76368.5","0.030357"],["76368.3","0"],["76368.2","0"],["76362.9","0.041"]],"a":[["76370.8","0.02845"]],"u":28058113,"seq":105954716285},"cts":1776816007263}
{"topic":"orderbook.200.BTCUSDT","ts":1776816007369,"type":"delta","data":{"s":"BTCUSDT","b":[["76362.9","0.001"],["76359.3","0.006544"],["76358.7","0"]],"a":[["76370.7","0.53512"],["76376","0"],["76377.3","0.006544"],["76383.7","0"],["76384.4","0.006545"],["76395.3","0"],["76458.4","0.00041"]],"u":28058114,"seq":105954716345},"cts":1776816007367}
{"topic":"orderbook.200.BTCUSDT","ts":1776816007469,"type":"delta","data":{"s":"BTCUSDT","b":[["76359.3","0"],["76359.2","0.030564"],["76230.7","0.000099"]],"a":[["76377.2","0.006544"],["76377.3","0"]],"u":28058115,"seq":105954716391},"cts":1776816007466}
{"topic":"orderbook.200.BTCUSDT","ts":1776816007569,"type":"delta","data":{"s":"BTCUSDT","b":[["76362.9","0.041"],["76359.3","0.006544"],["76359.2","0.02402"],["76230.7","0"]],"a":[["76377.2","0"],["76384.3","0.006545"],["76384.4","0"],["76458.8","0.000198"]],"u":28058116,"seq":105954716450},"cts":1776816007567}
{"topic":"orderbook.200.BTCUSDT","ts":1776816007669,"type":"delta","data":{"s":"BTCUSDT","b":[["76370.6","0.100087"],["76362.9","0.001"],["76359.5","0.021453"],["76359.4","0.026217"],["76359.3","0"],["76359.2","0"],["76358.6","0"],["76358","0.006544"]],"a":[["76370.7","0.53148"],["76383.6","0.006545"],["76384.3","0"]],"u":28058117,"seq":105954716543},"cts":1776816007660}
{"topic":"orderbook.200.BTCUSDT","ts":1776816007771,"type":"delta","data":{"s":"BTCUSDT","b":[["76370.6","0.120087"],["76359.5","0.027997"],["76358","0"],["76351.8","0"],["76230.7","0.000099"],["76229.3","0.001178"]],"a":[["76370.7","0.52034"],["76373.2","0.007516"],["76383.6","0"],["76384.4","0.006545"],["76458.8","0"]],"u":28058118,"seq":105954716599},"cts":1776816007769}
{"topic":"orderbook.200.BTCUSDT","ts":1776816007869,"type":"delta","data":{"s":"BTCUSDT","b":[["76370.6","0.364799"],["76365.5","0.004534"],["76363.1","0.011078"],["76363","0.081521"],["76362.9","0.127"],["76360.4","0.021453"],["76360.1","0"],["76359.5","0"],["76354.5","0.130981"],["76352.9","0"],["76296.8","0.650809"],["76229.3","0"]],"a":[["76370.7","0.33288"],["76373.2","0"],["76374.9","0.007586"],["76375.8","0.007516"],["76384.4","0"],["76384.9","0"],["76388.2","0.112382"],["76458.8","0.000198"]],"u":28058119,"seq":105954716746},"cts":1776816007861}
{"topic":"orderbook.200.BTCUSDT","ts":1776816007968,"type":"delta","data":{"s":"BTCUSDT","b":[["76370.6","0.474899"],["76363.2","0.006544"],["76363.1","0.004534"],["76356.1","0.14383"],["76354.6","0.031456"],["76298.7","0.244667"],["76231","0"],["76230.7","0"]],"a":[["76370.7","0.277818"],["76388.2","0.105837"],["76388.7","0.026175"]],"u":28058120,"seq":105954716787},"cts":1776816007948}
{"topic":"orderbook.200.BTCUSDT","ts":1776816008069,"type":"delta","data":{"s":"BTCUSDT","b":[["76370.6","0.468427"],["76363.3","0.006544"],["76363.2","0"],["76360.6","0.026217"],["76233.9","0"]],"a":[["76388.3","0.85222"],["76388.7","0.01963"],["76405.8","0.048439"]],"u":28058121,"seq":105954716867},"cts":1776816008057}
{"topic":"orderbook.200.BTCUSDT","ts":1776816008168,"type":"delta","data":{"s":"BTCUSDT","b":[["76370.6","0.461144"],["76363.3","0"],["76363.2","0.006544"]],"a":[["76370.7","0.34682"],["76388.1","0.295034"],["76388.3","0.845675"]],"u":28058122,"seq":105954716908},"cts":1776816008167}
{"topic":"orderbook.200.BTCUSDT","ts":1776816008269,"type":"delta","data":{"s":"BTCUSDT","b":[["76370.6","0.461328"],["76368.8","0.027638"],["76368.6","0.015498"],["76368.5","0"]],"a":[["76388","0.038001"],["76388.1","0.288489"]],"u":28058123,"seq":105954716938},"cts":1776816008257}
{"topic":"orderbook.200.BTCUSDT","ts":1776816008368,"type":"delta","data":{"s":"BTCUSDT","b":[["76363.2","0"],["76362.4","0.006544"]],"a":[["76370.7","0.52216"],["76387.9","0.006545"],["76388","0.031456"],["76458.8","0"]],"u":28058124,"seq":105954716967},"cts":1776816008351}
{"topic":"orderbook.200.BTCUSDT","ts":1776816008468,"type":"delta","data":{"s":"BTCUSDT","b":[],"a":[["76387.4","0.006545"],["76387.9","0"]],"u":28058125,"seq":105954716996},"cts":1776816008462}
{"topic":"orderbook.200.BTCUSDT","ts":1776816008669,"type":"delta","data":{"s":"BTCUSDT","b":[["76363.2","0.006544"],["76362.4","0"],["76361.3","0.026216"],["76360.6","0"]],"a":[["76370.7","0.34682"],["76387.4","0"],["76387.9","0.006545"],["76400.8","0"],["76458.8","0.000198"]],"u":28058126,"seq":105954717056},"cts":1776816008663}
{"topic":"orderbook.200.BTCUSDT","ts":1776816008769,"type":"delta","data":{"s":"BTCUSDT","b":[["76363.2","0"],["76362.4","0.006544"]],"a":[["76370.7","0.52216"],["76387.4","0.006545"],["76387.9","0"],["76402.4","0.363758"],["76458.8","0"]],"u":28058127,"seq":105954717103},"cts":1776816008745}
{"topic":"orderbook.200.BTCUSDT","ts":1776816008868,"type":"delta","data":{"s":"BTCUSDT","b":[["76370.6","0.253088"]],"a":[],"u":28058128,"seq":105954717129},"cts":1776816008842}
{"topic":"orderbook.200.BTCUSDT","ts":1776816009069,"type":"delta","data":{"s":"BTCUSDT","b":[["76370.6","0.259521"],["76367.9","0.004534"],["76365.5","0"],["76363","0.088065"],["76362.4","0"],["76361.7","0.001899"],["76361.3","0"],["76357.9","0.013102"],["76233.9","0.048439"]],"a":[["76370.7","0.273704"],["76372.5","0.01416"],["76374.3","0.007436"],["76376.1","0"],["76380.6","0.007399"],["76387.4","0"],["76387.9","0.006545"],["76402.4","0"]],"u":28058129,"seq":105954717219},"cts":1776816009066}
{"topic":"orderbook.200.BTCUSDT","ts":1776816009169,"type":"delta","data":{"s":"BTCUSDT","b":[["76363","0.081521"],["76362.4","0.006544"],["76361.4","0.056216"],["76233.9","0"]],"a":[["76370.7","0.460589"],["76387.4","0.006545"],["76387.9","0"]],"u":28058130,"seq":105954717278},"cts":1776816009149}
{"topic":"orderbook.200.BTCUSDT","ts":1776816009269,"type":"delta","data":{"s":"BTCUSDT","b":[["76370.6","0.253088"],["76369","0.025401"],["76368.8","0"],["76367.9","0"],["76365.3","0.004534"],["76362.5","0.006544"],["76362.4","0"]],"a":[["76403.4","0.373334"],["76458.4","0"]],"u":28058131,"seq":105954717324},"cts":1776816009267}
{"topic":"orderbook.200.BTCUSDT","ts":1776816009371,"type":"delta","data":{"s":"BTCUSDT","b":[["76370.6","0.251736"],["76362.5","0"],["76362.4","0.006544"],["76361.4","0.03"],["76360.6","0.026014"],["76234","0"]],"a":[["76371","0.007436"],["76374.3","0"],["76388.2","0.236818"],["76403.3","0.163891"],["76403.7","0"]],"u":28058132,"seq":105954717360},"cts":1776816009366}
{"topic":"orderbook.200.BTCUSDT","ts":1776816009469,"type":"delta","data":{"s":"BTCUSDT","b":[],"a":[["76370.7","0.514789"]],"u":28058133,"seq":105954717396},"cts":1776816009460}
{"topic":"orderbook.200.BTCUSDT","ts":1776816009569,"type":"delta","data":{"s":"BTCUSDT","b":[["76362.4","0"],["76361.8","0.006544"]],"a":[["76386.9","0.006545"],["76387.4","0"]],"u":28058134,"seq":105954717421},"cts":1776816009567}
{"topic":"orderbook.200.BTCUSDT","ts":1776816009669,"type":"delta","data":{"s":"BTCUSDT","b":[["76370.6","0.019584"],["76368.6","0"],["76368.4","0"],["76365.9","0"],["76365.3","0"],["76363.1","0.000198"],["76363","0.049408"],["76362.9","0.041"],["76362.2","0.02619"],["76361.8","0"],["76361.7","0"],["76360.6","0"],["76360.4","0"],["76359.4","0"],["76359","0"],["76358.1","0.004534"],["76356.3","0.004534"],["76356.2","0.026015"],["76355.1","0"],["76354.7","0.006544"],["76354.6","0.02619"],["76354.5","0"],["76351.6","0.001858"],["76347.2","0.001178"],["76344.6","0.025594"],["76344.2","0.031456"],["76344.1","0"],["76343.5","0"],["76343.1","0.130981"],["76340.2","0.068069"],["76336.9","0.162437"],["76336.8","0"],["76336.7","0"],["76335.9","0"],["76335.8","0"],["76330.5","0.031456"],["76330.4","0.001"],["76330.3","0.050645"],["76328.5","0"],["76326.2","0.130981"],["76258.2","0.335963"],["76234","0.000439"],["76233.9","0.048439"],["76231","0.00162"],["76230.7","0.000099"],["76229.3","0.001178"],["76227.4","0.004569"],["76226.4","0.00162"]],"a":[["76370.7","0.549358"],["76371","0"],["76372.5","0.001"],["76374.9","0"],["76375.8","0"],["76380.6","0"],["76381.1","0.006545"],["76384.8","0.031456"],["76386.9","0"],["76403.2","0.031456"],["76458.4","0.00041"],["76458.8","0.000198"]],"u":28058135,"seq":105954717741},"cts":1776816009666}
{"topic":"orderbook.200.BTCUSDT","ts":1776816009769,"type":"delta","data":{"s":"BTCUSDT","b":[["76370.6","0.023874"],["76359.2","0.019029"],["76357.6","0.026015"],["76357","0.010421"],["76356.2","0.006545"],["76355.5","0.026016"],["76354.7","0"],["76349.4","0"],["76347.1","0"],["76332.5","0.355309"],["76227.4","0"],["76226.4","0"]],"a":[["76370.7","0.556638"],["76381.1","0"],["76381.2","0.006545"]],"u":28058136,"seq":105954717881},"cts":1776816009764}
{"topic":"orderbook.200.BTCUSDT","ts":1776816009869,"type":"delta","data":{"s":"BTCUSDT","b":[["76370.6","0.078074"],["76363.2","0.081184"],["76363.1","0.055301"],["76363","0.0064"],["76362.9","0.001"],["76360.5","0.004534"],["76358.2","0.026114"],["76358.1","0"],["76357.6","0"],["76356.4","0.006545"],["76356.2","0"],["76355.4","0.001858"],["76351.6","0"]],"a":[["76388.8","0"],["76458.9","0.000233"]],"u":28058137,"seq":105954717984},"cts":1776816009857}
{"topic":"orderbook.200.BTCUSDT","ts":1776816010068,"type":"delta","data":{"s":"BTCUSDT","b":[["76370.6","0.023874"],["76363.2","0.052795"],["76363.1","0.000198"],["76362.9","0.041"]],"a":[["76370.7","0.556748"],["76381.1","0.01"],["76458.9","0"]],"u":28058138,"seq":105954718189},"cts":1776816010067}
{"topic":"orderbook.200.BTCUSDT","ts":1776816010171,"type":"delta","data":{"s":"BTCUSDT","b":[],"a":[["76381","0.006545"],["76381.2","0"]],"u":28058139,"seq":105954718288},"cts":1776816010163}
{"topic":"orderbook.200.BTCUSDT","ts":1776816010269,"type":"delta","data":{"s":"BTCUSDT","b":[["76369.1","0.023156"],["76369","0"],["76359","0.026014"],["76358.2","0.000099"],["76356.4","0"],["76356.2","0.006545"],["76229.3","0"]],"a":[["76375","0.006545"],["76381","0"],["76381.2","0.006545"],["76458.8","0"]],"u":28058140,"seq":105954718405},"cts":1776816010267}
{"topic":"orderbook.200.BTCUSDT","ts":1776816010368,"type":"delta","data":{"s":"BTCUSDT","b":[["76359","0"],["76358.2","0.026114"],["76356.5","0.006545"],["76356.2","0"],["76229.3","0.001178"]],"a":[["76381.2","0"],["76382.4","0.006545"],["76403.4","0"],["76458.8","0.000198"]],"u":28058141,"seq":105954718554},"cts":1776816010366}
{"topic":"orderbook.200.BTCUSDT","ts":1776816010469,"type":"delta","data":{"s":"BTCUSDT","b":[["76356.5","0"],["76356.4","0.006545"],["76332.5","0"],["76227.4","0.004569"]],"a":[["76400.4","0.358424"],["76403.3","0"]],"u":28058142,"seq":105954718657},"cts":1776816010466}
{"topic":"orderbook.200.BTCUSDT","ts":1776816010569,"type":"delta","data":{"s":"BTCUSDT","b":[["76370.6","0.045874"],["76358.7","0.026015"],["76358.2","0.000099"],["76356.6","0.006545"],["76356.4","0"],["76227.4","0"]],"a":[],"u":28058143,"seq":105954718766},"cts":1776816010567}
{"topic":"orderbook.200.BTCUSDT","ts":1776816010669,"type":"delta","data":{"s":"BTCUSDT","b":[["76357.1","0.006545"],["76356.6","0"],["76331.3","0.360197"],["76229.3","0"]],"a":[],"u":28058144,"seq":105954718854},"cts":1776816010665}
{"topic":"orderbook.200.BTCUSDT","ts":1776816010769,"type":"delta","data":{"s":"BTCUSDT","b":[["76362.9","0.001"],["76357.1","0"],["76356.2","0.006545"],["76234.8","0.006285"],["76230.7","0"]],"a":[["76381.2","0.006545"],["76382.4","0"]],"u":28058145,"seq":105954718946},"cts":1776816010765}
{"topic":"orderbook.200.BTCUSDT","ts":1776816010869,"type":"delta","data":{"s":"BTCUSDT","b":[["76370.6","0.368595"],["76369.2","0.022923"],["76369.1","0"],["76367.8","0.005534"],["76365.7","0.026012"],["76363.3","0.006544"],["76363.2","0.086204"],["76363","0.0104"],["76362.9","0.127"],["76362.6","0.004534"],["76361.9","0.026188"],["76360.5","0"],["76359.8","0.001817"],["76359.2","0"],["76358.7","0"],["76356.3","0"],["76356.2","0"],["76355.5","0"],["76355.4","0"],["76344.6","0"],["76230.7","0.000099"],["76229.3","0.001178"],["76227.4","0.004569"]],"a":[["76370.7","0.343844"],["76375","0"],["76375.6","0.007627"],["76376.1","0.007557"],["76378.3","0.0104"],["76381.2","0.006544"],["76387.5","0"],["76388.2","0.112382"],["76388.7","0"],["76391.9","0.068069"],["76458.9","0.000233"]],"u":28058146,"seq":105954719174},"cts":1776816010863}
{"topic":"orderbook.200.BTCUSDT","ts":1776816010972,"type":"delta","data":{"s":"BTCUSDT","b":[["76370.6","0.160425"],["76367.8","0.001"],["76365.8","0.013735"],["76365.7","0"],["76365.5","0.004534"],["76364.9","0.026012"],["76363.3","0"],["76361.5","0.006544"],["76349.3","0.130981"],["76230.7","0"],["76229.3","0"],["76227.4","0"]],"a":[["76370.7","0.53168"],["76372.5","0.014184"],["76374.2","0.007464"],["76378.9","0.006544"],["76380.5","0.007427"],["76381.2","0"],["76386.9","0.006545"],["76387.9","0.130981"],["76388.2","0.105837"],["76458.2","0"],["76458.4","0"],["76458.8","0"],["76458.9","0"]],"u":28058147,"seq":105954719254},"cts":1776816010961}
{"topic":"orderbook.200.BTCUSDT","ts":1776816011069,"type":"delta","data":{"s":"BTCUSDT","b":[["76370.6","0.069874"],["76365.8","0"],["76365.5","0"],["76364.9","0"],["76361.5","0"],["76359.9","0.006544"],["76359.5","0.017696"],["76359.4","0.026081"],["76352.2","0.025591"],["76349.4","0.031456"],["76348.3","0.01963"],["76340.2","0.048439"],["76337","0.079112"],["76234","0"],["76233.9","0"],["76231","0"]],"a":[["76370.9","0.007464"],["76373.8","0.007557"],["76374.2","0"],["76375.8","0.007427"],["76376.1","0"],["76378.2","0.006544"],["76378.9","0"],["76380.5","0"],["76385.6","0.006545"],["76386.9","0"],["76390.3","0.010169"],["76403.7","0.052451"],["76457.6","0"],["76458","0"]],"u":28058148,"seq":105954719364},"cts":1776816011067}
{"topic":"orderbook.200.BTCUSDT","ts":1776816011168,"type":"delta","data":{"s":"BTCUSDT","b":[["76370.6","0.049874"],["76369.2","0"],["76369.1","0.022864"],["76363.2","0.052795"],["76362.9","0.041"],["76362.6","0"],["76361.9","0"],["76361.4","0"],["76361.1","0.026014"],["76359.9","0"],["76359.8","0"],["76359.3","0.004534"],["76357.1","0.006545"],["76355.3","0.001817"],["76352.6","0.013638"]],"a":[["76370.7","0.546701"],["76370.9","0"],["76371.4","0.007627"],["76373.8","0"],["76375","0.006544"],["76375.6","0"],["76378.2","0"],["76382.4","0.006545"],["76385.6","0"],["76457.6","0.130981"],["76458","0.0001"]],"u":28058149,"seq":105954719587},"cts":1776816011167}
{"topic":"orderbook.200.BTCUSDT","ts":1776816011269,"type":"delta","data":{"s":"BTCUSDT","b":[["76370.6","0"],["76369.1","0"],["76367.8","0"],["76364.8","0"],["76363.2","0.0234"],["76363","0.020408"],["76362.9","0.001"],["76362.3","0"],["76362.2","0"],["76361.1","0"],["76359.5","0"],["76359.4","0"],["76359.3","0"],["76359.1","0"],["76357.1","0"],["76357","0"],["76356.1","0.049849"],["76355.6","0.0104"],["76355.3","0"],["76354.6","0"],["76354.4","0"],["76353.7","0"],["76353","0.004534"],["76352.6","0"],["76352.4","0.025965"],["76352.2","0"],["76349.5","0.004534"],["76349.4","0"],["76349.3","0"],["76348.3","0"],["76347.3","0.006545"],["76346.8","0"],["76346.5","0.028596"],["76346.4","0.001817"],["76346.2","0.023667"],["76344.2","0"],["76343.1","0"],["76340.6","0.025394"],["76340.4","0.031456"],["76340.3","0.01963"],["76336.4","0.009824"],["76318.1","0"],["76300","0.001178"],["76258.2","0.362727"],["76234","0.000439"],["76233.9","0.048439"],["76231","0.00162"],["76230.7","0.000099"],["76229.3","0.001178"],["76227.4","0.004569"],["76226.4","0.00162"],["76226.2","0.132601"],["76226.1","0.126"],["76226","0.001146"],["76225.6","6.604869"],["76223.6","0.714835"],["76223.2","0.000099"],["76223","0.048439"],["76222.7","0.0001"]],"a":[["76363.3","1.536792"],["76363.9","0.007627"],["76364.7","0.024381"],["76364.9","0.03"],["76365","0.028757"],["76365.5","0.007427"],["76367.7","0.006545"],["76367.9","0.029328"],["76370.6","0.061998"],["76370.7","0.15751"],["76370.9","0.0104"],["76371.4","0"],["76371.7","0.001"],["76372.5","0.033074"],["76372.6","0"],["76372.7","0.109227"],["76375","0.006546"],["76375.8","0"],["76377.2","0.013881"],["76377.3","0.031456"],["76377.4","0"],["76377.5","0"],["76377.9","0"],["76378.3","0"],["76379","0"],["76379.8","0.02943"],["76381.2","0.015929"],["76381.3","0.032456"],["76382.4","0"],["76383.8","0.019729"],["76391.9","0.048439"],["76413.1","0.013101"],["76440","0.000941"],["76456.2","0"],["76456.6","0"],["76456.7","0"],["76456.8","0"],["76456.9","0"],["76457","0"],["76457.6","0"],["76458","0"]],"u":28058150,"seq":105954720547},"cts":1776816011267}
{"topic":"orderbook.200.BTCUSDT","ts":1776816011369,"type":"delta","data":{"s":"BTCUSDT","b":[["76363.2","0.02795"],["76363","0"],["76361","0.017838"],["76360.9","0.020367"],["76359.7","0.026191"],["76352.4","0"],["76349.8","0.010204"],["76340.3","0"],["76332.3","0.01963"],["76319.2","0.362947"],["76312.1","0.743001"],["76297","0"],["76289.2","0.013101"],["76234","0.014898"],["76223.2","0"],["76223","0"],["76222.7","0"]],"a":[["76363.3","1.594996"],["76367.7","0"],["76367.8","0.006545"],["76370.7","0.1574"],["76373","0"],["76374.9","0.006546"],["76375","0"],["76384.5","0.013092"],["76385.5","0.00003"],["76411.5","0.013101"],["76413","0.013101"],["76455.2","0"],["76455.4","0"]],"u":28058151,"seq":105954720824},"cts":1776816011368}
{"topic":"orderbook.200.BTCUSDT","ts":1776816011469,"type":"delta","data":{"s":"BTCUSDT","b":[["76363.2","0.08189"],["76352.6","0.01875"],["76352.2","0.025965"],["76350.8","0.006545"],["76347.5","0.069871"],["76347.4","0.123196"],["76347.3","0"],["76346.2","0"],["76343.1","0.130981"],["76315","0.28887"],["76226.1","0"],["76226","0"],["76225.6","0"],["76223.6","0"]],"a":[["76363.3","1.600456"],["76366.2","0.000149"],["76367.8","0"],["76367.9","0.026858"],["76370.5","0.006545"],["76374.9","0"],["76378.5","0.006546"],["76455","0"]],"u":28058152,"seq":105954721060},"cts":1776816011460}
{"topic":"orderbook.200.BTCUSDT","ts":1776816011568,"type":"delta","data":{"s":"BTCUSDT","b":[["76363.2","0.10429"],["76356.2","0.056449"],["76355.1","0.025964"],["76353.3","0.006545"],["76353.2","0.055077"],["76353.1","0.025965"],["76352.6","0"],["76352.2","0"],["76351.3","0.125777"],["76350.8","0"],["76347.5","0.024561"],["76347.4","0"],["76346.5","0"],["76344","0.230807"],["76226.2","0"]],"a":[["76363.3","1.511967"],["76364.9","0"],["76370.5","0"],["76371.6","0.006545"],["76378.5","0"],["76379.7","0.006546"],["76390.3","0"],["76455","0.000078"],["76455.2","0.00027"]],"u":28058153,"seq":105954721180},"cts":1776816011556}
{"topic":"orderbook.200.BTCUSDT","ts":1776816011669,"type":"delta","data":{"s":"BTCUSDT","b":[["76356.3","0.075763"],["76356.1","0"],["76355.2","0.006545"],["76353.3","0"],["76353","0"],["76226.2","0.132601"]],"a":[["76371.6","0"],["76372.4","0.006545"]],"u":28058154,"seq":105954721207},"cts":1776816011668}
{"topic":"orderbook.200.BTCUSDT","ts":1776816011771,"type":"delta","data":{"s":"BTCUSDT","b":[["76355.5","0.004534"],["76355.1","0"],["76349.5","0"],["76226.1","0.126"]],"a":[["76363.3","1.482036"]],"u":28058155,"seq":105954721233},"cts":1776816011769}
{"topic":"orderbook.200.BTCUSDT","ts":1776816011868,"type":"delta","data":{"s":"BTCUSDT","b":[["76356.2","0"],["76355.9","0.025964"],["76355.2","0"],["76354.3","0.006545"],["76352.8","0.004534"],["76350.4","0.001784"],["76346.4","0"],["76226.1","0"]],"a":[["76363.3","1.474479"],["76365.9","0.007567"],["76455.2","0"]],"u":28058156,"seq":105954721283},"cts":1776816011867}
{"topic":"orderbook.200.BTCUSDT","ts":1776816011969,"type":"delta","data":{"s":"BTCUSDT","b":[["76363.2","0.11109"],["76356.7","0.025964"],["76356.3","0.054469"],["76355.9","0"],["76355.7","0.006545"],["76355.6","0.0172"],["76354.3","0"]],"a":[["76363.3","1.480988"],["76365.5","0"],["76370.2","0.007437"],["76370.9","0.0172"],["76372.4","0"],["76372.6","0.006545"],["76379.7","0"],["76381","0.006546"]],"u":28058157,"seq":105954721335},"cts":1776816011960}
{"topic":"orderbook.200.BTCUSDT","ts":1776816012069,"type":"delta","data":{"s":"BTCUSDT","b":[["76357.8","0.004534"],["76355.5","0"]],"a":[["76370.1","0.01"],["76381","0"],["76381.1","0.006546"],["76382.8","0.010403"],["76455","0"]],"u":28058158,"seq":105954721363},"cts":1776816012056}
{"topic":"orderbook.200.BTCUSDT","ts":1776816012169,"type":"delta","data":{"s":"BTCUSDT","b":[["76356.3","0.085793"],["76355.5","0.126"],["76334.1","0.126406"],["76226.2","0"]],"a":[["76363.3","1.480173"],["76372.6","0"],["76375","0.006545"]],"u":28058159,"seq":105954721417},"cts":1776816012166}
{"topic":"orderbook.200.BTCUSDT","ts":1776816012268,"type":"delta","data":{"s":"BTCUSDT","b":[["76361.1","0.018017"],["76360.9","0"],["76357.7","0.025963"],["76340.6","0"]],"a":[["76363.3","1.479472"]],"u":28058160,"seq":105954721460},"cts":1776816012267}
{"topic":"orderbook.200.BTCUSDT","ts":1776816012469,"type":"delta","data":{"s":"BTCUSDT","b":[["76355.7","0"],["76354.3","0.006545"]],"a":[["76372.4","0.006545"],["76375","0"],["76379.8","0.035976"],["76381.1","0"],["76455","0.000078"]],"u":28058161,"seq":105954721551},"cts":1776816012467}
{"topic":"orderbook.200.BTCUSDT","ts":1776816012571,"type":"delta","data":{"s":"BTCUSDT","b":[],"a":[["76379.8","0.02943"],["76381.1","0.006546"],["76455","0"]],"u":28058162,"seq":105954721577},"cts":1776816012553}
{"topic":"orderbook.200.BTCUSDT","ts":1776816012668,"type":"delta","data":{"s":"BTCUSDT","b":[],"a":[["76370.6","0.025252"],["76370.7","0.0314"],["76406.9","0.098803"],["76454.7","0"]],"u":28058163,"seq":105954721595},"cts":1776816012656}
{"topic":"orderbook.200.BTCUSDT","ts":1776816012769,"type":"delta","data":{"s":"BTCUSDT","b":[["76358.4","0.025963"],["76357.7","0"]],"a":[["76379.9","0.007546"],["76381.1","0"],["76454.7","0.0001"]],"u":28058164,"seq":105954721614},"cts":1776816012761}
{"topic":"orderbook.200.BTCUSDT","ts":1776816012969,"type":"delta","data":{"s":"BTCUSDT","b":[],"a":[["76379.7","0.006546"],["76379.9","0.001"],["76454.7","0"]],"u":28058165,"seq":105954721661},"cts":1776816012966}
{"topic":"orderbook.200.BTCUSDT","ts":1776816013069,"type":"delta","data":{"s":"BTCUSDT","b":[],"a":[["76370.1","0"],["76454.7","0.0001"]],"u":28058166,"seq":105954721704},"cts":1776816013067}
{"topic":"orderbook.200.BTCUSDT","ts":1776816013169,"type":"delta","data":{"s":"BTCUSDT","b":[["76363.2","0.08909"],["76359.5","0.025963"],["76358.4","0"],["76326.6","0.061959"]],"a":[["76379.7","0"],["76379.8","0.035975"],["76455","0.000078"]],"u":28058167,"seq":105954721760},"cts":1776816013158}
{"topic":"orderbook.200.BTCUSDT","ts":1776816013269,"type":"delta","data":{"s":"BTCUSDT","b":[["76361.4","0.015495"],["76361.1","0"],["76359.5","0"],["76359.2","0.023294"],["76354.4","0.006545"],["76354.3","0"]],"a":[["76363.3","1.466732"],["76372.4","0"],["76372.6","0.006545"],["76379.8","0.02943"],["76381.1","0.006546"],["76455","0"]],"u":28058168,"seq":105954721827},"cts":1776816013264}
{"topic":"orderbook.200.BTCUSDT","ts":1776816013372,"type":"delta","data":{"s":"BTCUSDT","b":[["76354.4","0"],["76354.3","0.006545"]],"a":[["76372.4","0.006545"],["76372.6","0"]],"u":28058169,"seq":105954721846},"cts":1776816013356}
{"topic":"orderbook.200.BTCUSDT","ts":1776816013469,"type":"delta","data":{"s":"BTCUSDT","b":[],"a":[["76379.9","0.007546"],["76381.1","0"],["76455","0.000078"]],"u":28058170,"seq":105954721863},"cts":1776816013466}
{"topic":"orderbook.200.BTCUSDT","ts":1776816013569,"type":"delta","data":{"s":"BTCUSDT","b":[["76363.2","0.11109"]],"a":[["76365.4","0.030693"],["76379.9","0.001"],["76381.1","0.006546"],["76454.7","0"],["76455","0"]],"u":28058171,"seq":105954721891},"cts":1776816013559}
{"topic":"orderbook.200.BTCUSDT","ts":1776816013669,"type":"delta","data":{"s":"BTCUSDT","b":[["76340.2","0.068069"],["76332.3","0"],["76226.2","0.132601"]],"a":[],"u":28058172,"seq":105954721904},"cts":1776816013667}
{"topic":"orderbook.200.BTCUSDT","ts":1776816013869,"type":"delta","data":{"s":"BTCUSDT","b":[],"a":[["76379.7","0.006545"],["76381.1","0"]],"u":28058173,"seq":105954721934},"cts":1776816013864}
{"topic":"orderbook.200.BTCUSDT","ts":1776816014171,"type":"delta","data":{"s":"BTCUSDT","b":[["76359.9","0.023294"],["76359.2","0"],["76340.7","0.044065"]],"a":[["76363.3","1.465395"],["76379.7","0"],["76381.1","0.006545"]],"u":28058174,"seq":105954721979},"cts":1776816014168}
{"topic":"orderbook.200.BTCUSDT","ts":1776816014269,"type":"delta","data":{"s":"BTCUSDT","b":[["76361.6","0.013304"],["76361.4","0"],["76227.4","0"],["76226.1","0.126"]],"a":[["76379.8","0.035975"],["76381.1","0"],["76454.7","0.0001"]],"u":28058175,"seq":105954722022},"cts":1776816014247}
{"topic":"orderbook.200.BTCUSDT","ts":1776816014369,"type":"delta","data":{"s":"BTCUSDT","b":[["76363.1","0"],["76355.6","0.023745"],["76354.3","0"],["76226","0.001146"],["76225.6","6.604869"]],"a":[["76372.4","0"],["76372.6","0.006545"],["76379.8","0.02943"],["76381.1","0.006545"],["76382.8","0"]],"u":28058176,"seq":105954722057},"cts":1776816014356}
{"topic":"orderbook.200.BTCUSDT","ts":1776816014469,"type":"delta","data":{"s":"BTCUSDT","b":[["76355.6","0.0172"],["76354.3","0.006545"],["76225.6","0"]],"a":[["76372.4","0.006545"],["76372.6","0"],["76379.9","0.007545"],["76381.1","0"],["76455","0.000078"]],"u":28058177,"seq":105954722080},"cts":1776816014442}
{"topic":"orderbook.200.BTCUSDT","ts":1776816014669,"type":"delta","data":{"s":"BTCUSDT","b":[],"a":[["76379.7","0.006545"],["76379.9","0.001"],["76455","0"]],"u":28058178,"seq":105954722117},"cts":1776816014660}
{"topic":"orderbook.200.BTCUSDT","ts":1776816014769,"type":"delta","data":{"s":"BTCUSDT","b":[["76226","0.005876"]],"a":[["76402.5","0"],["76455","0.000078"]],"u":28058179,"seq":105954722139},"cts":1776816014766}
{"topic":"orderbook.200.BTCUSDT","ts":1776816014869,"type":"delta","data":{"s":"BTCUSDT","b":[["76355.6","0.023745"],["76354.3","0"],["76225.6","6.604869"]],"a":[["76372.4","0"],["76379.7","0"],["76380.8","0.013092"],["76381.1","0.006545"],["76382.7","0.065463"],["76384.5","0"],["76384.6","0.065461"],["76386.4","0"],["76388.4","0"],["76455.2","0.00027"]],"u":28058180,"seq":105954722170},"cts":1776816014855}
{"topic":"orderbook.200.BTCUSDT","ts":1776816014972,"type":"delta","data":{"s":"BTCUSDT","b":[["76363.2","0.40381"],["76359.9","0"],["76356.8","0.006545"],["76356.1","0.115956"],["76355.6","0.0172"],["76353.2","0"],["76353.1","0"],["76351.3","0"],["76223.6","0.714835"],["76223.2","0.000099"]],"a":[["76363.3","1.286415"],["76364.7","0"],["76364.9","0.028066"],["76377.2","0"],["76377.3","0"],["76381.1","0"],["76381.2","0.033433"],["76381.3","0.001"],["76382.2","0.006545"],["76384.4","0.031456"],["76384.5","0.066579"],["76384.8","0"],["76385.4","0"],["76387.8","0.130981"],["76387.9","0.031456"],["76388","0"],["76455.4","0.000103"],["76456.2","0.016369"]],"u":28058181,"seq":105954722357},"cts":1776816014970}
{"topic":"orderbook.200.BTCUSDT","ts":1776816015069,"type":"delta","data":{"s":"BTCUSDT","b":[["76363.2","0.406148"],["76361","0.013112"],["76356.9","0.006545"],["76356.8","0"],["76337","0"],["76335.6","0.098421"],["76223","0.048439"]],"a":[["76382.2","0"],["76382.4","0.006545"]],"u":28058182,"seq":105954722421},"cts":1776816015066}
{"topic":"orderbook.200.BTCUSDT","ts":1776816015169,"type":"delta","data":{"s":"BTCUSDT","b":[["76363.2","0.411998"],["76356.9","0"],["76356.8","0.006545"],["76337","0.08118"],["76223","0"]],"a":[["76363.3","1.11034"]],"u":28058183,"seq":105954722467},"cts":1776816015158}
{"topic":"orderbook.200.BTCUSDT","ts":1776816015269,"type":"delta","data":{"s":"BTCUSDT","b":[["76363.2","0.407448"],["76361.8","0.011449"],["76361.6","0"],["76361","0.01331"],["76358.3","0.006545"],["76356.8","0"]],"a":[["76382.4","0"],["76383.7","0.006545"]],"u":28058184,"seq":105954722529},"cts":1776816015266}
{"topic":"orderbook.200.BTCUSDT","ts":1776816015369,"type":"delta","data":{"s":"BTCUSDT","b":[["76363.2","0.410698"]],"a":[],"u":28058185,"seq":105954722563},"cts":1776816015362}
{"topic":"orderbook.200.BTCUSDT","ts":1776816015469,"type":"delta","data":{"s":"BTCUSDT","b":[["76363.2","0.197978"],["76358.3","0"],["76358","0.006544"]],"a":[["76363.3","1.28568"],["76382.6","0.006545"],["76383.7","0"]],"u":28058186,"seq":105954722605},"cts":1776816015464}
{"topic":"orderbook.200.BTCUSDT","ts":1776816015569,"type":"delta","data":{"s":"BTCUSDT","b":[["76363.2","0.198628"],["76362","0.02352"],["76358","0"],["76356.2","0.006545"],["76343.1","0"],["76340.8","0.031456"],["76340.4","0"]],"a":[["76380.7","0.006545"],["76381.3","0.032456"],["76382.6","0"],["76399.7","0"],["76456.6","0.000542"]],"u":28058187,"seq":105954722689},"cts":1776816015565}
{"topic":"orderbook.200.BTCUSDT","ts":1776816015669,"type":"delta","data":{"s":"BTCUSDT","b":[["76363.2","0.167328"],["76362","0"],["76361","0.000198"],["76360.7","0.02352"],["76359.8","0.020133"],["76359.7","0.049712"],["76356.3","0.123809"],["76356.2","0"],["76355.3","0.006545"],["76343.1","0.130981"],["76223.6","0"],["76223.2","0"]],"a":[["76380.6","0.006545"],["76380.7","0"],["76383.7","0.010178"],["76399.6","0"],["76433.7","0.600672"],["76433.8","0.600232"],["76434.4","0.000181"],["76456.6","0"]],"u":28058188,"seq":105954722794},"cts":1776816015664}
{"topic":"orderbook.200.BTCUSDT","ts":1776816015771,"type":"delta","data":{"s":"BTCUSDT","b":[["76363.2","0.16109"],["76355.6","0.023745"],["76355.3","0"],["76223.6","0.714835"]],"a":[["76380.6","0"],["76380.7","0.006545"]],"u":28058189,"seq":105954722822},"cts":1776816015763}
{"topic":"orderbook.200.BTCUSDT","ts":1776816015869,"type":"delta","data":{"s":"BTCUSDT","b":[["76355.7","0.006545"],["76355.6","0.0172"],["76223.6","0"]],"a":[],"u":28058190,"seq":105954722852},"cts":1776816015868}
{"topic":"orderbook.200.BTCUSDT","ts":1776816015969,"type":"delta","data":{"s":"BTCUSDT","b":[["76361.3","0.02352"],["76360.7","0"],["76356.1","0.122501"],["76355.7","0"],["76223.6","0.714835"]],"a":[],"u":28058191,"seq":105954722869},"cts":1776816015963}
{"topic":"orderbook.200.BTCUSDT","ts":1776816016069,"type":"delta","data":{"s":"BTCUSDT","b":[["76356.2","0.006545"],["76356.1","0.115956"],["76223.6","0"]],"a":[["76406.8","0.031456"],["76456.2","0"]],"u":28058192,"seq":105954722894},"cts":1776816016051}
{"topic":"orderbook.200.BTCUSDT","ts":1776816016269,"type":"delta","data":{"s":"BTCUSDT","b":[["76361.9","0.009825"],["76361.8","0"]],"a":[["76363.3","1.28583"],["76370.7","0.03"],["76400.3","0.108527"],["76455.4","0"]],"u":28058193,"seq":105954722934},"cts":1776816016267}
{"topic":"orderbook.200.BTCUSDT","ts":1776816016369,"type":"delta","data":{"s":"BTCUSDT","b":[["76356.3","0.130354"],["76356.2","0"],["76223.6","0.714835"]],"a":[["76375","0.006545"],["76455.2","0"]],"u":28058194,"seq":105954722965},"cts":1776816016356}
{"topic":"orderbook.200.BTCUSDT","ts":1776816016469,"type":"delta","data":{"s":"BTCUSDT","b":[["76356.3","0.123809"],["76356.2","0.006545"],["76223.6","0"]],"a":[],"u":28058195,"seq":105954722982},"cts":1776816016467}
{"topic":"orderbook.200.BTCUSDT","ts":1776816016571,"type":"delta","data":{"s":"BTCUSDT","b":[],"a":[["76380.7","0"],["76381.1","0.006545"]],"u":28058196,"seq":105954723003},"cts":1776816016562}
{"topic":"orderbook.200.BTCUSDT","ts":1776816016668,"type":"delta","data":{"s":"BTCUSDT","b":[["76356.4","0.006545"],["76356.2","0"]],"a":[["76381.1","0"],["76381.2","0.039978"],["76455.2","0.00027"]],"u":28058197,"seq":105954723017},"cts":1776816016661}
{"topic":"orderbook.200.BTCUSDT","ts":1776816016769,"type":"delta","data":{"s":"BTCUSDT","b":[["76356.8","0.006545"],["76356.4","0"]],"a":[["76381.2","0.033433"],["76382.4","0.006545"],["76455.2","0"]],"u":28058198,"seq":105954723034},"cts":1776816016762}
{"topic":"orderbook.200.BTCUSDT","ts":1776816016869,"type":"delta","data":{"s":"BTCUSDT","b":[["76356.8","0"],["76356.4","0.006545"]],"a":[["76381.1","0.006545"],["76382.4","0"]],"u":28058199,"seq":105954723052},"cts":1776816016864}
{"topic":"orderbook.200.BTCUSDT","ts":1776816016969,"type":"delta","data":{"s":"BTCUSDT","b":[["76363.2","0.19109"]],"a":[],"u":28058200,"seq":105954723069},"cts":1776816016965}
{"topic":"orderbook.200.BTCUSDT","ts":1776816017169,"type":"delta","data":{"s":"BTCUSDT","b":[["76363.2","0.06489"],["76361.3","0"],["76359.8","0.013112"],["76359.7","0.026191"],["76357.8","0"],["76356.9","0.023521"],["76356.7","0"],["76356.4","0"],["76356.3","0.087805"],["76356","0.08901"],["76355.5","0"],["76354.7","0.004534"],["76353.1","0.025703"],["76353","0.02756"],["76347","0.028785"],["76344","0.199351"],["76343.1","0"],["76340.8","0"],["76340.3","0.031456"],["76337.2","0.08118"],["76337.1","0.162437"],["76337","0"],["76336.9","0"],["76223.6","0.714835"]],"a":[["76363.3","1.348549"],["76365.9","0"],["76370.5","0.006545"],["76370.6","0.057263"],["76371","0.126"],["76375","0"],["76378.5","0.006545"],["76381","0.077606"],["76381.1","0.130981"],["76381.2","0"],["76455","0"]],"u":28058201,"seq":105954723315},"cts":1776816017164}
{"topic":"orderbook.200.BTCUSDT","ts":1776816017269,"type":"delta","data":{"s":"BTCUSDT","b":[["76363.2","0.03489"],["76362.1","0.008375"],["76361.9","0"],["76356.9","0"],["76356.8","0.028048"],["76353.1","0.019158"],["76352.6","0.006545"],["76223.6","0"]],"a":[["76363.3","1.360379"],["76370.1","0.006545"],["76370.5","0"]],"u":28058202,"seq":105954723487},"cts":1776816017266}
{"topic":"orderbook.200.BTCUSDT","ts":1776816017371,"type":"delta","data":{"s":"BTCUSDT","b":[["76362.1","0"],["76362","0.008357"],["76352.6","0"],["76350.8","0.006545"]],"a":[["76370","0.008"],["76376.1","0.006546"],["76378.5","0"],["76454.7","0"]],"u":28058203,"seq":105954723606},"cts":1776816017370}
{"topic":"orderbook.200.BTCUSDT","ts":1776816017469,"type":"delta","data":{"s":"BTCUSDT","b":[["76363.2","0"],["76362.9","0"],["76362","0"],["76361","0"],["76359.8","0"],["76359.7","0"],["76358.2","0"],["76357.9","0"],["76356.8","0.0128"],["76356.5","0.008312"],["76356.3","0"],["76356.1","0"],["76356","0"],["76355.6","0"],["76355.4","0.002"],["76354.8","0.002"],["76354.7","0"],["76354.2","0"],["76354.1","0"],["76353.1","0"],["76353","0"],["76352.8","0"],["76352.5","0"],["76350.8","0"],["76350.4","0.015164"],["76349.8","0"],["76349.7","0.0004"],["76349.2","0.0128"],["76347.5","0"],["76347.3","0.025373"],["76347","0"],["76346.6","0.065488"],["76346","0.004534"],["76344.7","0.06551"],["76344","0.205897"],["76343","0"],["76341.4","0.004534"],["76340.7","0.030125"],["76340.3","0.001658"],["76340.2","0.026597"],["76337.2","0"],["76337.1","0"],["76336.4","0.003275"],["76335.6","0"],["76335.2","0.02409"],["76334.1","0.017178"],["76334","0.396886"],["76331.3","0"],["76330.5","0"],["76329","0.163437"],["76328.9","0.5"],["76327.2","0.006549"],["76326.8","0.01963"],["76326.6","0.015447"],["76326.2","0"],["76325.8","0"],["76322.8","0.130981"],["76319.7","0"],["76319.4","0.031456"],["76317.7","0"],["76316.3","0.162437"],["76316.2","0"],["76314.6","0"],["76313.3","0"],["76312.5","0.031456"],["76312.1","0"],["76311.5","0"],["76308.1","0.162437"],["76308","0"],["76307.9","0"],["76306.9","0"],["76304.8","0"],["76302.8","0"],["76297.5","0"],["76289.7","0.944997"],["76286.8","0"],["76274","0.031456"],["76270.4","0.031456"],["76268.7","0"],["76264.8","0.031456"],["76261.7","0.031456"],["76258.2","0.483971"],["76257","0.01963"],["76252.5","0.031456"],["76226","0.001146"],["76223.6","0.714835"],["76223.2","0.000099"],["76223","0.048439"],["76222.7","0.0001"],["76218.4","0.001"],["76217.6","0.001178"],["76217.2","0.005309"],["76215.5","0.130981"],["76214.6","0.126"],["76214.2","6.180768"],["76211","0.002357"],["76208.9","0.025633"],["76208.4","0.065507"],["76208.3","0.048439"],["76205.8","0.001178"],["76205.2","0.126"],["76204.8","0.130981"],["76201.6","0.006524"],["76200.4","0.006521"]],"a":[["76356.9","1.282567"],["76357.5","0.741443"],["76357.6","0.03"],["76357.9","0.067596"],["76358","0.06004"],["76358.3","0.073457"],["76359.8","0.023655"],["76360.9","0.006546"],["76361","0.144767"],["76361.1","0.2184"],["76361.4","0.007479"],["76362.9","0.126"],["76363.3","0.054368"],["76363.9","0"],["76364.5","0.0128"],["76364.9","0.045792"],["76365","0"],["76365.1","0.0004"],["76365.4","0"],["76366.2","0.001149"],["76367.9","0"],["76368.5","0.013092"],["76368.6","0.120406"],["76369.9","0.006547"],["76370.1","0.002"],["76370.2","0"],["76370.4","0.065463"],["76370.5","0.031456"],["76370.8","0.003178"],["76370.9","0"],["76372.3","0.065461"],["76372.5","0.032087"],["76372.7","0"],["76373.3","0.01963"],["76374.2","0.031456"],["76374.9","0.130981"],["76376","0.048439"],["76376.1","0"],["76380.8","0"],["76382.7","0"],["76383.7","0"],["76383.8","0.000099"],["76384.6","0"],["76392.1","0.396313"],["76399.9","0.623581"],["76405.4","0.013102"],["76406.6","0.200035"],["76407.8","0"],["76420.8","0"],["76421.1","0.3562"],["76422.3","0"],["76436.8","0"],["76452.2","0"],["76452.4","0"],["76452.7","0"],["76453.1","0"],["76453.2","0"],["76453.3","0"],["76453.4","0"],["76453.6","0"],["76453.8","0"],["76454","0"],["76454.3","0"],["76454.4","0"]],"u":28058204,"seq":105954724841},"cts":1776816017467}
{"topic":"orderbook.200.BTCUSDT","ts":1776816017569,"type":"delta","data":{"s":"BTCUSDT","b":[["76356.8","0"],["76356.5","0"],["76355.4","0"],["76354.8","0"],["76354.2","0.0282"],["76350.4","0"],["76350.3","0.008388"],["76349.7","0"],["76349.2","0"],["76347.4","0.048104"],["76347.3","0"],["76346.6","0.0152"],["76346","0"],["76344.8","0.034509"],["76344.7","0"],["76344","0"],["76342.8","0.028054"],["76342","0.013098"],["76341.6","0.004534"],["76341.4","0"],["76340.3","0"],["76340.1","0.065488"],["76338.1","0.06551"],["76337.6","0.004534"],["76336.1","0.001658"],["76335.2","0"],["76334.1","0.131498"],["76334","0"],["76333.5","0.006547"],["76333.4","0.024091"],["76331.1","0.126"],["76329","0.131981"],["76327.6","0.396886"],["76319.2","0"],["76316.6","0.367783"],["76315","0.039155"],["76311.2","0"],["76300.9","0.743111"],["76294.1","0.743177"],["76292.8","0"],["76289.8","0.285992"],["76289.2","0"],["76281.3","0.013102"],["76275.2","0.013103"],["76269.4","0.052898"],["76211","0"],["76200","0.007145"]],"a":[["76354.3","1.305846"],["76354.6","0.041223"],["76354.9","0.028919"],["76355.8","0.000198"],["76356.9","0.025278"],["76357.1","0.007479"],["76357.5","0"],["76357.6","0"],["76357.9","0"],["76358","0"],["76358.2","0.066556"],["76358.3","0.05"],["76359.8","0"],["76360.9","0.006547"],["76361","0.142767"],["76361.4","0"],["76361.9","0.0152"],["76362.1","0.023456"],["76362.4","0.013092"],["76363.3","0.081606"],["76364.3","0.065463"],["76364.5","0.01963"],["76365.1","0"],["76366.1","0.010177"],["76366.2","0.001"],["76366.3","0.065461"],["76367","0.031456"],["76368.5","0"],["76369.9","0"],["76370.1","0"],["76370.3","0.096403"],["76370.4","0"],["76370.6","0"],["76370.8","0.030408"],["76372.3","0"],["76372.5","0.066942"],["76373.3","0"],["76373.4","0.02923"],["76381","0.049167"],["76384.5","0"],["76394.4","0.01963"],["76397.7","0.013103"],["76403.8","0.139102"],["76405.3","0.013102"],["76406.8","0.109467"],["76407.7","0"],["76413.1","0"],["76419.2","0"],["76420.7","0"],["76422.2","0"],["76440.2","0.00055"],["76451.7","0.741646"],["76452.2","0.017644"]],"u":28058205,"seq":105954725792},"cts":1776816017568}
{"topic":"orderbook.200.BTCUSDT","ts":1776816017669,"type":"delta","data":{"s":"BTCUSDT","b":[["76354.2","0"],["76350.7","0"],["76350.3","0.0242"],["76350","0.00837"],["76347.4","0.028556"],["76346.6","0"],["76342.7","0.0132"],["76342","0.041152"],["76340.8","0.057633"],["76340.7","0"],["76338.2","0.022762"],["76336.5","0.006547"],["76334.1","0.090284"],["76333.8","0.126974"],["76333.5","0"],["76330.3","0.358803"],["76327.7","0.031456"],["76316.7","0.195882"],["76308.2","0.048487"],["76304","0.27715"],["76295.8","0.57021"],["76204.8","0"],["76201.6","0"],["76200.4","0"],["76200","0"]],"a":[["76350.4","1.45364"],["76350.8","0.05346"],["76352.3","0.028758"],["76354.1","0.047842"],["76354.3","0.083493"],["76354.6","0"],["76354.9","0"],["76356.8","0.006547"],["76356.9","0.023458"],["76358","0.0132"],["76358.4","0.10762"],["76360.9","0"],["76361","0.093332"],["76361.1","0"],["76361.9","0"],["76362.1","0"],["76362.8","0.006547"],["76364.9","0.028066"],["76366.9","0.02923"],["76368.6","0.000099"],["76370.3","0.065331"],["76373.4","0"],["76379.8","0"],["76385.6","0.037641"],["76391.6","0.137483"],["76391.8","0.031456"],["76399.8","0.294968"],["76400.3","0"],["76403.7","0.117159"],["76420.4","0.269561"],["76422.9","0.069454"],["76451.6","0"],["76451.7","0"],["76452.2","0"]],"u":28058206,"seq":105954726277},"cts":1776816017666}
{"topic":"orderbook.200.BTCUSDT","ts":1776816017769,"type":"delta","data":{"s":"BTCUSDT","b":[["76350.3","0.028421"],["76338.3","0.006547"],["76336.5","0"],["76319.3","0"],["76234","0.000439"],["76204.8","0.130981"]],"a":[["76350.4","1.459483"],["76354.1","0.028625"],["76354.3","0.081673"],["76362.8","0"],["76363.2","0.006547"],["76370.8","0.001178"],["76400.4","0"],["76437.3","0.120583"],["76451.6","0.000103"]],"u":28058207,"seq":105954726399},"cts":1776816017766}
{"topic":"orderbook.200.BTCUSDT","ts":1776816017869,"type":"delta","data":{"s":"BTCUSDT","b":[["76344.2","0.028053"],["76342.8","0"],["76282.9","0.024672"],["76204.8","0"]],"a":[["76350.4","1.464943"],["76350.5","0.017952"],["76350.6","0.031384"],["76355.7","0.006547"],["76356.8","0"],["76358.2","0.04705"],["76363.2","0"],["76363.3","0.08178"],["76364.2","0.006547"],["76382.4","0.013788"],["76389.9","0"],["76399.8","0.187978"],["76451.3","0"],["76451.6","0"]],"u":28058208,"seq":105954726517},"cts":1776816017859}
{"topic":"orderbook.200.BTCUSDT","ts":1776816017969,"type":"delta","data":{"s":"BTCUSDT","b":[["76338.4","0.006547"],["76338.3","0"],["76316.6","0"],["76204.8","0.130981"]],"a":[["76350.4","1.466763"],["76350.5","0.031615"],["76363.3","0.081606"]],"u":28058209,"seq":105954726640},"cts":1776816017956}
{"topic":"orderbook.200.BTCUSDT","ts":1776816018069,"type":"delta","data":{"s":"BTCUSDT","b":[["76338.7","0.006547"],["76338.4","0"],["76316.7","0.086098"],["76304.8","0.031456"],["76213.2","0.004553"],["76205.2","0"],["76204.8","0"]],"a":[["76350.4","1.467673"],["76355.7","0"],["76356.8","0.006547"]],"u":28058210,"seq":105954726675},"cts":1776816018062}
{"topic":"orderbook.200.BTCUSDT","ts":1776816018172,"type":"delta","data":{"s":"BTCUSDT","b":[["76339.5","0.006547"],["76338.7","0"],["76313.9","0.358637"],["76213.2","0"]],"a":[["76382.2","0.37206"],["76451.2","0"]],"u":28058211,"seq":105954726753},"cts":1776816018165}
{"topic":"orderbook.200.BTCUSDT","ts":1776816018269,"type":"delta","data":{"s":"BTCUSDT","b":[["76350.2","0.007162"],["76350","0"],["76335.1","0.010542"],["76315","0.141202"],["76205.8","0"]],"a":[["76350.4","1.460393"],["76381","0.158057"]],"u":28058212,"seq":105954726866},"cts":1776816018268}
{"topic":"orderbook.200.BTCUSDT","ts":1776816018369,"type":"delta","data":{"s":"BTCUSDT","b":[],"a":[["76350.4","1.464033"]],"u":28058213,"seq":105954726971},"cts":1776816018365}
{"topic":"orderbook.200.BTCUSDT","ts":1776816018468,"type":"delta","data":{"s":"BTCUSDT","b":[["76344.8","0.062562"],["76344.2","0"],["76339.5","0"],["76338.7","0.006547"],["76326.6","0.043176"],["76212.6","0.004781"]],"a":[],"u":28058214,"seq":105954727116},"cts":1776816018467}
{"topic":"orderbook.200.BTCUSDT","ts":1776816018569,"type":"delta","data":{"s":"BTCUSDT","b":[["76350.3","0.050421"],["76326.6","0.015447"]],"a":[],"u":28058215,"seq":105954727228},"cts":1776816018566}
{"topic":"orderbook.200.BTCUSDT","ts":1776816018668,"type":"delta","data":{"s":"BTCUSDT","b":[],"a":[["76350.4","1.461303"],["76354.3","0.023459"]],"u":28058216,"seq":105954727331},"cts":1776816018667}
{"topic":"orderbook.200.BTCUSDT","ts":1776816018769,"type":"delta","data":{"s":"BTCUSDT","b":[["76339.5","0.006547"],["76338.7","0"]],"a":[["76350.4","1.495923"],["76354.1","0.018251"]],"u":28058217,"seq":105954727436},"cts":1776816018760}
{"topic":"orderbook.200.BTCUSDT","ts":1776816018869,"type":"delta","data":{"s":"BTCUSDT","b":[["76344.8","0.034509"],["76343.6","0.028053"],["76208.3","0"]],"a":[["76350.4","1.496833"]],"u":28058218,"seq":105954727531},"cts":1776816018866}
{"topic":"orderbook.200.BTCUSDT","ts":1776816018971,"type":"delta","data":{"s":"BTCUSDT","b":[["76350.3","0.490398"],["76349.8","0.028051"],["76348.4","0.026195"],["76344.8","0.064377"],["76342.6","0.126"],["76342.1","0.006546"],["76342","0.013098"],["76339.5","0"],["76338.2","0.134019"],["76334.1","0.059784"],["76333.8","0"],["76333.4","0"],["76331.2","0.031456"],["76208.9","0"],["76208.4","0"]],"a":[["76350.4","1.005539"],["76350.8","0.02346"],["76356.8","0"],["76358.3","0.03"],["76360.9","0.006546"],["76363.3","0.03015"],["76364.2","0"],["76364.5","0"],["76366.1","0"],["76367","0"],["76368.5","0.006547"],["76369.9","0.01963"],["76370.5","0"],["76374.2","0"],["76374.9","0"],["76381.1","0"],["76451.2","0.000186"],["76451.3","0.130981"],["76451.6","0.000103"],["76451.7","0.741646"],["76452.2","0.017644"],["76452.4","0.000135"]],"u":28058219,"seq":105954727719},"cts":1776816018969}
{"topic":"orderbook.200.BTCUSDT","ts":1776816019069,"type":"delta","data":{"s":"BTCUSDT","b":[["76350.3","0.436699"],["76348.9","0.04815"],["76348.8","0.026594"],["76347.4","0"],["76346.5","0.028052"],["76346.4","0.004534"],["76344.8","0.094989"],["76342.2","0.104265"],["76342.1","0"],["76341.6","0"],["76340.9","0.004534"],["76340.8","0.037757"],["76340.2","0.008163"],["76338.2","0.022762"],["76337.6","0"],["76336.1","0"],["76326.6","0.043454"],["76323","0.100574"],["76212.6","0"]],"a":[["76350.4","0.716368"],["76350.5","0"],["76350.8","0"],["76352.3","0"],["76352.6","0.023459"],["76355.4","0.007693"],["76358.3","0"],["76360.7","0.006546"],["76360.8","0.024869"],["76360.9","0"],["76366.1","0.006546"],["76368.2","0.010399"],["76368.5","0"],["76370","0"],["76370.3","0.047216"],["76372.5","0.001"],["76375.9","0.014489"],["76378.1","0.031456"],["76380.9","0.130981"],["76394.4","0"],["76437.1","0.123861"],["76440.2","0.02018"],["76452.4","0"]],"u":28058220,"seq":105954727920},"cts":1776816019068}
{"topic":"orderbook.200.BTCUSDT","ts":1776816019169,"type":"delta","data":{"s":"BTCUSDT","b":[["76350.3","0.282273"],["76346.4","0"],["76343.6","0.032587"],["76343.3","0.006546"],["76340.2","0.001617"],["76317.6","0.03696"],["76258.2","0.133907"],["76214.2","0"]],"a":[["76350.4","0.967558"],["76350.6","0"],["76351.6","0.007693"],["76352.6","0"],["76353.6","0.007623"],["76354.1","0"],["76355.4","0"],["76356.9","0"],["76360.7","0.012"],["76362.3","0.006546"],["76366.1","0"],["76368.5","0.006546"],["76374.9","0.024959"],["76375","0.031456"],["76375.9","0"],["76452.4","0.000135"]],"u":28058221,"seq":105954728048},"cts":1776816019166}
{"topic":"orderbook.200.BTCUSDT","ts":1776816019269,"type":"delta","data":{"s":"BTCUSDT","b":[["76349.8","0"],["76349.5","0.026645"],["76348.8","0"],["76343.6","0.004534"],["76340.2","0"],["76339.4","0.035996"],["76336.2","0.001617"],["76214.2","6.180768"]],"a":[["76350.4","0.920981"],["76351.9","0.023459"],["76353.6","0"],["76360.7","0.006546"],["76362.3","0"],["76368.1","0.006546"],["76368.5","0"],["76452.7","0.00515"]],"u":28058222,"seq":105954728096},"cts":1776816019261}
{"topic":"orderbook.200.BTCUSDT","ts":1776816019369,"type":"delta","data":{"s":"BTCUSDT","b":[["76350.1","0.026645"],["76349.5","0"]],"a":[["76350.4","0.910628"],["76353.5","0.007623"],["76452.7","0"]],"u":28058223,"seq":105954728128},"cts":1776816019362}
{"topic":"orderbook.200.BTCUSDT","ts":1776816019469,"type":"delta","data":{"s":"BTCUSDT","b":[["76343.3","0"],["76341","0.006546"]],"a":[["76350.4","0.903348"],["76360.6","0.006546"],["76360.7","0"],["76366.1","0.006546"],["76368.1","0"]],"u":28058224,"seq":105954728208},"cts":1776816019466}
{"topic":"orderbook.200.BTCUSDT","ts":1776816019569,"type":"delta","data":{"s":"BTCUSDT","b":[["76350.3","0.288643"],["76342.3","0.006546"],["76341","0"]],"a":[["76350.4","0.728008"],["76360.6","0"],["76360.7","0.006546"],["76366.1","0"],["76368.1","0.006546"]],"u":28058225,"seq":105954728256},"cts":1776816019567}
{"topic":"orderbook.200.BTCUSDT","ts":1776816019669,"type":"delta","data":{"s":"BTCUSDT","b":[["76350.3","0.295923"],["76264.8","0.033735"]],"a":[["76350.4","0.903348"],["76374.6","0.064057"],["76374.7","0.130981"],["76374.9","0"],["76452.4","0"]],"u":28058226,"seq":105954728308},"cts":1776816019668}
{"topic":"orderbook.200.BTCUSDT","ts":1776816019771,"type":"delta","data":{"s":"BTCUSDT","b":[["76350.3","0.289553"],["76350.1","0"],["76348","0.026645"],["76344","0.023848"],["76342.8","0.006546"],["76342.3","0"],["76302.8","0.01963"],["76257","0"],["76214.2","0"]],"a":[["76362.8","0.012"],["76370.2","0.031456"],["76451.7","0"],["76452.2","0"]],"u":28058227,"seq":105954728363},"cts":1776816019770}
{"topic":"orderbook.200.BTCUSDT","ts":1776816019869,"type":"delta","data":{"s":"BTCUSDT","b":[["76350.3","0.282273"],["76343.3","0.006546"],["76342.8","0"]],"a":[],"u":28058228,"seq":105954728403},"cts":1776816019856}
{"topic":"orderbook.200.BTCUSDT","ts":1776816019969,"type":"delta","data":{"s":"BTCUSDT","b":[["76350.3","0.434598"]],"a":[["76353.8","0.018259"],["76353.9","0.030034"],["76451.3","0"],["76451.6","0"]],"u":28058229,"seq":105954728429},"cts":1776816019957}
