{"topic":"orderbook.200.BTCUSDT","ts":1776816040571,"type":"delta","data":{"s":"BTCUSDT","b":[["76323.4","0.28201"],["76322.8","0"],["76320.3","0.018221"],["76320.2","0.023396"],["76320","0.000432"],["76319.6","0.013818"],["76319.2","0.020543"],["76313.3","0.006548"],["76312.7","0"],["76312.5","0.03813"],["76312","0"],["76310.9","0.063483"],["76310.3","0.093071"],["76306.3","0.04703"],["76299.9","0.33601"],["76299.8","0.396886"],["76289.7","0.326037"],["76252.3","0.420367"],["76225.7","0.2969"],["76188.8","0"],["76172.3","0"],["76172","0"]],"a":[["76323.5","1.318882"],["76330.8","0.006549"],["76330.9","0.07089"],["76338.9","0.047734"],["76351.7","0.104278"],["76351.8","0.317784"],["76380.3","0.124648"],["76380.6","0"],["76404.5","0.008995"],["76405.9","0.299847"],["76426.2","0.323957"],["76437.3","0"],["76437.5","0"],["76437.9","0"],["76438","0"],["76438.1","0"]],"u":28058414,"seq":105954755546},"cts":1776816040558}
{"topic":"orderbook.200.BTCUSDT","ts":1776816040669,"type":"delta","data":{"s":"BTCUSDT","b":[["76313.3","0"],["76312.6","0.006548"],["76251.6","0.024672"],["76173.6","0"]],"a":[["76323.5","1.319792"],["76330.7","0.006548"],["76330.8","0"]],"u":28058415,"seq":105954755634},"cts":1776816040665}
{"topic":"orderbook.200.BTCUSDT","ts":1776816040768,"type":"delta","data":{"s":"BTCUSDT","b":[],"a":[["76330.7","0"],["76330.8","0.006548"]],"u":28058416,"seq":105954755685},"cts":1776816040767}
{"topic":"orderbook.200.BTCUSDT","ts":1776816040969,"type":"delta","data":{"s":"BTCUSDT","b":[["76323.4","0.300041"],["76313.3","0.006548"],["76312.6","0"],["76183.9","0.004659"],["76173.7","0"]],"a":[],"u":28058417,"seq":105954755776},"cts":1776816040968}
{"topic":"orderbook.200.BTCUSDT","ts":1776816041069,"type":"delta","data":{"s":"BTCUSDT","b":[["76323.4","0.278441"],["76321.8","0.01825"],["76321.7","0.023395"],["76320.3","0"],["76320.2","0"],["76313.3","0"],["76312.7","0.006548"]],"a":[["76323.5","1.319554"]],"u":28058418,"seq":105954755878},"cts":1776816041062}
{"topic":"orderbook.200.BTCUSDT","ts":1776816041169,"type":"delta","data":{"s":"BTCUSDT","b":[["76313.3","0.006548"],["76312.7","0"],["76292.6","0.100278"],["76234.7","0"]],"a":[["76323.5","1.133824"],["76411.1","0.12"],["76437.2","0"]],"u":28058419,"seq":105954755931},"cts":1776816041153}
{"topic":"orderbook.200.BTCUSDT","ts":1776816041269,"type":"delta","data":{"s":"BTCUSDT","b":[["76323.2","0.027063"],["76317.1","0.026206"],["76313.5","0.010647"],["76313.4","0.006548"],["76313.3","0"],["76310.3","0.065516"],["76292.6","0.097642"],["76234.7","0.195095"],["76180.8","0"],["76178.8","0"],["76177.6","0"],["76175.7","0"]],"a":[["76323.5","1.133981"],["76330.7","0.006548"],["76330.8","0"],["76365.3","0.098862"],["76428.2","0"],["76437.2","0.126"]],"u":28058420,"seq":105954756031},"cts":1776816041262}
{"topic":"orderbook.200.BTCUSDT","ts":1776816041371,"type":"delta","data":{"s":"BTCUSDT","b":[["76323.4","0.154562"],["76313.5","0.017195"],["76313.4","0"],["76178.8","0.002569"]],"a":[["76323.5","1.131251"],["76326.6","0.001"],["76330.7","0"],["76330.8","0.006548"],["76338","0"],["76338.8","0.006549"],["76437.2","0"]],"u":28058421,"seq":105954756099},"cts":1776816041360}
{"topic":"orderbook.200.BTCUSDT","ts":1776816041469,"type":"delta","data":{"s":"BTCUSDT","b":[["76323.4","0"],["76323.2","0"],["76321.8","0"],["76321.7","0"],["76320.7","0"],["76320","0"],["76319.6","0"],["76319.4","0.438931"],["76318.1","0.027065"],["76316.4","0"],["76316","0.026411"],["76315.8","0"],["76313.5","0.010647"],["76313.3","0.006548"],["76313.1","0.026886"],["76311.8","0.0004"],["76251.1","0"],["76247","0.687861"],["76177.6","0.008995"],["76175.7","0.000108"],["76173.7","0.008995"],["76173.6","0.048439"]],"a":[["76319.5","0.606203"],["76319.6","0.026541"],["76320.6","0.094562"],["76320.7","0.09"],["76321.1","0.01917"],["76323.2","0.11545"],["76323.3","0.203304"],["76323.4","0.2988"],["76323.5","0.428115"],["76324.5","0.001653"],["76325.8","0"],["76325.9","0"],["76326","0"],["76327.1","0.0044"],["76330.6","0.000099"],["76330.7","0.008201"],["76330.8","0"],["76331.1","0"],["76338","0.006549"],["76338.8","0"],["76435.9","0"],["76436","0"],["76436.1","0"],["76436.4","0"],["76436.5","0"],["76437","0"],["76437.1","0"]],"u":28058422,"seq":105954756366},"cts":1776816041462}
{"topic":"orderbook.200.BTCUSDT","ts":1776816041569,"type":"delta","data":{"s":"BTCUSDT","b":[["76319.4","0.319541"],["76319.2","0.039239"],["76313.7","0.006548"],["76313.3","0"],["76301","0"],["76287.2","0.150114"],["76281","0.000131"],["76264.9","0.268837"],["76252.3","0"],["76225.7","1.092283"],["76214.3","0.156671"],["76199.7","0.146145"]],"a":[["76319.5","0.381091"],["76320.6","0"],["76320.7","0"],["76321.1","0"],["76323.1","0.017433"],["76323.2","0.02545"],["76323.3","0"],["76323.4","0"],["76323.5","0.209865"],["76330.7","0.001653"],["76332.1","0.006548"],["76335.2","0"],["76335.3","0.028395"],["76336","0.02895"],["76338","0"],["76338.9","0.054283"],["76342.5","0.130981"],["76342.6","0.045322"],["76358","0.000131"],["76367.1","1.424962"],["76372.3","0"],["76378","0.031456"],["76411.2","0"],["76435.9","0.000143"],["76436","0.000328"]],"u":28058423,"seq":105954756566},"cts":1776816041568}
{"topic":"orderbook.200.BTCUSDT","ts":1776816041669,"type":"delta","data":{"s":"BTCUSDT","b":[["76319.4","0.337831"],["76316.1","0.004876"],["76173.6","0"]],"a":[["76319.5","0.380172"],["76324.5","0.006582"],["76326.4","0.00479"],["76327.1","0.004598"],["76330.4","0.004744"],["76330.7","0"],["76330.8","0.006548"],["76332.1","0"],["76332.2","0.001"],["76338.8","0.006549"],["76338.9","0.047734"],["76340","0"],["76436","0"]],"u":28058424,"seq":105954756692},"cts":1776816041664}
{"topic":"orderbook.200.BTCUSDT","ts":1776816041769,"type":"delta","data":{"s":"BTCUSDT","b":[["76319.4","0.314853"],["76316.5","0"],["76316.1","0"],["76313.7","0"],["76312.6","0.006548"],["76312.2","0.070279"],["76311.9","0"],["76309.2","0.000613"],["76173.6","0.048439"],["76172.3","0.126"]],"a":[["76319.5","0.558353"],["76321.1","0.008136"],["76323.5","0.034525"],["76324.5","0.001653"],["76330.5","0.006548"],["76330.8","0"],["76338.1","0.007549"],["76338.8","0"]],"u":28058425,"seq":105954756761},"cts":1776816041757}
{"topic":"orderbook.200.BTCUSDT","ts":1776816041869,"type":"delta","data":{"s":"BTCUSDT","b":[["76319.4","0.341917"],["76313.3","0.006548"],["76312.6","0"]],"a":[["76319.5","0.383179"],["76321.1","0.033587"],["76323.6","0"],["76330.4","0.011292"],["76330.5","0"],["76338.1","0.001"],["76338.8","0.006549"],["76436","0.000328"]],"u":28058426,"seq":105954756817},"cts":1776816041863}
{"topic":"orderbook.200.BTCUSDT","ts":1776816041969,"type":"delta","data":{"s":"BTCUSDT","b":[["76326.6","0.724043"],["76326.5","0.108936"],["76326.4","0.027062"],["76326.3","0.104467"],["76326","0.001458"],["76325.3","0.004765"],["76325.2","0.126"],["76323.8","0.054467"],["76323.5","0.277257"],["76323.4","0.055468"],["76322.4","0.000613"],["76319.7","0.235708"],["76319.4","0.0204"],["76319.2","0"],["76318.2","0.048467"],["76317.1","0"],["76316.2","0.108112"],["76316","0"],["76315.4","0"],["76313.3","0"],["76313.1","0"],["76312.2","0.065514"],["76311","0.031456"],["76310.9","0.033788"],["76310.8","0"],["76309.2","0"],["76307.3","0.019637"],["76306.5","0.086128"],["76306.4","0.130981"],["76306.3","0"],["76298.5","0"],["76294.7","0.006552"],["76263.1","0"],["76251","0.687863"],["76247","0"],["76225.7","0.421953"],["76199.7","0"],["76178.9","0"],["76178.8","0"],["76177.6","0"],["76175.7","0"],["76173.7","0"],["76173.6","0"],["76172.3","0"]],"a":[["76319.5","0"],["76319.6","0"],["76321.1","0"],["76323.1","0"],["76323.2","0"],["76323.5","0"],["76324.5","0"],["76326.4","0"],["76326.6","0"],["76326.7","0.014"],["76327.1","0"],["76327.2","0.0024"],["76329.3","0"],["76330.4","0"],["76330.6","0"],["76330.9","0"],["76331","0.000198"],["76331.1","0.002"],["76332.9","0"],["76335.1","0.008136"],["76335.3","0"],["76335.4","0"],["76336","0"],["76338.2","0.008096"],["76338.8","0"],["76339.4","0.007795"],["76342.2","0"],["76342.5","0"],["76342.7","0.041"],["76342.8","0.007951"],["76343.9","0"],["76346","0.043272"],["76346.5","0"],["76346.6","0.126"],["76347","0"],["76349.1","0"],["76349.6","0"],["76350.4","0"],["76352.9","0"],["76353.3","0.006548"],["76365.3","0"],["76367.1","0.031456"],["76374.9","1.379141"],["76393.1","1.379141"],["76420.6","0"],["76436.1","0.000574"],["76436.4","0.000133"],["76436.5","0.015482"],["76437","0.000099"],["76437.1","0.123861"],["76437.2","0.126"],["76437.3","0.000583"],["76437.5","0.002122"],["76437.9","0.00126"],["76438","0.000277"],["76438.1","0.000635"],["76439.3","0.130981"],["76440","0.000941"],["76440.2","0.00055"],["76440.7","0.048439"],["76440.8","0.000185"],["76441.5","0.130956"],["76441.6","0.000589"],["76442.2","0.00013"],["76442.5","0.000814"],["76442.7","0.014949"]],"u":28058427,"seq":105954757635},"cts":1776816041967}
{"topic":"orderbook.200.BTCUSDT","ts":1776816042069,"type":"delta","data":{"s":"BTCUSDT","b":[["76330.9","0.44758"],["76328.7","0.017372"],["76328.6","0.053467"],["76328.1","0.004731"],["76326.8","0.05515"],["76326.6","0.004765"],["76326.5","0"],["76326.4","0"],["76326.3","0.050198"],["76326","0.001"],["76325.3","0.006547"],["76323.8","0"],["76323.5","0"],["76323.4","0.001"],["76323.3","0.0004"],["76323","0.000613"],["76322.9","0.013821"],["76322.8","0.026204"],["76322.4","0"],["76320.7","0.000099"],["76319.7","0"],["76319.4","0.02"],["76319.2","0.013102"],["76318.2","0.032685"],["76318.1","0.002428"],["76317.3","0.065514"],["76315.4","0.065516"],["76314.1","0.031456"],["76312.7","0.073579"],["76312.6","0.130981"],["76312.5","0"],["76312.2","0"],["76311.8","0"],["76310.3","0"],["76304.6","0.006551"],["76294.7","0"],["76291.1","0.03"],["76270.3","0.715001"],["76264.9","0.047379"],["76256.6","0.687828"],["76184.9","0"],["76184.7","0"],["76183.9","0"],["76182.6","0"],["76182.5","0"],["76181.4","0"],["76180","0"]],"a":[["76326.7","0"],["76327.2","0"],["76331","0.2995"],["76331.1","0.026537"],["76334.6","0.025446"],["76334.8","0.008136"],["76335.1","0"],["76337.1","0"],["76338.6","0.0044"],["76338.7","0.046663"],["76338.9","0"],["76339","0"],["76339.4","0"],["76339.6","0.007795"],["76340","0.013092"],["76340.2","0.025402"],["76340.9","0"],["76341.9","0.065463"],["76343.3","0.006547"],["76343.9","0.065461"],["76347.5","0.02895"],["76351.6","0.006548"],["76351.7","0.135734"],["76353.3","0"],["76354.2","0.088076"],["76374.9","0"],["76393.1","0"],["76427.8","0"]],"u":28058428,"seq":105954758241},"cts":1776816042067}
{"topic":"orderbook.200.BTCUSDT","ts":1776816042172,"type":"delta","data":{"s":"BTCUSDT","b":[["76330.9","0.053158"],["76326.8","0.017356"],["76326.6","0"],["76325.3","0"],["76325.2","0"],["76323.5","0.006547"],["76323","0"],["76318.2","0.110773"],["76317.4","0.031456"],["76315.5","0.126"],["76312.7","0.054023"],["76311.1","0.023849"],["76310.9","0"],["76276.1","0.874333"],["76268.9","0.743422"],["76251","0"],["76184.9","0.130981"]],"a":[["76331","0.592399"],["76332.5","0.009928"],["76334.5","0.013332"],["76334.8","0"],["76337.1","0.009587"],["76338.7","0.159358"],["76339.6","0"],["76340.5","0.102642"],["76348.8","0.007548"],["76350.5","0.010603"],["76351.6","0"],["76357.8","0.019637"],["76426.2","0.08757"],["76426.4","0.741891"],["76433.6","0.741821"],["76441.5","0"],["76441.6","0"],["76442.2","0"],["76442.5","0"],["76442.7","0"]],"u":28058429,"seq":105954758388},"cts":1776816042171}
{"topic":"orderbook.200.BTCUSDT","ts":1776816042269,"type":"delta","data":{"s":"BTCUSDT","b":[["76323.5","0"],["76323","0.006547"],["76314.2","0.027522"],["76312.7","0"],["76312.6","0"],["76289.7","0"],["76184.7","0.006832"],["76183.9","0.004659"]],"a":[["76331","0.592723"],["76334.5","0.023121"],["76338.2","0.000099"],["76338.4","0.009743"],["76338.6","0.09235"],["76338.7","0.126"],["76340.4","0.006547"],["76342.8","0"],["76343.3","0"],["76348.8","0.001"],["76348.9","0.007548"],["76351.7","0.031456"],["76351.8","0"],["76441.5","0.130956"]],"u":28058430,"seq":105954758457},"cts":1776816042267}
{"topic":"orderbook.200.BTCUSDT","ts":1776816042369,"type":"delta","data":{"s":"BTCUSDT","b":[["76330.9","0"],["76328.7","0"],["76328.6","0.329833"],["76328.1","0"],["76327.2","0.031542"],["76327.1","0.026407"],["76326.8","0"],["76323.5","0.027063"],["76323.3","0"],["76323","0"],["76322.3","0.006547"],["76322","0.026883"],["76321","0.0004"],["76301.1","0.327598"],["76183.9","0"]],"a":[["76328.7","0.953621"],["76330.8","0.07685"],["76330.9","0.223724"],["76331","0.03"],["76331.1","0"],["76332.5","0"],["76336.3","0.0044"],["76338.6","0.063232"],["76339.9","0.006547"],["76340.2","0"],["76340.4","0"],["76345.2","0.02893"],["76347.4","0.006548"],["76348.9","0.001"],["76364.7","0.335838"],["76440.2","0"],["76440.7","0"],["76440.8","0"],["76441.5","0"]],"u":28058431,"seq":105954758712},"cts":1776816042365}
{"topic":"orderbook.200.BTCUSDT","ts":1776816042469,"type":"delta","data":{"s":"BTCUSDT","b":[["76322.3","0"],["76321.1","0.006547"]],"a":[["76330.9","0.217028"],["76341.8","0.012"],["76346.5","0.006548"],["76347.4","0"],["76347.5","0"]],"u":28058432,"seq":105954758762},"cts":1776816042466}
{"topic":"orderbook.200.BTCUSDT","ts":1776816042569,"type":"delta","data":{"s":"BTCUSDT","b":[["76328.6","0.380973"],["76303.5","0.118765"],["76281","0.033369"],["76252.3","0.24828"],["76225.7","0.079121"],["76184.7","0"]],"a":[["76328.7","0.778281"],["76330.8","0"],["76330.9","0.009928"],["76331","0.026537"],["76338.6","0.08915"],["76361.7","0.169776"],["76411","0.083931"],["76433.5","0.465121"],["76433.7","0"],["76440.2","0.00055"]],"u":28058433,"seq":105954758836},"cts":1776816042567}
{"topic":"orderbook.200.BTCUSDT","ts":1776816042669,"type":"delta","data":{"s":"BTCUSDT","b":[["76328.6","0.391893"],["76303.5","0.123915"],["76196.3","0.261425"],["76184.9","0"]],"a":[["76334.4","0.015609"],["76334.5","0.019363"],["76337.1","0"]],"u":28058434,"seq":105954758888},"cts":1776816042663}
{"topic":"orderbook.200.BTCUSDT","ts":1776816042769,"type":"delta","data":{"s":"BTCUSDT","b":[["76328.6","0.393713"],["76322.1","0.006547"],["76321.1","0"],["76300.8","0.00515"],["76186.3","0"]],"a":[["76341.8","0"],["76346.5","0"],["76348.7","0.006548"],["76440.7","0.048439"]],"u":28058435,"seq":105954758918},"cts":1776816042760}
{"topic":"orderbook.200.BTCUSDT","ts":1776816042869,"type":"delta","data":{"s":"BTCUSDT","b":[["76328.6","0.323113"]],"a":[["76372.1","0.00515"],["76440.7","0"]],"u":28058436,"seq":105954758952},"cts":1776816042866}
{"topic":"orderbook.200.BTCUSDT","ts":1776816042971,"type":"delta","data":{"s":"BTCUSDT","b":[["76328.6","0.310373"],["76322.1","0"],["76321.2","0.006547"]],"a":[["76328.7","0.953621"],["76335.5","0.0006"],["76346.5","0.006548"],["76348.7","0"],["76366.6","0.096814"],["76372.2","0.00515"],["76439.3","0"],["76440","0"],["76440.2","0"]],"u":28058437,"seq":105954759054},"cts":1776816042968}
{"topic":"orderbook.200.BTCUSDT","ts":1776816043068,"type":"delta","data":{"s":"BTCUSDT","b":[["76328.6","0.400373"],["76322.9","0.028018"],["76322.1","0.006547"],["76321.2","0"],["76291.1","0"],["76186.3","0.008995"]],"a":[["76346.5","0"],["76348.7","0.006548"]],"u":28058438,"seq":105954759128},"cts":1776816043067}
{"topic":"orderbook.200.BTCUSDT","ts":1776816043169,"type":"delta","data":{"s":"BTCUSDT","b":[["76328.6","0.428344"],["76322.1","0"],["76321.1","0.006547"]],"a":[["76331.7","0.026537"],["76346.5","0.006548"],["76348.7","0"],["76438.1","0"]],"u":28058439,"seq":105954759169},"cts":1776816043167}
{"topic":"orderbook.200.BTCUSDT","ts":1776816043269,"type":"delta","data":{"s":"BTCUSDT","b":[["76328.6","0.427434"]],"a":[["76330.9","0.026069"]],"u":28058440,"seq":105954759180},"cts":1776816043213}
{"topic":"orderbook.200.BTCUSDT","ts":1776816043369,"type":"delta","data":{"s":"BTCUSDT","b":[["76322.1","0.006547"],["76321.1","0"]],"a":[["76346.5","0"],["76348.7","0.006548"]],"u":28058441,"seq":105954759250},"cts":1776816043355}
{"topic":"orderbook.200.BTCUSDT","ts":1776816043469,"type":"delta","data":{"s":"BTCUSDT","b":[["76332.7","0.776135"],["76332.3","0.0607"],["76332.2","0.053689"],["76331.6","0.079883"],["76331.5","0.001"],["76328.8","0.110304"],["76328.7","0.024726"],["76328.6","0.3444"],["76328","0.026202"],["76327.2","0"],["76327.1","0"],["76326.4","0.018968"],["76326.3","0.05"],["76326.1","0.006547"],["76325.5","0.026231"],["76325.1","0.0004"],["76323.5","0"],["76322.8","0"],["76322.1","0"],["76322","0"],["76321.8","0.106771"],["76321","0"],["76318.1","0"],["76317.1","0.019637"],["76316.2","0"],["76315.6","0.130981"],["76313.5","0"],["76307.3","0"],["76187.8","0"],["76186.9","0"],["76186.4","0"],["76186.3","0"]],"a":[["76328.7","0"],["76330.9","0"],["76331","0"],["76331.7","0"],["76332.2","0"],["76332.8","0.2995"],["76333.9","0.019638"],["76334","0.028853"],["76334.4","0"],["76334.5","0"],["76334.6","0"],["76336","0.009915"],["76336.3","0"],["76336.4","0.024322"],["76338.4","0"],["76338.6","0.063232"],["76338.7","0"],["76339.3","0.033161"],["76339.9","0.009574"],["76340.4","0.0044"],["76342.7","0.011"],["76343.3","0.006547"],["76343.4","0.089018"],["76348.7","0"],["76350.5","0"],["76351.7","0"],["76353.3","0.006547"],["76354.1","0.130981"],["76354.2","0.056873"],["76354.5","0.031456"],["76356","0"],["76357.8","0"],["76358.5","0.031456"],["76361.5","0.130981"],["76361.6","0.031456"],["76362.8","0.019637"],["76363.6","0"],["76365.5","0.031456"],["76366","0"],["76366.6","0"],["76367.1","0"],["76370.6","0"],["76438.1","0.000635"],["76439.3","0.130981"],["76440","0.000941"],["76440.2","0.00055"],["76440.7","0.048439"],["76440.8","0.000185"]],"u":28058442,"seq":105954759847},"cts":1776816043468}
{"topic":"orderbook.200.BTCUSDT","ts":1776816043569,"type":"delta","data":{"s":"BTCUSDT","b":[["76332.7","0.769365"],["76332.3","0.046361"],["76331.6","0.077153"],["76328.8","0.052813"],["76328.6","0.126"],["76326.5","0.006547"],["76326.1","0"],["76269.4","0.268292"],["76241.9","0.061622"],["76214.3","0.265102"],["76188.7","0"]],"a":[["76332.8","0.332009"],["76333.9","0"],["76339.3","0.009776"],["76343.3","0"],["76343.7","0.023384"],["76345.1","0.006547"],["76354","0.095347"],["76354.2","0"],["76410","0.051275"]],"u":28058443,"seq":105954759925},"cts":1776816043566}
{"topic":"orderbook.200.BTCUSDT","ts":1776816043669,"type":"delta","data":{"s":"BTCUSDT","b":[["76332.3","0"],["76332.2","0.027153"],["76328.6","0.136563"],["76188.7","0.126984"]],"a":[["76355","0.010578"],["76440.8","0"]],"u":28058444,"seq":105954759949},"cts":1776816043657}
{"topic":"orderbook.200.BTCUSDT","ts":1776816043771,"type":"delta","data":{"s":"BTCUSDT","b":[["76332.7","0.79942"],["76332.2","0"],["76331.7","0.023329"]],"a":[["76332.8","0.332181"]],"u":28058445,"seq":105954759991},"cts":1776816043769}
{"topic":"orderbook.200.BTCUSDT","ts":1776816043869,"type":"delta","data":{"s":"BTCUSDT","b":[],"a":[["76333.8","0.009912"],["76336","0"],["76343.9","0.072008"],["76345.1","0"],["76440.8","0.000185"]],"u":28058446,"seq":105954760030},"cts":1776816043866}
{"topic":"orderbook.200.BTCUSDT","ts":1776816044069,"type":"delta","data":{"s":"BTCUSDT","b":[],"a":[["76332.8","0"],["76333.8","0"],["76343.8","0.006547"],["76343.9","0.065461"],["76345.2","0"],["76441.4","0.044911"],["76441.5","0.130956"]],"u":28058447,"seq":105954760075},"cts":1776816044068}
{"topic":"orderbook.200.BTCUSDT","ts":1776816044170,"type":"delta","data":{"s":"BTCUSDT","b":[["76348.7","0.566895"],["76346.2","0.131977"],["76346.1","0.131532"],["76346","0.027148"],["76343.5","0.060998"],["76343.4","0.000198"],["76343.3","0.203149"],["76342","0.002"],["76340.6","0.005308"],["76338.6","0.167801"],["76338.5","0.194476"],["76338.4","0.0004"],["76338","0.05"],["76337.4","0.001"],["76336.7","0.065514"],["76336.3","0.000984"],["76336.2","0.019637"],["76335.7","0.000099"],["76335.4","0.0004"],["76334.8","0.065516"],["76332.8","0.056363"],["76332.7","0.032441"],["76331.7","0"],["76331.6","0.05"],["76329","0.05167"],["76328.9","0.162437"],["76328.8","0"],["76328.7","0"],["76328.6","0.010563"],["76328.2","0.000099"],["76328","0"],["76327.2","0.002428"],["76326.5","0.000984"],["76325.5","0"],["76325.1","0"],["76324.2","0.396886"],["76322.9","0.101146"],["76321.9","0.130981"],["76321.5","0.048439"],["76320.6","0.031456"],["76319.2","0"],["76317.4","0.13116"],["76317.3","0"],["76317.1","0"],["76315.4","0"],["76305","0.000131"],["76304.6","0"],["76302.8","0.019637"],["76299.8","0"],["76295.5","0.391274"],["76292.6","0"],["76291.8","0.626179"],["76285.3","0"],["76281","0.033238"],["76276.1","0.130981"],["76273.2","0.687661"],["76272.6","1.008368"],["76270.7","0.013104"],["76268.9","0"],["76260.6","0.00262"],["76260.2","0.013106"],["76257.2","0"],["76257.1","0.236348"],["76257","0"],["76256.6","0"],["76255.3","0"],["76252.5","0.031456"],["76242.2","0"],["76234.2","0.184577"],["76214.3","0.156671"],["76200.4","0"],["76200","0"],["76199.6","0"],["76198.7","0"],["76198.5","0"],["76198.1","0"],["76197","0"],["76196.3","0"],["76196.2","0"],["76195.6","0"],["76195.1","0"],["76195","0"],["76192","0"],["76190.6","0"],["76189","0"],["76188.9","0"],["76188.7","0"]],"a":[["76334","0"],["76335.5","0"],["76336.1","0"],["76336.4","0"],["76338.1","0"],["76338.2","0"],["76338.6","0"],["76339.3","0"],["76339.9","0"],["76340","0"],["76340.4","0"],["76340.5","0"],["76341.9","0"],["76342.6","0"],["76342.7","0"],["76343.4","0"],["76343.7","0"],["76343.8","0"],["76343.9","0"],["76344","0"],["76345.8","0"],["76346","0"],["76346.2","0"],["76346.6","0"],["76348.8","0.503534"],["76349","0.029847"],["76353.3","0"],["76354","0"],["76354.1","0"],["76354.2","0.028653"],["76354.5","0"],["76354.6","0"],["76355","0"],["76356.1","0.000984"],["76356.4","0.004"],["76358","0"],["76358.5","0"],["76358.6","0"],["76358.7","0.004929"],["76358.8","0.004588"],["76359.4","0.023379"],["76360.3","0.00479"],["76361.5","0.020154"],["76361.6","0.060532"],["76361.7","0"],["76361.8","0.003712"],["76362.3","0"],["76362.7","0"],["76362.8","0"],["76364.7","0"],["76365.5","0"],["76365.9","0.000984"],["76369.1","0.02891"],["76374.1","0"],["76374.2","0.033932"],["76374.3","0"],["76377.4","0"],["76378","0"],["76379.6","0"],["76380.3","0.232722"],["76380.7","0"],["76381.5","0"],["76382","0.001131"],["76382.2","0"],["76382.3","0"],["76383.2","0.019637"],["76384","0.031456"],["76386.8","0.396313"],["76387.1","0.162437"],["76387.2","0"],["76391.3","0.105819"],["76391.8","0"],["76394.4","0"],["76395.8","0"],["76396.3","0.031456"],["76397.8","0.130981"],["76398.2","0"],["76399.5","0"],["76399.7","0.031456"],["76403.2","0"],["76408.4","0"],["76420.3","0.031456"],["76422.5","0"],["76426.1","0.031456"],["76426.2","0.28814"],["76426.4","0"],["76429.5","0.031456"],["76433.4","0.031456"],["76433.6","0"],["76435.4","0"],["76440.2","0.020187"],["76441.6","0.000589"],["76442.2","0.00013"],["76442.5","0.000814"],["76442.6","0.031456"],["76442.7","0.014949"],["76442.8","0.000897"],["76442.9","0.00041"],["76443.2","0.00032"],["76443.5","0.000094"],["76443.9","0.000074"],["76444","0.001124"],["76444.6","0.000099"],["76444.7","0.000984"],["76444.8","0.000102"],["76444.9","0.246269"],["76445","0.815025"],["76445.9","0.003961"],["76446.2","0.00282"],["76446.3","0.000356"],["76446.5","0.000108"],["76446.8","0.194737"],["76447.6","0.000423"],["76447.8","0.000116"],["76448","0.001811"],["76448.1","0.000402"],["76448.6","0.001252"],["76449.5","0.086451"],["76449.6","0.000016"],["76450","0.067061"],["76450.5","0.031456"],["76450.6","0.233214"],["76450.7","0.629604"],["76450.9","0.001395"],["76451.2","0.000186"],["76451.3","0.130981"],["76451.6","0.000103"],["76452.2","0.017644"],["76452.4","0.000135"],["76452.7","0.00515"],["76453.1","0.000412"],["76453.2","0.000219"]],"u":28058448,"seq":105954761696},"cts":1776816044168}
{"topic":"orderbook.200.BTCUSDT","ts":1776816044269,"type":"delta","data":{"s":"BTCUSDT","b":[["76348.7","0.571803"],["76346.3","0.006546"],["76346.2","0.024537"],["76346.1","0.005273"],["76343.5","0.087195"],["76343.3","0.282437"],["76342","0.006"],["76341.1","0.0004"],["76338.6","0.071272"],["76338.4","0"],["76336.9","0.031456"],["76336.8","0.045417"],["76335.4","0"],["76326.4","0.131567"],["76324.3","0.031456"],["76312.8","0.02904"],["76309.7","0.391274"],["76300","0.119794"],["76299.9","0.130981"],["76295.8","0.204497"],["76295.5","0"],["76295.2","0.397038"],["76291.9","0.186944"],["76287.2","0.038203"],["76285.9","0.008995"],["76277.1","0"],["76269.4","0.05318"],["76257.1","0.025806"],["76252.5","0"],["76234.2","0.512722"],["76208.3","0"],["76205.2","0"],["76204.8","0"],["76201.6","0"],["76201","0"],["76200.5","0"]],"a":[["76348.8","0.316667"],["76356.4","0.0044"],["76361.5","0"],["76361.6","0"],["76363.3","0.013095"],["76365.1","0.04833"],["76365.2","0.065474"],["76365.3","0.02888"],["76365.6","0"],["76367.1","0.065473"],["76370.6","0.074577"],["76370.9","0"],["76373.9","0.031456"],["76374","0.137527"],["76374.2","0"],["76377.7","0.326698"],["76380.2","0.05913"],["76380.3","0.162437"],["76380.4","0"],["76385.6","0.195111"],["76388.2","0.368361"],["76389.9","0.013105"],["76401.3","0.199936"],["76411","0.048111"],["76411.1","0"],["76415.8","1.043882"],["76426.2","0.08757"],["76429.4","0.017971"],["76433.5","0.185064"],["76452.4","0"],["76452.7","0"],["76453.1","0"],["76453.2","0"]],"u":28058449,"seq":105954761907},"cts":1776816044266}
{"topic":"orderbook.200.BTCUSDT","ts":1776816044368,"type":"delta","data":{"s":"BTCUSDT","b":[["76348.7","0.576777"],["76343.5","0.204158"],["76342.6","0.2048"],["76342","0.011"],["76338.6","0.013102"],["76338.5","0"],["76338.2","0.092127"],["76338.1","0.124426"],["76336.8","0"],["76322.9","0.068946"],["76321.8","0"],["76311.1","0.137595"],["76214.3","0"],["76208.3","0.048439"]],"a":[["76348.8","0.329767"],["76356.2","0.004588"],["76358.8","0"],["76362.5","0.035918"],["76362.6","0.103959"],["76369.1","0"],["76370.6","0.081395"],["76371.6","0.006546"],["76373.9","0.088371"],["76374","0.130981"],["76377.6","0.098147"],["76401.4","0"],["76427.4","0.086437"],["76451.3","0"],["76451.6","0"],["76452.2","0"]],"u":28058450,"seq":105954762017},"cts":1776816044367}
{"topic":"orderbook.200.BTCUSDT","ts":1776816044469,"type":"delta","data":{"s":"BTCUSDT","b":[["76346.3","0.017002"],["76346.2","0.031083"],["76343.3","0.283437"],["76301.1","0"],["76296.8","0.74315"],["76289.6","0.74322"],["76208.3","0"]],"a":[["76348.8","0.317027"],["76356.2","0.009517"],["76358.7","0"],["76370.5","0.006546"],["76370.6","0.049939"],["76370.8","0.031456"],["76371.6","0"],["76447.2","0.741689"],["76451.2","0"]],"u":28058451,"seq":105954762086},"cts":1776816044465}
{"topic":"orderbook.200.BTCUSDT","ts":1776816044572,"type":"delta","data":{"s":"BTCUSDT","b":[["76348.7","0.572434"],["76346.4","0.014753"],["76346.3","0"],["76346.2","0.024537"],["76346.1","0.010526"],["76343.6","0.006546"],["76342.6","0"],["76303.5","0.031489"],["76300","0.326309"],["76291.9","0.384895"],["76234.2","0.184577"]],"a":[["76354.1","0.014431"],["76356.8","0.00479"],["76360.3","0"],["76370.8","0"],["76380.2","0.054253"],["76444.9","0.494307"]],"u":28058452,"seq":105954762140},"cts":1776816044570}
{"topic":"orderbook.200.BTCUSDT","ts":1776816044669,"type":"delta","data":{"s":"BTCUSDT","b":[["76348.7","0.600863"],["76343.5","0.087195"],["76318.2","0.171921"],["76317.8","0.333973"],["76317.4","0.031456"],["76208.4","0"]],"a":[["76348.8","0.303927"],["76363.2","0.012274"],["76370.6","0.081395"],["76446.8","0.199549"]],"u":28058453,"seq":105954762188},"cts":1776816044660}
{"topic":"orderbook.200.BTCUSDT","ts":1776816044768,"type":"delta","data":{"s":"BTCUSDT","b":[["76348.7","0.599152"],["76343.3","0.204149"],["76260.9","0.12"],["76208.9","0"]],"a":[["76353.9","0.004588"],["76356.2","0.004929"],["76371.4","0.010584"],["76450.7","0"],["76450.9","0"]],"u":28058454,"seq":105954762217},"cts":1776816044762}
{"topic":"orderbook.200.BTCUSDT","ts":1776816044869,"type":"delta","data":{"s":"BTCUSDT","b":[["76348.7","0.593128"],["76345.6","0.005293"],["76261.6","0.111645"],["76241.9","0.025802"],["76241.8","0"]],"a":[["76348.8","0.317027"],["76354.1","0.01936"],["76356.2","0"],["76450.7","0.629604"]],"u":28058455,"seq":105954762254},"cts":1776816044867}
{"topic":"orderbook.200.BTCUSDT","ts":1776816044969,"type":"delta","data":{"s":"BTCUSDT","b":[["76346.1","0.005273"],["76343.5","0.092454"]],"a":[["76348.8","0.324009"]],"u":28058456,"seq":105954762273},"cts":1776816044955}
{"topic":"orderbook.200.BTCUSDT","ts":1776816045069,"type":"delta","data":{"s":"BTCUSDT","b":[["76348.7","0.372744"]],"a":[["76348.8","0.499349"],["76370.6","0.049939"],["76430.7","0.024672"],["76450.7","0"]],"u":28058457,"seq":105954762319},"cts":1776816045066}
{"topic":"orderbook.200.BTCUSDT","ts":1776816045169,"type":"delta","data":{"s":"BTCUSDT","b":[["76343.6","0"],["76343.5","0.099"],["76343.3","0.078149"],["76336.9","0"],["76332.9","0.024912"],["76332.8","0.031456"],["76332.7","0.001"],["76328.9","0.031456"],["76208.9","0.025633"]],"a":[["76351.6","0.028846"],["76356.5","0.126"],["76358.6","0.125794"],["76370.6","0.081395"],["76430.7","0"],["76450.5","0"],["76450.6","0"]],"u":28058458,"seq":105954762413},"cts":1776816045167}
{"topic":"orderbook.200.BTCUSDT","ts":1776816045269,"type":"delta","data":{"s":"BTCUSDT","b":[["76348.7","0.295597"],["76347.2","0.015625"],["76347.1","0.026173"],["76346.6","0.026173"],["76346.4","0"],["76346.2","0"],["76346.1","0"],["76346","0"],["76345.6","0"],["76343.5","0.052867"],["76342.1","0.005293"],["76341.3","0.005279"],["76340.7","0.006546"],["76340.6","0.005259"],["76337.2","0.023324"],["76336.8","0.031456"],["76336.3","0.006298"],["76333.4","0.062523"],["76333.3","0.126"],["76332.9","0"],["76329","0.013297"],["76328.6","0"],["76234.2","0.295313"],["76214.6","0"],["76214.2","0"],["76208.9","0"]],"a":[["76348.8","0.512089"],["76348.9","0.018549"],["76351.5","0.004588"],["76352","0.004929"],["76353.4","0.004889"],["76353.9","0"],["76354.1","0.047356"],["76356.8","0"],["76357.4","0.003695"],["76358.5","0.044558"],["76361.8","0"],["76362.5","0"],["76362.6","0"],["76365.8","0.006547"],["76370.5","0"],["76446.8","0"],["76450.5","0.031456"],["76450.6","0.233214"]],"u":28058459,"seq":105954762636},"cts":1776816045264}
{"topic":"orderbook.200.BTCUSDT","ts":1776816045371,"type":"delta","data":{"s":"BTCUSDT","b":[["76347.3","0.03148"],["76347.2","0.079288"],["76347.1","0"],["76341.2","0.006546"],["76340.7","0"]],"a":[["76348.8","0.499899"],["76365.8","0"],["76367","0.006547"],["76374.1","0.019637"],["76383.2","0"]],"u":28058460,"seq":105954762695},"cts":1776816045360}
{"topic":"orderbook.200.BTCUSDT","ts":1776816045469,"type":"delta","data":{"s":"BTCUSDT","b":[["76341.2","0"],["76340.7","0.006546"]],"a":[["76365.1","0.054877"],["76367","0"],["76430.7","0.024672"]],"u":28058461,"seq":105954762734},"cts":1776816045465}
{"topic":"orderbook.200.BTCUSDT","ts":1776816045568,"type":"delta","data":{"s":"BTCUSDT","b":[["76348.7","0.044841"],["76347.6","0.016198"],["76346.6","0"],["76346.2","0.026173"],["76340.7","0"],["76338.8","0.006546"],["76320.9","0.00655"],["76217.2","0"],["76215.5","0"]],"a":[["76348.8","0.517587"],["76349.6","0.004929"],["76351.5","0"],["76352","0"],["76365","0.006547"],["76365.1","0.04833"]],"u":28058462,"seq":105954762917},"cts":1776816045567}
{"topic":"orderbook.200.BTCUSDT","ts":1776816045669,"type":"delta","data":{"s":"BTCUSDT","b":[["76348.7","0"],["76347.6","0"],["76347.3","0"],["76347.2","0"],["76346.2","0"],["76343.5","0"],["76343.4","0"],["76343.3","0.029616"],["76342.1","0"],["76341.3","0"],["76341.1","0"],["76340.6","0"],["76340.5","0.0004"],["76338.8","0"],["76337.1","0.005279"],["76336.8","0"],["76336.3","0.000984"],["76336.2","0"],["76334.4","0.005259"],["76334","0.023325"],["76332.8","0"],["76331.3","0.005314"],["76329","0"],["76328.9","0"],["76327.7","0.019637"],["76324.5","0.031456"],["76324.3","0"],["76322.9","0.022414"],["76321.9","0"],["76320.6","0"],["76318.4","0.162437"],["76317.4","0"],["76315.6","0"],["76314.1","0"],["76311.2","0.130981"],["76311","0"],["76309.8","0.031456"],["76306.4","0"],["76302.8","0"],["76296.8","0"],["76289.6","0"],["76257","0.019637"],["76217.2","0.005309"],["76215.5","0.130981"],["76214.6","0.126"],["76214.2","6.180768"],["76208.9","0.025633"],["76208.4","0.066491"],["76208.3","0.048439"],["76205.2","0.126"],["76204.8","0.130981"],["76201.6","0.006524"],["76201","0.006284"],["76200.5","0.008995"],["76200.4","0.006521"],["76200","0.007145"],["76199.6","0.17438"],["76198.7","0.6"],["76198.6","0.001584"]],"a":[["76343.4","1.283112"],["76343.5","0.043393"],["76343.6","0.05805"],["76344.2","0.004929"],["76346","0.014377"],["76346.2","0.024797"],["76346.3","0.00479"],["76347.3","0.057509"],["76348.7","0.210697"],["76348.8","0.225108"],["76348.9","0.001"],["76349.6","0.000198"],["76349.9","0.041985"],["76350","0.111708"],["76351","0.004"],["76351.6","0"],["76353.1","0.003694"],["76353.4","0.000099"],["76354.1","0.047771"],["76354.2","0"],["76355.9","0.0004"],["76356.4","0"],["76357.4","0"],["76358.5","0"],["76358.6","0"],["76359.4","0"],["76360.9","0.006547"],["76361.7","0.022032"],["76361.8","0.048439"],["76364.9","0.120838"],["76365","0.130981"],["76365.1","0"],["76388.5","0.096785"],["76447.2","0"],["76447.6","0"],["76447.8","0"],["76448","0"],["76448.1","0"],["76448.6","0"],["76449.5","0"],["76449.6","0"],["76450","0"],["76450.5","0"],["76450.6","0"]],"u":28058463,"seq":105954763545},"cts":1776816045667}
{"topic":"orderbook.200.BTCUSDT","ts":1776816045768,"type":"delta","data":{"s":"BTCUSDT","b":[["76343.3","0.030016"],["76340.5","0"],["76338","0.03"],["76337.2","0"],["76337.1","0"],["76336","0.026199"],["76335.7","0.000499"],["76335.5","0.005293"],["76334.4","0"],["76334","0"],["76333","0.027961"],["76332","0.006547"],["76331.8","0.005279"],["76331.5","0.006259"],["76331.3","0"],["76327.7","0"],["76327","0.005314"],["76325.3","0.023328"],["76324.5","0"],["76324.4","0.031456"],["76318.6","0.019637"],["76306.5","0.047069"],["76300","0.119794"],["76291.9","0.186944"],["76234.2","0.498565"],["76225.7","0.302524"],["76198.6","0"]],"a":[["76343.4","1.297933"],["76343.5","0.018799"],["76344.2","0"],["76346","0"],["76346.3","0.028049"],["76347.3","0"],["76348.4","0.003694"],["76348.6","0.075092"],["76348.7","0"],["76348.8","0.20687"],["76351","0.0044"],["76353.1","0"],["76355.9","0"],["76359.8","0.024146"],["76359.9","0.02886"],["76360.4","0.03"],["76360.9","0"],["76365.4","0.019637"],["76374.1","0"],["76394.4","0.019637"],["76440.2","0.00055"],["76447.6","0.000423"]],"u":28058464,"seq":105954763901},"cts":1776816045767}
{"topic":"orderbook.200.BTCUSDT","ts":1776816045869,"type":"delta","data":{"s":"BTCUSDT","b":[["76343.3","0.043544"],["76338.9","0.084777"],["76338.8","0.024808"],["76338.7","0.070007"],["76333.5","0.006547"],["76333","0"],["76332","0"],["76326.5","0.131965"],["76199.6","0"],["76198.7","0"]],"a":[["76343.4","1.243582"],["76348.6","0.056131"],["76348.8","0.157"],["76359.7","0.006548"],["76359.8","0.017599"],["76365.3","0"],["76444.9","0.246269"]],"u":28058465,"seq":105954764064},"cts":1776816045858}
{"topic":"orderbook.200.BTCUSDT","ts":1776816045969,"type":"delta","data":{"s":"BTCUSDT","b":[["76343.3","0.261434"],["76340.9","0.026175"],["76338.9","0"],["76338.8","0"],["76338.7","0"],["76337.8","0.026176"],["76331","0.023326"],["76325.3","0"],["76289.4","0.743223"],["76282.2","0.743293"],["76200","0"]],"a":[["76343.4","1.235689"],["76439.7","0.741762"],["76447.6","0"]],"u":28058466,"seq":105954764196},"cts":1776816045962}
{"topic":"orderbook.200.BTCUSDT","ts":1776816046069,"type":"delta","data":{"s":"BTCUSDT","b":[["76333.5","0"],["76331.9","0.006547"],["76291.9","0.384896"],["76283","0.257808"],["76225.7","0.079121"]],"a":[["76343.4","1.276319"],["76437.1","0.298705"],["76444.9","0.495642"]],"u":28058467,"seq":105954764295},"cts":1776816046065}
{"topic":"orderbook.200.BTCUSDT","ts":1776816046171,"type":"delta","data":{"s":"BTCUSDT","b":[["76343.3","0.0144"],["76340.9","0"],["76339.9","0.015518"],["76337.8","0"],["76337.1","0.026176"],["76336","0"],["76334.1","0.027961"],["76333.3","0"],["76331.9","0"],["76331","0"],["76329.3","0.01045"],["76328.5","0.006547"],["76328.4","0.023327"],["76326.5","0.000984"],["76324.4","0"],["76320.9","0"],["76318.7","0.130981"],["76318.5","0.031456"],["76318.4","0"],["76311.8","0.006551"]],"a":[["76343.4","1.303783"],["76355.9","0.006547"],["76359.7","0"],["76361.6","0.031456"],["76446.5","0"]],"u":28058468,"seq":105954764641},"cts":1776816046170}
{"topic":"orderbook.200.BTCUSDT","ts":1776816046269,"type":"delta","data":{"s":"BTCUSDT","b":[["76343.3","0.017918"],["76339.9","0"],["76339.8","0.016243"],["76338.6","0"],["76338.2","0.095343"],["76337.3","0.026176"],["76337.1","0"],["76336.7","0"],["76335.5","0"],["76334.8","0"],["76333.8","0.013102"],["76333.4","0.018668"],["76331.9","0.065514"],["76330","0.065516"],["76329.5","0.006547"],["76329.4","0.014377"],["76328.5","0"],["76324.3","0.031456"],["76302.8","0.019637"],["76200.5","0"],["76200.4","0"]],"a":[["76343.4","1.312895"],["76355.9","0"],["76356","0.006548"],["76358.3","0.013095"],["76360.2","0.065474"],["76362.1","0.065473"],["76363.3","0"],["76365.2","0"],["76367.1","0"],["76394.4","0"],["76440.2","0.020187"],["76446.5","0.000108"]],"u":28058469,"seq":105954764840},"cts":1776816046267}
{"topic":"orderbook.200.BTCUSDT","ts":1776816046369,"type":"delta","data":{"s":"BTCUSDT","b":[["76343.3","0"],["76339.8","0"],["76338.2","0.054651"],["76338","0"],["76337.9","0.016201"],["76337.3","0"],["76334.8","0.026177"],["76333.4","0.035837"],["76332.3","0.005293"],["76331.7","0.006547"],["76330.1","0.033934"],["76329.5","0"],["76329.4","0"],["76328.4","0"],["76325.4","0.023328"],["76285.9","0"],["76200.5","0.008995"],["76200.4","0.006521"]],"a":[["76342.1","1.484925"],["76343.3","0.514311"],["76343.4","0.410397"],["76343.5","0"],["76346.3","0"],["76356","0.006547"],["76359.8","0.034893"],["76364.9","0.077037"]],"u":28058470,"seq":105954765285},"cts":1776816046367}
{"topic":"orderbook.200.BTCUSDT","ts":1776816046469,"type":"delta","data":{"s":"BTCUSDT","b":[["76342","0"],["76338.2","0.231819"],["76338","0.021205"],["76336.9","0.026176"],["76335.7","0.000099"],["76331.7","0"],["76330.6","0.0004"],["76330.2","0.006547"],["76330.1","0.025016"],["76273.6","0.008995"],["76273.2","0"],["76265.8","0.687634"],["76201","0"],["76200.5","0"],["76200.4","0"]],"a":[["76338.3","1.560465"],["76339.7","0.014377"],["76339.8","0.029728"],["76342.1","0.337513"],["76343.3","0"],["76343.4","0.027002"],["76343.6","0.03"],["76345.9","0.0044"],["76346.6","0.001"],["76348.9","0.007547"],["76349","0.001"],["76351","0"],["76446.2","0"],["76446.3","0"],["76446.5","0"]],"u":28058471,"seq":105954765654},"cts":1776816046468}
{"topic":"orderbook.200.BTCUSDT","ts":1776816046569,"type":"delta","data":{"s":"BTCUSDT","b":[["76338.2","0.233819"],["76330.7","0.006547"],["76330.6","0.0024"],["76330.2","0"],["76265.9","0.247356"],["76264.9","0.013105"],["76201.6","0"]],"a":[["76338.3","1.560656"],["76339.6","0.013165"],["76342","0.045204"],["76342.1","0.108248"],["76345.3","0.005198"],["76345.9","0.0064"],["76348.3","0.006547"],["76348.9","0.001"],["76349.6","0"],["76354.8","0.02884"],["76444.8","0"],["76444.9","0"],["76445","0"],["76445.9","0"]],"u":28058472,"seq":105954765759},"cts":1776816046564}
{"topic":"orderbook.200.BTCUSDT","ts":1776816046669,"type":"delta","data":{"s":"BTCUSDT","b":[["76336","0.026199"],["76331.6","0.056547"],["76330.7","0"],["76318.8","0.092254"],["76318.2","0"],["76317.8","0"],["76201.6","0.006524"]],"a":[["76342.1","0.107338"],["76345.3","0.010198"],["76348.3","0"],["76348.5","0.006547"],["76356","0"],["76356.4","0.006547"],["76359.9","0"],["76444.8","0.000102"]],"u":28058473,"seq":105954765823},"cts":1776816046667}
{"topic":"orderbook.200.BTCUSDT","ts":1776816046769,"type":"delta","data":{"s":"BTCUSDT","b":[["76338.2","0.234043"],["76338","0.037321"],["76337.9","0.026176"],["76334.8","0"],["76333.5","0.006547"],["76331.6","0.05"]],"a":[["76338.3","1.32009"],["76339.2","0.022577"],["76339.3","0.03153"],["76339.6","0"],["76342","0.020059"],["76345.3","0.011198"],["76348.5","0"],["76353.3","0.006547"],["76356.4","0"],["76359.7","0.006547"],["76359.8","0.017599"],["76360.4","0"]],"u":28058474,"seq":105954765903},"cts":1776816046767}
{"topic":"orderbook.200.BTCUSDT","ts":1776816046869,"type":"delta","data":{"s":"BTCUSDT","b":[["76338.2","0.374043"],["76333.9","0.006547"],["76333.5","0"],["76327.2","0.022065"],["76318.6","0"],["76308.2","0.336631"],["76257","0"],["76201","0.006284"]],"a":[["76338.3","1.05571"],["76339.8","0.024799"],["76341.3","0.004588"],["76342","0.049834"],["76444.8","0"]],"u":28058475,"seq":105954765971},"cts":1776816046867}
{"topic":"orderbook.200.BTCUSDT","ts":1776816046971,"type":"delta","data":{"s":"BTCUSDT","b":[["76333.9","0"],["76333.5","0.006547"],["76311.1","0.223537"]],"a":[["76342.1","0.112267"],["76365.4","0"],["76371.4","0"],["76373.4","0.019637"],["76444.8","0.000102"]],"u":28058476,"seq":105954766005},"cts":1776816046970}
{"topic":"orderbook.200.BTCUSDT","ts":1776816047069,"type":"delta","data":{"s":"BTCUSDT","b":[["76338.2","0.406343"],["76334.2","0.006547"],["76333.5","0"]],"a":[["76339.7","0"],["76444.9","0.495642"]],"u":28058477,"seq":105954766060},"cts":1776816047062}
{"topic":"orderbook.200.BTCUSDT","ts":1776816047169,"type":"delta","data":{"s":"BTCUSDT","b":[["76334.2","0"],["76332.8","0.006547"]],"a":[["76339.3","0"],["76349.9","0.048532"],["76353.3","0"],["76358.2","0.006547"],["76359.7","0"],["76445","0.815025"],["76445.9","0.003961"]],"u":28058478,"seq":105954766091},"cts":1776816047164}
{"topic":"orderbook.200.BTCUSDT","ts":1776816047269,"type":"delta","data":{"s":"BTCUSDT","b":[["76338.2","0.42846"],["76338","0.021205"],["76335.5","0.005288"],["76333.9","0.005254"],["76332.3","0"],["76331.5","0.001"],["76201","0"]],"a":[["76339.2","0"],["76343.6","0"],["76349.9","0.041985"],["76353.3","0.006547"],["76446.2","0.00282"]],"u":28058479,"seq":105954766115},"cts":1776816047243}
{"topic":"orderbook.200.BTCUSDT","ts":1776816047369,"type":"delta","data":{"s":"BTCUSDT","b":[],"a":[["76341.3","0"],["76343.7","0.004588"],["76349.8","0.006547"],["76353.3","0"],["76361.1","0.010685"],["76446.2","0"]],"u":28058480,"seq":105954766149},"cts":1776816047357}
{"topic":"orderbook.200.BTCUSDT","ts":1776816047569,"type":"delta","data":{"s":"BTCUSDT","b":[],"a":[["76349.8","0"],["76349.9","0.048532"],["76446.2","0.00282"]],"u":28058481,"seq":105954766188},"cts":1776816047559}
{"topic":"orderbook.200.BTCUSDT","ts":1776816047669,"type":"delta","data":{"s":"BTCUSDT","b":[],"a":[["76349.8","0.006547"],["76349.9","0.041985"],["76361.5","0.047056"],["76361.7","0"],["76446.2","0"]],"u":28058482,"seq":105954766212},"cts":1776816047648}
{"topic":"orderbook.200.BTCUSDT","ts":1776816047969,"type":"delta","data":{"s":"BTCUSDT","b":[["76338.2","0.33836"],["76332.8","0"],["76332.1","0.006547"]],"a":[["76349.8","0"],["76349.9","0.048532"],["76446.2","0.00282"]],"u":28058483,"seq":105954766254},"cts":1776816047963}
{"topic":"orderbook.200.BTCUSDT","ts":1776816048069,"type":"delta","data":{"s":"BTCUSDT","b":[["76332.1","0"],["76332","0.006547"],["76308.2","0"],["76201","0.006284"]],"a":[["76349.8","0.006547"],["76349.9","0.041985"],["76377.7","0"]],"u":28058484,"seq":105954766280},"cts":1776816048065}
{"topic":"orderbook.200.BTCUSDT","ts":1776816048169,"type":"delta","data":{"s":"BTCUSDT","b":[["76311.1","0.140644"]],"a":[["76377.6","0"],["76446.3","0.000356"]],"u":28058485,"seq":105954766295},"cts":1776816048148}
{"topic":"orderbook.200.BTCUSDT","ts":1776816048269,"type":"delta","data":{"s":"BTCUSDT","b":[["76309.1","0.321044"],["76201","0"]],"a":[["76370.2","0.337811"],["76446.3","0"]],"u":28058486,"seq":105954766311},"cts":1776816048245}
{"topic":"orderbook.200.BTCUSDT","ts":1776816048469,"type":"delta","data":{"s":"BTCUSDT","b":[],"a":[["76338.3","1.23105"],["76343.5","0.03153"],["76446.2","0"]],"u":28058487,"seq":105954766337},"cts":1776816048453}
{"topic":"orderbook.200.BTCUSDT","ts":1776816048571,"type":"delta","data":{"s":"BTCUSDT","b":[["76338.2","0.39816"],["76332.8","0.006547"],["76332","0"],["76331.7","0.026844"],["76325.4","0"]],"a":[["76338.3","1.05571"],["76349.8","0"],["76353.3","0.006547"]],"u":28058488,"seq":105954766373},"cts":1776816048556}
{"topic":"orderbook.200.BTCUSDT","ts":1776816048669,"type":"delta","data":{"s":"BTCUSDT","b":[["76338.2","0.39806"]],"a":[["76338.3","1.23105"],["76349.9","0.048532"],["76353.3","0"],["76370.1","0.160165"],["76370.6","0.031456"]],"u":28058489,"seq":105954766414},"cts":1776816048662}
{"topic":"orderbook.200.BTCUSDT","ts":1776816048769,"type":"delta","data":{"s":"BTCUSDT","b":[["76338.2","0.248153"],["76337.9","0"],["76337.1","0.028741"],["76336.9","0"],["76336","0"],["76332.8","0"],["76330.2","0.006547"],["76328.2","0.026944"],["76201","0.006284"],["76200.5","0.008995"]],"a":[["76338.3","1.28515"],["76348.7","0.006547"],["76349.9","0.041985"],["76356","0.006547"],["76358.2","0"],["76445.9","0"]],"u":28058490,"seq":105954766511},"cts":1776816048758}
{"topic":"orderbook.200.BTCUSDT","ts":1776816048869,"type":"delta","data":{"s":"BTCUSDT","b":[["76338.2","0.2303"],["76338.1","0"],["76338","0"],["76337.4","0.013573"],["76337.1","0"],["76335.6","0.028741"],["76335.5","0"],["76334.1","0"],["76333.9","0"],["76333.4","0.0502"],["76332.2","0.026201"],["76331.3","0.005285"],["76330.2","0"],["76329.6","0.005251"],["76328.3","0.006547"],["76328.2","0.000099"],["76325.5","0.026846"],["76324.4","0.031456"],["76324.3","0"],["76308.7","0.096568"]],"a":[["76338.3","1.289738"],["76339.8","0.024997"],["76340","0.004929"],["76342.1","0.107338"],["76343.7","0"],["76345.3","0.011"],["76346.1","0.006547"],["76348.7","0"],["76354","0.006548"],["76356","0"],["76379.2","0.693921"],["76445","0"]],"u":28058491,"seq":105954766731},"cts":1776816048858}
{"topic":"orderbook.200.BTCUSDT","ts":1776816048969,"type":"delta","data":{"s":"BTCUSDT","b":[["76338.2","0.233943"],["76331.8","0"],["76329.7","0.006547"],["76328.3","0"],["76327.9","0.005271"]],"a":[["76346.1","0"],["76346.5","0.006547"],["76354","0"],["76354.7","0.006548"]],"u":28058492,"seq":105954766799},"cts":1776816048967}
{"topic":"orderbook.200.BTCUSDT","ts":1776816049069,"type":"delta","data":{"s":"BTCUSDT","b":[["76336.3","0.029725"],["76335.6","0"],["76331.7","0"],["76330.7","0.006547"],["76329.7","0"],["76200.4","0.006521"],["76200","0.007145"]],"a":[["76338.3","1.2896"],["76346.5","0"],["76348.5","0.006547"],["76354.7","0"],["76356","0.006547"]],"u":28058493,"seq":105954766884},"cts":1776816049067}
{"topic":"orderbook.200.BTCUSDT","ts":1776816049169,"type":"delta","data":{"s":"BTCUSDT","b":[["76342","0.054086"],["76341.9","0.108172"],["76339.9","0.054086"],["76339.7","0.740782"],["76338.3","0.320212"],["76338.2","0.998117"],["76337.7","0.023639"],["76337.4","0.001"],["76336.5","0.005285"],["76333.1","0.005251"],["76332.2","0.123994"],["76332","0.036727"],["76331.3","0"],["76330.7","0"],["76330.6","0.0044"],["76330.5","0.126"],["76329.6","0"],["76327.9","0"],["76326.5","0.131965"],["76325.5","0"],["76201.6","0"],["76201","0"],["76200.5","0"],["76200.4","0"],["76200","0"]],"a":[["76338.3","0"],["76339.8","0"],["76340","0"],["76342","0"],["76343.4","0.022212"],["76345.9","0.0084"],["76346.2","0"],["76348.5","0"],["76348.8","0.001"],["76356","0"],["76356.5","0"],["76361.1","0"],["76361.6","0"],["76364.9","0.045581"],["76365","0"],["76370.2","0"],["76370.6","0"],["76373.9","0.056915"],["76374","0"],["76379.1","0.130981"],["76380.3","0.031456"],["76445","0.815025"],["76445.9","0.003961"],["76446.2","0.00282"],["76446.3","0.000356"],["76446.5","0.000108"],["76446.9","0.741692"],["76447.6","0.000423"],["76447.8","0.199322"],["76448","0.001811"],["76448.1","0.000402"],["76448.6","0.001252"],["76449.5","0.086451"],["76449.6","0.000016"]],"u":28058494,"seq":105954767074},"cts":1776816049168}
{"topic":"orderbook.200.BTCUSDT","ts":1776816049269,"type":"delta","data":{"s":"BTCUSDT","b":[["76342","1.262634"],["76341.9","0"],["76340.3","0.006546"],["76340.1","0.019637"],["76339.9","0.052297"],["76339.7","0.368038"],["76339.2","0.005306"],["76338.3","0"],["76338.2","0.05"],["76337.7","0"],["76337.6","0.050148"],["76337.5","0.026199"],["76337.4","0.001101"],["76336.5","0.11429"],["76334.4","0.0044"],["76333.4","0.08147"],["76333.1","0"],["76332.2","0"],["76332","0.031456"],["76330.6","0.068489"],["76330.1","0"],["76327.2","0.002428"],["76327","0"],["76313.9","0.006551"],["76311.8","0"],["76239.3","0.143347"],["76234.2","0"],["76201.6","0.006524"],["76201","0.006284"]],"a":[["76342.1","0.102688"],["76343.5","0"],["76345.3","0.011095"],["76345.9","0"],["76347.3","0.015481"],["76347.4","0.024432"],["76348.4","0"],["76348.6","0"],["76349.2","0.024432"],["76349.7","0.0084"],["76351.9","0.004929"],["76353.9","0.004588"],["76354.1","0"],["76354.5","0.017584"],["76354.6","0.025364"],["76355.1","0.00479"],["76355.7","0.003719"],["76358.1","0.006546"],["76361.5","0.023207"],["76361.8","0"],["76364.9","0"],["76365.2","0.010606"],["76365.8","0.006546"],["76369.8","0.130981"],["76370","0.031456"],["76370.1","0"],["76373.4","0"],["76373.9","0"],["76380.2","0.016103"],["76386.2","0.019637"],["76447.8","0"],["76448","0"],["76448.1","0"],["76448.6","0"],["76449.5","0"],["76449.6","0"]],"u":28058495,"seq":105954767498},"cts":1776816049267}
{"topic":"orderbook.200.BTCUSDT","ts":1776816049371,"type":"delta","data":{"s":"BTCUSDT","b":[["76342","1.266634"],["76340.3","0"],["76339.8","0.006546"],["76338.3","0.023638"],["76334.4","0.0084"],["76201","0"]],"a":[["76342.1","0.106331"],["76347.3","0"],["76347.4","0"],["76349.7","0.0104"],["76351.4","0.004588"],["76353.9","0"],["76365.1","0.006546"],["76365.8","0"],["76369.6","0.075016"],["76369.7","0.162437"],["76369.8","0"],["76370","0"],["76378.6","0.080352"],["76379","0.054152"],["76447.8","0.199322"]],"u":28058496,"seq":105954767582},"cts":1776816049368}
{"topic":"orderbook.200.BTCUSDT","ts":1776816049468,"type":"delta","data":{"s":"BTCUSDT","b":[["76342","1.268634"],["76340","0.006546"],["76339.8","0"],["76334.4","0.0104"]],"a":[["76342.1","0.173631"],["76342.5","0.024048"],["76354.5","0"],["76354.6","0"],["76355.1","0"],["76358.1","0"],["76358.2","0.006546"],["76379","0"],["76448","0.001811"],["76448.1","0.000402"],["76448.6","0.001252"]],"u":28058497,"seq":105954767620},"cts":1776816049467}
{"topic":"orderbook.200.BTCUSDT","ts":1776816049569,"type":"delta","data":{"s":"BTCUSDT","b":[["76342","1.298634"],["76340","0"],["76339.9","0.129064"],["76339.3","0.006546"]],"a":[["76342.1","0.123071"],["76345.7","0.024047"],["76347.6","0.017307"],["76347.7","0.030549"],["76349.8","0.004929"],["76351.8","0.025365"],["76351.9","0.00479"],["76369.4","0.319466"],["76369.6","0"],["76378.6","0.001"],["76447.6","0"],["76447.8","0"],["76448","0"],["76448.1","0"],["76448.6","0"]],"u":28058498,"seq":105954767686},"cts":1776816049567}
{"topic":"orderbook.200.BTCUSDT","ts":1776816049669,"type":"delta","data":{"s":"BTCUSDT","b":[["76342","1.293383"],["76339.4","0.00525"],["76339.3","0"],["76339.2","0"],["76338.4","0.006546"],["76334.6","0.005305"],["76333.4","0.0502"],["76311.1","0.24732"],["76264.8","0.031456"],["76201.6","0"]],"a":[["76342.1","0.187281"],["76349.1","0.004588"],["76351.4","0"],["76379.1","0.338446"]],"u":28058499,"seq":105954767737},"cts":1776816049666}
{"topic":"orderbook.200.BTCUSDT","ts":1776816049769,"type":"delta","data":{"s":"BTCUSDT","b":[["76342","1.293571"]],"a":[["76342.1","0.174369"],["76343.6","0.026388"],["76347.6","0"],["76349.2","0"],["76447.6","0.000423"]],"u":28058500,"seq":105954767755},"cts":1776816049768}
{"topic":"orderbook.200.BTCUSDT","ts":1776816049869,"type":"delta","data":{"s":"BTCUSDT","b":[["76329.3","0"],["76201.6","0.006524"]],"a":[["76342.1","0.115619"]],"u":28058501,"seq":105954767792},"cts":1776816049865}
{"topic":"orderbook.200.BTCUSDT","ts":1776816049969,"type":"delta","data":{"s":"BTCUSDT","b":[["76342","1.296301"],["76338.5","0.006546"],["76338.4","0"]],"a":[["76342.1","0.119619"],["76356","0.006546"],["76358.2","0"]],"u":28058502,"seq":105954767897},"cts":1776816049963}
{"topic":"orderbook.200.BTCUSDT","ts":1776816050069,"type":"delta","data":{"s":"BTCUSDT","b":[["76342","1.304491"],["76338.5","0"],["76338.4","0.006546"]],"a":[["76342.1","0.106519"],["76342.5","0"],["76347.3","0.024432"]],"u":28058503,"seq":105954767967},"cts":1776816050064}
{"topic":"orderbook.200.BTCUSDT","ts":1776816050171,"type":"delta","data":{"s":"BTCUSDT","b":[["76342","1.305401"],["76339.5","0.006546"],["76338.4","0"]],"a":[["76342.1","0.173819"],["76342.8","0.024048"],["76343.6","0"],["76347.2","0.018677"],["76356","0"],["76358.2","0.006546"],["76447.6","0"]],"u":28058504,"seq":105954768001},"cts":1776816050169}
{"topic":"orderbook.200.BTCUSDT","ts":1776816050269,"type":"delta","data":{"s":"BTCUSDT","b":[["76342","1.301761"]],"a":[["76342.1","0.130567"],["76347.2","0"],["76347.3","0"],["76447.6","0.000423"],["76447.8","0.199322"]],"u":28058505,"seq":105954768032},"cts":1776816050267}
{"topic":"orderbook.200.BTCUSDT","ts":1776816050369,"type":"delta","data":{"s":"BTCUSDT","b":[["76342","1.305401"]],"a":[],"u":28058506,"seq":105954768047},"cts":1776816050352}
{"topic":"orderbook.200.BTCUSDT","ts":1776816050469,"type":"delta","data":{"s":"BTCUSDT","b":[["76342","1.299941"],["76339.5","0"],["76338.4","0.006546"]],"a":[["76342.1","0.197867"]],"u":28058507,"seq":105954768081},"cts":1776816050462}
{"topic":"orderbook.200.BTCUSDT","ts":1776816050569,"type":"delta","data":{"s":"BTCUSDT","b":[["76342","1.296301"],["76339.5","0.006546"],["76338.4","0"]],"a":[],"u":28058508,"seq":105954768120},"cts":1776816050567}
{"topic":"orderbook.200.BTCUSDT","ts":1776816050669,"type":"delta","data":{"s":"BTCUSDT","b":[["76342","1.28921"],["76239.3","0.195497"]],"a":[["76342.1","0.184767"],["76369.3","0.193787"],["76447.8","0"]],"u":28058509,"seq":105954768176},"cts":1776816050664}
{"topic":"orderbook.200.BTCUSDT","ts":1776816050769,"type":"delta","data":{"s":"BTCUSDT","b":[["76342","1.225384"],["76339.9","0.063855"],["76339.7","0.149638"],["76339.5","0"],["76338.4","0.006546"],["76338.1","0.005269"],["76332","0"],["76326.5","0.000984"]],"a":[["76342.1","0.373207"],["76357.4","0.063047"],["76357.5","0.126"],["76358.2","0"],["76359.8","0"]],"u":28058510,"seq":105954768255},"cts":1776816050768}
{"topic":"orderbook.200.BTCUSDT","ts":1776816050869,"type":"delta","data":{"s":"BTCUSDT","b":[["76342","1.020884"],["76339.9","0.032558"],["76339.7","0.023638"],["76338.4","0"],["76338.2","0.056546"],["76333.4","0.035078"],["76201","0.006284"]],"a":[["76342.7","0.024298"],["76365.1","0.006547"],["76447.6","0"]],"u":28058511,"seq":105954768322},"cts":1776816050867}
{"topic":"orderbook.200.BTCUSDT","ts":1776816050971,"type":"delta","data":{"s":"BTCUSDT","b":[["76214.3","0.032507"],["76201","0"]],"a":[["76363.1","0.006547"],["76365.1","0"]],"u":28058512,"seq":105954768346},"cts":1776816050969}
{"topic":"orderbook.200.BTCUSDT","ts":1776816051069,"type":"delta","data":{"s":"BTCUSDT","b":[["76342","1.026118"],["76338.2","0.05"],["76337.6","0.056694"]],"a":[["76342.1","0.197867"]],"u":28058513,"seq":105954768392},"cts":1776816051068}
{"topic":"orderbook.200.BTCUSDT","ts":1776816051169,"type":"delta","data":{"s":"BTCUSDT","b":[["76342","1.025979"],["76337.7","0.006546"],["76337.6","0.050148"],["76201.6","0"]],"a":[],"u":28058514,"seq":105954768415},"cts":1776816051160}
{"topic":"orderbook.200.BTCUSDT","ts":1776816051269,"type":"delta","data":{"s":"BTCUSDT","b":[["76336.8","0.010445"],["76204.8","0"]],"a":[["76342.1","0.210965"]],"u":28058515,"seq":105954768430},"cts":1776816051251}
{"topic":"orderbook.200.BTCUSDT","ts":1776816051369,"type":"delta","data":{"s":"BTCUSDT","b":[["76342","0.933381"]],"a":[],"u":28058516,"seq":105954768443},"cts":1776816051367}
{"topic":"orderbook.200.BTCUSDT","ts":1776816051469,"type":"delta","data":{"s":"BTCUSDT","b":[["76342","0.930745"],["76338.2","0.056546"],["76337.7","0"],["76204.8","0.130981"]],"a":[["76342.1","0.225885"]],"u":28058517,"seq":105954768476},"cts":1776816051464}
{"topic":"orderbook.200.BTCUSDT","ts":1776816051568,"type":"delta","data":{"s":"BTCUSDT","b":[["76338.2","0.05"],["76337.7","0.006546"],["76204.8","0"]],"a":[],"u":28058518,"seq":105954768491},"cts":1776816051556}
{"topic":"orderbook.200.BTCUSDT","ts":1776816051669,"type":"delta","data":{"s":"BTCUSDT","b":[["76342","0.436383"],["76340.1","0"],["76339.7","0"],["76339.6","0.025573"],["76339.4","0"],["76338","0.005278"],["76337.7","0"],["76336.8","0.015689"],["76332","0.006546"],["76331.6","0.075262"],["76324.4","0"],["76324.3","0.031456"],["76318.8","0.047294"],["76318.7","0"],["76318.5","0"],["76317.5","0.130981"],["76315.6","0.031456"],["76239.3","0.307125"],["76204.8","0.130981"]],"a":[["76342.1","0.607759"],["76345.1","0.004929"],["76346.8","0.004588"],["76348.4","0.00479"],["76349.1","0"],["76349.8","0.126"],["76351.1","0.00374"],["76351.9","0"],["76355.7","0"],["76358.2","0.006547"],["76362","0.031456"],["76363.1","0"],["76363.5","0.130981"],["76365.6","0.031456"],["76375.9","0.014489"],["76445.9","0"],["76446.2","0"],["76446.3","0"],["76446.5","0"],["76446.9","0"]],"u":28058519,"seq":105954768680},"cts":1776816051668}
{"topic":"orderbook.200.BTCUSDT","ts":1776816051771,"type":"delta","data":{"s":"BTCUSDT","b":[["76342","0"],["76339.9","0"],["76339.6","0"],["76338.3","0"],["76338.2","0"],["76338.1","0"],["76338","0"],["76337.6","0"],["76337.5","0"],["76337.4","0"],["76336.8","0"],["76336.5","0"],["76336.3","0.239284"],["76335.6","0.017954"],["76334.6","0"],["76334.4","0"],["76333.8","0"],["76333.4","0.035179"],["76332","0"],["76331.9","0"],["76331.6","0.05"],["76331.4","0.019637"],["76330.6","0.034905"],["76330.5","0"],["76330.3","0.025576"],["76330","0"],["76329","0.01838"],["76328.9","0.026626"],["76328.7","0.0104"],["76327.4","0.025104"],["76327.1","0.065514"],["76327","0.010508"],["76325.2","0.065516"],["76324.3","0"],["76324.2","0"],["76323.2","0.005299"],["76321.4","0.025265"],["76317.5","0"],["76315.6","0"],["76314.7","0.396886"],["76312.9","0.031456"],["76311.3","0.130981"],["76311.2","0"],["76309.7","0"],["76300.2","0.391274"],["76201.6","0.006524"],["76201","0.006284"],["76200.5","0.008995"],["76200.4","0.006521"],["76200","0.007145"],["76199.6","0.17438"],["76198.7","0.6"],["76198.5","0.000984"],["76198.1","0.082685"]],"a":[["76336.4","1.195528"],["76337.5","0.034981"],["76337.7","0.026766"],["76338.2","0.00479"],["76339.1","0.025843"],["76339.2","0.01917"],["76340.6","0.001"],["76342","0.063986"],["76342.1","0.145496"],["76342.5","0.00374"],["76342.7","0"],["76344","0.0104"],["76345.1","0"],["76345.7","0"],["76345.8","0.000099"],["76345.9","0.042057"],["76346","0.106344"],["76346.8","0"],["76347.7","0"],["76348.4","0"],["76349.7","0.046328"],["76349.9","0"],["76350","0"],["76351.1","0"],["76351.8","0"],["76352.6","0.013095"],["76353.3","0.006548"],["76354.5","0.065474"],["76356.4","0.065473"],["76357.2","0.111535"],["76357.3","0.162437"],["76357.4","0"],["76358.2","0"],["76358.3","0"],["76359.8","0.048439"],["76360.2","0"],["76362.1","0"],["76376.5","0.396313"],["76376.9","0.019637"],["76386.2","0"],["76386.8","0"],["76391","0.199936"],["76401.3","0"],["76444.6","0"],["76444.7","0"],["76444.8","0"],["76444.9","0"],["76445","0"]],"u":28058520,"seq":105954769445},"cts":1776816051770}
{"topic":"orderbook.200.BTCUSDT","ts":1776816051869,"type":"delta","data":{"s":"BTCUSDT","b":[["76333.4","0.021485"],["76330.6","0.050651"],["76330.5","0.025576"],["76330.3","0"],["76327.6","0.006547"],["76327.4","0"],["76326.4","0.034235"],["76321.5","0.818439"],["76311.1","0.140644"]],"a":[["76336.4","1.200078"],["76337.7","0.028586"],["76342.1","0.137306"],["76345.3","0.011"],["76353.2","0.006548"],["76353.3","0"],["76354.4","0.04799"],["76365.2","0"],["76385.6","0.000984"]],"u":28058521,"seq":105954769602},"cts":1776816051862}
{"topic":"orderbook.200.BTCUSDT","ts":1776816051969,"type":"delta","data":{"s":"BTCUSDT","b":[["76336.3","0.243216"],["76332","0.026201"],["76327.6","0"],["76326.4","0.065895"],["76323.5","0.112602"],["76322.9","0.25498"],["76198.1","0"]],"a":[["76336.4","1.151338"],["76337.7","0.026766"],["76342.1","0.135486"],["76353.2","0"],["76353.3","0.006548"],["76392","0.004462"],["76444","0"]],"u":28058522,"seq":105954769659},"cts":1776816051966}
{"topic":"orderbook.200.BTCUSDT","ts":1776816052069,"type":"delta","data":{"s":"BTCUSDT","b":[["76334.5","0.025575"],["76333.5","0.032781"],["76333.4","0.025676"],["76328.3","0.006547"],["76321.5","0.048439"],["76321.4","0"],["76198.7","0"],["76198.5","0"]],"a":[["76336.4","1.120049"],["76337.5","0.023154"],["76338.8","0.004929"],["76375.8","0.03244"],["76443.9","0"]],"u":28058523,"seq":105954769720},"cts":1776816052063}
{"topic":"orderbook.200.BTCUSDT","ts":1776816052169,"type":"delta","data":{"s":"BTCUSDT","b":[["76336.3","0.243116"],["76329.7","0.005244"],["76327","0.005264"],["76324.9","0.010377"],["76322.9","0.022414"],["76200","0"],["76199.6","0"]],"a":[["76336.4","1.077865"],["76339.2","0.023758"],["76354.6","0.010634"],["76443.5","0"]],"u":28058524,"seq":105954769759},"cts":1776816052164}
{"topic":"orderbook.200.BTCUSDT","ts":1776816052269,"type":"delta","data":{"s":"BTCUSDT","b":[],"a":[["76338.2","0"],["76341.6","0.00479"]],"u":28058525,"seq":105954769773},"cts":1776816052256}
{"topic":"orderbook.200.BTCUSDT","ts":1776816052369,"type":"delta","data":{"s":"BTCUSDT","b":[["76336.3","0.251008"],["76335.2","0.025575"],["76334.6","0.049215"],["76334.5","0"],["76333.5","0"],["76332.5","0.005244"],["76332.2","0.005278"],["76331.2","0.005264"],["76329.7","0"],["76329","0.013102"],["76328.3","0"],["76327.5","0.006547"],["76327.4","0.005299"],["76327","0"],["76323.2","0"],["76200.4","0"]],"a":[["76336.4","1.103289"],["76338.8","0"],["76339.2","0.01917"],["76341.9","0.004929"],["76342.1","0.140074"],["76342.5","0"],["76347.9","0.00374"]],"u":28058526,"seq":105954769825},"cts":1776816052367}
{"topic":"orderbook.200.BTCUSDT","ts":1776816052571,"type":"delta","data":{"s":"BTCUSDT","b":[],"a":[["76345.2","0.006547"],["76443.2","0"]],"u":28058527,"seq":105954769860},"cts":1776816052556}
{"topic":"orderbook.200.BTCUSDT","ts":1776816052668,"type":"delta","data":{"s":"BTCUSDT","b":[["76336.3","0.251108"],["76330.5","0"],["76314.8","0.153439"],["76314.2","0"],["76239.3","0"],["76214.3","0.068904"],["76200.4","0.006521"],["76200","0.007145"]],"a":[["76352.5","0.006548"],["76353.3","0"],["76354.6","0"],["76361.5","0.049184"],["76385.6","0.091024"],["76443.2","0.00032"]],"u":28058528,"seq":105954769894},"cts":1776816052667}
{"topic":"orderbook.200.BTCUSDT","ts":1776816052769,"type":"delta","data":{"s":"BTCUSDT","b":[["76336.3","0.251185"],["76336.2","0.025574"],["76200","0"]],"a":[["76336.4","1.103366"],["76352.5","0"],["76353.3","0.006548"]],"u":28058529,"seq":105954769917},"cts":1776816052764}
{"topic":"orderbook.200.BTCUSDT","ts":1776816052869,"type":"delta","data":{"s":"BTCUSDT","b":[],"a":[["76352.4","0.006547"],["76353.3","0"]],"u":28058530,"seq":105954769943},"cts":1776816052865}
{"topic":"orderbook.200.BTCUSDT","ts":1776816052969,"type":"delta","data":{"s":"BTCUSDT","b":[["76336.3","0.251085"]],"a":[["76352.4","0"],["76353.3","0.006547"]],"u":28058531,"seq":105954769963},"cts":1776816052963}
{"topic":"orderbook.200.BTCUSDT","ts":1776816053068,"type":"delta","data":{"s":"BTCUSDT","b":[["76317.4","0.031456"],["76200.4","0"]],"a":[["76339.2","0"],["76392","0"],["76443.5","0.000094"],["76443.9","0.000074"]],"u":28058532,"seq":105954769989},"cts":1776816053067}
{"topic":"orderbook.200.BTCUSDT","ts":1776816053269,"type":"delta","data":{"s":"BTCUSDT","b":[["76328.3","0.006547"],["76327.5","0"]],"a":[["76336.4","1.067931"]],"u":28058533,"seq":105954770021},"cts":1776816053267}
{"topic":"orderbook.200.BTCUSDT","ts":1776816053371,"type":"delta","data":{"s":"BTCUSDT","b":[["76328.3","0"],["76327.5","0.006547"]],"a":[],"u":28058534,"seq":105954770039},"cts":1776816053369}
{"topic":"orderbook.200.BTCUSDT","ts":1776816053469,"type":"delta","data":{"s":"BTCUSDT","b":[["76336.3","0.833313"],["76335.3","0.005274"],["76332.3","0.006547"],["76332.2","0"],["76330.6","0.1051"],["76328.7","0.0172"],["76328.6","0.126"],["76327.9","0.119521"],["76327.5","0"],["76326.5","0.03244"],["76326.4","0.034235"],["76323.5","0"],["76318.8","0.080346"],["76317.5","0.130981"],["76201","0"],["76200.5","0"]],"a":[["76336.4","0.439154"],["76337","0.024935"],["76337.5","0"],["76337.7","0"],["76341.6","0"],["76342.1","0.110074"],["76342.8","0"],["76344","0.0172"],["76345.2","0"],["76345.7","0.028215"],["76349.6","0.006547"],["76353.3","0"],["76357.1","0.006547"],["76357.2","0"],["76357.3","0"],["76361.5","0"],["76362","0"],["76363.5","0"],["76365.6","0"],["76369.2","0.130981"],["76369.7","0.031456"],["76444","0.001124"],["76444.6","0.000099"],["76444.7","0.000984"],["76444.8","0.000102"],["76444.9","0.495642"],["76445","0.815025"],["76445.9","0.003961"]],"u":28058535,"seq":105954770191},"cts":1776816053449}
{"topic":"orderbook.200.BTCUSDT","ts":1776816053569,"type":"delta","data":{"s":"BTCUSDT","b":[["76336.3","0.838553"],["76332.5","0"],["76332.3","0"],["76332.1","0.006546"],["76201","0.006284"]],"a":[["76336.4","0.324341"],["76337","0"],["76341.9","0"],["76344.4","0.004929"],["76349.6","0"],["76352.5","0.006546"],["76357.1","0"],["76359.7","0.006547"],["76366.5","0.031456"]],"u":28058536,"seq":105954770276},"cts":1776816053566}
{"topic":"orderbook.200.BTCUSDT","ts":1776816053669,"type":"delta","data":{"s":"BTCUSDT","b":[["76336.3","0.833313"],["76333.9","0.005237"],["76332.8","0.006546"],["76332.1","0"],["76303.5","0.150321"],["76239.3","0.535671"],["76201.6","0"],["76201","0"]],"a":[["76336.4","0.378441"],["76357.4","0.054054"],["76445.9","0"]],"u":28058537,"seq":105954770324},"cts":1776816053667}
{"topic":"orderbook.200.BTCUSDT","ts":1776816053769,"type":"delta","data":{"s":"BTCUSDT","b":[["76333.5","0.006546"],["76332.8","0"]],"a":[["76336.4","0.324341"]],"u":28058538,"seq":105954770357},"cts":1776816053766}
{"topic":"orderbook.200.BTCUSDT","ts":1776816053869,"type":"delta","data":{"s":"BTCUSDT","b":[["76336.3","0.842518"],["76335.5","0.005257"],["76334.7","0.006546"],["76334.6","0.072788"],["76333.9","0"],["76333.5","0"],["76332","0.150566"],["76331.6","0.055292"],["76331.2","0"],["76330.6","0.076496"],["76327.9","0"],["76327.4","0"],["76304.6","0.03"],["76201.6","0.006524"],["76201","0.006284"]],"a":[["76336.4","0.072695"],["76337.4","0.031773"],["76342.1","0.105486"],["76344.4","0"],["76345.1","0.004588"],["76347.9","0"],["76349.7","0"],["76349.8","0"],["76352.4","0.00376"],["76445.9","0.003961"]],"u":28058539,"seq":105954770481},"cts":1776816053865}
{"topic":"orderbook.200.BTCUSDT","ts":1776816053969,"type":"delta","data":{"s":"BTCUSDT","b":[["76334.7","0"],["76333.7","0.006546"]],"a":[["76336.4","0.047759"],["76337.4","0"],["76337.5","0.024935"],["76346.7","0.004929"],["76414.8","0.086434"],["76427.4","0"],["76445.9","0"]],"u":28058540,"seq":105954770588},"cts":1776816053967}
{"topic":"orderbook.200.BTCUSDT","ts":1776816054069,"type":"delta","data":{"s":"BTCUSDT","b":[["76334.7","0.006546"],["76333.7","0"]],"a":[["76352.3","0.006546"],["76352.5","0"]],"u":28058541,"seq":105954770671},"cts":1776816054067}
{"topic":"orderbook.200.BTCUSDT","ts":1776816054172,"type":"delta","data":{"s":"BTCUSDT","b":[["76201.6","0"],["76200.5","0.008995"]],"a":[["76336.4","0.088309"]],"u":28058542,"seq":105954770769},"cts":1776816054170}
{"topic":"orderbook.200.BTCUSDT","ts":1776816054269,"type":"delta","data":{"s":"BTCUSDT","b":[["76335.7","0.0175"],["76335.6","0"],["76238.5","0"],["76200","0.007145"],["76199.6","0.17438"]],"a":[["76344.6","0.004929"],["76346.7","0"]],"u":28058543,"seq":105954770852},"cts":1776816054260}
{"topic":"orderbook.200.BTCUSDT","ts":1776816054369,"type":"delta","data":{"s":"BTCUSDT","b":[],"a":[["76336.4","0.034109"],["76336.8","0.024935"],["76337.5","0"]],"u":28058544,"seq":105954770924},"cts":1776816054364}
{"topic":"orderbook.200.BTCUSDT","ts":1776816054469,"type":"delta","data":{"s":"BTCUSDT","b":[["76335.4","0.006546"],["76334.7","0"],["76324.9","0"],["76198.7","0.6"]],"a":[["76336.4","0.088309"],["76352.3","0"],["76352.5","0.006546"],["76359.7","0"],["76359.9","0.010682"],["76360.9","0.006547"],["76445","0"]],"u":28058545,"seq":105954771001},"cts":1776816054458}
{"topic":"orderbook.200.BTCUSDT","ts":1776816054569,"type":"delta","data":{"s":"BTCUSDT","b":[],"a":[["76336.4","0.034109"],["76352.3","0.006546"],["76352.5","0"]],"u":28058546,"seq":105954771057},"cts":1776816054566}
{"topic":"orderbook.200.BTCUSDT","ts":1776816054669,"type":"delta","data":{"s":"BTCUSDT","b":[["76336.3","0.83855"],["76335.4","0"],["76334.7","0.006546"]],"a":[["76336.4","0.262009"],["76359.8","0.054986"],["76360.9","0"],["76445","0.815025"]],"u":28058547,"seq":105954771129},"cts":1776816054662}
{"topic":"orderbook.200.BTCUSDT","ts":1776816054769,"type":"delta","data":{"s":"BTCUSDT","b":[["76336.3","0.846438"],["76335.3","0.01182"],["76334.7","0"],["76198.5","0.000984"]],"a":[["76336.4","0.034109"],["76359.7","0.006547"],["76359.8","0.048439"],["76375.7","0.024172"],["76375.9","0"],["76445","0"]],"u":28058548,"seq":105954771211},"cts":1776816054766}
{"topic":"orderbook.200.BTCUSDT","ts":1776816054869,"type":"delta","data":{"s":"BTCUSDT","b":[["76308.7","0.096559"]],"a":[["76342","0"],["76359.7","0"],["76359.8","0.054986"],["76445","0.815025"],["76445.9","0.003961"]],"u":28058549,"seq":105954771305},"cts":1776816054867}
{"topic":"orderbook.200.BTCUSDT","ts":1776816054971,"type":"delta","data":{"s":"BTCUSDT","b":[["76335.5","0.015512"]],"a":[["76342","0.057828"],["76445.9","0"]],"u":28058550,"seq":105954771375},"cts":1776816054968}
{"topic":"orderbook.200.BTCUSDT","ts":1776816055069,"type":"delta","data":{"s":"BTCUSDT","b":[["76335.3","0.005274"],["76334.7","0.006546"],["76304.6","0"]],"a":[["76359.7","0.006547"],["76359.8","0.048439"],["76445","0"]],"u":28058551,"seq":105954771468},"cts":1776816055068}
{"topic":"orderbook.200.BTCUSDT","ts":1776816055169,"type":"delta","data":{"s":"BTCUSDT","b":[],"a":[["76338.6","0.024935"],["76444.9","0"]],"u":28058552,"seq":105954771516},"cts":1776816055160}
{"topic":"orderbook.200.BTCUSDT","ts":1776816055269,"type":"delta","data":{"s":"BTCUSDT","b":[["76335.8","0.016897"],["76335.7","0.000099"],["76334.8","0.006546"],["76334.7","0"],["76198.5","0"]],"a":[],"u":28058553,"seq":105954771593},"cts":1776816055267}
{"topic":"orderbook.200.BTCUSDT","ts":1776816055369,"type":"delta","data":{"s":"BTCUSDT","b":[["76342","0.422627"],["76341.6","0.006546"],["76341.5","0.005269"],["76340.5","0.024969"],["76339.9","0.005255"],["76339.1","0.023974"],["76339","0.127"],["76338.5","0.1773"],["76337.2","0.013102"],["76336.5","0.112845"],["76336.3","0.323786"],["76336.2","0"],["76336","0.00529"],["76335.9","0.026199"],["76335.8","0"],["76335.5","0.010255"],["76335.3","0.065514"],["76335.2","0"],["76334.8","0"],["76334.6","0"],["76334.4","0.0172"],["76333.4","0.065617"],["76333.3","0.033916"],["76332.1","0.031456"],["76332","0"],["76331.6","0.05"],["76329","0"],["76328.9","0"],["76328.7","0"],["76327.1","0"],["76325.2","0"],["76323","0.396886"],["76314.7","0"],["76310","0.03"],["76261.6","0.067201"],["76257.1","0"],["76252.3","0"],["76248.5","0"],["76245.4","0.00515"],["76241.9","0"],["76239.3","0"],["76225.7","0"],["76214.3","0"],["76198.5","0.000984"],["76198.1","0.082685"]],"a":[["76336.4","0"],["76336.8","0"],["76338.6","0"],["76339.1","0"],["76340.6","0"],["76342","0"],["76342.1","0.202986"],["76344","0"],["76344.6","0"],["76345.1","0"],["76345.7","0"],["76345.9","0"],["76346","0"],["76346.9","0.017612"],["76347","0.031773"],["76348","0.024227"],["76349.7","0.0172"],["76351","0.004588"],["76352.3","0"],["76352.4","0"],["76352.5","0.004929"],["76354.6","0.00479"],["76357","0.003766"],["76357.4","0.037641"],["76359.7","0"],["76359.8","0"],["76359.9","0"],["76360.8","0.006546"],["76366.5","0"],["76368.5","0.006547"],["76369.1","0.162437"],["76369.2","0"],["76369.7","0"],["76375.6","0.162437"],["76375.7","0"],["76375.8","0.000984"],["76379","0.031456"],["76379.1","0.207465"],["76380.3","0"],["76384","0"],["76444.9","0.495642"],["76445","0.815025"],["76445.9","0.003961"],["76446.2","0.00282"],["76446.3","0.000356"],["76446.5","0.000108"],["76446.9","0.741692"],["76447.6","0.000423"],["76447.8","0.199322"],["76448","0.001811"]],"u":28058554,"seq":105954772292},"cts":1776816055368}
{"topic":"orderbook.200.BTCUSDT","ts":1776816055469,"type":"delta","data":{"s":"BTCUSDT","b":[["76342","0.423464"],["76341.6","0"],["76340.6","0.006546"],["76339.1","0.076809"],["76338.5","0.05"],["76336.3","0.322949"],["76330.6","0"],["76328.7","0.038365"],["76326.4","0.129616"],["76323.1","0.031456"],["76314.8","0"]],"a":[["76342.1","0.152695"],["76346.9","0"],["76347","0"],["76360.8","0"],["76360.9","0.006546"],["76365.9","0.007531"],["76366","0.031456"],["76368.5","0"],["76380.2","0"],["76391.3","0"],["76414.8","0"],["76438.3","0.086434"],["76448.1","0.000402"],["76448.6","0.001252"],["76449.6","0.000016"],["76450","0.067061"]],"u":28058555,"seq":105954772446},"cts":1776816055466}
{"topic":"orderbook.200.BTCUSDT","ts":1776816055569,"type":"delta","data":{"s":"BTCUSDT","b":[],"a":[["76342.1","0.193795"],["76357.4","0.072332"],["76359.6","0.006546"],["76359.7","0.125794"],["76360.9","0"],["76365.8","0.006547"],["76365.9","0.000984"],["76384.6","0.105816"],["76422.6","0.086434"],["76448.1","0"],["76448.6","0"],["76449.6","0"],["76450","0"]],"u":28058556,"seq":105954772518},"cts":1776816055564}
{"topic":"orderbook.200.BTCUSDT","ts":1776816055669,"type":"delta","data":{"s":"BTCUSDT","b":[["76309.1","0"],["76197","0.126"]],"a":[["76342.1","0.139595"],["76352.5","0"],["76358.8","0.006546"],["76358.9","0.03"],["76359.6","0"],["76369.3","0"],["76369.4","0"],["76448.1","0.000402"],["76448.6","0.001252"]],"u":28058557,"seq":105954772596},"cts":1776816055668}
{"topic":"orderbook.200.BTCUSDT","ts":1776816055772,"type":"delta","data":{"s":"BTCUSDT","b":[["76342","0.423537"],["76340.6","0"],["76340","0.006546"],["76311.1","0"],["76196.2","0.145575"]],"a":[["76342.1","0.152768"],["76350.4","0.004509"],["76357.4","0.078878"],["76358.8","0"],["76363.8","0.010255"],["76376.4","0.341314"],["76379.1","0"],["76448.6","0"]],"u":28058558,"seq":105954772705},"cts":1776816055770}
{"topic":"orderbook.200.BTCUSDT","ts":1776816055869,"type":"delta","data":{"s":"BTCUSDT","b":[],"a":[["76357.3","0.006546"],["76357.4","0.072332"],["76374.2","0.323215"],["76448","0"],["76448.1","0"]],"u":28058559,"seq":105954772762},"cts":1776816055861}
{"topic":"orderbook.200.BTCUSDT","ts":1776816055969,"type":"delta","data":{"s":"BTCUSDT","b":[["76340","0"],["76338.6","0.006546"],["76337.3","0.000097"],["76333.5","0.04097"],["76333.4","0.065516"],["76333.3","0"],["76332.1","0"],["76315.3","0.331275"],["76196.2","0"]],"a":[["76342.1","0.177558"],["76350.3","0.024689"],["76352.5","0.060418"],["76354.3","0.054925"],["76354.4","0.077304"],["76355.2","0.103656"],["76356","0.006546"],["76357.3","0"],["76357.4","0.037641"],["76359.7","0"],["76363.7","0.006547"],["76365.8","0"],["76446.9","0"],["76447.6","0"],["76447.8","0"]],"u":28058560,"seq":105954772864},"cts":1776816055966}
{"topic":"orderbook.200.BTCUSDT","ts":1776816056069,"type":"delta","data":{"s":"BTCUSDT","b":[["76342","0.418302"],["76338.6","0"],["76337.4","0.006546"]],"a":[["76342.1","0.256688"],["76351.4","0.004701"],["76354.6","0"],["76363.1","0.006547"],["76363.7","0"]],"u":28058561,"seq":105954772904},"cts":1776816056068}
{"topic":"orderbook.200.BTCUSDT","ts":1776816056169,"type":"delta","data":{"s":"BTCUSDT","b":[["76342","0.324326"],["76339.4","0.005074"],["76339","0.001"],["76338.5","0.074969"],["76336.5","0.063004"],["76336.3","0.104549"],["76197","0"]],"a":[["76342.1","0.433848"],["76342.5","0.023912"],["76348.6","0.004683"],["76349.6","0.013191"],["76350.3","0"],["76351","0"],["76352.5","0"],["76354.3","0"],["76354.7","0.006546"],["76356","0"],["76358.9","0"],["76446.9","0.741692"],["76447.6","0.000423"]],"u":28058562,"seq":105954772966},"cts":1776816056166}
{"topic":"orderbook.200.BTCUSDT","ts":1776816056268,"type":"delta","data":{"s":"BTCUSDT","b":[["76340.6","0.040369"],["76339.1","0.023974"],["76198.1","0"]],"a":[["76342.1","0.452463"],["76343.4","0"],["76447.8","0.199322"]],"u":28058563,"seq":105954772990},"cts":1776816056267}
{"topic":"orderbook.200.BTCUSDT","ts":1776816056369,"type":"delta","data":{"s":"BTCUSDT","b":[["76342","0.325091"],["76337.4","0"],["76337.3","0.006643"],["76335.5","0"],["76310","0"],["76198.1","0.082685"],["76197","0.126"],["76196.2","0.145575"]],"a":[["76348.3","0.004509"],["76350.4","0"],["76354.4","0.08385"],["76354.7","0"],["76448","0.001811"]],"u":28058564,"seq":105954773035},"cts":1776816056359}
{"topic":"orderbook.200.BTCUSDT","ts":1776816056469,"type":"delta","data":{"s":"BTCUSDT","b":[["76337.4","0.006546"],["76337.3","0.000097"],["76196.2","0"]],"a":[["76354.3","0.006546"],["76354.4","0.077304"],["76448","0"]],"u":28058565,"seq":105954773056},"cts":1776816056460}
{"topic":"orderbook.200.BTCUSDT","ts":1776816056571,"type":"delta","data":{"s":"BTCUSDT","b":[["76333.1","0.010595"],["76197","0"]],"a":[["76354.3","0"],["76354.7","0.006546"]],"u":28058566,"seq":105954773099},"cts":1776816056563}
{"topic":"orderbook.200.BTCUSDT","ts":1776816056669,"type":"delta","data":{"s":"BTCUSDT","b":[["76342","0.27992"],["76341.5","0"],["76340.6","0.03013"],["76340.5","0"],["76340","0.024969"],["76339.9","0"],["76339.4","0"],["76339.1","0"],["76337.4","0"],["76336","0"],["76335.6","0.005083"],["76334.7","0.005446"],["76333.6","0.005069"],["76332.9","0.006546"],["76332.8","0.025753"],["76331","0.005249"],["76323.2","0.031456"],["76323.1","0"],["76318.8","0.047294"],["76317.5","0"],["76317.4","0"],["76315.6","0.162437"],["76312.9","0"],["76311.3","0"],["76309.8","0"],["76197","0.126"],["76196.2","0.145575"],["76195.6","0.130981"],["76195.1","0.008995"]],"a":[["76342.1","0.4641"],["76342.4","0.017589"],["76343.3","0.004509"],["76343.4","0.023912"],["76345.1","0.004701"],["76347.9","0.029311"],["76348.3","0"],["76348.6","0"],["76349.6","0.074948"],["76349.8","0.126"],["76351.2","0.107494"],["76351.4","0"],["76352.4","0.004303"],["76354.4","0.04799"],["76354.7","0"],["76355.2","0"],["76357","0"],["76360.9","0.006547"],["76363.1","0"],["76447.6","0"],["76447.8","0"]],"u":28058567,"seq":105954773342},"cts":1776816056665}
{"topic":"orderbook.200.BTCUSDT","ts":1776816056769,"type":"delta","data":{"s":"BTCUSDT","b":[["76340.6","0.055098"],["76333.2","0.006546"],["76332.9","0"],["76315.4","0.124464"],["76252.3","0.24828"],["76225.7","0.850623"],["76196.2","0"],["76195.6","0"],["76195.1","0"]],"a":[["76342.1","0.459417"],["76345.7","0.023911"],["76374.1","0.16083"],["76446.5","0"],["76446.9","0"]],"u":28058568,"seq":105954773382},"cts":1776816056768}
{"topic":"orderbook.200.BTCUSDT","ts":1776816056869,"type":"delta","data":{"s":"BTCUSDT","b":[["76333.6","0.011615"],["76333.2","0"],["76196.2","0.145575"]],"a":[["76343.3","0"],["76344.7","0.004683"]],"u":28058569,"seq":105954773397},"cts":1776816056848}
{"topic":"orderbook.200.BTCUSDT","ts":1776816056969,"type":"delta","data":{"s":"BTCUSDT","b":[["76342","0"],["76340.6","0"],["76340","0"],["76339","0"],["76338.5","0"],["76337.3","0"],["76337.2","0.030717"],["76336.5","0"],["76336.3","0.000984"],["76335.9","0"],["76335.6","0"],["76335.4","0.021347"],["76335.3","0"],["76334.7","0"],["76334.4","0"],["76333.7","0.000198"],["76333.6","0"],["76333.4","0"],["76333.1","0"],["76332.9","0.002"],["76332.8","0"],["76331.4","0"],["76331","0"],["76329.9","0.013102"],["76329.6","0.0152"],["76329.3","0.04"],["76328.7","0"],["76328.6","0"],["76328","0.065514"],["76326.9","0.005446"],["76326.5","0.000984"],["76326.4","0.134699"],["76326.1","0.065516"],["76325.8","0.005069"],["76323.2","0"],["76323","0"],["76322.4","0.019637"],["76321","0.005249"],["76315.7","0.428342"],["76315.6","0"],["76310.1","0.031456"],["76308.7","0"],["76306.9","0.130981"],["76302.8","0"],["76301.7","0"],["76300.9","0.031456"],["76300.3","0.130981"],["76299.9","0"],["76297.8","0.1058"],["76257","0.019637"],["76252.5","0.031456"],["76195.6","0.130981"],["76195.1","0.008995"],["76195","0.590244"],["76190.6","0.008995"],["76190.2","0.004749"],["76190.1","0.001584"],["76189","0.008995"],["76188.9","0.008995"]],"a":[["76337.3","1.327002"],["76337.4","0.469101"],["76338.5","0.203"],["76339.8","0.01917"],["76340.6","0.025627"],["76342","0.132812"],["76342.1","0.200851"],["76342.2","0.001"],["76342.4","0"],["76342.5","0"],["76343.4","0"],["76343.6","0.004303"],["76344.7","0"],["76344.9","0.0132"],["76345.1","0"],["76345.6","0.125418"],["76345.7","0"],["76345.9","0.015135"],["76346","0.03"],["76347.2","0.002"],["76347.9","0"],["76348","0"],["76348.2","0.002"],["76349.6","0.051536"],["76349.7","0"],["76351.2","0"],["76352.4","0"],["76354.3","0.031456"],["76354.4","0.082907"],["76356","0.006547"],["76356.3","0.130981"],["76359.6","0.048439"],["76360.9","0"],["76362.4","0.031456"],["76362.6","0.130981"],["76368.3","0.019637"],["76376.9","0"],["76394.4","0.019637"],["76440.2","0.00055"],["76444","0"],["76444.6","0"],["76444.7","0"],["76444.8","0"],["76444.9","0"],["76445","0"],["76445.9","0"],["76446.2","0"],["76446.3","0"]],"u":28058570,"seq":105954774095},"cts":1776816056968}
{"topic":"orderbook.200.BTCUSDT","ts":1776816057069,"type":"delta","data":{"s":"BTCUSDT","b":[["76337.2","0.2139"],["76335.4","0"],["76334.4","0.017665"],["76333.7","0"],["76333.5","0.016238"],["76332.9","0"],["76331.6","0.020198"],["76331.5","0.025971"],["76329.6","0.0132"],["76329.4","0.044713"],["76329.3","0.039992"],["76329.1","0.024972"],["76326.4","0.039318"],["76325.4","0.010482"],["76323.1","0.006547"],["76323","0.035575"],["76322.9","0.025756"],["76319.5","0.031456"],["76318.8","0.159718"],["76315.8","0.130981"],["76313.9","0"],["76300","0"],["76204.9","0.039098"],["76190.2","0"],["76190.1","0"],["76189","0"],["76188.9","0"]],"a":[["76337.3","1.331402"],["76337.4","0.078346"],["76338.5","0.023913"],["76339.4","0.004303"],["76339.8","0"],["76342.1","0.187201"],["76343.6","0"],["76344.9","0.0172"],["76345.9","0"],["76347.2","0"],["76348.2","0"],["76348.7","0.006548"],["76356","0"],["76444","0.001124"],["76444.6","0.000099"],["76444.7","0.000984"],["76444.8","0.000102"]],"u":28058571,"seq":105954774532},"cts":1776816057068}
{"topic":"orderbook.200.BTCUSDT","ts":1776816057169,"type":"delta","data":{"s":"BTCUSDT","b":[["76337.2","0.219484"],["76330.2","0.026201"],["76330","0.040476"],["76329.4","0"],["76329.3","0"],["76323.5","0.006547"],["76323.1","0"],["76322.3","0.116751"],["76190.6","0"]],"a":[["76337.3","1.343232"],["76348.7","0"],["76349.5","0.006548"]],"u":28058572,"seq":105954774668},"cts":1776816057165}
{"topic":"orderbook.200.BTCUSDT","ts":1776816057269,"type":"delta","data":{"s":"BTCUSDT","b":[["76334.4","0"],["76334.3","0.018497"],["76323","0.075267"],["76315.4","0"],["76315.3","0"],["76190.6","0.008995"],["76190.2","0.004749"]],"a":[["76337.3","1.345052"],["76348.8","0.007548"],["76349.5","0"],["76444.9","0.495642"]],"u":28058573,"seq":105954774815},"cts":1776816057268}
{"topic":"orderbook.200.BTCUSDT","ts":1776816057372,"type":"delta","data":{"s":"BTCUSDT","b":[["76337.2","0"],["76336.3","0"],["76335.7","0"],["76334.3","0"],["76333.8","0.23795"],["76333.5","0"],["76332.5","0.021005"],["76332.4","0.024198"],["76330.2","0"],["76329.6","0"],["76328.5","0.026202"],["76326.2","0.0132"],["76323.6","0.006547"],["76323.5","0"],["76319.6","0.031456"],["76319.5","0"],["76305.2","0.006551"],["76300.9","0.36708"],["76289.4","0"],["76282.2","0"],["76265.8","0"],["76261.4","0.687694"],["76190.1","0.001584"],["76189","0.008995"],["76188.9","0.008995"]],"a":[["76333.9","1.481024"],["76334","0.488676"],["76334.5","0.004509"],["76334.9","0.000899"],["76335.4","0.014377"],["76335.5","0.003594"],["76335.8","0.139182"],["76336.4","0.466272"],["76337.3","0.004701"],["76337.4","0.023914"],["76340.6","0"],["76341.4","0.042745"],["76341.5","0.0172"],["76341.6","0.126"],["76342","0.104048"],["76344.9","0"],["76346.2","0.000984"],["76348.7","0.006548"],["76348.8","0.001"],["76350.4","0.02865"],["76439.7","0"],["76442.7","0"],["76442.8","0"],["76442.9","0"],["76443.2","0"],["76443.5","0"],["76443.9","0"],["76444","0"],["76444.6","0"],["76444.7","0"],["76444.8","0"],["76444.9","0"]],"u":28058574,"seq":105954775320},"cts":1776816057365}
{"topic":"orderbook.200.BTCUSDT","ts":1776816057468,"type":"delta","data":{"s":"BTCUSDT","b":[["76333.1","0.021303"],["76333","0.024198"],["76332.5","0"],["76332.4","0"],["76323.6","0"],["76323.5","0.006547"],["76291.9","0.186944"],["76283","0.05365"],["76265.9","0"],["76188.7","0.126984"]],"a":[["76333.9","1.481934"],["76334","0.2027"],["76335.7","0.080683"],["76335.8","0"],["76336.4","0.299304"],["76342.1","0.167201"],["76348.7","0"],["76348.8","0.007548"],["76354.8","0"],["76437.1","0.123861"],["76442.7","0.014949"],["76442.8","0.000897"]],"u":28058575,"seq":105954775376},"cts":1776816057465}
{"topic":"orderbook.200.BTCUSDT","ts":1776816057569,"type":"delta","data":{"s":"BTCUSDT","b":[["76333.8","0.2467"],["76333.6","0.021303"],["76333.5","0.024198"],["76333.1","0"],["76333","0"],["76332","0.001"],["76282.2","0.743292"],["76274.9","0.743364"],["76189","0"],["76188.9","0"],["76188.7","0"]],"a":[["76333.9","1.427601"],["76334.5","0"],["76336.4","0.261708"],["76348.8","0.001"],["76349.5","0.006548"],["76363.8","0"],["76432.4","0.744214"],["76439.8","0.741761"]],"u":28058576,"seq":105954775453},"cts":1776816057567}
{"topic":"orderbook.200.BTCUSDT","ts":1776816057669,"type":"delta","data":{"s":"BTCUSDT","b":[["76328.2","0.005166"],["76325.8","0"],["76283","0.257807"],["76189","0.008995"]],"a":[["76333.9","1.435791"],["76335.7","0.086197"],["76336.7","0.004683"],["76337","0.004509"],["76339.4","0"],["76349.5","0"],["76350.3","0.006548"],["76374.2","0"],["76429.4","0.244488"]],"u":28058577,"seq":105954775496},"cts":1776816057664}
{"topic":"orderbook.200.BTCUSDT","ts":1776816057769,"type":"delta","data":{"s":"BTCUSDT","b":[["76333.8","0.246777"],["76330.1","0.005444"],["76326.9","0"],["76303.5","0.268548"],["76261.6","0.316921"],["76225.7","0.060965"]],"a":[["76333.9","1.468834"],["76343.9","0.00431"],["76349.7","0.006548"],["76350.3","0"],["76355","0.010276"],["76369","0.098426"],["76374.1","0"],["76442.7","0"],["76442.8","0"]],"u":28058578,"seq":105954775532},"cts":1776816057764}
{"topic":"orderbook.200.BTCUSDT","ts":1776816057869,"type":"delta","data":{"s":"BTCUSDT","b":[["76333.8","0.254474"],["76326.4","0.054198"],["76325.5","0.006547"],["76323.5","0"],["76323.1","0.031456"],["76189","0"]],"a":[["76337","0"],["76337.3","0"],["76339.2","0.004509"],["76340.9","0.004701"],["76349.7","0"],["76350.3","0.006548"],["76363.1","0.335401"],["76442.6","0"]],"u":28058579,"seq":105954775564},"cts":1776816057860}
{"topic":"orderbook.200.BTCUSDT","ts":1776816057969,"type":"delta","data":{"s":"BTCUSDT","b":[["76325.5","0.011794"],["76321","0"],["76189","0.008995"]],"a":[["76333.9","1.46188"],["76334","0"],["76336.7","0"],["76339.5","0.004683"],["76346","0"],["76442.6","0.031456"],["76442.7","0.014949"]],"u":28058580,"seq":105954775590},"cts":1776816057968}
{"topic":"orderbook.200.BTCUSDT","ts":1776816058069,"type":"delta","data":{"s":"BTCUSDT","b":[["76333.8","0.254574"],["76325.5","0.005247"],["76323.5","0.006547"],["76189","0"]],"a":[["76333.9","1.461867"],["76335.7","0.025091"],["76336.4","0.059008"]],"u":28058581,"seq":105954775641},"cts":1776816058060}
{"topic":"orderbook.200.BTCUSDT","ts":1776816058171,"type":"delta","data":{"s":"BTCUSDT","b":[["76325.6","0.006547"],["76323.5","0"]],"a":[],"u":28058582,"seq":105954775659},"cts":1776816058160}
{"topic":"orderbook.200.BTCUSDT","ts":1776816058269,"type":"delta","data":{"s":"BTCUSDT","b":[["76333.8","0.374574"],["76326.4","0.091472"],["76326.1","0.191516"],["76325.6","0"],["76325.5","0.011794"],["76189","0.008995"]],"a":[["76333.9","1.308158"],["76335.7","0.015797"],["76336.4","0.029008"],["76350.2","0.006548"],["76350.3","0"]],"u":28058583,"seq":105954775703},"cts":1776816058262}
{"topic":"orderbook.200.BTCUSDT","ts":1776816058369,"type":"delta","data":{"s":"BTCUSDT","b":[["76330.6","0.005067"],["76328.2","0.000099"],["76326.2","0.019747"],["76325.5","0.005247"],["76189","0"]],"a":[["76334.9","0"],["76335.4","0"],["76335.5","0"],["76350.2","0"],["76352.5","0.006547"],["76442.8","0.000897"],["76442.9","0.00041"],["76443.2","0.00032"]],"u":28058584,"seq":105954775739},"cts":1776816058365}
{"topic":"orderbook.200.BTCUSDT","ts":1776816058469,"type":"delta","data":{"s":"BTCUSDT","b":[["76326.2","0.0132"],["76325.6","0.006547"],["76190.1","0"]],"a":[],"u":28058585,"seq":105954775757},"cts":1776816058460}
{"topic":"orderbook.200.BTCUSDT","ts":1776816058569,"type":"delta","data":{"s":"BTCUSDT","b":[],"a":[["76343.8","0.006547"],["76350.3","0.006548"],["76352.5","0"],["76443.2","0"]],"u":28058586,"seq":105954775774},"cts":1776816058548}
{"topic":"orderbook.200.BTCUSDT","ts":1776816058669,"type":"delta","data":{"s":"BTCUSDT","b":[["76326.1","0.198063"],["76325.6","0"],["76190.1","0.001584"]],"a":[["76350.3","0"],["76352.5","0.006548"]],"u":28058587,"seq":105954775800},"cts":1776816058665}
{"topic":"orderbook.200.BTCUSDT","ts":1776816058769,"type":"delta","data":{"s":"BTCUSDT","b":[["76326.1","0.191516"],["76325.6","0.006547"],["76303.5","0.273698"],["76190.1","0"]],"a":[],"u":28058588,"seq":105954775816},"cts":1776816058751}
{"topic":"orderbook.200.BTCUSDT","ts":1776816058868,"type":"delta","data":{"s":"BTCUSDT","b":[["76333.8","0.284574"],["76307","0.088416"],["76306.5","0"],["76264.9","0.05061"],["76240.5","0.025802"],["76214.3","0.994254"],["76190.6","0"],["76190.2","0"]],"a":[["76350.3","0.006548"],["76352.5","0"],["76362.5","0.142879"],["76437.1","0.324505"],["76442.9","0"]],"u":28058589,"seq":105954775843},"cts":1776816058852}
{"topic":"orderbook.200.BTCUSDT","ts":1776816058971,"type":"delta","data":{"s":"BTCUSDT","b":[["76333.8","0.284474"]],"a":[],"u":28058590,"seq":105954775852},"cts":1776816058967}
{"topic":"orderbook.200.BTCUSDT","ts":1776816059069,"type":"delta","data":{"s":"BTCUSDT","b":[],"a":[["76350.2","0.006548"],["76350.3","0"]],"u":28058591,"seq":105954775874},"cts":1776816059056}
{"topic":"orderbook.200.BTCUSDT","ts":1776816059169,"type":"delta","data":{"s":"BTCUSDT","b":[["76333.8","0.284574"]],"a":[["76350.2","0"],["76352.5","0.006548"]],"u":28058592,"seq":105954775888},"cts":1776816059163}
{"topic":"orderbook.200.BTCUSDT","ts":1776816059368,"type":"delta","data":{"s":"BTCUSDT","b":[["76333.8","0.374574"]],"a":[],"u":28058593,"seq":105954775902},"cts":1776816059360}
{"topic":"orderbook.200.BTCUSDT","ts":1776816059469,"type":"delta","data":{"s":"BTCUSDT","b":[["76333.8","0.254474"]],"a":[],"u":28058594,"seq":105954775923},"cts":1776816059462}
{"topic":"orderbook.200.BTCUSDT","ts":1776816059569,"type":"delta","data":{"s":"BTCUSDT","b":[],"a":[["76333.9","1.309379"],["76350.3","0.006548"],["76352.5","0"]],"u":28058595,"seq":105954775939},"cts":1776816059563}
{"topic":"orderbook.200.BTCUSDT","ts":1776816059669,"type":"delta","data":{"s":"BTCUSDT","b":[["76333.8","0.396903"],["76326.1","0.198063"],["76325.6","0"],["76190.6","0.008995"]],"a":[["76333.9","1.132818"],["76338.4","0.016419"],["76341.4","0"],["76341.6","0"],["76350.3","0"],["76352.5","0.006548"],["76355","0"],["76442.9","0.00041"],["76443.2","0.00032"]],"u":28058596,"seq":105954775977},"cts":1776816059667}
{"topic":"orderbook.200.BTCUSDT","ts":1776816059771,"type":"delta","data":{"s":"BTCUSDT","b":[["76326.2","0.019747"],["76326.1","0.191516"]],"a":[["76413.3","0.086434"],["76422.6","0"]],"u":28058597,"seq":105954775986},"cts":1776816059766}
{"topic":"orderbook.200.BTCUSDT","ts":1776816059869,"type":"delta","data":{"s":"BTCUSDT","b":[["76326.2","0.0132"],["76325.6","0.006547"],["76298.7","0.071307"],["76245.4","0.094577"],["76223.7","0.227897"],["76214.3","0"],["76195","0"],["76190.6","0"]],"a":[["76365.9","0.016563"],["76411","0.06776"]],"u":28058598,"seq":105954776006},"cts":1776816059836}
{"topic":"orderbook.200.BTCUSDT","ts":1776816059968,"type":"delta","data":{"s":"BTCUSDT","b":[["76333.8","0.242827"]],"a":[["76333.9","1.308158"],["76350.3","0.006548"],["76352.5","0"]],"u":28058599,"seq":105954776039},"cts":1776816059967}
