{"topic":"orderbook.200.BTCUSDT","ts":1776816000869,"type":"snapshot","data":{"s":"BTCUSDT","b":[["76358.2","0.523407"],["76354.7","0.033132"],["76353.8","0.102995"],["76352.6","0.079088"],["76352.5","0.05"],["76351.9","0.026194"],["76350.8","0.006545"],["76350.7","0.038843"],["76350.6","0.0132"],["76350.5","0.126"],["76349.6","0.023689"],["76348.9","0.060707"],["76348.8","0.065488"],["76347.2","0.001178"],["76346.9","0.06551"],["76346.2","0.010099"],["76346.1","0.079288"],["76345.7","0.001"],["76345.6","0.001"],["76345.5","0.001"],["76344.1","0.031456"],["76344","0.057257"],["76343.9","0.05"],["76343.4","0.026144"],["76343.2","0.000099"],["76342.8","0.126"],["76340","0.015735"],["76339.7","0.033236"],["76339.6","0.026145"],["76339.4","0.011"],["76338.6","0.05"],["76337.4","0.031456"],["76335.9","0.157949"],["76335.8","0.130981"],["76335.7","0.396985"],["76335.4","0.001178"],["76334.1","0.034003"],["76334","0.031456"],["76333.2","0.051"],["76330.8","0.031456"],["76330.4","0.001"],["76330.3","0.086668"],["76330.2","0.105837"],["76329","0.001"],["76328.4","0.130981"],["76328.2","0.050099"],["76327.8","0.002428"],["76326.6","0.015447"],["76326.5","0.048439"],["76323.6","0.001178"],["76323.5","0.001"],["76323.4","0.001"],["76323","0.000131"],["76322.7","0.031456"],["76322.6","0.163087"],["76321.2","0.391274"],["76320.7","0.000099"],["76320","0.000432"],["76319.7","0.130981"],["76319.3","0.03564"],["76319.2","0.056481"],["76319.1","0.052"],["76317.7","0.031456"],["76315.8","0.126"],["76315","0.087359"],["76314.6","0.031456"],["76313.3","0.130981"],["76313.2","0.000099"],["76312.5","0.015735"],["76312.4","0.05"],["76311.8","0.049617"],["76311.5","0.031456"],["76307.7","0.315626"],["76306.9","0.130981"],["76306.7","0.397038"],["76305.7","0.000099"],["76304.8","0.031456"],["76304.7","0.126"],["76304","0.275862"],["76303.9","0.743081"],["76303.4","0.05"],["76301.2","0.000099"],["76300.7","0.130981"],["76300","0.001178"],["76298.5","0.024344"],["76298.4","0.05"],["76298.2","0.000099"],["76297.8","0.031456"],["76295.7","0.126"],["76294.9","0.284783"],["76294.8","0.74317"],["76294","0.031456"],["76293.8","0.048439"],["76292.7","0.130981"],["76290.7","0.000099"],["76288.6","0.031456"],["76288.2","0.001178"],["76286.9","0.049185"],["76286.8","0.024672"],["76285.8","0.001"],["76285.5","0.126"],["76285.1","0.013102"],["76284.6","0.031456"],["76283.7","0.326235"],["76283.6","0.945455"],["76283.2","0.000099"],["76283","0.003277"],["76282.8","0.130981"],["76282.1","0.013102"],["76281","0.033238"],["76280.9","0.031456"],["76278.1","0.048439"],["76277.5","0.031456"],["76277.1","0.162149"],["76277","0.126"],["76276.9","0.050064"],["76276.7","0.036936"],["76276.4","0.001178"],["76276.1","0.130981"],["76276","0.192558"],["76275.7","0.000656"],["76274.3","0.031456"],["76274.2","0.013103"],["76273.5","0.00515"],["76272.7","0.239702"],["76270.7","0.056566"],["76270.4","0.031456"],["76270.3","0.715001"],["76269.8","0.130981"],["76269.4","0.052898"],["76269.3","0.126"],["76269","0.048439"],["76268.2","0.000099"],["76267.5","0.002675"],["76264.7","0.001178"],["76263.4","0.000099"],["76262.7","0.024174"],["76262.6","0.080986"],["76262.2","0.090671"],["76261.6","0.013107"],["76261.2","0.031456"],["76260.7","0.127099"],["76259.1","0.130981"],["76256.8","0.033171"],["76256.7","0.086452"],["76254.2","0.031456"],["76253.8","0.03564"],["76253.2","0.000099"],["76253","0.126"],["76252.9","0.001178"],["76252.2","0.637801"],["76250.9","0.000854"],["76250.8","0.048439"],["76249.7","0.042135"],["76248.4","0.130981"],["76247.4","0.003168"],["76245.7","0.000099"],["76245.4","0.068147"],["76245.3","0.126"],["76245.1","0.00515"],["76245","0.079895"],["76242.9","0.062625"],["76242.3","0.004007"],["76241.8","0.12"],["76241.1","0.001178"],["76240.4","0.08644"],["76238.2","0.000099"],["76237.6","0.126"],["76236.9","0.130981"],["76234","0.120439"],["76233.9","0.048439"],["76231","0.00162"],["76230.7","0.000099"],["76229.4","0.12"],["76229.3","0.001178"],["76226.4","0.00162"],["76226.2","0.132601"],["76226.1","0.126"],["76226","0.001153"],["76225.7","0.765642"],["76225.6","6.604869"],["76223.6","0.714835"],["76223.2","0.000099"],["76223","0.048439"],["76222.7","0.0001"],["76218.4","0.001"],["76217.6","0.001178"],["76217.2","0.005349"],["76215.5","0.130981"],["76214.6","0.126"],["76214.2","6.180768"],["76208.9","0.025633"],["76208.4","0.065507"],["76208.3","0.648339"],["76205.8","0.001178"],["76205.2","0.126"],["76204.8","0.130981"],["76203.4","0.677626"],["76200","0.007145"],["76199.6","0.17438"]],"a":[["76358.3","0.706848"],["76361.6","0.013787"],["76361.7","0.03"],["76363.1","0.012913"],["76363.2","0.003274"],["76365.1","0.001"],["76365.9","0.0132"],["76367.6","0.037447"],["76368.1","0.110578"],["76368.3","0.002546"],["76368.6","0.001099"],["76369.9","0.006545"],["76370","0.000103"],["76370.6","0.01"],["76370.8","0.001178"],["76372.5","0.001"],["76372.7","0.018905"],["76372.8","0.045735"],["76374.8","0.02962"],["76375.1","0.000614"],["76375.3","0.001"],["76375.4","0.001"],["76375.5","0.001"],["76376.2","0.000099"],["76376.4","0.006545"],["76376.5","0.056035"],["76376.7","0.126"],["76377.9","0.03"],["76378.6","0.001"],["76379.9","0.001"],["76380","0.000103"],["76380.9","0.130981"],["76381.3","0.005462"],["76382.4","0.031456"],["76382.5","0.001178"],["76383.8","0.000099"],["76385.5","0.031456"],["76385.6","0.071926"],["76385.7","0.126"],["76387","0.000099"],["76387.1","0.130981"],["76388.1","0.041341"],["76388.2","0.105837"],["76389.4","0.031456"],["76390","0.000103"],["76390.5","0.001"],["76391.4","0.000099"],["76391.6","0.161622"],["76391.9","0.048439"],["76392.6","0.031456"],["76392.7","0.097927"],["76393.3","0.130981"],["76393.4","0.003825"],["76394.3","0.001178"],["76394.5","0.396313"],["76395","0.015735"],["76395.9","0.03768"],["76396","0.126"],["76399","0.00023"],["76399.5","0.162437"],["76399.6","0.197718"],["76399.7","0.5999"],["76400","0.001005"],["76400.5","0.00515"],["76401.2","0.013104"],["76403.7","0.065752"],["76403.8","0.126"],["76404.3","0.013102"],["76405","0.031456"],["76405.8","0.048439"],["76406.1","0.001178"],["76406.6","0.000099"],["76407.3","0.013102"],["76408.3","0.360379"],["76408.9","0.108199"],["76409","0.199936"],["76410","0.000103"],["76410.2","0.162437"],["76411.3","0.001"],["76413.3","0.04703"],["76413.4","0.126"],["76414","0.031456"],["76414.2","0.000099"],["76417.4","0.048839"],["76417.5","0.162437"],["76417.9","0.001178"],["76418.6","0.005094"],["76419.7","0.048439"],["76420","0.000103"],["76420.4","0.187164"],["76420.5","0.626916"],["76421.8","0.000099"],["76422.5","0.015735"],["76422.9","0.175777"],["76423","0.126"],["76423.5","0.3562"],["76424.8","0.00119"],["76424.9","0.000099"],["76426.2","0.08757"],["76426.3","0.12981"],["76426.7","0.031456"],["76428.3","0.00002"],["76428.6","0.130981"],["76428.7","0.001"],["76429.4","0.000099"],["76429.6","0.001178"],["76430","0.000103"],["76431.7","0.010144"],["76431.8","0.005216"],["76432.2","0.00017"],["76432.4","0.002381"],["76432.6","0.000142"],["76432.9","0.005112"],["76433.5","0.000215"],["76433.8","0.000332"],["76434","0.000411"],["76434.3","0.00011"],["76434.4","0.314468"],["76434.5","1.004092"],["76434.7","0.000092"],["76435","0.000078"],["76435.3","0.000411"],["76435.9","0.031599"],["76436","0.000328"],["76436.1","0.000574"],["76436.4","0.000133"],["76436.5","0.015482"],["76437","0.000099"],["76437.1","0.058913"],["76437.2","0.126"],["76437.3","0.000583"],["76437.5","0.002122"],["76437.9","0.00126"],["76438","0.000277"],["76438.1","0.000635"],["76439.3","0.130981"],["76440","0.000941"],["76440.2","0.00055"],["76440.7","0.048439"],["76440.8","0.074855"],["76440.9","0.086451"],["76441.4","0.001178"],["76441.5","0.130956"],["76441.6","0.000589"],["76442.2","0.00013"],["76442.5","0.000814"],["76442.7","0.014949"],["76442.8","0.000897"],["76442.9","0.00041"],["76443.2","0.00032"],["76443.5","0.000094"],["76443.9","0.000074"],["76444","0.001124"],["76444.2","0.031456"],["76444.6","0.000099"],["76444.8","0.000102"],["76444.9","0.246269"],["76445","0.815025"],["76445.9","0.003961"],["76446.2","0.00282"],["76446.3","0.000356"],["76446.5","0.000108"],["76447.6","0.000423"],["76447.8","0.000116"],["76448","0.001811"],["76448.1","0.000402"],["76448.6","0.001252"],["76449.5","0.086451"],["76449.6","0.000016"],["76450","0.067061"],["76450.5","0.031456"],["76450.6","0.232916"],["76450.7","0.629604"],["76450.9","0.000395"],["76451.2","0.000186"],["76451.3","0.130981"],["76451.6","0.000103"],["76452.2","0.017644"],["76452.4","0.741774"],["76452.7","0.00515"],["76453.1","0.000412"],["76453.2","0.001397"],["76453.3","0.038924"],["76453.4","0.126172"],["76453.6","0.000342"],["76454","0.000859"],["76454.3","0.0001"],["76454.4","0.001373"],["76454.7","0.0001"],["76455","0.000078"],["76455.2","0.00027"],["76455.4","0.000103"],["76456.2","0.016369"],["76456.6","0.000542"],["76456.7","0.031456"],["76456.8","0.402305"],["76456.9","1.206"],["76457","0.001759"],["76457.6","0.130981"],["76458","0.0001"]],"u":28058049,"seq":105954705558},"cts":1776816000866}
{"topic":"orderbook.200.BTCUSDT","ts":1776816000968,"type":"delta","data":{"s":"BTCUSDT","b":[["76358.2","0.573407"],["76351.8","0.025642"],["76351","0.006545"],["76350.8","0"],["76350.7","0.013201"],["76339.6","0"],["76330.2","0.115928"],["76307.7","0.204644"],["76258.1","1.74729"],["76251.5","1.747441"],["76200","0"],["76199.6","0"]],"a":[["76358.3","0.247653"],["76361.7","0"],["76376.4","0"],["76377.8","0.006545"],["76379.2","0.031456"],["76380.8","0.050499"],["76458","0"]],"u":28058050,"seq":105954705653},"cts":1776816000967}
{"topic":"orderbook.200.BTCUSDT","ts":1776816001069,"type":"delta","data":{"s":"BTCUSDT","b":[["76363","0.861962"],["76359.1","0.058802"],["76359","0.131257"],["76358.2","0.065735"],["76356","0.006544"],["76355.9","0.026193"],["76355.4","0.0132"],["76354.9","0.025641"],["76352.6","0.07889"],["76351.9","0"],["76351","0"],["76350.6","0"],["76346.2","0"],["76339.7","0.018209"],["76331.5","0.096955"],["76321.6","0.365306"],["76294.8","0"],["76258.2","0.547372"],["76256.8","0"],["76252.3","0.726709"],["76245.4","0.00515"],["76242.9","0"],["76225.7","0"],["76212.1","0.00464"],["76205.8","0"],["76205.2","0"],["76204.8","0"],["76203.4","0"]],"a":[["76358.3","0"],["76361.6","0"],["76363.1","0.040747"],["76365.9","0"],["76369.9","0"],["76370.6","0"],["76370.7","0.0132"],["76374.7","0.006545"],["76377.8","0"],["76379.2","0"],["76380.8","0"],["76380.9","0"],["76382","0.05931"],["76382.1","0.03766"],["76382.2","0.064959"],["76385.2","0.108964"],["76385.3","0.076503"],["76385.6","0"],["76408.2","0.108199"],["76408.3","0"],["76408.9","0"],["76437.1","0.085592"],["76452.3","0.262122"],["76452.4","0.000135"],["76453.3","0"],["76458","0.0001"],["76458.2","0.00041"],["76458.4","0.00041"],["76458.8","0.000198"]],"u":28058051,"seq":105954705991},"cts":1776816001062}
{"topic":"orderbook.200.BTCUSDT","ts":1776816001169,"type":"delta","data":{"s":"BTCUSDT","b":[["76363","0.625638"],["76356","0"],["76355.5","0.006544"],["76354.9","0"],["76354","0.025641"],["76334.1","0.058597"],["76294.9","0"],["76205.8","0.001178"]],"a":[["76363.1","0.044711"],["76367.2","0.092173"],["76367.3","0.114824"],["76367.5","0.079741"],["76367.6","0"],["76376.4","0.031456"],["76381.2","0.006545"],["76381.9","0.027475"],["76382","0"],["76382.1","0"],["76382.2","0"],["76385.3","0"],["76452.3","0"]],"u":28058052,"seq":105954706066},"cts":1776816001155}
{"topic":"orderbook.200.BTCUSDT","ts":1776816001269,"type":"delta","data":{"s":"BTCUSDT","b":[["76363","0.679738"],["76355.6","0.006544"],["76355.5","0"],["76322.6","0.254884"],["76301.3","0.743107"],["76295.8","0.100557"],["76208.3","0"],["76205.8","0"]],"a":[["76363.1","0.123721"],["76367","0.034096"],["76367.2","0"],["76367.3","0"],["76367.5","0"],["76374.7","0"],["76376.4","0"],["76381.9","0"],["76408.3","0.357539"],["76453.3","0.038625"],["76458.9","0.741809"],["76459.5","0.0061"],["76459.8","0.000107"]],"u":28058053,"seq":105954706190},"cts":1776816001265}
{"topic":"orderbook.200.BTCUSDT","ts":1776816001371,"type":"delta","data":{"s":"BTCUSDT","b":[["76360.8","0.019486"],["76355.6","0"],["76354.1","0.006544"],["76354","0"],["76353.2","0.026256"],["76351.8","0"],["76340.6","0.024186"],["76304","0.462411"],["76252.3","0"],["76211","0.002357"],["76208.4","0"]],"a":[["76363.1","0.11229"],["76379.8","0.006545"],["76380","0.05935"],["76381.2","0"],["76381.3","0.001"],["76382","0.048093"],["76382.1","0.062068"],["76382.3","0.066314"],["76385.1","0.052109"],["76408.2","0.201091"],["76443.8","0.024672"],["76456.8","0.571796"],["76458.4","0"],["76458.8","0"],["76458.9","0"],["76459.5","0"],["76459.8","0"]],"u":28058054,"seq":105954706272},"cts":1776816001362}
{"topic":"orderbook.200.BTCUSDT","ts":1776816001469,"type":"delta","data":{"s":"BTCUSDT","b":[["76354.1","0"],["76353.9","0.006544"],["76340.7","0.030125"],["76339.7","0"],["76330.2","0.105837"],["76252.3","0.384911"],["76208.9","0"]],"a":[["76363.1","0.11502"],["76377.6","0.010106"],["76382","0.028298"],["76382.3","0"],["76385.1","0"],["76408.2","0.108199"],["76408.3","0"],["76458.4","0.00041"],["76458.8","0.000198"]],"u":28058055,"seq":105954706354},"cts":1776816001464}
{"topic":"orderbook.200.BTCUSDT","ts":1776816001569,"type":"delta","data":{"s":"BTCUSDT","b":[["76354.8","0.006544"],["76353.9","0"],["76271.6","0.12"],["76211","0"]],"a":[["76363.1","0.11775"],["76394.2","0.015214"],["76394.3","0.358206"],["76458.8","0"]],"u":28058056,"seq":105954706400},"cts":1776816001561}
{"topic":"orderbook.200.BTCUSDT","ts":1776816001669,"type":"delta","data":{"s":"BTCUSDT","b":[["76334.1","0.034003"],["76331.5","0"],["76276","0"],["76229.4","0"],["76211","0.002357"],["76208.9","0.025633"],["76208.4","0.065507"]],"a":[["76363.1","0.129075"],["76366","0.011304"],["76368.6","0.012117"],["76370","0.01133"],["76377.6","0"],["76391.6","0.307119"],["76392.7","0"],["76393.2","0.015181"],["76394.2","0"],["76448.4","0.12"]],"u":28058057,"seq":105954706464},"cts":1776816001664}
{"topic":"orderbook.200.BTCUSDT","ts":1776816001768,"type":"delta","data":{"s":"BTCUSDT","b":[["76363","0.679857"],["76354.8","0"],["76353.9","0.006544"],["76353.2","0"],["76352.5","0.076256"],["76277.1","0.108582"],["76252.3","0.463072"],["76208.3","0.648339"]],"a":[["76363.1","0.129194"],["76382","0"],["76382.1","0"],["76458.8","0.000198"],["76458.9","0.741809"]],"u":28058058,"seq":105954706494},"cts":1776816001756}
{"topic":"orderbook.200.BTCUSDT","ts":1776816001869,"type":"delta","data":{"s":"BTCUSDT","b":[],"a":[["76392.5","0.015151"],["76393.2","0"]],"u":28058059,"seq":105954706508},"cts":1776816001866}
{"topic":"orderbook.200.BTCUSDT","ts":1776816001969,"type":"delta","data":{"s":"BTCUSDT","b":[["76363","0.099784"],["76360.6","0.058802"],["76360.5","0.131059"],["76359.1","0"],["76359","0.000198"],["76355.4","0.0064"],["76353.9","0"],["76352.7","0.010211"],["76352.5","0.05"],["76351.3","0.026256"],["76350.8","0.006544"],["76208.9","0"],["76208.4","0"],["76208.3","0"]],"a":[["76363.1","0.751722"],["76370.7","0.0064"],["76376.1","0.006545"],["76379.8","0"],["76380","0.000103"],["76381","0.010119"],["76458.9","0"]],"u":28058060,"seq":105954706799},"cts":1776816001967}
{"topic":"orderbook.200.BTCUSDT","ts":1776816002069,"type":"delta","data":{"s":"BTCUSDT","b":[["76363","0.045584"],["76360.9","0.001309"],["76358.2","0.035735"],["76351.3","0"],["76350.8","0"],["76349","0.006545"],["76347","0.023765"],["76344.1","0"],["76340.8","0.031456"],["76301.4","0.031456"],["76245","0.048439"],["76212.1","0"],["76211","0"]],"a":[["76363.1","0.768226"],["76365.8","0.011227"],["76365.9","0.011018"],["76366","0"],["76368.6","0.001099"],["76370","0.000103"],["76374.7","0.006546"],["76376.1","0"],["76377.9","0.078439"],["76379.3","0.031456"],["76458.4","0"],["76458.8","0"]],"u":28058061,"seq":105954707041},"cts":1776816002068}
{"topic":"orderbook.200.BTCUSDT","ts":1776816002171,"type":"delta","data":{"s":"BTCUSDT","b":[["76352.6","0.05843"],["76349.8","0.006545"],["76349.6","0"],["76349","0"],["76348.8","0.091745"],["76294","1.02642"],["76212.1","0.00464"]],"a":[["76363.1","0.779934"],["76365.9","0"],["76369.3","0.015735"],["76370.6","0.01"],["76372.8","0.03"],["76450.6","1.21194"],["76458.2","0"]],"u":28058062,"seq":105954707208},"cts":1776816002167}
{"topic":"orderbook.200.BTCUSDT","ts":1776816002268,"type":"delta","data":{"s":"BTCUSDT","b":[["76360.9","0"],["76360.8","0"],["76360.7","0.001309"],["76360.3","0.021967"],["76349.8","0"],["76349","0.006545"],["76332.3","0.006549"],["76295.8","0.384698"],["76212.1","0"]],"a":[["76374.7","0"],["76375","0.006546"],["76450.5","0.556323"],["76450.6","0.979434"]],"u":28058063,"seq":105954707365},"cts":1776816002264}
{"topic":"orderbook.200.BTCUSDT","ts":1776816002369,"type":"delta","data":{"s":"BTCUSDT","b":[["76360.7","0"],["76360.6","0.001309"],["76350.6","0.006545"],["76349","0"],["76267.5","0"],["76242.3","0"],["76217.2","0.005309"],["76212.1","0.00464"],["76211","0.002357"],["76208.9","0.025633"]],"a":[["76363.1","0.774474"],["76368.3","0"],["76375","0"],["76375.2","0.006546"],["76393.4","0"],["76418.6","0"],["76458.2","0.00041"],["76458.4","0.00041"],["76458.8","0.000198"]],"u":28058064,"seq":105954707467},"cts":1776816002366}
{"topic":"orderbook.200.BTCUSDT","ts":1776816002470,"type":"delta","data":{"s":"BTCUSDT","b":[["76363","0"],["76360.6","0"],["76360.5","0"],["76360.3","0"],["76359","0"],["76358.2","0"],["76355.9","0"],["76355.4","0"],["76354.7","0"],["76354.2","0.193535"],["76353.9","0.055558"],["76352.7","0"],["76352.6","0"],["76352.5","0.02"],["76351.9","0.026194"],["76350.6","0"],["76350.5","0"],["76348.8","0.065488"],["76348","0.0004"],["76347","0"],["76346.6","0.006"],["76345.4","0.015735"],["76343.4","0"],["76340.8","0"],["76340","0"],["76337.4","0"],["76335.3","0.024188"],["76334.1","0.017178"],["76334","0"],["76330.8","0"],["76330.4","0.032456"],["76328.5","0.130981"],["76328.4","0.00515"],["76325.8","0.031456"],["76285","0.015735"],["76267.5","0.002634"],["76242.3","0.003966"],["76208.4","0.065507"],["76208.3","0.648339"],["76205.8","0.001178"],["76205.2","0.126"],["76204.8","0.130981"],["76203.4","0.677626"],["76200","0.007145"],["76199.6","0.17438"]],"a":[["76354.3","0.989564"],["76354.7","0.004196"],["76355","0.011194"],["76356","0.03"],["76360.4","0.011124"],["76361","0.010994"],["76361.7","0.015735"],["76361.9","0.006"],["76363.1","0.100423"],["76363.4","0.0004"],["76364.1","0.112448"],["76365.8","0"],["76368.1","0"],["76368.2","0.006546"],["76368.3","0.002588"],["76368.4","0.126"],["76369.3","0"],["76370.7","0"],["76370.8","0.030748"],["76371.6","0.031456"],["76375.2","0"],["76376.2","0.031555"],["76380.6","0.052188"],["76380.7","0.130981"],["76418.6","0.005136"],["76443.8","0"],["76456.2","0"],["76456.6","0"],["76456.7","0"],["76456.8","0"],["76456.9","0"],["76457","0"],["76457.6","0"],["76458","0"],["76458.2","0"],["76458.4","0"],["76458.8","0"]],"u":28058065,"seq":105954708541},"cts":1776816002468}
{"topic":"orderbook.200.BTCUSDT","ts":1776816002569,"type":"delta","data":{"s":"BTCUSDT","b":[["76354.2","0.251919"],["76348","0"],["76346.6","0.0064"],["76345.3","0.026258"],["76344.4","0.026259"],["76344","0.063803"],["76335.3","0"],["76332.2","0.024189"],["76328.3","0.00515"],["76275.7","0.000099"],["76268.7","0.197629"],["76250.9","0"],["76226","0.001146"],["76200","0"],["76199.6","0"]],"a":[["76354.7","0"],["76356","0.03091"],["76357.4","0.011124"],["76360.4","0.019839"],["76361.9","0.0064"],["76362.9","0.075902"],["76363","0.045584"],["76363.1","0.091023"],["76363.4","0"],["76368.2","0"],["76369.9","0.006546"],["76370.7","0.018568"],["76374.8","0"],["76375.1","0"],["76393.4","0.003868"],["76400","0.000103"],["76424.8","0"]],"u":28058066,"seq":105954708697},"cts":1776816002568}
{"topic":"orderbook.200.BTCUSDT","ts":1776816002669,"type":"delta","data":{"s":"BTCUSDT","b":[["76354.2","0.267639"],["76353.9","0.040655"],["76351.9","0"],["76345.3","0"],["76344.5","0.006546"],["76344","0.057257"],["76339.4","0.039997"],["76277.1","0.35617"],["76275.7","0.00065"],["76273.9","0.849888"],["76269.4","0.105115"],["76252.3","0.078161"],["76250.9","0.000848"],["76203.4","0"]],"a":[["76354.3","0.992804"],["76356","0.03"],["76360.4","0"],["76371.6","0.041876"],["76375.1","0.000621"],["76381","0"],["76388.1","0.288489"],["76388.3","0.845675"],["76424.8","0.001196"],["76431.1","0.00515"],["76455.2","0"],["76455.4","0"]],"u":28058067,"seq":105954708788},"cts":1776816002668}
{"topic":"orderbook.200.BTCUSDT","ts":1776816002769,"type":"delta","data":{"s":"BTCUSDT","b":[["76354.2","0.251919"],["76345.8","0.006546"],["76345.7","0.027258"],["76344.5","0"],["76340.7","0.044691"],["76340.2","0.048439"],["76339.4","0.011"],["76335.9","0.189405"],["76204.8","0"]],"a":[["76354.3","0.997496"],["76356","0"],["76363.1","0.071023"],["76369.9","0"],["76370.5","0.006546"],["76400","0.001012"],["76439.8","0.024672"]],"u":28058068,"seq":105954708904},"cts":1776816002767}
{"topic":"orderbook.200.BTCUSDT","ts":1776816002869,"type":"delta","data":{"s":"BTCUSDT","b":[["76351.9","0.026194"],["76348.7","0.015735"],["76345.8","0"],["76345.6","0.007546"],["76345.4","0"]],"a":[["76354.3","0.9508"]],"u":28058069,"seq":105954708958},"cts":1776816002868}
{"topic":"orderbook.200.BTCUSDT","ts":1776816002971,"type":"delta","data":{"s":"BTCUSDT","b":[["76351.9","0"],["76345.7","0.001"],["76345.6","0.001"],["76345.3","0.026258"],["76344.5","0.006546"],["76340.6","0"],["76339.6","0.028997"],["76321.6","0"]],"a":[["76354.3","0.95353"],["76369.9","0.006546"],["76370.5","0"],["76394.3","0.001178"]],"u":28058070,"seq":105954709045},"cts":1776816002968}
{"topic":"orderbook.200.BTCUSDT","ts":1776816003069,"type":"delta","data":{"s":"BTCUSDT","b":[["76354.2","0.489352"],["76351.9","0.026194"],["76347.3","0.006546"],["76346.4","0.026258"],["76345.3","0"],["76344.5","0"],["76322.6","0.16669"],["76252.3","0.099748"],["76205.2","0"]],"a":[["76354.3","0.488252"],["76357.4","0"],["76360.3","0.011134"],["76369.9","0"],["76372.4","0.006546"],["76391.6","0.161622"]],"u":28058071,"seq":105954709154},"cts":1776816003066}
{"topic":"orderbook.200.BTCUSDT","ts":1776816003169,"type":"delta","data":{"s":"BTCUSDT","b":[["76354.2","0.492082"],["76348.9","0.067253"],["76347.3","0"],["76347.1","0.026258"],["76346.4","0"],["76345.9","0.010481"],["76332.2","0"],["76321.4","0.365513"]],"a":[["76354.3","0.257784"],["76368.3","0.034044"],["76370.6","0"],["76371.6","0.031456"],["76372.4","0"],["76375","0.006546"],["76388.3","1.210491"],["76455.2","0.00027"]],"u":28058072,"seq":105954709245},"cts":1776816003168}
{"topic":"orderbook.200.BTCUSDT","ts":1776816003269,"type":"delta","data":{"s":"BTCUSDT","b":[["76354.2","0.492992"],["76351.7","0.028083"],["76348.9","0.060707"],["76348.8","0.072033"],["76344.4","0"],["76322.6","0.254485"]],"a":[["76354.3","0.257126"],["76391.5","0.014977"],["76392.5","0"]],"u":28058073,"seq":105954709339},"cts":1776816003261}
{"topic":"orderbook.200.BTCUSDT","ts":1776816003369,"type":"delta","data":{"s":"BTCUSDT","b":[["76354.2","0.505072"],["76352","0.015735"],["76349","0.006545"],["76348.8","0.065488"],["76348.7","0"],["76205.8","0"]],"a":[["76355","0"],["76361.7","0"],["76365.4","0.015735"],["76443.1","0.12"]],"u":28058074,"seq":105954709391},"cts":1776816003368}
{"topic":"orderbook.200.BTCUSDT","ts":1776816003469,"type":"delta","data":{"s":"BTCUSDT","b":[["76361.4","0.391704"],["76359.8","0.276102"],["76359.7","0.0275"],["76359.2","0.255348"],["76359.1","0.2628"],["76357.1","0.004373"],["76354.9","0.01749"],["76354.8","0.126"],["76354.3","0.24609"],["76354.2","0.26412"],["76353.8","0.109395"],["76351.7","0"],["76350.8","0.006545"],["76350.7","0.041285"],["76349","0"],["76346.6","0"],["76345.7","0.024378"],["76332.3","0"],["76298.6","0.082001"],["76292.2","0.013101"],["76289.8","0.013101"],["76270.7","0"],["76261.6","0"],["76214.6","0"],["76214.2","0"],["76212.1","0"],["76211","0"],["76208.9","0"],["76208.4","0"],["76208.3","0"]],"a":[["76354.3","0"],["76360.3","0"],["76361","0"],["76361.5","0.468481"],["76361.8","0.126359"],["76361.9","0"],["76363.1","0.041023"],["76364.4","0.011204"],["76365.4","0"],["76368.3","0.002588"],["76368.4","0.011004"],["76369.1","0.0064"],["76371.9","0.011134"],["76375","0"],["76376.1","0.006546"],["76401.2","0"],["76404.3","0"],["76413","0.013101"],["76418","0.013101"],["76440.8","0.106917"]],"u":28058075,"seq":105954709858},"cts":1776816003467}
{"topic":"orderbook.200.BTCUSDT","ts":1776816003569,"type":"delta","data":{"s":"BTCUSDT","b":[["76361.4","0.204426"],["76359.8","0"],["76359.7","0"],["76359.2","0"],["76359.1","0.02"],["76357.1","0"],["76355.4","0.015735"],["76354.9","0"],["76354.3","0"],["76354.2","0.03"],["76353.9","0"],["76352.1","0.026793"],["76352","0"],["76350.7","0.013201"],["76348.1","0.028085"],["76347.1","0"],["76340","0.015735"],["76336.2","0.027177"],["76317","0.097441"],["76298.7","0.048821"],["76298.5","0"],["76285","0"],["76258.2","0.17542"],["76214.6","0.126"],["76214.2","6.180768"],["76212.1","0.00464"],["76211","0.002357"]],"a":[["76361.5","0.676614"],["76361.8","0"],["76361.9","0.022109"],["76365.3","0.011134"],["76367","0"],["76368","0.015735"],["76370.7","0"],["76371.6","0"],["76371.9","0"],["76376.1","0.031456"],["76376.2","0.000099"],["76377.1","0.006546"],["76377.2","0.010203"],["76379.3","0"],["76380.6","0"],["76380.7","0"],["76385.1","0.130981"],["76385.2","0"],["76387.1","0"],["76396.1","0.096196"],["76425.9","0.002279"],["76455.4","0.000103"],["76456.2","0.016369"]],"u":28058076,"seq":105954710162},"cts":1776816003567}
{"topic":"orderbook.200.BTCUSDT","ts":1776816003669,"type":"delta","data":{"s":"BTCUSDT","b":[["76355.4","0"],["76354.8","0"],["76354.3","0.041609"],["76352.6","0.02438"],["76352.1","0"],["76351.8","0.015735"],["76350.8","0"],["76349.3","0.006545"],["76349.2","0.028084"],["76340.3","0.031456"],["76340","0"],["76339.6","0"],["76336.7","0.006549"],["76285","0.015735"],["76225.7","0.239392"],["76214.2","0"],["76212.1","0"],["76211","0"]],"a":[["76361.5","0.710296"],["76361.9","0"],["76364.1","0.123463"],["76364.4","0"],["76365.3","0"],["76368.4","0"],["76375.3","0.007546"],["76377.1","0"],["76456.6","0.000542"],["76456.7","0.031456"],["76456.8","0.571796"],["76456.9","1.206"],["76457","0.001759"]],"u":28058077,"seq":105954710346},"cts":1776816003665}
{"topic":"orderbook.200.BTCUSDT","ts":1776816003771,"type":"delta","data":{"s":"BTCUSDT","b":[["76355.6","0.015735"],["76351.8","0"],["76350.8","0.006545"],["76349.3","0"],["76349.2","0"],["76340","0.015735"],["76285","0"],["76214.2","6.180768"]],"a":[["76361.5","0.7318"],["76369.9","0.011"],["76375.3","0.001"],["76376","0.006546"],["76378.3","0.03"],["76389.9","0.014929"],["76391.5","0"],["76456.8","0"],["76456.9","0"],["76457","0"]],"u":28058078,"seq":105954710426},"cts":1776816003769}
{"topic":"orderbook.200.BTCUSDT","ts":1776816003869,"type":"delta","data":{"s":"BTCUSDT","b":[["76361.4","0.481946"],["76360.1","0.01428"],["76359.4","0.015735"],["76358.6","0.026192"],["76355.7","0.006544"],["76355.6","0"],["76353.7","0.126"],["76351.9","0"],["76351.5","0.028083"],["76350.8","0"],["76346.2","0.031456"],["76345.7","0.001"],["76344","0.084343"],["76342.9","0.130981"],["76303.9","0"],["76254.2","0"],["76215.5","0"],["76214.6","0"],["76214.2","0"]],"a":[["76361.5","0.208591"],["76362.9","0"],["76363.1","0.040825"],["76364.1","0.112448"],["76368","0.000198"],["76368.6","0.012244"],["76369.6","0.011015"],["76372.7","0"],["76376","0"],["76376.1","0"],["76377.2","0"],["76377.9","0.03"],["76381.2","0.006545"],["76382.4","0"],["76383.1","0.031456"],["76385.1","0"],["76385.5","0"],["76386.3","0.031456"],["76388.3","0.845675"],["76389.4","0"],["76392.6","0"],["76394.4","0.031456"],["76395","0"],["76396.1","0"],["76439.8","0"],["76456.8","0.571796"],["76456.9","1.206"],["76457","0.001759"],["76457.5","0.193578"],["76457.6","0.130981"],["76458","0.0001"],["76458.2","0.00041"],["76458.4","0.00041"]],"u":28058079,"seq":105954710697},"cts":1776816003867}
{"topic":"orderbook.200.BTCUSDT","ts":1776816003969,"type":"delta","data":{"s":"BTCUSDT","b":[["76367.9","0.983278"],["76366.1","0.423412"],["76365.1","0.065865"],["76365","0.404062"],["76364.8","0.147652"],["76364.6","0.004534"],["76364","0.058022"],["76363.5","0.479956"],["76363.3","0.002"],["76363.2","0.128452"],["76363.1","0.047556"],["76363","0.103602"],["76362.9","0.061422"],["76361.6","0.000198"],["76361.4","0.03"],["76360.3","0.002"],["76360.1","0"],["76359.4","0"],["76359.2","0.022827"],["76359","0.026192"],["76358.6","0.002102"],["76358.2","0.000099"],["76356.5","0.002"],["76355.7","0"],["76355.3","0.0024"],["76354.8","0.028082"],["76354.3","0.073901"],["76353.8","0.102995"],["76352.5","0.068439"],["76345.9","0"],["76336.7","0"],["76336.2","0"],["76319.2","0.084388"],["76316.2","0.945148"],["76304","0.275862"],["76297.5","0.013099"],["76297","0.0131"],["76292.8","0.0131"],["76283.6","0"],["76282.1","0"],["76274.2","0"],["76269.4","0.052898"],["76262.2","0"],["76258.2","0"],["76252.3","0.021587"],["76249.7","0"],["76226.4","0"],["76226.2","0"],["76226.1","0"],["76226","0"],["76225.7","0"],["76225.6","0"],["76223.6","0"],["76223.2","0"],["76223","0"],["76222.7","0"],["76218.4","0"],["76217.6","0"],["76217.2","0"]],"a":[["76361.5","0"],["76363","0"],["76363.1","0"],["76363.2","0"],["76364.1","0"],["76365.1","0"],["76368","0.179301"],["76368.6","0.001099"],["76369.1","0"],["76369.6","0"],["76369.9","0"],["76370.6","0.0024"],["76370.8","0.001178"],["76371.9","0.002"],["76372.8","0"],["76375.1","0.008152"],["76375.6","0.002"],["76376.5","0"],["76376.7","0"],["76377.9","0"],["76378","0.007461"],["76378.3","0"],["76379.7","0.007331"],["76381.2","0"],["76382.4","0.021522"],["76382.5","0.072003"],["76383.1","0"],["76383.7","0.010249"],["76385.4","0.064702"],["76386.3","0"],["76388","0.031456"],["76393.2","0.006545"],["76407.3","0"],["76413","0"],["76419.2","0.0131"],["76420.7","0.0131"],["76420.8","0.013099"],["76450","0.082796"],["76457.5","0"],["76458.8","0.000198"],["76458.9","0.741809"],["76459.5","0.0061"],["76459.8","0.000107"],["76460","0.000919"],["76460.5","0.000283"],["76461","0.254756"]],"u":28058080,"seq":105954711569},"cts":1776816003967}
{"topic":"orderbook.200.BTCUSDT","ts":1776816004069,"type":"delta","data":{"s":"BTCUSDT","b":[["76370.7","1.491087"],["76368.5","0.461487"],["76368.3","0.162186"],["76368.2","0.397752"],["76368","0.03"],["76367.9","0.045735"],["76367.8","0.001"],["76366.1","0"],["76365.1","0.006543"],["76365","0.2184"],["76364.8","0.02"],["76364","0"],["76363.5","0"],["76363.3","0"],["76363.2","0"],["76363.1","0.0064"],["76363","0.126"],["76362.9","0.003102"],["76361.4","0.03065"],["76360.3","0"],["76359.8","0.013818"],["76359.7","0.026191"],["76359.2","0"],["76359","0"],["76358.6","0"],["76356.5","0"],["76355.3","0"],["76354.5","0.013102"],["76354.4","0.031456"],["76352.6","0.039025"],["76352.5","0.133927"],["76350.7","0.000099"],["76350.6","0.06551"],["76349.6","0.031456"],["76349.4","0.119993"],["76349.3","0.130981"],["76348.9","0"],["76348.8","0"],["76346.9","0"],["76319.2","0.362947"],["76311.1","0.743011"],["76300","0.001244"],["76283.7","0.040106"],["76270.4","0"],["76261.2","0"],["76258.2","0.175877"],["76238.5","0.00652"],["76229.3","0"]],"a":[["76368","0"],["76368.3","0"],["76368.6","0"],["76370","0"],["76370.6","0"],["76370.8","0.252822"],["76371.9","0"],["76375.4","0.008368"],["76375.6","0"],["76376.8","0.013092"],["76377.8","0.030714"],["76378.4","0.0064"],["76378.7","0.065463"],["76380.6","0.065461"],["76381","0.063165"],["76382.4","0"],["76382.5","0.001178"],["76383.7","0"],["76384.5","0.02956"],["76385.4","0.037641"],["76387.9","0.015735"],["76388","0"],["76391.3","0.006544"],["76393.2","0"],["76393.3","0"],["76394.4","0"],["76396.4","0.031456"],["76440","0.000875"],["76461","0.03826"],["76461.1","0.126"],["76461.2","0.000713"],["76462.5","0.000192"]],"u":28058081,"seq":105954712413},"cts":1776816004067}
{"topic":"orderbook.200.BTCUSDT","ts":1776816004169,"type":"delta","data":{"s":"BTCUSDT","b":[["76370.7","1.475075"],["76368.6","0.072814"],["76368.5","0"],["76368.3","0.004534"],["76368.2","0"],["76368","0"],["76365.1","0"],["76364.7","0.006543"],["76363.1","0.081602"],["76362.3","0.113081"],["76361.4","0.03"],["76361","0.0222"],["76360.9","0.026191"],["76359.8","0"],["76359.7","0"],["76358","0.028081"],["76354.3","0.041609"],["76353.8","0"],["76352.6","0.072345"],["76352.5","0.085488"],["76349.4","0.08089"],["76336.4","0.003275"],["76317","0"],["76311.2","0.221789"],["76283","0"],["76269.4","0.101564"],["76261.5","0.5999"],["76258.2","0"],["76229.3","0.001178"]],"a":[["76370.8","0.312846"],["76377.8","0.029405"],["76380.5","0.02022"],["76381","0"],["76385.4","0.070323"],["76386.8","0.12561"],["76388.2","0.137293"],["76391.3","0"],["76391.8","0.006544"],["76400.8","0.37155"],["76405.8","0.147389"],["76416.6","0.003272"],["76461.1","0"],["76461.2","0"],["76462.5","0"]],"u":28058082,"seq":105954712679},"cts":1776816004160}
{"topic":"orderbook.200.BTCUSDT","ts":1776816004269,"type":"delta","data":{"s":"BTCUSDT","b":[["76370.7","1.479609"],["76368.6","0"],["76368.3","0"],["76365.1","0.006544"],["76365","0"],["76364.7","0"],["76363.1","0.054145"],["76362.3","0.139271"],["76360.9","0"],["76358","0"],["76357.9","0.013102"],["76357.3","0.028081"],["76356","0.065488"],["76354.5","0"],["76354.1","0.06551"],["76352.5","0.02"],["76350.6","0"],["76343","0.396886"],["76335.7","0.000099"],["76301.3","0"],["76261.6","0.067201"],["76226.4","0.00162"],["76226.2","0.132601"]],"a":[["76370.8","0.318306"],["76375.1","0.000621"],["76376.8","0"],["76378.2","0.007531"],["76378.6","0.012"],["76378.7","0"],["76380.6","0"],["76382.4","0.006543"],["76384.5","0.042652"],["76386.4","0.065463"],["76388.4","0.065461"],["76389.9","0.021473"],["76390.5","0"],["76391.8","0"],["76393.2","0.130981"],["76394.5","0"],["76407.8","0.396313"],["76409","0"],["76422.3","0.199936"],["76423.5","0"],["76425.9","0"],["76428.7","0"],["76436.8","0.3562"],["76450.9","0.001395"],["76458.9","0.000233"],["76461.1","0.126"],["76461.2","0.000713"]],"u":28058083,"seq":105954712820},"cts":1776816004267}
{"topic":"orderbook.200.BTCUSDT","ts":1776816004369,"type":"delta","data":{"s":"BTCUSDT","b":[["76370.7","0.255996"],["76368","0.01992"],["76367.9","0.015735"],["76365.1","0"],["76364.6","0"],["76364.1","0.004534"],["76363.1","0.0064"],["76363","0"],["76362.9","0.001"],["76362.4","0.068959"],["76362.3","0.113081"],["76361","0"],["76359.2","0.006544"],["76359","0.010417"],["76358.1","0.002102"],["76357.3","0"],["76356.1","0.103441"],["76354.4","0"],["76354.3","0"],["76352.6","0.023772"],["76349.7","0.031456"],["76349.6","0"],["76349.4","0.041792"],["76349.3","0"],["76346.8","0.006548"],["76344","0.199351"],["76343.5","0.027174"],["76335.9","0.070935"],["76321.4","0"],["76307.9","0.743042"],["76304","0.063442"],["76261.6","0.247516"],["76258.2","0.153717"],["76226.4","0"],["76226.2","0"]],"a":[["76370.8","0.739994"],["76371.3","0.007368"],["76373.4","0.007461"],["76373.6","0.007531"],["76375.4","0.001"],["76377.7","0.014438"],["76377.8","0"],["76378","0"],["76378.2","0"],["76378.3","0.006544"],["76380.5","0"],["76382","0.031048"],["76382.1","0.118473"],["76382.4","0"],["76386.2","0.006545"],["76386.8","0"],["76387.5","0.010544"],["76387.9","0"],["76388","0.031456"],["76388.2","0.105837"],["76389.9","0.014929"],["76391.6","0.055063"],["76406.2","0.03"],["76407.7","0.166818"],["76408.2","0"],["76422.2","0.111765"],["76422.9","0.031456"],["76434.9","0.002279"],["76456.8","0.402305"],["76459.8","0"],["76460","0"],["76460.5","0"],["76461","0"],["76461.1","0"],["76461.2","0"]],"u":28058084,"seq":105954713151},"cts":1776816004367}
{"topic":"orderbook.200.BTCUSDT","ts":1776816004469,"type":"delta","data":{"s":"BTCUSDT","b":[["76370.7","0"],["76368","0"],["76367.9","0.111224"],["76363.1","0"],["76360.9","0.004534"],["76360.3","0.0064"],["76359.2","0.013647"],["76356.2","0.006544"],["76322.6","0.16669"],["76311.2","0.415232"],["76300","0.001178"],["76258.2","0.28007"]],"a":[["76368","0.953523"],["76370.7","0.122845"],["76370.8","0.099912"],["76374.8","0.006544"],["76374.9","0.007331"],["76375.6","0.0064"],["76375.7","0.126"],["76377.5","0.11875"],["76377.7","0"],["76378.3","0"],["76378.4","0"],["76379.7","0"],["76382","0"],["76382.1","0"],["76385.6","0.130981"],["76386.2","0"],["76395","0.015735"],["76403.7","0.091926"],["76440","0.000941"],["76450","0.067061"],["76458.9","0"],["76459.5","0"]],"u":28058085,"seq":105954713483},"cts":1776816004467}
{"topic":"orderbook.200.BTCUSDT","ts":1776816004572,"type":"delta","data":{"s":"BTCUSDT","b":[["76367.9","0.103799"],["76360.4","0.015735"],["76358.3","0.006544"],["76356.2","0"],["76355.8","0.028082"],["76348.1","0"],["76229.3","0"]],"a":[["76368","0.871992"],["76370.6","0.068964"],["76370.8","0.089382"],["76373.3","0.015735"],["76374.8","0"],["76375.5","0.042504"],["76377.4","0.045902"],["76383.6","0.006545"],["76458.2","0"],["76458.4","0"],["76458.8","0"]],"u":28058086,"seq":105954713614},"cts":1776816004567}
{"topic":"orderbook.200.BTCUSDT","ts":1776816004669,"type":"delta","data":{"s":"BTCUSDT","b":[["76367.9","0.375122"],["76364.9","0.006544"],["76364.1","0"],["76363.9","0.004534"],["76362.6","0.002085"],["76360.9","0"],["76360.5","0.022208"],["76359.2","0"],["76358.3","0"],["76358.1","0"],["76355.8","0"],["76354.4","0.048439"],["76337.8","0.098941"],["76336.7","0.369302"],["76230.7","0"]],"a":[["76368","0.251315"],["76370.6","0.001309"],["76370.8","0.059382"],["76371.3","0"],["76373.3","0"],["76373.4","0"],["76373.6","0"],["76374.9","0"],["76375.5","0.001"],["76375.7","0"],["76376","0.007374"],["76377.3","0.007467"],["76377.4","0.039358"],["76378.3","0.007537"],["76380.6","0.007337"],["76382.4","0.006544"],["76383.6","0"],["76384.4","0.031456"],["76385.6","0"],["76389.8","0.006545"],["76458.2","0.00041"]],"u":28058087,"seq":105954713795},"cts":1776816004666}
{"topic":"orderbook.200.BTCUSDT","ts":1776816004769,"type":"delta","data":{"s":"BTCUSDT","b":[["76367.9","0.518884"],["76367.3","0.004534"],["76364.9","0"],["76363.9","0"],["76363","0.006544"],["76362.7","0.02619"],["76362.4","0.042769"],["76359.6","0.02808"],["76353.8","0.031456"],["76343.5","0"],["76336.8","0.160083"],["76335.9","0.031456"],["76234","0"],["76233.9","0"],["76231","0"]],"a":[["76368","0.032581"],["76370.6","0.052129"],["76377.3","0"],["76378.5","0.007467"],["76384.4","0"],["76387.9","0.031456"],["76388","0"],["76391.6","0.020662"],["76393.2","0"],["76402.5","0.006837"],["76458.4","0.00041"]],"u":28058088,"seq":105954713981},"cts":1776816004768}
{"topic":"orderbook.200.BTCUSDT","ts":1776816004869,"type":"delta","data":{"s":"BTCUSDT","b":[["76367.9","0.528976"],["76367.3","0"],["76364.2","0.015735"],["76363.9","0.004534"],["76360.5","0.01493"],["76360.4","0"],["76359.6","0"],["76347.1","0.027173"]],"a":[["76368","0.086781"],["76371.9","0.007374"],["76374.2","0.007537"],["76374.6","0.007467"],["76376","0"],["76376.8","0.015735"],["76378.3","0"],["76378.5","0"],["76381.2","0.006544"],["76382.4","0"],["76388.3","0.85222"],["76389.8","0"],["76391.6","0.057118"],["76393.2","0.130981"],["76450.6","1.004106"],["76458.4","0"]],"u":28058089,"seq":105954714075},"cts":1776816004864}
{"topic":"orderbook.200.BTCUSDT","ts":1776816004968,"type":"delta","data":{"s":"BTCUSDT","b":[["76367.9","0.533852"],["76365.4","0.004534"],["76236.9","0"]],"a":[["76368","0.077681"],["76380.5","0.006544"],["76381.2","0"],["76388.1","0.295034"],["76388.3","0.845675"]],"u":28058090,"seq":105954714124},"cts":1776816004953}
{"topic":"orderbook.200.BTCUSDT","ts":1776816005069,"type":"delta","data":{"s":"BTCUSDT","b":[["76367.9","0.53559"],["76365.4","0"],["76363","0"],["76362.8","0.006544"],["76356.7","0.028081"]],"a":[["76368","0.253021"],["76379.8","0.006544"],["76380.5","0"],["76387.4","0.006545"],["76388.1","0.288489"],["76458.2","0"]],"u":28058091,"seq":105954714214},"cts":1776816005059}
{"topic":"orderbook.200.BTCUSDT","ts":1776816005169,"type":"delta","data":{"s":"BTCUSDT","b":[["76362.8","0"],["76362.5","0.006544"],["76284.5","0.12"],["76237.6","0"]],"a":[["76378.6","0.001"]],"u":28058092,"seq":105954714251},"cts":1776816005163}
{"topic":"orderbook.200.BTCUSDT","ts":1776816005268,"type":"delta","data":{"s":"BTCUSDT","b":[["76367.9","0.537838"],["76363","0.006544"],["76362.5","0"],["76357.3","0.028272"],["76356.7","0"],["76284.6","0.106403"],["76283.7","0"],["76237.6","0.126"]],"a":[["76368","0.077681"],["76379.8","0"],["76379.9","0.007544"],["76387.4","0"],["76387.9","0"],["76388","0.006545"],["76458.2","0.00041"],["76458.4","0.00041"]],"u":28058093,"seq":105954714327},"cts":1776816005266}
{"topic":"orderbook.200.BTCUSDT","ts":1776816005371,"type":"delta","data":{"s":"BTCUSDT","b":[["76370.6","0.308335"],["76370.5","0.02"],["76368.4","0.043036"],["76368.3","0.033977"],["76367.9","0.034534"],["76367.7","0.015735"],["76365.9","0.026189"],["76364.2","0"],["76363","0.087761"],["76362.9","0.127"],["76362.7","0.006544"],["76362.4","0"],["76361.6","0"],["76360.3","0"],["76358.2","0.028371"],["76357.3","0"],["76356.1","0.143773"],["76354.9","0.130981"],["76353.2","0.023547"],["76353.1","0.027329"],["76352.6","0"],["76351.5","0"],["76311.1","0"],["76300","0.001244"],["76258.2","0.153717"],["76237.6","0"]],"a":[["76368","0"],["76370.6","0"],["76370.7","0.536855"],["76374.6","0"],["76375.6","0"],["76376.8","0"],["76378.3","0.0064"],["76378.5","0.007467"],["76379.3","0.015735"],["76379.9","0.001"],["76380.4","0.006544"],["76387.4","0.006545"],["76388","0.031456"],["76391.6","0.020662"],["76393.2","0"],["76395.8","0.031456"],["76395.9","0.07196"],["76396.4","0"],["76398.2","0.130981"],["76399.5","0.031456"],["76405","0"],["76406.2","0"],["76440","0.000875"],["76450.6","0.979434"],["76458.8","0.000198"],["76458.9","0.000233"]],"u":28058094,"seq":105954714678},"cts":1776816005368}
{"topic":"orderbook.200.BTCUSDT","ts":1776816005469,"type":"delta","data":{"s":"BTCUSDT","b":[["76370.6","0.110616"],["76368.4","0.030476"],["76367.9","0.004534"],["76367.7","0"],["76364.6","0.015735"],["76362.7","0"],["76361.5","0.006544"],["76358.2","0.000099"],["76357.5","0.028272"],["76311.2","0.221789"],["76258.2","0.19505"],["76238.2","0"]],"a":[["76370.7","0.542315"],["76370.8","0.086654"],["76372.6","0.025115"],["76376","0.007467"],["76377.9","0.024325"],["76378.4","0.006544"],["76378.5","0"],["76380.4","0"],["76386.8","0.006545"],["76387.4","0"],["76388.2","0.236818"],["76458.8","0"],["76458.9","0"]],"u":28058095,"seq":105954714778},"cts":1776816005461}
{"topic":"orderbook.200.BTCUSDT","ts":1776816005568,"type":"delta","data":{"s":"BTCUSDT","b":[["76370.6","0.164816"],["76367.9","0"],["76357.5","0"],["76356.5","0.028273"],["76318.1","0.742943"]],"a":[["76370.7","0.555587"],["76372.5","0.014131"],["76373","0.00015"],["76375.9","0.015735"],["76378.4","0"],["76378.9","0.006544"],["76379","0.023877"],["76379.3","0"],["76386.8","0"],["76386.9","0.006545"],["76458.2","0"],["76458.4","0"]],"u":28058096,"seq":105954714858},"cts":1776816005566}
{"topic":"orderbook.200.BTCUSDT","ts":1776816005668,"type":"delta","data":{"s":"BTCUSDT","b":[["76370.6","0.186816"],["76365.5","0.004534"],["76362.4","0.006544"],["76361.5","0"],["76319.2","0.520016"],["76238.5","0"]],"a":[["76370.7","0.548307"],["76378.9","0"],["76379.8","0.006544"],["76386.9","0"],["76387.3","0.006545"]],"u":28058097,"seq":105954714925},"cts":1776816005665}
{"topic":"orderbook.200.BTCUSDT","ts":1776816005769,"type":"delta","data":{"s":"BTCUSDT","b":[["76370.6","0.187074"],["76362.4","0"],["76361.5","0.006544"]],"a":[["76370.7","0.559485"],["76386.9","0.006545"],["76387.3","0"]],"u":28058098,"seq":105954714972},"cts":1776816005761}
{"topic":"orderbook.200.BTCUSDT","ts":1776816005869,"type":"delta","data":{"s":"BTCUSDT","b":[["76370.6","0.187271"],["76357.9","0.041374"],["76356.5","0"],["76238.5","0.00652"]],"a":[["76370.7","0.561305"],["76405.8","0.048439"],["76453.8","0.024672"],["76458","0"]],"u":28058099,"seq":105954715001},"cts":1776816005856}
{"topic":"orderbook.200.BTCUSDT","ts":1776816005969,"type":"delta","data":{"s":"BTCUSDT","b":[["76362.4","0.006544"],["76361.5","0"],["76337.8","0"],["76335.6","0.098042"]],"a":[["76386.9","0"],["76387.4","0.006545"],["76403.7","0.065752"],["76405.8","0.146079"]],"u":28058100,"seq":105954715032},"cts":1776816005966}
{"topic":"orderbook.200.BTCUSDT","ts":1776816006069,"type":"delta","data":{"s":"BTCUSDT","b":[["76362.7","0.006544"],["76362.4","0"]],"a":[["76370.7","0.548565"],["76375.9","0"],["76379.8","0"],["76379.9","0.007544"],["76387.4","0"],["76387.8","0.006545"],["76395","0"],["76458","0.0001"],["76458.2","0.00041"],["76458.4","0.00041"]],"u":28058101,"seq":105954715114},"cts":1776816006062}
{"topic":"orderbook.200.BTCUSDT","ts":1776816006171,"type":"delta","data":{"s":"BTCUSDT","b":[["76370.6","0.190911"],["76362.7","0"],["76361.5","0.006544"],["76357.9","0.013102"],["76357.7","0.028272"],["76238.5","0"]],"a":[["76370.7","0.537113"],["76377","0.015735"],["76379.8","0.006544"],["76379.9","0.001"],["76387.4","0.006545"],["76387.8","0"],["76395","0.015735"],["76458","0"],["76458.2","0"],["76458.4","0"]],"u":28058102,"seq":105954715194},"cts":1776816006166}
{"topic":"orderbook.200.BTCUSDT","ts":1776816006268,"type":"delta","data":{"s":"BTCUSDT","b":[["76370.6","0.187271"]],"a":[["76370.7","0.55272"],["76379.6","0.006544"],["76379.8","0"],["76395.3","0.03"],["76457.6","0"]],"u":28058103,"seq":105954715259},"cts":1776816006261}
{"topic":"orderbook.200.BTCUSDT","ts":1776816006369,"type":"delta","data":{"s":"BTCUSDT","b":[["76370.6","0.023887"],["76370.5","0"],["76368.4","0.000198"],["76368.3","0"],["76368.2","0.033703"],["76365.9","0"],["76365.5","0"],["76364.6","0"],["76363.9","0"],["76363.1","0.004534"],["76363","0.049408"],["76362.9","0.041"],["76362.6","0"],["76361.5","0"],["76360.1","0.004534"],["76358.3","0.006544"],["76357.9","0.015136"],["76357.7","0"],["76356.1","0.103441"],["76354.9","0"],["76354.8","0"],["76353.8","0"],["76353.1","0"],["76351.8","0.028275"],["76349.7","0"],["76347.2","0.032634"],["76346.2","0"],["76344.1","0.162437"],["76343.2","0.028294"],["76342.9","0"],["76340.3","0"],["76308","0.031456"],["76274.3","0"],["76238.5","0.00652"],["76238.2","0.000099"],["76237.6","0.126"],["76236.9","0.130981"],["76234","0.000439"],["76233.9","0.048439"],["76231","0.00162"],["76230.7","0.000099"],["76229.3","0.001178"],["76226.4","0.00162"],["76226.2","0.132601"]],"a":[["76370.7","0.564865"],["76371.9","0"],["76376","0"],["76376.1","0.007354"],["76376.9","0.006544"],["76379.6","0"],["76380.6","0"],["76384.4","0.006545"],["76387.4","0"],["76457.6","0.130981"],["76458","0.0001"]],"u":28058104,"seq":105954715473},"cts":1776816006366}
{"topic":"orderbook.200.BTCUSDT","ts":1776816006468,"type":"delta","data":{"s":"BTCUSDT","b":[["76370.6","0.078087"],["76368.3","0.024146"],["76365.9","0.026189"],["76362.9","0.001"],["76361.1","0.015735"],["76355.1","0.028273"],["76353.2","0"],["76352.9","0.01444"],["76343.2","0.000099"],["76339.5","0.028197"],["76231","0"],["76230.7","0"],["76229.3","0"],["76226.4","0"],["76226.2","0"]],"a":[["76370.7","0.577605"],["76373.2","0.015735"],["76376","0.006544"],["76376.9","0"],["76377","0"],["76383.7","0.006545"],["76384.4","0"]],"u":28058105,"seq":105954715633},"cts":1776816006466}
{"topic":"orderbook.200.BTCUSDT","ts":1776816006569,"type":"delta","data":{"s":"BTCUSDT","b":[["76357.6","0.028272"],["76339.5","0"]],"a":[["76370.7","0.570121"],["76373.1","0.007484"],["76458","0"]],"u":28058106,"seq":105954715699},"cts":1776816006558}
{"topic":"orderbook.200.BTCUSDT","ts":1776816006669,"type":"delta","data":{"s":"BTCUSDT","b":[["76370.6","0.100087"],["76360.5","0"],["76359.2","0.02402"],["76359.1","0.026544"],["76358.6","0.028272"],["76358.3","0"],["76357.6","0"],["76231","0.00162"]],"a":[["76376","0"],["76377.3","0.006544"],["76383.7","0"],["76384.4","0.006545"]],"u":28058107,"seq":105954715737},"cts":1776816006656}
{"topic":"orderbook.200.BTCUSDT","ts":1776816006768,"type":"delta","data":{"s":"BTCUSDT","b":[["76359.3","0.006544"],["76359.1","0.02"],["76231","0"]],"a":[["76377.2","0.006544"],["76377.3","0"]],"u":28058108,"seq":105954715772},"cts":1776816006767}
{"topic":"orderbook.200.BTCUSDT","ts":1776816006868,"type":"delta","data":{"s":"BTCUSDT","b":[["76370.6","0.045887"],["76359.3","0"],["76231","0.00162"]],"a":[["76377.2","0"],["76377.3","0.006544"],["76384.4","0"],["76385.3","0.006545"]],"u":28058109,"seq":105954715839},"cts":1776816006867}
{"topic":"orderbook.200.BTCUSDT","ts":1776816006971,"type":"delta","data":{"s":"BTCUSDT","b":[["76358","0.006544"],["76231","0"]],"a":[["76370.7","0.585323"],["76373.1","0"],["76374.2","0"],["76376","0.006544"],["76377.3","0"],["76383.7","0.006545"],["76385.3","0"],["76388.8","0.03"],["76458","0.0001"]],"u":28058110,"seq":105954716009},"cts":1776816006958}
{"topic":"orderbook.200.BTCUSDT","ts":1776816007069,"type":"delta","data":{"s":"BTCUSDT","b":[["76362.9","0.041"],["76358.7","0.006544"],["76358","0"]],"a":[["76370.7","0.585061"],["76384.9","0.031456"],["76458","0"]],"u":28058111,"seq":105954716088},"cts":1776816007066}
{"topic":"orderbook.200.BTCUSDT","ts":1776816007169,"type":"delta","data":{"s":"BTCUSDT","b":[["76362.9","0.001"],["76361.1","0"],["76343.5","0.01963"],["76340.7","0.030125"],["76340","0"],["76312.5","0"],["76302.8","0.01963"],["76231","0.00162"]],"a":[["76373.2","0"],["76388.7","0.01963"],["76395","0"],["76422.5","0"],["76440.2","0.02018"],["76458","0.0001"],["76458.2","0.00041"]],"u":28058112,"seq":105954716190},"cts":1776816007165}
{"topic":"orderbook.200.BTCUSDT","ts":1776816007269,"type":"delta","data":{"s":"BTCUSDT","b":[["76368.6","0.023207"],["76368.5","0.030357"],["76368.3","0"],["76368.2","0"],["76362.9","0.041"]],"a":[["76370.8","0.02845"]],"u":28058113,"seq":105954716285},"cts":1776816007263}
{"topic":"orderbook.200.BTCUSDT","ts":1776816007369,"type":"delta","data":{"s":"BTCUSDT","b":[["76362.9","0.001"],["76359.3","0.006544"],["76358.7","0"]],"a":[["76370.7","0.53512"],["76376","0"],["76377.3","0.006544"],["76383.7","0"],["76384.4","0.006545"],["76395.3","0"],["76458.4","0.00041"]],"u":28058114,"seq":105954716345},"cts":1776816007367}
{"topic":"orderbook.200.BTCUSDT","ts":1776816007469,"type":"delta","data":{"s":"BTCUSDT","b":[["76359.3","0"],["76359.2","0.030564"],["76230.7","0.000099"]],"a":[["76377.2","0.006544"],["76377.3","0"]],"u":28058115,"seq":105954716391},"cts":1776816007466}
{"topic":"orderbook.200.BTCUSDT","ts":1776816007569,"type":"delta","data":{"s":"BTCUSDT","b":[["76362.9","0.041"],["76359.3","0.006544"],["76359.2","0.02402"],["76230.7","0"]],"a":[["76377.2","0"],["76384.3","0.006545"],["76384.4","0"],["76458.8","0.000198"]],"u":28058116,"seq":105954716450},"cts":1776816007567}
{"topic":"orderbook.200.BTCUSDT","ts":1776816007669,"type":"delta","data":{"s":"BTCUSDT","b":[["76370.6","0.100087"],["76362.9","0.001"],["76359.5","0.021453"],["76359.4","0.026217"],["76359.3","0"],["76359.2","0"],["76358.6","0"],["76358","0.006544"]],"a":[["76370.7","0.53148"],["76383.6","0.006545"],["76384.3","0"]],"u":28058117,"seq":105954716543},"cts":1776816007660}
{"topic":"orderbook.200.BTCUSDT","ts":1776816007771,"type":"delta","data":{"s":"BTCUSDT","b":[["76370.6","0.120087"],["76359.5","0.027997"],["76358","0"],["76351.8","0"],["76230.7","0.000099"],["76229.3","0.001178"]],"a":[["76370.7","0.52034"],["76373.2","0.007516"],["76383.6","0"],["76384.4","0.006545"],["76458.8","0"]],"u":28058118,"seq":105954716599},"cts":1776816007769}
{"topic":"orderbook.200.BTCUSDT","ts":1776816007869,"type":"delta","data":{"s":"BTCUSDT","b":[["76370.6","0.364799"],["76365.5","0.004534"],["76363.1","0.011078"],["76363","0.081521"],["76362.9","0.127"],["76360.4","0.021453"],["76360.1","0"],["76359.5","0"],["76354.5","0.130981"],["76352.9","0"],["76296.8","0.650809"],["76229.3","0"]],"a":[["76370.7","0.33288"],["76373.2","0"],["76374.9","0.007586"],["76375.8","0.007516"],["76384.4","0"],["76384.9","0"],["76388.2","0.112382"],["76458.8","0.000198"]],"u":28058119,"seq":105954716746},"cts":1776816007861}
{"topic":"orderbook.200.BTCUSDT","ts":1776816007968,"type":"delta","data":{"s":"BTCUSDT","b":[["76370.6","0.474899"],["76363.2","0.006544"],["76363.1","0.004534"],["76356.1","0.14383"],["76354.6","0.031456"],["76298.7","0.244667"],["76231","0"],["76230.7","0"]],"a":[["76370.7","0.277818"],["76388.2","0.105837"],["76388.7","0.026175"]],"u":28058120,"seq":105954716787},"cts":1776816007948}
{"topic":"orderbook.200.BTCUSDT","ts":1776816008069,"type":"delta","data":{"s":"BTCUSDT","b":[["76370.6","0.468427"],["76363.3","0.006544"],["76363.2","0"],["76360.6","0.026217"],["76233.9","0"]],"a":[["76388.3","0.85222"],["76388.7","0.01963"],["76405.8","0.048439"]],"u":28058121,"seq":105954716867},"cts":1776816008057}
{"topic":"orderbook.200.BTCUSDT","ts":1776816008168,"type":"delta","data":{"s":"BTCUSDT","b":[["76370.6","0.461144"],["76363.3","0"],["76363.2","0.006544"]],"a":[["76370.7","0.34682"],["76388.1","0.295034"],["76388.3","0.845675"]],"u":28058122,"seq":105954716908},"cts":1776816008167}
{"topic":"orderbook.200.BTCUSDT","ts":1776816008269,"type":"delta","data":{"s":"BTCUSDT","b":[["76370.6","0.461328"],["76368.8","0.027638"],["76368.6","0.015498"],["76368.5","0"]],"a":[["76388","0.038001"],["76388.1","0.288489"]],"u":28058123,"seq":105954716938},"cts":1776816008257}
{"topic":"orderbook.200.BTCUSDT","ts":1776816008368,"type":"delta","data":{"s":"BTCUSDT","b":[["76363.2","0"],["76362.4","0.006544"]],"a":[["76370.7","0.52216"],["76387.9","0.006545"],["76388","0.031456"],["76458.8","0"]],"u":28058124,"seq":105954716967},"cts":1776816008351}
{"topic":"orderbook.200.BTCUSDT","ts":1776816008468,"type":"delta","data":{"s":"BTCUSDT","b":[],"a":[["76387.4","0.006545"],["76387.9","0"]],"u":28058125,"seq":105954716996},"cts":1776816008462}
{"topic":"orderbook.200.BTCUSDT","ts":1776816008669,"type":"delta","data":{"s":"BTCUSDT","b":[["76363.2","0.006544"],["76362.4","0"],["76361.3","0.026216"],["76360.6","0"]],"a":[["76370.7","0.34682"],["76387.4","0"],["76387.9","0.006545"],["76400.8","0"],["76458.8","0.000198"]],"u":28058126,"seq":105954717056},"cts":1776816008663}
{"topic":"orderbook.200.BTCUSDT","ts":1776816008769,"type":"delta","data":{"s":"BTCUSDT","b":[["76363.2","0"],["76362.4","0.006544"]],"a":[["76370.7","0.52216"],["76387.4","0.006545"],["76387.9","0"],["76402.4","0.363758"],["76458.8","0"]],"u":28058127,"seq":105954717103},"cts":1776816008745}
{"topic":"orderbook.200.BTCUSDT","ts":1776816008868,"type":"delta","data":{"s":"BTCUSDT","b":[["76370.6","0.253088"]],"a":[],"u":28058128,"seq":105954717129},"cts":1776816008842}
{"topic":"orderbook.200.BTCUSDT","ts":1776816009069,"type":"delta","data":{"s":"BTCUSDT","b":[["76370.6","0.259521"],["76367.9","0.004534"],["76365.5","0"],["76363","0.088065"],["76362.4","0"],["76361.7","0.001899"],["76361.3","0"],["76357.9","0.013102"],["76233.9","0.048439"]],"a":[["76370.7","0.273704"],["76372.5","0.01416"],["76374.3","0.007436"],["76376.1","0"],["76380.6","0.007399"],["76387.4","0"],["76387.9","0.006545"],["76402.4","0"]],"u":28058129,"seq":105954717219},"cts":1776816009066}
{"topic":"orderbook.200.BTCUSDT","ts":1776816009169,"type":"delta","data":{"s":"BTCUSDT","b":[["76363","0.081521"],["76362.4","0.006544"],["76361.4","0.056216"],["76233.9","0"]],"a":[["76370.7","0.460589"],["76387.4","0.006545"],["76387.9","0"]],"u":28058130,"seq":105954717278},"cts":1776816009149}
{"topic":"orderbook.200.BTCUSDT","ts":1776816009269,"type":"delta","data":{"s":"BTCUSDT","b":[["76370.6","0.253088"],["76369","0.025401"],["76368.8","0"],["76367.9","0"],["76365.3","0.004534"],["76362.5","0.006544"],["76362.4","0"]],"a":[["76403.4","0.373334"],["76458.4","0"]],"u":28058131,"seq":105954717324},"cts":1776816009267}
{"topic":"orderbook.200.BTCUSDT","ts":1776816009371,"type":"delta","data":{"s":"BTCUSDT","b":[["76370.6","0.251736"],["76362.5","0"],["76362.4","0.006544"],["76361.4","0.03"],["76360.6","0.026014"],["76234","0"]],"a":[["76371","0.007436"],["76374.3","0"],["76388.2","0.236818"],["76403.3","0.163891"],["76403.7","0"]],"u":28058132,"seq":105954717360},"cts":1776816009366}
{"topic":"orderbook.200.BTCUSDT","ts":1776816009469,"type":"delta","data":{"s":"BTCUSDT","b":[],"a":[["76370.7","0.514789"]],"u":28058133,"seq":105954717396},"cts":1776816009460}
{"topic":"orderbook.200.BTCUSDT","ts":1776816009569,"type":"delta","data":{"s":"BTCUSDT","b":[["76362.4","0"],["76361.8","0.006544"]],"a":[["76386.9","0.006545"],["76387.4","0"]],"u":28058134,"seq":105954717421},"cts":1776816009567}
{"topic":"orderbook.200.BTCUSDT","ts":1776816009669,"type":"delta","data":{"s":"BTCUSDT","b":[["76370.6","0.019584"],["76368.6","0"],["76368.4","0"],["76365.9","0"],["76365.3","0"],["76363.1","0.000198"],["76363","0.049408"],["76362.9","0.041"],["76362.2","0.02619"],["76361.8","0"],["76361.7","0"],["76360.6","0"],["76360.4","0"],["76359.4","0"],["76359","0"],["76358.1","0.004534"],["76356.3","0.004534"],["76356.2","0.026015"],["76355.1","0"],["76354.7","0.006544"],["76354.6","0.02619"],["76354.5","0"],["76351.6","0.001858"],["76347.2","0.001178"],["76344.6","0.025594"],["76344.2","0.031456"],["76344.1","0"],["76343.5","0"],["76343.1","0.130981"],["76340.2","0.068069"],["76336.9","0.162437"],["76336.8","0"],["76336.7","0"],["76335.9","0"],["76335.8","0"],["76330.5","0.031456"],["76330.4","0.001"],["76330.3","0.050645"],["76328.5","0"],["76326.2","0.130981"],["76258.2","0.335963"],["76234","0.000439"],["76233.9","0.048439"],["76231","0.00162"],["76230.7","0.000099"],["76229.3","0.001178"],["76227.4","0.004569"],["76226.4","0.00162"]],"a":[["76370.7","0.549358"],["76371","0"],["76372.5","0.001"],["76374.9","0"],["76375.8","0"],["76380.6","0"],["76381.1","0.006545"],["76384.8","0.031456"],["76386.9","0"],["76403.2","0.031456"],["76458.4","0.00041"],["76458.8","0.000198"]],"u":28058135,"seq":105954717741},"cts":1776816009666}
{"topic":"orderbook.200.BTCUSDT","ts":1776816009769,"type":"delta","data":{"s":"BTCUSDT","b":[["76370.6","0.023874"],["76359.2","0.019029"],["76357.6","0.026015"],["76357","0.010421"],["76356.2","0.006545"],["76355.5","0.026016"],["76354.7","0"],["76349.4","0"],["76347.1","0"],["76332.5","0.355309"],["76227.4","0"],["76226.4","0"]],"a":[["76370.7","0.556638"],["76381.1","0"],["76381.2","0.006545"]],"u":28058136,"seq":105954717881},"cts":1776816009764}
{"topic":"orderbook.200.BTCUSDT","ts":1776816009869,"type":"delta","data":{"s":"BTCUSDT","b":[["76370.6","0.078074"],["76363.2","0.081184"],["76363.1","0.055301"],["76363","0.0064"],["76362.9","0.001"],["76360.5","0.004534"],["76358.2","0.026114"],["76358.1","0"],["76357.6","0"],["76356.4","0.006545"],["76356.2","0"],["76355.4","0.001858"],["76351.6","0"]],"a":[["76388.8","0"],["76458.9","0.000233"]],"u":28058137,"seq":105954717984},"cts":1776816009857}
{"topic":"orderbook.200.BTCUSDT","ts":1776816010068,"type":"delta","data":{"s":"BTCUSDT","b":[["76370.6","0.023874"],["76363.2","0.052795"],["76363.1","0.000198"],["76362.9","0.041"]],"a":[["76370.7","0.556748"],["76381.1","0.01"],["76458.9","0"]],"u":28058138,"seq":105954718189},"cts":1776816010067}
{"topic":"orderbook.200.BTCUSDT","ts":1776816010171,"type":"delta","data":{"s":"BTCUSDT","b":[],"a":[["76381","0.006545"],["76381.2","0"]],"u":28058139,"seq":105954718288},"cts":1776816010163}
{"topic":"orderbook.200.BTCUSDT","ts":1776816010269,"type":"delta","data":{"s":"BTCUSDT","b":[["76369.1","0.023156"],["76369","0"],["76359","0.026014"],["76358.2","0.000099"],["76356.4","0"],["76356.2","0.006545"],["76229.3","0"]],"a":[["76375","0.006545"],["76381","0"],["76381.2","0.006545"],["76458.8","0"]],"u":28058140,"seq":105954718405},"cts":1776816010267}
{"topic":"orderbook.200.BTCUSDT","ts":1776816010368,"type":"delta","data":{"s":"BTCUSDT","b":[["76359","0"],["76358.2","0.026114"],["76356.5","0.006545"],["76356.2","0"],["76229.3","0.001178"]],"a":[["76381.2","0"],["76382.4","0.006545"],["76403.4","0"],["76458.8","0.000198"]],"u":28058141,"seq":105954718554},"cts":1776816010366}
{"topic":"orderbook.200.BTCUSDT","ts":1776816010469,"type":"delta","data":{"s":"BTCUSDT","b":[["76356.5","0"],["76356.4","0.006545"],["76332.5","0"],["76227.4","0.004569"]],"a":[["76400.4","0.358424"],["76403.3","0"]],"u":28058142,"seq":105954718657},"cts":1776816010466}
{"topic":"orderbook.200.BTCUSDT","ts":1776816010569,"type":"delta","data":{"s":"BTCUSDT","b":[["76370.6","0.045874"],["76358.7","0.026015"],["76358.2","0.000099"],["76356.6","0.006545"],["76356.4","0"],["76227.4","0"]],"a":[],"u":28058143,"seq":105954718766},"cts":1776816010567}
{"topic":"orderbook.200.BTCUSDT","ts":1776816010669,"type":"delta","data":{"s":"BTCUSDT","b":[["76357.1","0.006545"],["76356.6","0"],["76331.3","0.360197"],["76229.3","0"]],"a":[],"u":28058144,"seq":105954718854},"cts":1776816010665}
{"topic":"orderbook.200.BTCUSDT","ts":1776816010769,"type":"delta","data":{"s":"BTCUSDT","b":[["76362.9","0.001"],["76357.1","0"],["76356.2","0.006545"],["76234.8","0.006285"],["76230.7","0"]],"a":[["76381.2","0.006545"],["76382.4","0"]],"u":28058145,"seq":105954718946},"cts":1776816010765}
{"topic":"orderbook.200.BTCUSDT","ts":1776816010869,"type":"delta","data":{"s":"BTCUSDT","b":[["76370.6","0.368595"],["76369.2","0.022923"],["76369.1","0"],["76367.8","0.005534"],["76365.7","0.026012"],["76363.3","0.006544"],["76363.2","0.086204"],["76363","0.0104"],["76362.9","0.127"],["76362.6","0.004534"],["76361.9","0.026188"],["76360.5","0"],["76359.8","0.001817"],["76359.2","0"],["76358.7","0"],["76356.3","0"],["76356.2","0"],["76355.5","0"],["76355.4","0"],["76344.6","0"],["76230.7","0.000099"],["76229.3","0.001178"],["76227.4","0.004569"]],"a":[["76370.7","0.343844"],["76375","0"],["76375.6","0.007627"],["76376.1","0.007557"],["76378.3","0.0104"],["76381.2","0.006544"],["76387.5","0"],["76388.2","0.112382"],["76388.7","0"],["76391.9","0.068069"],["76458.9","0.000233"]],"u":28058146,"seq":105954719174},"cts":1776816010863}
{"topic":"orderbook.200.BTCUSDT","ts":1776816010972,"type":"delta","data":{"s":"BTCUSDT","b":[["76370.6","0.160425"],["76367.8","0.001"],["76365.8","0.013735"],["76365.7","0"],["76365.5","0.004534"],["76364.9","0.026012"],["76363.3","0"],["76361.5","0.006544"],["76349.3","0.130981"],["76230.7","0"],["76229.3","0"],["76227.4","0"]],"a":[["76370.7","0.53168"],["76372.5","0.014184"],["76374.2","0.007464"],["76378.9","0.006544"],["76380.5","0.007427"],["76381.2","0"],["76386.9","0.006545"],["76387.9","0.130981"],["76388.2","0.105837"],["76458.2","0"],["76458.4","0"],["76458.8","0"],["76458.9","0"]],"u":28058147,"seq":105954719254},"cts":1776816010961}
{"topic":"orderbook.200.BTCUSDT","ts":1776816011069,"type":"delta","data":{"s":"BTCUSDT","b":[["76370.6","0.069874"],["76365.8","0"],["76365.5","0"],["76364.9","0"],["76361.5","0"],["76359.9","0.006544"],["76359.5","0.017696"],["76359.4","0.026081"],["76352.2","0.025591"],["76349.4","0.031456"],["76348.3","0.01963"],["76340.2","0.048439"],["76337","0.079112"],["76234","0"],["76233.9","0"],["76231","0"]],"a":[["76370.9","0.007464"],["76373.8","0.007557"],["76374.2","0"],["76375.8","0.007427"],["76376.1","0"],["76378.2","0.006544"],["76378.9","0"],["76380.5","0"],["76385.6","0.006545"],["76386.9","0"],["76390.3","0.010169"],["76403.7","0.052451"],["76457.6","0"],["76458","0"]],"u":28058148,"seq":105954719364},"cts":1776816011067}
{"topic":"orderbook.200.BTCUSDT","ts":1776816011168,"type":"delta","data":{"s":"BTCUSDT","b":[["76370.6","0.049874"],["76369.2","0"],["76369.1","0.022864"],["76363.2","0.052795"],["76362.9","0.041"],["76362.6","0"],["76361.9","0"],["76361.4","0"],["76361.1","0.026014"],["76359.9","0"],["76359.8","0"],["76359.3","0.004534"],["76357.1","0.006545"],["76355.3","0.001817"],["76352.6","0.013638"]],"a":[["76370.7","0.546701"],["76370.9","0"],["76371.4","0.007627"],["76373.8","0"],["76375","0.006544"],["76375.6","0"],["76378.2","0"],["76382.4","0.006545"],["76385.6","0"],["76457.6","0.130981"],["76458","0.0001"]],"u":28058149,"seq":105954719587},"cts":1776816011167}
{"topic":"orderbook.200.BTCUSDT","ts":1776816011269,"type":"delta","data":{"s":"BTCUSDT","b":[["76370.6","0"],["76369.1","0"],["76367.8","0"],["76364.8","0"],["76363.2","0.0234"],["76363","0.020408"],["76362.9","0.001"],["76362.3","0"],["76362.2","0"],["76361.1","0"],["76359.5","0"],["76359.4","0"],["76359.3","0"],["76359.1","0"],["76357.1","0"],["76357","0"],["76356.1","0.049849"],["76355.6","0.0104"],["76355.3","0"],["76354.6","0"],["76354.4","0"],["76353.7","0"],["76353","0.004534"],["76352.6","0"],["76352.4","0.025965"],["76352.2","0"],["76349.5","0.004534"],["76349.4","0"],["76349.3","0"],["76348.3","0"],["76347.3","0.006545"],["76346.8","0"],["76346.5","0.028596"],["76346.4","0.001817"],["76346.2","0.023667"],["76344.2","0"],["76343.1","0"],["76340.6","0.025394"],["76340.4","0.031456"],["76340.3","0.01963"],["76336.4","0.009824"],["76318.1","0"],["76300","0.001178"],["76258.2","0.362727"],["76234","0.000439"],["76233.9","0.048439"],["76231","0.00162"],["76230.7","0.000099"],["76229.3","0.001178"],["76227.4","0.004569"],["76226.4","0.00162"],["76226.2","0.132601"],["76226.1","0.126"],["76226","0.001146"],["76225.6","6.604869"],["76223.6","0.714835"],["76223.2","0.000099"],["76223","0.048439"],["76222.7","0.0001"]],"a":[["76363.3","1.536792"],["76363.9","0.007627"],["76364.7","0.024381"],["76364.9","0.03"],["76365","0.028757"],["76365.5","0.007427"],["76367.7","0.006545"],["76367.9","0.029328"],["76370.6","0.061998"],["76370.7","0.15751"],["76370.9","0.0104"],["76371.4","0"],["76371.7","0.001"],["76372.5","0.033074"],["76372.6","0"],["76372.7","0.109227"],["76375","0.006546"],["76375.8","0"],["76377.2","0.013881"],["76377.3","0.031456"],["76377.4","0"],["76377.5","0"],["76377.9","0"],["76378.3","0"],["76379","0"],["76379.8","0.02943"],["76381.2","0.015929"],["76381.3","0.032456"],["76382.4","0"],["76383.8","0.019729"],["76391.9","0.048439"],["76413.1","0.013101"],["76440","0.000941"],["76456.2","0"],["76456.6","0"],["76456.7","0"],["76456.8","0"],["76456.9","0"],["76457","0"],["76457.6","0"],["76458","0"]],"u":28058150,"seq":105954720547},"cts":1776816011267}
{"topic":"orderbook.200.BTCUSDT","ts":1776816011369,"type":"delta","data":{"s":"BTCUSDT","b":[["76363.2","0.02795"],["76363","0"],["76361","0.017838"],["76360.9","0.020367"],["76359.7","0.026191"],["76352.4","0"],["76349.8","0.010204"],["76340.3","0"],["76332.3","0.01963"],["76319.2","0.362947"],["76312.1","0.743001"],["76297","0"],["76289.2","0.013101"],["76234","0.014898"],["76223.2","0"],["76223","0"],["76222.7","0"]],"a":[["76363.3","1.594996"],["76367.7","0"],["76367.8","0.006545"],["76370.7","0.1574"],["76373","0"],["76374.9","0.006546"],["76375","0"],["76384.5","0.013092"],["76385.5","0.00003"],["76411.5","0.013101"],["76413","0.013101"],["76455.2","0"],["76455.4","0"]],"u":28058151,"seq":105954720824},"cts":1776816011368}
{"topic":"orderbook.200.BTCUSDT","ts":1776816011469,"type":"delta","data":{"s":"BTCUSDT","b":[["76363.2","0.08189"],["76352.6","0.01875"],["76352.2","0.025965"],["76350.8","0.006545"],["76347.5","0.069871"],["76347.4","0.123196"],["76347.3","0"],["76346.2","0"],["76343.1","0.130981"],["76315","0.28887"],["76226.1","0"],["76226","0"],["76225.6","0"],["76223.6","0"]],"a":[["76363.3","1.600456"],["76366.2","0.000149"],["76367.8","0"],["76367.9","0.026858"],["76370.5","0.006545"],["76374.9","0"],["76378.5","0.006546"],["76455","0"]],"u":28058152,"seq":105954721060},"cts":1776816011460}
{"topic":"orderbook.200.BTCUSDT","ts":1776816011568,"type":"delta","data":{"s":"BTCUSDT","b":[["76363.2","0.10429"],["76356.2","0.056449"],["76355.1","0.025964"],["76353.3","0.006545"],["76353.2","0.055077"],["76353.1","0.025965"],["76352.6","0"],["76352.2","0"],["76351.3","0.125777"],["76350.8","0"],["76347.5","0.024561"],["76347.4","0"],["76346.5","0"],["76344","0.230807"],["76226.2","0"]],"a":[["76363.3","1.511967"],["76364.9","0"],["76370.5","0"],["76371.6","0.006545"],["76378.5","0"],["76379.7","0.006546"],["76390.3","0"],["76455","0.000078"],["76455.2","0.00027"]],"u":28058153,"seq":105954721180},"cts":1776816011556}
{"topic":"orderbook.200.BTCUSDT","ts":1776816011669,"type":"delta","data":{"s":"BTCUSDT","b":[["76356.3","0.075763"],["76356.1","0"],["76355.2","0.006545"],["76353.3","0"],["76353","0"],["76226.2","0.132601"]],"a":[["76371.6","0"],["76372.4","0.006545"]],"u":28058154,"seq":105954721207},"cts":1776816011668}
{"topic":"orderbook.200.BTCUSDT","ts":1776816011771,"type":"delta","data":{"s":"BTCUSDT","b":[["76355.5","0.004534"],["76355.1","0"],["76349.5","0"],["76226.1","0.126"]],"a":[["76363.3","1.482036"]],"u":28058155,"seq":105954721233},"cts":1776816011769}
{"topic":"orderbook.200.BTCUSDT","ts":1776816011868,"type":"delta","data":{"s":"BTCUSDT","b":[["76356.2","0"],["76355.9","0.025964"],["76355.2","0"],["76354.3","0.006545"],["76352.8","0.004534"],["76350.4","0.001784"],["76346.4","0"],["76226.1","0"]],"a":[["76363.3","1.474479"],["76365.9","0.007567"],["76455.2","0"]],"u":28058156,"seq":105954721283},"cts":1776816011867}
{"topic":"orderbook.200.BTCUSDT","ts":1776816011969,"type":"delta","data":{"s":"BTCUSDT","b":[["76363.2","0.11109"],["76356.7","0.025964"],["76356.3","0.054469"],["76355.9","0"],["76355.7","0.006545"],["76355.6","0.0172"],["76354.3","0"]],"a":[["76363.3","1.480988"],["76365.5","0"],["76370.2","0.007437"],["76370.9","0.0172"],["76372.4","0"],["76372.6","0.006545"],["76379.7","0"],["76381","0.006546"]],"u":28058157,"seq":105954721335},"cts":1776816011960}
{"topic":"orderbook.200.BTCUSDT","ts":1776816012069,"type":"delta","data":{"s":"BTCUSDT","b":[["76357.8","0.004534"],["76355.5","0"]],"a":[["76370.1","0.01"],["76381","0"],["76381.1","0.006546"],["76382.8","0.010403"],["76455","0"]],"u":28058158,"seq":105954721363},"cts":1776816012056}
{"topic":"orderbook.200.BTCUSDT","ts":1776816012169,"type":"delta","data":{"s":"BTCUSDT","b":[["76356.3","0.085793"],["76355.5","0.126"],["76334.1","0.126406"],["76226.2","0"]],"a":[["76363.3","1.480173"],["76372.6","0"],["76375","0.006545"]],"u":28058159,"seq":105954721417},"cts":1776816012166}
{"topic":"orderbook.200.BTCUSDT","ts":1776816012268,"type":"delta","data":{"s":"BTCUSDT","b":[["76361.1","0.018017"],["76360.9","0"],["76357.7","0.025963"],["76340.6","0"]],"a":[["76363.3","1.479472"]],"u":28058160,"seq":105954721460},"cts":1776816012267}
{"topic":"orderbook.200.BTCUSDT","ts":1776816012469,"type":"delta","data":{"s":"BTCUSDT","b":[["76355.7","0"],["76354.3","0.006545"]],"a":[["76372.4","0.006545"],["76375","0"],["76379.8","0.035976"],["76381.1","0"],["76455","0.000078"]],"u":28058161,"seq":105954721551},"cts":1776816012467}
{"topic":"orderbook.200.BTCUSDT","ts":1776816012571,"type":"delta","data":{"s":"BTCUSDT","b":[],"a":[["76379.8","0.02943"],["76381.1","0.006546"],["76455","0"]],"u":28058162,"seq":105954721577},"cts":1776816012553}
{"topic":"orderbook.200.BTCUSDT","ts":1776816012668,"type":"delta","data":{"s":"BTCUSDT","b":[],"a":[["76370.6","0.025252"],["76370.7","0.0314"],["76406.9","0.098803"],["76454.7","0"]],"u":28058163,"seq":105954721595},"cts":1776816012656}
{"topic":"orderbook.200.BTCUSDT","ts":1776816012769,"type":"delta","data":{"s":"BTCUSDT","b":[["76358.4","0.025963"],["76357.7","0"]],"a":[["76379.9","0.007546"],["76381.1","0"],["76454.7","0.0001"]],"u":28058164,"seq":105954721614},"cts":1776816012761}
{"topic":"orderbook.200.BTCUSDT","ts":1776816012969,"type":"delta","data":{"s":"BTCUSDT","b":[],"a":[["76379.7","0.006546"],["76379.9","0.001"],["76454.7","0"]],"u":28058165,"seq":105954721661},"cts":1776816012966}
{"topic":"orderbook.200.BTCUSDT","ts":1776816013069,"type":"delta","data":{"s":"BTCUSDT","b":[],"a":[["76370.1","0"],["76454.7","0.0001"]],"u":28058166,"seq":105954721704},"cts":1776816013067}
{"topic":"orderbook.200.BTCUSDT","ts":1776816013169,"type":"delta","data":{"s":"BTCUSDT","b":[["76363.2","0.08909"],["76359.5","0.025963"],["76358.4","0"],["76326.6","0.061959"]],"a":[["76379.7","0"],["76379.8","0.035975"],["76455","0.000078"]],"u":28058167,"seq":105954721760},"cts":1776816013158}
{"topic":"orderbook.200.BTCUSDT","ts":1776816013269,"type":"delta","data":{"s":"BTCUSDT","b":[["76361.4","0.015495"],["76361.1","0"],["76359.5","0"],["76359.2","0.023294"],["76354.4","0.006545"],["76354.3","0"]],"a":[["76363.3","1.466732"],["76372.4","0"],["76372.6","0.006545"],["76379.8","0.02943"],["76381.1","0.006546"],["76455","0"]],"u":28058168,"seq":105954721827},"cts":1776816013264}
{"topic":"orderbook.200.BTCUSDT","ts":1776816013372,"type":"delta","data":{"s":"BTCUSDT","b":[["76354.4","0"],["76354.3","0.006545"]],"a":[["76372.4","0.006545"],["76372.6","0"]],"u":28058169,"seq":105954721846},"cts":1776816013356}
{"topic":"orderbook.200.BTCUSDT","ts":1776816013469,"type":"delta","data":{"s":"BTCUSDT","b":[],"a":[["76379.9","0.007546"],["76381.1","0"],["76455","0.000078"]],"u":28058170,"seq":105954721863},"cts":1776816013466}
{"topic":"orderbook.200.BTCUSDT","ts":1776816013569,"type":"delta","data":{"s":"BTCUSDT","b":[["76363.2","0.11109"]],"a":[["76365.4","0.030693"],["76379.9","0.001"],["76381.1","0.006546"],["76454.7","0"],["76455","0"]],"u":28058171,"seq":105954721891},"cts":1776816013559}
{"topic":"orderbook.200.BTCUSDT","ts":1776816013669,"type":"delta","data":{"s":"BTCUSDT","b":[["76340.2","0.068069"],["76332.3","0"],["76226.2","0.132601"]],"a":[],"u":28058172,"seq":105954721904},"cts":1776816013667}
{"topic":"orderbook.200.BTCUSDT","ts":1776816013869,"type":"delta","data":{"s":"BTCUSDT","b":[],"a":[["76379.7","0.006545"],["76381.1","0"]],"u":28058173,"seq":105954721934},"cts":1776816013864}
{"topic":"orderbook.200.BTCUSDT","ts":1776816014171,"type":"delta","data":{"s":"BTCUSDT","b":[["76359.9","0.023294"],["76359.2","0"],["76340.7","0.044065"]],"a":[["76363.3","1.465395"],["76379.7","0"],["76381.1","0.006545"]],"u":28058174,"seq":105954721979},"cts":1776816014168}
{"topic":"orderbook.200.BTCUSDT","ts":1776816014269,"type":"delta","data":{"s":"BTCUSDT","b":[["76361.6","0.013304"],["76361.4","0"],["76227.4","0"],["76226.1","0.126"]],"a":[["76379.8","0.035975"],["76381.1","0"],["76454.7","0.0001"]],"u":28058175,"seq":105954722022},"cts":1776816014247}
{"topic":"orderbook.200.BTCUSDT","ts":1776816014369,"type":"delta","data":{"s":"BTCUSDT","b":[["76363.1","0"],["76355.6","0.023745"],["76354.3","0"],["76226","0.001146"],["76225.6","6.604869"]],"a":[["76372.4","0"],["76372.6","0.006545"],["76379.8","0.02943"],["76381.1","0.006545"],["76382.8","0"]],"u":28058176,"seq":105954722057},"cts":1776816014356}
{"topic":"orderbook.200.BTCUSDT","ts":1776816014469,"type":"delta","data":{"s":"BTCUSDT","b":[["76355.6","0.0172"],["76354.3","0.006545"],["76225.6","0"]],"a":[["76372.4","0.006545"],["76372.6","0"],["76379.9","0.007545"],["76381.1","0"],["76455","0.000078"]],"u":28058177,"seq":105954722080},"cts":1776816014442}
{"topic":"orderbook.200.BTCUSDT","ts":1776816014669,"type":"delta","data":{"s":"BTCUSDT","b":[],"a":[["76379.7","0.006545"],["76379.9","0.001"],["76455","0"]],"u":28058178,"seq":105954722117},"cts":1776816014660}
{"topic":"orderbook.200.BTCUSDT","ts":1776816014769,"type":"delta","data":{"s":"BTCUSDT","b":[["76226","0.005876"]],"a":[["76402.5","0"],["76455","0.000078"]],"u":28058179,"seq":105954722139},"cts":1776816014766}
{"topic":"orderbook.200.BTCUSDT","ts":1776816014869,"type":"delta","data":{"s":"BTCUSDT","b":[["76355.6","0.023745"],["76354.3","0"],["76225.6","6.604869"]],"a":[["76372.4","0"],["76379.7","0"],["76380.8","0.013092"],["76381.1","0.006545"],["76382.7","0.065463"],["76384.5","0"],["76384.6","0.065461"],["76386.4","0"],["76388.4","0"],["76455.2","0.00027"]],"u":28058180,"seq":105954722170},"cts":1776816014855}
{"topic":"orderbook.200.BTCUSDT","ts":1776816014972,"type":"delta","data":{"s":"BTCUSDT","b":[["76363.2","0.40381"],["76359.9","0"],["76356.8","0.006545"],["76356.1","0.115956"],["76355.6","0.0172"],["76353.2","0"],["76353.1","0"],["76351.3","0"],["76223.6","0.714835"],["76223.2","0.000099"]],"a":[["76363.3","1.286415"],["76364.7","0"],["76364.9","0.028066"],["76377.2","0"],["76377.3","0"],["76381.1","0"],["76381.2","0.033433"],["76381.3","0.001"],["76382.2","0.006545"],["76384.4","0.031456"],["76384.5","0.066579"],["76384.8","0"],["76385.4","0"],["76387.8","0.130981"],["76387.9","0.031456"],["76388","0"],["76455.4","0.000103"],["76456.2","0.016369"]],"u":28058181,"seq":105954722357},"cts":1776816014970}
{"topic":"orderbook.200.BTCUSDT","ts":1776816015069,"type":"delta","data":{"s":"BTCUSDT","b":[["76363.2","0.406148"],["76361","0.013112"],["76356.9","0.006545"],["76356.8","0"],["76337","0"],["76335.6","0.098421"],["76223","0.048439"]],"a":[["76382.2","0"],["76382.4","0.006545"]],"u":28058182,"seq":105954722421},"cts":1776816015066}
{"topic":"orderbook.200.BTCUSDT","ts":1776816015169,"type":"delta","data":{"s":"BTCUSDT","b":[["76363.2","0.411998"],["76356.9","0"],["76356.8","0.006545"],["76337","0.08118"],["76223","0"]],"a":[["76363.3","1.11034"]],"u":28058183,"seq":105954722467},"cts":1776816015158}
{"topic":"orderbook.200.BTCUSDT","ts":1776816015269,"type":"delta","data":{"s":"BTCUSDT","b":[["76363.2","0.407448"],["76361.8","0.011449"],["76361.6","0"],["76361","0.01331"],["76358.3","0.006545"],["76356.8","0"]],"a":[["76382.4","0"],["76383.7","0.006545"]],"u":28058184,"seq":105954722529},"cts":1776816015266}
{"topic":"orderbook.200.BTCUSDT","ts":1776816015369,"type":"delta","data":{"s":"BTCUSDT","b":[["76363.2","0.410698"]],"a":[],"u":28058185,"seq":105954722563},"cts":1776816015362}
{"topic":"orderbook.200.BTCUSDT","ts":1776816015469,"type":"delta","data":{"s":"BTCUSDT","b":[["76363.2","0.197978"],["76358.3","0"],["76358","0.006544"]],"a":[["76363.3","1.28568"],["76382.6","0.006545"],["76383.7","0"]],"u":28058186,"seq":105954722605},"cts":1776816015464}
{"topic":"orderbook.200.BTCUSDT","ts":1776816015569,"type":"delta","data":{"s":"BTCUSDT","b":[["76363.2","0.198628"],["76362","0.02352"],["76358","0"],["76356.2","0.006545"],["76343.1","0"],["76340.8","0.031456"],["76340.4","0"]],"a":[["76380.7","0.006545"],["76381.3","0.032456"],["76382.6","0"],["76399.7","0"],["76456.6","0.000542"]],"u":28058187,"seq":105954722689},"cts":1776816015565}
{"topic":"orderbook.200.BTCUSDT","ts":1776816015669,"type":"delta","data":{"s":"BTCUSDT","b":[["76363.2","0.167328"],["76362","0"],["76361","0.000198"],["76360.7","0.02352"],["76359.8","0.020133"],["76359.7","0.049712"],["76356.3","0.123809"],["76356.2","0"],["76355.3","0.006545"],["76343.1","0.130981"],["76223.6","0"],["76223.2","0"]],"a":[["76380.6","0.006545"],["76380.7","0"],["76383.7","0.010178"],["76399.6","0"],["76433.7","0.600672"],["76433.8","0.600232"],["76434.4","0.000181"],["76456.6","0"]],"u":28058188,"seq":105954722794},"cts":1776816015664}
{"topic":"orderbook.200.BTCUSDT","ts":1776816015771,"type":"delta","data":{"s":"BTCUSDT","b":[["76363.2","0.16109"],["76355.6","0.023745"],["76355.3","0"],["76223.6","0.714835"]],"a":[["76380.6","0"],["76380.7","0.006545"]],"u":28058189,"seq":105954722822},"cts":1776816015763}
{"topic":"orderbook.200.BTCUSDT","ts":1776816015869,"type":"delta","data":{"s":"BTCUSDT","b":[["76355.7","0.006545"],["76355.6","0.0172"],["76223.6","0"]],"a":[],"u":28058190,"seq":105954722852},"cts":1776816015868}
{"topic":"orderbook.200.BTCUSDT","ts":1776816015969,"type":"delta","data":{"s":"BTCUSDT","b":[["76361.3","0.02352"],["76360.7","0"],["76356.1","0.122501"],["76355.7","0"],["76223.6","0.714835"]],"a":[],"u":28058191,"seq":105954722869},"cts":1776816015963}
{"topic":"orderbook.200.BTCUSDT","ts":1776816016069,"type":"delta","data":{"s":"BTCUSDT","b":[["76356.2","0.006545"],["76356.1","0.115956"],["76223.6","0"]],"a":[["76406.8","0.031456"],["76456.2","0"]],"u":28058192,"seq":105954722894},"cts":1776816016051}
{"topic":"orderbook.200.BTCUSDT","ts":1776816016269,"type":"delta","data":{"s":"BTCUSDT","b":[["76361.9","0.009825"],["76361.8","0"]],"a":[["76363.3","1.28583"],["76370.7","0.03"],["76400.3","0.108527"],["76455.4","0"]],"u":28058193,"seq":105954722934},"cts":1776816016267}
{"topic":"orderbook.200.BTCUSDT","ts":1776816016369,"type":"delta","data":{"s":"BTCUSDT","b":[["76356.3","0.130354"],["76356.2","0"],["76223.6","0.714835"]],"a":[["76375","0.006545"],["76455.2","0"]],"u":28058194,"seq":105954722965},"cts":1776816016356}
{"topic":"orderbook.200.BTCUSDT","ts":1776816016469,"type":"delta","data":{"s":"BTCUSDT","b":[["76356.3","0.123809"],["76356.2","0.006545"],["76223.6","0"]],"a":[],"u":28058195,"seq":105954722982},"cts":1776816016467}
{"topic":"orderbook.200.BTCUSDT","ts":1776816016571,"type":"delta","data":{"s":"BTCUSDT","b":[],"a":[["76380.7","0"],["76381.1","0.006545"]],"u":28058196,"seq":105954723003},"cts":1776816016562}
{"topic":"orderbook.200.BTCUSDT","ts":1776816016668,"type":"delta","data":{"s":"BTCUSDT","b":[["76356.4","0.006545"],["76356.2","0"]],"a":[["76381.1","0"],["76381.2","0.039978"],["76455.2","0.00027"]],"u":28058197,"seq":105954723017},"cts":1776816016661}
{"topic":"orderbook.200.BTCUSDT","ts":1776816016769,"type":"delta","data":{"s":"BTCUSDT","b":[["76356.8","0.006545"],["76356.4","0"]],"a":[["76381.2","0.033433"],["76382.4","0.006545"],["76455.2","0"]],"u":28058198,"seq":105954723034},"cts":1776816016762}
{"topic":"orderbook.200.BTCUSDT","ts":1776816016869,"type":"delta","data":{"s":"BTCUSDT","b":[["76356.8","0"],["76356.4","0.006545"]],"a":[["76381.1","0.006545"],["76382.4","0"]],"u":28058199,"seq":105954723052},"cts":1776816016864}
{"topic":"orderbook.200.BTCUSDT","ts":1776816016969,"type":"delta","data":{"s":"BTCUSDT","b":[["76363.2","0.19109"]],"a":[],"u":28058200,"seq":105954723069},"cts":1776816016965}
{"topic":"orderbook.200.BTCUSDT","ts":1776816017169,"type":"delta","data":{"s":"BTCUSDT","b":[["76363.2","0.06489"],["76361.3","0"],["76359.8","0.013112"],["76359.7","0.026191"],["76357.8","0"],["76356.9","0.023521"],["76356.7","0"],["76356.4","0"],["76356.3","0.087805"],["76356","0.08901"],["76355.5","0"],["76354.7","0.004534"],["76353.1","0.025703"],["76353","0.02756"],["76347","0.028785"],["76344","0.199351"],["76343.1","0"],["76340.8","0"],["76340.3","0.031456"],["76337.2","0.08118"],["76337.1","0.162437"],["76337","0"],["76336.9","0"],["76223.6","0.714835"]],"a":[["76363.3","1.348549"],["76365.9","0"],["76370.5","0.006545"],["76370.6","0.057263"],["76371","0.126"],["76375","0"],["76378.5","0.006545"],["76381","0.077606"],["76381.1","0.130981"],["76381.2","0"],["76455","0"]],"u":28058201,"seq":105954723315},"cts":1776816017164}
{"topic":"orderbook.200.BTCUSDT","ts":1776816017269,"type":"delta","data":{"s":"BTCUSDT","b":[["76363.2","0.03489"],["76362.1","0.008375"],["76361.9","0"],["76356.9","0"],["76356.8","0.028048"],["76353.1","0.019158"],["76352.6","0.006545"],["76223.6","0"]],"a":[["76363.3","1.360379"],["76370.1","0.006545"],["76370.5","0"]],"u":28058202,"seq":105954723487},"cts":1776816017266}
{"topic":"orderbook.200.BTCUSDT","ts":1776816017371,"type":"delta","data":{"s":"BTCUSDT","b":[["76362.1","0"],["76362","0.008357"],["76352.6","0"],["76350.8","0.006545"]],"a":[["76370","0.008"],["76376.1","0.006546"],["76378.5","0"],["76454.7","0"]],"u":28058203,"seq":105954723606},"cts":1776816017370}
{"topic":"orderbook.200.BTCUSDT","ts":1776816017469,"type":"delta","data":{"s":"BTCUSDT","b":[["76363.2","0"],["76362.9","0"],["76362","0"],["76361","0"],["76359.8","0"],["76359.7","0"],["76358.2","0"],["76357.9","0"],["76356.8","0.0128"],["76356.5","0.008312"],["76356.3","0"],["76356.1","0"],["76356","0"],["76355.6","0"],["76355.4","0.002"],["76354.8","0.002"],["76354.7","0"],["76354.2","0"],["76354.1","0"],["76353.1","0"],["76353","0"],["76352.8","0"],["76352.5","0"],["76350.8","0"],["76350.4","0.015164"],["76349.8","0"],["76349.7","0.0004"],["76349.2","0.0128"],["76347.5","0"],["76347.3","0.025373"],["76347","0"],["76346.6","0.065488"],["76346","0.004534"],["76344.7","0.06551"],["76344","0.205897"],["76343","0"],["76341.4","0.004534"],["76340.7","0.030125"],["76340.3","0.001658"],["76340.2","0.026597"],["76337.2","0"],["76337.1","0"],["76336.4","0.003275"],["76335.6","0"],["76335.2","0.02409"],["76334.1","0.017178"],["76334","0.396886"],["76331.3","0"],["76330.5","0"],["76329","0.163437"],["76328.9","0.5"],["76327.2","0.006549"],["76326.8","0.01963"],["76326.6","0.015447"],["76326.2","0"],["76325.8","0"],["76322.8","0.130981"],["76319.7","0"],["76319.4","0.031456"],["76317.7","0"],["76316.3","0.162437"],["76316.2","0"],["76314.6","0"],["76313.3","0"],["76312.5","0.031456"],["76312.1","0"],["76311.5","0"],["76308.1","0.162437"],["76308","0"],["76307.9","0"],["76306.9","0"],["76304.8","0"],["76302.8","0"],["76297.5","0"],["76289.7","0.944997"],["76286.8","0"],["76274","0.031456"],["76270.4","0.031456"],["76268.7","0"],["76264.8","0.031456"],["76261.7","0.031456"],["76258.2","0.483971"],["76257","0.01963"],["76252.5","0.031456"],["76226","0.001146"],["76223.6","0.714835"],["76223.2","0.000099"],["76223","0.048439"],["76222.7","0.0001"],["76218.4","0.001"],["76217.6","0.001178"],["76217.2","0.005309"],["76215.5","0.130981"],["76214.6","0.126"],["76214.2","6.180768"],["76211","0.002357"],["76208.9","0.025633"],["76208.4","0.065507"],["76208.3","0.048439"],["76205.8","0.001178"],["76205.2","0.126"],["76204.8","0.130981"],["76201.6","0.006524"],["76200.4","0.006521"]],"a":[["76356.9","1.282567"],["76357.5","0.741443"],["76357.6","0.03"],["76357.9","0.067596"],["76358","0.06004"],["76358.3","0.073457"],["76359.8","0.023655"],["76360.9","0.006546"],["76361","0.144767"],["76361.1","0.2184"],["76361.4","0.007479"],["76362.9","0.126"],["76363.3","0.054368"],["76363.9","0"],["76364.5","0.0128"],["76364.9","0.045792"],["76365","0"],["76365.1","0.0004"],["76365.4","0"],["76366.2","0.001149"],["76367.9","0"],["76368.5","0.013092"],["76368.6","0.120406"],["76369.9","0.006547"],["76370.1","0.002"],["76370.2","0"],["76370.4","0.065463"],["76370.5","0.031456"],["76370.8","0.003178"],["76370.9","0"],["76372.3","0.065461"],["76372.5","0.032087"],["76372.7","0"],["76373.3","0.01963"],["76374.2","0.031456"],["76374.9","0.130981"],["76376","0.048439"],["76376.1","0"],["76380.8","0"],["76382.7","0"],["76383.7","0"],["76383.8","0.000099"],["76384.6","0"],["76392.1","0.396313"],["76399.9","0.623581"],["76405.4","0.013102"],["76406.6","0.200035"],["76407.8","0"],["76420.8","0"],["76421.1","0.3562"],["76422.3","0"],["76436.8","0"],["76452.2","0"],["76452.4","0"],["76452.7","0"],["76453.1","0"],["76453.2","0"],["76453.3","0"],["76453.4","0"],["76453.6","0"],["76453.8","0"],["76454","0"],["76454.3","0"],["76454.4","0"]],"u":28058204,"seq":105954724841},"cts":1776816017467}
{"topic":"orderbook.200.BTCUSDT","ts":1776816017569,"type":"delta","data":{"s":"BTCUSDT","b":[["76356.8","0"],["76356.5","0"],["76355.4","0"],["76354.8","0"],["76354.2","0.0282"],["76350.4","0"],["76350.3","0.008388"],["76349.7","0"],["76349.2","0"],["76347.4","0.048104"],["76347.3","0"],["76346.6","0.0152"],["76346","0"],["76344.8","0.034509"],["76344.7","0"],["76344","0"],["76342.8","0.028054"],["76342","0.013098"],["76341.6","0.004534"],["76341.4","0"],["76340.3","0"],["76340.1","0.065488"],["76338.1","0.06551"],["76337.6","0.004534"],["76336.1","0.001658"],["76335.2","0"],["76334.1","0.131498"],["76334","0"],["76333.5","0.006547"],["76333.4","0.024091"],["76331.1","0.126"],["76329","0.131981"],["76327.6","0.396886"],["76319.2","0"],["76316.6","0.367783"],["76315","0.039155"],["76311.2","0"],["76300.9","0.743111"],["76294.1","0.743177"],["76292.8","0"],["76289.8","0.285992"],["76289.2","0"],["76281.3","0.013102"],["76275.2","0.013103"],["76269.4","0.052898"],["76211","0"],["76200","0.007145"]],"a":[["76354.3","1.305846"],["76354.6","0.041223"],["76354.9","0.028919"],["76355.8","0.000198"],["76356.9","0.025278"],["76357.1","0.007479"],["76357.5","0"],["76357.6","0"],["76357.9","0"],["76358","0"],["76358.2","0.066556"],["76358.3","0.05"],["76359.8","0"],["76360.9","0.006547"],["76361","0.142767"],["76361.4","0"],["76361.9","0.0152"],["76362.1","0.023456"],["76362.4","0.013092"],["76363.3","0.081606"],["76364.3","0.065463"],["76364.5","0.01963"],["76365.1","0"],["76366.1","0.010177"],["76366.2","0.001"],["76366.3","0.065461"],["76367","0.031456"],["76368.5","0"],["76369.9","0"],["76370.1","0"],["76370.3","0.096403"],["76370.4","0"],["76370.6","0"],["76370.8","0.030408"],["76372.3","0"],["76372.5","0.066942"],["76373.3","0"],["76373.4","0.02923"],["76381","0.049167"],["76384.5","0"],["76394.4","0.01963"],["76397.7","0.013103"],["76403.8","0.139102"],["76405.3","0.013102"],["76406.8","0.109467"],["76407.7","0"],["76413.1","0"],["76419.2","0"],["76420.7","0"],["76422.2","0"],["76440.2","0.00055"],["76451.7","0.741646"],["76452.2","0.017644"]],"u":28058205,"seq":105954725792},"cts":1776816017568}
{"topic":"orderbook.200.BTCUSDT","ts":1776816017669,"type":"delta","data":{"s":"BTCUSDT","b":[["76354.2","0"],["76350.7","0"],["76350.3","0.0242"],["76350","0.00837"],["76347.4","0.028556"],["76346.6","0"],["76342.7","0.0132"],["76342","0.041152"],["76340.8","0.057633"],["76340.7","0"],["76338.2","0.022762"],["76336.5","0.006547"],["76334.1","0.090284"],["76333.8","0.126974"],["76333.5","0"],["76330.3","0.358803"],["76327.7","0.031456"],["76316.7","0.195882"],["76308.2","0.048487"],["76304","0.27715"],["76295.8","0.57021"],["76204.8","0"],["76201.6","0"],["76200.4","0"],["76200","0"]],"a":[["76350.4","1.45364"],["76350.8","0.05346"],["76352.3","0.028758"],["76354.1","0.047842"],["76354.3","0.083493"],["76354.6","0"],["76354.9","0"],["76356.8","0.006547"],["76356.9","0.023458"],["76358","0.0132"],["76358.4","0.10762"],["76360.9","0"],["76361","0.093332"],["76361.1","0"],["76361.9","0"],["76362.1","0"],["76362.8","0.006547"],["76364.9","0.028066"],["76366.9","0.02923"],["76368.6","0.000099"],["76370.3","0.065331"],["76373.4","0"],["76379.8","0"],["76385.6","0.037641"],["76391.6","0.137483"],["76391.8","0.031456"],["76399.8","0.294968"],["76400.3","0"],["76403.7","0.117159"],["76420.4","0.269561"],["76422.9","0.069454"],["76451.6","0"],["76451.7","0"],["76452.2","0"]],"u":28058206,"seq":105954726277},"cts":1776816017666}
{"topic":"orderbook.200.BTCUSDT","ts":1776816017769,"type":"delta","data":{"s":"BTCUSDT","b":[["76350.3","0.028421"],["76338.3","0.006547"],["76336.5","0"],["76319.3","0"],["76234","0.000439"],["76204.8","0.130981"]],"a":[["76350.4","1.459483"],["76354.1","0.028625"],["76354.3","0.081673"],["76362.8","0"],["76363.2","0.006547"],["76370.8","0.001178"],["76400.4","0"],["76437.3","0.120583"],["76451.6","0.000103"]],"u":28058207,"seq":105954726399},"cts":1776816017766}
{"topic":"orderbook.200.BTCUSDT","ts":1776816017869,"type":"delta","data":{"s":"BTCUSDT","b":[["76344.2","0.028053"],["76342.8","0"],["76282.9","0.024672"],["76204.8","0"]],"a":[["76350.4","1.464943"],["76350.5","0.017952"],["76350.6","0.031384"],["76355.7","0.006547"],["76356.8","0"],["76358.2","0.04705"],["76363.2","0"],["76363.3","0.08178"],["76364.2","0.006547"],["76382.4","0.013788"],["76389.9","0"],["76399.8","0.187978"],["76451.3","0"],["76451.6","0"]],"u":28058208,"seq":105954726517},"cts":1776816017859}
{"topic":"orderbook.200.BTCUSDT","ts":1776816017969,"type":"delta","data":{"s":"BTCUSDT","b":[["76338.4","0.006547"],["76338.3","0"],["76316.6","0"],["76204.8","0.130981"]],"a":[["76350.4","1.466763"],["76350.5","0.031615"],["76363.3","0.081606"]],"u":28058209,"seq":105954726640},"cts":1776816017956}
{"topic":"orderbook.200.BTCUSDT","ts":1776816018069,"type":"delta","data":{"s":"BTCUSDT","b":[["76338.7","0.006547"],["76338.4","0"],["76316.7","0.086098"],["76304.8","0.031456"],["76213.2","0.004553"],["76205.2","0"],["76204.8","0"]],"a":[["76350.4","1.467673"],["76355.7","0"],["76356.8","0.006547"]],"u":28058210,"seq":105954726675},"cts":1776816018062}
{"topic":"orderbook.200.BTCUSDT","ts":1776816018172,"type":"delta","data":{"s":"BTCUSDT","b":[["76339.5","0.006547"],["76338.7","0"],["76313.9","0.358637"],["76213.2","0"]],"a":[["76382.2","0.37206"],["76451.2","0"]],"u":28058211,"seq":105954726753},"cts":1776816018165}
{"topic":"orderbook.200.BTCUSDT","ts":1776816018269,"type":"delta","data":{"s":"BTCUSDT","b":[["76350.2","0.007162"],["76350","0"],["76335.1","0.010542"],["76315","0.141202"],["76205.8","0"]],"a":[["76350.4","1.460393"],["76381","0.158057"]],"u":28058212,"seq":105954726866},"cts":1776816018268}
{"topic":"orderbook.200.BTCUSDT","ts":1776816018369,"type":"delta","data":{"s":"BTCUSDT","b":[],"a":[["76350.4","1.464033"]],"u":28058213,"seq":105954726971},"cts":1776816018365}
{"topic":"orderbook.200.BTCUSDT","ts":1776816018468,"type":"delta","data":{"s":"BTCUSDT","b":[["76344.8","0.062562"],["76344.2","0"],["76339.5","0"],["76338.7","0.006547"],["76326.6","0.043176"],["76212.6","0.004781"]],"a":[],"u":28058214,"seq":105954727116},"cts":1776816018467}
{"topic":"orderbook.200.BTCUSDT","ts":1776816018569,"type":"delta","data":{"s":"BTCUSDT","b":[["76350.3","0.050421"],["76326.6","0.015447"]],"a":[],"u":28058215,"seq":105954727228},"cts":1776816018566}
{"topic":"orderbook.200.BTCUSDT","ts":1776816018668,"type":"delta","data":{"s":"BTCUSDT","b":[],"a":[["76350.4","1.461303"],["76354.3","0.023459"]],"u":28058216,"seq":105954727331},"cts":1776816018667}
{"topic":"orderbook.200.BTCUSDT","ts":1776816018769,"type":"delta","data":{"s":"BTCUSDT","b":[["76339.5","0.006547"],["76338.7","0"]],"a":[["76350.4","1.495923"],["76354.1","0.018251"]],"u":28058217,"seq":105954727436},"cts":1776816018760}
{"topic":"orderbook.200.BTCUSDT","ts":1776816018869,"type":"delta","data":{"s":"BTCUSDT","b":[["76344.8","0.034509"],["76343.6","0.028053"],["76208.3","0"]],"a":[["76350.4","1.496833"]],"u":28058218,"seq":105954727531},"cts":1776816018866}
{"topic":"orderbook.200.BTCUSDT","ts":1776816018971,"type":"delta","data":{"s":"BTCUSDT","b":[["76350.3","0.490398"],["76349.8","0.028051"],["76348.4","0.026195"],["76344.8","0.064377"],["76342.6","0.126"],["76342.1","0.006546"],["76342","0.013098"],["76339.5","0"],["76338.2","0.134019"],["76334.1","0.059784"],["76333.8","0"],["76333.4","0"],["76331.2","0.031456"],["76208.9","0"],["76208.4","0"]],"a":[["76350.4","1.005539"],["76350.8","0.02346"],["76356.8","0"],["76358.3","0.03"],["76360.9","0.006546"],["76363.3","0.03015"],["76364.2","0"],["76364.5","0"],["76366.1","0"],["76367","0"],["76368.5","0.006547"],["76369.9","0.01963"],["76370.5","0"],["76374.2","0"],["76374.9","0"],["76381.1","0"],["76451.2","0.000186"],["76451.3","0.130981"],["76451.6","0.000103"],["76451.7","0.741646"],["76452.2","0.017644"],["76452.4","0.000135"]],"u":28058219,"seq":105954727719},"cts":1776816018969}
{"topic":"orderbook.200.BTCUSDT","ts":1776816019069,"type":"delta","data":{"s":"BTCUSDT","b":[["76350.3","0.436699"],["76348.9","0.04815"],["76348.8","0.026594"],["76347.4","0"],["76346.5","0.028052"],["76346.4","0.004534"],["76344.8","0.094989"],["76342.2","0.104265"],["76342.1","0"],["76341.6","0"],["76340.9","0.004534"],["76340.8","0.037757"],["76340.2","0.008163"],["76338.2","0.022762"],["76337.6","0"],["76336.1","0"],["76326.6","0.043454"],["76323","0.100574"],["76212.6","0"]],"a":[["76350.4","0.716368"],["76350.5","0"],["76350.8","0"],["76352.3","0"],["76352.6","0.023459"],["76355.4","0.007693"],["76358.3","0"],["76360.7","0.006546"],["76360.8","0.024869"],["76360.9","0"],["76366.1","0.006546"],["76368.2","0.010399"],["76368.5","0"],["76370","0"],["76370.3","0.047216"],["76372.5","0.001"],["76375.9","0.014489"],["76378.1","0.031456"],["76380.9","0.130981"],["76394.4","0"],["76437.1","0.123861"],["76440.2","0.02018"],["76452.4","0"]],"u":28058220,"seq":105954727920},"cts":1776816019068}
{"topic":"orderbook.200.BTCUSDT","ts":1776816019169,"type":"delta","data":{"s":"BTCUSDT","b":[["76350.3","0.282273"],["76346.4","0"],["76343.6","0.032587"],["76343.3","0.006546"],["76340.2","0.001617"],["76317.6","0.03696"],["76258.2","0.133907"],["76214.2","0"]],"a":[["76350.4","0.967558"],["76350.6","0"],["76351.6","0.007693"],["76352.6","0"],["76353.6","0.007623"],["76354.1","0"],["76355.4","0"],["76356.9","0"],["76360.7","0.012"],["76362.3","0.006546"],["76366.1","0"],["76368.5","0.006546"],["76374.9","0.024959"],["76375","0.031456"],["76375.9","0"],["76452.4","0.000135"]],"u":28058221,"seq":105954728048},"cts":1776816019166}
{"topic":"orderbook.200.BTCUSDT","ts":1776816019269,"type":"delta","data":{"s":"BTCUSDT","b":[["76349.8","0"],["76349.5","0.026645"],["76348.8","0"],["76343.6","0.004534"],["76340.2","0"],["76339.4","0.035996"],["76336.2","0.001617"],["76214.2","6.180768"]],"a":[["76350.4","0.920981"],["76351.9","0.023459"],["76353.6","0"],["76360.7","0.006546"],["76362.3","0"],["76368.1","0.006546"],["76368.5","0"],["76452.7","0.00515"]],"u":28058222,"seq":105954728096},"cts":1776816019261}
{"topic":"orderbook.200.BTCUSDT","ts":1776816019369,"type":"delta","data":{"s":"BTCUSDT","b":[["76350.1","0.026645"],["76349.5","0"]],"a":[["76350.4","0.910628"],["76353.5","0.007623"],["76452.7","0"]],"u":28058223,"seq":105954728128},"cts":1776816019362}
{"topic":"orderbook.200.BTCUSDT","ts":1776816019469,"type":"delta","data":{"s":"BTCUSDT","b":[["76343.3","0"],["76341","0.006546"]],"a":[["76350.4","0.903348"],["76360.6","0.006546"],["76360.7","0"],["76366.1","0.006546"],["76368.1","0"]],"u":28058224,"seq":105954728208},"cts":1776816019466}
{"topic":"orderbook.200.BTCUSDT","ts":1776816019569,"type":"delta","data":{"s":"BTCUSDT","b":[["76350.3","0.288643"],["76342.3","0.006546"],["76341","0"]],"a":[["76350.4","0.728008"],["76360.6","0"],["76360.7","0.006546"],["76366.1","0"],["76368.1","0.006546"]],"u":28058225,"seq":105954728256},"cts":1776816019567}
{"topic":"orderbook.200.BTCUSDT","ts":1776816019669,"type":"delta","data":{"s":"BTCUSDT","b":[["76350.3","0.295923"],["76264.8","0.033735"]],"a":[["76350.4","0.903348"],["76374.6","0.064057"],["76374.7","0.130981"],["76374.9","0"],["76452.4","0"]],"u":28058226,"seq":105954728308},"cts":1776816019668}
{"topic":"orderbook.200.BTCUSDT","ts":1776816019771,"type":"delta","data":{"s":"BTCUSDT","b":[["76350.3","0.289553"],["76350.1","0"],["76348","0.026645"],["76344","0.023848"],["76342.8","0.006546"],["76342.3","0"],["76302.8","0.01963"],["76257","0"],["76214.2","0"]],"a":[["76362.8","0.012"],["76370.2","0.031456"],["76451.7","0"],["76452.2","0"]],"u":28058227,"seq":105954728363},"cts":1776816019770}
{"topic":"orderbook.200.BTCUSDT","ts":1776816019869,"type":"delta","data":{"s":"BTCUSDT","b":[["76350.3","0.282273"],["76343.3","0.006546"],["76342.8","0"]],"a":[],"u":28058228,"seq":105954728403},"cts":1776816019856}
{"topic":"orderbook.200.BTCUSDT","ts":1776816019969,"type":"delta","data":{"s":"BTCUSDT","b":[["76350.3","0.434598"]],"a":[["76353.8","0.018259"],["76353.9","0.030034"],["76451.3","0"],["76451.6","0"]],"u":28058229,"seq":105954728429},"cts":1776816019957}
{"topic":"orderbook.200.BTCUSDT","ts":1776816020069,"type":"delta","data":{"s":"BTCUSDT","b":[["76350.3","0.437328"],["76343.3","0"],["76342.9","0.006546"]],"a":[],"u":28058230,"seq":105954728467},"cts":1776816020066}
{"topic":"orderbook.200.BTCUSDT","ts":1776816020169,"type":"delta","data":{"s":"BTCUSDT","b":[["76350.3","0.447119"],["76342.9","0"],["76342.8","0.006546"]],"a":[],"u":28058231,"seq":105954728494},"cts":1776816020164}
{"topic":"orderbook.200.BTCUSDT","ts":1776816020269,"type":"delta","data":{"s":"BTCUSDT","b":[["76350.3","0.449849"],["76349.2","0.026645"],["76346.5","0"]],"a":[],"u":28058232,"seq":105954728526},"cts":1776816020266}
{"topic":"orderbook.200.BTCUSDT","ts":1776816020368,"type":"delta","data":{"s":"BTCUSDT","b":[["76350.3","0.450759"]],"a":[],"u":28058233,"seq":105954728548},"cts":1776816020367}
{"topic":"orderbook.200.BTCUSDT","ts":1776816020469,"type":"delta","data":{"s":"BTCUSDT","b":[["76350.3","0.458152"],["76350.2","0"],["76350","0.026645"],["76349.2","0"],["76345.9","0.004534"],["76344.9","0.006546"],["76343.6","0"],["76342.8","0"],["76214.2","6.180768"]],"a":[["76350.4","0.459083"],["76360.7","0"],["76362.8","0"],["76368.1","0"],["76368.2","0"],["76370.2","0"],["76370.6","0.006546"],["76370.9","0.031456"],["76374.4","0.060866"],["76374.5","0.162437"],["76374.6","0"],["76374.7","0"],["76375","0"],["76451.3","0.130981"],["76451.6","0.000103"],["76451.7","0.741646"],["76452.2","0.017644"]],"u":28058234,"seq":105954728701},"cts":1776816020465}
{"topic":"orderbook.200.BTCUSDT","ts":1776816020571,"type":"delta","data":{"s":"BTCUSDT","b":[["76350.3","0.459972"],["76344.9","0"],["76344.2","0.004534"],["76344.1","0.006545"],["76340.9","0"],["76340","0.001617"],["76336.2","0"]],"a":[["76350.4","0.416414"],["76350.8","0.024068"],["76351.6","0"],["76353.5","0"],["76353.8","0.02579"],["76356.2","0.007694"],["76356.6","0.007624"],["76369.8","0.006546"],["76370.6","0"],["76374.2","0.064057"],["76374.3","0.130981"],["76374.4","0"],["76374.5","0.031456"],["76451.7","0"],["76452.2","0"]],"u":28058235,"seq":105954728765},"cts":1776816020569}
{"topic":"orderbook.200.BTCUSDT","ts":1776816020669,"type":"delta","data":{"s":"BTCUSDT","b":[["76350.3","0.460882"],["76344.9","0.006546"],["76344.1","0"]],"a":[["76373.4","0.010048"],["76451.6","0"]],"u":28058236,"seq":105954728810},"cts":1776816020668}
{"topic":"orderbook.200.BTCUSDT","ts":1776816020769,"type":"delta","data":{"s":"BTCUSDT","b":[["76346.2","0.006546"],["76344.9","0"]],"a":[["76350.4","0.1434"],["76369.8","0"],["76371.6","0.006546"]],"u":28058237,"seq":105954728866},"cts":1776816020763}
{"topic":"orderbook.200.BTCUSDT","ts":1776816020869,"type":"delta","data":{"s":"BTCUSDT","b":[["76346.2","0"],["76344.9","0.006546"]],"a":[["76370.2","0.006546"],["76371.6","0"]],"u":28058238,"seq":105954728915},"cts":1776816020861}
{"topic":"orderbook.200.BTCUSDT","ts":1776816020969,"type":"delta","data":{"s":"BTCUSDT","b":[["76350.3","0.459972"],["76313.9","0"],["76212.6","0.004781"]],"a":[["76350.4","0.1976"],["76350.7","0.014187"],["76369.8","0.006546"],["76370.2","0"],["76451.3","0"]],"u":28058239,"seq":105954728958},"cts":1776816020957}
{"topic":"orderbook.200.BTCUSDT","ts":1776816021069,"type":"delta","data":{"s":"BTCUSDT","b":[["76350.3","0.460882"],["76315","0.039155"],["76258.2","0.235954"]],"a":[],"u":28058240,"seq":105954728971},"cts":1776816021049}
{"topic":"orderbook.200.BTCUSDT","ts":1776816021169,"type":"delta","data":{"s":"BTCUSDT","b":[["76350.3","0.459062"],["76321.3","0.334617"],["76212.6","0"]],"a":[["76369.8","0"],["76370.2","0.006546"]],"u":28058241,"seq":105954729015},"cts":1776816021144}
{"topic":"orderbook.200.BTCUSDT","ts":1776816021269,"type":"delta","data":{"s":"BTCUSDT","b":[["76350.3","0.460882"]],"a":[["76350.4","0.203584"],["76363.3","0.03"]],"u":28058242,"seq":105954729048},"cts":1776816021256}
{"topic":"orderbook.200.BTCUSDT","ts":1776816021371,"type":"delta","data":{"s":"BTCUSDT","b":[["76345","0.006546"],["76344.9","0"],["76330.3","0.218942"],["76328.9","0"],["76212.6","0.004781"]],"a":[["76350.4","0.149384"],["76350.7","0"],["76451.3","0.130981"]],"u":28058243,"seq":105954729087},"cts":1776816021360}
{"topic":"orderbook.200.BTCUSDT","ts":1776816021469,"type":"delta","data":{"s":"BTCUSDT","b":[["76345","0"],["76344.9","0.006546"],["76234","0.014898"]],"a":[["76350.7","0.014187"],["76451.3","0"]],"u":28058244,"seq":105954729114},"cts":1776816021435}
{"topic":"orderbook.200.BTCUSDT","ts":1776816021569,"type":"delta","data":{"s":"BTCUSDT","b":[["76264","0.193318"],["76212.6","0"]],"a":[],"u":28058245,"seq":105954729145},"cts":1776816021560}
{"topic":"orderbook.200.BTCUSDT","ts":1776816021669,"type":"delta","data":{"s":"BTCUSDT","b":[],"a":[["76350.4","0.203584"],["76369.8","0.006546"],["76370.2","0"]],"u":28058246,"seq":105954729177},"cts":1776816021664}
{"topic":"orderbook.200.BTCUSDT","ts":1776816021769,"type":"delta","data":{"s":"BTCUSDT","b":[["76335.1","0"],["76212.6","0.004781"]],"a":[["76350.4","0.203323"]],"u":28058247,"seq":105954729207},"cts":1776816021760}
{"topic":"orderbook.200.BTCUSDT","ts":1776816021869,"type":"delta","data":{"s":"BTCUSDT","b":[["76344.9","0"],["76344.3","0.006546"],["76323","0.098301"],["76264","0.198524"]],"a":[],"u":28058248,"seq":105954729228},"cts":1776816021858}
{"topic":"orderbook.200.BTCUSDT","ts":1776816022069,"type":"delta","data":{"s":"BTCUSDT","b":[["76350.3","0.454731"],["76345.9","0"],["76345.2","0.010399"],["76344.9","0.006546"],["76344.3","0"],["76344.2","0"],["76343.7","0.004534"],["76340.4","0.004534"],["76218.5","0.01799"],["76215.6","0.008995"],["76214.6","0"],["76214.2","0"],["76212.6","0"]],"a":[["76350.4","0.210854"],["76351.6","0.007694"],["76353.1","0.007624"],["76353.8","0.018259"],["76356.2","0"],["76356.6","0"]],"u":28058249,"seq":105954729313},"cts":1776816022044}
{"topic":"orderbook.200.BTCUSDT","ts":1776816022171,"type":"delta","data":{"s":"BTCUSDT","b":[["76350.3","0.447228"],["76346.5","0.004534"],["76344.9","0"],["76344.1","0.006546"],["76343.7","0"]],"a":[["76353.1","0"],["76355.8","0.007822"],["76451.3","0.130981"]],"u":28058250,"seq":105954729358},"cts":1776816022163}
{"topic":"orderbook.200.BTCUSDT","ts":1776816022269,"type":"delta","data":{"s":"BTCUSDT","b":[["76344.9","0.006546"],["76344.1","0"],["76218.6","0.008995"],["76215.7","0.008995"],["76215.6","0"],["76215.5","0"]],"a":[["76350.4","0.209503"]],"u":28058251,"seq":105954729394},"cts":1776816022248}
{"topic":"orderbook.200.BTCUSDT","ts":1776816022369,"type":"delta","data":{"s":"BTCUSDT","b":[["76258.2","0.377875"]],"a":[["76362.3","0.006546"],["76451.3","0"]],"u":28058252,"seq":105954729420},"cts":1776816022366}
{"topic":"orderbook.200.BTCUSDT","ts":1776816022869,"type":"delta","data":{"s":"BTCUSDT","b":[["76344.9","0"],["76344.1","0.006546"]],"a":[["76350.4","0.239503"]],"u":28058253,"seq":105954729534},"cts":1776816022856}
{"topic":"orderbook.200.BTCUSDT","ts":1776816023069,"type":"delta","data":{"s":"BTCUSDT","b":[["76283","0.008995"],["76215.7","0"]],"a":[["76350.4","0.209503"]],"u":28058254,"seq":105954729582},"cts":1776816023059}
{"topic":"orderbook.200.BTCUSDT","ts":1776816023169,"type":"delta","data":{"s":"BTCUSDT","b":[["76330.7","0.019637"],["76326.8","0"],["76302.8","0.019637"]],"a":[["76369.9","0"],["76375.7","0.019637"],["76440.2","0.039817"]],"u":28058255,"seq":105954729619},"cts":1776816023166}
{"topic":"orderbook.200.BTCUSDT","ts":1776816023269,"type":"delta","data":{"s":"BTCUSDT","b":[["76350.3","0.294903"]],"a":[["76350.4","0.485518"],["76369.8","0"],["76370.2","0.006546"]],"u":28058256,"seq":105954729665},"cts":1776816023262}
{"topic":"orderbook.200.BTCUSDT","ts":1776816023369,"type":"delta","data":{"s":"BTCUSDT","b":[["76350.3","0.407018"],["76350","0"],["76349.8","0.026909"],["76344.1","0"],["76343.4","0.006546"],["76264.1","0.083463"],["76262.7","0"]],"a":[["76350.4","0.455518"],["76360.9","0.006546"],["76362.3","0"],["76368.5","0.006546"],["76370.2","0"]],"u":28058257,"seq":105954729772},"cts":1776816023365}
{"topic":"orderbook.200.BTCUSDT","ts":1776816023469,"type":"delta","data":{"s":"BTCUSDT","b":[["76350.3","0.412478"],["76344","0.030394"],["76343.4","0"],["76215.7","0.008995"]],"a":[["76360.9","0"],["76362.3","0.006546"],["76368.5","0"],["76370.2","0.006546"]],"u":28058258,"seq":105954729809},"cts":1776816023465}
{"topic":"orderbook.200.BTCUSDT","ts":1776816023569,"type":"delta","data":{"s":"BTCUSDT","b":[["76350.3","0.412386"],["76344","0.023848"],["76343.3","0.006546"],["76215.7","0"]],"a":[["76350.4","0.443787"],["76360.7","0.006546"],["76362.3","0"],["76368.5","0.006546"],["76370.2","0"]],"u":28058259,"seq":105954729840},"cts":1776816023567}
{"topic":"orderbook.200.BTCUSDT","ts":1776816023969,"type":"delta","data":{"s":"BTCUSDT","b":[["76350.3","0.039535"],["76349.8","0"],["76348.9","0"],["76348.4","0"],["76348","0"],["76346.5","0"],["76346.2","0.023667"],["76345.2","0"],["76344.8","0.039003"],["76344","0"],["76343.9","0"],["76343.3","0"],["76342.6","0"],["76340.4","0"],["76340","0"],["76338.2","0.029308"],["76337","0.03161"],["76336.4","0.007809"],["76331.2","0"],["76330.7","0"],["76329","0.001"],["76326.6","0.015447"],["76323.1","0.031456"],["76323","0.000131"],["76322.9","0.019637"],["76322.8","0"],["76322.7","0"],["76322.6","0.116954"],["76321.3","0"],["76319.4","0"],["76316.8","0.130981"],["76316.3","0"],["76313.9","0.031456"],["76312.5","0"],["76308.3","0.162437"],["76308.1","0"],["76304.9","0.031456"],["76304.8","0"],["76302.8","0"],["76264","0"],["76257","0.019637"],["76215.7","0.008995"],["76215.6","0.008995"],["76215.5","0.130981"],["76214.6","0.126"],["76214.2","6.180768"],["76213.4","0.008995"],["76212.7","0.008995"],["76210.3","0.01799"],["76208.9","0.025633"],["76208.4","0.065507"],["76208.3","0.048439"],["76206.6","0.01799"],["76205.8","0.001178"],["76205.2","0.126"],["76204.8","0.130981"]],"a":[["76350.4","0.683197"],["76350.7","0.014385"],["76351.6","0"],["76352.4","0.007496"],["76355.7","0.006546"],["76355.8","0"],["76357.1","0"],["76360.7","0"],["76362.3","0.006547"],["76362.8","0.031456"],["76364.9","0.073493"],["76366.2","0.020637"],["76367.7","0.031456"],["76368.1","0.130981"],["76368.5","0"],["76375.7","0"],["76394.4","0.019637"],["76440.2","0.00055"],["76450.5","0.524867"],["76451.2","0"]],"u":28058260,"seq":105954730142},"cts":1776816023967}
{"topic":"orderbook.200.BTCUSDT","ts":1776816024069,"type":"delta","data":{"s":"BTCUSDT","b":[["76350.3","0.088474"],["76343.3","0.026197"],["76343.1","0.026912"],["76342.3","0.026912"],["76338.2","0.022762"],["76337.1","0.006546"],["76337","0.004534"],["76333.6","0.027077"],["76331.4","0.001608"],["76323.2","0.130981"],["76316.7","0"],["76308.2","0"],["76264.1","0"],["76237.7","0.076709"],["76214.3","0.204216"],["76208.4","0"],["76208.3","0"],["76206.6","0"],["76205.8","0"],["76205.2","0"],["76204.8","0"]],"a":[["76350.4","0.687747"],["76355.7","0"],["76357.9","0.006546"],["76362.3","0"],["76362.8","0.038003"],["76451.2","0.000186"]],"u":28058261,"seq":105954730383},"cts":1776816024066}
{"topic":"orderbook.200.BTCUSDT","ts":1776816024169,"type":"delta","data":{"s":"BTCUSDT","b":[["76350.3","0.027947"],["76350.2","0.00631"],["76344.8","0.057902"],["76343.1","0"],["76337.2","0.006546"],["76337.1","0"],["76321.3","0.322116"],["76208.9","0"]],"a":[["76350.4","0.696847"],["76357.8","0.011"],["76362.7","0.006547"],["76362.8","0.031456"],["76450.9","0"],["76451.2","0"]],"u":28058262,"seq":105954730533},"cts":1776816024166}
{"topic":"orderbook.200.BTCUSDT","ts":1776816024269,"type":"delta","data":{"s":"BTCUSDT","b":[["76350.3","0.034189"],["76350.2","0"],["76337.2","0"],["76337.1","0.006546"],["76208.9","0.025633"]],"a":[["76350.4","0.697"],["76357.7","0.006546"],["76357.9","0"],["76361","0.231329"],["76362.3","0.006547"],["76362.7","0"],["76364.8","0.542015"],["76450.7","0"]],"u":28058263,"seq":105954730638},"cts":1776816024267}
{"topic":"orderbook.200.BTCUSDT","ts":1776816024369,"type":"delta","data":{"s":"BTCUSDT","b":[["76350.3","0.027947"],["76350.2","0.006231"],["76338","0.024405"],["76337.1","0.006547"],["76252.3","0.298072"],["76210.3","0"],["76208.9","0"]],"a":[["76357.7","0.006547"],["76382.2","0"],["76450.7","0.629604"]],"u":28058264,"seq":105954730770},"cts":1776816024367}
{"topic":"orderbook.200.BTCUSDT","ts":1776816024469,"type":"delta","data":{"s":"BTCUSDT","b":[["76350.2","0.00622"],["76346.2","0"],["76344.8","0"],["76343.3","0"],["76342.3","0.035033"],["76340.8","0"],["76340.2","0.040785"],["76339.4","0.011"],["76338.7","0.010146"],["76338","0"],["76337.1","0"],["76337","0"],["76336.4","0.003275"],["76335.8","0.006547"],["76334.8","0.004534"],["76331.5","0.004534"],["76327.7","0"],["76326.6","0.061959"],["76322.9","0"],["76319.3","0.099673"],["76318.2","0.019637"],["76210.3","0.01799"],["76209.1","0.004592"]],"a":[["76350.4","0.704496"],["76352.4","0"],["76353.6","0.060634"],["76353.7","0.121156"],["76353.8","0"],["76357.7","0.014677"],["76358.2","0"],["76358.4","0"],["76362.2","0.006547"],["76362.3","0"],["76373.4","0"],["76380.8","0.053283"],["76381","0"],["76387.3","0.097376"],["76450.9","0.001395"],["76451.2","0.000186"]],"u":28058265,"seq":105954730996},"cts":1776816024467}
{"topic":"orderbook.200.BTCUSDT","ts":1776816024571,"type":"delta","data":{"s":"BTCUSDT","b":[["76350.3","0"],["76350.2","0"],["76347.2","0"],["76346.1","0.09641"],["76342.7","0"],["76338.7","0"],["76338.5","0.0092"],["76336","0.004534"],["76335.8","0"],["76335.6","0.024921"],["76334.8","0"],["76333.6","0"],["76332.4","0.024407"],["76332.3","0.004534"],["76331.5","0"],["76330.5","0.006547"],["76327.2","0"],["76327","0.02708"],["76319.3","0"],["76300.9","0"],["76287.2","0.743244"],["76209.1","0"],["76208.9","0.025633"],["76208.4","0.065507"],["76208.3","0.048439"],["76206.6","0.01799"],["76205.8","0.001178"]],"a":[["76346.2","1.28033"],["76347.2","0.014921"],["76347.3","0.029064"],["76348.1","0.014377"],["76350","0.006547"],["76350.1","0.056265"],["76350.4","0.063633"],["76350.7","0.000198"],["76350.8","0"],["76351.9","0"],["76353.6","0.077804"],["76353.8","0.0132"],["76353.9","0.126"],["76357.7","0.006547"],["76358","0"],["76359","0.001178"],["76360.8","0.039127"],["76360.9","0.130981"],["76362.2","0"],["76362.7","0.02909"],["76363","0.010472"],["76366.9","0"],["76374.3","0.449824"],["76392.1","0.400775"],["76402.7","0.013104"],["76444.8","0.741815"],["76449.6","0"],["76450","0"],["76450.5","0"],["76450.6","0"],["76450.7","0"],["76450.9","0"],["76451.2","0"]],"u":28058266,"seq":105954731706},"cts":1776816024570}
{"topic":"orderbook.200.BTCUSDT","ts":1776816024669,"type":"delta","data":{"s":"BTCUSDT","b":[["76338","0.026913"],["76332.5","0.006547"],["76332.1","0.010234"],["76330.5","0"],["76317.6","0"],["76304","0.063442"],["76287.3","0.263679"],["76286.9","0"],["76284.6","0.031456"],["76284.5","0"]],"a":[["76346.2","1.31495"],["76350","0"],["76350.1","0.044302"],["76353.5","0.006547"],["76357.7","0"],["76358.9","0.006547"],["76411.5","0.022096"],["76444.7","0.503521"],["76444.9","0"]],"u":28058267,"seq":105954731914},"cts":1776816024665}
{"topic":"orderbook.200.BTCUSDT","ts":1776816024768,"type":"delta","data":{"s":"BTCUSDT","b":[["76346.1","0.150774"],["76341.7","0.026912"],["76341.4","0.026198"],["76338","0"],["76334.2","0.006547"],["76332.5","0"],["76327.7","0.031456"],["76327","0"],["76205.8","0"]],"a":[["76346.2","1.323304"]],"u":28058268,"seq":105954732014},"cts":1776816024767}
{"topic":"orderbook.200.BTCUSDT","ts":1776816024869,"type":"delta","data":{"s":"BTCUSDT","b":[["76335.4","0"],["76323.6","0"],["76311.8","0.048439"],["76300","0"],["76288.2","0"],["76276.4","0"],["76264.7","0"],["76252.9","0"],["76241.1","0"],["76229.3","0"],["76217.6","0"],["76205.2","0.126"],["76204.8","0.130981"],["76201.7","0.01799"],["76201.6","0.006524"],["76200.4","0.006521"],["76200","0.007145"],["76199.6","0.176737"],["76198.7","0.6"],["76198.1","0.082685"],["76197","0.126"]],"a":[["76358.9","0"],["76359","0"],["76360.7","0.006547"],["76370.8","0"],["76382.5","0"],["76394.3","0"],["76406.1","0"],["76417.9","0"],["76429.6","0"],["76441.4","0"],["76449.6","0.000016"],["76450","0.067061"],["76450.5","0.524867"],["76450.6","0.979434"],["76450.7","0.629604"],["76450.9","0.001395"],["76451.2","0.000186"],["76451.3","0.130981"]],"u":28058269,"seq":105954732191},"cts":1776816024859}
{"topic":"orderbook.200.BTCUSDT","ts":1776816024969,"type":"delta","data":{"s":"BTCUSDT","b":[["76346.1","0.096574"],["76341.7","0"],["76341.4","0"],["76341.2","0.026912"],["76196.2","0.145575"]],"a":[["76430.9","0.12"],["76451.3","0"]],"u":28058270,"seq":105954732278},"cts":1776816024964}
{"topic":"orderbook.200.BTCUSDT","ts":1776816025069,"type":"delta","data":{"s":"BTCUSDT","b":[["76346.1","0.150774"],["76341.2","0"],["76341","0.026198"],["76335.6","0"],["76334.2","0"],["76333.4","0.006547"],["76332.4","0"],["76328.7","0.027079"],["76195.6","0.130981"]],"a":[["76353.4","0.006547"],["76353.5","0"],["76360.6","0.006547"],["76360.7","0"],["76360.8","0"],["76360.9","0"],["76448.4","0"],["76451.3","0.130981"],["76451.6","0.000103"],["76451.7","0.741646"]],"u":28058271,"seq":105954732463},"cts":1776816025066}
{"topic":"orderbook.200.BTCUSDT","ts":1776816025169,"type":"delta","data":{"s":"BTCUSDT","b":[["76346.1","0.096574"],["76334.2","0.006547"],["76333.4","0"],["76301.5","0.03036"],["76234.8","0"],["76201","0.006284"],["76195.6","0"]],"a":[["76360.6","0"],["76360.9","0.006547"]],"u":28058272,"seq":105954732511},"cts":1776816025159}
{"topic":"orderbook.200.BTCUSDT","ts":1776816025269,"type":"delta","data":{"s":"BTCUSDT","b":[["76321.3","0"],["76195.6","0.130981"]],"a":[["76353.4","0"],["76353.5","0.006547"],["76374.3","0.130981"]],"u":28058273,"seq":105954732540},"cts":1776816025253}
{"topic":"orderbook.200.BTCUSDT","ts":1776816025371,"type":"delta","data":{"s":"BTCUSDT","b":[["76343.2","0.02413"],["76318.3","0.08257"],["76264.9","0.034274"],["76214.3","0"],["76195.6","0"]],"a":[],"u":28058274,"seq":105954732587},"cts":1776816025370}
{"topic":"orderbook.200.BTCUSDT","ts":1776816025468,"type":"delta","data":{"s":"BTCUSDT","b":[["76346.1","0.095224"],["76343.2","0.000099"],["76342.6","0.024031"],["76312.7","0.331553"],["76197","0"],["76196.2","0"]],"a":[["76346.2","1.322304"],["76347.2","0"],["76348.1","0"],["76452.2","0.017644"],["76452.4","0.000135"]],"u":28058275,"seq":105954732747},"cts":1776816025464}
{"topic":"orderbook.200.BTCUSDT","ts":1776816025569,"type":"delta","data":{"s":"BTCUSDT","b":[["76258.1","1.940977"],["76207.3","0.004668"],["76198.1","0"]],"a":[["76370.3","0.371679"],["76392.1","0.396313"]],"u":28058276,"seq":105954732859},"cts":1776816025556}
{"topic":"orderbook.200.BTCUSDT","ts":1776816025668,"type":"delta","data":{"s":"BTCUSDT","b":[["76346.1","0.149424"]],"a":[["76346.2","1.352923"]],"u":28058277,"seq":105954732924},"cts":1776816025667}
{"topic":"orderbook.200.BTCUSDT","ts":1776816025769,"type":"delta","data":{"s":"BTCUSDT","b":[["76346.1","0.095224"],["76342.6","0"],["76198.1","0.082685"]],"a":[["76353.5","0"],["76452.7","0.00515"]],"u":28058278,"seq":105954733010},"cts":1776816025767}
{"topic":"orderbook.200.BTCUSDT","ts":1776816025869,"type":"delta","data":{"s":"BTCUSDT","b":[["76335.8","0.006547"],["76334.2","0"]],"a":[],"u":28058279,"seq":105954733078},"cts":1776816025864}
{"topic":"orderbook.200.BTCUSDT","ts":1776816025969,"type":"delta","data":{"s":"BTCUSDT","b":[["76346.1","0.521635"],["76342.6","0.024031"],["76339.5","0.006547"],["76335.8","0"],["76331.2","0.031456"],["76330.4","0.131981"],["76328.7","0"],["76198.1","0"]],"a":[["76346.2","0.688873"],["76347.3","0"],["76350.1","0.025248"],["76350.4","0.013633"],["76353.6","0.054087"],["76353.9","0"],["76357.8","0"],["76357.9","0.028332"],["76360.9","0"],["76362.8","0"],["76363","0"],["76364.2","0.006546"],["76364.9","0.028066"],["76367.7","0"],["76368.1","0"],["76370.2","0.031456"],["76370.9","0"],["76374.1","0.031456"],["76374.2","0"],["76374.3","0"],["76374.5","0"],["76378","0.031456"],["76378.1","0"],["76380.7","0.130981"],["76380.8","0"],["76380.9","0"],["76381.3","0.001"],["76384.4","0"],["76387.2","0.162437"],["76387.8","0"],["76387.9","0"],["76453.1","0.000412"],["76453.2","0.000219"],["76453.3","0.038625"],["76453.4","0.126172"],["76453.6","0.000342"],["76453.8","0.024672"],["76454","0.000859"],["76454.3","0.0001"],["76454.4","0.001373"],["76454.7","0.0001"],["76455","0.000078"]],"u":28058280,"seq":105954733279},"cts":1776816025968}
{"topic":"orderbook.200.BTCUSDT","ts":1776816026069,"type":"delta","data":{"s":"BTCUSDT","b":[["76345.5","0.02503"],["76340.3","0.006546"],["76339.5","0"],["76338.4","0.004731"],["76336","0"],["76335.5","0.004765"],["76332.3","0"],["76326.7","0.019637"],["76318.2","0"],["76302.8","0.019637"],["76257","0"]],"a":[["76346.2","0.681247"],["76346.5","0.026618"],["76347.2","0.026618"],["76357.9","0"],["76364.2","0"],["76364.7","0.006546"],["76370.2","0.175173"],["76370.3","0.324463"],["76374.5","0.130981"],["76454.7","0"],["76455","0"]],"u":28058281,"seq":105954733325},"cts":1776816026068}
{"topic":"orderbook.200.BTCUSDT","ts":1776816026171,"type":"delta","data":{"s":"BTCUSDT","b":[["76346.1","0.79731"],["76341.1","0.006546"],["76340.3","0"]],"a":[["76346.2","0.650628"],["76348.7","0.007539"],["76348.9","0.001129"],["76350.4","0.01348"],["76364.7","0"],["76368.5","0.006546"],["76394.4","0"],["76440.2","0.020187"],["76454.4","0"]],"u":28058282,"seq":105954733386},"cts":1776816026157}
{"topic":"orderbook.200.BTCUSDT","ts":1776816026269,"type":"delta","data":{"s":"BTCUSDT","b":[["76346.1","0.521635"],["76342.4","0.006546"],["76341.1","0"],["76341","0.030929"],["76338.4","0"],["76312.7","0"],["76198.1","0.082685"],["76197","0.126"]],"a":[["76346.2","0.650778"],["76350.4","0.007496"],["76364.7","0.031456"],["76368.8","0.01029"],["76454","0"],["76454.3","0"]],"u":28058283,"seq":105954733432},"cts":1776816026258}
{"topic":"orderbook.200.BTCUSDT","ts":1776816026369,"type":"delta","data":{"s":"BTCUSDT","b":[["76346.1","0.608197"],["76342.7","0.006546"],["76342.4","0"],["76308.4","0.048487"],["76283","0.059368"],["76258.2","0.537667"],["76237.7","0"]],"a":[["76346.2","0.637128"],["76350","0.018973"],["76353.2","0.030619"],["76361","0.093332"],["76364.8","0"],["76374.4","0.054667"],["76430.8","0.044272"],["76453.4","0"],["76453.6","0"],["76453.8","0"]],"u":28058284,"seq":105954733491},"cts":1776816026358}
{"topic":"orderbook.200.BTCUSDT","ts":1776816026469,"type":"delta","data":{"s":"BTCUSDT","b":[["76346.1","0.535285"],["76342.7","0"],["76341.1","0.006546"],["76320.1","0.331799"],["76197","0"]],"a":[["76346.2","0.607128"],["76368.4","0.006546"],["76368.5","0"]],"u":28058285,"seq":105954733552},"cts":1776816026463}
{"topic":"orderbook.200.BTCUSDT","ts":1776816026569,"type":"delta","data":{"s":"BTCUSDT","b":[["76346.1","0.527095"],["76342.7","0.006546"],["76341.1","0"],["76332.1","0"],["76197","0.126"]],"a":[["76368.4","0"],["76368.5","0.006546"]],"u":28058286,"seq":105954733591},"cts":1776816026563}
{"topic":"orderbook.200.BTCUSDT","ts":1776816026669,"type":"delta","data":{"s":"BTCUSDT","b":[["76346.1","0.538445"],["76342.2","0.114525"],["76335.2","0.001385"],["76331.4","0"]],"a":[["76346.2","0.599432"],["76350.4","0.015235"]],"u":28058287,"seq":105954733631},"cts":1776816026660}
{"topic":"orderbook.200.BTCUSDT","ts":1776816026769,"type":"delta","data":{"s":"BTCUSDT","b":[["76346.1","0.539355"]],"a":[],"u":28058288,"seq":105954733646},"cts":1776816026761}
{"topic":"orderbook.200.BTCUSDT","ts":1776816026869,"type":"delta","data":{"s":"BTCUSDT","b":[["76336.3","0.000984"],["76326.5","0.049423"],["76316.6","0.000984"],["76306.8","0.000984"],["76296.9","0.000984"],["76287.1","0.000984"],["76277.3","0.000984"],["76267.4","0.000984"],["76257.6","0.000984"],["76247.7","0.000984"],["76237.9","0.000984"],["76228","0.000984"],["76218.2","0.000984"],["76208.4","0.066491"],["76206.6","0"],["76205.2","0"],["76204.8","0"],["76201.7","0"],["76201.6","0"],["76201","0"],["76200.4","0"],["76200","0"],["76199.6","0"],["76198.7","0"],["76198.1","0"],["76197","0"]],"a":[["76356.1","0.000984"],["76365.9","0.000984"],["76375.8","0.000984"],["76385.6","0.038625"],["76395.5","0.000984"],["76405.3","0.014086"],["76415.1","0.000984"],["76425","0.000984"],["76434.8","0.000984"],["76444.7","0.504505"],["76451.7","0"],["76452.2","0"],["76452.4","0"],["76452.7","0"],["76453.1","0"],["76453.2","0"],["76453.3","0"]],"u":28058289,"seq":105954733704},"cts":1776816026863}
{"topic":"orderbook.200.BTCUSDT","ts":1776816026971,"type":"delta","data":{"s":"BTCUSDT","b":[["76346.1","0.533205"],["76342.7","0"],["76342.4","0.006546"]],"a":[],"u":28058290,"seq":105954733788},"cts":1776816026964}
{"topic":"orderbook.200.BTCUSDT","ts":1776816027169,"type":"delta","data":{"s":"BTCUSDT","b":[["76337.3","0.026914"],["76207.3","0"]],"a":[],"u":28058291,"seq":105954733800},"cts":1776816027167}
{"topic":"orderbook.200.BTCUSDT","ts":1776816027468,"type":"delta","data":{"s":"BTCUSDT","b":[["76346.1","0.555205"],["76342.4","0"],["76341.1","0.006546"],["76322.6","0.201043"],["76252.3","0.021587"]],"a":[["76346.2","0.599294"],["76380.6","0.043542"],["76451.6","0"]],"u":28058292,"seq":105954733847},"cts":1776816027461}
{"topic":"orderbook.200.BTCUSDT","ts":1776816027570,"type":"delta","data":{"s":"BTCUSDT","b":[["76356","0.436555"],["76355.1","0.02832"],["76354.1","0.006545"],["76353.1","0.034494"],["76351.9","0.004751"],["76351.5","0.126"],["76351.1","0.05"],["76348.8","0.026167"],["76348.6","0.013098"],["76348.4","0.0092"],["76347.2","0.027764"],["76346.8","0.026196"],["76346.7","0.065488"],["76346.5","0.107472"],["76346.2","0.000984"],["76346.1","0.129498"],["76345.5","0.001"],["76344.8","0.06551"],["76342.6","0"],["76342","0"],["76341.1","0"],["76341","0"],["76340.3","0.031456"],["76340.1","0"],["76338.5","0"],["76338.2","0.038266"],["76338.1","0"],["76337.3","0"],["76336.8","0.048439"],["76336.7","0.019637"],["76335.5","0"],["76335.2","0"],["76334.5","0.396886"],["76327.6","0"],["76326.7","0"],["76319.3","0.097087"],["76282.9","0.037774"],["76258.2","0.377875"],["76215.5","0"],["76214.6","0"],["76214.2","0"],["76213.4","0"],["76212.7","0"],["76210.3","0"],["76208.9","0"],["76208.4","0"],["76208.3","0"]],"a":[["76346.2","0"],["76346.5","0"],["76347.2","0"],["76348.7","0"],["76348.9","0"],["76350","0"],["76350.1","0"],["76350.4","0"],["76350.7","0"],["76353.2","0"],["76353.6","0"],["76353.7","0"],["76353.8","0"],["76354.3","0"],["76356.1","0.310299"],["76358.1","0.03785"],["76358.2","0.026198"],["76361","0.023548"],["76362.4","0"],["76362.7","0"],["76362.9","0"],["76363","0.027628"],["76363.3","0"],["76363.7","0.0152"],["76364.3","0"],["76364.5","0.005366"],["76364.6","0.005026"],["76364.7","0"],["76365.3","0.005228"],["76366.2","0.001"],["76366.3","0"],["76367.3","0.013092"],["76368.5","0"],["76368.8","0"],["76369.2","0.065463"],["76370.2","0.052726"],["76370.3","0.005181"],["76371.1","0.065461"],["76374.1","0.073031"],["76374.2","0.130981"],["76374.3","0.031456"],["76374.4","0"],["76374.5","0"],["76375.1","0.029701"],["76380.6","0.050088"],["76383.7","0.019637"],["76387.3","0"],["76397.7","0"],["76411.5","0.013101"],["76451.6","0.000103"],["76451.7","0.741646"],["76452.2","0.017644"],["76452.4","0.000135"],["76452.7","0.00515"],["76453.1","0.000412"],["76453.2","0.000219"],["76453.3","0.038625"],["76453.4","0.126172"],["76453.6","0.000342"],["76453.8","0.024672"],["76454","0.000859"],["76454.3","0.0001"],["76454.4","0.001373"]],"u":28058293,"seq":105954735083},"cts":1776816027567}
{"topic":"orderbook.200.BTCUSDT","ts":1776816027669,"type":"delta","data":{"s":"BTCUSDT","b":[["76356","0.445677"],["76354.1","0"],["76353.1","0.040135"],["76352","0.006545"],["76348.4","0.0112"],["76347.3","0.074604"],["76346.5","0"],["76346.1","0.127938"],["76344.9","0.05377"],["76342.3","0"],["76340.4","0.027598"],["76340.2","0"],["76334.6","0.031456"],["76330.3","0"],["76292.8","0.008995"],["76258.2","0.543039"],["76215.6","0"]],"a":[["76356.1","0.326311"],["76356.3","0.001528"],["76358.1","0"],["76361","0.015985"],["76363.7","0.0172"],["76364.9","0"],["76369.1","0.087492"],["76370.2","0"],["76372.6","0.02908"],["76377.9","0.006545"],["76380.6","0.043542"],["76454.4","0"]],"u":28058294,"seq":105954735178},"cts":1776816027666}
{"topic":"orderbook.200.BTCUSDT","ts":1776816027772,"type":"delta","data":{"s":"BTCUSDT","b":[["76353.1","0.039225"],["76352","0"],["76348.9","0.006545"]],"a":[["76356.1","0.504381"],["76361.4","0.005366"],["76364.5","0"],["76369.6","0.118418"],["76371","0.157456"],["76375.1","0.000621"],["76375.7","0.006546"],["76377.9","0"],["76380.3","0.326025"],["76454","0"],["76454.3","0"]],"u":28058295,"seq":105954735253},"cts":1776816027770}
{"topic":"orderbook.200.BTCUSDT","ts":1776816027869,"type":"delta","data":{"s":"BTCUSDT","b":[["76356","0.166464"],["76353.2","0.028321"],["76352.6","0.004765"],["76351.4","0.027564"],["76218.2","0"],["76217.2","0"],["76215.7","0"]],"a":[["76356.1","0.505291"],["76356.2","0.02428"],["76356.3","0.028944"],["76358.8","0.026198"],["76361.8","0.005025"],["76364.6","0"],["76369.1","0.233682"],["76371","0.549174"],["76375","0.006546"],["76375.7","0"],["76453.6","0"],["76453.8","0"]],"u":28058296,"seq":105954735331},"cts":1776816027866}
{"topic":"orderbook.200.BTCUSDT","ts":1776816027968,"type":"delta","data":{"s":"BTCUSDT","b":[["76355.6","0.02832"],["76355.1","0"],["76353.1","0.034494"],["76351.5","0"],["76350.7","0.004731"],["76348.8","0.022"],["76340.7","0.05582"],["76340.6","0.126"],["76340.4","0"],["76340.3","0"]],"a":[["76356.1","0.512928"],["76361.2","0.005227"],["76365.3","0"],["76365.5","0.005181"],["76370.3","0"],["76374.1","0.079577"],["76375","0"],["76453.6","0.000342"]],"u":28058297,"seq":105954735391},"cts":1776816027964}
{"topic":"orderbook.200.BTCUSDT","ts":1776816028069,"type":"delta","data":{"s":"BTCUSDT","b":[["76356","0.159342"],["76353.1","0"],["76352.6","0"],["76351.9","0"],["76349.3","0.004765"],["76348.9","0"],["76347.5","0.004751"],["76345.8","0.006545"],["76344.4","0.004172"]],"a":[["76358","0.005366"],["76359.4","0.005025"],["76361.4","0"],["76361.8","0"],["76365.2","0.043684"],["76365.3","0.125988"],["76369.6","0"],["76371","0.55572"],["76374.1","0.073031"],["76374.6","0.010292"],["76388.6","0.03"],["76453.3","0"],["76453.4","0"],["76453.6","0"]],"u":28058298,"seq":105954735512},"cts":1776816028068}
{"topic":"orderbook.200.BTCUSDT","ts":1776816028169,"type":"delta","data":{"s":"BTCUSDT","b":[["76356","0.033544"],["76355.6","0"],["76353.2","0"],["76351.4","0"],["76351.1","0.02"],["76350.7","0"],["76349.3","0"],["76347.9","0.004731"],["76345.8","0"],["76344.4","0"],["76343.3","0.006545"],["76342.9","0.025054"],["76329.4","0.006549"],["76218.2","0.000984"],["76217.2","0.005309"],["76215.7","0.008995"]],"a":[["76356.1","0.523319"],["76357.2","0.005227"],["76358","0"],["76359.4","0"],["76361.1","0.005181"],["76361.2","0"],["76365.5","0"],["76369","0.006546"],["76371","0.549174"],["76453.3","0.038625"]],"u":28058299,"seq":105954735735},"cts":1776816028168}
{"topic":"orderbook.200.BTCUSDT","ts":1776816028269,"type":"delta","data":{"s":"BTCUSDT","b":[["76356","0.0242"],["76354.5","0.011147"],["76351.1","0"],["76347.9","0.028323"],["76347.5","0.04"],["76346.1","0.132703"],["76345","0.004731"],["76343.5","0.004751"],["76343.3","0"],["76342.2","0.104265"],["76341.4","0.006546"],["76341.3","0.025054"],["76340.7","0.078863"],["76339.7","0.004172"],["76338.2","0.1352"],["76336.7","0"],["76334.6","0"],["76330.4","0.001"],["76327.7","0"],["76327.2","0.019637"],["76326.3","0.031456"],["76323.3","0.130981"],["76323.2","0"],["76218.2","0"],["76217.2","0"],["76215.7","0"]],"a":[["76356.1","0.524236"],["76361","0.047752"],["76361.4","0.116438"],["76365.2","0"],["76365.3","0"],["76367.2","0.006546"],["76369","0"],["76374.1","0.092668"],["76383.7","0"],["76453.4","0.126172"],["76453.6","0.000342"]],"u":28058300,"seq":105954735995},"cts":1776816028259}
{"topic":"orderbook.200.BTCUSDT","ts":1776816028369,"type":"delta","data":{"s":"BTCUSDT","b":[["76347.9","0"],["76347.2","0.000198"],["76345.1","0.02468"],["76341.4","0.027568"],["76341.3","0"],["76340.8","0.006546"],["76336","0.025056"],["76218.4","0"]],"a":[["76356.1","0.545319"],["76358.1","0.006546"],["76365.8","0.006547"],["76367.2","0"],["76453.6","0"]],"u":28058301,"seq":105954736148},"cts":1776816028365}
{"topic":"orderbook.200.BTCUSDT","ts":1776816028469,"type":"delta","data":{"s":"BTCUSDT","b":[["76356","0"],["76354.5","0"],["76348.8","0"],["76348.6","0"],["76348.4","0"],["76347.5","0"],["76347.3","0"],["76347.2","0"],["76346.8","0"],["76346.7","0"],["76346.2","0"],["76346.1","0.084738"],["76345.1","0"],["76345","0"],["76344.9","0"],["76344.8","0"],["76343.5","0"],["76343.2","0"],["76342.9","0"],["76342.2","0.104463"],["76341.4","0"],["76341.2","0.0004"],["76341.1","0.002"],["76340.8","0"],["76340.7","0"],["76340.6","0"],["76339.9","0.002"],["76339.7","0"],["76338.5","0.0068"],["76336.8","0"],["76336.4","0.068785"],["76336","0"],["76334.5","0"],["76334","0.004765"],["76332","0.024684"],["76331.2","0"],["76330.3","0.058461"],["76330.1","0.004731"],["76329.4","0"],["76328.6","0.004172"],["76328.5","0.006546"],["76327.2","0"],["76326.6","0.015447"],["76326.3","0"],["76326.1","0.396886"],["76323.3","0"],["76323.1","0"],["76321.2","0"],["76319.3","0"],["76319.2","0.00655"],["76318.7","0.019637"],["76311.6","0.391274"],["76302.8","0"],["76292.8","0"],["76285.1","0"],["76282.9","0.024672"],["76281.3","0"],["76274.7","0.013104"],["76273.2","0.013104"],["76257","0.019637"],["76218.4","0.001"],["76218.2","0.000984"],["76217.2","0.005309"],["76215.7","0.008995"],["76215.6","0.008995"],["76215.5","0.130981"],["76214.6","0.126"],["76214.2","6.180768"],["76213.4","0.008995"],["76212.7","0.008995"],["76210.3","0.01799"],["76208.9","0.025633"],["76208.4","0.066491"],["76208.3","0.048439"],["76207.3","0.004668"],["76206.6","0.01799"],["76205.2","0.126"],["76204.8","0.130981"],["76201.7","0.01799"],["76201.6","0.006524"],["76201","0.006284"]],"a":[["76346.2","1.428452"],["76346.3","0.555807"],["76347.1","0.005181"],["76348.7","0.002"],["76348.9","0.169819"],["76350.3","0.013914"],["76353.8","0.0088"],["76354.4","0.006547"],["76354.5","0.102864"],["76354.6","0.155416"],["76355.2","0.002"],["76356.1","0.20126"],["76356.2","0"],["76356.3","0.001528"],["76356.4","0.002"],["76356.5","0.0004"],["76357.2","0"],["76358.1","0"],["76358.2","0"],["76358.8","0"],["76360.9","0.031456"],["76361","0.015985"],["76361.1","0"],["76361.4","0"],["76362.9","0.013092"],["76363","0.004"],["76363.7","0"],["76364.7","0.031456"],["76364.8","0.065463"],["76365.4","0.02908"],["76365.6","0.019637"],["76365.7","0.01"],["76365.8","0"],["76366.7","0.065461"],["76367.3","0"],["76367.8","0.048517"],["76367.9","0.031456"],["76368","0.130981"],["76369.2","0"],["76371.1","0"],["76374.1","0.073031"],["76374.6","0"],["76380.2","0.14086"],["76380.6","0"],["76394.4","0.019637"],["76396.1","0.013104"],["76397.6","0.013104"],["76397.7","0.013105"],["76411.5","0"],["76413","0"],["76440.2","0.00055"],["76450.7","0"],["76450.9","0"],["76451.2","0"],["76451.3","0"],["76451.6","0"],["76451.7","0"],["76452.2","0"],["76452.4","0"],["76452.7","0"],["76453.1","0"],["76453.2","0"],["76453.3","0"],["76453.4","0"]],"u":28058302,"seq":105954737059},"cts":1776816028468}
{"topic":"orderbook.200.BTCUSDT","ts":1776816028571,"type":"delta","data":{"s":"BTCUSDT","b":[["76346.1","0"],["76345.7","0"],["76345.6","0.0062"],["76343.3","0.011172"],["76342.2","0.000198"],["76341.2","0"],["76341.1","0"],["76339.9","0"],["76338.7","0.018149"],["76338.5","0"],["76338.2","0.058511"],["76338","0.0052"],["76337.6","0.028327"],["76336.7","0.028327"],["76336.4","0.003275"],["76335.7","0.040099"],["76334.4","0.06832"],["76334","0"],["76332.9","0.010056"],["76332.4","0.004731"],["76332","0"],["76330.5","0.06551"],["76330.1","0"],["76330","0.004765"],["76328.8","0.004751"],["76328.6","0"],["76328.5","0"],["76326.7","0.006547"],["76326.6","0.131884"],["76325.7","0.025059"],["76323.7","0.004172"],["76322.6","0.116954"],["76320.3","0.031456"],["76306.7","0"],["76291.2","0.397038"],["76258.1","1.74729"],["76225.7","0.249519"],["76207.3","0"],["76204.8","0"],["76201.7","0"],["76201.6","0"],["76201","0"]],"a":[["76345.7","1.45448"],["76345.8","0.037596"],["76346","0.035535"],["76346.1","0.02742"],["76346.2","0.00091"],["76346.3","0.027419"],["76348.6","0.023417"],["76348.7","0"],["76348.9","0.14"],["76349","0.001"],["76350.3","0"],["76351.5","0.118085"],["76353.2","0.006547"],["76353.3","0.0172"],["76353.4","0.000099"],["76353.8","0"],["76354.4","0"],["76354.5","0"],["76354.6","0.153416"],["76355.2","0"],["76356.1","0.062114"],["76356.4","0"],["76356.5","0"],["76357.5","0.013092"],["76359.4","0.065463"],["76359.5","0.010416"],["76361","0.0321"],["76361.3","0.065461"],["76362.7","0.02908"],["76362.9","0"],["76363","0"],["76364.8","0"],["76366.7","0"],["76369.1","0"],["76372.6","0"],["76381.6","0.396313"],["76392.1","0"],["76396.1","0.21304"],["76406.6","0.000099"],["76450.6","0"]],"u":28058303,"seq":105954737628},"cts":1776816028569}
{"topic":"orderbook.200.BTCUSDT","ts":1776816028669,"type":"delta","data":{"s":"BTCUSDT","b":[["76345.6","0"],["76345.5","0"],["76343.3","0.072401"],["76338.7","0.046476"],["76338.2","0.02822"],["76338","0"],["76337.6","0"],["76335.7","0.003299"],["76334.4","0.068328"],["76334.3","0.0131"],["76333.2","0.055765"],["76332.3","0.065503"],["76330","0"],["76328.9","0.006547"],["76326.7","0"],["76317.1","0.096875"],["76307.7","0.047324"],["76204.8","0.130981"],["76201.7","0.01799"]],"a":[["76343.4","1.519296"],["76345.5","0.015458"],["76345.6","0.05742"],["76345.7","0.009777"],["76345.8","0"],["76346","0.019508"],["76346.1","0"],["76346.2","0"],["76347","0.006547"],["76348.8","0.001"],["76348.9","0.141"],["76351","0.0172"],["76351.4","0.042366"],["76353.2","0"],["76353.3","0"],["76354.4","0.006547"],["76354.5","0.064792"],["76354.6","0.126"],["76356.1","0.050984"],["76359.3","0.032069"],["76359.9","0.02908"],["76365.4","0"],["76387.3","0.100008"],["76391.6","0.020662"],["76403.7","0.052451"],["76410.1","0.008995"],["76448","0"],["76448.1","0"],["76448.6","0"],["76449.5","0"],["76449.6","0"],["76450","0"],["76450.5","0"]],"u":28058304,"seq":105954738038},"cts":1776816028667}
{"topic":"orderbook.200.BTCUSDT","ts":1776816028768,"type":"delta","data":{"s":"BTCUSDT","b":[["76338.2","0.019168"],["76334.4","0.028328"],["76330.3","0.065008"],["76328.9","0"],["76317.1","0"],["76201.6","0.006524"],["76201","0.006284"]],"a":[["76343.4","1.523846"],["76345.5","0"],["76345.6","0.02742"],["76345.7","0.005227"],["76347","0"],["76348.5","0.006547"],["76354.4","0"],["76356","0.006547"],["76362.7","0"],["76380.3","0"],["76448","0.001811"],["76448.1","0.000402"],["76448.6","0.001252"]],"u":28058305,"seq":105954738157},"cts":1776816028766}
{"topic":"orderbook.200.BTCUSDT","ts":1776816028869,"type":"delta","data":{"s":"BTCUSDT","b":[["76343.3","0.018201"],["76338.2","0"],["76336.8","0.019168"],["76334.4","0.068328"],["76330.6","0.106604"],["76330.5","0.072057"],["76330.3","0"],["76327.1","0.109661"],["76201","0"]],"a":[["76343.4","1.53048"],["76346","0.050682"],["76371","0.157456"]],"u":28058306,"seq":105954738344},"cts":1776816028865}
{"topic":"orderbook.200.BTCUSDT","ts":1776816028969,"type":"delta","data":{"s":"BTCUSDT","b":[["76334.4","0.028328"],["76331.2","0.006547"],["76330.5","0.06551"],["76201.6","0"]],"a":[["76343.4","1.530435"],["76369.7","0.324717"],["76448.6","0"]],"u":28058307,"seq":105954738443},"cts":1776816028967}
{"topic":"orderbook.200.BTCUSDT","ts":1776816029069,"type":"delta","data":{"s":"BTCUSDT","b":[["76343.3","0.039923"],["76342.2","0"],["76338.8","0.028327"],["76338.7","0.018149"],["76329.9","0.025058"],["76325.7","0"],["76315","0.137516"],["76204.8","0.135638"]],"a":[["76381.5","0.031456"],["76448.1","0"]],"u":28058308,"seq":105954738565},"cts":1776816029067}
{"topic":"orderbook.200.BTCUSDT","ts":1776816029169,"type":"delta","data":{"s":"BTCUSDT","b":[["76343.3","0.094123"],["76341.5","0.028326"],["76339.6","0.074992"],["76339.5","0.104461"],["76338.9","0.026198"],["76338.8","0"],["76338.7","0"],["76336.8","0.013546"],["76336.3","0.005749"],["76334.8","0.004731"],["76334.4","0"],["76334.1","0.105456"],["76333.2","0.051"],["76332.6","0.004751"],["76332.4","0"],["76331.4","0.006547"],["76331.3","0.116838"],["76331.2","0"],["76330.6","0.079224"],["76328.8","0"],["76327.9","0.004175"],["76327.1","0"],["76323.7","0"],["76322.6","0"],["76320.1","0"],["76201.6","0.006524"]],"a":[["76343.4","1.474463"],["76348.5","0"],["76348.9","0.121"],["76350.9","0.006547"],["76356","0"],["76357.4","0.006547"],["76359.5","0"],["76363.8","0.010514"],["76365.6","0"],["76388.6","0"],["76448.1","0.000402"],["76448.6","0.001252"]],"u":28058309,"seq":105954738695},"cts":1776816029165}
{"topic":"orderbook.200.BTCUSDT","ts":1776816029269,"type":"delta","data":{"s":"BTCUSDT","b":[["76339.6","0.041151"],["76339.5","0.05066"],["76310","0.331954"],["76201.6","0"]],"a":[["76343.4","1.553751"],["76348.7","0.006547"],["76350.9","0"],["76364.6","0.019637"],["76448.6","0"]],"u":28058310,"seq":105954738731},"cts":1776816029264}
{"topic":"orderbook.200.BTCUSDT","ts":1776816029372,"type":"delta","data":{"s":"BTCUSDT","b":[["76342","0.026424"],["76341.5","0"],["76339.6","0.026029"],["76339.5","0"],["76201.6","0.006524"]],"a":[["76348.5","0.006547"],["76348.7","0"],["76356.2","0.006547"],["76357.4","0"]],"u":28058311,"seq":105954738780},"cts":1776816029356}
{"topic":"orderbook.200.BTCUSDT","ts":1776816029469,"type":"delta","data":{"s":"BTCUSDT","b":[["76332.4","0.006547"],["76331.4","0"],["76310.1","0.147576"],["76308.4","0"],["76252.3","0.375596"]],"a":[["76348.5","0"],["76350.9","0.006547"],["76356.2","0"],["76357.4","0.006547"],["76369.6","0.153182"],["76395.9","0.138993"],["76448.1","0"]],"u":28058312,"seq":105954738856},"cts":1776816029464}
{"topic":"orderbook.200.BTCUSDT","ts":1776816029569,"type":"delta","data":{"s":"BTCUSDT","b":[["76326.2","0.031456"],["76201.6","0"]],"a":[["76343.4","1.523751"]],"u":28058313,"seq":105954738896},"cts":1776816029558}
{"topic":"orderbook.200.BTCUSDT","ts":1776816029669,"type":"delta","data":{"s":"BTCUSDT","b":[["76342.7","0.026424"],["76342","0"],["76332.7","0.006547"],["76332.4","0"],["76294.5","2.030751"],["76270.9","0.687682"],["76204.8","0"],["76201.7","0"]],"a":[["76390.5","1.120518"],["76415.8","0.687682"],["76447.8","0"],["76448","0"]],"u":28058314,"seq":105954738936},"cts":1776816029660}
{"topic":"orderbook.200.BTCUSDT","ts":1776816029768,"type":"delta","data":{"s":"BTCUSDT","b":[["76333.3","0.006547"],["76332.7","0"],["76297.1","2.030751"],["76294.5","0"]],"a":[["76343.4","1.554615"],["76357.4","0"],["76359.1","0.006547"]],"u":28058315,"seq":105954738991},"cts":1776816029761}
{"topic":"orderbook.200.BTCUSDT","ts":1776816029869,"type":"delta","data":{"s":"BTCUSDT","b":[["76333.3","0"],["76333","0.006547"]],"a":[["76343.4","1.554477"],["76359.1","0"],["76359.2","0.006547"]],"u":28058316,"seq":105954739021},"cts":1776816029863}
{"topic":"orderbook.200.BTCUSDT","ts":1776816029969,"type":"delta","data":{"s":"BTCUSDT","b":[["76333","0"],["76332.7","0.006547"],["76299.7","2.042461"],["76297.1","0"]],"a":[["76357.4","0.006547"],["76359.2","0"]],"u":28058317,"seq":105954739041},"cts":1776816029964}
{"topic":"orderbook.200.BTCUSDT","ts":1776816030171,"type":"delta","data":{"s":"BTCUSDT","b":[["76339.8","0.028326"],["76333.8","0.028943"],["76329.9","0"],["76205.2","0"]],"a":[],"u":28058318,"seq":105954739089},"cts":1776816030168}
{"topic":"orderbook.200.BTCUSDT","ts":1776816030269,"type":"delta","data":{"s":"BTCUSDT","b":[],"a":[["76357.4","0"],["76359.2","0.006547"]],"u":28058319,"seq":105954739121},"cts":1776816030268}
{"topic":"orderbook.200.BTCUSDT","ts":1776816030369,"type":"delta","data":{"s":"BTCUSDT","b":[["76332.7","0"],["76331.4","0.006547"]],"a":[["76348.8","0.007547"],["76350.9","0"],["76356.2","0.006547"],["76359.2","0"],["76447.8","0.000116"]],"u":28058320,"seq":105954739162},"cts":1776816030365}
{"topic":"orderbook.200.BTCUSDT","ts":1776816030469,"type":"delta","data":{"s":"BTCUSDT","b":[["76343.3","0.014372"],["76342.7","0"],["76339.8","0"],["76339.6","0"],["76338.9","0"],["76336.8","0.013744"],["76336.7","0"],["76335.1","0.0262"],["76334.8","0"],["76332.9","0"],["76331.4","0"],["76326.2","0"],["76320.3","0"],["76316.9","0.162437"],["76316.8","0"],["76315","0.150593"],["76313.9","0"],["76311.9","0.031456"],["76310","0"],["76299.7","0"],["76287.2","0"],["76276.3","2.042461"],["76272.7","0.472363"],["76252.3","0.021587"],["76205.2","0.126"],["76204.8","0.130981"],["76201.7","0.01799"],["76201.6","0.006524"],["76201","0.006284"],["76200.4","0.006521"],["76200","0.007145"],["76199.6","0.176737"],["76198.7","0.6"],["76198.5","0.000984"],["76198.1","0.082685"]],"a":[["76343.4","1.554479"],["76346.2","0.006547"],["76348.8","0.001"],["76361.8","0.130981"],["76388.1","0"],["76415.7","0.258648"],["76417.4","0"],["76428.2","0.12"],["76443.1","0"],["76444.2","0"]],"u":28058321,"seq":105954739294},"cts":1776816030468}
{"topic":"orderbook.200.BTCUSDT","ts":1776816030569,"type":"delta","data":{"s":"BTCUSDT","b":[["76343.3","0"],["76339.4","0.024217"],["76338.6","0"],["76336.8","0.000198"],["76336.3","0.000984"],["76335.7","0.000099"],["76335.6","0.026427"],["76335.1","0"],["76334","0.0262"],["76333.8","0"],["76332.6","0"],["76332.3","0.093713"],["76331.8","0.0032"],["76331.1","0"],["76330.6","0.043158"],["76330.2","0"],["76329.9","0.004765"],["76328","0.004731"],["76327.9","0"],["76327.8","0.007179"],["76326.1","0"],["76324.1","0.006547"],["76324","0.126"],["76323.5","0.005169"],["76319.2","0"],["76318.2","0.396886"],["76317","0.130981"],["76316.9","0.031456"],["76310.1","0"],["76297.8","0.137256"],["76294.1","0"],["76287.3","0"],["76276.3","0"],["76270.9","0"],["76268.5","2.042461"],["76267","0.687682"],["76251.5","0"],["76245.4","0.058757"],["76223.7","0.128028"],["76199.6","0.17438"],["76197","0.126"],["76196.2","0.145575"],["76195.6","0.130981"],["76195.2","4.109518"]],"a":[["76339.5","1.574622"],["76341","0.024462"],["76342.5","0.005182"],["76343.4","0.170393"],["76345.5","0.006547"],["76345.7","0"],["76346","0.082887"],["76346.2","0"],["76346.3","0"],["76347.1","0.131022"],["76348.6","0"],["76350.7","0.006547"],["76351","0"],["76351.4","0.013092"],["76351.5","0"],["76353.3","0.065463"],["76355.2","0.065461"],["76356","0.02905"],["76356.2","0"],["76357.5","0"],["76359.3","0.045759"],["76359.4","0"],["76361","0.073035"],["76361.3","0"],["76379.6","0.700711"],["76387.9","1.108484"],["76390.5","0"],["76404.6","0.3562"],["76421.1","0"],["76422.5","0.024672"],["76440.8","0.070902"],["76444.8","0.000102"]],"u":28058322,"seq":105954739896},"cts":1776816030567}
{"topic":"orderbook.200.BTCUSDT","ts":1776816030669,"type":"delta","data":{"s":"BTCUSDT","b":[["76339.4","0.027769"],["76335.6","0"],["76335.5","0.026427"],["76326.7","0.006547"],["76326.6","0.054224"],["76325.5","0.028946"],["76324.1","0"],["76323","0"],["76313.2","0.333514"],["76301","0.000131"],["76295.8","0"],["76291.9","2.08231"],["76286.9","0.743247"],["76279.9","0.743315"],["76272.7","0.239702"],["76268.5","0"],["76234.1","1.747839"],["76196.2","0"],["76195.6","0"],["76195.2","0"]],"a":[["76339.5","1.578262"],["76343.4","0.168573"],["76350.7","0"],["76351.3","0.023478"],["76353.2","0.006548"],["76356.3","0"],["76359.3","0"],["76359.9","0"],["76378","0.031587"],["76399","0.000099"],["76404.5","0.008995"],["76420.4","0.187164"],["76437.4","0.741784"],["76444.4","0.741716"],["76444.7","0.000984"],["76447.8","0"]],"u":28058323,"seq":105954740082},"cts":1776816030665}
{"topic":"orderbook.200.BTCUSDT","ts":1776816030769,"type":"delta","data":{"s":"BTCUSDT","b":[["76339.4","0.027952"],["76327.9","0.006547"],["76326.7","0"],["76261.6","0.250136"]],"a":[["76339.5","1.589983"],["76412.1","0.00262"],["76447.6","0"]],"u":28058324,"seq":105954740186},"cts":1776816030766}
{"topic":"orderbook.200.BTCUSDT","ts":1776816030869,"type":"delta","data":{"s":"BTCUSDT","b":[["76336.1","0.026426"],["76335.5","0"],["76330.3","0.004731"],["76328","0"],["76294.5","2.08231"],["76291.9","0"]],"a":[],"u":28058325,"seq":105954740295},"cts":1776816030861}
{"topic":"orderbook.200.BTCUSDT","ts":1776816031069,"type":"delta","data":{"s":"BTCUSDT","b":[["76336.1","0"],["76334","0"],["76333.9","0.026427"],["76331","0.010196"],["76329.8","0.02821"],["76327.9","0"],["76326.7","0.006547"],["76200.4","0.01128"],["76197","0"]],"a":[["76343.3","0.060458"],["76354.4","0.031456"],["76357.8","0.031456"],["76435.9","0.000143"],["76446.2","0"],["76446.3","0"],["76446.5","0"]],"u":28058326,"seq":105954740588},"cts":1776816031065}
{"topic":"orderbook.200.BTCUSDT","ts":1776816031169,"type":"delta","data":{"s":"BTCUSDT","b":[["76339.4","0"],["76336.9","0.087337"],["76333.9","0"],["76332.8","0.026428"],["76332.3","0.065503"],["76331.8","0"],["76330.3","0"],["76329.3","0.0012"],["76327.3","0.004731"],["76326.7","0"],["76326.5","0.000984"],["76323.6","0.028947"],["76323.5","0.011717"],["76318.3","0.194306"],["76317","0"],["76316.9","0"],["76315.9","0.162437"],["76312","0.031456"],["76311.9","0"],["76310.9","0.006551"],["76294.5","0"],["76294","0.031456"],["76286.7","2.08231"],["76283","0.050373"],["76274.7","0"],["76273.2","0"],["76266.6","0.013105"],["76265.1","0.013105"],["76261.5","0"],["76227.5","0.5999"],["76218.6","0"],["76218.5","0"],["76215.7","0"],["76215.6","0"],["76213.4","0"],["76212.7","0"],["76210.4","0.008995"],["76210.3","0"],["76206.7","0.008995"],["76206.6","0"],["76201.8","0.01799"],["76201.7","0"],["76198.8","0.008995"],["76197","0.126"],["76196.2","0.145575"],["76195.6","0.130981"],["76195.2","4.109518"],["76195.1","0.008995"]],"a":[["76337","1.521361"],["76339.3","0.159052"],["76339.4","0.037596"],["76339.5","0.048042"],["76342.3","0.006548"],["76342.7","0.001"],["76343.3","0.085215"],["76343.4","0.136709"],["76344.6","0.0172"],["76344.7","0.126"],["76345.5","0"],["76345.6","0"],["76345.8","0.000099"],["76347.1","0.113822"],["76348.7","0.006547"],["76351.2","0.031456"],["76353.2","0"],["76354.2","0.129529"],["76354.3","0.130981"],["76354.5","0"],["76357.4","0.048439"],["76388.4","0.013105"],["76389.9","0.013105"],["76403.8","0.126"],["76405.3","0.000984"],["76426.7","0"],["76443.2","0"],["76443.5","0"],["76443.9","0"],["76444","0"],["76444.4","0"],["76444.6","0"],["76444.7","0"],["76444.8","0"],["76445","0"],["76445.9","0"]],"u":28058327,"seq":105954741123},"cts":1776816031168}
{"topic":"orderbook.200.BTCUSDT","ts":1776816031269,"type":"delta","data":{"s":"BTCUSDT","b":[["76336.9","0.033137"],["76336.8","0"],["76333.2","0.051198"],["76329.9","0"],["76328.7","0.025664"],["76326.7","0.004765"],["76325.5","0"],["76270.5","0.008995"],["76261.6","0.069821"],["76258.1","0"],["76239.2","1.747722"],["76201.9","0.008995"],["76200.4","0.006521"],["76199.7","0.008995"],["76196.3","0.008995"],["76195.6","0"],["76195.2","0"],["76195.1","0"]],"a":[["76337","1.512968"],["76339.3","0.018524"],["76339.5","0.034392"],["76342.7","0.005"],["76348.7","0"],["76351.1","0.006548"],["76353.5","0.02905"],["76442.9","0"]],"u":28058328,"seq":105954741375},"cts":1776816031265}
{"topic":"orderbook.200.BTCUSDT","ts":1776816031369,"type":"delta","data":{"s":"BTCUSDT","b":[["76336.9","0.091072"],["76333.5","0.025619"],["76332.1","0.026201"],["76328.7","0"],["76324.1","0.006548"],["76323.5","0.005169"],["76258.2","0"],["76196.2","0"]],"a":[["76337","1.519338"],["76339.4","0"],["76342.3","0"],["76342.7","0.01"],["76343.2","0.006548"],["76356","0"],["76442.9","0.00041"],["76443.2","0.00032"]],"u":28058329,"seq":105954741525},"cts":1776816031364}
{"topic":"orderbook.200.BTCUSDT","ts":1776816031469,"type":"delta","data":{"s":"BTCUSDT","b":[["76334.1","0.131075"],["76333.5","0"],["76326.6","0.060771"],["76324.1","0"],["76315","0.23587"],["76287","0.881338"],["76252.3","0.202336"],["76196.2","0.145575"]],"a":[["76337","1.557702"],["76339.3","0"],["76339.4","0.017568"],["76342.7","0.011"],["76343.2","0"],["76344.5","0.006547"],["76351.1","0"],["76351.2","0.038003"],["76387.8","0.622793"]],"u":28058330,"seq":105954741592},"cts":1776816031466}
{"topic":"orderbook.200.BTCUSDT","ts":1776816031569,"type":"delta","data":{"s":"BTCUSDT","b":[["76336.9","0.036872"],["76334.1","0.059784"],["76332.1","0"],["76331","0"],["76328.9","0.025664"],["76327.4","0.006547"],["76326.6","0.054224"],["76198.8","0.013603"]],"a":[["76344.5","0"],["76351.2","0.031456"],["76353.2","0.006547"]],"u":28058331,"seq":105954741733},"cts":1776816031567}
{"topic":"orderbook.200.BTCUSDT","ts":1776816031669,"type":"delta","data":{"s":"BTCUSDT","b":[["76336.9","0.091072"],["76333.3","0.025619"],["76332.8","0"],["76332","0.026201"],["76327.9","0.006547"],["76327.4","0"],["76325.6","0.010194"],["76289.3","2.08231"],["76287","0.235622"],["76286.7","0"],["76196.3","0"],["76196.2","0"]],"a":[["76361","0.000099"],["76363.8","0"],["76443.5","0.000094"]],"u":28058332,"seq":105954741841},"cts":1776816031658}
{"topic":"orderbook.200.BTCUSDT","ts":1776816031771,"type":"delta","data":{"s":"BTCUSDT","b":[["76336.9","0.091335"],["76327.9","0"],["76327.4","0.006547"]],"a":[["76337","1.557965"]],"u":28058333,"seq":105954741866},"cts":1776816031763}
{"topic":"orderbook.200.BTCUSDT","ts":1776816031869,"type":"delta","data":{"s":"BTCUSDT","b":[["76333.3","0"],["76327.4","0"],["76326.8","0.006547"],["76289.3","0"],["76278.9","2.08231"],["76196.3","0.008995"]],"a":[],"u":28058334,"seq":105954741946},"cts":1776816031866}
{"topic":"orderbook.200.BTCUSDT","ts":1776816031968,"type":"delta","data":{"s":"BTCUSDT","b":[["76336.9","0.015135"],["76332.8","0.025619"],["76332","0"],["76329.8","0"],["76328.3","0.030814"],["76286.7","2.119528"],["76278.9","0"],["76196.2","0.145575"]],"a":[["76351.1","0.037972"],["76351.3","0"],["76352.9","0.006548"],["76353","0.010551"],["76353.2","0"],["76443.5","0"]],"u":28058335,"seq":105954742057},"cts":1776816031966}
{"topic":"orderbook.200.BTCUSDT","ts":1776816032069,"type":"delta","data":{"s":"BTCUSDT","b":[["76332.8","0"],["76331.8","0.02562"],["76326.8","0"],["76326.6","0.060772"],["76195.6","0.130981"]],"a":[["76337","1.549645"],["76351.3","0.006548"],["76352.9","0"]],"u":28058336,"seq":105954742225},"cts":1776816032067}
{"topic":"orderbook.200.BTCUSDT","ts":1776816032168,"type":"delta","data":{"s":"BTCUSDT","b":[["76331.8","0"],["76331.2","0.02562"],["76327.8","0.002428"],["76326.8","0.006548"],["76326.6","0.054224"],["76195.6","0"]],"a":[["76337","1.558745"],["76351.3","0"],["76352.9","0.006548"],["76424.1","0.12"],["76443.2","0"]],"u":28058337,"seq":105954742362},"cts":1776816032167}
{"topic":"orderbook.200.BTCUSDT","ts":1776816032268,"type":"delta","data":{"s":"BTCUSDT","b":[["76334.1","0"],["76333.3","0.077359"],["76327.3","0"],["76324.5","0.004731"],["76323.9","0.004751"],["76323.5","0.001"],["76318.3","0.198489"],["76286.7","0"],["76284.1","2.119528"],["76196.2","0"]],"a":[["76337","1.563968"],["76338","0.005177"],["76339.5","0.029164"],["76342.5","0"],["76352.8","0.006548"],["76352.9","0"],["76422.9","0.100709"],["76437.3","0.000583"]],"u":28058338,"seq":105954742532},"cts":1776816032267}
{"topic":"orderbook.200.BTCUSDT","ts":1776816032369,"type":"delta","data":{"s":"BTCUSDT","b":[["76333.2","0.021198"],["76331.2","0"],["76330.9","0.02562"],["76328.9","0"],["76320.9","0.028263"],["76286.7","2.119528"],["76284.1","0"],["76272.6","0.995264"],["76196.3","0"]],"a":[["76343","0.127169"],["76346","0.036716"],["76347.1","0"],["76352.8","0"],["76352.9","0.006548"]],"u":28058339,"seq":105954742711},"cts":1776816032368}
{"topic":"orderbook.200.BTCUSDT","ts":1776816032469,"type":"delta","data":{"s":"BTCUSDT","b":[["76333.2","0.001198"],["76308.4","0.048487"],["76197","0"]],"a":[["76361.7","0.054349"],["76442.9","0"]],"u":28058340,"seq":105954742803},"cts":1776816032463}
{"topic":"orderbook.200.BTCUSDT","ts":1776816032571,"type":"delta","data":{"s":"BTCUSDT","b":[["76331.4","0.02562"],["76323.6","0"],["76289.3","2.119528"],["76287","0.862324"],["76286.7","0"]],"a":[["76385.6","0.112152"]],"u":28058341,"seq":105954742913},"cts":1776816032570}
{"topic":"orderbook.200.BTCUSDT","ts":1776816032668,"type":"delta","data":{"s":"BTCUSDT","b":[["76331.9","0.02562"],["76331.4","0"],["76287","0.235622"],["76241.9","0.061622"],["76198.1","0"]],"a":[],"u":28058342,"seq":105954743040},"cts":1776816032666}
{"topic":"orderbook.200.BTCUSDT","ts":1776816032769,"type":"delta","data":{"s":"BTCUSDT","b":[["76289.7","0"],["76214.3","0.972473"]],"a":[],"u":28058343,"seq":105954743098},"cts":1776816032765}
{"topic":"orderbook.200.BTCUSDT","ts":1776816032868,"type":"delta","data":{"s":"BTCUSDT","b":[["76313.2","0.000099"]],"a":[],"u":28058344,"seq":105954743142},"cts":1776816032867}
{"topic":"orderbook.200.BTCUSDT","ts":1776816032969,"type":"delta","data":{"s":"BTCUSDT","b":[["76326.8","0"],["76326.6","0.060772"],["76315","0"],["76198.1","0.082685"],["76197","0.126"]],"a":[["76351.3","0.006548"],["76352.9","0"],["76369.6","0"],["76369.7","0"],["76442.9","0.00041"],["76443.2","0.00032"]],"u":28058345,"seq":105954743249},"cts":1776816032957}
{"topic":"orderbook.200.BTCUSDT","ts":1776816033069,"type":"delta","data":{"s":"BTCUSDT","b":[["76326.7","0.011313"],["76326.6","0.054224"],["76305.4","0.318667"],["76197","0"]],"a":[["76365.7","0.33015"]],"u":28058346,"seq":105954743370},"cts":1776816033067}
{"topic":"orderbook.200.BTCUSDT","ts":1776816033169,"type":"delta","data":{"s":"BTCUSDT","b":[["76336.9","0"],["76336.4","0"],["76336.3","0"],["76335.7","0"],["76334.3","0"],["76333.3","0"],["76333.2","0"],["76332.3","0.187439"],["76331.9","0"],["76331.3","0"],["76330.9","0"],["76330.5","0"],["76329.3","0"],["76328.3","0.00515"],["76326.9","0.025665"],["76326.7","0"],["76326.6","0"],["76326.1","0.013101"],["76325.6","0"],["76325","0.024732"],["76324.9","0.024033"],["76324.7","0.0012"],["76324.2","0.065503"],["76324","0"],["76323","0.004765"],["76322.3","0.06551"],["76321","0.03552"],["76319.3","0.028264"],["76318.7","0"],["76315.9","0"],["76312","0"],["76311.9","0.131254"],["76311.7","0.031456"],["76311.6","0"],["76309.9","0.019637"],["76308.6","0.048487"],["76308.5","0.162437"],["76308.4","0"],["76308.3","0"],["76307.7","0.127006"],["76304.9","0"],["76297.8","0.52853"],["76295.8","0.100557"],["76286.7","2.119528"],["76275.2","0"],["76267","0"],["76260.8","0.68774"],["76260.2","0.013106"],["76198.8","0.008995"],["76197","0.126"],["76196.3","0.008995"],["76196.2","0.145575"],["76195.6","0.130981"],["76195.3","0.199122"],["76195.2","4.109518"]],"a":[["76332.4","1.108804"],["76332.5","0.000225"],["76333","0.00612"],["76333.2","0.432651"],["76333.3","0.396498"],["76333.4","0.217798"],["76334.2","0.003594"],["76334.5","0.014377"],["76336.4","0.003"],["76336.5","0.02"],["76337","0.081696"],["76339.4","0"],["76340","0.0152"],["76341","0.002"],["76343.4","0.109288"],["76344.6","0"],["76346.2","0.000984"],["76348.4","0.013092"],["76348.7","0.006548"],["76350.3","0.065463"],["76351.3","0"],["76351.4","0"],["76352.2","0.065461"],["76353.3","0"],["76355.2","0"],["76355.4","0.019637"],["76357.3","0.033268"],["76364.6","0"],["76365.6","0.147659"],["76367.8","0"],["76370.9","0.047299"],["76372.8","0.396313"],["76379.5","0.209491"],["76381.6","0"],["76390","0.013209"],["76405.4","0"],["76440.2","0"],["76440.7","0"],["76440.8","0"],["76440.9","0"],["76441.5","0"],["76441.6","0"],["76442.2","0"],["76442.5","0"],["76442.7","0"],["76442.8","0"],["76442.9","0"],["76443.2","0"]],"u":28058347,"seq":105954744011},"cts":1776816033167}
{"topic":"orderbook.200.BTCUSDT","ts":1776816033269,"type":"delta","data":{"s":"BTCUSDT","b":[["76332.3","0.006926"],["76330.6","0"],["76329.2","0.00979"],["76328.2","0.000099"],["76326.9","0"],["76324.9","0"],["76324.5","0"],["76323.9","0"],["76323.5","0.041"],["76323","0.024241"],["76322.4","0.032935"],["76321.3","0.006548"],["76321","0"],["76320.9","0"],["76319.7","0.004751"],["76318.9","0.004765"],["76318.3","0.199037"],["76316.4","0.027594"],["76312.8","0.004189"],["76312.5","0.038774"],["76311.9","0"],["76311.7","0"],["76310.9","0"],["76308.7","0.162437"],["76308.5","0"],["76305.5","0.031456"],["76301.4","0.098469"],["76300","0.006552"],["76296.8","0"],["76292.2","0"],["76289.8","0"],["76289.3","0"],["76286.9","0"],["76286.7","0"],["76282.9","0"],["76281","0.133303"],["76279.9","0"],["76279.2","0.743322"],["76271.6","0"],["76271.1","2.2226"],["76269.8","0.874394"],["76266.6","0"],["76265.1","0"],["76257.2","0.013107"],["76255.3","0.013107"],["76214.3","0"],["76195.1","0.008995"],["76195","0.590244"],["76193","0.008995"],["76192","0.006524"],["76190.1","0.008995"],["76188.7","0.126984"],["76188","0.008995"],["76187.8","0.034161"]],"a":[["76332.4","1.319858"],["76332.5","0"],["76333","0"],["76333.1","0.005175"],["76333.2","0.016069"],["76333.3","0.023828"],["76333.4","0"],["76334.2","0"],["76334.5","0"],["76336.4","0.024827"],["76337","0.067848"],["76338","0"],["76339.4","0.01384"],["76340","0.0172"],["76341","0"],["76346.1","0.006548"],["76348","0.031456"],["76348.7","0"],["76348.9","0.15005"],["76380","0.402673"],["76380.1","1.158211"],["76380.2","0"],["76380.7","0.144088"],["76382.2","0.013107"],["76387.4","0.013106"],["76387.8","0"],["76387.9","0"],["76396.1","0.199936"],["76397.6","0"],["76406","1.004412"],["76417.5","0.130981"],["76418","0"],["76422.9","0.069253"],["76427.4","0.741882"],["76433.7","0"],["76434.5","0"],["76436.7","0.741791"],["76437.4","0"],["76440.2","0.00055"],["76440.7","0.048439"],["76440.8","0.070902"],["76440.9","0.086451"],["76441.5","0.130956"],["76441.6","0.000589"]],"u":28058348,"seq":105954744476},"cts":1776816033268}
{"topic":"orderbook.200.BTCUSDT","ts":1776816033371,"type":"delta","data":{"s":"BTCUSDT","b":[["76332.3","0.182233"],["76326.8","0.013801"],["76326.2","0.095644"],["76325.7","0.026525"],["76325","0"],["76324.7","0.000598"],["76324.6","0.126"],["76323.9","0.026204"],["76323.7","0.004751"],["76323.5","0.001"],["76322.5","0.006548"],["76321.5","0.010178"],["76321.3","0"],["76319.7","0"],["76319.5","0.013767"],["76319.4","0.004189"],["76319.1","0.164571"],["76318.9","0"],["76318.3","0.194306"],["76312.8","0"],["76308.8","0.048487"],["76308.6","0"],["76304","0.093826"],["76301.6","0.031456"],["76287","0"],["76276.3","2.2226"],["76271.1","0"],["76192","0"],["76190.1","0"],["76188.7","0"],["76188","0"],["76187.8","0"]],"a":[["76332.4","0.960499"],["76333.1","0"],["76333.2","0"],["76333.3","0"],["76336.4","0"],["76336.5","0"],["76337","0"],["76339.2","0.056113"],["76339.3","0.025378"],["76339.4","0.02"],["76339.5","0.001528"],["76340","0.0104"],["76342.7","0.14501"],["76342.9","0.031456"],["76343.3","0"],["76346","0.092841"],["76346.1","0"],["76347.9","0.137529"],["76353.5","0"],["76380.1","0"],["76382","0.001"],["76388.2","0.370067"],["76400.9","1.158211"],["76442.2","0.00013"],["76442.5","0.000814"],["76442.7","0.014949"],["76442.8","0.000897"]],"u":28058349,"seq":105954745013},"cts":1776816033369}
{"topic":"orderbook.200.BTCUSDT","ts":1776816033469,"type":"delta","data":{"s":"BTCUSDT","b":[["76332.3","0.100799"],["76325.7","0"],["76322.5","0"],["76320.8","0.006548"],["76291.3","0.118545"],["76286.7","2.2226"],["76281","0.238077"],["76277.1","0.983864"],["76276.3","0"],["76272.7","0.527503"],["76248.5","0.040337"],["76239.3","0.600673"],["76234.2","0.29148"],["76234","0.000439"],["76225.7","0"],["76195.3","0"],["76193","0"]],"a":[["76332.4","0.98717"],["76339.2","0"],["76345.9","0.006548"],["76347.9","0.130981"],["76372.7","0.18265"],["76374.1","0"],["76380","0.000103"],["76380.6","0.061055"],["76399.8","0.513583"],["76400.9","0"],["76403.5","1.158211"],["76403.7","0.454515"],["76426.2","0.323958"],["76433.7","0.406953"],["76442.7","0"],["76442.8","0"]],"u":28058350,"seq":105954745136},"cts":1776816033466}
{"topic":"orderbook.200.BTCUSDT","ts":1776816033569,"type":"delta","data":{"s":"BTCUSDT","b":[["76326.8","0.040326"],["76319.3","0"],["76277.1","0"],["76234.2","0.342842"],["76193","0.008995"],["76192","0.006524"]],"a":[["76333.3","0.023828"],["76365.6","0.052094"],["76365.7","0.01"],["76380.1","1.158211"],["76399.8","0.187978"],["76403.5","0"],["76403.7","0"]],"u":28058351,"seq":105954745242},"cts":1776816033565}
{"topic":"orderbook.200.BTCUSDT","ts":1776816033669,"type":"delta","data":{"s":"BTCUSDT","b":[["76326.8","0.013801"],["76325.7","0.026525"],["76321.7","0.006548"],["76321.6","0.025666"],["76320.8","0"],["76286.8","0.701356"],["76276.2","0.302373"],["76261.6","0.280268"],["76257.1","0.03558"],["76234.2","0.29148"],["76223.7","0"],["76195.1","0"],["76195","0"],["76193","0"],["76192","0"]],"a":[["76333.2","0.014225"],["76336.4","0.023827"],["76345.9","0"],["76347.8","0.006548"],["76380","0.406884"],["76380.6","0"],["76404.5","0.42992"],["76442.5","0"]],"u":28058352,"seq":105954745387},"cts":1776816033664}
{"topic":"orderbook.200.BTCUSDT","ts":1776816033769,"type":"delta","data":{"s":"BTCUSDT","b":[["76332.3","0.100933"],["76286.7","0"],["76281.5","2.2226"]],"a":[["76332.4","0.987304"],["76339.2","0.017106"],["76354.2","0.186402"],["76356.5","0.320882"],["76441.6","0"],["76442.2","0"]],"u":28058353,"seq":105954745434},"cts":1776816033766}
{"topic":"orderbook.200.BTCUSDT","ts":1776816033869,"type":"delta","data":{"s":"BTCUSDT","b":[["76321.8","0.013771"],["76321.7","0"],["76321.6","0.032214"],["76319.5","0"],["76286.8","0"],["76283","0.696104"],["76258.4","0.024672"],["76195.1","0.008995"]],"a":[["76339.5","0"],["76441.6","0.000589"]],"u":28058354,"seq":105954745507},"cts":1776816033863}
{"topic":"orderbook.200.BTCUSDT","ts":1776816033969,"type":"delta","data":{"s":"BTCUSDT","b":[["76332.3","0"],["76330.4","0"],["76329.2","0.144303"],["76326.2","0.032893"],["76325.7","0"],["76325.4","0.026526"],["76324.7","0.000198"],["76324.6","0"],["76323.9","0"],["76321.8","0"],["76321.6","0.026066"],["76321.5","0"],["76320.1","0.006548"],["76301.4","0"],["76287.2","0.038203"],["76260.8","0"],["76256.8","0.687781"],["76243.7","0.12"],["76195","0.590244"],["76193","0.008995"],["76192","0.006524"],["76190.1","0.008995"]],"a":[["76329.3","1.091955"],["76330.4","0.47468"],["76330.5","0.47974"],["76332.3","0.121864"],["76332.4","0.114905"],["76333.2","0"],["76333.3","0"],["76335.5","0.001"],["76336.8","0.040715"],["76336.9","0.0104"],["76337","0.126"],["76338.2","0.000099"],["76339.2","0"],["76339.3","0"],["76340","0"],["76345.7","0.006548"],["76347.8","0"],["76362.7","0.105805"],["76388.2","0.26423"],["76415.3","0.12"],["76440.2","0"],["76440.7","0"],["76440.8","0"],["76440.9","0"],["76441.5","0"],["76441.6","0"]],"u":28058355,"seq":105954745883},"cts":1776816033967}
{"topic":"orderbook.200.BTCUSDT","ts":1776816034069,"type":"delta","data":{"s":"BTCUSDT","b":[["76329.2","0.147064"],["76320.1","0"],["76319.5","0.006548"],["76318.9","0.013771"],["76261.6","0.069821"],["76257.1","0.236334"],["76245.4","0.087724"],["76190.1","0"]],"a":[["76329.3","1.267295"],["76330.3","0.041393"],["76330.4","0"],["76330.5","0"],["76332.3","0.031864"],["76332.4","0.105805"],["76333.6","0.001"],["76338.6","0.043439"],["76338.7","0.125525"],["76342.7","0.101279"],["76343","0"],["76344.6","0.006548"],["76345.7","0"],["76345.8","0.029149"],["76377.5","1.200196"],["76379.5","0"],["76380","0.000103"],["76380.1","0"],["76430.8","0"],["76430.9","0"],["76440.2","0.00055"],["76440.7","0.048439"]],"u":28058356,"seq":105954746083},"cts":1776816034066}
{"topic":"orderbook.200.BTCUSDT","ts":1776816034171,"type":"delta","data":{"s":"BTCUSDT","b":[["76326.5","0.027509"],["76322.4","0.023038"],["76321.6","0.0004"]],"a":[["76329.3","1.270025"],["76330.5","0.023941"],["76342.9","0"],["76348.9","0.121"],["76377.4","0.577477"],["76440.7","0"]],"u":28058357,"seq":105954746273},"cts":1776816034169}
{"topic":"orderbook.200.BTCUSDT","ts":1776816034269,"type":"delta","data":{"s":"BTCUSDT","b":[["76328","0.026525"],["76326.5","0.000984"],["76319.5","0"],["76319.2","0.006548"],["76283","0.699381"],["76192","0"]],"a":[["76329.3","1.267295"],["76363.2","0.003274"],["76380.6","0.061055"],["76416.6","0"],["76440.2","0"]],"u":28058358,"seq":105954746389},"cts":1776816034262}
{"topic":"orderbook.200.BTCUSDT","ts":1776816034369,"type":"delta","data":{"s":"BTCUSDT","b":[["76329.2","0.141064"],["76328","0"],["76323.4","0.027204"],["76319.2","0"],["76318.9","0.024023"],["76316.5","0.006548"],["76301.4","0.09863"],["76281.5","0"],["76265.9","2.297369"]],"a":[["76342.6","0.006548"],["76344.6","0.031456"],["76421.7","0.985365"],["76434.9","0"],["76440","0"]],"u":28058359,"seq":105954746616},"cts":1776816034367}
{"topic":"orderbook.200.BTCUSDT","ts":1776816034469,"type":"delta","data":{"s":"BTCUSDT","b":[["76329.2","0.090483"],["76328","0.026525"],["76319.2","0.006548"],["76316.5","0"],["76301.4","0"],["76283","0.05365"],["76269.4","0.732181"],["76268.5","2.297369"],["76265.9","0"],["76241.9","0.111126"],["76240.3","0.192234"],["76193","0"]],"a":[["76329.3","1.221213"],["76332.4","0.085805"],["76336.3","0.006548"],["76342.6","0"],["76344.5","0.006548"],["76420.4","0.457367"],["76427.6","0.19457"],["76438.1","0"],["76439.3","0"]],"u":28058360,"seq":105954746766},"cts":1776816034464}
{"topic":"orderbook.200.BTCUSDT","ts":1776816034569,"type":"delta","data":{"s":"BTCUSDT","b":[["76335.4","0.710247"],["76333.5","0.026523"],["76332.9","0.001"],["76332.3","0.232174"],["76332.2","0.126"],["76332","0.013829"],["76330.5","0.000198"],["76329.3","0.028283"],["76329.2","0.05"],["76328.6","0.026524"],["76328","0"],["76327.8","0.006828"],["76326.8","0"],["76326.2","0"],["76325.4","0"],["76324.7","0"],["76323.7","0"],["76323.6","0.111286"],["76323.5","0.032456"],["76323.4","0.001"],["76323","0.037089"],["76322.9","0.048439"],["76322.4","0"],["76321.6","0"],["76319.4","0"],["76319.2","0.019637"],["76319.1","0.052"],["76318.9","0.010252"],["76318.4","0.162437"],["76316.4","0"],["76309.9","0"],["76308.7","0.168988"],["76301.4","0.096718"],["76300","0"],["76291.9","2.297369"],["76268.5","0"],["76264.9","0.047379"],["76263","0.013105"],["76261.1","0.687798"],["76256.8","0"],["76252.3","0.021587"],["76248.5","0"],["76245.4","0.00515"],["76241.9","0"],["76239.3","0"],["76234.2","0"],["76193","0.008995"],["76192","0.006524"]],"a":[["76329.3","0"],["76330.3","0"],["76330.5","0"],["76332.3","0"],["76332.4","0"],["76333.6","0"],["76335.5","0.0244"],["76336.3","0"],["76336.4","0"],["76336.6","0.023939"],["76336.8","0"],["76336.9","0"],["76337","0"],["76338.6","0"],["76338.7","0"],["76339.4","0"],["76340.2","0.055165"],["76342.5","0.044091"],["76342.6","0.057923"],["76342.7","0.011"],["76343.1","0.0104"],["76343.4","0.079288"],["76344.5","0"],["76344.6","0"],["76344.7","0"],["76345.8","0.000099"],["76346","0.082963"],["76347.9","0"],["76348","0"],["76348.3","0.071714"],["76350.2","0.04226"],["76351.1","0"],["76351.2","0"],["76353","0"],["76354.2","0.056873"],["76354.3","0"],["76354.4","0"],["76355.1","0.02905"],["76355.4","0"],["76356.5","0"],["76357.3","0"],["76357.4","0"],["76357.8","0"],["76360.9","0"],["76361.8","0"],["76362.3","0.126"],["76364.7","0"],["76367.1","0.031456"],["76367.2","0.130981"],["76367.9","0"],["76368","0"],["76370.6","0.031456"],["76370.7","0.049637"],["76371","0.126"],["76377.5","0"],["76411.3","1.201196"],["76427.6","0"],["76438.1","0.000635"],["76439.3","0.130981"],["76440","0.000941"],["76440.2","0.00055"],["76440.7","0.048439"],["76440.8","0.070902"],["76440.9","0.086451"],["76441.5","0.130956"],["76441.6","0.000589"],["76442.2","0.00013"],["76442.5","0.000814"],["76442.7","0.014949"],["76442.8","0.000897"],["76442.9","0.00041"],["76443.2","0.00032"],["76443.5","0.000094"],["76443.9","0.000074"],["76444","0.001124"],["76444.6","0.000099"],["76444.7","0.000984"],["76444.8","0.000102"],["76444.9","0.246269"],["76445","0.815025"],["76445.9","0.003961"]],"u":28058361,"seq":105954747997},"cts":1776816034568}
{"topic":"orderbook.200.BTCUSDT","ts":1776816034669,"type":"delta","data":{"s":"BTCUSDT","b":[["76335.4","0.71647"],["76334.8","0.001"],["76332.4","0.006547"],["76332.3","0.00065"],["76332.2","0.026523"],["76329.4","0.031456"],["76329.3","0.0701"],["76329","0.027202"],["76327.7","0.126"],["76324.3","0.062758"],["76291.9","0"],["76281.5","2.297369"],["76269.4","0"],["76261.6","0.28765"],["76257.1","0.03558"],["76252.3","0.202336"],["76225.7","1.470246"],["76195.2","0"],["76195.1","0"],["76195","0"],["76193","0"],["76192","0"]],"a":[["76335.5","0.255433"],["76336.6","0"],["76340.2","0"],["76341.1","0.026321"],["76342.3","0.026801"],["76342.5","0"],["76342.6","0"],["76346","0.066787"],["76348.3","0"],["76351.8","0.006547"],["76352","0.02905"],["76356.8","0.010335"],["76360.8","0.006547"],["76360.9","0.039127"],["76361","0.13108"],["76362.2","0.031456"],["76377.4","0.219219"],["76398.3","1.200196"],["76411.2","0.406369"],["76411.3","0.001"],["76413.3","0"],["76444.8","0"],["76444.9","0"],["76445","0"],["76445.9","0"]],"u":28058362,"seq":105954748278},"cts":1776816034666}
{"topic":"orderbook.200.BTCUSDT","ts":1776816034769,"type":"delta","data":{"s":"BTCUSDT","b":[["76335.4","0.717447"],["76332.4","0"],["76332.3","0"],["76330.6","0.006547"],["76327.5","0.103022"],["76323.6","0"],["76291.9","2.297369"],["76283","0.721699"],["76281.5","0"],["76269.4","0.05318"],["76241.9","0.119004"],["76225.7","0.719993"],["76195.6","0"]],"a":[["76335.5","0.255664"],["76341.1","0"],["76348.7","0.006547"],["76350.2","0.077943"],["76351.2","0.119141"],["76351.8","0"],["76355.1","0"],["76356","0.006547"],["76360.8","0"],["76365.6","0.144019"],["76366.1","0.330268"],["76393.1","1.200196"],["76395.9","0.48082"],["76398.3","0"],["76411.2","0.048111"]],"u":28058363,"seq":105954748360},"cts":1776816034768}
{"topic":"orderbook.200.BTCUSDT","ts":1776816034869,"type":"delta","data":{"s":"BTCUSDT","b":[["76335.4","0.738134"],["76324.3","0.029539"],["76292","0.750253"],["76291.3","0"],["76283","0.05365"],["76245.4","0.094577"],["76239.3","0.138932"],["76225.7","0.115889"],["76196.2","0"]],"a":[["76335.5","0.027764"],["76341.8","0.102187"],["76341.9","0.028238"],["76342","0.094599"],["76342.1","0.044113"],["76342.3","0"],["76345.9","0.042871"],["76346","0.02587"],["76356","0"],["76356.7","0.006547"],["76357.5","0.048439"],["76390.5","1.200196"],["76391.6","0.386482"],["76393.1","0"],["76395.9","0.138993"],["76443.5","0"],["76443.9","0"],["76444","0"],["76444.6","0"],["76444.7","0"]],"u":28058364,"seq":105954748470},"cts":1776816034863}
{"topic":"orderbook.200.BTCUSDT","ts":1776816034972,"type":"delta","data":{"s":"BTCUSDT","b":[["76335.4","0.744504"],["76239.3","0"],["76225.7","0"],["76196.2","0.145575"],["76195.6","0.130981"]],"a":[["76335.5","0.043064"],["76341.5","0.052424"],["76341.6","0.073439"],["76341.9","0"],["76342","0"],["76342.1","0.030085"],["76354.2","0.089696"],["76354.5","0.130981"],["76356.6","0.006547"],["76356.7","0"],["76356.8","0"],["76388.2","0.588707"],["76391.6","0.020662"]],"u":28058365,"seq":105954748578},"cts":1776816034970}
{"topic":"orderbook.200.BTCUSDT","ts":1776816035068,"type":"delta","data":{"s":"BTCUSDT","b":[["76335.4","0.749964"],["76248.5","0.040337"],["76239.3","0.527992"],["76196.2","0"],["76195.6","0"]],"a":[["76335.5","0.027764"],["76341.1","0.034984"],["76341.2","0.052825"],["76341.5","0"],["76341.6","0"],["76341.8","0"],["76356","0.006547"],["76356.6","0"],["76443.5","0.000094"]],"u":28058366,"seq":105954748671},"cts":1776816035067}
{"topic":"orderbook.200.BTCUSDT","ts":1776816035169,"type":"delta","data":{"s":"BTCUSDT","b":[["76335.4","0.836526"],["76333.2","0.000139"],["76332.3","0.006547"],["76330.6","0"],["76196.3","0"]],"a":[["76341.1","0.015768"],["76348.7","0"],["76350.1","0.006547"],["76356","0"],["76357.4","0.006547"]],"u":28058367,"seq":105954748772},"cts":1776816035167}
{"topic":"orderbook.200.BTCUSDT","ts":1776816035269,"type":"delta","data":{"s":"BTCUSDT","b":[["76332.3","0"],["76330.6","0.006547"]],"a":[["76340.9","0.019105"],["76341","0.064003"],["76341.1","0"],["76341.2","0"],["76348.3","0.006547"],["76350.1","0"],["76356","0.006547"],["76357.4","0"]],"u":28058368,"seq":105954748851},"cts":1776816035265}
{"topic":"orderbook.200.BTCUSDT","ts":1776816035369,"type":"delta","data":{"s":"BTCUSDT","b":[],"a":[["76335.5","0.027257"]],"u":28058369,"seq":105954748893},"cts":1776816035365}
{"topic":"orderbook.200.BTCUSDT","ts":1776816035469,"type":"delta","data":{"s":"BTCUSDT","b":[["76335.4","0.781073"]],"a":[],"u":28058370,"seq":105954748961},"cts":1776816035468}
{"topic":"orderbook.200.BTCUSDT","ts":1776816035569,"type":"delta","data":{"s":"BTCUSDT","b":[["76333.6","0.022256"],["76294.5","2.367816"],["76291.9","0"],["76197","0"]],"a":[["76335.5","0.081457"],["76382.7","1.214363"],["76390.5","0"]],"u":28058371,"seq":105954749016},"cts":1776816035566}
{"topic":"orderbook.200.BTCUSDT","ts":1776816035669,"type":"delta","data":{"s":"BTCUSDT","b":[["76330.6","0.006546"],["76299.8","0.298155"],["76299.7","2.367816"],["76298.7","0"],["76294.5","0"],["76292","0"],["76291.3","0.118545"],["76234.2","0.035032"],["76198.1","0"]],"a":[["76380.6","0.415736"],["76388.2","0.26423"]],"u":28058372,"seq":105954749070},"cts":1776816035666}
{"topic":"orderbook.200.BTCUSDT","ts":1776816035772,"type":"delta","data":{"s":"BTCUSDT","b":[["76330.6","0"],["76329.5","0.006546"],["76299.8","0.803693"],["76251.4","0.12"],["76198.5","0"]],"a":[["76340.8","0.001309"],["76443.5","0"]],"u":28058373,"seq":105954749093},"cts":1776816035761}
{"topic":"orderbook.200.BTCUSDT","ts":1776816035869,"type":"delta","data":{"s":"BTCUSDT","b":[["76234.2","0.05263"]],"a":[],"u":28058374,"seq":105954749124},"cts":1776816035861}
{"topic":"orderbook.200.BTCUSDT","ts":1776816036169,"type":"delta","data":{"s":"BTCUSDT","b":[["76335.4","0.867635"],["76330.6","0.006546"],["76329.5","0"]],"a":[["76336","0.02394"],["76443.2","0"]],"u":28058375,"seq":105954749196},"cts":1776816036159}
{"topic":"orderbook.200.BTCUSDT","ts":1776816036269,"type":"delta","data":{"s":"BTCUSDT","b":[["76335.3","0.007076"],["76274","0.980277"],["76198.7","0"]],"a":[],"u":28058376,"seq":105954749218},"cts":1776816036265}
{"topic":"orderbook.200.BTCUSDT","ts":1776816036369,"type":"delta","data":{"s":"BTCUSDT","b":[["76335.4","0.781073"]],"a":[],"u":28058377,"seq":105954749234},"cts":1776816036362}
{"topic":"orderbook.200.BTCUSDT","ts":1776816036469,"type":"delta","data":{"s":"BTCUSDT","b":[["76335.4","0.767299"],["76332.7","0.013781"],["76330.6","0"],["76329.4","0.006547"],["76318.9","0"],["76198.7","0.6"]],"a":[["76335.5","0.216457"],["76338.2","0"],["76340.8","0"],["76340.9","0"],["76341","0"],["76342.1","0"],["76343","0.026801"],["76345.9","0.078253"],["76347.2","0.111023"],["76348.2","0.006547"],["76348.3","0"],["76350.2","0.04226"],["76351.2","0"],["76354.5","0"],["76355.9","0.006547"],["76356","0"],["76356.9","0.01021"],["76362.2","0"],["76382.7","0"],["76408.7","1.214363"],["76443.2","0.00032"],["76443.5","0.000094"],["76443.9","0.000074"],["76444","0.001124"],["76444.6","0.000099"]],"u":28058378,"seq":105954749390},"cts":1776816036468}
{"topic":"orderbook.200.BTCUSDT","ts":1776816036571,"type":"delta","data":{"s":"BTCUSDT","b":[["76342.6","0.31109"],["76342.4","0.02019"],["76342.3","0.028059"],["76340.3","0.02549"],["76340.1","0.013815"],["76339.9","0.009281"],["76339.5","0.013802"],["76336","0.283857"],["76335.9","0.037596"],["76335.5","0.037596"],["76335.4","0.083068"],["76335.3","0.020857"],["76335","0.0044"],["76333.6","0"],["76332.8","0.049825"],["76332.7","0"],["76332.2","0"],["76332","0.04003"],["76331.7","0.10656"],["76331.1","0.013101"],["76330.5","0"],["76329.4","0"],["76329.2","0.115503"],["76329","0.001"],["76328.6","0"],["76327.8","0.033884"],["76327.5","0"],["76327.3","0.06551"],["76326.1","0"],["76324.2","0"],["76322.3","0"],["76308.7","0.162437"],["76304.9","2.367816"],["76299.7","0"],["76290.7","0.685263"],["76279.2","0"],["76270.2","0.687753"],["76269.8","0.130981"],["76261.1","0"],["76239.3","0.039705"],["76214.3","0.156671"],["76200","0"],["76199.7","0"],["76199.6","0"],["76198.8","0"],["76198.7","0"]],"a":[["76335.5","0"],["76336","0"],["76342.7","0.481979"],["76343.1","0"],["76345.6","0.027389"],["76348.2","0"],["76348.4","0"],["76349.1","0.024682"],["76350.3","0.0084"],["76351.3","0.013092"],["76352.2","0"],["76353.2","0.065463"],["76353.3","0.006546"],["76354.2","0.056873"],["76355.1","0.065461"],["76355.9","0"],["76356.9","0"],["76357.4","0.06493"],["76360.7","0.006547"],["76360.8","0.031456"],["76360.9","0"],["76380.6","0.061055"],["76400.9","1.204549"],["76406.8","0.464666"],["76408.7","0"],["76427.4","0"],["76436.7","0"],["76444.7","0.000984"],["76444.8","0.000102"]],"u":28058379,"seq":105954750001},"cts":1776816036570}
{"topic":"orderbook.200.BTCUSDT","ts":1776816036669,"type":"delta","data":{"s":"BTCUSDT","b":[["76342.6","0.34999"],["76342.3","0"],["76341.7","0.02806"],["76336","0.030739"],["76335.9","0"],["76335.5","0"],["76335.4","0.076522"],["76334.8","0.001198"],["76333.2","0"],["76332.1","0.006547"],["76324.3","0"],["76323","0.023034"],["76307.7","0.23745"],["76299.8","0.25669"],["76281","0"],["76261.6","0.069821"],["76200","0.007145"],["76199.7","0.008995"],["76199.6","0.17438"],["76198.8","0.008995"]],"a":[["76342.7","0.493809"],["76353.3","0"],["76390.5","1.204549"],["76400.9","0"],["76406.8","0.109467"],["76426.2","0.08757"],["76433.7","0.184849"],["76444.9","0.246269"]],"u":28058380,"seq":105954750098},"cts":1776816036667}
{"topic":"orderbook.200.BTCUSDT","ts":1776816036769,"type":"delta","data":{"s":"BTCUSDT","b":[["76342.6","0.291156"],["76333.6","0.006547"],["76332.1","0"],["76285.1","0.743265"],["76278","0.743334"],["76199.6","0"],["76198.8","0"]],"a":[["76342.7","0.494719"],["76353.1","0.006547"],["76435.5","0.741803"],["76442.6","0.741734"],["76444.7","0"],["76444.8","0"],["76444.9","0"]],"u":28058381,"seq":105954750158},"cts":1776816036767}
{"topic":"orderbook.200.BTCUSDT","ts":1776816036869,"type":"delta","data":{"s":"BTCUSDT","b":[["76341.7","0"],["76338.5","0.025491"],["76333.6","0"],["76333","0.006547"]],"a":[["76348.7","0.01"],["76351.2","0.006547"],["76353.1","0"],["76365.7","0"]],"u":28058382,"seq":105954750186},"cts":1776816036868}
{"topic":"orderbook.200.BTCUSDT","ts":1776816036969,"type":"delta","data":{"s":"BTCUSDT","b":[["76342.6","0.414956"],["76333.6","0.006547"],["76333","0"]],"a":[["76348.7","0"],["76351.2","0"],["76351.8","0.006547"],["76444.7","0.000984"]],"u":28058383,"seq":105954750231},"cts":1776816036967}
{"topic":"orderbook.200.BTCUSDT","ts":1776816037068,"type":"delta","data":{"s":"BTCUSDT","b":[["76342.6","0.360756"],["76332.1","0.010312"],["76199.7","0"]],"a":[["76351.2","0.006547"],["76351.8","0"],["76354.2","0.202676"],["76356.2","0.460895"],["76359.8","0.006547"],["76359.9","0.010497"],["76360.7","0"],["76444.6","0"],["76444.7","0"]],"u":28058384,"seq":105954750262},"cts":1776816037067}
{"topic":"orderbook.200.BTCUSDT","ts":1776816037169,"type":"delta","data":{"s":"BTCUSDT","b":[["76342.6","0.322265"],["76333.6","0"],["76331.8","0.006547"]],"a":[["76348.8","0.007547"],["76351.2","0"],["76357.4","0.071477"],["76359.8","0"],["76378.1","0.03"],["76444.6","0.000099"]],"u":28058385,"seq":105954750353},"cts":1776816037158}
{"topic":"orderbook.200.BTCUSDT","ts":1776816037269,"type":"delta","data":{"s":"BTCUSDT","b":[["76339.9","0"],["76339.6","0.01193"],["76332.9","0.007547"],["76331.8","0"],["76199.7","0.008995"]],"a":[["76348.8","0.001"],["76350.1","0.006547"],["76357.4","0.06493"],["76359.8","0.006547"],["76444","0"],["76444.6","0"]],"u":28058386,"seq":105954750385},"cts":1776816037265}
{"topic":"orderbook.200.BTCUSDT","ts":1776816037371,"type":"delta","data":{"s":"BTCUSDT","b":[["76333","0.006547"],["76332.9","0.001"],["76199.7","0"]],"a":[["76350.1","0"],["76351.2","0.006547"]],"u":28058387,"seq":105954750408},"cts":1776816037355}
{"topic":"orderbook.200.BTCUSDT","ts":1776816037469,"type":"delta","data":{"s":"BTCUSDT","b":[["76341","0.024071"],["76340.3","0"]],"a":[],"u":28058388,"seq":105954750432},"cts":1776816037461}
{"topic":"orderbook.200.BTCUSDT","ts":1776816037569,"type":"delta","data":{"s":"BTCUSDT","b":[["76340.8","0.001"],["76333.6","0.006547"],["76333","0"],["76276.2","0.546938"],["76200","0"]],"a":[],"u":28058389,"seq":105954750457},"cts":1776816037561}
{"topic":"orderbook.200.BTCUSDT","ts":1776816037669,"type":"delta","data":{"s":"BTCUSDT","b":[["76333.6","0"],["76333","0.006547"]],"a":[],"u":28058390,"seq":105954750466},"cts":1776816037660}
{"topic":"orderbook.200.BTCUSDT","ts":1776816037769,"type":"delta","data":{"s":"BTCUSDT","b":[["76333.6","0.006547"],["76333","0"]],"a":[],"u":28058391,"seq":105954750489},"cts":1776816037749}
{"topic":"orderbook.200.BTCUSDT","ts":1776816038069,"type":"delta","data":{"s":"BTCUSDT","b":[["76342.6","0.746709"],["76341","0"],["76340.1","0"],["76337.8","0.013783"],["76336.4","0.013838"],["76336.1","0.006547"],["76335.4","0.05"],["76335.3","0.007076"],["76333.6","0"],["76332","0.026201"]],"a":[["76342.7","0.304079"],["76343","0"],["76345.9","0"],["76348.9","0.091"],["76351.2","0"],["76356.1","0.030984"],["76357.4","0.019576"],["76357.5","0"],["76359.8","0"],["76360.8","0"],["76360.9","0.006547"],["76361","0.000099"],["76367.2","0"],["76370.7","0.03"],["76371.8","0.03"],["76444","0.001124"],["76444.6","0.000099"],["76444.7","0.000984"],["76444.8","0.000102"],["76444.9","0.246269"]],"u":28058392,"seq":105954750615},"cts":1776816038058}
{"topic":"orderbook.200.BTCUSDT","ts":1776816038171,"type":"delta","data":{"s":"BTCUSDT","b":[["76342.6","0.336082"],["76342.4","0"],["76341.5","0.024071"],["76339.7","0.01529"],["76337.9","0.025267"],["76336.1","0"],["76336","0.018708"],["76332.1","0"],["76327.8","0.002428"],["76323.5","0.001"],["76319.3","0.031456"],["76318.5","0.130981"],["76318.4","0"],["76200.4","0"]],"a":[["76342.7","0.807555"],["76343.3","0.031873"],["76347.1","0.068268"],["76357.4","0"],["76358.7","0.048439"],["76360.9","0"],["76361.6","0.006547"],["76363.6","0.031456"],["76366","0.130981"],["76371.3","0.019637"],["76371.8","0"],["76444.6","0"],["76444.7","0"],["76444.8","0"],["76444.9","0"]],"u":28058393,"seq":105954750768},"cts":1776816038169}
{"topic":"orderbook.200.BTCUSDT","ts":1776816038269,"type":"delta","data":{"s":"BTCUSDT","b":[["76342.6","0.322265"],["76341.5","0"],["76340.9","0.026661"],["76340.8","0.025072"],["76339.7","0.011135"],["76339.6","0"],["76339.4","0.013817"],["76338","0.034495"],["76337.8","0"],["76336","0"],["76333.9","0.013783"],["76333.6","0.006546"],["76201","0"]],"a":[["76342.7","0.811853"],["76358.5","0.006547"],["76358.6","0.017622"],["76361.6","0"],["76361.7","0.078474"],["76362.5","0.019637"],["76371.3","0"],["76444","0"]],"u":28058394,"seq":105954750857},"cts":1776816038266}
{"topic":"orderbook.200.BTCUSDT","ts":1776816038369,"type":"delta","data":{"s":"BTCUSDT","b":[["76333.6","0"],["76333","0.006547"]],"a":[],"u":28058395,"seq":105954750880},"cts":1776816038360}
{"topic":"orderbook.200.BTCUSDT","ts":1776816038469,"type":"delta","data":{"s":"BTCUSDT","b":[["76342.6","0.26787"],["76340.9","0"],["76333","0"],["76331.8","0.006547"],["76201","0.006284"]],"a":[["76378.1","0"],["76444","0.001124"]],"u":28058396,"seq":105954750976},"cts":1776816038465}
{"topic":"orderbook.200.BTCUSDT","ts":1776816038568,"type":"delta","data":{"s":"BTCUSDT","b":[["76340.8","0.001"],["76338.5","0"],["76338","0.022839"],["76337.9","0"],["76336.4","0"],["76333","0.006547"],["76332.1","0.013838"],["76331.8","0"],["76330.4","0.010649"],["76327.7","0.14943"],["76307.7","0.818882"],["76278.1","0.279714"],["76239.3","0.409001"],["76200.4","0.006521"]],"a":[["76388.2","0.590007"],["76433.7","0.382644"]],"u":28058397,"seq":105954751135},"cts":1776816038567}
{"topic":"orderbook.200.BTCUSDT","ts":1776816038669,"type":"delta","data":{"s":"BTCUSDT","b":[["76339.6","0.01543"],["76338.9","0.024072"],["76333.5","0"],["76333","0"],["76332.2","0.006547"],["76200.4","0"]],"a":[],"u":28058398,"seq":105954751236},"cts":1776816038651}
{"topic":"orderbook.200.BTCUSDT","ts":1776816038971,"type":"delta","data":{"s":"BTCUSDT","b":[["76338.9","0"],["76338.3","0.024072"]],"a":[],"u":28058399,"seq":105954751317},"cts":1776816038956}
{"topic":"orderbook.200.BTCUSDT","ts":1776816039169,"type":"delta","data":{"s":"BTCUSDT","b":[["76342.6","0"],["76340.8","0"],["76339.7","0"],["76339.6","0"],["76339.5","0"],["76339.4","0"],["76338.3","0"],["76338","0"],["76335.4","0"],["76335.3","0"],["76335","0"],["76334.8","0"],["76333.9","0"],["76332.9","0"],["76332.8","0"],["76332.2","0"],["76332.1","0"],["76332","0"],["76331.7","0"],["76331.1","0.017"],["76330.4","0.032553"],["76329.3","0"],["76329.2","0.065503"],["76329","0.003"],["76327.7","0"],["76326.9","0.013817"],["76326.2","0.0004"],["76325.5","0.013803"],["76323.5","0.005"],["76323","0"],["76322.9","0"],["76321.6","0.015398"],["76321.5","0.013838"],["76321.2","0.023432"],["76319.6","0.013783"],["76319.3","0"],["76319.2","0"],["76318.5","0"],["76312.5","0.07023"],["76308.8","0"],["76308.7","0"],["76307.7","0"],["76305.5","0"],["76305.4","0"],["76304.9","0"],["76304.8","0.031456"],["76303.3","0.019637"],["76302.7","0.006552"],["76301.7","0.130981"],["76300.7","0"],["76270.2","0"],["76263.3","2.366966"],["76260.5","0.687688"],["76214.3","0.982607"],["76200.4","0.006521"],["76200","0.007145"],["76199.7","0.008995"],["76199.6","0.17438"],["76198.8","0.008995"],["76198.7","0.6"],["76198.5","0.000984"],["76198.1","0.082685"],["76197","0.126"],["76196.3","0.008995"],["76196.2","0.145575"],["76195.6","0.130981"],["76195.2","4.109518"],["76195.1","0.008995"],["76195","0.590244"],["76193","0.008995"],["76192","0.006524"],["76190.5","0.00471"],["76190.1","0.008995"],["76188.8","0.054702"],["76188.7","0.126984"]],"a":[["76331.2","0.913884"],["76332.9","0.126"],["76334.9","0.126"],["76335.4","0.074777"],["76336.1","0.001"],["76338.1","0.001"],["76338.7","0.006548"],["76338.8","0.0044"],["76340.9","0.000198"],["76342.7","0.192405"],["76343.3","0"],["76344","0.001"],["76344.4","0.002"],["76345.6","0"],["76346","0"],["76347","0.01"],["76347.1","0"],["76347.2","0"],["76348.9","0.001"],["76349.1","0"],["76350.3","0"],["76350.4","0.019637"],["76352.9","0.031456"],["76356","0.162437"],["76358.5","0"],["76362.5","0"],["76387.9","1.401837"],["76390.5","0"],["76435.4","0.196394"],["76442.7","0"],["76442.8","0"],["76442.9","0"],["76443.2","0"],["76443.5","0"],["76443.9","0"],["76444","0"]],"u":28058400,"seq":105954752432},"cts":1776816039167}
{"topic":"orderbook.200.BTCUSDT","ts":1776816039269,"type":"delta","data":{"s":"BTCUSDT","b":[["76331.1","0"],["76330.4","0"],["76329.2","0"],["76329","0"],["76328.4","0"],["76328.3","0"],["76328.2","0"],["76327.8","0.006828"],["76327.3","0"],["76326.9","0"],["76326.2","0"],["76325.9","0.007951"],["76325.5","0"],["76323.5","0.001"],["76323.4","0.014817"],["76321.8","0.019947"],["76321.6","0"],["76321.5","0"],["76321.2","0"],["76320.8","0.013803"],["76320.2","0.0044"],["76320","0.040432"],["76319.8","0.023396"],["76319.6","0"],["76318.3","0.123448"],["76318.2","0"],["76316.8","0.079354"],["76315.8","0"],["76314.1","0.027554"],["76313.4","0.013783"],["76312.5","0.038774"],["76311.9","0.006548"],["76306.2","0.396886"],["76305","0.086098"],["76304.9","0.162437"],["76304.8","0"],["76304","0"],["76303.3","0"],["76302.5","0.325307"],["76301.7","0.031456"],["76301.6","0"],["76301.5","0"],["76301.4","0"],["76291.2","0"],["76285.1","0"],["76278.1","0.048439"],["76278","0"],["76277.1","0.397038"],["76276.3","0.74335"],["76269.2","0.74342"],["76263.3","0"],["76260.5","0"],["76260.2","0"],["76258.4","0"],["76252.5","0.044563"],["76210.4","0"],["76206.7","0"],["76201.8","0"],["76200.5","0.008995"],["76198.8","0"],["76190.6","0.008995"],["76190.5","0"],["76190.1","0"],["76188.9","0.008995"],["76188","0.008995"],["76187.8","0.034161"],["76186.9","0.048439"],["76186.3","0.008995"],["76184.9","0.130981"],["76184.7","0.006832"],["76182.5","0.008995"],["76181.4","0.003934"],["76180.8","15.797537"],["76180","0.126"],["76178.8","0.002569"],["76177.6","0.008995"],["76176.4","0.008995"],["76175.7","0.000108"],["76173.6","0.048439"],["76172.3","0.126"],["76172","0.639436"]],"a":[["76327.9","1.037027"],["76328.4","0.716332"],["76328.5","0.247096"],["76329.3","0.082084"],["76331.2","0.025428"],["76332.2","0.001"],["76332.8","0.037611"],["76334.8","0.046952"],["76335.4","0.05"],["76335.5","0.0044"],["76336.1","0.001198"],["76336.7","0.006549"],["76337.4","0.024997"],["76338.2","0.000099"],["76338.7","0"],["76338.8","0"],["76340.9","0"],["76342.3","0.013092"],["76342.6","0.086279"],["76342.7","0.179665"],["76344.2","0.065463"],["76344.4","0"],["76345.8","0.029089"],["76346.1","0.065461"],["76349.1","0.130981"],["76349.6","0.031456"],["76351.3","0"],["76353.2","0"],["76355.1","0"],["76365.9","0.397297"],["76372.8","0"],["76380.4","0.199936"],["76382.3","0.013107"],["76387.9","0"],["76388.2","0.26423"],["76396.1","0"],["76397.7","0"],["76408.4","0.00228"],["76426.7","0.741889"],["76433.7","0.184849"],["76433.8","1.342051"],["76435.5","0"],["76440.2","0"],["76440.7","0"],["76440.8","0"],["76440.9","0"],["76441.5","0"],["76441.6","0"],["76442.2","0"],["76442.5","0"],["76442.6","0"]],"u":28058401,"seq":105954753334},"cts":1776816039268}
{"topic":"orderbook.200.BTCUSDT","ts":1776816039369,"type":"delta","data":{"s":"BTCUSDT","b":[["76327.8","0"],["76326.5","0"],["76325.9","0.040139"],["76321.8","0"],["76320.6","0.013102"],["76320.2","0"],["76320","0.000432"],["76319.8","0"],["76319.2","0.051441"],["76318.8","0.023396"],["76318.6","0.065514"],["76318.3","0.0024"],["76316.4","0.025754"],["76316","0.013783"],["76314.2","0.006548"],["76313.4","0"],["76311.9","0"],["76311.6","0.027555"],["76310.9","0.033788"],["76310.8","0.113191"],["76298.5","0.019637"],["76281.5","2.367439"],["76255.4","0.687816"],["76177.6","0"],["76176.4","0"],["76175.7","0"],["76173.6","0"],["76172.3","0"],["76172","0"]],"a":[["76326","1.685645"],["76326.5","0.106613"],["76327.8","0.246896"],["76327.9","0.028184"],["76328.4","0"],["76328.5","0.0026"],["76329.3","0.078184"],["76331.2","0.024778"],["76333.6","0.0044"],["76334.8","0"],["76334.9","0"],["76335.2","0.036936"],["76335.3","0.120457"],["76335.5","0"],["76336.4","0.000984"],["76336.7","0"],["76337.4","0"],["76342.2","0.006549"],["76342.5","0.02899"],["76342.7","0.061"],["76350.2","0"],["76352","0"],["76354.2","0.056873"],["76356.2","0"],["76372.7","0"],["76395.9","0"],["76440.2","0.00055"],["76440.7","0.048439"]],"u":28058402,"seq":105954753780},"cts":1776816039367}
{"topic":"orderbook.200.BTCUSDT","ts":1776816039469,"type":"delta","data":{"s":"BTCUSDT","b":[["76325.9","0"],["76323.5","0"],["76323.4","0.008665"],["76320.8","0"],["76319.7","0.013817"],["76319.2","0.071984"],["76319.1","0.032"],["76318.3","0.0004"],["76316.8","0.065516"],["76316.5","0.013803"],["76316","0"],["76314.2","0"],["76314.1","0"],["76313.2","0.040099"],["76312.9","0.013783"],["76312.4","0.089992"],["76311.9","0.013838"],["76311","0.006549"],["76309.9","0.027555"],["76306.3","0.156111"],["76305","0"],["76304.9","0"],["76302.5","0"],["76299.9","0.130981"],["76291.3","0"],["76290.7","0.000099"],["76281.5","0"],["76261.6","0.067201"],["76251.1","0.687839"],["76242.2","0.00262"],["76240.3","0"],["76195.2","0"],["76177.6","0.008995"],["76176.4","0.008995"],["76175.7","0.000108"]],"a":[["76323.5","1.443362"],["76323.6","0.241294"],["76325.9","0.026158"],["76326","0.028585"],["76326.5","0"],["76326.7","0.001"],["76327.8","0"],["76327.9","0"],["76328.5","0"],["76329.2","0.023338"],["76330.9","0.07089"],["76331","0.105888"],["76331.1","0.004"],["76331.2","0"],["76332.2","0.001198"],["76332.8","0"],["76333.6","0.0004"],["76335.2","0.015845"],["76335.3","0"],["76336","0.006549"],["76336.1","0.001"],["76342.2","0"],["76342.3","0.131978"],["76342.4","0.162437"],["76342.6","0"],["76345.8","0.000099"],["76346.5","0.031456"],["76359.9","0"],["76365.3","0.098551"],["76366.1","0"],["76387.3","0"],["76406.9","0"],["76440.8","0.070902"]],"u":28058403,"seq":105954754358},"cts":1776816039467}
{"topic":"orderbook.200.BTCUSDT","ts":1776816039569,"type":"delta","data":{"s":"BTCUSDT","b":[["76323.4","0.068835"],["76318.3","0"],["76315.8","0.0004"],["76313.8","0.010254"],["76313.2","0.000099"],["76312.6","0.006549"],["76312.4","0.05"],["76311.6","0"],["76311","0"],["76304.8","0.031456"],["76303.5","0.026339"],["76269.4","0.268291"],["76255.4","0"],["76241.9","0"],["76234.2","0.529591"]],"a":[["76323.5","1.445062"],["76323.6","0.094825"],["76326","0.028185"],["76331.1","0.0044"],["76333.6","0"],["76336","0"],["76338","0.006549"],["76340","0.02899"],["76343.9","0.010447"],["76346","0.081591"],["76374.1","0.064351"],["76387.9","1.401837"],["76395.9","0.076738"],["76401.4","0.086431"],["76406.8","0.031456"],["76433.7","0.441273"],["76438.1","0"],["76439.3","0"],["76440","0"],["76440.2","0"],["76440.7","0"],["76440.8","0"]],"u":28058404,"seq":105954754588},"cts":1776816039567}
{"topic":"orderbook.200.BTCUSDT","ts":1776816039669,"type":"delta","data":{"s":"BTCUSDT","b":[["76313.9","0.006548"],["76312.6","0"],["76184.8","0.004731"],["76175.7","0"]],"a":[["76323.5","1.389562"],["76323.6","0.048186"],["76338","0"],["76339.9","0.006549"],["76342.5","0"],["76438.1","0.000635"]],"u":28058405,"seq":105954754707},"cts":1776816039660}
{"topic":"orderbook.200.BTCUSDT","ts":1776816039771,"type":"delta","data":{"s":"BTCUSDT","b":[["76323.4","0.06811"],["76320.7","0.015247"],["76320","0.023828"],["76319.4","0.023396"],["76318.8","0"],["76313.9","0"],["76313","0.006548"],["76302.7","0"],["76276.3","0"],["76270.5","0"],["76269.2","0"],["76259.2","0.008995"],["76201.9","0"],["76199.7","0"],["76196.3","0"],["76193","0"],["76188","0"],["76184.8","0"],["76176.4","0"],["76175.7","0.000108"],["76173.6","0.048439"],["76172.3","0.126"],["76172","0.639436"],["76171","0.003961"],["76170.3","0.6348"],["76169","0.000984"],["76168.1","0.000657"],["76167.7","0.008995"],["76166.5","0.0001"]],"a":[["76323.5","1.353991"],["76325.8","0.01652"],["76338","0.006549"],["76339.9","0"],["76352.4","0.328801"],["76372.3","1.401837"],["76387.9","0"],["76426.7","0"],["76433.8","0.600232"],["76438.1","0"]],"u":28058406,"seq":105954754888},"cts":1776816039765}
{"topic":"orderbook.200.BTCUSDT","ts":1776816039869,"type":"delta","data":{"s":"BTCUSDT","b":[["76313.9","0.006548"],["76313","0"],["76270.3","1.45841"],["76269.4","0.05318"],["76263.1","0.743478"],["76189","0.008995"],["76186.4","0.008995"],["76182.6","0.008995"],["76178.9","0.008995"],["76173.7","0.008995"],["76171","0"],["76170.3","0"],["76169","0"],["76168.1","0"],["76167.7","0"],["76166.5","0"]],"a":[["76323.5","1.363351"],["76338","0"],["76339.9","0.006549"],["76420.6","0.741947"],["76427.8","0.741878"],["76433.7","0.184849"],["76437.9","0"],["76438","0"]],"u":28058407,"seq":105954754941},"cts":1776816039868}
{"topic":"orderbook.200.BTCUSDT","ts":1776816039968,"type":"delta","data":{"s":"BTCUSDT","b":[["76323.4","0.26041"],["76320","0.000432"],["76317.1","0.026206"],["76316.5","0.020351"],["76313.9","0"],["76312.5","0.019056"],["76311.8","0"],["76309.9","0"],["76308.1","0.048439"],["76289.7","0.317635"]],"a":[["76323.5","1.354242"],["76339.9","0"],["76342.2","0.038005"],["76342.3","0.013092"],["76342.4","0"],["76437.9","0.00126"]],"u":28058408,"seq":105954755051},"cts":1776816039964}
{"topic":"orderbook.200.BTCUSDT","ts":1776816040069,"type":"delta","data":{"s":"BTCUSDT","b":[["76316.6","0.007532"],["76316.5","0.013803"],["76315.4","0.013784"],["76312.9","0"],["76251.6","0.024672"],["76172","0"]],"a":[["76323.6","0.028186"],["76329.2","0.017368"],["76329.3","0.058184"],["76342.1","0.006549"],["76342.2","0.031456"],["76437.9","0"]],"u":28058409,"seq":105954755114},"cts":1776816040065}
{"topic":"orderbook.200.BTCUSDT","ts":1776816040169,"type":"delta","data":{"s":"BTCUSDT","b":[["76323.4","0.35041"],["76316.6","0.000984"],["76315.9","0.006548"],["76251.6","0"]],"a":[["76323.5","1.35394"],["76329.2","0"],["76329.3","0.028184"],["76437.9","0.00126"]],"u":28058410,"seq":105954755150},"cts":1776816040166}
{"topic":"orderbook.200.BTCUSDT","ts":1776816040269,"type":"delta","data":{"s":"BTCUSDT","b":[["76323.4","0.28201"],["76322.9","0.015178"],["76322.8","0.013818"],["76320.7","0.000099"],["76319.7","0"],["76315.9","0"],["76315.5","0.006548"],["76184.4","0.004742"],["76173.6","0"],["76172.3","0"]],"a":[["76323.5","1.317062"]],"u":28058411,"seq":105954755201},"cts":1776816040265}
{"topic":"orderbook.200.BTCUSDT","ts":1776816040368,"type":"delta","data":{"s":"BTCUSDT","b":[["76315.5","0"],["76313.9","0.006548"],["76289.7","0"],["76173.6","0.048439"]],"a":[["76339.9","0.006549"],["76342.1","0"],["76352.4","0"],["76438","0.000277"]],"u":28058412,"seq":105954755219},"cts":1776816040366}
{"topic":"orderbook.200.BTCUSDT","ts":1776816040469,"type":"delta","data":{"s":"BTCUSDT","b":[["76323.4","0.280223"],["76322.9","0"],["76320.6","0"],["76320","0.023828"],["76318.6","0"],["76317.1","0"],["76316.8","0"],["76314.1","0.013102"],["76313.9","0"],["76313.8","0"],["76312.7","0.027554"],["76312.2","0.065514"],["76312","0.006548"],["76310.3","0.065516"],["76306.2","0"],["76299.8","0.653576"],["76297.8","0.137256"],["76285.3","0.391274"],["76234.7","0.192309"],["76184.4","0"],["76172.3","0.126"],["76172","0.639436"]],"a":[["76330.9","0.077438"],["76337.1","0.013092"],["76338","0.006549"],["76339","0.065463"],["76339.9","0"],["76340.9","0.065461"],["76342.3","0"],["76344.2","0"],["76346.1","0"],["76389.9","0.369305"],["76404.6","0"],["76438.1","0.000635"]],"u":28058413,"seq":105954755388},"cts":1776816040467}
