{"instId":"BTC-USDT","action":"update","ts":"1776816006090","asks":[["76381.6","0.00654436","1"],["76381.9","0","0"]],"bids":[["76362.4","0.00654436","1"],["76362.3","0.1","1"],["76186","0","0"]]}
{"instId":"BTC-USDT","action":"update","ts":"1776816006100","asks":[["76372.5","0.33511171","10"],["76386.8","0.32725595","1"],["76387.3","0","0"]],"bids":[["76372.4","0.35585876","16"],["76362.4","0.1","1"],["76362.2","0","0"],["76360","0.00655468","2"],["76354.3","0.00305","1"],["76353.4","0.00654512","1"]]}
{"instId":"BTC-USDT","action":"update","ts":"1776816006110","asks":[["76380.4","0.00714284","2"],["76381.6","0","0"],["76388.6","0.00654515","1"],["76391.5","0","0"],["76397","0.01560248","1"]],"bids":[["76359.8","0","0"],["76186","0.00170529","1"]]}
{"instId":"BTC-USDT","action":"update","ts":"1776816006120","asks":[["76372.5","0.31571171","9"],["76380.4","0.0005985","1"],["76381.6","0.00654439","1"],["76473.2","0","0"]],"bids":[["76359.9","0.0413601","2"]]}
{"instId":"BTC-USDT","action":"update","ts":"1776816006140","asks":[["76372.5","0.31631021","10"],["76380.4","0","0"],["76401.3","0.10780066","1"],["76425.2","0","0"],["76435.4","0","0"],["76473.2","0.00001599","1"],["76473.3","0.00564466","1"]],"bids":[]}
{"instId":"BTC-USDT","action":"update","ts":"1776816006150","asks":[["76372.5","0.33571021","11"]],"bids":[]}
{"instId":"BTC-USDT","action":"update","ts":"1776816006160","asks":[["76444.6","0.00001012","1"]],"bids":[]}
{"instId":"BTC-USDT","action":"update","ts":"1776816006170","asks":[["76372.5","0.33552691","11"],["76380.4","0.00654449","1"],["76381.6","0","0"]],"bids":[]}
{"instId":"BTC-USDT","action":"update","ts":"1776816006180","asks":[["76380.4","0","0"],["76381.6","0.00654448","1"]],"bids":[]}
{"instId":"BTC-USDT","action":"update","ts":"1776816006200","asks":[["76372.5","0.33534623","11"],["76381.6","0.0065445","1"]],"bids":[]}
{"instId":"BTC-USDT","action":"update","ts":"1776816006210","asks":[["76372.5","0.33528077","11"],["76380.4","0.0065445","1"],["76381.6","0","0"]],"bids":[]}
{"instId":"BTC-USDT","action":"update","ts":"1776816006220","asks":[["76380.4","0","0"],["76381.6","0.00654452","1"]],"bids":[["76372.4","0.34038883","16"]]}
{"instId":"BTC-USDT","action":"update","ts":"1776816006230","asks":[["76387.8","0.21223725","3"]],"bids":[]}
{"instId":"BTC-USDT","action":"update","ts":"1776816006240","asks":[["76403.1","0.05305931","1"],["76435.4","0.00003961","1"],["76473.2","0","0"],["76473.3","0","0"]],"bids":[]}
{"instId":"BTC-USDT","action":"update","ts":"1776816006260","asks":[["76372.5","0.33646077","12"],["76387.9","0.00654523","1"],["76388.6","0","0"]],"bids":[["76372.4","0.30817394","15"]]}
{"instId":"BTC-USDT","action":"update","ts":"1776816006270","asks":[],"bids":[["76372.4","0.26184394","13"]]}
{"instId":"BTC-USDT","action":"update","ts":"1776816006280","asks":[],"bids":[["76372.4","0.30494394","14"],["76353.4","0","0"],["76352.4","0.00654522","1"]]}
{"instId":"BTC-USDT","action":"update","ts":"1776816006290","asks":[],"bids":[["76353.4","0.00654522","1"],["76352.4","0","0"]]}
{"instId":"BTC-USDT","action":"update","ts":"1776816006300","asks":[["76372.5","0.33508594","12"],["76403.1","0","0"],["76473.2","0.00001599","1"]],"bids":[]}
{"instId":"BTC-USDT","action":"update","ts":"1776816006310","asks":[["76385.2","0.3272616","1"],["76386.8","0","0"],["76387.7","0.00654523","1"],["76387.9","0","0"]],"bids":[["76367.1","0.00001034","1"],["76355.4","0","0"],["76353.4","0","0"],["76352.4","0.33380683","2"],["76185.3","0.00002512","1"]]}
{"instId":"BTC-USDT","action":"update","ts":"1776816006320","asks":[["76387.8","0.26529656","4"]],"bids":[["76365","0.00002996","2"],["76334.7","0.00001316","1"],["76185.3","0","0"]]}
{"instId":"BTC-USDT","action":"update","ts":"1776816006330","asks":[["76377.6","0.12929021","6"],["76378.6","0.47151308","1"],["76421.3","0","0"]],"bids":[["76372.4","0.0002805","9"],["76368.9","0","0"],["76368.8","0.0000168","1"],["76364.7","0.1","1"],["76185.3","0.00002512","1"]]}
{"instId":"BTC-USDT","action":"update","ts":"1776816006340","asks":[["76367.1","0.91146817","15"],["76367.2","0.00375277","1"],["76368.9","0.09143","1"],["76370.7","0.47151308","1"],["76372.4","0.11733863","1"],["76372.5","0.10457632","5"],["76377.5","0.31307441","2"],["76377.6","0.01512057","5"],["76378.5","0.00654458","1"],["76381.6","0.08378297","1"],["76382.5","0.32726841","1"],["76382.6","0","0"],["76383.8","0.07997","1"],["76385.1","0.13446017","2"],["76385.2","0","0"],["76387.5","0","0"],["76387.7","0","0"],["76387.8","0","0"],["76391.7","0.00001316","1"],["76397","0.14390416","1"],["76401.6","0","0"],["76406.7","0.14123927","1"],["76406.8","0","0"],["76411.6","0.1305797","1"],["76411.7","0.00001316","1"],["76416.7","0.01372832","1"],["76420.8","0.000015","1"],["76424.6","0.00016335","2"],["76472.4","0","0"],["76472.5","0","0"],["76472.6","0","0"],["76473","0","0"],["76473.2","0","0"]],"bids":[["76372.4","0","0"],["76370.5","0","0"],["76368.8","0","0"],["76368.6","0","0"],["76367.1","0","0"],["76367","0.24249409","4"],["76366.9","0.12003417","1"],["76366.8","0.00001155","1"],["76366.5","0.09564086","2"],["76360","0.00001033","1"],["76357.3","0.00654458","1"],["76357","0","0"],["76356.8","0","0"],["76355.3","0","0"],["76352.4","0","0"],["76352.2","0","0"],["76351.3","0.3273147","2"],["76349.9","0.00654536","1"],["76349.8","0.14257208","1"],["76346","1.4771113","2"],["76345.7","0.09233047","6"],["76342","0.47152988","2"],["76341.8","0","0"],["76341.6","0","0"],["76341.5","0.00523632","1"],["76325.6","0","0"],["76317.6","0.1238899","2"],["76211.2","1.00559822","1"],["76184.8","0.01614584","1"],["76184.2","3.72","1"],["76184.1","0.47151308","1"],["76183.9","0.00003806","1"],["76183.7","0.00001319","1"],["76183.4","0.00005866","1"],["76183.3","0.00009283","1"],["76183","0.01496","1"]]}
{"instId":"BTC-USDT","action":"update","ts":"1776816006350","asks":[["76367.1","0.93269141","18"],["76367.2","0","0"],["76368.9","0","0"],["76370.1","0.0471715","1"],["76370.6","0.14074665","1"],["76372.4","0","0"],["76372.5","0.10195856","4"],["76372.8","0","0"],["76381.6","0","0"],["76382.4","0.21223725","3"],["76382.5","0","0"],["76383.7","0.32726841","1"],["76420.8","0.12526492","2"],["76440","0.01150708","9"],["76472.4","0.00002715","1"],["76472.5","0.00008103","2"]],"bids":[["76367","0.24511201","5"],["76366.9","0.05848514","1"],["76357.2","0.07424978","7"],["76352.3","0.000015","1"],["76351.2","0.06551567","2"],["76349.9","0.47805844","2"],["76347","0.01344324","1"],["76341.7","0.08379382","2"],["76336.4","0.26182997","4"],["76300","0.00358153","3"],["76184","0.1305","1"],["76183.4","0","0"],["76183.3","0","0"],["76183","0","0"]]}
{"instId":"BTC-USDT","action":"update","ts":"1776816006360","asks":[["76367.1","0.95552141","19"],["76372.4","0.03366942","1"],["76472.5","0","0"]],"bids":[["76351.4","0.30252152","1"],["76183.7","0","0"]]}
{"instId":"BTC-USDT","action":"update","ts":"1776816006370","asks":[["76382.4","0.15917794","2"]],"bids":[["76364.7","0.12619","2"],["76349.1","0.51949013","3"]]}
{"instId":"BTC-USDT","action":"update","ts":"1776816006380","asks":[["76367.1","0.85091708","16"]],"bids":[["76367","0.51877384","8"],["76336.4","0.21095284","3"]]}
{"instId":"BTC-USDT","action":"update","ts":"1776816006390","asks":[["76367.1","0.85091707","15"],["76382.4","0.05305931","1"],["76385","0.07987316","2"],["76392.7","0.01597292","1"],["76397.7","0.05305931","1"],["76425.3","0.10683643","1"],["76442.2","0.57584894","5"],["76445.9","0","0"],["76472","0","0"],["76472.4","0","0"]],"bids":[["76367","0.52269549","11"],["76348.3","0.0158081","1"],["76341.8","0.17663413","1"],["76331.7","0","0"],["76319.4","0","0"],["76315.3","0.00235221","2"]]}
{"instId":"BTC-USDT","action":"update","ts":"1776816006400","asks":[["76367.1","0.85087779","15"],["76440.4","0.00093678","1"],["76442.2","0.57491216","4"],["76443.1","0.0005044","6"],["76448.8","0","0"]],"bids":[["76365.3","0.0471715","1"],["76322","0","0"],["76317","0.00325149","1"],["76315.3","0.00001681","1"],["76314.2","0.0023354","1"],["76184","0","0"],["76183.9","0","0"]]}
{"instId":"BTC-USDT","action":"update","ts":"1776816006410","asks":[["76367.1","0.85079006","15"],["76382.4","0","0"],["76472","0.000059","1"]],"bids":[["76364.7","0.12625462","3"],["76336.4","0.15917794","2"]]}
{"instId":"BTC-USDT","action":"update","ts":"1776816006430","asks":[["76370","0.00076028","1"],["76376.3","0.0002005","4"],["76378.8","0.00001034","1"],["76381.1","0.00001086","1"],["76384.1","0","0"],["76385.8","0.0001361","2"],["76397.7","0.26529656","4"],["76471.7","0","0"],["76471.8","0","0"],["76471.9","0","0"],["76472","0","0"]],"bids":[["76351.7","0.10265203","2"],["76326.3","0.10131016","2"],["76184.1","0","0"]]}
{"instId":"BTC-USDT","action":"update","ts":"1776816006440","asks":[["76374.7","0","0"],["76376.3","0.00023743","5"],["76377.4","0.0065817","2"],["76378.5","0","0"],["76379.6","0.00001033","1"],["76382.6","0.00001154","1"],["76385.1","0.13447051","3"],["76385.8","0.00018116","3"],["76392.7","0","0"],["76397.7","0.15917793","3"],["76431.7","0.00003959","1"],["76435.4","0","0"]],"bids":[["76357.3","0.00654476","1"],["76326.4","0.03742293","1"],["76310.1","0","0"],["76306.5","1.00939481","2"]]}
{"instId":"BTC-USDT","action":"update","ts":"1776816006450","asks":[["76367.1","0.83443006","15"],["76382","0","0"],["76397.7","0.21223725","3"],["76429.9","0.00003959","1"],["76431.7","0","0"],["76471.7","0.00029028","5"]],"bids":[["76367","0.68269549","12"],["76351.7","0.05087713","1"],["76306.5","1.00616208","1"],["76304.4","0.00323273","1"],["76184.2","0","0"]]}
{"instId":"BTC-USDT","action":"update","ts":"1776816006460","asks":[["76397.7","0.26529656","4"]],"bids":[]}
{"instId":"BTC-USDT","action":"update","ts":"1776816006470","asks":[["76367.1","0.81160006","14"]],"bids":[["76336.4","0","0"],["76184.2","3.72","1"]]}
{"instId":"BTC-USDT","action":"update","ts":"1776816006480","asks":[["76372.5","0.00094856","2"]],"bids":[["76367","0.52269549","11"]]}
{"instId":"BTC-USDT","action":"update","ts":"1776816006490","asks":[["76367.1","0.87678006","15"],["76372.4","0","0"],["76471.8","0.00007776","1"]],"bids":[["76334.2","0.00027016","8"],["76330.4","0.00017509","4"],["76328.6","0.12386253","3"],["76326.6","0.00023743","5"],["76323","0.00001155","1"],["76322.8","0.13203918","6"],["76319","0.00023744","5"],["76317.4","0.5553076","3"],["76315.1","0.00023744","5"],["76311.8","0.00001155","1"],["76311.3","0.00023744","5"],["76307.5","0.00023747","5"],["76306.2","0.00001155","1"],["76303.7","0.00023748","5"],["76299.9","0.00023748","5"],["76185.3","0","0"],["76184.8","0","0"],["76184.2","0","0"]]}
{"instId":"BTC-USDT","action":"update","ts":"1776816006500","asks":[],"bids":[["76351.7","0.26182997","4"],["76334.2","0.0002805","9"],["76330.4","0.00023743","5"],["76328.9","0.00001034","1"],["76323.6","0.00001034","1"],["76318.3","0.00001034","1"],["76313","0.00001035","1"],["76307.7","0.00002716","2"],["76302.4","0.00001035","1"],["76187.7","0","0"],["76187.5","0","0"],["76187","0","0"],["76186.4","0","0"],["76186","0","0"]]}
{"instId":"BTC-USDT","action":"update","ts":"1776816006510","asks":[],"bids":[["76334.5","0","0"],["76304.4","0","0"],["76187.7","0.47151308","1"],["76187.5","0.00032499","3"]]}
{"instId":"BTC-USDT","action":"update","ts":"1776816006530","asks":[["76384.1","0.00008403","1"],["76471.8","0","0"]],"bids":[["76351.7","0.15571134","3"]]}
{"instId":"BTC-USDT","action":"update","ts":"1776816006540","asks":[["76377.4","0.00654476","1"],["76382.6","0","0"],["76471.8","0.00007776","1"]],"bids":[["76351.7","0.10265203","2"],["76187.8","0","0"],["76187","0.00011911","5"]]}
{"instId":"BTC-USDT","action":"update","ts":"1776816006550","asks":[],"bids":[["76347","0","0"],["76336.4","0.10611863","1"]]}
{"instId":"BTC-USDT","action":"update","ts":"1776816006560","asks":[["76429.9","0","0"],["76471.9","0.0003932","1"]],"bids":[["76351","0.01344254","1"],["76336.4","0.15917794","2"],["76304.5","0.0032459","2"],["76187","0","0"]]}
{"instId":"BTC-USDT","action":"update","ts":"1776816006590","asks":[["76397.7","0.10611862","2"]],"bids":[["76351.7","0.05087713","1"]]}
{"instId":"BTC-USDT","action":"update","ts":"1776816006600","asks":[["76382.4","0.15917794","2"],["76471.9","0","0"]],"bids":[["76336.4","0.21095284","3"]]}
{"instId":"BTC-USDT","action":"update","ts":"1776816006610","asks":[["76372.5","0.00093856","1"]],"bids":[]}
{"instId":"BTC-USDT","action":"update","ts":"1776816006630","asks":[],"bids":[["76330.2","0.00002865","1"],["76187.5","0","0"]]}
{"instId":"BTC-USDT","action":"update","ts":"1776816006640","asks":[["76376.3","0.0002005","4"],["76379.6","0.0000842","2"],["76382.6","0.00001154","1"],["76393.5","0.01599489","1"],["76471.7","0","0"],["76471.8","0","0"]],"bids":[["76348.3","0","0"],["76187.5","0.00032499","3"]]}
{"instId":"BTC-USDT","action":"update","ts":"1776816006650","asks":[["76429.9","0.00003958","1"],["76471.5","0","0"]],"bids":[]}
{"instId":"BTC-USDT","action":"update","ts":"1776816006710","asks":[["76367.1","0.87674078","15"]],"bids":[]}
{"instId":"BTC-USDT","action":"update","ts":"1776816006740","asks":[["76376.3","0.00027436","5"],["76379.6","0.00001033","1"]],"bids":[]}
{"instId":"BTC-USDT","action":"update","ts":"1776816006800","asks":[],"bids":[["76187.7","0.47454308","2"]]}
{"instId":"BTC-USDT","action":"update","ts":"1776816006820","asks":[],"bids":[["76237.2","0.000655","1"],["76187.5","0","0"]]}
{"instId":"BTC-USDT","action":"update","ts":"1776816006840","asks":[["76376.3","0.0002005","4"],["76379.6","0.00004727","2"]],"bids":[]}
{"instId":"BTC-USDT","action":"update","ts":"1776816006850","asks":[["76367.1","0.87750106","16"],["76370","0","0"],["76377.4","0.13058892","1"],["76380.4","0.00654468","1"],["76383.7","0","0"],["76384.9","0.32726976","1"],["76397.7","0.05305931","1"]],"bids":[["76351.8","0.32726976","1"],["76351.7","0","0"],["76351.3","0.00004629","1"]]}
{"instId":"BTC-USDT","action":"update","ts":"1776816006860","asks":[["76367.7","0.0471715","1"],["76370.1","0","0"],["76377.3","0.00654468","1"],["76380.4","0","0"],["76381.6","0.32726978","1"],["76382.4","0.21223725","3"],["76384.9","0.00654539","1"],["76385.1","0.12792515","2"],["76397.7","0","0"]],"bids":[["76367","0.43642115","8"],["76359.6","0.12254086","1"],["76357.3","0.00654468","1"],["76356.7","0.00261817","1"],["76351.8","0","0"],["76351.4","0.2088445","1"],["76350","0.00655694","2"],["76349.9","0.47151308","1"],["76349.2","0.32726978","1"],["76336.4","0.26182997","4"],["76187.7","0","0"]]}
{"instId":"BTC-USDT","action":"update","ts":"1776816006870","asks":[["76367.1","0.87674078","15"],["76370","0.00076028","1"],["76377.3","0.13446852","2"],["76377.5","0.1796518","1"],["76382.4","0.26529656","4"],["76383.7","0.00654539","1"],["76384.9","0","0"],["76471.4","0","0"]],"bids":[["76357.3","0","0"],["76356.7","0","0"],["76356.5","0.00262851","2"],["76355.3","0.00654468","1"],["76350","0.00001155","1"],["76347.5","0.00659168","2"],["76187.7","0.47454308","2"]]}
{"instId":"BTC-USDT","action":"update","ts":"1776816006880","asks":[["76367.1","0.89957078","16"]],"bids":[]}
{"instId":"BTC-USDT","action":"update","ts":"1776816006900","asks":[],"bids":[["76347.6","0.00655575","2"],["76347.5","0.00004629","1"]]}
{"instId":"BTC-USDT","action":"update","ts":"1776816006910","asks":[["76377.2","0.00654499","1"],["76377.3","0.12792384","1"],["76381.6","0","0"],["76382","0.32727247","1"],["76382.4","0.15917794","2"],["76383.7","0","0"],["76384","0.00654544","1"],["76471.3","0","0"]],"bids":[["76362.5","0.16","1"],["76357.3","0.00654499","1"],["76355.3","0","0"],["76350","0.32728402","2"],["76349.6","0.00654544","1"],["76349.2","0","0"],["76347.6","0.00001033","1"],["76336.4","0.21095284","3"],["76187.7","0","0"]]}
{"instId":"BTC-USDT","action":"update","ts":"1776816006920","asks":[["76377.4","0","0"],["76384","0","0"],["76384.9","0.00654551","1"],["76397.7","0.05305931","1"]],"bids":[["76364.8","0.2365817","8"]]}
{"instId":"BTC-USDT","action":"update","ts":"1776816006940","asks":[["76376.3","0.00027436","5"],["76397.7","0.10611862","2"]],"bids":[["76362.5","0","0"],["76351.7","0.05087713","1"]]}
{"instId":"BTC-USDT","action":"update","ts":"1776816006950","asks":[],"bids":[["76364.8","0.169766","7"]]}
{"instId":"BTC-USDT","action":"update","ts":"1776816006960","asks":[["76397.7","0.05305931","1"]],"bids":[["76351.7","0","0"],["76187.7","0.47454308","2"]]}
{"instId":"BTC-USDT","action":"update","ts":"1776816006970","asks":[["76382.4","0.21223725","3"]],"bids":[]}
{"instId":"BTC-USDT","action":"update","ts":"1776816007010","asks":[["76367.1","0.8990863","16"]],"bids":[["76357.3","0","0"],["76356.6","0.00654478","1"]]}
{"instId":"BTC-USDT","action":"update","ts":"1776816007020","asks":[["76382.4","0.05305931","1"]],"bids":[["76336.4","0.26182997","4"]]}
{"instId":"BTC-USDT","action":"update","ts":"1776816007040","asks":[["76382.4","0.21223725","3"]],"bids":[["76351.2","0.08094234","3"]]}
{"instId":"BTC-USDT","action":"update","ts":"1776816007050","asks":[["76410.8","0.05237861","1"],["76471.2","0","0"]],"bids":[["76335.4","0.05237861","1"],["76187.7","0","0"]]}
{"instId":"BTC-USDT","action":"update","ts":"1776816007090","asks":[["76407.7","0.14404118","1"],["76471.1","0","0"]],"bids":[["76328","0.14406467","3"]]}
{"instId":"BTC-USDT","action":"update","ts":"1776816007100","asks":[["76367.1","0.8988768","16"]],"bids":[["76329.8","0.24687173","2"]]}
{"instId":"BTC-USDT","action":"update","ts":"1776816007110","asks":[["76367.1","0.89858873","16"]],"bids":[]}
{"instId":"BTC-USDT","action":"update","ts":"1776816007120","asks":[["76377.6","0.01461293","4"]],"bids":[["76328.6","0.12255241","2"],["76320.9","0.00131025","1"],["76187.9","0","0"]]}
{"instId":"BTC-USDT","action":"update","ts":"1776816007130","asks":[["76382.4","0.15917794","2"],["76416.6","0.13180861","2"],["76424.3","0","0"],["76471.1","0.47253258","5"]],"bids":[["76339.3","0.00040006","1"],["76336.4","0.21095284","3"],["76308.6","0.08378297","1"],["76277.6","0.00001316","1"]]}
{"instId":"BTC-USDT","action":"update","ts":"1776816007140","asks":[["76367.7","0","0"],["76379.4","0.05889073","1"],["76382.4","0.21223725","3"]],"bids":[["76365.3","0","0"],["76352.8","0.05889073","1"],["76351.7","0.05087713","1"],["76336.6","0.14404118","1"],["76328","0.00002349","2"],["76188.7","0","0"],["76188.3","0","0"]]}
{"instId":"BTC-USDT","action":"update","ts":"1776816007150","asks":[["76382","0","0"],["76383.7","0.32727701","1"]],"bids":[["76351.5","0.32729017","2"],["76350","0.00001155","1"],["76346.1","0.11992013","1"],["76341.9","0.00023748","5"],["76188.9","0","0"]]}
{"instId":"BTC-USDT","action":"update","ts":"1776816007170","asks":[["76382.4","0.15917794","2"],["76429.6","0.00001048","1"]],"bids":[["76351.7","0","0"],["76188.9","0.00002109","2"]]}
{"instId":"BTC-USDT","action":"update","ts":"1776816007180","asks":[["76382.4","0.21223725","3"],["76429.5","0.04964509","1"]],"bids":[["76336.4","0.26182997","4"]]}
{"instId":"BTC-USDT","action":"update","ts":"1776816007190","asks":[],"bids":[["76349.9","0.471546","2"],["76319.3","0.00072946","2"]]}
{"instId":"BTC-USDT","action":"update","ts":"1776816007200","asks":[["76424.2","0.10124337","3"]],"bids":[]}
{"instId":"BTC-USDT","action":"update","ts":"1776816007210","asks":[["76377.6","0.01359765","2"]],"bids":[]}
{"instId":"BTC-USDT","action":"update","ts":"1776816007220","asks":[["76417.6","0.00130859","1"],["76425.4","1.00658248","3"],["76471.1","0","0"]],"bids":[]}
{"instId":"BTC-USDT","action":"update","ts":"1776816007230","asks":[["76382.4","0.15917794","2"]],"bids":[["76330.2","0","0"],["76188.7","0.0108121","8"]]}
{"instId":"BTC-USDT","action":"update","ts":"1776816007250","asks":[["76367.1","0.87575873","15"]],"bids":[]}
{"instId":"BTC-USDT","action":"update","ts":"1776816007260","asks":[["76397.7","0.10611862","2"]],"bids":[]}
{"instId":"BTC-USDT","action":"update","ts":"1776816007280","asks":[["76397.7","0.05305931","1"]],"bids":[]}
{"instId":"BTC-USDT","action":"update","ts":"1776816007300","asks":[],"bids":[["76287.7","0.00004611","2"]]}
{"instId":"BTC-USDT","action":"update","ts":"1776816007310","asks":[["76382.4","0","0"],["76471.1","0.47253258","5"]],"bids":[["76336.4","0.21095284","3"]]}
{"instId":"BTC-USDT","action":"update","ts":"1776816007320","asks":[["76382.4","0.15917794","2"],["76397.7","0.10611862","2"],["76471.1","0","0"]],"bids":[["76351.7","0.05087713","1"],["76351.2","0.06551567","2"],["76188.7","0","0"]]}
{"instId":"BTC-USDT","action":"update","ts":"1776816007330","asks":[["76452.3","0.00014279","2"],["76455.6","0.0001534","4"]],"bids":[["76351.7","0","0"],["76330.2","0.00002865","1"]]}
{"instId":"BTC-USDT","action":"update","ts":"1776816007340","asks":[["76377.6","0.01309","1"]],"bids":[["76336.4","0.26182997","4"]]}
{"instId":"BTC-USDT","action":"update","ts":"1776816007350","asks":[["76367.1","0.87651166","16"],["76370","0","0"],["76471.1","0.47253258","5"]],"bids":[["76314.6","0.10563311","2"]]}
{"instId":"BTC-USDT","action":"update","ts":"1776816007380","asks":[["76377.2","0.12418382","2"]],"bids":[]}
{"instId":"BTC-USDT","action":"update","ts":"1776816007450","asks":[["76432.7","0","0"],["76471.2","0.00002013","1"]],"bids":[]}
{"instId":"BTC-USDT","action":"update","ts":"1776816007500","asks":[["76367.1","0.87638072","16"]],"bids":[]}
{"instId":"BTC-USDT","action":"update","ts":"1776816007550","asks":[["76367.1","0.87637072","16"]],"bids":[]}
{"instId":"BTC-USDT","action":"update","ts":"1776816007570","asks":[["76471.2","0.00067513","2"]],"bids":[]}
{"instId":"BTC-USDT","action":"update","ts":"1776816007580","asks":[["76382.4","0","0"],["76471.3","0.01047498","5"]],"bids":[["76336.4","0.21095284","3"]]}
{"instId":"BTC-USDT","action":"update","ts":"1776816007590","asks":[["76367.1","0.87561779","15"],["76370.5","0.00074557","1"],["76471.3","0","0"]],"bids":[["76348.8","0.01571222","2"],["76336.4","0.26182997","4"]]}
{"instId":"BTC-USDT","action":"update","ts":"1776816007600","asks":[["76367.1","0.87636336","16"],["76370.5","0","0"],["76382.4","0.15917794","2"]],"bids":[]}
{"instId":"BTC-USDT","action":"update","ts":"1776816007620","asks":[["76367.1","0.78493336","15"],["76397.7","0.05305931","1"]],"bids":[]}
{"instId":"BTC-USDT","action":"update","ts":"1776816007630","asks":[],"bids":[["76367","0.53642115","9"],["76336.4","0.21095284","3"]]}
{"instId":"BTC-USDT","action":"update","ts":"1776816007640","asks":[["76397.7","0.10611862","2"]],"bids":[]}
{"instId":"BTC-USDT","action":"update","ts":"1776816007650","asks":[["76393.5","0","0"],["76397.7","0.05305931","1"],["76471.3","0.01047498","5"]],"bids":[]}
{"instId":"BTC-USDT","action":"update","ts":"1776816007660","asks":[["76382.4","0.21223725","3"]],"bids":[]}
{"instId":"BTC-USDT","action":"update","ts":"1776816007670","asks":[],"bids":[["76336.4","0.26182997","4"]]}
{"instId":"BTC-USDT","action":"update","ts":"1776816007680","asks":[],"bids":[["76291","0.02006","1"],["76188.9","0","0"]]}
{"instId":"BTC-USDT","action":"update","ts":"1776816007710","asks":[["76367.1","0.78494336","16"],["76377.2","0.11763883","1"],["76378.5","0.00654493","1"],["76471.3","0","0"]],"bids":[["76357.3","0.00654493","1"],["76356.6","0","0"]]}
{"instId":"BTC-USDT","action":"update","ts":"1776816007730","asks":[["76367.1","0.78419779","15"],["76370.5","0.00074557","1"],["76377.5","0.18619672","2"],["76378.5","0","0"],["76382.4","0.15917794","2"]],"bids":[["76336.4","0.21095284","3"]]}
{"instId":"BTC-USDT","action":"update","ts":"1776816007740","asks":[["76377.5","0.1796518","1"],["76378.4","0.00654491","1"],["76384.9","0","0"],["76385.7","0.00654534","1"],["76397.7","0.10611862","2"],["76471.2","0","0"]],"bids":[["76351.7","0.05087713","1"],["76350","0.00655689","2"],["76349.6","0","0"]]}
{"instId":"BTC-USDT","action":"update","ts":"1776816007760","asks":[["76367.1","0.643162","12"],["76382.4","0.05305931","1"],["76383.7","0","0"],["76384.9","0.32726668","1"]],"bids":[["76367","0.54262115","10"],["76352.9","0.32726668","1"],["76351.5","0.00001316","1"],["76351","0","0"]]}
{"instId":"BTC-USDT","action":"update","ts":"1776816007770","asks":[["76367.1","0.56569759","11"],["76380.5","0.20820194","1"],["76382.4","0","0"],["76385.7","0","0"],["76386.8","0.0065453","1"],["76395.2","0.01577828","1"],["76397.7","0.21223725","3"]],"bids":[["76367","0.70262115","11"],["76353.5","0.01344209","1"],["76353","1.81248734","3"],["76351.4","0","0"],["76351.3","0.00659159","2"],["76350","0.00001155","1"],["76348.8","0.00001086","1"],["76211.2","0","0"]]}
{"instId":"BTC-USDT","action":"update","ts":"1776816007780","asks":[["76367.1","0.56644316","12"],["76370.5","0","0"],["76378.4","0","0"],["76379.3","0.00694495","2"],["76471.2","0.00067513","2"],["76471.3","0.01047498","5"]],"bids":[["76353","1.4771824","2"]]}
{"instId":"BTC-USDT","action":"update","ts":"1776816007790","asks":[],"bids":[["76359.7","0.00654502","1"],["76357.3","0","0"],["76353.1","0.76786177","1"],["76314.6","0.00001316","1"],["76190","0","0"]]}
{"instId":"BTC-USDT","action":"update","ts":"1776816007800","asks":[["76367.1","0.47052972","11"],["76382.4","0.05305931","1"],["76471.3","0","0"]],"bids":[["76359.7","0","0"],["76357.3","0.006545","1"]]}
{"instId":"BTC-USDT","action":"update","ts":"1776816007810","asks":[["76367.1","0.08382371","5"],["76369.8","0.00074557","1"],["76370.6","0","0"],["76370.7","0","0"],["76382.4","0","0"],["76384.9","0","0"],["76387.5","0.32726415","1"],["76387.6","0.19939442","1"],["76395.2","0","0"],["76471.3","0.01047498","5"],["76471.4","0.00505207","2"],["76471.5","0.00004115","1"]],"bids":[["76362.5","0.12258502","1"],["76359.7","0.006545","1"],["76359.3","0.1305","1"],["76357.3","0","0"],["76355.3","0.32726415","1"],["76352.9","0","0"],["76336.4","0.05305931","1"],["76190.9","0","0"],["76190.4","0","0"]]}
{"instId":"BTC-USDT","action":"update","ts":"1776816007820","asks":[["76367.1","0.08120579","4"],["76369.8","0","0"],["76377.1","0.00074557","1"],["76377.3","0","0"],["76379.3","0.00040006","1"],["76382","0.00654495","1"],["76385.3","0.20316663","1"],["76386.8","0","0"],["76388","0","0"],["76391.5","0.00654522","1"],["76429.7","0.11726545","2"],["76471.7","0.00029028","5"]],"bids":[["76364.8","0.22541332","8"],["76362.6","0.00654495","1"],["76359.7","0","0"],["76358.7","0.01614584","1"],["76355.2","0.1248978","2"],["76351.7","0.20877066","3"],["76351.3","0.00004629","1"],["76350","0.08379452","2"],["76266.2","0","0"],["76261.2","0","0"],["76190.9","0.00015413","4"]]}
{"instId":"BTC-USDT","action":"update","ts":"1776816007830","asks":[["76367.1","0.11104245","5"],["76379.4","0","0"],["76381.6","0.00654486","1"],["76382","0","0"],["76385.4","0.53116863","3"],["76387.5","0","0"],["76388.6","0.3272606","1"],["76391.5","0.11690132","2"],["76397","0","0"],["76471.8","0.00007776","1"],["76471.9","0.0003932","1"]],"bids":[["76362.6","0.11725524","1"],["76360","0.00655519","2"],["76359.6","0","0"],["76355.2","0.11835258","1"],["76354.4","0.00654525","1"],["76327.7","0","0"],["76320.3","0.11463797","1"],["76317.6","0.01372103","1"]]}
{"instId":"BTC-USDT","action":"update","ts":"1776816007840","asks":[],"bids":[["76362.4","0.10654486","2"],["76360","0.00001033","1"],["76357.2","0.09216026","8"]]}
{"instId":"BTC-USDT","action":"update","ts":"1776816007850","asks":[],"bids":[["76357.2","0.03124792","7"]]}
{"instId":"BTC-USDT","action":"update","ts":"1776816007860","asks":[["76397.7","0.26529656","4"]],"bids":[["76265.9","0","0"],["76190.4","0.00001319","1"]]}
{"instId":"BTC-USDT","action":"update","ts":"1776816007870","asks":[["76381.6","0","0"],["76382.6","0.00655636","2"],["76472","0.000059","1"]],"bids":[["76362.7","0.00654482","1"],["76362.4","0.1","1"],["76190.4","0","0"]]}
{"instId":"BTC-USDT","action":"update","ts":"1776816007890","asks":[],"bids":[["76358.9","0.05889073","1"],["76352.8","0","0"]]}
{"instId":"BTC-USDT","action":"update","ts":"1776816007900","asks":[["76407.7","0","0"],["76412.5","0.455407","2"],["76472.4","0.00002715","1"]],"bids":[["76362.7","0.16654482","2"],["76359.9","0.06006694","3"]]}
{"instId":"BTC-USDT","action":"update","ts":"1776816007910","asks":[["76367.1","0.08004245","3"],["76429.9","0","0"],["76472.5","0.00008103","2"]],"bids":[["76364.8","0.30301324","7"]]}
{"instId":"BTC-USDT","action":"update","ts":"1776816007950","asks":[["76432.8","0.01908645","2"]],"bids":[]}
{"instId":"BTC-USDT","action":"update","ts":"1776816007960","asks":[],"bids":[["76352","0.01535495","1"],["76190.9","0","0"]]}
{"instId":"BTC-USDT","action":"update","ts":"1776816007970","asks":[],"bids":[["76357.2","0.16653846","8"]]}
{"instId":"BTC-USDT","action":"update","ts":"1776816007990","asks":[["76367.1","0.08124245","4"],["76382","0.00654456","1"],["76382.6","0.00001154","1"],["76387.5","0.33380774","2"],["76388.6","0","0"],["76391.5","0.1103561","1"],["76399.5","0","0"],["76432.8","0.00002941","1"]],"bids":[["76362.7","0.16","1"],["76362.6","0.1237998","2"],["76355.4","0.32726249","1"],["76355.3","0","0"],["76354.4","0","0"],["76352.1","0.00654525","1"],["76336.4","0","0"],["76190.9","0.00015413","4"]]}
{"instId":"BTC-USDT","action":"update","ts":"1776816008000","asks":[["76385.3","0.29446674","2"],["76387.5","0","0"],["76387.6","0","0"],["76388.6","0.32726248","1"],["76391.4","0.00654525","1"]],"bids":[["76355.4","0","0"],["76355.3","0.32726248","1"],["76354.5","0.00654525","1"],["76352.1","0","0"],["76351.7","0.26182997","4"]]}
{"instId":"BTC-USDT","action":"update","ts":"1776816008010","asks":[["76388.5","1.24606206","2"],["76388.6","0.32726247","1"],["76391.4","0.12646538","2"],["76472.5","0","0"]],"bids":[["76355.3","0.32726247","1"],["76354.5","0","0"],["76354.4","0.00654525","1"],["76351.7","0.20877066","3"]]}
{"instId":"BTC-USDT","action":"update","ts":"1776816008020","asks":[["76367.1","0.11104245","5"],["76388.4","0.64815158","2"],["76388.5","1.00566932","1"]],"bids":[["76362.6","0.12379976","2"],["76354.6","0.00654525","1"],["76354.4","0","0"],["76336.4","0.05305931","1"],["76190.9","0","0"]]}
{"instId":"BTC-USDT","action":"update","ts":"1776816008030","asks":[["76367.1","0.08124245","4"],["76388.3","0.32726246","1"],["76388.6","0","0"],["76391.3","0.00654525","1"],["76391.4","0.11992013","1"],["76398.5","0.01551047","2"],["76472.4","0","0"]],"bids":[["76362.6","0.11725524","1"],["76362.5","0.12912954","2"],["76354.6","0","0"],["76354.4","0.00654525","1"],["76351.2","0.0810789","3"],["76336.4","0","0"],["76304.5","0.00001316","1"],["76304.4","0.00323274","1"]]}
{"instId":"BTC-USDT","action":"update","ts":"1776816008040","asks":[["76382","0.00654459","1"],["76388.2","0.11725524","1"],["76388.4","0.4787065","2"],["76391.6","0.20550612","1"],["76429.7","0.00001021","1"],["76472","0","0"]],"bids":[["76362.5","0.12912961","2"],["76354.5","0.00654524","1"],["76354.4","0","0"]]}
{"instId":"BTC-USDT","action":"update","ts":"1776816008050","asks":[["76367.1","0.11104245","5"],["76429.9","0.00003958","1"],["76471.9","0","0"]],"bids":[["76351.7","0.05087713","1"]]}
{"instId":"BTC-USDT","action":"update","ts":"1776816008060","asks":[["76367.1","0.08124245","4"],["76381.6","0.00654456","1"],["76382","0","0"]],"bids":[["76362.5","0.12258502","1"],["76362.4","0.10654456","2"],["76336.4","0.15789353","2"],["76191","0","0"]]}
{"instId":"BTC-USDT","action":"update","ts":"1776816008070","asks":[["76381.6","0","0"],["76382","0.00654451","1"]],"bids":[["76362.5","0.12912953","2"],["76362.4","0.1","1"]]}
{"instId":"BTC-USDT","action":"update","ts":"1776816008080","asks":[["76367.1","0.08029833","4"]],"bids":[["76336.4","0.15917794","2"]]}
{"instId":"BTC-USDT","action":"update","ts":"1776816008090","asks":[["76381.6","0.00654451","1"],["76382","0","0"]],"bids":[["76351.7","0.10265203","2"]]}
{"instId":"BTC-USDT","action":"update","ts":"1776816008100","asks":[["76367.1","0.08003644","4"]],"bids":[["76337.6","0.25811057","2"],["76336.4","0","0"],["76191","0.00014147","1"]]}
{"instId":"BTC-USDT","action":"update","ts":"1776816008110","asks":[["76367.1","0.08000724","4"],["76381.6","0","0"],["76382","0.00654453","1"]],"bids":[["76362.6","0.12379977","2"],["76362.5","0.12258502","1"]]}
{"instId":"BTC-USDT","action":"update","ts":"1776816008120","asks":[],"bids":[["76351.7","0.26182997","4"]]}
{"instId":"BTC-USDT","action":"update","ts":"1776816008130","asks":[["76367.1","0.07997104","4"]],"bids":[]}
{"instId":"BTC-USDT","action":"update","ts":"1776816008150","asks":[],"bids":[["76265.2","0.015715","1"],["76216.1","0","0"]]}
{"instId":"BTC-USDT","action":"update","ts":"1776816008190","asks":[["76367.1","0.10977104","5"]],"bids":[]}
{"instId":"BTC-USDT","action":"update","ts":"1776816008200","asks":[["76381.6","0.00654449","1"],["76382","0","0"]],"bids":[["76362.6","0.11725524","1"],["76360","0.00655482","2"]]}
{"instId":"BTC-USDT","action":"update","ts":"1776816008220","asks":[],"bids":[["76367","0.54262115","10"]]}
{"instId":"BTC-USDT","action":"update","ts":"1776816008280","asks":[],"bids":[["76351.7","0.20877066","3"]]}
{"instId":"BTC-USDT","action":"update","ts":"1776816008290","asks":[],"bids":[["76336.4","0.05305931","1"],["76191","0","0"]]}
{"instId":"BTC-USDT","action":"update","ts":"1776816008330","asks":[["76435.4","0.00001316","1"],["76459","0.00001316","1"],["76471.7","0","0"],["76471.8","0","0"]],"bids":[]}
{"instId":"BTC-USDT","action":"update","ts":"1776816008360","asks":[["76377.1","0.00124892","2"],["76386.8","0.32726312","1"],["76388.3","0","0"]],"bids":[]}
{"instId":"BTC-USDT","action":"update","ts":"1776816008370","asks":[["76377.1","0.00175227","3"],["76388.6","0.00654526","1"],["76391.3","0","0"]],"bids":[["76354.5","0","0"],["76353.6","0.00654526","1"]]}
{"instId":"BTC-USDT","action":"update","ts":"1776816008380","asks":[["76367.1","0.07997104","4"],["76386.8","0","0"],["76388.1","0.32726305","1"]],"bids":[]}
{"instId":"BTC-USDT","action":"update","ts":"1776816008390","asks":[["76386.8","0.32726301","1"],["76388.1","0","0"],["76388.6","0","0"],["76391.3","0.00654526","1"],["76391.4","0","0"],["76471.7","0.00029028","5"]],"bids":[["76354.3","0.00959526","2"],["76353.6","0","0"],["76191","0.00014147","1"]]}
{"instId":"BTC-USDT","action":"update","ts":"1776816008410","asks":[["76367.1","0.10977104","5"]],"bids":[["76214.3","0.00010934","1"],["76191","0","0"]]}
{"instId":"BTC-USDT","action":"update","ts":"1776816008420","asks":[["76388.6","0.00654526","1"],["76391.3","0","0"]],"bids":[["76354.3","0.00305","1"],["76353.6","0.00654526","1"],["76191.2","0","0"]]}
{"instId":"BTC-USDT","action":"update","ts":"1776816008430","asks":[["76397.2","0.15456372","1"],["76471.7","0","0"]],"bids":[]}
{"instId":"BTC-USDT","action":"update","ts":"1776816008460","asks":[["76367.1","0.10976104","5"]],"bids":[["76351.7","0.10265203","2"]]}
{"instId":"BTC-USDT","action":"update","ts":"1776816008480","asks":[],"bids":[["76336.4","0.15917794","2"],["76211.1","6.55609","1"]]}
{"instId":"BTC-USDT","action":"update","ts":"1776816008490","asks":[["76398.5","0.00001316","1"],["76434","0.0193111","2"]],"bids":[]}
{"instId":"BTC-USDT","action":"update","ts":"1776816008510","asks":[["76377.1","0.00225563","4"]],"bids":[]}
{"instId":"BTC-USDT","action":"update","ts":"1776816008530","asks":[],"bids":[["76260.3","0.60055564","2"]]}
{"instId":"BTC-USDT","action":"update","ts":"1776816008570","asks":[["76367.1","0.10953844","5"]],"bids":[["76367","0.70262115","12"]]}
{"instId":"BTC-USDT","action":"update","ts":"1776816008580","asks":[["76388.6","0","0"],["76391.4","0.00654526","1"]],"bids":[]}
{"instId":"BTC-USDT","action":"update","ts":"1776816008600","asks":[["76367.1","0.10927656","5"]],"bids":[]}
{"instId":"BTC-USDT","action":"update","ts":"1776816008610","asks":[["76367.1","0.10888374","5"],["76386.8","0.32726283","1"]],"bids":[["76336.4","0.05305931","1"]]}
{"instId":"BTC-USDT","action":"update","ts":"1776816008620","asks":[["76386.8","0","0"],["76388.1","0.32726233","1"]],"bids":[]}
{"instId":"BTC-USDT","action":"update","ts":"1776816008630","asks":[["76386.8","0.32726283","1"],["76388.1","0","0"],["76397.4","1.4928205","3"]],"bids":[["76351.7","0.20877066","3"],["76336.4","0","0"],["76191.2","0.0000842","4"]]}
{"instId":"BTC-USDT","action":"update","ts":"1776816008640","asks":[["76386.8","0","0"],["76388.1","0.32726283","1"]],"bids":[["76354.4","0.00654526","1"],["76353.6","0","0"],["76336.4","0.05305931","1"],["76191.2","0","0"]]}
{"instId":"BTC-USDT","action":"update","ts":"1776816008650","asks":[],"bids":[["76367","0.54262115","10"]]}
{"instId":"BTC-USDT","action":"update","ts":"1776816008690","asks":[["76367.1","0.10883137","5"],["76386.8","0.32726306","1"],["76388.1","0","0"]],"bids":[]}
{"instId":"BTC-USDT","action":"update","ts":"1776816008700","asks":[["76367.1","0.10411731","5"],["76386.8","0","0"],["76388.1","0.32726346","1"]],"bids":[]}
{"instId":"BTC-USDT","action":"update","ts":"1776816008730","asks":[],"bids":[["76362.7","0","0"],["76336.4","0","0"],["76191.2","0.0000842","4"],["76191","0.00014147","1"]]}
{"instId":"BTC-USDT","action":"update","ts":"1776816008740","asks":[["76388.6","0.00654526","1"],["76391.4","0","0"]],"bids":[["76354.4","0","0"],["76353.6","0.00654526","1"],["76351.7","0.26182997","4"]]}
{"instId":"BTC-USDT","action":"update","ts":"1776816008750","asks":[["76377.1","0.00275898","5"]],"bids":[]}
{"instId":"BTC-USDT","action":"update","ts":"1776816008800","asks":[["76367.1","0.10385542","5"]],"bids":[]}
{"instId":"BTC-USDT","action":"update","ts":"1776816008830","asks":[["76388.6","0","0"],["76391.4","0.00654526","1"]],"bids":[["76354.3","0.00959526","2"],["76353.6","0","0"],["76190.9","0.00015413","4"]]}
{"instId":"BTC-USDT","action":"update","ts":"1776816008850","asks":[["76367.1","0.10379002","5"],["76388.6","0.00654528","1"],["76391.4","0","0"]],"bids":[["76354.3","0.00305","1"],["76353.6","0.00654528","1"],["76190.9","0","0"]]}
{"instId":"BTC-USDT","action":"update","ts":"1776816008880","asks":[],"bids":[["76362.7","0.16","1"],["76191","0","0"]]}
{"instId":"BTC-USDT","action":"update","ts":"1776816008900","asks":[["76367.1","0.09075402","4"]],"bids":[]}
{"instId":"BTC-USDT","action":"update","ts":"1776816008910","asks":[["76367.1","0.10560647","5"],["76397.4","1.4771113","2"],["76429.9","0","0"],["76471.7","0.00029028","5"]],"bids":[]}
{"instId":"BTC-USDT","action":"update","ts":"1776816008940","asks":[],"bids":[["76362.7","0","0"],["76191","0.00014147","1"]]}
{"instId":"BTC-USDT","action":"update","ts":"1776816009000","asks":[["76429.9","0.00003959","1"],["76471.7","0","0"]],"bids":[]}
{"instId":"BTC-USDT","action":"update","ts":"1776816009010","asks":[["76386.8","0.32726499","1"],["76388.1","0","0"]],"bids":[]}
{"instId":"BTC-USDT","action":"update","ts":"1776816009030","asks":[["76367.1","0.07460647","3"],["76377.5","0","0"],["76386.8","0","0"],["76388.1","0.32726298","1"],["76388.5","0","0"],["76388.6","0","0"],["76391.4","0.00654527","1"],["76392.9","0","0"],["76471.7","0.00029028","5"],["76471.8","0.00007776","1"],["76471.9","0.0003932","1"]],"bids":[["76355.4","0.08378297","1"],["76270.8","0","0"]]}
{"instId":"BTC-USDT","action":"update","ts":"1776816009040","asks":[["76386.8","0.32726299","1"],["76388","0.27539751","1"],["76388.1","0","0"],["76388.4","0.00001316","1"],["76391.3","0.00654524","1"],["76391.4","0","0"],["76391.6","0","0"],["76397.5","0.09945136","2"]],"bids":[["76354.3","0.00959524","2"],["76353.6","0","0"],["76190.9","0.00015413","4"]]}
{"instId":"BTC-USDT","action":"update","ts":"1776816009050","asks":[["76386.8","0.32726177","1"],["76388","0.1777095","1"]],"bids":[["76355.5","0.32726242","1"],["76355.3","0","0"],["76351.7","0.15571134","3"]]}
{"instId":"BTC-USDT","action":"update","ts":"1776816009060","asks":[["76386.8","0","0"],["76387.9","0.32726196","1"]],"bids":[]}
{"instId":"BTC-USDT","action":"update","ts":"1776816009070","asks":[["76367.1","0.07580647","4"],["76386.7","1.00566932","1"],["76387.8","0.2753972","1"],["76388","0","0"],["76471.9","0","0"]],"bids":[["76351.7","0.10265203","2"],["76336.4","0.10611863","1"],["76278.8","0.12","1"],["76191","0","0"],["76190.9","0","0"]]}
{"instId":"BTC-USDT","action":"update","ts":"1776816009080","asks":[["76385.3","0.48334488","1"]],"bids":[["76336.4","0.15917794","2"]]}
{"instId":"BTC-USDT","action":"update","ts":"1776816009090","asks":[["76367.1","0.10560647","5"],["76377.5","0.14498323","1"],["76386.8","0.32726196","1"],["76387.9","0","0"],["76471.8","0","0"]],"bids":[]}
{"instId":"BTC-USDT","action":"update","ts":"1776816009100","asks":[["76367.1","0.10543624","5"],["76386.8","0","0"],["76387.7","0.32726201","1"],["76387.8","0.1777095","1"],["76391.3","0","0"],["76391.4","0.00654525","1"]],"bids":[["76354.3","0.00305","1"],["76353.6","0.00654525","1"],["76191.2","0","0"]]}
{"instId":"BTC-USDT","action":"update","ts":"1776816009110","asks":[["76387.6","0.27539722","1"],["76387.8","0","0"]],"bids":[["76236.9","0.0982906","1"]]}
{"instId":"BTC-USDT","action":"update","ts":"1776816009120","asks":[["76388.6","0.00654526","1"],["76391.4","0","0"]],"bids":[]}
{"instId":"BTC-USDT","action":"update","ts":"1776816009130","asks":[["76386.6","0.32726246","1"],["76387.7","0","0"],["76392.9","0.14610037","1"],["76471.7","0","0"]],"bids":[]}
{"instId":"BTC-USDT","action":"update","ts":"1776816009140","asks":[["76387.6","0.17770951","1"],["76392.8","0.08378297","1"],["76471.5","0","0"]],"bids":[]}
{"instId":"BTC-USDT","action":"update","ts":"1776816009170","asks":[],"bids":[["76238","0","0"],["76191.2","0.0000842","4"]]}
{"instId":"BTC-USDT","action":"update","ts":"1776816009180","asks":[["76397.7","0.21223725","3"]],"bids":[["76351.7","0.05087713","1"]]}
{"instId":"BTC-USDT","action":"update","ts":"1776816009200","asks":[],"bids":[["76250.1","0","0"],["76191","0.00014147","1"]]}
{"instId":"BTC-USDT","action":"update","ts":"1776816009210","asks":[["76388.6","0","0"],["76391.4","0.00654529","1"],["76397.7","0.26529656","4"]],"bids":[["76351.7","0.10265203","2"]]}
{"instId":"BTC-USDT","action":"update","ts":"1776816009220","asks":[["76388.6","0.00654532","1"],["76391.4","0","0"],["76397.7","0.21223725","3"]],"bids":[["76351.7","0.05087713","1"]]}
{"instId":"BTC-USDT","action":"update","ts":"1776816009250","asks":[],"bids":[["76330.2","0","0"],["76190.9","0.00015413","4"]]}
{"instId":"BTC-USDT","action":"update","ts":"1776816009280","asks":[["76382.4","0.05305931","1"],["76471.4","0","0"]],"bids":[["76336.4","0.21095284","3"]]}
{"instId":"BTC-USDT","action":"update","ts":"1776816009320","asks":[["76367.1","0.12483624","6"]],"bids":[]}
{"instId":"BTC-USDT","action":"update","ts":"1776816009340","asks":[["76367.1","0.10543624","5"],["76371.6","0.00001316","1"],["76465.7","0.00001316","1"],["76471.2","0","0"],["76471.3","0","0"]],"bids":[["76330.2","0.00002865","1"],["76190.9","0","0"]]}
{"instId":"BTC-USDT","action":"update","ts":"1776816009350","asks":[],"bids":[["76362.7","0.16","1"],["76191","0","0"]]}
{"instId":"BTC-USDT","action":"update","ts":"1776816009360","asks":[["76367.1","0.12483624","6"]],"bids":[["76362.7","0","0"],["76351.7","0","0"],["76191","0.00014147","1"],["76190.9","0.00015413","4"]]}
{"instId":"BTC-USDT","action":"update","ts":"1776816009370","asks":[["76367.1","0.12477077","6"]],"bids":[]}
{"instId":"BTC-USDT","action":"update","ts":"1776816009380","asks":[],"bids":[["76351.7","0.05087713","1"],["76190.9","0","0"]]}
{"instId":"BTC-USDT","action":"update","ts":"1776816009400","asks":[["76367.1","0.12463984","6"]],"bids":[]}
{"instId":"BTC-USDT","action":"update","ts":"1776816009410","asks":[["76367.1","0.10513509","5"]],"bids":[]}
{"instId":"BTC-USDT","action":"update","ts":"1776816009420","asks":[["76382.4","0","0"],["76471.2","0.00067513","2"]],"bids":[["76336.4","0.15917794","2"]]}
{"instId":"BTC-USDT","action":"update","ts":"1776816009430","asks":[["76397.7","0.26529656","4"]],"bids":[["76351.7","0.10265203","2"]]}
{"instId":"BTC-USDT","action":"update","ts":"1776816009500","asks":[["76397.7","0.21223725","3"]],"bids":[["76351.7","0.05087713","1"],["76255","0.00514367","1"],["76191","0","0"]]}
{"instId":"BTC-USDT","action":"update","ts":"1776816009510","asks":[["76382.4","0.05305931","1"],["76471.2","0","0"]],"bids":[["76336.4","0.21095284","3"]]}
{"instId":"BTC-USDT","action":"update","ts":"1776816009550","asks":[["76380.4","0.00654452","1"],["76381.6","0","0"]],"bids":[]}
{"instId":"BTC-USDT","action":"update","ts":"1776816009580","asks":[["76367.1","0.78752101","13"],["76375.5","0.47151308","1"],["76376.3","0.12552427","6"],["76380.4","0","0"],["76381.6","0.00654454","1"],["76382.4","0","0"],["76384.9","0.32726474","1"],["76386.6","0","0"],["76397.7","0","0"],["76425.3","0","0"],["76471.2","0.00067513","2"],["76471.3","0.01047498","5"]],"bids":[["76367","0.53642115","9"],["76366.9","0","0"],["76364.7","0.10006462","2"],["76362.5","0","0"],["76358.9","0","0"],["76358.7","0","0"],["76355.5","0","0"],["76355.4","0","0"],["76353","0","0"],["76351.7","0","0"],["76350","0.00001155","1"],["76349.9","0.00003292","1"],["76346.2","0.47152764","2"],["76346","0","0"],["76342.1","1.00566932","1"],["76342","0.0000168","1"],["76337.8","0.47151308","1"],["76337.2","0","0"],["76336.4","0.15917794","2"],["76334.2","1.4774629","11"],["76334","0","0"],["76332.2","0.00004629","1"],["76211.2","1.00566932","1"],["76191","0.00014147","1"],["76190.9","0.00015413","4"],["76190.4","0.00001319","1"],["76190","0.00001428","1"],["76188.9","0.00002109","2"],["76188.7","0.0108121","8"],["76188.3","0.00001061","1"],["76187.9","0.00001002","1"]]}
{"instId":"BTC-USDT","action":"update","ts":"1776816009590","asks":[["76367.1","0.81132453","15"],["76374.2","0.00654454","1"],["76375.4","0.14074665","1"],["76377.1","0.00201341","4"],["76379.1","0.05889073","1"],["76380.4","1.41671698","3"],["76381.5","0.00654577","1"],["76381.6","0","0"],["76382.4","0.26529656","4"],["76384.9","0.08378297","1"],["76385.4","0.4722779","2"],["76388.6","0","0"],["76470.8","0","0"],["76471.1","0","0"],["76471.2","0","0"],["76471.3","0","0"]],"bids":[["76367","0.48137323","6"],["76366.5","0.00001086","1"],["76364.8","0.10023743","6"],["76360","0.00001033","1"],["76359.9","0.0413601","2"],["76359.3","0","0"],["76357.2","0.03124792","7"],["76353.7","0.00654454","1"],["76353.6","0","0"],["76353.5","0","0"],["76353.1","0","0"],["76351.2","0.06551567","2"],["76349.1","0.05980089","2"],["76346","0.00654577","1"],["76345.9","0.00001035","1"],["76341.7","0.00001085","1"],["76337.6","0.18190496","1"],["76336.4","0.26182997","4"],["76334.1","0.10745499","1"],["76316.8","0.11725524","1"],["76264.8","0.08378297","1"],["76254.8","0.08378297","1"],["76244.8","0.08378297","1"],["76188.3","0","0"],["76187.9","0","0"]]}
{"instId":"BTC-USDT","action":"update","ts":"1776816009600","asks":[["76367.1","0.81394252","16"],["76380.3","0.69639869","1"],["76380.5","0","0"]],"bids":[["76359.9","0.00001501","1"],["76357.2","0.06483743","8"],["76354.4","0.00654512","1"],["76353.7","0","0"],["76351.2","0.00001035","1"]]}
{"instId":"BTC-USDT","action":"update","ts":"1776816009610","asks":[],"bids":[["76364.9","0.02992087","1"],["76354.4","0","0"],["76352.1","0.00654499","1"],["76349.9","0.471546","2"],["76348.6","0.01241483","1"],["76343","0.47151308","1"],["76190","0","0"],["76188.9","0","0"],["76188.7","0","0"]]}
{"instId":"BTC-USDT","action":"update","ts":"1776816009620","asks":[],"bids":[["76364.8","0.22489376","7"],["76354.4","0.00654495","1"],["76352.1","0","0"],["76350","1.00568087","2"],["76348.8","0.06551618","2"],["76211.2","0","0"],["76190","0.00001428","1"]]}
{"instId":"BTC-USDT","action":"update","ts":"1776816009630","asks":[],"bids":[["76364.9","0","0"],["76354.4","0","0"],["76352.1","0.00654495","1"],["76350.1","0.48350999","1"]]}
{"instId":"BTC-USDT","action":"update","ts":"1776816009640","asks":[],"bids":[["76347.5","0.32733793","2"],["76341.9","0.08402045","6"]]}
{"instId":"BTC-USDT","action":"update","ts":"1776816009650","asks":[],"bids":[["76354.3","0.00959515","2"],["76352.1","0","0"],["76349.5","0.05912817","6"],["76349.1","0.34900283","3"],["76188.9","0.00002109","2"]]}
{"instId":"BTC-USDT","action":"update","ts":"1776816009660","asks":[["76367.1","0.81354969","16"]],"bids":[["76334.3","0.53900048","1"],["76188.9","0","0"]]}
{"instId":"BTC-USDT","action":"update","ts":"1776816009690","asks":[["76397.5","0.08378297","1"]],"bids":[["76361","0.02642744","6"],["76347.5","0.3432245","3"]]}
{"instId":"BTC-USDT","action":"update","ts":"1776816009710","asks":[],"bids":[["76298.7","0","0"],["76295.6","0.00013107","1"],["76290.1","0","0"],["76287.1","0.00054217","1"]]}
{"instId":"BTC-USDT","action":"update","ts":"1776816009750","asks":[],"bids":[["76349.9","0.47151308","1"],["76319.3","0.00040006","1"],["76287.7","0.00001316","1"]]}
{"instId":"BTC-USDT","action":"update","ts":"1776816009760","asks":[["76380.4","1.33293401","2"]],"bids":[["76330.2","0","0"],["76304.4","0","0"],["76188.9","0.00002109","2"],["76188.7","0.0108121","8"]]}
{"instId":"BTC-USDT","action":"update","ts":"1776816009780","asks":[["76367.1","0.81348422","16"]],"bids":[["76367","0.39529727","5"]]}
{"instId":"BTC-USDT","action":"update","ts":"1776816009810","asks":[["76367.1","0.81269855","16"]],"bids":[["76304.4","0.00323289","1"],["76188.7","0","0"]]}
{"instId":"BTC-USDT","action":"update","ts":"1776816009820","asks":[["76379.1","0","0"],["76380.4","0.32726469","1"],["76470.8","0.0001444","7"]],"bids":[["76349.9","0.47154631","2"],["76319.3","0.00076582","2"]]}
{"instId":"BTC-USDT","action":"update","ts":"1776816009830","asks":[["76367.1","0.81256761","16"],["76374.2","0","0"],["76375.3","0.0065453","1"],["76380.3","0.37119719","1"],["76380.4","0","0"],["76381.5","0","0"],["76381.6","0.32728752","1"],["76382.3","0.00654568","1"]],"bids":[["76355.3","0.0065453","1"],["76354.3","0.00305","1"],["76350.9","0.01241447","1"],["76349.6","0.32728752","1"],["76348.6","0","0"],["76347.6","0.00655601","2"],["76347.5","0.01593286","2"],["76346","0","0"],["76188.9","0","0"]]}
{"instId":"BTC-USDT","action":"update","ts":"1776816009840","asks":[],"bids":[["76349.1","0.05980089","2"]]}
{"instId":"BTC-USDT","action":"update","ts":"1776816009870","asks":[],"bids":[["76362.7","0.16","1"],["76190","0","0"]]}
{"instId":"BTC-USDT","action":"update","ts":"1776816009880","asks":[["76396.4","0.01554596","1"],["76470.8","0","0"]],"bids":[["76367","0.41792727","6"],["76330.2","0.00002865","1"],["76190.4","0","0"]]}
{"instId":"BTC-USDT","action":"update","ts":"1776816009890","asks":[["76377.3","0.05889073","1"],["76470.6","0","0"]],"bids":[]}
{"instId":"BTC-USDT","action":"update","ts":"1776816009900","asks":[],"bids":[["76364.9","0.02992087","1"],["76190.9","0","0"]]}
{"instId":"BTC-USDT","action":"update","ts":"1776816009920","asks":[],"bids":[["76362.7","0","0"],["76190.9","0.00015413","4"]]}
{"instId":"BTC-USDT","action":"update","ts":"1776816009970","asks":[["76375.2","0.00656018","2"],["76375.3","0","0"],["76382","0.00654567","1"],["76382.3","0","0"],["76470.6","0.01580142","1"]],"bids":[["76355.3","0","0"],["76355.1","0.04259146","3"],["76347.6","0.00001033","1"],["76346.3","0.00654567","1"]]}
{"instId":"BTC-USDT","action":"update","ts":"1776816009980","asks":[],"bids":[["76367","0.39529727","5"]]}
{"instId":"BTC-USDT","action":"update","ts":"1776816009990","asks":[["76375.1","0.00654518","1"],["76375.2","0.00001501","1"],["76470.6","0","0"]],"bids":[["76355.1","0.04259147","3"]]}
{"instId":"BTC-USDT","action":"update","ts":"1776816010000","asks":[["76367.1","0.81231991","16"]],"bids":[]}
{"instId":"BTC-USDT","action":"update","ts":"1776816010010","asks":[["76375","0.00654518","1"],["76375.1","0","0"],["76382","0","0"],["76382.3","0.00654568","1"]],"bids":[["76355.3","0.00654518","1"],["76355.1","0.03604629","2"],["76347.6","0.00655601","2"],["76346.3","0","0"]]}
{"instId":"BTC-USDT","action":"update","ts":"1776816010020","asks":[["76374.9","0.00655841","2"],["76375","0","0"],["76470.6","0.01580142","1"]],"bids":[]}
{"instId":"BTC-USDT","action":"update","ts":"1776816010030","asks":[["76374.8","0.00654524","1"],["76374.9","0.00001316","1"],["76470.6","0","0"]],"bids":[]}
{"instId":"BTC-USDT","action":"update","ts":"1776816010040","asks":[["76374.8","0","0"],["76375.3","0.00654524","1"]],"bids":[]}
{"instId":"BTC-USDT","action":"update","ts":"1776816010050","asks":[["76375.3","0.0065453","1"]],"bids":[]}
{"instId":"BTC-USDT","action":"update","ts":"1776816010080","asks":[["76374.2","0.00654519","1"],["76375.3","0","0"],["76380.2","0.32728357","1"],["76381.6","0","0"],["76382","0.00654562","1"],["76382.3","0","0"]],"bids":[["76355.3","0","0"],["76354.4","0.00654519","1"],["76349.6","0","0"],["76348.9","0.32728357","1"],["76347.6","0.00001033","1"],["76346.3","0.00654562","1"],["76190.9","0","0"]]}
{"instId":"BTC-USDT","action":"update","ts":"1776816010090","asks":[["76380.3","0.27350863","1"]],"bids":[["76349.2","0.32728358","1"],["76348.9","0","0"]]}
{"instId":"BTC-USDT","action":"update","ts":"1776816010110","asks":[["76374.2","0","0"],["76375.3","0.00654519","1"]],"bids":[["76355.1","0.04259148","3"],["76354.4","0","0"],["76190.9","0.00015413","4"]]}
{"instId":"BTC-USDT","action":"update","ts":"1776816010120","asks":[],"bids":[["76347.5","0.02247847","3"],["76346.3","0","0"],["76190.4","0.00001319","1"]]}
{"instId":"BTC-USDT","action":"update","ts":"1776816010130","asks":[["76380.2","0","0"],["76381.6","0.32728011","1"],["76382","0","0"],["76382.3","0.00654561","1"]],"bids":[["76349.6","0.32728011","1"],["76349.2","0","0"],["76347.6","0.00655594","2"],["76347.5","0.01593286","2"]]}
{"instId":"BTC-USDT","action":"update","ts":"1776816010160","asks":[],"bids":[["76367","0.39412243","5"]]}
{"instId":"BTC-USDT","action":"update","ts":"1776816010170","asks":[["76367.1","0.81229373","16"]],"bids":[]}
{"instId":"BTC-USDT","action":"update","ts":"1776816010180","asks":[["76367.1","0.81757373","17"]],"bids":[]}
{"instId":"BTC-USDT","action":"update","ts":"1776816010190","asks":[["76380.2","0.32727985","1"],["76381.6","0","0"]],"bids":[["76349.6","0","0"],["76349.2","0.32727985","1"]]}
{"instId":"BTC-USDT","action":"update","ts":"1776816010200","asks":[["76367.1","0.81752136","17"]],"bids":[]}
{"instId":"BTC-USDT","action":"update","ts":"1776816010210","asks":[["76367.1","0.81725948","17"]],"bids":[]}
{"instId":"BTC-USDT","action":"update","ts":"1776816010220","asks":[["76380.2","0","0"],["76381.6","0.32727797","1"]],"bids":[["76349.6","0.32727797","1"],["76349.2","0","0"]]}
{"instId":"BTC-USDT","action":"update","ts":"1776816010230","asks":[["76466.8","0","0"],["76470.6","0.01580142","1"]],"bids":[["76340.8","0","0"],["76315.2","0","0"],["76190","0.00001428","1"],["76188.9","0.00002109","2"]]}
{"instId":"BTC-USDT","action":"update","ts":"1776816010240","asks":[["76382.3","0","0"],["76382.6","0.00655711","2"],["76411.5","0.17974497","1"],["76412.4","0","0"],["76470.8","0.0001444","7"]],"bids":[]}
{"instId":"BTC-USDT","action":"update","ts":"1776816010270","asks":[["76380.2","0.32727934","1"],["76381.6","0","0"]],"bids":[]}
{"instId":"BTC-USDT","action":"update","ts":"1776816010280","asks":[["76380.2","0.32727931","1"]],"bids":[]}
{"instId":"BTC-USDT","action":"update","ts":"1776816010290","asks":[["76380.2","0","0"],["76381.6","0.32727928","1"]],"bids":[]}
{"instId":"BTC-USDT","action":"update","ts":"1776816010300","asks":[["76367.1","0.8172202","17"]],"bids":[]}
{"instId":"BTC-USDT","action":"update","ts":"1776816010310","asks":[],"bids":[["76367","0.41675243","6"]]}
{"instId":"BTC-USDT","action":"update","ts":"1776816010320","asks":[["76380.2","0.32727804","1"],["76381.6","0","0"],["76382.5","0.00654557","1"],["76382.6","0.00001154","1"],["76470.8","0","0"]],"bids":[["76349.6","0","0"],["76349.2","0.32727804","1"]]}
{"instId":"BTC-USDT","action":"update","ts":"1776816010330","asks":[["76380.2","0","0"],["76381.5","0.32727801","1"]],"bids":[["76349.7","0.32727801","1"],["76349.2","0","0"]]}
{"instId":"BTC-USDT","action":"update","ts":"1776816010350","asks":[["76407.8","0","0"],["76470.5","0.00927944","19"],["76470.8","0.0001444","7"]],"bids":[["76331.3","0","0"],["76260.6","0.00001316","1"]]}
{"instId":"BTC-USDT","action":"update","ts":"1776816010390","asks":[["76403.8","0.06296983","1"],["76470.8","0","0"]],"bids":[["76327.3","0.06390095","1"],["76188.9","0","0"]]}
{"instId":"BTC-USDT","action":"update","ts":"1776816010410","asks":[["76367.1","0.81719402","17"],["76382.4","0.21223725","3"]],"bids":[]}
{"instId":"BTC-USDT","action":"update","ts":"1776816010420","asks":[["76397.7","0.05305931","1"],["76470.6","0","0"]],"bids":[]}
{"instId":"BTC-USDT","action":"update","ts":"1776816010430","asks":[["76397.7","0","0"],["76470.6","0.01580142","1"]],"bids":[]}
{"instId":"BTC-USDT","action":"update","ts":"1776816010450","asks":[["76382.4","0.26529656","4"]],"bids":[["76330.2","0","0"],["76188.9","0.00002109","2"]]}
{"instId":"BTC-USDT","action":"update","ts":"1776816010500","asks":[["76367.1","0.80415802","17"]],"bids":[]}
{"instId":"BTC-USDT","action":"update","ts":"1776816010510","asks":[["76367.1","0.80383066","17"]],"bids":[]}
{"instId":"BTC-USDT","action":"update","ts":"1776816010520","asks":[["76382.5","0","0"],["76383.7","0.00654567","1"]],"bids":[]}
{"instId":"BTC-USDT","action":"update","ts":"1776816010530","asks":[],"bids":[["76330.2","0.00002865","1"],["76188.9","0","0"]]}
{"instId":"BTC-USDT","action":"update","ts":"1776816010540","asks":[["76382.4","0.05305931","1"]],"bids":[]}
{"instId":"BTC-USDT","action":"update","ts":"1776816010560","asks":[["76397.7","0.21223725","3"],["76470.6","0","0"]],"bids":[]}
{"instId":"BTC-USDT","action":"update","ts":"1776816010590","asks":[["76397.7","0.10611862","2"]],"bids":[]}
{"instId":"BTC-USDT","action":"update","ts":"1776816010600","asks":[["76367.1","0.8037652","17"]],"bids":[]}
{"instId":"BTC-USDT","action":"update","ts":"1776816010610","asks":[["76382.4","0.15917794","2"],["76404.5","0.01","1"],["76470.5","0","0"]],"bids":[["76336.4","0.21095284","3"]]}
{"instId":"BTC-USDT","action":"update","ts":"1776816010630","asks":[],"bids":[["76336.4","0.26182997","4"]]}
{"instId":"BTC-USDT","action":"update","ts":"1776816010700","asks":[["76367.1","0.80343784","17"],["76382.6","0.00655719","2"],["76383.7","0","0"],["76470.5","0.00927944","19"]],"bids":[]}
{"instId":"BTC-USDT","action":"update","ts":"1776816010770","asks":[["76396.4","0","0"],["76470.6","0.01580142","1"]],"bids":[]}
{"instId":"BTC-USDT","action":"update","ts":"1776816010790","asks":[["76367.1","0.67900205","15"],["76397.7","0","0"],["76470.8","0.0001444","7"]],"bids":[]}
{"instId":"BTC-USDT","action":"update","ts":"1776816010800","asks":[["76367.1","0.0674484","6"],["76375.3","0.00075293","1"],["76375.4","0","0"],["76378.5","0.00654504","1"],["76381.5","0","0"],["76382.4","0.21223725","3"],["76382.6","0.00001154","1"],["76384.9","0","0"],["76385.2","0.00654556","1"],["76386.7","0","0"],["76387.5","0.3272771","1"],["76397.7","0.05305931","1"]],"bids":[["76367","0.45787315","17"],["76359.3","0.1305","1"],["76358.2","0.1172684","2"],["76357.3","0.00654504","1"],["76355.3","0.3272771","1"],["76355.1","0.03604629","2"],["76350.9","0","0"],["76350.2","0.00654556","1"],["76349.7","0","0"],["76347.6","0.00001033","1"],["76346.3","0.08378297","1"],["76244.8","0","0"],["76190.4","0","0"],["76190","0","0"]]}
{"instId":"BTC-USDT","action":"update","ts":"1776816010810","asks":[["76367.1","0.04997796","4"],["76372","0.01307527","1"],["76377.3","0","0"],["76377.5","0","0"],["76378.5","0","0"],["76382","0.00654504","1"],["76385.2","0","0"],["76385.3","0.30091292","1"],["76387.5","0","0"],["76388.1","0.32726935","1"],["76391.4","0.0065454","1"],["76397.7","0","0"],["76471.1","0.47253258","5"],["76471.2","0.00067513","2"]],"bids":[["76367","0.46049116","18"],["76364.9","0.12992087","2"],["76362.9","0.01303954","1"],["76362.7","0.00654504","1"],["76362.3","0","0"],["76359.4","0.09603963","2"],["76357.3","0","0"],["76355.4","0.47151308","1"],["76355.2","0.12489798","2"],["76350.2","0.08378297","1"],["76254.8","0","0"],["76190.9","0","0"]]}
{"instId":"BTC-USDT","action":"update","ts":"1776816010820","asks":[["76382","0.00654485","1"],["76385.3","0.2032207","1"],["76388","0.32726895","1"],["76388.1","0","0"],["76391.4","0","0"],["76392.7","0.00654539","1"],["76397.7","0.05305931","1"],["76429.2","0.11086323","2"],["76471.2","0","0"]],"bids":[["76365","0.05980083","3"],["76364.9","0.1","1"],["76362.9","0","0"],["76362.8","0.00654485","1"],["76362.7","0","0"],["76362","0.01303969","1"],["76356.6","0.00654539","1"],["76356","0.05889073","1"],["76355.5","0.32726895","1"],["76355.3","0","0"],["76355.2","0.11835258","1"],["76349.5","0.00023744","5"],["76326.5","0.00131016","1"],["76326.3","0.1","1"],["76191.7","0","0"],["76191.2","0","0"],["76191","0","0"]]}
{"instId":"BTC-USDT","action":"update","ts":"1776816010830","asks":[["76382","0","0"],["76382.4","0.10611862","2"],["76383.7","0.00654484","1"],["76387.6","0.25072572","2"],["76391.3","0.0065454","1"],["76392.7","0","0"]],"bids":[["76365","0.15980083","4"],["76362.8","0","0"],["76362.7","0.00654484","1"],["76362.4","0","0"],["76357.3","0.32726895","1"],["76357.2","0.31655865","7"],["76356.6","0","0"],["76355.5","0.0065454","1"],["76191.2","0.0000842","4"]]}
{"instId":"BTC-USDT","action":"update","ts":"1776816010840","asks":[["76392.8","0","0"],["76397.7","0.15917794","2"],["76471.2","0.00067513","2"]],"bids":[["76364.8","0.17885746","7"],["76362","0","0"],["76357.2","0.01333744","6"],["76191.7","0.1305","1"]]}
{"instId":"BTC-USDT","action":"update","ts":"1776816010850","asks":[["76382.3","0.00654487","1"],["76383.7","0","0"],["76388","0","0"],["76388.1","0.3272695","1"],["76392.8","0.08378297","1"],["76471.2","0","0"]],"bids":[["76359.6","0.01304011","1"],["76359.4","0.17758023","3"],["76357.3","0","0"],["76356.1","0.3272695","1"],["76191.2","0","0"]]}
{"instId":"BTC-USDT","action":"update","ts":"1776816010860","asks":[],"bids":[["76367","0.62049116","19"],["76362.7","0.16654484","2"],["76359.4","0.09603963","2"],["76356.2","0.30902094","1"],["76191.7","0","0"]]}
{"instId":"BTC-USDT","action":"update","ts":"1776816010870","asks":[["76382.4","0.05305931","1"],["76387.5","1.00566932","1"],["76471.1","0","0"]],"bids":[["76364.8","0.2126737","8"]]}
{"instId":"BTC-USDT","action":"update","ts":"1776816010880","asks":[["76385.3","0.47743163","2"],["76391.3","0","0"],["76391.4","0.00654535","1"],["76397.7","0.21223725","3"]],"bids":[["76355.5","0","0"],["76354.4","0.00654535","1"]]}
{"instId":"BTC-USDT","action":"update","ts":"1776816010890","asks":[["76382","0.00654468","1"],["76382.3","0","0"],["76383.1","0.05889073","1"],["76470.8","0","0"]],"bids":[["76362.7","0.16","1"],["76361.1","0.00656148","2"],["76336.4","0.21095284","3"]]}
{"instId":"BTC-USDT","action":"update","ts":"1776816010900","asks":[["76377.1","0.18211183","5"]],"bids":[["76351.7","0.05087713","1"],["76192.2","0","0"]]}
{"instId":"BTC-USDT","action":"update","ts":"1776816010910","asks":[["76369.7","0.01307565","1"],["76372","0","0"]],"bids":[]}
{"instId":"BTC-USDT","action":"update","ts":"1776816010930","asks":[["76367.1","0.09917796","6"]],"bids":[["76367","0.42449116","17"]]}
{"instId":"BTC-USDT","action":"update","ts":"1776816010940","asks":[["76388.6","0.00654544","1"],["76391.4","0","0"]],"bids":[["76354.4","0","0"],["76353.4","0.00654544","1"]]}
{"instId":"BTC-USDT","action":"update","ts":"1776816010950","asks":[["76375.4","0.14074665","1"],["76380.2","0.00654471","1"],["76382","0","0"],["76386.8","0.32727124","1"],["76388","0.00654544","1"],["76388.1","0","0"],["76388.6","0","0"],["76470.6","0","0"]],"bids":[["76361.1","0.0000168","1"],["76359.7","0.00654471","1"],["76356.1","0","0"],["76355.2","0.44562382","2"],["76353.4","0","0"],["76352.1","0.00654544","1"]]}
{"instId":"BTC-USDT","action":"update","ts":"1776816010960","asks":[["76387.6","0.17770951","1"]],"bids":[["76355.2","0.11835258","1"],["76351.8","0.3272714","1"],["76192.3","0","0"]]}
{"instId":"BTC-USDT","action":"update","ts":"1776816010970","asks":[["76367.1","0.07962083","5"]],"bids":[["76367","0.48449116","18"],["76356.2","0.20937719","1"]]}
{"instId":"BTC-USDT","action":"update","ts":"1776816010990","asks":[["76384.9","0.32726986","1"],["76386.8","0","0"]],"bids":[["76367","0.42449116","17"]]}
{"instId":"BTC-USDT","action":"update","ts":"1776816011000","asks":[["76367.1","0.079503","5"]],"bids":[]}
{"instId":"BTC-USDT","action":"update","ts":"1776816011010","asks":[["76367.1","0.07942182","5"]],"bids":[["76235","0.47699664","2"],["76233.6","0","0"],["76208.2","0.00021397","1"],["76206.6","0","0"],["76192.3","2.54203491","4"]]}
{"instId":"BTC-USDT","action":"update","ts":"1776816011020","asks":[["76400","0.03033899","4"]],"bids":[["76336.4","0.10483421","2"]]}
{"instId":"BTC-USDT","action":"update","ts":"1776816011030","asks":[],"bids":[["76355.4","0","0"],["76337.6","0","0"],["76336.4","0.21095284","3"],["76192.2","0.00007834","2"],["76191.2","0.0000842","4"]]}
{"instId":"BTC-USDT","action":"update","ts":"1776816011040","asks":[["76367.1","0.09882182","6"],["76382.4","0","0"],["76470.6","0.01580142","1"]],"bids":[["76359.6","0","0"],["76356.6","0.01304062","1"],["76356.2","0.06863054","1"],["76336.4","0.15917794","2"],["76191.7","0.1305","1"],["76191.2","0","0"]]}
{"instId":"BTC-USDT","action":"update","ts":"1776816011050","asks":[["76367.1","0.07942182","5"],["76371.6","0.00076609","2"],["76375.3","0","0"],["76470.8","0.0001444","7"]],"bids":[]}
{"instId":"BTC-USDT","action":"update","ts":"1776816011060","asks":[["76371.6","0.00001316","1"],["76372.5","0.00169149","2"],["76378.5","0.00654492","1"],["76380.2","0","0"],["76386.8","0.00654547","1"],["76388","0","0"]],"bids":[["76362.7","0","0"],["76359.7","0","0"],["76358.3","0.00654492","1"],["76356.6","0","0"],["76352.1","0","0"],["76350.3","0.00654547","1"],["76191.2","0.0000842","4"],["76191","0.00014147","1"]]}
{"instId":"BTC-USDT","action":"update","ts":"1776816011070","asks":[["76367.1","0.16475182","7"],["76378.5","0","0"],["76380.1","0.00654487","1"],["76429.2","0.00009765","1"]],"bids":[["76364.8","0.17885746","7"],["76359.4","0.1025845","3"],["76358.3","0","0"],["76354.2","0.01609103","2"],["76190.9","0.00015413","4"]]}
{"instId":"BTC-USDT","action":"update","ts":"1776816011080","asks":[["76367.1","0.37553083","10"],["76369.2","0.00075293","1"],["76372.5","0.00093856","1"],["76377.5","0.00654487","1"],["76380.1","0","0"],["76382.4","0.05305931","1"],["76387.4","0.08378297","1"],["76397.7","0.05305931","1"],["76470.5","0","0"],["76470.6","0","0"],["76470.8","0","0"]],"bids":[["76367","0.40051044","7"],["76359.4","0.07989379","1"],["76357.3","0.00654487","1"],["76351.7","0","0"],["76336.4","0.21095284","3"],["76287.7","0.00011334","2"],["76244.9","0","0"],["76190.4","0.00001319","1"]]}
{"instId":"BTC-USDT","action":"update","ts":"1776816011090","asks":[["76367.1","0.37628376","11"],["76369.2","0","0"],["76382.4","0.15917794","2"],["76383","0.3272758","1"],["76384.9","0.00654553","1"],["76386.8","0","0"],["76470.5","0.00927944","19"]],"bids":[["76351.8","0","0"],["76350.3","0.33382127","2"],["76336.4","0.26182997","4"],["76190","0.00001428","1"]]}
{"instId":"BTC-USDT","action":"update","ts":"1776816011100","asks":[["76367.1","0.37890171","12"],["76376.2","0.00654489","1"],["76377.5","0","0"],["76383.7","0.00654553","1"],["76384.9","0","0"]],"bids":[["76367","0.39789243","6"],["76359.3","0","0"],["76357.3","0","0"],["76356.3","0.00654489","1"],["76350.3","0.3272758","1"],["76347.6","0.00655586","2"],["76188.9","0.00002109","2"]]}
{"instId":"BTC-USDT","action":"update","ts":"1776816011110","asks":[["76367.1","0.37883624","12"],["76375.3","0.10838162","1"],["76470.5","0","0"]],"bids":[["76359.5","0.05885291","1"],["76359.4","0","0"]]}
{"instId":"BTC-USDT","action":"update","ts":"1776816011120","asks":[["76400","0.0144791","3"]],"bids":[["76359.5","0.03500462","1"]]}
{"instId":"BTC-USDT","action":"update","ts":"1776816011130","asks":[["76375.2","0.00656007","2"],["76376.2","0","0"],["76470.5","0.00927944","19"]],"bids":[["76356.3","0","0"],["76355.3","0.00654506","1"]]}
{"instId":"BTC-USDT","action":"update","ts":"1776816011140","asks":[["76382.4","0.21223725","3"]],"bids":[]}
{"instId":"BTC-USDT","action":"update","ts":"1776816011150","asks":[],"bids":[["76367","0.42052243","7"]]}
{"instId":"BTC-USDT","action":"update","ts":"1776816011160","asks":[["76367.1","0.42791233","14"],["76369.7","0","0"],["76375.2","0.00001501","1"],["76376.2","0.00654503","1"],["76397.7","0","0"],["76470.6","0.01580142","1"]],"bids":[["76367","0.10019739","2"],["76356.6","0.00654503","1"],["76355.3","0","0"],["76355.1","0.00004629","1"],["76350.2","0","0"],["76188.7","0.0108121","8"]]}
{"instId":"BTC-USDT","action":"update","ts":"1776816011170","asks":[["76365.1","1.20708441","18"],["76366.3","0.00637105","2"],["76366.8","0.47151308","1"],["76367","0.12773183","1"],["76367.1","0.10005039","6"],["76371.6","0.11903705","2"],["76372.4","0.00654528","1"],["76374.7","0.00075293","1"],["76376.2","0","0"],["76377.2","0","0"],["76379.9","0.00655652","2"],["76380.2","0.32728277","1"],["76380.4","0.05305931","1"],["76382.4","0","0"],["76382.5","0.1305","1"],["76382.9","0.08378297","1"],["76383","0","0"],["76383.7","0","0"],["76385.1","0.00001034","1"],["76416","0","0"],["76420.8","0.000015","1"],["76470.2","0","0"],["76470.3","0","0"],["76470.5","0","0"],["76470.6","0","0"]],"bids":[["76367","0","0"],["76366.8","0","0"],["76366.5","0","0"],["76366.2","0","0"],["76365","0.1431168","3"],["76364.8","0.10023743","6"],["76362.6","0","0"],["76361.6","0","0"],["76361","0.00023744","5"],["76356.6","0","0"],["76356.5","0.00001034","1"],["76354.2","0.00305","1"],["76353.6","0.00261827","1"],["76350.4","0.00654528","1"],["76350.3","0","0"],["76350","0.00001155","1"],["76349.9","0.00003323","1"],["76347.6","0.00001033","1"],["76347.5","0.34321563","3"],["76346.3","0","0"],["76346.1","0","0"],["76343.1","0.00654567","1"],["76337.9","0.33701761","1"],["76336.4","0","0"],["76323","0.12259978","2"],["76320.3","0","0"],["76254.8","0.08378297","1"],["76244.8","0.08378297","1"],["76211.2","1.00566932","1"],["76188.3","0.00001061","1"],["76187.9","0.00001002","1"],["76187.7","0.47454308","2"],["76187.5","0.00032499","3"],["76187","0.00011911","5"]]}
{"instId":"BTC-USDT","action":"update","ts":"1776816011180","asks":[["76365.1","1.21420847","21"],["76366.3","0","0"],["76366.7","0.1706117","1"],["76367","0","0"],["76367.1","0.09743244","5"],["76372.3","0.00654561","1"],["76372.4","0","0"],["76374.7","0","0"],["76376.3","0.00027436","5"],["76376.9","0.05889073","1"],["76377","0.3272952","1"],["76380.1","1.12242877","2"],["76380.2","0","0"],["76380.4","0.26529656","4"],["76383.1","0","0"],["76385.2","0.12525319","1"],["76408.9","0.01412241","1"],["76416.7","0","0"]],"bids":[["76365","0.1000168","2"],["76356","0","0"],["76352.1","0.00654561","1"],["76350.4","0","0"],["76350.1","0.04257113","1"],["76348.7","0.05889073","1"],["76347.5","0.01593286","2"],["76346.2","0.00001456","1"],["76345.4","0.01304254","1"],["76343.1","0.33384087","2"],["76342.1","0","0"],["76334.4","0.21007187","4"],["76317.6","0","0"],["76309.8","0.01411781","1"],["76200","1.01902529","52"]]}
{"instId":"BTC-USDT","action":"update","ts":"1776816011190","asks":[["76371.5","0.04403203","2"],["76372.3","0","0"],["76375.2","0.32731577","2"],["76376.2","0.00654603","1"],["76377","0","0"],["76378.5","0.08378297","1"],["76379.9","0.00001085","1"],["76382.3","0.01614584","1"],["76394","0.1405","2"],["76462.7","0","0"],["76466.4","0","0"]],"bids":[["76365","0.0000168","1"],["76364.9","0","0"],["76364.8","0.00023743","5"],["76364.7","0.00006462","1"],["76359.5","0","0"],["76356.2","0.04108721","1"],["76354.3","0","0"],["76354.2","0","0"],["76352.1","0","0"],["76349.1","0.04365505","1"],["76347.6","0.00655596","2"],["76347.5","0.00004629","1"],["76346.1","0.00305","1"],["76345.4","0","0"],["76343.1","0","0"],["76342","0.32731756","2"],["76341.9","0.00023748","5"],["76341.1","0.00654603","1"],["76341","0","0"],["76335.1","0.00305","1"],["76332.9","0.00305","1"],["76316.7","0","0"],["76312.8","0","0"],["76200","0.01335597","51"],["76186.4","0.00022771","1"],["76186","0.00170529","1"],["76185.3","0.00002512","1"],["76184.8","0.01614584","1"],["76184.2","3.72","1"],["76184.1","0.47151308","1"]]}
{"instId":"BTC-USDT","action":"update","ts":"1776816011200","asks":[["76371.2","0.05889073","1"],["76371.5","0.15842605","3"],["76375.1","0.27275632","1"],["76375.4","0","0"],["76376.9","0","0"],["76380.4","0.21223725","3"],["76383","0.07955","1"],["76411.6","0","0"]],"bids":[["76358.3","0.03898584","1"],["76358.2","0.10001316","2"],["76344.6","0.01304267","1"],["76342","1.33298688","3"],["76308.7","0.11059534","1"],["76306.7","0.13059813","2"],["76184.8","0","0"],["76184.2","0","0"],["76184.1","0","0"]]}
{"instId":"BTC-USDT","action":"update","ts":"1776816011210","asks":[["76371.4","0.08282274","1"],["76371.5","0.12093963","2"],["76375.3","0","0"],["76415.3","0.17057517","2"]],"bids":[["76358.3","0.13898584","2"],["76349.1","0.07340106","2"],["76334.4","0.26184677","5"]]}
{"instId":"BTC-USDT","action":"update","ts":"1776816011220","asks":[["76371.1","0.00654579","1"],["76371.5","0.11439402","1"],["76380","0.68337142","2"],["76380.3","0","0"],["76440.3","0.01598","1"],["76470","0","0"]],"bids":[["76358.4","0.06368515","1"],["76358.3","0.1","1"],["76347.6","0.00001033","1"],["76347.5","0.00659208","2"],["76326.3","0","0"]]}
{"instId":"BTC-USDT","action":"update","ts":"1776816011230","asks":[["76379.9","0.11727223","2"],["76380.4","0.10611862","2"],["76415.3","0.00001316","1"],["76438.4","0.13848613","5"],["76440.4","0","0"],["76441.3","0.00002069","1"],["76443.1","0.0004837","5"]],"bids":[["76358.4","0.16368515","2"],["76345.8","0.59524002","2"],["76317","0","0"],["76314.6","0.00326501","2"],["76314.2","0","0"],["76311.4","0.00233579","1"],["76184.8","0.01614584","1"]]}
{"instId":"BTC-USDT","action":"update","ts":"1776816011240","asks":[["76375","0.32731105","1"],["76375.2","0.00001501","1"],["76469.7","0","0"]],"bids":[["76353.6","0","0"],["76349.4","0.00261842","1"],["76342","1.00568612","2"],["76341.5","0","0"],["76340.3","0.32731105","1"],["76334.1","0.11269183","2"],["76326.5","0","0"],["76317.3","0.00131031","1"],["76261.2","0.78071845","1"],["76184.8","0","0"]]}
{"instId":"BTC-USDT","action":"update","ts":"1776816011250","asks":[["76365.1","1.27643847","22"],["76366.6","0.00654581","1"],["76367.1","0.05436609","4"],["76371.1","0","0"],["76374.2","0.00654623","1"],["76374.9","0.24042063","2"],["76375.1","0","0"],["76376.2","0","0"],["76385","0.00001316","1"],["76404.8","0.14404495","1"],["76412.5","0.345807","1"]],"bids":[["76347.5","0.00004629","1"],["76346.2","0.00656037","2"],["76341.1","0","0"],["76338.2","0.00656303","2"],["76184.8","0.01614584","1"]]}
{"instId":"BTC-USDT","action":"update","ts":"1776816011260","asks":[["76372.8","0.05305931","1"],["76380.4","0.21223725","3"],["76411.5","0.10805133","1"],["76456.7","0.66055008","3"],["76460.4","0.657656","1"],["76469.4","0","0"],["76469.6","0","0"]],"bids":[["76358.5","0.02619","1"],["76324.3","0.1","1"],["76310.7","0.658944","1"],["76306.8","0.660491","1"],["76186.4","0","0"],["76186","0","0"],["76185.3","0","0"],["76184.8","0","0"]]}
{"instId":"BTC-USDT","action":"update","ts":"1776816011270","asks":[["76379.6","0.00003694","1"],["76381.1","0","0"],["76382.6","0","0"],["76384.9","0.00001155","1"],["76393.4","0.01547689","1"]],"bids":[["76358.5","0.12619","2"],["76348.7","0","0"],["76342.5","0.05889073","1"],["76340.2","0.05895139","2"],["76306.9","0.68184207","1"],["76306.6","0","0"]]}
{"instId":"BTC-USDT","action":"update","ts":"1776816011280","asks":[["76366.6","0","0"],["76371.1","0.00654578","1"],["76374.2","0","0"],["76375.4","0.00654616","1"],["76391.5","0","0"],["76397.2","0","0"],["76411.4","0.12792151","1"],["76428.2","0.00003959","1"],["76429.9","0","0"],["76469.4","0.00265436","2"]],"bids":[["76358.6","0.13120287","1"],["76358.4","0.1","1"],["76347.5","0.00659207","2"],["76346.2","0.00001456","1"],["76340.4","0.00654616","1"],["76338.2","0.0000168","1"],["76304.4","0","0"],["76301.8","0.00323306","1"],["76187.5","0","0"],["76187","0","0"]]}
{"instId":"BTC-USDT","action":"update","ts":"1776816011290","asks":[["76377.1","0.18160847","4"],["76387.3","0.01138548","1"],["76394","0.1305","1"],["76397.2","0.11992641","1"],["76407.4","0.00130877","1"],["76408.5","0.00132191","2"],["76416.6","0.1305","1"],["76417.6","0","0"],["76469.2","0","0"],["76469.4","0","0"]],"bids":[["76358.6","0.23120287","2"],["76274.8","0.21045355","3"],["76249.1","0.01352688","2"]]}
{"instId":"BTC-USDT","action":"update","ts":"1776816011300","asks":[],"bids":[["76349.9","0","0"],["76319.3","0.00040006","1"],["76187.5","0.00032499","3"]]}
{"instId":"BTC-USDT","action":"update","ts":"1776816011310","asks":[["76375","0","0"],["76375.4","0","0"],["76377","0.32730986","1"],["76377.5","0.00654621","1"]],"bids":[["76343.1","0.32730986","1"],["76342.6","0.00654621","1"],["76340.4","0","0"],["76340.3","0","0"],["76295.6","0","0"],["76292.6","0.00013107","1"],["76287.1","0","0"],["76284","0.00054217","1"]]}
{"instId":"BTC-USDT","action":"update","ts":"1776816011320","asks":[["76374.9","0.14076429","2"],["76377.1","0.18060177","2"],["76403.8","0","0"],["76469.2","0.08378297","1"]],"bids":[["76327.3","0","0"],["76187","0.00011911","5"]]}
{"instId":"BTC-USDT","action":"update","ts":"1776816011330","asks":[["76376.9","0.30479817","1"],["76377.1","0.00050335","1"],["76469.2","0","0"]],"bids":[]}
{"instId":"BTC-USDT","action":"update","ts":"1776816011340","asks":[["76377.1","0","0"],["76469.2","0.08378297","1"]],"bids":[["76330.2","0","0"],["76301.8","0","0"],["76186.4","0.00022771","1"],["76186","0.00170529","1"]]}
{"instId":"BTC-USDT","action":"update","ts":"1776816011350","asks":[["76376.8","0.0065463","1"],["76377.5","0","0"],["76469.2","0.21428297","2"]],"bids":[["76342.6","0","0"],["76341","0.0065463","1"],["76331.4","0.00001316","1"],["76264.2","0.00001316","1"],["76186.4","0","0"],["76186","0","0"]]}
{"instId":"BTC-USDT","action":"update","ts":"1776816011360","asks":[["76381.1","0.00002172","1"],["76469.2","0","0"]],"bids":[["76349.8","0.1426055","2"],["76319.2","0.57023808","3"]]}
{"instId":"BTC-USDT","action":"update","ts":"1776816011370","asks":[["76379.6","0.0000576","2"],["76382.6","0.00002309","1"],["76384.9","0","0"]],"bids":[]}
{"instId":"BTC-USDT","action":"update","ts":"1776816011390","asks":[],"bids":[["76320.9","0","0"],["76312.1","0.0013104","1"]]}
{"instId":"BTC-USDT","action":"update","ts":"1776816011400","asks":[],"bids":[["76301.8","0.00323309","1"],["76187","0","0"]]}
{"instId":"BTC-USDT","action":"update","ts":"1776816011410","asks":[["76365.1","1.27512898","21"],["76372.8","0","0"],["76469.2","0.08378297","1"]],"bids":[["76284","0.00054216","1"]]}
{"instId":"BTC-USDT","action":"update","ts":"1776816011420","asks":[["76380.4","0.26529656","4"],["76469.2","0.21428297","2"]],"bids":[]}
{"instId":"BTC-USDT","action":"update","ts":"1776816011450","asks":[["76388.2","0","0"],["76469.4","0.00265436","2"]],"bids":[["76365","0.0625168","2"]]}
{"instId":"BTC-USDT","action":"update","ts":"1776816011470","asks":[["76365.1","1.15794354","20"],["76376.8","0","0"],["76377","0","0"],["76378.4","0.32731819","1"],["76379.2","0.00654638","1"],["76416","0.10751437","1"],["76469.4","0","0"]],"bids":[["76365","0.0923168","3"],["76345.9","0.32732854","2"],["76343.2","0.00654638","1"],["76343.1","0","0"],["76341","0","0"],["76306.7","0.00001501","1"],["76287.7","0.00014678","3"],["76187","0.00011911","5"]]}
{"instId":"BTC-USDT","action":"update","ts":"1776816011480","asks":[["76376.8","0.32731819","1"],["76378.4","0","0"]],"bids":[["76349.1","0.14972373","1"],["76345.9","0.00001035","1"],["76343.2","0.33386457","2"],["76328.4","0.00007495","2"]]}
{"instId":"BTC-USDT","action":"update","ts":"1776816011490","asks":[["76376.9","0.20695215","1"]],"bids":[["76349.1","0.06140344","1"]]}
{"instId":"BTC-USDT","action":"update","ts":"1776816011500","asks":[["76371.4","0.05848948","1"]],"bids":[]}
{"instId":"BTC-USDT","action":"update","ts":"1776816011510","asks":[["76371.1","0","0"],["76371.3","0.00654567","1"],["76376.8","0","0"],["76378.4","0.32731818","1"],["76393.4","0","0"],["76469.4","0.00265436","2"]],"bids":[["76352.1","0.00654567","1"],["76347.5","0.00004629","1"],["76345.9","0.32732853","2"],["76344.6","0","0"],["76343.2","0.00654638","1"],["76340.2","0.0429","1"]]}
{"instId":"BTC-USDT","action":"update","ts":"1776816011520","asks":[["76365.1","0.98297715","18"],["76367.1","0.01836609","3"],["76380.1","1.00566932","1"]],"bids":[["76365","0.35492855","5"],["76356.2","0.15834859","2"],["76352.1","0","0"],["76350.2","0.00654566","1"],["76349.2","1.00566932","1"],["76349.1","0.14930369","2"],["76347.5","0.47155937","2"],["76347","0.01304226","1"],["76211.2","0","0"],["76187","0","0"]]}
{"instId":"BTC-USDT","action":"update","ts":"1776816011530","asks":[["76371.3","0","0"],["76374.2","0.00654537","1"],["76378.4","0","0"],["76378.5","0","0"],["76379.2","0","0"],["76379.8","0.32730645","1"],["76381.6","0.00654607","1"],["76469.6","0.00441584","1"]],"bids":[["76365","0.35532862","6"],["76356.3","0.07348733","1"],["76356.2","0.11726138","1"],["76352.1","0.00654537","1"],["76350.2","0","0"],["76347.5","0.79886582","3"],["76346.2","0.00656063","2"],["76345.9","0.00001035","1"],["76343.2","0","0"],["76342.1","0.08378297","1"],["76338.1","0.11751202","7"],["76323.9","0.14140231","2"],["76322.8","0.00023744","5"],["76308.7","0","0"]]}
{"instId":"BTC-USDT","action":"update","ts":"1776816011540","asks":[["76378.5","0.32730205","1"],["76379.8","0","0"],["76379.9","0.12381829","3"],["76381.6","0","0"],["76400.5","0.0155999","1"]],"bids":[["76349.3","0.60393656","1"],["76349.1","0","0"],["76347.5","0.47155937","2"],["76346.2","0.00001456","1"],["76345.9","0.3273124","2"],["76343.1","0.00654606","1"],["76187.5","0","0"]]}
{"instId":"BTC-USDT","action":"update","ts":"1776816011550","asks":[["76379.9","0.11727223","2"],["76381.6","0.00654606","1"],["76469.6","0","0"]],"bids":[["76346.2","0.00656062","2"],["76343.1","0","0"],["76187.5","0.00032499","3"]]}
{"instId":"BTC-USDT","action":"update","ts":"1776816011580","asks":[["76400.5","0","0"],["76469.6","0.00441584","1"]],"bids":[]}
{"instId":"BTC-USDT","action":"update","ts":"1776816011600","asks":[["76365.1","0.96994081","18"],["76434","0.00001968","1"]],"bids":[]}
{"instId":"BTC-USDT","action":"update","ts":"1776816011610","asks":[],"bids":[["76350.1","0.17848773","2"],["76323","0.00001155","1"],["76320.3","0.11152215","1"],["76187.5","0","0"]]}
{"instId":"BTC-USDT","action":"update","ts":"1776816011620","asks":[],"bids":[["76350.2","0.08314229","1"],["76350.1","0.1359166","1"],["76187.7","0","0"]]}
{"instId":"BTC-USDT","action":"update","ts":"1776816011630","asks":[],"bids":[["76350.3","0.13325157","1"],["76349.8","0.00003342","1"],["76337.5","0","0"]]}
{"instId":"BTC-USDT","action":"update","ts":"1776816011640","asks":[],"bids":[["76350.4","0.08036012","1"],["76350.2","0","0"]]}
{"instId":"BTC-USDT","action":"update","ts":"1776816011650","asks":[],"bids":[["76350.5","0.1279215","1"],["76350.1","0","0"]]}
{"instId":"BTC-USDT","action":"update","ts":"1776816011660","asks":[],"bids":[["76350.6","0.07797358","1"],["76350.4","0","0"]]}
{"instId":"BTC-USDT","action":"update","ts":"1776816011670","asks":[],"bids":[["76350.7","0.12259144","1"],["76350.3","0","0"]]}
{"instId":"BTC-USDT","action":"update","ts":"1776816011680","asks":[],"bids":[["76350.8","0.07479154","1"],["76350.6","0","0"]]}
{"instId":"BTC-USDT","action":"update","ts":"1776816011710","asks":[["76392.7","0.01536329","1"],["76469.6","0","0"]],"bids":[["76340.6","0.01545527","2"]]}
{"instId":"BTC-USDT","action":"update","ts":"1776816011770","asks":[["76365.1","0.96987535","18"]],"bids":[]}
{"instId":"BTC-USDT","action":"update","ts":"1776816011780","asks":[["76395.1","0.10655788","2"],["76404.5","0","0"],["76469.6","0.00441584","1"]],"bids":[]}
{"instId":"BTC-USDT","action":"update","ts":"1776816011790","asks":[],"bids":[["76347","0","0"],["76187.7","0.47454308","2"]]}
{"instId":"BTC-USDT","action":"update","ts":"1776816011800","asks":[["76365.1","0.96958729","18"]],"bids":[["76350.1","0.01304173","1"],["76349.8","0","0"],["76319.2","0.5699037","2"],["76287.7","0.00011334","2"]]}
{"instId":"BTC-USDT","action":"update","ts":"1776816011840","asks":[],"bids":[["76348.9","0.05889073","1"],["76342.5","0","0"]]}
{"instId":"BTC-USDT","action":"update","ts":"1776816011860","asks":[["76399.3","0.0635665","2"]],"bids":[["76349.5","0.00027092","6"],["76322.9","0.06352291","2"],["76318.4","0.19946005","2"]]}
{"instId":"BTC-USDT","action":"update","ts":"1776816011870","asks":[],"bids":[["76365","0.35223475","5"]]}
{"instId":"BTC-USDT","action":"update","ts":"1776816011890","asks":[["76392.7","0","0"],["76469.7","0.00021564","6"]],"bids":[]}
{"instId":"BTC-USDT","action":"update","ts":"1776816011960","asks":[["76384.1","0","0"],["76391.4","0.01579812","1"]],"bids":[["76287.7","0.00014685","3"]]}
{"instId":"BTC-USDT","action":"update","ts":"1776816012010","asks":[["76378.5","0","0"],["76379.8","0.32729978","1"]],"bids":[["76348.9","0.38619051","2"],["76345.9","0.00001035","1"]]}
{"instId":"BTC-USDT","action":"update","ts":"1776816012040","asks":[],"bids":[["76312.2","0.0023357","1"],["76311.4","0","0"]]}
{"instId":"BTC-USDT","action":"update","ts":"1776816012050","asks":[["76384.1","0.00010083","1"],["76469.7","0","0"]],"bids":[]}
{"instId":"BTC-USDT","action":"update","ts":"1776816012060","asks":[],"bids":[["76349.5","0.00023744","5"],["76318.4","0.19912505","1"],["76287.7","0.00011334","2"]]}
{"instId":"BTC-USDT","action":"update","ts":"1776816012100","asks":[["76367.1","0.01835609","2"],["76434.2","0.01916811","2"]],"bids":[]}
{"instId":"BTC-USDT","action":"update","ts":"1776816012130","asks":[],"bids":[["76357.2","0.01337092","7"],["76326.6","0.00057239","6"]]}
{"instId":"BTC-USDT","action":"update","ts":"1776816012140","asks":[["76374.2","0","0"],["76374.8","0.00654532","1"],["76379.8","0","0"],["76380.3","0.32729945","1"],["76381.6","0","0"],["76382","0.006546","1"]],"bids":[["76355.1","0.00659161","2"],["76352.1","0","0"],["76349.4","0.32991787","2"],["76348.9","0.05889073","1"],["76347.5","0.47810537","3"],["76346.2","0.00001456","1"],["76187.5","0.00032499","3"]]}
{"instId":"BTC-USDT","action":"update","ts":"1776816012160","asks":[["76374.2","0.00654534","1"],["76374.8","0","0"],["76379.8","0.32730053","1"],["76380.3","0","0"]],"bids":[["76355.1","0.00004629","1"],["76352.1","0.00654534","1"],["76349.4","0.00261842","1"],["76349","0.32730053","1"],["76347.5","0.47155937","2"],["76346.2","0.00656059","2"],["76187.7","0","0"],["76187.5","0","0"]]}
{"instId":"BTC-USDT","action":"update","ts":"1776816012170","asks":[["76424.2","0.00124337","2"]],"bids":[]}
{"instId":"BTC-USDT","action":"update","ts":"1776816012210","asks":[["76422.2","0.1","1"],["76469.6","0","0"]],"bids":[]}
{"instId":"BTC-USDT","action":"update","ts":"1776816012250","asks":[["76367.1","0.01307609","1"]],"bids":[["76365","0.35617368","6"]]}
{"instId":"BTC-USDT","action":"update","ts":"1776816012280","asks":[["76365.1","0.96944326","18"]],"bids":[]}
{"instId":"BTC-USDT","action":"update","ts":"1776816012290","asks":[["76381.6","0.006546","1"],["76382","0","0"]],"bids":[]}
{"instId":"BTC-USDT","action":"update","ts":"1776816012300","asks":[["76365.1","0.9693647","18"]],"bids":[]}
{"instId":"BTC-USDT","action":"update","ts":"1776816012320","asks":[["76381.6","0","0"],["76382","0.006546","1"]],"bids":[]}
{"instId":"BTC-USDT","action":"update","ts":"1776816012340","asks":[],"bids":[["76340.6","0.00001035","1"]]}
{"instId":"BTC-USDT","action":"update","ts":"1776816012390","asks":[["76380.4","0.15917794","2"],["76391.4","0","0"],["76469.6","0.00441584","1"]],"bids":[["76334.4","0.15919474","3"]]}
{"instId":"BTC-USDT","action":"update","ts":"1776816012400","asks":[["76395.7","0.10611862","2"],["76402.8","0.07697878","2"],["76469.6","0","0"]],"bids":[["76349.7","0.10265203","2"],["76187.9","0","0"]]}
{"instId":"BTC-USDT","action":"update","ts":"1776816012410","asks":[],"bids":[["76365","0.35089368","6"],["76349","0","0"],["76347.6","0.32730952","2"],["76310.8","0.47569561","1"],["76310","0","0"],["76187.9","0.00001002","1"]]}
{"instId":"BTC-USDT","action":"update","ts":"1776816012420","asks":[],"bids":[["76349.7","0","0"],["76345.4","0.01531777","1"]]}
{"instId":"BTC-USDT","action":"update","ts":"1776816012430","asks":[["76395.7","0.05305931","1"]],"bids":[]}
{"instId":"BTC-USDT","action":"update","ts":"1776816012440","asks":[["76395.7","0","0"],["76469.6","0.00441584","1"]],"bids":[]}
{"instId":"BTC-USDT","action":"update","ts":"1776816012480","asks":[["76380.4","0.26529656","4"]],"bids":[["76334.4","0.26184677","5"]]}
{"instId":"BTC-USDT","action":"update","ts":"1776816012570","asks":[["76365.1","0.96784571","18"]],"bids":[]}
{"instId":"BTC-USDT","action":"update","ts":"1776816012600","asks":[["76365.1","0.96778024","18"]],"bids":[]}
{"instId":"BTC-USDT","action":"update","ts":"1776816012610","asks":[["76365.1","0.96747777","18"]],"bids":[]}
{"instId":"BTC-USDT","action":"update","ts":"1776816012620","asks":[["76380.4","0.10611863","1"]],"bids":[["76334.4","0.15919474","3"]]}
{"instId":"BTC-USDT","action":"update","ts":"1776816012630","asks":[["76380.4","0.15917794","2"],["76395.7","0.10611862","2"],["76469.6","0","0"]],"bids":[["76349.7","0.10265203","2"],["76187.9","0","0"]]}
{"instId":"BTC-USDT","action":"update","ts":"1776816012650","asks":[["76395.7","0","0"],["76469.6","0.00441584","1"]],"bids":[["76349.7","0","0"],["76187.9","0.00001002","1"]]}
{"instId":"BTC-USDT","action":"update","ts":"1776816012670","asks":[["76365.1","0.96728135","18"]],"bids":[]}
{"instId":"BTC-USDT","action":"update","ts":"1776816012700","asks":[["76365.1","0.96044999","18"]],"bids":[]}
{"instId":"BTC-USDT","action":"update","ts":"1776816012710","asks":[["76380.4","0.26529656","4"]],"bids":[["76334.4","0.26184677","5"]]}
{"instId":"BTC-USDT","action":"update","ts":"1776816012870","asks":[["76380.4","0.15917794","2"]],"bids":[]}
{"instId":"BTC-USDT","action":"update","ts":"1776816012890","asks":[["76395.7","0.10611862","2"],["76469.6","0","0"]],"bids":[]}
{"instId":"BTC-USDT","action":"update","ts":"1776816012900","asks":[["76365.1","0.9601881","18"]],"bids":[]}
{"instId":"BTC-USDT","action":"update","ts":"1776816012910","asks":[["76365.1","0.95625961","18"],["76395.7","0","0"],["76469.6","0.00441584","1"]],"bids":[]}
{"instId":"BTC-USDT","action":"update","ts":"1776816012930","asks":[["76380.4","0.26529656","4"]],"bids":[]}
{"instId":"BTC-USDT","action":"update","ts":"1776816012950","asks":[],"bids":[["76208.4","0.001571","1"],["76187.9","0","0"]]}
{"instId":"BTC-USDT","action":"update","ts":"1776816013070","asks":[["76392","0.01546847","1"],["76469.6","0","0"]],"bids":[]}
{"instId":"BTC-USDT","action":"update","ts":"1776816013110","asks":[],"bids":[["76352.8","0.01435034","1"],["76350.1","0","0"]]}
{"instId":"BTC-USDT","action":"update","ts":"1776816013120","asks":[],"bids":[["76352.9","0.00654553","1"],["76352.1","0","0"]]}
{"instId":"BTC-USDT","action":"update","ts":"1776816013140","asks":[["76380.4","0.15917794","2"]],"bids":[["76334.4","0.15919474","3"]]}
{"instId":"BTC-USDT","action":"update","ts":"1776816013150","asks":[["76395.7","0.10611862","2"],["76469.4","0","0"]],"bids":[["76349.7","0.10265203","2"],["76188.3","0","0"]]}
{"instId":"BTC-USDT","action":"update","ts":"1776816013170","asks":[],"bids":[["76349.7","0.05087713","1"]]}
{"instId":"BTC-USDT","action":"update","ts":"1776816013180","asks":[],"bids":[["76349.7","0","0"],["76188.3","0.00001061","1"]]}
{"instId":"BTC-USDT","action":"update","ts":"1776816013210","asks":[["76365.1","0.95626961","19"],["76378.5","0.08378297","1"],["76469.2","0","0"]],"bids":[]}
{"instId":"BTC-USDT","action":"update","ts":"1776816013230","asks":[],"bids":[["76349.7","0.10265203","2"],["76188.3","0","0"]]}
{"instId":"BTC-USDT","action":"update","ts":"1776816013240","asks":[],"bids":[["76365","0.45089368","7"],["76358.2","0.00001316","1"]]}
{"instId":"BTC-USDT","action":"update","ts":"1776816013310","asks":[],"bids":[["76349.7","0.0517749","1"]]}
{"instId":"BTC-USDT","action":"update","ts":"1776816013320","asks":[["76395.7","0.05305931","1"]],"bids":[["76349.7","0","0"],["76188.3","0.00001061","1"]]}
{"instId":"BTC-USDT","action":"update","ts":"1776816013330","asks":[["76380.4","0.21223725","3"]],"bids":[["76334.4","0.26184677","5"]]}
{"instId":"BTC-USDT","action":"update","ts":"1776816013370","asks":[["76365.1","0.95607319","19"]],"bids":[]}
{"instId":"BTC-USDT","action":"update","ts":"1776816013400","asks":[["76365.1","0.95498637","19"]],"bids":[]}
{"instId":"BTC-USDT","action":"update","ts":"1776816013410","asks":[["76365.1","0.95423998","19"],["76380.4","0.15917794","2"]],"bids":[["76334.4","0.15919474","3"]]}
{"instId":"BTC-USDT","action":"update","ts":"1776816013430","asks":[["76395.7","0.10611862","2"]],"bids":[["76349.7","0.10265203","2"],["76188.3","0","0"]]}
{"instId":"BTC-USDT","action":"update","ts":"1776816013440","asks":[],"bids":[["76326.4","0.06964299","2"]]}
{"instId":"BTC-USDT","action":"update","ts":"1776816013480","asks":[["76395.7","0.05305931","1"]],"bids":[["76349.7","0","0"],["76188.3","0.00001061","1"]]}
{"instId":"BTC-USDT","action":"update","ts":"1776816013490","asks":[],"bids":[["76334.4","0.21007187","4"]]}
{"instId":"BTC-USDT","action":"update","ts":"1776816013510","asks":[["76365.1","0.95419284","19"],["76380.4","0.21223725","3"]],"bids":[["76334.4","0.26184677","5"]]}
{"instId":"BTC-USDT","action":"update","ts":"1776816013550","asks":[["76380.4","0.10611863","1"]],"bids":[["76334.4","0.10613543","2"]]}
{"instId":"BTC-USDT","action":"update","ts":"1776816013570","asks":[["76380.4","0.15917794","2"]],"bids":[["76349.7","0.05087713","1"],["76334.4","0.15919474","3"],["76188.3","0","0"]]}
{"instId":"BTC-USDT","action":"update","ts":"1776816013580","asks":[["76449.3","0","0"],["76469.2","0.08378297","1"]],"bids":[]}
{"instId":"BTC-USDT","action":"update","ts":"1776816013590","asks":[["76395.7","0.10611862","2"],["76469.2","0.21428297","2"]],"bids":[["76349.7","0.10265203","2"]]}
{"instId":"BTC-USDT","action":"update","ts":"1776816013710","asks":[["76365.1","0.95414047","19"]],"bids":[]}
{"instId":"BTC-USDT","action":"update","ts":"1776816013780","asks":[["76450","0.55655623","30"]],"bids":[]}
{"instId":"BTC-USDT","action":"update","ts":"1776816013790","asks":[["76392","0","0"],["76469.4","0.00265436","2"]],"bids":[]}
{"instId":"BTC-USDT","action":"update","ts":"1776816013800","asks":[["76365.1","0.95411076","19"]],"bids":[]}
{"instId":"BTC-USDT","action":"update","ts":"1776816013820","asks":[["76365.1","0.95408458","19"]],"bids":[]}
{"instId":"BTC-USDT","action":"update","ts":"1776816013860","asks":[],"bids":[["76237.2","0","0"],["76188.3","0.00001061","1"]]}
{"instId":"BTC-USDT","action":"update","ts":"1776816014000","asks":[["76365.1","0.9540584","19"]],"bids":[]}
{"instId":"BTC-USDT","action":"update","ts":"1776816014010","asks":[["76381.6","0.00654599","1"],["76382","0","0"]],"bids":[]}
{"instId":"BTC-USDT","action":"update","ts":"1776816014030","asks":[],"bids":[["76195.7","0.02049965","1"],["76188.3","0","0"]]}
{"instId":"BTC-USDT","action":"update","ts":"1776816014100","asks":[["76395.7","0.05305931","1"]],"bids":[["76349.7","0.0517749","1"],["76195.7","0","0"],["76188.3","0.00001061","1"]]}
{"instId":"BTC-USDT","action":"update","ts":"1776816014130","asks":[["76380.4","0.21223725","3"]],"bids":[["76334.4","0.21007187","4"]]}
{"instId":"BTC-USDT","action":"update","ts":"1776816014170","asks":[["76365.1","0.95399293","19"],["76380.4","0.15917794","2"]],"bids":[["76334.4","0.15919474","3"]]}
{"instId":"BTC-USDT","action":"update","ts":"1776816014200","asks":[["76365.1","0.95327536","19"],["76380.4","0.10611863","1"]],"bids":[["76352","0","0"],["76187.9","0.00001002","1"]]}
{"instId":"BTC-USDT","action":"update","ts":"1776816014210","asks":[["76365.1","0.86630715","18"],["76395.7","0.10611862","2"]],"bids":[["76349.7","0.10265203","2"],["76334.4","0.10613543","2"]]}
{"instId":"BTC-USDT","action":"update","ts":"1776816014220","asks":[["76395.7","0.15917793","3"]],"bids":[["76349.7","0.15571134","3"]]}
{"instId":"BTC-USDT","action":"update","ts":"1776816014230","asks":[["76395.7","0.10611862","2"]],"bids":[["76365","0.29331772","6"],["76350.8","0.11169944","2"],["76349.7","0.10265203","2"]]}
{"instId":"BTC-USDT","action":"update","ts":"1776816014270","asks":[["76365.1","0.86601908","18"]],"bids":[]}
{"instId":"BTC-USDT","action":"update","ts":"1776816014300","asks":[["76380.4","0.15917794","2"]],"bids":[["76334.4","0.15919474","3"]]}
{"instId":"BTC-USDT","action":"update","ts":"1776816014310","asks":[["76365.1","0.8658423","18"]],"bids":[]}
{"instId":"BTC-USDT","action":"update","ts":"1776816014410","asks":[["76365.1","0.86571136","18"]],"bids":[]}
{"instId":"BTC-USDT","action":"update","ts":"1776816014440","asks":[["76380.4","0.10611863","1"]],"bids":[["76334.4","0.10613543","2"]]}
{"instId":"BTC-USDT","action":"update","ts":"1776816014460","asks":[["76380.4","0.15917794","2"]],"bids":[["76334.4","0.15919474","3"]]}
{"instId":"BTC-USDT","action":"update","ts":"1776816014500","asks":[["76365.1","0.86551494","18"]],"bids":[]}
{"instId":"BTC-USDT","action":"update","ts":"1776816014590","asks":[["76395.7","0","0"],["76469.6","0.00441584","1"]],"bids":[]}
{"instId":"BTC-USDT","action":"update","ts":"1776816014600","asks":[["76380.4","0.26529656","4"]],"bids":[]}
{"instId":"BTC-USDT","action":"update","ts":"1776816014640","asks":[["76393","0.30891845","2"]],"bids":[]}
{"instId":"BTC-USDT","action":"update","ts":"1776816014650","asks":[],"bids":[["76365","0.16351772","4"]]}
{"instId":"BTC-USDT","action":"update","ts":"1776816014660","asks":[],"bids":[["76346.2","0.00001456","1"],["76345.9","0.0065563","2"]]}
{"instId":"BTC-USDT","action":"update","ts":"1776816014710","asks":[],"bids":[["76349.7","0","0"],["76187.7","0.47454308","2"]]}
{"instId":"BTC-USDT","action":"update","ts":"1776816014720","asks":[["76365.1","0.86453283","18"]],"bids":[["76365","0.19331772","5"],["76350.8","0.07479154","1"],["76334.4","0.26184677","5"],["76262.6","0.44108604","1"],["76187.7","0","0"]]}
{"instId":"BTC-USDT","action":"update","ts":"1776816014730","asks":[],"bids":[["76261.2","0","0"],["76187.7","0.47454308","2"]]}
{"instId":"BTC-USDT","action":"update","ts":"1776816014780","asks":[["76365.1","0.86446736","18"]],"bids":[]}
{"instId":"BTC-USDT","action":"update","ts":"1776816014850","asks":[],"bids":[["76348.9","0.38618778","2"],["76347.6","0.00001033","1"]]}
{"instId":"BTC-USDT","action":"update","ts":"1776816014860","asks":[["76365.1","0.86101736","16"],["76366.7","0","0"],["76374.2","0","0"],["76375.4","0.00654544","1"],["76379.8","0","0"],["76380.4","0.10611863","1"],["76381.6","0","0"],["76382","0.32729703","1"],["76382.6","0.00656904","2"],["76408.9","0","0"],["76417","0.01833018","1"],["76469.7","0.00021564","6"],["76470","0.00007723","1"]],"bids":[["76365","0.64631269","10"],["76355.3","0.00654544","1"],["76352.9","0","0"],["76350.9","0.32729703","1"],["76348.9","0.05889073","1"],["76347.6","0.00655628","2"],["76345.9","0.00001035","1"],["76334.4","0.10613543","2"],["76187.7","0","0"]]}
{"instId":"BTC-USDT","action":"update","ts":"1776816014870","asks":[["76365.1","0.85802303","15"],["76375.4","0","0"],["76376.8","0.00654544","1"],["76382.6","0.00002309","1"],["76384","0.00654595","1"],["76395.7","0.15917793","3"],["76469.7","0","0"],["76470","0","0"]],"bids":[["76365","0.64893086","11"],["76356.4","0.00654544","1"],["76355.3","0","0"],["76351","0.17247972","1"],["76350.8","0","0"],["76350.5","0","0"],["76349.7","0.15571134","3"],["76349.3","0.61048251","2"],["76347.6","0.00001033","1"]]}
{"instId":"BTC-USDT","action":"update","ts":"1776816014880","asks":[["76371.6","0.00001316","1"],["76383.7","0.00654595","1"],["76384","0","0"]],"bids":[["76360","0.11583462","2"],["76349.4","0.12254169","2"],["76349.3","0.60393656","1"],["76349","0.00654595","1"],["76187.9","0","0"]]}
{"instId":"BTC-USDT","action":"update","ts":"1776816014890","asks":[["76371.1","0.05172943","1"],["76371.4","0","0"]],"bids":[]}
{"instId":"BTC-USDT","action":"update","ts":"1776816014900","asks":[["76366.8","0","0"],["76375.5","0","0"],["76378.5","0","0"],["76378.6","0","0"],["76380.1","0","0"],["76383.7","0","0"],["76384","0.00654594","1"],["76387.5","0","0"],["76469.7","0.00021564","6"],["76470","0.00007723","1"],["76470.2","0.05814278","2"],["76470.3","0.00003942","1"],["76470.5","0.00927944","19"],["76470.6","0.01580142","1"]],"bids":[["76349.3","0.6104825","2"],["76349","0","0"],["76187.9","0.00001002","1"]]}
{"instId":"BTC-USDT","action":"update","ts":"1776816014910","asks":[["76371.2","0","0"],["76374.9","0.00001316","1"],["76376.9","0.03924218","1"],["76377.3","0.05889073","1"],["76377.8","0.47151308","1"],["76380","0.0000812","1"],["76382","0","0"],["76382.3","0","0"],["76382.4","0.32729199","1"],["76382.5","0","0"],["76384","0","0"],["76385.1","1.0122519","3"],["76385.3","0.2032207","1"],["76390.4","0.12260323","2"],["76393","0.29343","1"],["76424.5","0.10698249","2"],["76470.8","0.0001444","7"],["76471.1","0.47253258","5"]],"bids":[["76365","0.74893086","12"],["76357.3","0.00654525","1"],["76356.4","0","0"],["76352.8","0","0"],["76351.1","0.32729653","1"],["76351","0.6439928","2"],["76350.9","0","0"],["76349.6","0.0065459","1"],["76349.3","0.60393656","1"],["76317.9","0.02162548","3"],["76309.8","0","0"],["76187.7","0.47454308","2"]]}
{"instId":"BTC-USDT","action":"update","ts":"1776816014920","asks":[["76365.1","0.76459282","14"],["76371.1","0.03415054","1"],["76376.8","0.00654525","1"],["76381.6","0.3272841","1"],["76382.4","0","0"],["76383.7","0.00654567","1"],["76385.1","1.005706","2"],["76471.1","0","0"]],"bids":[["76357.5","0.01375265","1"],["76357.3","0","0"],["76356.4","0.00654516","1"],["76351.2","0.3234858","2"],["76351.1","0","0"],["76351","0.47151308","1"],["76350.8","0.3272841","1"],["76349.6","0","0"],["76348.9","0.0654364","2"]]}
{"instId":"BTC-USDT","action":"update","ts":"1776816014930","asks":[["76376.9","0.19255068","2"]],"bids":[]}
{"instId":"BTC-USDT","action":"update","ts":"1776816014940","asks":[["76374.3","0.4819878","5"],["76381.6","0","0"],["76382.8","0.32729853","2"],["76383.7","0","0"],["76385","0.00655884","2"],["76471.1","0.47253258","5"],["76471.2","0.00002013","1"]],"bids":[["76357.3","0.00654521","1"],["76356.4","0","0"],["76351.3","0.32732982","2"],["76350.8","0","0"],["76349.8","0.00654568","1"],["76348.9","0.05889073","1"]]}
{"instId":"BTC-USDT","action":"update","ts":"1776816014950","asks":[["76374.2","0.14393884","1"],["76381.6","0.32728383","1"],["76382.8","0.000015","1"],["76383.7","0.00654575","1"],["76385","0.00001316","1"],["76395.7","0.10611862","2"],["76470.8","0","0"],["76471.1","0","0"],["76471.2","0","0"]],"bids":[["76357.3","0","0"],["76356.4","0.00654521","1"],["76351.3","0.00004629","1"],["76351.2","0.22578772","2"],["76350.8","0.32728383","1"],["76349.8","0","0"],["76349.7","0.10265203","2"],["76349","0.00654575","1"],["76187.7","0","0"]]}
{"instId":"BTC-USDT","action":"update","ts":"1776816014960","asks":[["76380.4","0.15917794","2"],["76381.5","0.34076697","1"],["76381.6","0","0"],["76382","0.32728701","1"],["76470.6","0","0"]],"bids":[["76356.5","0.0065556","2"],["76356.4","0","0"],["76351.1","0.32728701","1"],["76350.8","0","0"],["76349.1","0.0065457","1"],["76349","0","0"],["76334.4","0.15919474","3"],["76187.7","0.47454308","2"]]}
{"instId":"BTC-USDT","action":"update","ts":"1776816014970","asks":[["76365.1","0.76426154","14"],["76385","0.56923296","2"],["76385.3","0","0"],["76470.6","0.01580142","1"]],"bids":[]}
{"instId":"BTC-USDT","action":"update","ts":"1776816015000","asks":[["76365.1","0.76390276","14"],["76400.5","0.0154421","1"],["76470.6","0","0"]],"bids":[["76349.2","1.02145671","2"]]}
{"instId":"BTC-USDT","action":"update","ts":"1776816015010","asks":[["76365.1","0.76387658","14"]],"bids":[]}
{"instId":"BTC-USDT","action":"update","ts":"1776816015020","asks":[["76371.1","0","0"],["76470.6","0.01580142","1"]],"bids":[["76349.1","0","0"],["76347.6","0.00655612","2"],["76320.1","0.02531027","2"],["76312.1","0","0"],["76187.5","0.00032499","3"],["76187","0.00011911","5"]]}
{"instId":"BTC-USDT","action":"update","ts":"1776816015030","asks":[["76382","0.32728877","1"],["76383.7","0","0"],["76384","0.00654579","1"]],"bids":[["76351.1","0.32728877","1"],["76349.3","0.61048235","2"],["76347.6","0.00001033","1"]]}
{"instId":"BTC-USDT","action":"update","ts":"1776816015050","asks":[["76380.4","0.10611863","1"]],"bids":[["76334.4","0.10613543","2"]]}
{"instId":"BTC-USDT","action":"update","ts":"1776816015060","asks":[["76371.4","0.03415054","1"],["76395.7","0.15915335","3"],["76470.6","0","0"]],"bids":[["76349.7","0.15568676","3"]]}
{"instId":"BTC-USDT","action":"update","ts":"1776816015080","asks":[],"bids":[["76312.2","0","0"],["76311.4","0.0023357","1"]]}
{"instId":"BTC-USDT","action":"update","ts":"1776816015170","asks":[["76395.7","0.10611862","2"],["76422.2","0","0"],["76470.6","0.01580142","1"]],"bids":[["76349.7","0.10265203","2"]]}
{"instId":"BTC-USDT","action":"update","ts":"1776816015180","asks":[["76380.4","0.15915336","2"],["76382","0","0"],["76382.8","0.32730478","2"],["76384","0","0"],["76384.9","0.00654577","1"],["76470.8","0.0001444","7"]],"bids":[["76360","0.21583462","3"],["76358.3","0","0"],["76357.3","0.00654512","1"],["76356.5","0.00001034","1"],["76351.3","0.32733607","2"],["76351.1","0","0"],["76349.8","0.00654577","1"],["76349.3","0.60393656","1"],["76334.4","0.15917016","3"],["76246.9","0.000655","1"],["76187","0","0"]]}
{"instId":"BTC-USDT","action":"update","ts":"1776816015190","asks":[],"bids":[["76360.1","0.17185286","1"],["76358.6","0.1","1"],["76187.5","0","0"]]}
{"instId":"BTC-USDT","action":"update","ts":"1776816015200","asks":[["76365.1","0.7638504","14"]],"bids":[]}
{"instId":"BTC-USDT","action":"update","ts":"1776816015210","asks":[["76422.1","0.1","1"],["76470.8","0","0"]],"bids":[]}
{"instId":"BTC-USDT","action":"update","ts":"1776816015240","asks":[["76380.4","0.10611863","1"]],"bids":[["76334.4","0.10613543","2"]]}
{"instId":"BTC-USDT","action":"update","ts":"1776816015250","asks":[["76380.4","0.15915336","2"]],"bids":[["76334.4","0.15917016","3"]]}
{"instId":"BTC-USDT","action":"update","ts":"1776816015270","asks":[["76365.1","0.76309747","13"],["76371.3","0.00075293","1"],["76380.4","0.10611863","1"],["76470.6","0","0"]],"bids":[["76334.4","0.10613543","2"]]}
{"instId":"BTC-USDT","action":"update","ts":"1776816015300","asks":[["76395.7","0.05305931","1"]],"bids":[]}
{"instId":"BTC-USDT","action":"update","ts":"1776816015310","asks":[["76380.4","0.15915336","2"]],"bids":[]}
{"instId":"BTC-USDT","action":"update","ts":"1776816015340","asks":[["76380.4","0.21218809","3"]],"bids":[["76365","0.74774224","12"],["76349.7","0.05087713","1"],["76334.4","0.15917016","3"]]}
{"instId":"BTC-USDT","action":"update","ts":"1776816015350","asks":[["76395.7","0","0"],["76470.6","0.01580142","1"]],"bids":[["76360.1","0.27185286","2"],["76358.4","0","0"],["76349.7","0","0"],["76334.4","0.21084673","4"],["76187.5","0.00032499","3"],["76187","0.00011911","5"]]}
{"instId":"BTC-USDT","action":"update","ts":"1776816015370","asks":[["76380.4","0.26522282","4"]],"bids":[["76365","0.66519216","11"],["76334.4","0.26162553","5"]]}
{"instId":"BTC-USDT","action":"update","ts":"1776816015380","asks":[],"bids":[["76357.3","0","0"],["76356.4","0.00654496","1"]]}
{"instId":"BTC-USDT","action":"update","ts":"1776816015450","asks":[["76365.1","0.7638504","14"],["76371.3","0","0"],["76470.8","0.0001444","7"]],"bids":[]}
{"instId":"BTC-USDT","action":"update","ts":"1776816015490","asks":[["76383.7","0.00654587","1"],["76384.9","0","0"]],"bids":[["76349.8","0","0"],["76348.9","0.0654366","2"],["76186.4","0.00022771","1"]]}
{"instId":"BTC-USDT","action":"update","ts":"1776816015500","asks":[["76377.7","1.00569566","1"],["76382.9","0","0"]],"bids":[["76349.2","0.01578739","1"],["76237.1","0.00107799","1"],["76211.2","1.00569566","1"],["76187","0","0"],["76186.4","0","0"]]}
{"instId":"BTC-USDT","action":"update","ts":"1776816015510","asks":[["76371.2","0.47151308","1"],["76376.9","0.47315065","1"],["76381.4","0.32729402","1"],["76382.8","0.000015","1"],["76393.2","0.01564858","1"],["76470.5","0","0"],["76470.6","0","0"],["76470.8","0","0"]],"bids":[["76356.4","0","0"],["76355.3","0.00654511","1"],["76351.3","0.00004629","1"],["76351","0","0"],["76349.5","0.32753146","6"],["76349.3","0.22444154","1"],["76348.9","0.05889073","1"],["76347.6","0.00655622","2"],["76347.5","0.00004629","1"],["76343.1","0.47151308","1"],["76343","0","0"],["76342.2","1.00569566","1"],["76342","0.0000168","1"]]}
{"instId":"BTC-USDT","action":"update","ts":"1776816015520","asks":[["76371.1","0.1748972","1"],["76371.4","0","0"],["76381.5","0","0"],["76470.5","0.00927944","19"]],"bids":[["76351.2","0.03660734","2"],["76349.3","0","0"],["76187","0.00011911","5"]]}
{"instId":"BTC-USDT","action":"update","ts":"1776816015530","asks":[["76380.3","0.39493632","1"],["76382","0.08378297","1"],["76470.3","0","0"],["76470.5","0","0"]],"bids":[["76349.6","0.21804172","1"],["76187","0","0"]]}
{"instId":"BTC-USDT","action":"update","ts":"1776816015580","asks":[["76374.1","0.00654517","1"],["76376.8","0","0"],["76404.8","0","0"],["76406.7","0.24703927","2"],["76470.3","0.00003942","1"]],"bids":[["76355.3","0","0"],["76351.3","0.00659146","2"],["76187","0.00011911","5"]]}
{"instId":"BTC-USDT","action":"update","ts":"1776816015590","asks":[["76381.9","0.00654589","1"],["76383.7","0","0"],["76402.8","0.03896266","1"],["76424.5","0.0001315","1"]],"bids":[["76365","0.66257399","10"],["76357.5","0","0"],["76347.6","0.00001033","1"],["76346.2","0.00656045","2"],["76186.4","0.00022771","1"]]}
{"instId":"BTC-USDT","action":"update","ts":"1776816015600","asks":[["76379.8","0.32729156","1"],["76381.4","0","0"]],"bids":[["76365","0.56257399","9"],["76352.3","0.01376859","2"],["76349.5","0.00023744","5"],["76347.5","0.32733785","2"]]}
{"instId":"BTC-USDT","action":"update","ts":"1776816015610","asks":[],"bids":[["76352.4","0.00654519","1"],["76351.3","0.00004629","1"],["76186.4","0","0"]]}
{"instId":"BTC-USDT","action":"update","ts":"1776816015670","asks":[["76428.2","0","0"],["76470.5","0.00927944","19"]],"bids":[]}
{"instId":"BTC-USDT","action":"update","ts":"1776816015710","asks":[],"bids":[["76284","0.00054217","1"]]}
{"instId":"BTC-USDT","action":"update","ts":"1776816015770","asks":[["76365.1","0.76352304","14"]],"bids":[]}
{"instId":"BTC-USDT","action":"update","ts":"1776816015790","asks":[],"bids":[["76334.4","0.21084673","4"]]}
{"instId":"BTC-USDT","action":"update","ts":"1776816015800","asks":[["76365.1","0.76281594","14"],["76428.2","0.00003959","1"],["76470.5","0","0"]],"bids":[]}
{"instId":"BTC-USDT","action":"update","ts":"1776816015810","asks":[["76365.1","0.76258026","14"],["76380.4","0.15910419","3"]],"bids":[["76334.4","0.1047281","3"]]}
{"instId":"BTC-USDT","action":"update","ts":"1776816015820","asks":[["76380.3","0.29057187","1"],["76380.4","0.05303473","1"]],"bids":[["76349.7","0.15684826","2"],["76334.4","0.05305153","2"],["76187","0","0"]]}
{"instId":"BTC-USDT","action":"update","ts":"1776816015830","asks":[],"bids":[["76351.2","0.0787477","3"],["76349.7","0.0507788","1"],["76337.9","0","0"],["76187","0.00011911","5"]]}
{"instId":"BTC-USDT","action":"update","ts":"1776816015840","asks":[["76380.4","0.10606946","2"],["76395.7","0.05303473","1"],["76470.3","0","0"]],"bids":[["76351.2","0.03660734","2"],["76337.9","0.24115571","1"],["76334.4","0.1047281","3"],["76187","0","0"]]}
{"instId":"BTC-USDT","action":"update","ts":"1776816015870","asks":[["76365.1","0.76218742","14"]],"bids":[]}
{"instId":"BTC-USDT","action":"update","ts":"1776816015900","asks":[["76380.4","0.21213892","3"]],"bids":[["76334.4","0.21079756","4"]]}
{"instId":"BTC-USDT","action":"update","ts":"1776816015910","asks":[["76374.1","0","0"],["76374.2","0.1504841","2"],["76470.3","0.00003942","1"]],"bids":[["76355.1","0.00659155","2"],["76352.4","0","0"],["76187","0.00011911","5"]]}
{"instId":"BTC-USDT","action":"update","ts":"1776816015920","asks":[],"bids":[["76355.1","0.00004629","1"],["76352.4","0.00654526","1"],["76187","0","0"]]}
{"instId":"BTC-USDT","action":"update","ts":"1776816015930","asks":[],"bids":[["76355.1","0.00659155","2"],["76352.4","0","0"],["76187","0.00011911","5"]]}
{"instId":"BTC-USDT","action":"update","ts":"1776816015940","asks":[["76374.2","0.14393884","1"],["76376.8","0.00654526","1"],["76470.3","0","0"]],"bids":[]}
{"instId":"BTC-USDT","action":"update","ts":"1776816015950","asks":[["76380.4","0.15910419","2"]],"bids":[["76334.4","0.15912099","3"]]}
{"instId":"BTC-USDT","action":"update","ts":"1776816015960","asks":[],"bids":[["76352.3","0.000015","1"]]}
{"instId":"BTC-USDT","action":"update","ts":"1776816015970","asks":[],"bids":[["76354.5","0.01375319","1"],["76187","0","0"]]}
{"instId":"BTC-USDT","action":"update","ts":"1776816015980","asks":[["76380.4","0.21213892","3"]],"bids":[["76349.7","0.10245537","2"],["76347.6","0.47152341","2"]]}
{"instId":"BTC-USDT","action":"update","ts":"1776816015990","asks":[["76374.2","0.15048411","2"],["76376.8","0","0"],["76470.3","0.00003942","1"]],"bids":[["76355.1","0.00004629","1"],["76354.6","0.00654527","1"],["76351.2","0.06251142","3"],["76187.5","0","0"]]}
{"instId":"BTC-USDT","action":"update","ts":"1776816016000","asks":[["76365.1","0.762046","14"]],"bids":[["76349.6","0.33091144","2"]]}
{"instId":"BTC-USDT","action":"update","ts":"1776816016010","asks":[["76379.8","0","0"],["76380.2","0.32728803","1"]],"bids":[["76349","0.32728803","1"],["76347.5","0.00004629","1"],["76187.7","0","0"]]}
{"instId":"BTC-USDT","action":"update","ts":"1776816016040","asks":[["76374.2","0.14393884","1"],["76376.8","0.00654536","1"],["76381.9","0","0"],["76382.6","0.00656886","2"]],"bids":[["76355.1","0.00659165","2"],["76354.6","0","0"],["76349.5","0.32752539","6"],["76349","0","0"],["76347.5","0.00659206","2"],["76346.2","0.00001456","1"],["76187.7","0.47454308","2"],["76187.5","0.00032499","3"]]}
{"instId":"BTC-USDT","action":"update","ts":"1776816016090","asks":[["76382","0.09032874","2"],["76382.6","0.00002309","1"]],"bids":[]}
{"instId":"BTC-USDT","action":"update","ts":"1776816016160","asks":[["76382","0.08378297","1"],["76382.6","0.00656885","2"]],"bids":[]}
{"instId":"BTC-USDT","action":"update","ts":"1776816016190","asks":[["76382","0.09032873","2"],["76382.6","0.00002309","1"]],"bids":[["76349.7","0.0507788","1"]]}
{"instId":"BTC-USDT","action":"update","ts":"1776816016200","asks":[["76395.7","0","0"],["76470.5","0.00927944","19"]],"bids":[["76334.4","0.21079756","4"]]}
{"instId":"BTC-USDT","action":"update","ts":"1776816016240","asks":[["76380.4","0.26517365","4"]],"bids":[["76317.5","0.28351031","2"],["76317.3","0","0"],["76187","0.00011911","5"]]}
{"instId":"BTC-USDT","action":"update","ts":"1776816016290","asks":[["76382","0.08378297","1"],["76382.6","0.00656886","2"]],"bids":[["76355.3","0.00654512","1"],["76355.1","0.00004629","1"],["76347.7","0.00654577","1"],["76347.5","0.00004629","1"],["76187.5","0","0"],["76187","0","0"]]}
{"instId":"BTC-USDT","action":"update","ts":"1776816016300","asks":[["76365.1","0.68732482","13"]],"bids":[["76347.7","0","0"],["76347.5","0.00659208","2"],["76187.5","0.00032499","3"]]}
{"instId":"BTC-USDT","action":"update","ts":"1776816016310","asks":[["76380.2","0","0"],["76380.3","0.61786094","2"],["76470.6","0.01580142","1"]],"bids":[["76365","0.56519203","10"]]}
{"instId":"BTC-USDT","action":"update","ts":"1776816016340","asks":[],"bids":[["76349.7","0","0"],["76287.7","0.00001316","1"],["76187","0.00011911","5"]]}
{"instId":"BTC-USDT","action":"update","ts":"1776816016350","asks":[["76382","0.09032876","2"],["76382.6","0.00002309","1"]],"bids":[["76355.3","0","0"],["76355.1","0.00659144","2"],["76351.2","0.03660734","2"],["76186.4","0.00022771","1"]]}
{"instId":"BTC-USDT","action":"update","ts":"1776816016360","asks":[],"bids":[["76334.4","0.26157636","5"]]}
{"instId":"BTC-USDT","action":"update","ts":"1776816016490","asks":[["76382","0.08378297","1"],["76382.6","0.00656886","2"]],"bids":[]}
{"instId":"BTC-USDT","action":"update","ts":"1776816016570","asks":[["76365.1","0.68720698","13"]],"bids":[]}
{"instId":"BTC-USDT","action":"update","ts":"1776816016580","asks":[["76380.3","0.29057187","1"],["76381.6","0.32728793","1"],["76470.6","0","0"]],"bids":[["76349.7","0.32728793","1"],["76349.5","0.00023744","5"],["76186.4","0","0"]]}
{"instId":"BTC-USDT","action":"update","ts":"1776816016590","asks":[],"bids":[["76355.3","0.00654513","1"],["76355.1","0.00004629","1"],["76351.2","0.12962394","3"],["76187","0","0"]]}
{"instId":"BTC-USDT","action":"update","ts":"1776816016600","asks":[["76365.1","0.68692416","13"]],"bids":[]}
{"instId":"BTC-USDT","action":"update","ts":"1776816016610","asks":[["76365.1","0.68681156","13"]],"bids":[]}
{"instId":"BTC-USDT","action":"update","ts":"1776816016680","asks":[["76380.4","0.21213892","3"]],"bids":[["76334.4","0.15912099","3"]]}
{"instId":"BTC-USDT","action":"update","ts":"1776816016700","asks":[["76380.4","0.26517365","4"]],"bids":[["76349.7","0.37806673","2"],["76334.4","0.21079756","4"]]}
{"instId":"BTC-USDT","action":"update","ts":"1776816016710","asks":[["76365.1","0.68605863","12"],["76371","0.00075293","1"],["76470.5","0","0"]],"bids":[]}
{"instId":"BTC-USDT","action":"update","ts":"1776816016720","asks":[],"bids":[["76349.7","0.32728793","1"]]}
{"instId":"BTC-USDT","action":"update","ts":"1776816016740","asks":[["76365.1","0.68681156","13"],["76371","0","0"],["76470.5","0.00927944","19"]],"bids":[]}
{"instId":"BTC-USDT","action":"update","ts":"1776816016770","asks":[["76365.1","0.68605863","12"],["76371","0.00075293","1"],["76470.5","0","0"]],"bids":[]}
{"instId":"BTC-USDT","action":"update","ts":"1776816016780","asks":[],"bids":[["76334.4","0.26157636","5"]]}
{"instId":"BTC-USDT","action":"update","ts":"1776816016790","asks":[["76365.1","0.68681156","13"],["76371","0.16","1"]],"bids":[]}
{"instId":"BTC-USDT","action":"update","ts":"1776816016960","asks":[["76380.4","0.21213892","3"]],"bids":[["76334.4","0.21079756","4"]]}
{"instId":"BTC-USDT","action":"update","ts":"1776816016980","asks":[["76395.7","0.05303473","1"],["76470.3","0","0"]],"bids":[["76349.7","0.37806673","2"]]}
{"instId":"BTC-USDT","action":"update","ts":"1776816017020","asks":[["76395.7","0","0"],["76470.3","0.00003942","1"]],"bids":[]}
{"instId":"BTC-USDT","action":"update","ts":"1776816017030","asks":[],"bids":[["76334.4","0.15912099","3"]]}
{"instId":"BTC-USDT","action":"update","ts":"1776816017040","asks":[],"bids":[["76349.7","0.4297433","3"]]}
{"instId":"BTC-USDT","action":"update","ts":"1776816017070","asks":[["76371","0","0"],["76395.7","0.05303473","1"]],"bids":[["76349.7","0.37806673","2"]]}
{"instId":"BTC-USDT","action":"update","ts":"1776816017080","asks":[["76365.1","0.75190156","15"]],"bids":[["76365","0.09864811","3"],["76350.7","0","0"],["76334.4","0.21079756","4"],["76187","0.00011911","5"]]}
{"instId":"BTC-USDT","action":"update","ts":"1776816017090","asks":[["76371","0.10871478","1"],["76372.4","0.00654513","1"],["76376.8","0","0"],["76377.2","0.08378297","1"],["76377.6","0.34037779","2"],["76379.8","0.00654584","1"],["76380.5","0.1305","1"],["76381.6","0","0"],["76382.5","0.01614584","1"],["76382.6","0.00002309","1"],["76393.2","0","0"],["76395.7","0","0"],["76470.2","0","0"],["76470.3","0","0"]],"bids":[["76365","0.09603007","2"],["76360.1","0.17185286","1"],["76360","0.11583462","2"],["76358.6","0","0"],["76355.3","0","0"],["76354.5","0","0"],["76351.3","0.00659142","2"],["76349.7","0","0"],["76349.4","0.00261842","1"],["76347.6","0.00001033","1"],["76347.5","0.00004629","1"],["76345.9","0.32729814","2"],["76345.4","0","0"],["76343.2","0.00654584","1"],["76342.1","0","0"],["76186.4","0.00022771","1"],["76186","0.00170529","1"],["76185.3","0.00002512","1"],["76184.8","0.01614584","1"],["76184.2","3.72","1"]]}
{"instId":"BTC-USDT","action":"update","ts":"1776816017100","asks":[["76370.9","0.00654528","1"],["76372.4","0","0"],["76376.8","0.32729035","1"],["76377.6","0.01309","1"],["76379.2","0.00654598","1"],["76379.8","0","0"],["76380.4","0.26517365","4"],["76407.1","0.00130877","1"],["76407.4","0","0"],["76470","0","0"]],"bids":[["76360.1","0.07624398","1"],["76351.2","0.00001035","1"],["76349.6","0.21804172","1"],["76349.3","0.01219641","1"],["76346","0.11701634","1"],["76345.9","0.00001035","1"],["76345.8","0.92253943","3"],["76343.1","0","0"],["76342.2","0","0"],["76336.6","0","0"],["76331.3","0.11469999","1"],["76200","1.01905163","52"]]}
{"instId":"BTC-USDT","action":"update","ts":"1776816017110","asks":[["76365.1","0.75177062","15"],["76370.9","0.13068182","2"]],"bids":[["76351.4","0.00654527","1"],["76351.3","0.00004629","1"],["76345.8","0.07766814","1"],["76343.2","0.33384525","2"],["76341.9","0.47175056","6"],["76337.7","0","0"],["76240","0.08386417","2"]]}
{"instId":"BTC-USDT","action":"update","ts":"1776816017120","asks":[["76370.9","0.12413654","1"],["76372.4","0.00654515","1"],["76376.8","0","0"],["76377.6","0.34039155","2"],["76379.1","0.00654604","1"],["76379.2","0","0"]],"bids":[["76361.2","0.00004565","2"],["76357.2","0.01333744","6"],["76351.5","0.00655831","2"],["76351.4","0","0"],["76349.6","0.12116342","1"],["76346.1","0.33035155","2"],["76343.3","1.0122417","2"],["76343.2","0","0"],["76326.6","0.00023743","5"],["76200","0.01335597","51"],["76184.1","0.47151308","1"]]}
{"instId":"BTC-USDT","action":"update","ts":"1776816017130","asks":[["76372.4","0","0"],["76374.1","0.00654519","1"],["76377.6","0.01309","1"],["76379.1","0","0"],["76379.8","0.32730155","1"],["76379.9","0.12381828","3"]],"bids":[["76351.6","0.00654519","1"],["76351.5","0.00001316","1"],["76349.6","0.20337243","2"],["76347.5","0.32734789","2"],["76346.1","0.00305","1"],["76184.1","0","0"]]}
{"instId":"BTC-USDT","action":"update","ts":"1776816017140","asks":[],"bids":[["76351.7","0.00654535","1"],["76351.6","0","0"],["76345.8","0.36793863","2"]]}
{"instId":"BTC-USDT","action":"update","ts":"1776816017150","asks":[["76372.4","0.00654538","1"],["76374.1","0","0"]],"bids":[["76351.8","0.00654538","1"],["76351.7","0","0"],["76347.5","0.00004629","1"],["76346.1","0.3303511","2"],["76345.9","0.47152343","2"],["76334.4","0.26157636","5"]]}
{"instId":"BTC-USDT","action":"update","ts":"1776816017160","asks":[["76371.1","0.18144262","2"],["76372.4","0","0"],["76377.1","0.32730084","1"],["76379.8","0","0"],["76470","0.00007723","1"]],"bids":[["76351.9","0.00654542","1"],["76351.8","0","0"],["76349.6","0.33360869","1"]]}
{"instId":"BTC-USDT","action":"update","ts":"1776816017170","asks":[["76370.9","0.13068201","2"],["76371.1","0.1748972","1"]],"bids":[["76351.9","0","0"],["76349.7","0.00654547","1"]]}
{"instId":"BTC-USDT","action":"update","ts":"1776816017180","asks":[],"bids":[["76330.6","0.00039205","2"]]}
{"instId":"BTC-USDT","action":"update","ts":"1776816017210","asks":[],"bids":[["76362.5","0.00172256","1"],["76184.2","0","0"]]}
{"instId":"BTC-USDT","action":"update","ts":"1776816017220","asks":[["76376.8","0.32730584","1"],["76377.1","0","0"]],"bids":[["76346.1","0.00305","1"],["76343.4","0.32730584","1"],["76261.2","0.78071845","1"],["76185.3","0","0"],["76184.8","0","0"]]}
{"instId":"BTC-USDT","action":"update","ts":"1776816017230","asks":[],"bids":[["76345.9","0.79882926","3"],["76343.4","0","0"],["76185.3","0.00002512","1"]]}
{"instId":"BTC-USDT","action":"update","ts":"1776816017270","asks":[],"bids":[["76345.9","0.47152343","2"],["76343.4","0.32730583","1"],["76185.3","0","0"]]}
{"instId":"BTC-USDT","action":"update","ts":"1776816017290","asks":[["76378","0.00654613","1"],["76379.9","0.11727223","2"],["76470","0","0"]],"bids":[["76343.3","1.00569566","1"],["76343","0.00654613","1"],["76186","0","0"]]}
{"instId":"BTC-USDT","action":"update","ts":"1776816017320","asks":[["76407.7","0.00130876","1"],["76408.5","0.00001316","1"],["76469.7","0","0"]],"bids":[]}
{"instId":"BTC-USDT","action":"update","ts":"1776816017350","asks":[],"bids":[["76301.8","0","0"],["76186","0.00170529","1"]]}
{"instId":"BTC-USDT","action":"update","ts":"1776816017360","asks":[],"bids":[["76328.4","0.0000463","1"]]}
{"instId":"BTC-USDT","action":"update","ts":"1776816017370","asks":[["76365.1","0.74906","15"]],"bids":[]}
{"instId":"BTC-USDT","action":"update","ts":"1776816017380","asks":[["76362.6","0.42568494","7"],["76364.7","0.09623688","1"],["76364.8","0.284341","3"],["76364.9","0.95487827","14"],["76365","0.50523779","5"],["76365.1","0.99298394","15"],["76370.9","0.12413654","1"],["76372.4","0.00654571","1"],["76372.8","0.1305","1"],["76376.8","0","0"],["76377.7","1.33300299","2"],["76380.4","0","0"],["76405.9","0.04924214","1"],["76406.6","0.10756247","1"],["76406.7","0.1058","1"],["76407.5","0.20752612","2"],["76411.4","0","0"],["76416","0","0"],["76417","0","0"],["76421.4","0.08378297","1"],["76469","0","0"],["76469.2","0","0"],["76469.4","0","0"],["76469.6","0","0"]],"bids":[["76365","0","0"],["76364.8","0","0"],["76364.7","0","0"],["76360.1","0","0"],["76360","0.00001033","1"],["76358.5","0","0"],["76356.3","0","0"],["76356.2","0","0"],["76355.2","0","0"],["76348.9","0","0"],["76348.8","0.00001086","1"],["76347.4","0","0"],["76345.9","0.00001035","1"],["76344.2","0.00238869","1"],["76343.4","0","0"],["76343.3","0","0"],["76341.9","0.00023748","5"],["76337.8","0","0"],["76334.4","0.15686506","3"],["76334.2","0.0002805","9"],["76327.7","1.00569566","1"],["76327.6","0","0"],["76324.7","0.47151308","1"],["76322.6","0","0"],["76320.4","1.47720874","2"],["76320.2","0","0"],["76317.9","0.0032721","2"],["76317.4","0.08379452","2"],["76313.4","1.47720874","2"],["76313.2","0","0"],["76313.1","0.00004629","1"],["76308.3","0","0"],["76308","0.01971068","2"],["76307","0.47151308","1"],["76306.5","0","0"],["76211.2","0","0"],["76185.3","0.00002512","1"],["76184.8","0.01614584","1"],["76184.2","3.72","1"],["76184.1","0.47151308","1"],["76183.9","0.00003806","1"],["76183.7","0.00001319","1"],["76183.4","0.00005866","1"],["76183.3","0.00009283","1"],["76182.7","0.00002401","2"],["76182.2","0.00875","1"],["76181.6","0.00073364","2"],["76180","0.0000812","1"],["76179.9","0.47151308","1"],["76179.3","0.00040006","1"]]}
{"instId":"BTC-USDT","action":"update","ts":"1776816017390","asks":[["76361.1","0.0949","4"],["76361.2","0.172326","2"],["76361.3","0.287536","3"],["76361.9","1.04434009","14"],["76362.5","0.63979964","1"],["76362.6","0.74918146","8"],["76364.6","0.036","1"],["76364.7","0","0"],["76364.8","0.09563","1"],["76364.9","0.29996599","3"],["76365","0","0"],["76365.1","0.09824","3"],["76365.8","0.00649862","1"],["76367","0.01285421","2"],["76367.1","0","0"],["76368.2","0.00001316","1"],["76370.6","0.05889073","1"],["76370.9","0","0"],["76371","1.00569566","1"],["76371.1","0.25868017","2"],["76371.5","0","0"],["76372.4","0","0"],["76372.7","0.32730732","1"],["76376.8","0.00654641","1"],["76377.1","0.06550532","1"],["76377.3","0","0"],["76377.7","1.00569566","1"],["76378","0","0"],["76379.9","0.00001085","1"],["76386.4","0.01570195","1"],["76394.4","0","0"],["76401.8","0.05239485","2"],["76406.6","0","0"],["76410.8","0","0"],["76468.7","0","0"],["76468.8","0","0"],["76468.9","0","0"]],"bids":[["76362.5","0","0"],["76361.8","0","0"],["76361.2","0","0"],["76361.1","0","0"],["76361","0","0"],["76360.8","0.00166905","1"],["76359.9","0","0"],["76349.7","0","0"],["76349.6","0.04507695","1"],["76349.4","0","0"],["76349.3","0","0"],["76349.2","0","0"],["76346.2","0.00656028","2"],["76345.8","0.07766814","1"],["76344.2","0","0"],["76343","0","0"],["76342","0.00656321","2"],["76338.6","0.00261879","1"],["76337.9","0","0"],["76335.8","0.01584952","1"],["76334.4","0.0000168","1"],["76334.3","0","0"],["76334.1","0.10745499","1"],["76331.2","0.1047113","2"],["76330.9","0","0"],["76327.8","1.56099171","3"],["76327.7","0","0"],["76326.2","0","0"],["76324.7","0","0"],["76323.3","0.00523758","1"],["76323","0.47152463","2"],["76321.8","0.04185773","3"],["76320.5","1.00569566","1"],["76320.4","0","0"],["76320.1","0.024","1"],["76317.6","0.47151308","1"],["76317.5","0.2822","1"],["76316.1","0","0"],["76313.5","0.12525729","1"],["76311.9","0.00131041","1"],["76310.9","0.02508","1"],["76310.8","0","0"],["76309.1","0.00131045","1"],["76308","0.02756705","3"],["76306.9","0","0"],["76305.7","0.04924399","1"],["76303.6","1.00569566","1"],["76300.4","0.12821137","1"],["76298.5","0","0"],["76296.4","0.13182471","1"],["76292.7","0.48198824","2"],["76289.5","1.46281308","2"],["76277.5","0.01309395","1"],["76260.9","0.00001316","1"],["76231","0.08378297","1"],["76219.9","1.00572189","2"],["76219.8","0","0"],["76211.2","1.00569566","1"],["76200","1.01905163","52"],["76184","0.1305","1"],["76178.9","0.0008637","1"],["76177.9","0.00004571","1"],["76177.8","0.00105547","4"],["76175.4","0.00003868","3"]]}
{"instId":"BTC-USDT","action":"update","ts":"1776816017400","asks":[["76360.7","0.76936587","13"],["76360.8","1.13626362","1"],["76360.9","0.28249658","6"],["76361","0.00131","1"],["76361.1","0","0"],["76361.2","0","0"],["76361.3","0","0"],["76361.9","0.036","1"],["76362.5","0","0"],["76362.6","0.50751308","2"],["76363.5","0.05889073","1"],["76364.9","0","0"],["76366.9","0.00654624","1"],["76367","0.00630842","1"],["76370.5","0.12792519","1"],["76370.6","0","0"],["76372.6","0.32733275","1"],["76372.7","0","0"],["76374.1","0.00654681","1"],["76376.8","0.10630821","1"],["76378.8","0.15916034","3"],["76384.4","0.11994442","2"],["76394.4","0.14404966","1"],["76400.7","0.01970896","1"],["76406.7","0","0"],["76407.5","0.18783","1"],["76468.4","0","0"],["76468.5","0","0"],["76468.6","0","0"]],"bids":[["76360.8","0","0"],["76360.6","0","0"],["76360.5","0.00161476","1"],["76347.4","0.00261849","1"],["76346.2","0.0065608","2"],["76345.7","0.00023747","5"],["76342.9","0.00001086","1"],["76342","0.0000168","1"],["76340.3","0.01219784","1"],["76340.2","0.1654953","2"],["76339.4","0.00654681","1"],["76338.6","0","0"],["76338.2","0.0563979","2"],["76335.8","0","0"],["76334.2","0.47179358","10"],["76332.1","0.04123698","2"],["76331.2","0","0"],["76331","0.47151308","1"],["76324.6","0.09212346","3"],["76323.3","0","0"],["76320.3","0","0"],["76319.2","0.32596191","1"],["76316.8","0.12511071","2"],["76308","0.11994427","2"],["76303.7","0.12549756","6"],["76301.2","0.01970896","1"],["76296.4","0","0"],["76176.3","0.1305","1"],["76175.1","0.47151308","1"]]}
{"instId":"BTC-USDT","action":"update","ts":"1776816017410","asks":[["76357.3","1.78206239","21"],["76360.6","0.66488391","5"],["76360.7","0","0"],["76360.8","0","0"],["76360.9","0.036","1"],["76361","0","0"],["76362.5","0.20836309","1"],["76366.9","0","0"],["76370.4","0.32734189","1"],["76370.5","0","0"],["76370.9","0.00654643","1"],["76371.3","0.01614584","1"],["76372.6","0","0"],["76376.3","0.12554757","6"],["76385.2","0","0"],["76390.4","0.000015","1"],["76392.9","0.19848323","2"],["76401.3","0","0"],["76401.8","0.00001316","1"],["76405.2","0.12652723","2"],["76468.4","0.00002034","1"],["76468.5","0.00038944","1"]],"bids":[["76360.5","0","0"],["76360","0","0"],["76358.2","0","0"],["76354.9","0","0"],["76350","0.02620155","2"],["76349.7","0.00654643","1"],["76346.2","0.00001456","1"],["76345.8","0","0"],["76340.9","0","0"],["76340.3","0.13213501","2"],["76340.2","0.16550244","2"],["76340","0.06558652","2"],["76334.2","0.0002805","9"],["76331","0","0"],["76327.9","0.47151308","1"],["76327.8","0","0"],["76324.7","0.47151308","1"],["76323","0.00001155","1"],["76321.8","0.03601033","2"],["76320.6","0.12260782","1"],["76319.3","0.47191314","2"],["76317.6","0","0"],["76311.9","0","0"],["76310.7","0","0"],["76309.1","0","0"],["76308.2","0","0"],["76303.7","0.77638162","7"],["76303.5","0.00001085","1"],["76302.8","0.00131056","1"],["76301.8","0.00323307","1"],["76300.7","0.0013106","1"],["76300.4","0","0"],["76298.8","0.00985685","1"],["76257.5","0","0"],["76217.5","0","0"],["76188.7","0.00047516","7"],["76175","0.00029601","2"],["76173.9","0.00399999","1"],["76173.7","0.00070045","3"],["76173.6","0.00002308","1"],["76173.2","0.00001006","1"],["76173","0.00001059","1"],["76171.4","0.00683413","1"],["76171.1","0.00001024","1"]]}
{"instId":"BTC-USDT","action":"update","ts":"1776816017420","asks":[["76357.3","1.80214662","24"],["76360.5","0.20921385","1"],["76360.6","0.20892531","2"],["76365","0.03510552","1"],["76365.7","0.00654662","1"],["76367.6","0.00001501","1"],["76370.9","0.59338731","2"],["76371.1","0.08378297","1"],["76372.7","0.00654697","1"],["76374.1","0","0"],["76449.9","0.00005654","1"],["76456.7","0.00135308","2"],["76460.4","0","0"],["76468.3","0","0"],["76468.4","0","0"],["76468.5","0","0"]],"bids":[["76357.2","0.01751754","8"],["76350","0.00001155","1"],["76349.7","0","0"],["76346.1","0","0"],["76342.8","0.00654641","1"],["76340.3","0.11993717","1"],["76339.4","0","0"],["76338.3","0.00654697","1"],["76335.4","0","0"],["76333.3","0.00305","1"],["76332.9","0","0"],["76331.4","0.47152624","2"],["76331.1","1.00569566","1"],["76327.6","0.5","1"],["76327.1","0.04600469","1"],["76319.2","0","0"],["76312.6","0.00305","1"],["76306.8","0","0"]]}
{"instId":"BTC-USDT","action":"update","ts":"1776816017430","asks":[["76360.5","0.07311021","1"],["76364.7","0.00654651","1"],["76365.1","0.09843138","4"],["76365.7","0","0"],["76370.8","0.00654724","1"],["76372.7","0","0"],["76390.4","0.1100918","2"],["76402.8","0.08644459","2"]],"bids":[["76357.2","0.01489898","7"],["76347.4","0","0"],["76342.9","0.00655737","2"],["76342.8","0","0"],["76340.2","0.0429","1"],["76339.1","0.01219804","1"],["76338.3","0","0"],["76338.2","0.0360318","2"],["76337.8","0.00305","1"],["76335.2","0.00916614","2"],["76333.3","0","0"],["76332.1","0.036","1"],["76324.3","0","0"],["76324.1","0.00305","1"],["76319.9","0.0052378","1"],["76316.8","0.11725524","1"],["76312.6","0","0"],["76304.6","0.0078567","1"],["76296.4","0.11994243","1"],["76171.1","0","0"]]}
{"instId":"BTC-USDT","action":"update","ts":"1776816017440","asks":[["76360.4","0.0065468","1"],["76364.7","0","0"],["76370.3","0.00654721","1"],["76370.8","0","0"],["76377.5","0.012","1"],["76377.6","0","0"],["76380.3","0.30366187","2"],["76386.4","0","0"],["76387.3","0","0"],["76393","0","0"],["76401","0.29343","1"],["76434","0.01599968","2"],["76435.9","1.00867674","2"],["76438.4","0.13754939","4"],["76438.7","0.00002069","1"],["76440.3","0","0"],["76441.3","0","0"],["76468.3","0.01147749","1"],["76468.4","0.00002034","1"],["76468.5","0.00038944","1"]],"bids":[["76357.2","0.00023744","5"],["76356.6","0.00156124","1"],["76351.5","0.01311316","2"],["76343.5","0.00261862","1"],["76342.9","0.00001086","1"],["76340.4","0.0065468","1"],["76335.2","0","0"],["76333.3","0.00654721","1"],["76333","0.01536286","1"],["76332.7","0.05889073","1"],["76331.5","0.47530571","1"],["76328.4","0.00007494","2"],["76328.2","0.00523724","1"],["76324.8","0.11994243","1"],["76320.6","0","0"],["76319.9","0","0"],["76315.2","0.00785562","1"],["76314.6","0.00001316","1"],["76312.4","0.00325215","1"],["76311.4","0","0"],["76309.4","0.00234641","2"],["76304.6","0","0"],["76296.7","0.11994243","1"],["76296.4","0","0"],["76173.9","0","0"],["76173.7","0","0"],["76173.6","0","0"],["76173.2","0","0"],["76173","0","0"],["76171.4","0","0"]]}
{"instId":"BTC-USDT","action":"update","ts":"1776816017450","asks":[["76360.4","0","0"],["76362.6","0.57069308","3"],["76363.4","0.00654685","1"],["76365.1","0.03620138","3"],["76369.9","0.01309","1"],["76375.2","0.15912501","3"],["76380.3","0.29057187","1"],["76383","0","0"],["76390.6","0.29343","1"],["76401","0","0"],["76435.2","0.00093674","1"],["76435.9","1.00774","1"],["76437.2","0.00002069","1"],["76438.7","0","0"],["76468.5","0","0"]],"bids":[["76351.5","0.00001316","1"],["76347.7","0.0131","1"],["76342.8","0.00654685","1"],["76342.7","0","0"],["76340.4","0","0"],["76339.8","0","0"],["76333","0","0"],["76330.6","0.0000168","1"],["76330.2","0.30279","1"],["76314.8","0.0663713","1"],["76312.4","0","0"],["76310.9","0.02833215","2"],["76309.4","0.00001033","1"],["76308.7","0.00233609","1"]]}
{"instId":"BTC-USDT","action":"update","ts":"1776816017460","asks":[["76360.4","0.00654689","1"],["76363.4","0","0"],["76365","0.01463742","1"],["76430.8","0.00093674","1"],["76435.2","0","0"]],"bids":[["76356.6","0","0"],["76356.4","0.00156094","1"],["76342.8","0","0"],["76341.8","0.11092641","1"],["76340.4","0.00654689","1"],["76334.2","0.32763983","10"],["76331.3","0","0"],["76322.9","0.20758257","3"],["76314.8","0","0"],["76310.9","0.02508","1"],["76310","0.00325215","1"],["76308.7","0","0"],["76304.4","0.00233608","1"],["76173.9","0.00399999","1"]]}
{"instId":"BTC-USDT","action":"update","ts":"1776816017470","asks":[["76357.3","1.80201566","24"],["76365","0.27981107","5"],["76365.1","0.03601","2"],["76367","0.11564417","2"],["76434.1","0.00002069","1"],["76437.2","0","0"]],"bids":[["76339.1","0","0"],["76326.6","0.26179699","9"],["76321.8","0.13601033","3"],["76310","0","0"],["76307.1","0.00325214","1"],["76173.7","0.00070045","3"]]}
{"instId":"BTC-USDT","action":"update","ts":"1776816017480","asks":[["76364.9","0.12026162","1"],["76365","0.26517365","4"],["76376.3","0.12527321","1"],["76379.6","0.00002066","1"],["76385.8","0","0"]],"bids":[["76336.7","0.01219842","1"],["76318.4","0","0"],["76312.3","0","0"],["76284.7","1.40806308","2"],["76173.6","0.00002308","1"]]}
{"instId":"BTC-USDT","action":"update","ts":"1776816017490","asks":[["76378.8","0.15915","2"],["76384.1","0","0"],["76385.1","1.00569566","1"],["76401.3","0.10840455","1"],["76405.2","0.00001316","1"],["76425.4","1.00662207","4"],["76428.2","0","0"],["76468.5","0.00038944","1"]],"bids":[["76340.2","0","0"],["76339.7","0","0"],["76314.5","0.55138816","2"],["76301.8","0","0"],["76300.1","0.00323339","1"],["76299.7","0.19944577","1"],["76183.9","0.01027098","2"],["76173.2","0.00001006","1"]]}
{"instId":"BTC-USDT","action":"update","ts":"1776816017500","asks":[["76357.4","0.05889073","1"],["76360.4","0","0"],["76361.8","0.00654683","1"],["76363.5","0","0"],["76365","0.39567365","5"],["76378.8","0.07949","1"],["76381.1","0","0"],["76382.6","0","0"],["76383.8","0","0"],["76394.2","0.00988132","1"],["76402.8","0.03896266","1"],["76417.4","1.00844082","2"],["76423.9","0.00003959","1"],["76425.4","1.00658248","3"],["76468.6","0.00001531","1"]],"bids":[["76356.4","0","0"],["76356.3","0.00156028","1"],["76341.8","0.05747964","1"],["76340.5","0.00654683","1"],["76340.4","0","0"],["76340","0.0000812","1"],["76300.1","0","0"],["76297.9","0.00323339","1"],["76295.3","0","0"],["76183.9","0.00003806","1"],["76173","0.00001059","1"]]}
{"instId":"BTC-USDT","action":"update","ts":"1776816017510","asks":[["76357.3","1.80856268","25"],["76361.8","0.32737554","1"],["76364.5","0.00654748","1"],["76364.7","1.08947863","2"],["76370.3","0","0"],["76370.4","0","0"],["76379.6","0","0"],["76421.3","0.00003959","1"],["76423.9","0","0"],["76454","0.00131075","2"],["76463.7","0","0"],["76464.1","0.00006549","2"],["76468.7","0.00109488","1"],["76468.8","0.01162259","2"]],"bids":[["76356.3","0","0"],["76354.4","0.00005292","1"],["76352.3","0","0"],["76350.5","0.00156024","1"],["76349.6","0","0"],["76346.1","0.03493247","1"],["76343.5","0","0"],["76341.8","0","0"],["76340.5","0","0"],["76337.4","0.00261883","1"],["76335.2","0.00654702","1"],["76334.2","0.0002805","9"],["76333.3","0","0"],["76331.4","0.00001316","1"],["76330.3","0.32737554","1"],["76328.7","0.00654748","1"],["76328.2","0","0"],["76327.1","0","0"],["76322.9","0.06352291","2"],["76322.7","0","0"],["76322.1","0.00523766","1"],["76321.8","0.03601033","2"],["76319.1","0.11222826","2"],["76318","0.05238533","1"],["76316.3","0","0"],["76315.2","0","0"],["76304.6","0.0078567","1"],["76297.9","0","0"],["76294.1","0.00323339","1"],["76292.6","0","0"],["76291","0","0"],["76285","0.00013109","1"],["76284","0","0"],["76276.4","0.00054216","1"],["76221","0.08378297","1"],["76171.4","0.00683413","1"],["76171.1","0.00001024","1"]]}
{"instId":"BTC-USDT","action":"update","ts":"1776816017520","asks":[["76361.8","0","0"],["76362.5","0.51016842","2"],["76364.5","0.3339221","2"],["76468.9","0.00002508","2"]],"bids":[["76350.5","0","0"],["76350.2","0.00156008","1"],["76340.4","0.03595872","1"],["76331.6","0.32737462","1"],["76331.5","0","0"],["76330.3","0","0"],["76323.9","0.01614584","1"],["76320.6","0.11364593","1"],["76313.5","0","0"],["76308.7","0.13060398","1"],["76303.7","0.65112154","6"],["76300.4","0.11994243","1"],["76171.4","0","0"],["76171.1","0","0"]]}
{"instId":"BTC-USDT","action":"update","ts":"1776816017530","asks":[["76360.4","0.08378297","1"],["76363","0.01614584","1"],["76468.8","0","0"],["76468.9","0","0"]],"bids":[["76334.3","0.06550532","1"],["76331.7","0.39793042","1"],["76317.4","0.00001155","1"],["76302.8","0","0"],["76300.7","0","0"],["76299.7","0","0"],["76294.5","0.00131071","1"],["76290.2","0.00135708","2"],["76211.3","0.08378297","1"],["76173","0","0"]]}
{"instId":"BTC-USDT","action":"update","ts":"1776816017540","asks":[["76357.3","1.80871644","26"],["76360.4","0.41115547","2"],["76361.8","0.00654743","1"],["76364.5","0","0"]],"bids":[["76335.2","0","0"],["76332.8","0.00654701","1"],["76331.6","0","0"],["76328.7","0","0"],["76326.7","0.3273725","1"],["76326.5","0.00654743","1"],["76316.5","0.10001086","2"]]}
{"instId":"BTC-USDT","action":"update","ts":"1776816017550","asks":[["76360.3","0.19584011","1"],["76360.5","0","0"],["76360.8","0.00654747","1"],["76361.8","0","0"],["76363.9","0.01309","1"],["76369.9","0","0"],["76372.5","0.01293856","2"],["76378.8","0","0"],["76468.8","0.01162259","2"]],"bids":[["76347.7","0","0"],["76341.1","0.0131","1"],["76337.8","0","0"],["76335.1","0","0"],["76330.2","0","0"],["76326.5","0","0"],["76326.3","0.01566114","1"],["76325.2","0.00305","1"],["76324.9","0.00654747","1"],["76324.1","0","0"],["76323.8","0.30279","1"],["76321.7","0.003065","2"],["76304.6","0.0109067","2"],["76299.7","0.19329274","1"]]}
{"instId":"BTC-USDT","action":"update","ts":"1776816017560","asks":[["76360.4","0.08378297","1"],["76360.8","0","0"],["76361.8","0.32737229","1"],["76362.9","0.00654761","1"],["76377","0.01574748","1"],["76468.7","0","0"],["76468.8","0","0"]],"bids":[["76330.3","0.32737229","1"],["76329.7","0.00305","1"],["76328.4","0.0000463","1"],["76328","0.0065711","3"],["76326.7","0","0"],["76325.2","0","0"],["76324.9","0","0"],["76299.7","0","0"],["76294.1","0","0"],["76173","0.00001059","1"],["76171.4","0.00683413","1"],["76171.1","0.00001024","1"]]}
{"instId":"BTC-USDT","action":"update","ts":"1776816017570","asks":[["76357.3","1.80869025","26"],["76360.3","0.09811942","1"],["76376.3","0.12589497","4"],["76382","0.08403233","2"]],"bids":[["76316","0.00305","1"],["76304.6","0.0078567","1"],["76297.7","0.19397952","1"],["76285.9","0","0"],["76278.8","0","0"],["76274.8","0.09045355","2"],["76193.9","0.01496","1"],["76171.1","0","0"]]}
{"instId":"BTC-USDT","action":"update","ts":"1776816017580","asks":[["76376.3","0.12622294","6"],["76379","0.00011081","1"],["76382","0.08416751","3"],["76384.1","0.00011763","1"],["76468.5","0","0"],["76468.6","0","0"]],"bids":[["76334.4","0.00656409","2"],["76332.8","0","0"],["76297.7","0","0"],["76171.1","0.00001024","1"],["76170.8","0.00003094","3"]]}
{"instId":"BTC-USDT","action":"update","ts":"1776816017590","asks":[["76378.8","0.00003102","1"],["76381.1","0.00003258","1"],["76468.3","0","0"],["76468.4","0","0"]],"bids":[["76299.3","0.19499552","2"]]}
{"instId":"BTC-USDT","action":"update","ts":"1776816017600","asks":[["76361.8","0.32738751","1"],["76382.6","0.00003464","1"],["76468.2","0","0"]],"bids":[["76330.4","0.80452591","7"],["76330.3","0","0"],["76329.8","0","0"],["76299.3","0.00040006","1"],["76187.7","0.47151308","1"],["76170.2","0.00001385","1"],["76168.9","0.000015","1"]]}
{"instId":"BTC-USDT","action":"update","ts":"1776816017610","asks":[["76357.3","1.80866406","26"],["76365","0.28960419","4"],["76365.1","0.036","1"],["76379.6","0.00003099","1"],["76468","0","0"]],"bids":[["76299.3","0.19396939","2"],["76285","0","0"],["76281.9","0.00013109","1"],["76276.4","0","0"],["76273.3","0.33292919","2"],["76237.9","2.06119551","3"],["76168.4","0.00011049","4"]]}
{"instId":"BTC-USDT","action":"update","ts":"1776816017620","asks":[],"bids":[["76331.2","0.47151308","1"],["76299.3","0.00040006","1"],["76168.4","0","0"]]}
{"instId":"BTC-USDT","action":"update","ts":"1776816017630","asks":[["76372.6","0.10606946","1"],["76467.9","0","0"]],"bids":[["76300.2","0.20245794","1"],["76168.9","0","0"]]}
{"instId":"BTC-USDT","action":"update","ts":"1776816017640","asks":[["76362.9","0","0"],["76364.5","0.00654772","1"],["76372.7","0.23042658","1"],["76374.2","0","0"]],"bids":[["76328.7","0.00654772","1"],["76328","0.00002349","2"],["76300.2","0","0"]]}
{"instId":"BTC-USDT","action":"update","ts":"1776816017650","asks":[],"bids":[["76300.2","0.20301917","1"],["76294.6","0.0032337","1"],["76274.8","0.08378297","1"],["76249.1","0.00652277","1"],["76170.8","0","0"],["76170.2","0","0"]]}
{"instId":"BTC-USDT","action":"update","ts":"1776816017660","asks":[],"bids":[["76300.2","0","0"],["76170.8","0.00003094","3"]]}
{"instId":"BTC-USDT","action":"update","ts":"1776816017670","asks":[["76382","0.08378297","1"]],"bids":[["76337.5","0.0065472","1"],["76334.4","0.0000168","1"],["76300.2","0.20070516","1"],["76171.1","0","0"],["76170.8","0","0"]]}
{"instId":"BTC-USDT","action":"update","ts":"1776816017680","asks":[["76361.8","0","0"],["76364.5","0.33393248","2"],["76467.9","0.00001035","1"]],"bids":[["76331.8","0.32738476","1"],["76330.4","0.4771384","6"],["76300.2","0","0"]]}
{"instId":"BTC-USDT","action":"update","ts":"1776816017690","asks":[["76357.3","1.80816399","26"],["76364.9","0.05527384","1"],["76379","0","0"],["76468","1.00618616","2"]],"bids":[["76317.6","0.08378297","1"],["76300.2","0.19927491","1"],["76173","0","0"],["76171.4","0","0"]]}
{"instId":"BTC-USDT","action":"update","ts":"1776816017700","asks":[["76364.9","0.11611523","2"],["76365","0.18353473","2"],["76394.1","0.06429474","1"],["76399.3","0.00040006","1"],["76445.3","0.6596687","6"],["76449.1","0.657752","1"],["76467.9","0","0"],["76468","0","0"]],"bids":[["76322.9","0.0000168","1"],["76300.2","0","0"],["76299.5","0.659041","1"],["76295.5","0.660589","1"],["76173.2","0","0"]]}
{"instId":"BTC-USDT","action":"update","ts":"1776816017710","asks":[["76365","0.1305","1"]],"bids":[["76300.2","0.19666087","1"],["76173.6","0","0"]]}
{"instId":"BTC-USDT","action":"update","ts":"1776816017720","asks":[["76360.3","0.03575522","1"],["76364.9","0.05527384","1"],["76372.6","0.26517365","4"]],"bids":[["76300.2","0","0"],["76173.6","0.00002308","1"]]}
{"instId":"BTC-USDT","action":"update","ts":"1776816017730","asks":[["76360.3","0.09354819","2"],["76465.4","0.00574024","1"],["76467.8","0","0"]],"bids":[["76320.6","0.11367458","2"],["76300.2","0.19319633","1"],["76253","0.00666766","1"],["76227.4","0.00700104","1"],["76173.9","0","0"],["76173.7","0","0"],["76173.6","0","0"]]}
{"instId":"BTC-USDT","action":"update","ts":"1776816017760","asks":[["76376.3","0.12597358","5"]],"bids":[]}
{"instId":"BTC-USDT","action":"update","ts":"1776816017770","asks":[["76376.3","0.12579334","4"],["76389.9","0.1075566","1"],["76394.4","0","0"]],"bids":[]}
{"instId":"BTC-USDT","action":"update","ts":"1776816017780","asks":[["76392.9","0.05238286","1"]],"bids":[]}
{"instId":"BTC-USDT","action":"update","ts":"1776816017790","asks":[["76364.9","0.07910163","2"],["76376.3","0.12564561","3"],["76379","0.00003694","1"],["76467.3","0","0"]],"bids":[]}
{"instId":"BTC-USDT","action":"update","ts":"1776816017800","asks":[],"bids":[["76187.9","0.00304002","2"]]}
{"instId":"BTC-USDT","action":"update","ts":"1776816017810","asks":[["76357.3","1.80803303","26"]],"bids":[]}
{"instId":"BTC-USDT","action":"update","ts":"1776816017850","asks":[["76376.3","0.12589497","4"]],"bids":[]}
{"instId":"BTC-USDT","action":"update","ts":"1776816017860","asks":[["76376.3","0.12607521","5"]],"bids":[]}
{"instId":"BTC-USDT","action":"update","ts":"1776816017890","asks":[["76376.3","0.12622294","6"]],"bids":[]}
{"instId":"BTC-USDT","action":"update","ts":"1776816017930","asks":[["76377","0","0"],["76467.3","0.00050101","1"]],"bids":[["76303.4","0.49138925","2"],["76212.7","0.01413094","1"],["76175","0","0"]]}
{"instId":"BTC-USDT","action":"update","ts":"1776816017940","asks":[],"bids":[["76326.3","0","0"],["76175","0.00029601","2"]]}
{"instId":"BTC-USDT","action":"update","ts":"1776816017950","asks":[["76422.1","0","0"],["76467.8","0.47151308","1"]],"bids":[]}
{"instId":"BTC-USDT","action":"update","ts":"1776816017990","asks":[["76419.6","0.1","1"],["76467.8","0","0"]],"bids":[]}
{"instId":"BTC-USDT","action":"update","ts":"1776816018000","asks":[["76357.3","1.80148601","25"],["76360.2","0.00654718","1"],["76467.3","0","0"]],"bids":[["76338.2","0.04257898","3"],["76337.5","0","0"],["76320.6","0.11364593","1"],["76173.9","0.00399999","1"]]}
{"instId":"BTC-USDT","action":"update","ts":"1776816018010","asks":[["76364.5","0.32738476","1"],["76365.7","0.00654762","1"],["76467.2","0","0"]],"bids":[["76338.3","0.00654717","1"],["76338.2","0.0360318","2"],["76332.2","0.32742688","2"],["76331.8","0","0"],["76330.5","0.00654762","1"],["76328.7","0","0"]]}
{"instId":"BTC-USDT","action":"update","ts":"1776816018020","asks":[["76371.9","0.01607962","1"],["76467.1","0","0"]],"bids":[["76325.5","0.0159917","1"],["76173.9","0","0"]]}
{"instId":"BTC-USDT","action":"update","ts":"1776816018030","asks":[["76434.1","0","0"],["76467.1","0.00181702","1"]],"bids":[]}
{"instId":"BTC-USDT","action":"update","ts":"1776816018040","asks":[],"bids":[["76338.3","0","0"],["76338.2","0.0425789","3"],["76173.9","0.00399999","1"]]}
{"instId":"BTC-USDT","action":"update","ts":"1776816018050","asks":[["76365","0.13704759","2"],["76365.7","0","0"],["76467.2","0.00011781","1"]],"bids":[]}
{"instId":"BTC-USDT","action":"update","ts":"1776816018070","asks":[["76441.1","0.12016","3"]],"bids":[]}
{"instId":"BTC-USDT","action":"update","ts":"1776816018080","asks":[["76365","0.1305","1"],["76365.7","0.00654759","1"],["76467.2","0","0"]],"bids":[["76332.8","0.32737894","1"],["76332.2","0.00004629","1"],["76303.4","0.47151308","1"],["76212.7","0","0"]]}
{"instId":"BTC-USDT","action":"update","ts":"1776816018090","asks":[],"bids":[["76320.6","0.11367458","2"]]}
{"instId":"BTC-USDT","action":"update","ts":"1776816018100","asks":[["76390.3","0.00130906","1"],["76407.1","0","0"]],"bids":[]}
{"instId":"BTC-USDT","action":"update","ts":"1776816018140","asks":[["76381.7","0.00001316","1"]],"bids":[]}
{"instId":"BTC-USDT","action":"update","ts":"1776816018150","asks":[["76364.2","0.092063","1"],["76380.3","0.20979693","1"],["76467.1","0","0"]],"bids":[["76255","0","0"],["76173.7","0.00070045","3"]]}
{"instId":"BTC-USDT","action":"update","ts":"1776816018160","asks":[["76364.1","0.32737847","1"],["76364.5","0","0"]],"bids":[["76350.2","0","0"],["76173.6","0.00002308","1"]]}
{"instId":"BTC-USDT","action":"update","ts":"1776816018170","asks":[["76357.3","1.80084431","25"]],"bids":[]}
{"instId":"BTC-USDT","action":"update","ts":"1776816018180","asks":[["76419.6","0","0"],["76467.1","0.00181702","1"]],"bids":[]}
{"instId":"BTC-USDT","action":"update","ts":"1776816018190","asks":[["76371.9","0","0"],["76467.2","0.00011781","1"]],"bids":[]}
{"instId":"BTC-USDT","action":"update","ts":"1776816018200","asks":[["76357.3","1.79819886","25"]],"bids":[]}
{"instId":"BTC-USDT","action":"update","ts":"1776816018210","asks":[["76357.3","1.79783218","25"],["76414.3","0.1","1"],["76467.2","0","0"]],"bids":[["76350.8","0.00107124","1"],["76173.6","0","0"]]}
{"instId":"BTC-USDT","action":"update","ts":"1776816018290","asks":[["76464.5","0.02050181","1"],["76467.1","0","0"]],"bids":[]}
{"instId":"BTC-USDT","action":"update","ts":"1776816018300","asks":[["76357.3","1.79741311","25"]],"bids":[]}
{"instId":"BTC-USDT","action":"update","ts":"1776816018320","asks":[["76393.5","0.00130901","1"],["76407.7","0","0"]],"bids":[]}
{"instId":"BTC-USDT","action":"update","ts":"1776816018380","asks":[["76357.3","1.8039602","26"],["76360.2","0","0"],["76364.7","1.09602611","3"],["76365.7","0","0"],["76467.1","0.00181702","1"],["76467.2","0.00011781","1"]],"bids":[["76338.2","0.0360318","2"],["76337.5","0.00654709","1"],["76337.2","0.01537191","1"],["76332.8","0","0"],["76332.2","0.32742471","2"],["76330.5","0","0"],["76330.2","0.00654748","1"],["76173.7","0","0"]]}
{"instId":"BTC-USDT","action":"update","ts":"1776816018390","asks":[["76364.9","0.07911479","3"]],"bids":[["76338.1","0.00025064","6"],["76252.2","0.00001316","1"],["76173.9","0","0"]]}
{"instId":"BTC-USDT","action":"update","ts":"1776816018400","asks":[["76357.3","1.80382924","26"]],"bids":[["76338.2","0.0000168","1"]]}
{"instId":"BTC-USDT","action":"update","ts":"1776816018410","asks":[["76357.3","1.80376376","26"]],"bids":[["76239.4","0.00514472","1"],["76175","0","0"]]}
{"instId":"BTC-USDT","action":"update","ts":"1776816018420","asks":[["76364.7","1.08947863","2"],["76364.9","0.08566223","4"]],"bids":[["76330.5","0.00654744","1"],["76330.2","0","0"]]}
{"instId":"BTC-USDT","action":"update","ts":"1776816018430","asks":[["76357.3","1.79721667","25"],["76360.2","0.00654709","1"],["76372","0.01555054","1"],["76467.1","0","0"],["76467.2","0","0"]],"bids":[["76337.2","0","0"],["76302.7","0.01947407","1"],["76212.1","0.01451724","1"],["76175.1","0","0"]]}
{"instId":"BTC-USDT","action":"update","ts":"1776816018450","asks":[["76364.9","0.07911479","3"],["76365.7","0.00654744","1"],["76466.7","0","0"]],"bids":[]}
{"instId":"BTC-USDT","action":"update","ts":"1776816018530","asks":[],"bids":[["76186.6","0.00683192","1"],["76175.4","0","0"]]}
{"instId":"BTC-USDT","action":"update","ts":"1776816018540","asks":[],"bids":[["76298.1","0.00131064","1"],["76290.2","0.0000463","1"],["76176.3","0","0"]]}
{"instId":"BTC-USDT","action":"update","ts":"1776816018550","asks":[["76357.3","1.86113667","26"],["76362.6","0.50751308","2"]],"bids":[]}
{"instId":"BTC-USDT","action":"update","ts":"1776816018560","asks":[["76377.5","0","0"],["76466.7","0.00025453","6"]],"bids":[["76332.8","0.32737079","1"],["76332.2","0.00004629","1"],["76177.8","0","0"]]}
{"instId":"BTC-USDT","action":"update","ts":"1776816018630","asks":[],"bids":[["76332.8","0","0"],["76332.2","0.32741687","2"],["76177.8","0.00105547","4"]]}
{"instId":"BTC-USDT","action":"update","ts":"1776816018640","asks":[],"bids":[["76326.4","0.29512701","1"]]}
{"instId":"BTC-USDT","action":"update","ts":"1776816018670","asks":[],"bids":[["76350.8","0","0"],["76350.7","0.00106599","1"]]}
{"instId":"BTC-USDT","action":"update","ts":"1776816018690","asks":[],"bids":[["76350.8","0.00106577","1"],["76350.7","0","0"]]}
{"instId":"BTC-USDT","action":"update","ts":"1776816018700","asks":[["76357.3","1.86114667","27"]],"bids":[]}
{"instId":"BTC-USDT","action":"update","ts":"1776816018770","asks":[["76357.3","2.02114667","28"],["76360.2","0.16654709","2"]],"bids":[]}
{"instId":"BTC-USDT","action":"update","ts":"1776816018780","asks":[["76360.1","0.14783373","1"],["76360.3","0","0"]],"bids":[]}
{"instId":"BTC-USDT","action":"update","ts":"1776816018830","asks":[["76357.3","2.02049186","28"]],"bids":[]}
{"instId":"BTC-USDT","action":"update","ts":"1776816018860","asks":[],"bids":[["76331.2","0.47806049","2"],["76330.5","0","0"],["76175.4","0.00003868","3"]]}
{"instId":"BTC-USDT","action":"update","ts":"1776816018870","asks":[],"bids":[["76299.6","0.29996516","1"],["76299.2","0","0"],["76176.3","0.1305","1"],["76175.4","0","0"]]}
{"instId":"BTC-USDT","action":"update","ts":"1776816018880","asks":[],"bids":[["76254.9","0.04404922","2"]]}
{"instId":"BTC-USDT","action":"update","ts":"1776816018910","asks":[["76360.6","0.11329531","1"],["76364.8","0","0"],["76467.1","0.00181702","1"]],"bids":[]}
{"instId":"BTC-USDT","action":"update","ts":"1776816018920","asks":[["76357.3","1.71091388","23"],["76357.4","0","0"],["76360","0.00654708","1"],["76360.2","0","0"],["76360.6","0","0"],["76364.1","0","0"],["76364.7","0.08378297","1"],["76365","0","0"],["76365.7","0","0"],["76370.8","0.0065474","1"],["76372","0","0"],["76376.8","0","0"],["76390.4","0.000015","1"],["76392.8","0.19271332","2"],["76406.8","0.13589544","1"],["76467.2","0.00011781","1"],["76467.3","0.00050101","1"],["76467.8","0.47151308","1"],["76467.9","0.00001035","1"],["76468","1.00618616","2"]],"bids":[["76357.2","0.15836744","7"],["76347.2","0.02619","1"],["76346.2","0.11237383","2"],["76340.5","0.00654708","1"],["76337.5","0","0"],["76336.7","0","0"],["76334.4","0.32738666","2"],["76332.8","0.0065474","1"],["76332.2","0.00004629","1"],["76331.2","0.47151308","1"],["76303.2","0.00132089","2"],["76296.7","0","0"],["76294.5","0","0"],["76175.4","0.00003868","3"]]}
{"instId":"BTC-USDT","action":"update","ts":"1776816018930","asks":[["76360","0","0"],["76360.1","0.03575522","1"],["76360.4","0","0"],["76362.4","0.00654678","1"],["76362.5","0.20836309","1"],["76363","0","0"],["76364.9","0.055287","2"],["76411.4","0.10755198","1"],["76468.2","0.00158724","2"]],"bids":[["76346.3","0.06847606","1"],["76346.1","0","0"],["76341.5","0.01372413","1"],["76341.2","0.00654678","1"],["76340.5","0","0"],["76334.5","0.00654723","1"],["76332.8","0","0"],["76325.5","0","0"],["76211.3","0","0"],["76175.1","0.47151308","1"]]}
{"instId":"BTC-USDT","action":"update","ts":"1776816018940","asks":[["76360.1","0","0"],["76362.4","0.00654679","1"],["76391.7","0.12502965","2"],["76468.3","0.01147749","1"]],"bids":[["76341.6","0.00654679","1"],["76341.2","0","0"],["76334.5","0.10427215","2"],["76322.6","0.08378297","1"],["76175.1","0","0"]]}
{"instId":"BTC-USDT","action":"update","ts":"1776816018950","asks":[["76360.8","0.00654681","1"],["76362.4","0","0"]],"bids":[["76346.4","0.11031429","1"],["76341.6","0","0"],["76340.5","0.00654681","1"],["76334.5","0.09772492","1"],["76333.3","0.00654722","1"],["76176.3","0","0"],["76175.4","0","0"]]}
{"instId":"BTC-USDT","action":"update","ts":"1776816018960","asks":[["76357.3","1.2394008","22"],["76362.6","0.036","1"],["76364.4","0.47151308","1"],["76364.7","0","0"],["76371","0","0"],["76376.8","1.0057984","1"],["76377.7","0","0"],["76468.4","0.00002034","1"]],"bids":[["76357.2","0.18816744","8"],["76341.2","0.00654683","1"],["76340.5","0","0"],["76334.6","0.47151308","1"],["76221","0","0"]]}
{"instId":"BTC-USDT","action":"update","ts":"1776816018970","asks":[["76360.8","0","0"],["76361.8","0.00654685","1"],["76366.9","0.32736081","1"],["76370.9","0.29318715","2"],["76376.9","0","0"]],"bids":[["76341.6","0.00654685","1"],["76341.2","0","0"],["76337.2","0.01523348","1"],["76334.7","0.23848473","2"],["76334.5","0","0"],["76326.7","0.08378297","1"],["76177.8","0","0"]]}
{"instId":"BTC-USDT","action":"update","ts":"1776816018980","asks":[["76364.9","0.13787774","3"]],"bids":[["76280.3","0.00008018","1"],["76177.9","0","0"]]}
{"instId":"BTC-USDT","action":"update","ts":"1776816018990","asks":[["76366.8","0.05889073","1"],["76366.9","0","0"],["76370.8","0.33390778","2"],["76377.8","0.48755502","2"]],"bids":[["76339.9","0.05893702","2"],["76334.8","0.32736038","1"],["76334.5","0.00654721","1"],["76334.4","0.0000168","1"],["76333.3","0","0"],["76332.7","0","0"],["76329.1","0.01582528","1"],["76178.9","0","0"]]}
{"instId":"BTC-USDT","action":"update","ts":"1776816019000","asks":[["76357.3","1.23668989","22"],["76364.9","0.055287","2"],["76370.7","0.2702508","1"],["76370.9","0.12260782","1"],["76468.4","0","0"]],"bids":[["76334.9","0.24042701","1"],["76334.7","0.00001316","1"],["76320.6","0.11364593","1"],["76179.3","0","0"]]}
{"instId":"BTC-USDT","action":"update","ts":"1776816019010","asks":[["76357.3","1.23534098","22"],["76366.9","0.32734879","1"],["76370.8","0.0065474","1"],["76468.3","0","0"]],"bids":[["76335","0.32734879","1"],["76334.8","0","0"]]}
{"instId":"BTC-USDT","action":"update","ts":"1776816019020","asks":[["76364.9","0.15545304","3"],["76370.6","1.0057984","1"],["76370.7","0","0"],["76381.1","0.12793417","2"]],"bids":[["76335.1","0.24042355","1"],["76334.9","0","0"]]}
{"instId":"BTC-USDT","action":"update","ts":"1776816019030","asks":[["76357.3","1.22162882","21"],["76360.8","0.00654651","1"],["76361.8","0","0"],["76366.7","0.3273483","1"],["76366.9","0","0"],["76370.5","0.47931152","2"],["76370.6","0","0"],["76370.8","0","0"],["76468.3","0.01147749","1"]],"bids":[["76357.2","0.18936744","9"],["76341.6","0","0"],["76341.5","0","0"],["76340.5","0.00654651","1"],["76335","0","0"],["76334.7","0.32736146","2"],["76334.5","0","0"],["76333.3","0.00654698","1"],["76294.6","0","0"],["76294.1","0.00323346","1"],["76179.3","0.00040006","1"],["76178.9","0.0008637","1"]]}
{"instId":"BTC-USDT","action":"update","ts":"1776816019040","asks":[["76361.5","0.0104826","1"],["76370.4","0.31365382","1"],["76370.5","0.00654697","1"],["76468.2","0","0"],["76468.3","0","0"]],"bids":[["76346.7","0.0137232","1"],["76178.9","0","0"]]}
{"instId":"BTC-USDT","action":"update","ts":"1776816019050","asks":[["76360.8","0","0"],["76361.8","0.00654644","1"],["76366.7","0","0"],["76370.3","0.33387702","2"],["76370.4","0.1725336","1"],["76370.5","0","0"],["76468.2","0.00158724","2"]],"bids":[["76346.7","0.14162479","2"],["76346","0","0"],["76341.2","0.00654644","1"],["76340.5","0","0"],["76335.2","0.32733041","1"],["76334.8","0.00654661","1"],["76334.7","0.00001316","1"],["76333.3","0","0"],["76300.4","0","0"],["76178.9","0.0008637","1"]]}
{"instId":"BTC-USDT","action":"update","ts":"1776816019060","asks":[["76361.4","0.00654648","1"],["76361.8","0","0"],["76364.9","0.055287","2"],["76366.9","0.32733044","1"],["76370.2","0.27024162","1"],["76370.3","1.01234501","2"],["76370.4","0","0"],["76468.2","0","0"]],"bids":[["76346.8","0.10875049","1"],["76346.3","0","0"],["76335.1","0","0"],["76177.9","0.00004571","1"]]}
{"instId":"BTC-USDT","action":"update","ts":"1776816019070","asks":[["76361.4","0.0065465","1"],["76364.9","0.15544756","3"],["76366.9","0","0"],["76370.1","0.32733265","1"]],"bids":[["76357.2","0.18816744","8"],["76346.9","0.12523697","1"],["76346.2","0.00001456","1"],["76335.8","0.00305","1"],["76335.2","0","0"],["76334.7","0.32734581","2"],["76329.7","0","0"]]}
{"instId":"BTC-USDT","action":"update","ts":"1776816019080","asks":[["76361.3","0.00654646","1"],["76361.4","0","0"],["76364.9","0.055287","2"],["76366.7","0.32733268","1"],["76370","0.00654666","1"],["76370.1","0","0"],["76370.2","0.43821446","2"],["76370.3","1.0057984","1"],["76468","0","0"]],"bids":[["76346.8","0.07521125","1"],["76341.3","0.00654646","1"],["76341.2","0","0"],["76334.8","0","0"],["76334.7","0.32734584","2"],["76333.3","0.00654666","1"],["76331.3","0.00305","1"],["76321.7","0.000015","1"],["76317.5","0.34694062","2"],["76177.9","0","0"]]}
{"instId":"BTC-USDT","action":"update","ts":"1776816019090","asks":[["76361.5","0","0"],["76364.9","0.15544823","3"],["76366.7","0","0"],["76370.1","0.32733271","1"],["76421.3","0","0"],["76468","1.00618616","2"],["76468.2","0.00158724","2"]],"bids":[["76334.8","0.2384644","1"],["76300.4","0.12237067","1"],["76179.3","0","0"],["76178.9","0","0"]]}
{"instId":"BTC-USDT","action":"update","ts":"1776816019100","asks":[["76357.3","1.22112463","21"],["76359","0.01048296","1"],["76361.3","0","0"],["76361.8","0.00654641","1"],["76364.9","0.055287","2"],["76366.9","0.32733266","1"],["76370.1","0","0"],["76468.2","0","0"]],"bids":[["76357.2","0.09586744","6"],["76341.3","0","0"],["76341.2","0.00654641","1"],["76334.9","0.32733266","1"],["76334.7","0.00001316","1"],["76179.9","0","0"]]}
{"instId":"BTC-USDT","action":"update","ts":"1776816019110","asks":[["76358.9","0.01387516","1"],["76468","0","0"]],"bids":[["76335","0.2384644","1"],["76334.8","0","0"],["76273.3","0.3329292","2"]]}
{"instId":"BTC-USDT","action":"update","ts":"1776816019120","asks":[["76364.9","0.15544822","3"],["76390.3","0","0"],["76398.3","0.00130892","1"]],"bids":[]}
{"instId":"BTC-USDT","action":"update","ts":"1776816019130","asks":[],"bids":[["76346.7","0.12790159","1"]]}
{"instId":"BTC-USDT","action":"update","ts":"1776816019140","asks":[["76361.8","0","0"],["76363.8","0.00654639","1"],["76366.9","0","0"],["76370","0","0"],["76370.1","0.33387893","2"],["76468","1.00618616","2"]],"bids":[["76343.9","0.0137237","1"],["76335.1","0.32733229","1"],["76334.9","0","0"],["76334.7","0.0065598","2"],["76333.3","0","0"]]}
{"instId":"BTC-USDT","action":"update","ts":"1776816019150","asks":[["76364.9","0.055287","2"],["76370.1","0.32733229","1"],["76370.8","0.00654664","1"],["76468","0","0"]],"bids":[["76335.9","0.00654664","1"],["76335.2","0.24041846","1"],["76335","0","0"],["76334.7","0.00001316","1"],["76320.6","0.11367458","2"],["76180","0","0"]]}
{"instId":"BTC-USDT","action":"update","ts":"1776816019160","asks":[["76362.5","0.21490947","2"],["76363.8","0","0"],["76468","1.00618616","2"]],"bids":[["76341.2","0.00654638","1"],["76335.9","0","0"],["76335.2","0.2469651","2"],["76180","0.0000812","1"]]}
{"instId":"BTC-USDT","action":"update","ts":"1776816019210","asks":[["76366.9","0.08378297","1"],["76421.3","0.00003967","1"],["76467.9","0","0"],["76468","0","0"]],"bids":[["76351.5","0.00047119","2"],["76350.8","0","0"],["76179.9","0.47151308","1"]]}
{"instId":"BTC-USDT","action":"update","ts":"1776816019220","asks":[["76364.9","0.08274864","3"]],"bids":[["76343.9","0","0"],["76343.7","0.01377004","2"],["76329.1","0","0"],["76179.3","0.00040006","1"],["76178.9","0.0008637","1"]]}
{"instId":"BTC-USDT","action":"update","ts":"1776816019360","asks":[["76366.7","0.13056621","1"],["76411.4","0","0"]],"bids":[["76357.2","0.00023744","5"]]}
{"instId":"BTC-USDT","action":"update","ts":"1776816019370","asks":[["76364.9","0.11821174","2"],["76370","0.0065469","1"],["76370.8","0","0"]],"bids":[["76335.2","0.24041846","1"],["76334.4","0.0065637","2"]]}
{"instId":"BTC-USDT","action":"update","ts":"1776816019420","asks":[["76357.3","0.99934463","18"]],"bids":[]}
{"instId":"BTC-USDT","action":"update","ts":"1776816019430","asks":[],"bids":[["76347.5","0.00135629","2"]]}
{"instId":"BTC-USDT","action":"update","ts":"1776816019450","asks":[["76360.8","0.00654636","1"],["76362.5","0.20836309","1"],["76366.6","0.32734437","1"],["76370.1","0","0"],["76467.8","0","0"]],"bids":[["76335.3","0.32734437","1"],["76335.1","0","0"],["76334.4","0.0000168","1"],["76333.3","0.00654689","1"],["76178.9","0","0"]]}
{"instId":"BTC-USDT","action":"update","ts":"1776816019460","asks":[["76364.9","0.21139014","3"],["76366.5","0.10687235","1"],["76367","0.00630842","1"],["76370.9","0","0"],["76406.7","0.13323082","1"],["76406.8","0","0"]],"bids":[["76341.2","0","0"],["76340.5","0.00654637","1"],["76335.4","0.23846789","1"],["76335.3","0","0"],["76335.2","0","0"],["76334.7","0.32735753","2"],["76333.3","0","0"],["76332.2","0.00659318","2"],["76178.9","0.0008637","1"],["76177.9","0.00004571","1"]]}
{"instId":"BTC-USDT","action":"update","ts":"1776816019480","asks":[["76411.4","0.12790159","1"],["76467.3","0","0"]],"bids":[["76357.2","0.09253744","7"]]}
{"instId":"BTC-USDT","action":"update","ts":"1776816019490","asks":[],"bids":[["76347.5","0.00004629","1"],["76330.9","0.01578917","1"],["76177.9","0","0"]]}
{"instId":"BTC-USDT","action":"update","ts":"1776816019530","asks":[["76360.8","0","0"],["76361.8","0.00654646","1"]],"bids":[["76341.2","0.00654646","1"],["76340.5","0","0"]]}
{"instId":"BTC-USDT","action":"update","ts":"1776816019540","asks":[["76370","0","0"],["76370.1","0.00654667","1"]],"bids":[["76334.2","0.00682717","10"],["76332.2","0.00004629","1"]]}
{"instId":"BTC-USDT","action":"update","ts":"1776816019550","asks":[["76369.9","0.00654667","1"],["76370.1","0","0"]],"bids":[["76334.2","0.0002805","9"],["76333.3","0.00654667","1"],["76178.9","0","0"]]}
{"instId":"BTC-USDT","action":"update","ts":"1776816019600","asks":[["76366.6","0","0"],["76370.1","0.32733193","1"]],"bids":[["76335.5","0.32733193","1"],["76334.7","0.00001316","1"],["76179.3","0","0"]]}
{"instId":"BTC-USDT","action":"update","ts":"1776816019610","asks":[["76364.9","0.11821174","2"],["76366.8","0.38622253","2"],["76370.1","0","0"],["76467.3","0.00050101","1"]],"bids":[["76335.6","0.23846418","1"],["76335.4","0","0"]]}
{"instId":"BTC-USDT","action":"update","ts":"1776816019620","asks":[["76364.9","0.21065107","3"],["76366.8","0.05889073","1"],["76370.1","0.32733176","1"],["76467.3","0","0"]],"bids":[["76335.7","0.32733176","1"],["76335.5","0","0"]]}
{"instId":"BTC-USDT","action":"update","ts":"1776816019630","asks":[["76364.9","0.11821174","2"],["76366.8","0.38622242","2"],["76370.1","0","0"],["76467.3","0.00050101","1"]],"bids":[["76335.8","0.24151413","2"],["76335.6","0","0"],["76179.3","0.00040006","1"]]}
{"instId":"BTC-USDT","action":"update","ts":"1776816019640","asks":[["76364.9","0.21065103","3"]],"bids":[]}
{"instId":"BTC-USDT","action":"update","ts":"1776816019650","asks":[["76366.8","0.38622273","2"]],"bids":[["76357.2","0.00023744","5"],["76335.9","0.32733205","1"],["76335.7","0","0"]]}
{"instId":"BTC-USDT","action":"update","ts":"1776816019660","asks":[["76366.4","0.32733195","1"],["76366.8","0.05889073","1"],["76467.3","0","0"]],"bids":[["76336","0.23942093","2"],["76335.9","0","0"],["76335.8","0.00305","1"],["76334.7","0.32734511","2"],["76178.9","0.0008637","1"]]}
{"instId":"BTC-USDT","action":"update","ts":"1776816019670","asks":[["76366.3","0.12257236","1"],["76411.4","0","0"]],"bids":[["76318.1","0.21096944","1"],["76178.9","0","0"]]}
{"instId":"BTC-USDT","action":"update","ts":"1776816019750","asks":[],"bids":[["76343.7","0.00004629","1"],["76334.6","0","0"],["76178.9","0.0008637","1"]]}
{"instId":"BTC-USDT","action":"update","ts":"1776816019760","asks":[["76364.1","0.16","1"],["76366.4","0","0"],["76370.1","0.32733305","1"],["76467.2","0","0"]],"bids":[["76341.2","0.02027064","2"],["76336.1","0.32733305","1"],["76336","0.09867425","2"],["76334.7","0.00001316","1"],["76330.9","0","0"]]}
{"instId":"BTC-USDT","action":"update","ts":"1776816019770","asks":[["76357.3","0.9987946","18"]],"bids":[["76336.2","0.09862828","1"],["76336","0.00004629","1"],["76178.9","0","0"]]}
{"instId":"BTC-USDT","action":"update","ts":"1776816019780","asks":[["76366.8","0.3862236","2"],["76370.1","0","0"],["76467.2","0.00011781","1"]],"bids":[["76336.2","0.42596115","2"],["76336.1","0","0"],["76334.4","0.47152988","2"],["76178.9","0.0008637","1"]]}
{"instId":"BTC-USDT","action":"update","ts":"1776816019790","asks":[],"bids":[["76336.3","0.23937488","1"],["76336.2","0","0"],["76334.5","0.32733287","1"],["76178.9","0","0"]]}
{"instId":"BTC-USDT","action":"update","ts":"1776816019800","asks":[["76357.3","0.99715497","18"]],"bids":[]}
{"instId":"BTC-USDT","action":"update","ts":"1776816019810","asks":[["76357.3","0.9970633","18"],["76366.8","0.05889073","1"],["76370.1","0.32733176","1"],["76467.2","0","0"]],"bids":[["76357.2","0.06273744","6"]]}
{"instId":"BTC-USDT","action":"update","ts":"1776816019820","asks":[["76372.6","0.15910419","2"]],"bids":[["76357.2","0.09253744","7"],["76326.6","0.21012042","8"]]}
{"instId":"BTC-USDT","action":"update","ts":"1776816019830","asks":[["76387.9","0.10606946","2"],["76467.1","0","0"]],"bids":[["76341.9","0.05191405","6"],["76330","0.01547047","1"],["76179.3","0","0"]]}
{"instId":"BTC-USDT","action":"update","ts":"1776816019840","asks":[["76372.6","0.10606946","1"]],"bids":[["76341.3","0.06350684","1"],["76340.4","0","0"]]}
{"instId":"BTC-USDT","action":"update","ts":"1776816019860","asks":[["76387.9","0.15910419","3"]],"bids":[]}
{"instId":"BTC-USDT","action":"update","ts":"1776816019880","asks":[],"bids":[["76326.6","0.15934162","7"]]}
{"instId":"BTC-USDT","action":"update","ts":"1776816019890","asks":[],"bids":[["76341.9","0.10269285","7"]]}
{"instId":"BTC-USDT","action":"update","ts":"1776816019910","asks":[["76357.3","0.99699782","18"]],"bids":[["76320.6","0.11364593","1"],["76294.1","0","0"],["76179.3","0.00040006","1"]]}
{"instId":"BTC-USDT","action":"update","ts":"1776816019960","asks":[],"bids":[["76357.2","0.00023744","5"],["76294.1","0.00323341","1"],["76179.3","0","0"]]}
{"instId":"BTC-USDT","action":"update","ts":"1776816019980","asks":[],"bids":[["76280.3","0.00016036","2"]]}
{"instId":"BTC-USDT","action":"update","ts":"1776816020000","asks":[],"bids":[["76341.9","0.05191405","6"],["76320.6","0.11367457","2"]]}
{"instId":"BTC-USDT","action":"update","ts":"1776816020010","asks":[["76369.9","0","0"],["76370","0.00654663","1"]],"bids":[["76342","0.00656293","2"],["76341.2","0.01372418","1"],["76334.4","0.47807651","3"],["76333.3","0","0"],["76179.3","0.00040006","1"]]}
{"instId":"BTC-USDT","action":"update","ts":"1776816020020","asks":[["76369.9","0.00654663","1"],["76370","0","0"]],"bids":[["76336.4","0.32733141","1"],["76334.5","0","0"],["76326.6","0.21012042","8"]]}
{"instId":"BTC-USDT","action":"update","ts":"1776816020030","asks":[["76387.9","0.10606946","2"]],"bids":[["76341.9","0.00023748","5"],["76336.5","0.24132862","1"],["76336.3","0","0"]]}
{"instId":"BTC-USDT","action":"update","ts":"1776816020040","asks":[["76372.6","0.15910419","2"],["76376.7","0.4906701","1"],["76466.7","0","0"]],"bids":[["76342.1","0.00654618","1"],["76342","0.0000168","1"],["76336.4","0","0"],["76334.5","0.32733142","1"],["76326.6","0.26179699","9"],["76179.3","0","0"]]}
{"instId":"BTC-USDT","action":"update","ts":"1776816020050","asks":[],"bids":[["76342.1","0","0"],["76341.4","0.00656967","3"],["76179.3","0.00040006","1"]]}
{"instId":"BTC-USDT","action":"update","ts":"1776816020060","asks":[],"bids":[["76341.4","0.00656961","3"]]}
{"instId":"BTC-USDT","action":"update","ts":"1776816020100","asks":[["76357.3","0.99686686","18"]],"bids":[]}
{"instId":"BTC-USDT","action":"update","ts":"1776816020140","asks":[],"bids":[["76326.6","0.21012042","8"]]}
{"instId":"BTC-USDT","action":"update","ts":"1776816020160","asks":[],"bids":[["76341.9","0.05191405","6"]]}
{"instId":"BTC-USDT","action":"update","ts":"1776816020170","asks":[],"bids":[["76342","0.00656292","2"],["76341.4","0.00002349","2"]]}
{"instId":"BTC-USDT","action":"update","ts":"1776816020180","asks":[],"bids":[["76330","0","0"],["76178.9","0.0008637","1"]]}
{"instId":"BTC-USDT","action":"update","ts":"1776816020200","asks":[["76428.3","0.05998615","3"]],"bids":[]}
{"instId":"BTC-USDT","action":"update","ts":"1776816020210","asks":[],"bids":[["76351.5","0.00001316","1"]]}
{"instId":"BTC-USDT","action":"update","ts":"1776816020260","asks":[],"bids":[["76341.9","0.00023748","5"]]}
{"instId":"BTC-USDT","action":"update","ts":"1776816020270","asks":[["76428.2","0.05986655","1"],["76466.6","0","0"]],"bids":[["76342","0.0000168","1"],["76341.4","0.00656962","3"]]}
{"instId":"BTC-USDT","action":"update","ts":"1776816020280","asks":[],"bids":[["76326.6","0.26179699","9"]]}
{"instId":"BTC-USDT","action":"update","ts":"1776816020350","asks":[],"bids":[["76357.2","0.09253744","7"],["76326.6","0.21012042","8"]]}
{"instId":"BTC-USDT","action":"update","ts":"1776816020360","asks":[],"bids":[["76336.6","0.32733197","1"],["76334.5","0","0"]]}
{"instId":"BTC-USDT","action":"update","ts":"1776816020370","asks":[["76361.8","0","0"],["76362.4","0.00654612","1"],["76364.1","0","0"],["76466.6","0.00546094","15"]],"bids":[["76341.9","0.05191405","6"],["76336.7","0.2413426","1"],["76336.5","0","0"]]}
{"instId":"BTC-USDT","action":"update","ts":"1776816020390","asks":[["76364.4","0","0"],["76370.3","0","0"],["76376.8","0","0"],["76466.7","0.00025453","6"],["76467.1","0.00181702","1"],["76467.2","0.00011781","1"]],"bids":[["76357.2","0.32631011","10"]]}
{"instId":"BTC-USDT","action":"update","ts":"1776816020400","asks":[["76357.3","0.89216956","17"],["76360.9","0","0"],["76362.4","0","0"],["76362.5","0.05288017","1"],["76363.4","0.47151308","1"],["76363.8","0.00654609","1"],["76366.9","0","0"],["76369.9","0","0"],["76370.2","0.16797284","1"],["76371","0.00654658","1"],["76376.6","1.0057984","1"],["76376.7","0","0"],["76377.8","0.47151308","1"],["76411.4","0.12790159","1"]],"bids":[["76357.2","0.44378607","11"],["76342","0.00656289","2"],["76341.4","0.00002349","2"],["76341.2","0","0"],["76335.9","0.00654658","1"],["76334.4","0.47152988","2"]]}
{"instId":"BTC-USDT","action":"update","ts":"1776816020410","asks":[["76358.9","0","0"],["76362.5","0.18882021","2"],["76364.9","0.11821174","2"],["76467.3","0.00050101","1"]],"bids":[["76344","0.01225365","1"],["76332.2","0.01543983","2"],["76178.9","0","0"]]}
{"instId":"BTC-USDT","action":"update","ts":"1776816020420","asks":[["76363.3","0.00654605","1"],["76363.8","0","0"],["76370","0.27024202","1"],["76370.2","0","0"]],"bids":[["76344.1","0.00654605","1"],["76342","0.0000168","1"],["76179.3","0","0"]]}
{"instId":"BTC-USDT","action":"update","ts":"1776816020430","asks":[["76363.3","0","0"],["76363.7","0.00654605","1"],["76371","0","0"],["76372.4","0.00654661","1"]],"bids":[["76336.8","0.00654661","1"],["76335.9","0","0"]]}
{"instId":"BTC-USDT","action":"update","ts":"1776816020440","asks":[["76363.7","0","0"],["76364.1","0.00654605","1"]],"bids":[]}
{"instId":"BTC-USDT","action":"update","ts":"1776816020450","asks":[],"bids":[["76357.2","0.44258607","10"]]}
{"instId":"BTC-USDT","action":"update","ts":"1776816020470","asks":[["76372.6","0.10606946","1"]],"bids":[]}
{"instId":"BTC-USDT","action":"update","ts":"1776816020480","asks":[["76369.9","1.0057984","1"],["76467.3","0","0"]],"bids":[]}
{"instId":"BTC-USDT","action":"update","ts":"1776816020490","asks":[["76369.8","0.57047285","1"],["76370","0","0"],["76371.2","0.47805978","2"],["76372.4","0","0"],["76372.6","0.15910419","2"],["76467.3","0.00050101","1"]],"bids":[]}
{"instId":"BTC-USDT","action":"update","ts":"1776816020500","asks":[["76383.6","0.01549402","1"],["76467.3","0","0"]],"bids":[["76332.2","0.00004629","1"]]}
{"instId":"BTC-USDT","action":"update","ts":"1776816020510","asks":[["76369.9","0","0"],["76371.2","0.47151308","1"],["76372.4","0.00654669","1"]],"bids":[]}
{"instId":"BTC-USDT","action":"update","ts":"1776816020520","asks":[["76357.3","0.73823589","16"],["76361.9","0","0"],["76369.8","0.27024205","1"],["76370","0.32733481","1"],["76370.1","0","0"],["76387.9","0.05303473","1"],["76467.3","0.00050101","1"]],"bids":[["76346.6","0.01225323","1"],["76344","0","0"],["76336.8","0.33388142","2"],["76336.6","0","0"],["76307.4","0.00131048","1"],["76298.1","0","0"],["76179.3","0.00040006","1"]]}
{"instId":"BTC-USDT","action":"update","ts":"1776816020530","asks":[["76364.1","0","0"],["76364.5","0.00654595","1"],["76366.5","0","0"],["76366.7","0","0"],["76369.9","0.32733496","1"],["76370","0","0"],["76372.6","0.21213892","3"],["76467.8","0.47151308","1"],["76467.9","0.00001035","1"]],"bids":[["76344.2","0.00654595","1"],["76344.1","0","0"],["76336.7","0","0"],["76178.9","0.0008637","1"]]}
{"instId":"BTC-USDT","action":"update","ts":"1776816020540","asks":[["76364.9","0.0687572","2"],["76369.7","0.32733503","1"],["76369.9","0","0"],["76371","0.0065467","1"],["76372.4","0","0"]],"bids":[["76344.2","0","0"],["76342","0.00656275","2"],["76336.9","0.32733503","1"],["76336.8","0","0"],["76335.9","0.0065467","1"]]}
{"instId":"BTC-USDT","action":"update","ts":"1776816020550","asks":[["76369.6","0.27024303","1"],["76369.8","0","0"]],"bids":[["76337","0.32733515","1"],["76336.9","0","0"]]}
{"instId":"BTC-USDT","action":"update","ts":"1776816020560","asks":[["76369.5","0.32733521","1"],["76369.6","1.27604143","2"],["76369.7","0","0"],["76383.6","0","0"],["76468","1.00618616","2"]],"bids":[["76337.1","0.32735021","2"],["76337","0","0"],["76177.9","0.00004571","1"]]}
{"instId":"BTC-USDT","action":"update","ts":"1776816020570","asks":[["76357.3","0.73800017","16"],["76369.5","0.80009955","2"],["76369.6","1.0057984","1"],["76434.2","0.00001051","1"]],"bids":[["76341.9","0.00023748","5"],["76337.2","0.3425688","2"],["76337.1","0.000015","1"]]}
{"instId":"BTC-USDT","action":"update","ts":"1776816020580","asks":[["76363.3","0.006546","1"],["76364.5","0","0"],["76369.4","0.32733537","1"],["76369.5","0.47276434","1"],["76372.6","0.15910419","2"],["76468","0","0"]],"bids":[["76342","0.0000168","1"],["76341.4","0.00656949","3"],["76337.3","0.32733537","1"],["76337.2","0.01523348","1"],["76177.9","0","0"]]}
{"instId":"BTC-USDT","action":"update","ts":"1776816020590","asks":[["76369.4","0.44659489","2"],["76387.9","0.10606946","2"]],"bids":[["76337.4","0.32994712","2"],["76337.3","0","0"],["76335.9","0","0"],["76334.5","0.00654656","1"],["76326.6","0.26179699","9"],["76177.9","0.00004571","1"]]}
{"instId":"BTC-USDT","action":"update","ts":"1776816020600","asks":[["76357.3","0.73666435","15"],["76369.3","0.32732825","1"],["76369.4","0.11925952","1"],["76467.9","0","0"]],"bids":[["76337.5","0.79883943","2"],["76337.4","0.00261883","1"],["76177.9","0","0"]]}
{"instId":"BTC-USDT","action":"update","ts":"1776816020610","asks":[["76357.3","0.7358","15"],["76372.6","0.10606946","1"]],"bids":[["76337.6","0.32732629","1"],["76337.5","0.47151308","1"],["76326.6","0.15934162","7"],["76178.9","0","0"]]}
{"instId":"BTC-USDT","action":"update","ts":"1776816020620","asks":[["76372.6","0.15910419","2"]],"bids":[["76341.9","0.10269285","7"],["76337.7","1.0057984","1"],["76200","0.01335597","51"],["76179.3","0","0"]]}
{"instId":"BTC-USDT","action":"update","ts":"1776816020630","asks":[],"bids":[["76341.9","0.00023748","5"],["76335.9","0.00654652","1"],["76334.5","0","0"]]}
{"instId":"BTC-USDT","action":"update","ts":"1776816020650","asks":[["76387.9","0.05303473","1"]],"bids":[]}
{"instId":"BTC-USDT","action":"update","ts":"1776816020660","asks":[["76383.9","0.01594931","1"],["76467.8","0","0"]],"bids":[["76334","0.01607334","1"],["76326.6","0.21101819","8"],["76179.9","0","0"]]}
{"instId":"BTC-USDT","action":"update","ts":"1776816020670","asks":[["76372.6","0.21213892","3"]],"bids":[["76337.8","0.68765174","1"],["76180","0","0"]]}
{"instId":"BTC-USDT","action":"update","ts":"1776816020680","asks":[],"bids":[["76307.1","0.30614271","2"],["76237.9","0.14664584","2"]]}
{"instId":"BTC-USDT","action":"update","ts":"1776816020690","asks":[],"bids":[["76326.6","0.26179699","9"],["76253.5","0.96497306","2"]]}
{"instId":"BTC-USDT","action":"update","ts":"1776816020700","asks":[["76363.3","0","0"],["76364.8","0.00654601","1"],["76369.3","0","0"],["76371","0.33387113","2"],["76467.8","0.47151308","1"]],"bids":[["76357.2","0.54258607","11"],["76337.9","0.32732443","1"],["76337.6","0","0"]]}
{"instId":"BTC-USDT","action":"update","ts":"1776816020710","asks":[["76357.3","0.73566904","15"],["76371","0.32732443","1"],["76372.4","0.00654648","1"],["76467.8","0","0"]],"bids":[["76337.8","0.69419822","2"],["76335.9","0","0"],["76180","0.0000812","1"]]}
{"instId":"BTC-USDT","action":"update","ts":"1776816020720","asks":[],"bids":[["76334","0","0"],["76179.9","0.47151308","1"]]}
{"instId":"BTC-USDT","action":"update","ts":"1776816020780","asks":[],"bids":[["76337.8","0.68765174","1"],["76337.3","0.00654664","1"],["76179.9","0","0"]]}
{"instId":"BTC-USDT","action":"update","ts":"1776816020790","asks":[],"bids":[["76337.3","0","0"],["76335.9","0.00654664","1"],["76326.6","0.21012042","8"]]}
{"instId":"BTC-USDT","action":"update","ts":"1776816020810","asks":[["76357.3","0.73518974","15"]],"bids":[["76326.6","0.26179699","9"]]}
{"instId":"BTC-USDT","action":"update","ts":"1776816020840","asks":[["76387.9","0","0"],["76467.8","0.47151308","1"]],"bids":[["76326.6","0.21012042","8"]]}
{"instId":"BTC-USDT","action":"update","ts":"1776816020850","asks":[["76371.1","0.09032961","2"],["76372.4","0","0"],["76467.9","0.00001035","1"]],"bids":[["76326.6","0.26179699","9"]]}
{"instId":"BTC-USDT","action":"update","ts":"1776816020880","asks":[["76372.6","0.26517365","4"]],"bids":[["76357.2","0.43755028","10"]]}
{"instId":"BTC-USDT","action":"update","ts":"1776816020890","asks":[["76363.3","0.00654605","1"],["76364.8","0","0"]],"bids":[]}
{"instId":"BTC-USDT","action":"update","ts":"1776816020990","asks":[],"bids":[["76335.7","0.01573108","1"],["76180","0","0"]]}
{"instId":"BTC-USDT","action":"update","ts":"1776816021010","asks":[["76369.3","0.32733226","1"],["76371","0","0"]],"bids":[]}
{"instId":"BTC-USDT","action":"update","ts":"1776816021020","asks":[["76363.3","0","0"],["76363.8","0.00654609","1"]],"bids":[]}
{"instId":"BTC-USDT","action":"update","ts":"1776816021070","asks":[["76418.2","0.01954178","1"],["76467.9","0","0"]],"bids":[["76341.8","0.1305","1"],["76181.6","0","0"]]}
{"instId":"BTC-USDT","action":"update","ts":"1776816021080","asks":[["76371.1","0.08378297","1"],["76371.2","0.47805971","2"],["76376.5","0.48588158","1"],["76467.8","0","0"]],"bids":[["76341.9","0.09861202","6"],["76341.3","0","0"],["76181.6","0.00073364","2"]]}
{"instId":"BTC-USDT","action":"update","ts":"1776816021110","asks":[["76371.2","0.47151308","1"],["76372.4","0.00654663","1"],["76467.3","0","0"]],"bids":[]}
{"instId":"BTC-USDT","action":"update","ts":"1776816021140","asks":[["76371.2","0.47805972","2"],["76372.4","0","0"],["76467.3","0.00050101","1"]],"bids":[]}
{"instId":"BTC-USDT","action":"update","ts":"1776816021170","asks":[["76363.8","0","0"],["76364.1","0.00654606","1"],["76369.3","0","0"],["76371","0.32733234","1"],["76371.2","0.47151308","1"],["76372.4","0.00654668","1"],["76467.3","0","0"]],"bids":[["76342","0.00656286","2"],["76341.4","0.00002349","2"]]}
{"instId":"BTC-USDT","action":"update","ts":"1776816021180","asks":[["76369.5","0.80009658","2"],["76371","0","0"],["76467.3","0.00050101","1"]],"bids":[]}
{"instId":"BTC-USDT","action":"update","ts":"1776816021250","asks":[["76371.2","0.47805977","2"],["76372.4","0","0"],["76467.8","0.47151308","1"]],"bids":[]}
{"instId":"BTC-USDT","action":"update","ts":"1776816021320","asks":[],"bids":[["76327.6","0","0"],["76180","0.0000812","1"]]}
{"instId":"BTC-USDT","action":"update","ts":"1776816021330","asks":[["76371.2","0.47151308","1"],["76372.4","0.00654669","1"],["76467.8","0","0"]],"bids":[["76330.4","0.00023743","5"]]}
{"instId":"BTC-USDT","action":"update","ts":"1776816021370","asks":[["76357.3","0.73516355","15"]],"bids":[]}
{"instId":"BTC-USDT","action":"update","ts":"1776816021400","asks":[["76357.3","0.73505879","15"]],"bids":[]}
{"instId":"BTC-USDT","action":"update","ts":"1776816021410","asks":[["76357.3","0.73477068","15"]],"bids":[]}
{"instId":"BTC-USDT","action":"update","ts":"1776816021470","asks":[["76357.3","0.73474449","15"]],"bids":[]}
{"instId":"BTC-USDT","action":"update","ts":"1776816021510","asks":[["76357.3","0.73463972","15"],["76366.2","0.08378297","1"],["76371","0.0065467","1"],["76372.4","0","0"],["76467.3","0","0"]],"bids":[]}
{"instId":"BTC-USDT","action":"update","ts":"1776816021520","asks":[["76363.8","0.00654608","1"],["76364.1","0","0"]],"bids":[]}
{"instId":"BTC-USDT","action":"update","ts":"1776816021530","asks":[],"bids":[["76306.3","0.01674088","1"],["76234.1","0.4652109","1"],["76181.6","0","0"],["76180","0","0"]]}
{"instId":"BTC-USDT","action":"update","ts":"1776816021650","asks":[["76372.6","0.15910419","2"]],"bids":[["76326.6","0.21012042","8"]]}
{"instId":"BTC-USDT","action":"update","ts":"1776816021660","asks":[["76372.6","0.21213892","3"],["76387.9","0.05303473","1"],["76467.2","0","0"]],"bids":[["76341.9","0.15028859","7"]]}
{"instId":"BTC-USDT","action":"update","ts":"1776816021690","asks":[["76387.9","0","0"],["76467.2","0.00011781","1"]],"bids":[["76341.9","0.09861202","6"]]}
{"instId":"BTC-USDT","action":"update","ts":"1776816021730","asks":[["76383.9","0","0"],["76467.3","0.00050101","1"]],"bids":[["76357.2","0.32007432","9"]]}
{"instId":"BTC-USDT","action":"update","ts":"1776816021740","asks":[["76363.3","0.16","1"],["76372.6","0.26517365","4"],["76467.3","0","0"]],"bids":[["76346.6","0","0"],["76344","0.01225365","1"],["76326.6","0.26179699","9"],["76246.9","0","0"],["76181.6","0.00073364","2"]]}
{"instId":"BTC-USDT","action":"update","ts":"1776816021750","asks":[],"bids":[["76329.7","0.1881112","1"],["76181.6","0","0"]]}
{"instId":"BTC-USDT","action":"update","ts":"1776816021760","asks":[],"bids":[["76357.2","0.22007432","8"],["76292.5","0.43587805","2"]]}
{"instId":"BTC-USDT","action":"update","ts":"1776816021770","asks":[["76442.9","0.01328693","1"],["76467.2","0","0"]],"bids":[["76357.2","0.22127432","9"]]}
{"instId":"BTC-USDT","action":"update","ts":"1776816021790","asks":[],"bids":[["76337.2","0","0"],["76181.6","0.00073364","2"]]}
{"instId":"BTC-USDT","action":"update","ts":"1776816021830","asks":[],"bids":[["76182","0.01015936","1"],["76181.6","0","0"]]}
{"instId":"BTC-USDT","action":"update","ts":"1776816021840","asks":[["76418.2","0","0"],["76467.2","0.00011781","1"]],"bids":[["76182","0","0"],["76181.6","0.00073364","2"]]}
{"instId":"BTC-USDT","action":"update","ts":"1776816021910","asks":[],"bids":[["76320.6","0.11364593","1"],["76294.1","0","0"],["76180","0.0000812","1"]]}
{"instId":"BTC-USDT","action":"update","ts":"1776816021920","asks":[],"bids":[["76250.1","0.25961713","1"],["76180","0","0"]]}
{"instId":"BTC-USDT","action":"update","ts":"1776816021930","asks":[],"bids":[["76357.2","0.19147432","8"]]}
{"instId":"BTC-USDT","action":"update","ts":"1776816021960","asks":[],"bids":[["76294.1","0.00323333","1"],["76181.6","0","0"]]}
{"instId":"BTC-USDT","action":"update","ts":"1776816022010","asks":[["76363.2","0.00654611","1"],["76363.8","0","0"],["76369.3","0.32733586","1"],["76369.5","0.47276434","1"],["76467.2","0","0"]],"bids":[["76337.9","0","0"],["76337.8","1.0149876","2"],["76181.6","0.00073364","2"]]}
{"instId":"BTC-USDT","action":"update","ts":"1776816022020","asks":[],"bids":[["76341.8","0","0"],["76337.8","0.68765174","1"],["76337.6","0.32733588","1"]]}
{"instId":"BTC-USDT","action":"update","ts":"1776816022030","asks":[],"bids":[["76341.9","0.05770379","6"],["76337.8","1.01498761","2"],["76337.6","0","0"],["76335.9","0","0"],["76335.8","0.0095967","2"],["76180","0.0000812","1"],["76179.9","0.47151308","1"]]}
{"instId":"BTC-USDT","action":"update","ts":"1776816022040","asks":[],"bids":[["76320.6","0.11367457","2"],["76307.2","0.0032521","1"],["76307.1","0.30289057","1"],["76179.9","0","0"]]}
{"instId":"BTC-USDT","action":"update","ts":"1776816022050","asks":[["76382.3","0.01608117","1"],["76467.1","0","0"]],"bids":[]}
{"instId":"BTC-USDT","action":"update","ts":"1776816022070","asks":[],"bids":[["76294.2","0.00323334","1"],["76294.1","0","0"]]}
{"instId":"BTC-USDT","action":"update","ts":"1776816022170","asks":[["76357.3","0.73445638","15"]],"bids":[["76357.2","0.22127432","9"]]}
{"instId":"BTC-USDT","action":"update","ts":"1776816022180","asks":[],"bids":[["76337.8","0.68765174","1"],["76337.6","0.32733827","1"],["76335.8","0.00959675","2"],["76180","0","0"]]}
{"instId":"BTC-USDT","action":"update","ts":"1776816022190","asks":[],"bids":[["76306.5","0.01672544","1"],["76181.6","0","0"]]}
{"instId":"BTC-USDT","action":"update","ts":"1776816022200","asks":[["76357.3","0.73388801","15"]],"bids":[]}
{"instId":"BTC-USDT","action":"update","ts":"1776816022210","asks":[["76357.3","0.73374396","15"]],"bids":[]}
{"instId":"BTC-USDT","action":"update","ts":"1776816022340","asks":[["76418.4","0.0189191","1"],["76466.7","0","0"]],"bids":[["76320.6","0.11364593","1"]]}
{"instId":"BTC-USDT","action":"update","ts":"1776816022350","asks":[["76382.3","0","0"],["76391.6","0.17126092","1"],["76392.8","0.08378297","1"]],"bids":[["76335.7","0","0"],["76181.6","0.00073364","2"]]}
{"instId":"BTC-USDT","action":"update","ts":"1776816022360","asks":[["76397.2","0","0"],["76466.7","0.00025453","6"]],"bids":[]}
{"instId":"BTC-USDT","action":"update","ts":"1776816022380","asks":[["76363.3","0","0"],["76467.1","0.00181702","1"]],"bids":[]}
{"instId":"BTC-USDT","action":"update","ts":"1776816022390","asks":[["76363.1","0.00654633","1"],["76363.2","0","0"]],"bids":[]}
{"instId":"BTC-USDT","action":"update","ts":"1776816022400","asks":[["76363.1","0","0"],["76363.3","0.00654634","1"]],"bids":[]}
{"instId":"BTC-USDT","action":"update","ts":"1776816022410","asks":[["76357.3","0.73370468","15"],["76381.8","0.01551436","1"],["76467.1","0","0"]],"bids":[["76336.3","0.0156384","1"],["76181.6","0","0"]]}
{"instId":"BTC-USDT","action":"update","ts":"1776816022450","asks":[],"bids":[["76320.6","0.11367457","2"]]}
{"instId":"BTC-USDT","action":"update","ts":"1776816022550","asks":[],"bids":[["76265.2","0","0"],["76246.2","0.015712","1"]]}
{"instId":"BTC-USDT","action":"update","ts":"1776816022610","asks":[["76357.3","0.73367849","15"]],"bids":[]}
{"instId":"BTC-USDT","action":"update","ts":"1776816022630","asks":[["76442.6","0.01374717","4"]],"bids":[]}
{"instId":"BTC-USDT","action":"update","ts":"1776816022730","asks":[["76363.3","0.16654634","2"]],"bids":[]}
{"instId":"BTC-USDT","action":"update","ts":"1776816022760","asks":[],"bids":[["76239.4","0","0"],["76181.6","0.00073364","2"]]}
{"instId":"BTC-USDT","action":"update","ts":"1776816022770","asks":[],"bids":[["76310","0.20303343","1"],["76181.6","0","0"]]}
{"instId":"BTC-USDT","action":"update","ts":"1776816022800","asks":[["76357.3","0.7336523","15"]],"bids":[]}
{"instId":"BTC-USDT","action":"update","ts":"1776816022840","asks":[["76381.8","0","0"],["76467.1","0.00181702","1"]],"bids":[["76337.2","0.01534073","1"],["76182.2","0","0"]]}
{"instId":"BTC-USDT","action":"update","ts":"1776816022970","asks":[["76357.3","0.73040443","14"]],"bids":[]}
{"instId":"BTC-USDT","action":"update","ts":"1776816023000","asks":[["76357.3","0.72984131","14"]],"bids":[["76320.6","0.11364593","1"],["76294.2","0","0"],["76182.2","0.00875","1"]]}
{"instId":"BTC-USDT","action":"update","ts":"1776816023010","asks":[["76357.3","0.72972345","14"]],"bids":[["76337.9","0.32733873","1"],["76337.6","0","0"],["76280.3","0.00361629","5"],["76274.3","0.00001319","1"]]}
{"instId":"BTC-USDT","action":"update","ts":"1776816023020","asks":[],"bids":[["76242.6","0.0051445","1"],["76182.2","0","0"]]}
{"instId":"BTC-USDT","action":"update","ts":"1776816023060","asks":[],"bids":[["76294.1","0.00323344","1"],["76182.7","0","0"]]}
{"instId":"BTC-USDT","action":"update","ts":"1776816023070","asks":[],"bids":[["76239.2","0.000655","1"],["76183.3","0","0"]]}
{"instId":"BTC-USDT","action":"update","ts":"1776816023100","asks":[["76357.3","0.72966452","14"]],"bids":[["76320.6","0.11367457","2"]]}
{"instId":"BTC-USDT","action":"update","ts":"1776816023110","asks":[["76357.3","0.72962524","14"]],"bids":[]}
{"instId":"BTC-USDT","action":"update","ts":"1776816023160","asks":[["76366.4","0.05896264","1"],["76366.8","0","0"],["76400","0.07344174","4"]],"bids":[["76340","0.05904384","2"],["76339.9","0.00004629","1"],["76285.4","0.05896264","1"],["76183.4","0","0"]]}
{"instId":"BTC-USDT","action":"update","ts":"1776816023170","asks":[],"bids":[["76285.5","0.04260956","1"],["76285.3","0","0"]]}
{"instId":"BTC-USDT","action":"update","ts":"1776816023210","asks":[["76357.3","0.72933713","13"]],"bids":[]}
{"instId":"BTC-USDT","action":"update","ts":"1776816023240","asks":[["76362.5","0.1953667","3"],["76363.3","0.16","1"]],"bids":[["76337.9","0","0"],["76335.8","0.00305","1"],["76334.5","0.33388598","2"]]}
{"instId":"BTC-USDT","action":"update","ts":"1776816023270","asks":[["76362.4","0.00654648","1"],["76362.5","0.18882021","2"],["76369.5","0.4793111","2"],["76371","0","0"],["76381.5","0.01569178","1"],["76467.1","0","0"]],"bids":[["76342","0.00656328","2"],["76334.6","0.33388584","2"],["76334.5","0","0"]]}
{"instId":"BTC-USDT","action":"update","ts":"1776816023280","asks":[],"bids":[["76269.3","0.071281","1"],["76183.7","0","0"]]}
{"instId":"BTC-USDT","action":"update","ts":"1776816023300","asks":[["76357.3","0.73082713","14"],["76369.5","0.47276434","1"],["76371","0.00654677","1"],["76466.7","0","0"]],"bids":[["76334.7","0.00655993","2"],["76334.6","0.32733908","1"]]}
{"instId":"BTC-USDT","action":"update","ts":"1776816023310","asks":[["76357.3","0.71773081","14"],["76369.3","0.33388264","2"],["76371","0","0"],["76466.7","0.00025453","6"]],"bids":[]}
{"instId":"BTC-USDT","action":"update","ts":"1776816023360","asks":[["76369.3","0.32733586","1"],["76371","0.00654676","1"],["76466.7","0","0"]],"bids":[]}
{"instId":"BTC-USDT","action":"update","ts":"1776816023380","asks":[["76357.3","0.71750163","14"]],"bids":[]}
{"instId":"BTC-USDT","action":"update","ts":"1776816023400","asks":[["76381.5","0","0"],["76466.7","0.00025453","6"]],"bids":[]}
{"instId":"BTC-USDT","action":"update","ts":"1776816023510","asks":[["76369.5","0.47931111","2"],["76371","0","0"],["76421.3","0","0"],["76467.1","0.00181702","1"],["76467.2","0.00011781","1"]],"bids":[]}
{"instId":"BTC-USDT","action":"update","ts":"1776816023540","asks":[["76380.5","0.14655291","2"]],"bids":[]}
{"instId":"BTC-USDT","action":"update","ts":"1776816023570","asks":[["76421.3","0.00003967","1"],["76467.2","0","0"]],"bids":[]}
{"instId":"BTC-USDT","action":"update","ts":"1776816023720","asks":[["76362.4","0.16654648","2"]],"bids":[]}
{"instId":"BTC-USDT","action":"update","ts":"1776816023770","asks":[["76357.3","0.71699089","14"]],"bids":[]}
{"instId":"BTC-USDT","action":"update","ts":"1776816023800","asks":[["76357.3","0.7169647","14"]],"bids":[]}
{"instId":"BTC-USDT","action":"update","ts":"1776816023810","asks":[["76357.3","0.71671588","14"]],"bids":[]}
{"instId":"BTC-USDT","action":"update","ts":"1776816023900","asks":[["76357.3","0.7166635","14"],["76369.5","0.47276434","1"],["76371","0.00654677","1"],["76467.1","0","0"]],"bids":[]}
{"instId":"BTC-USDT","action":"update","ts":"1776816023910","asks":[["76357.3","0.71659802","14"]],"bids":[["76280.3","0.00362825","6"],["76279.1","0","0"],["76183.7","0.00001319","1"]]}
{"instId":"BTC-USDT","action":"update","ts":"1776816023920","asks":[],"bids":[["76320.6","0.11364593","1"],["76305.3","0.34708852","2"],["76303.2","0.00001033","1"]]}
{"instId":"BTC-USDT","action":"update","ts":"1776816023930","asks":[["76355.1","1.96552537","22"],["76355.2","0.00637209","2"],["76356.6","0.09563","1"],["76357.2","0.52766292","4"],["76357.3","0.25354332","7"],["76361.5","0.016159","2"],["76362.3","1.08958137","2"],["76364.8","0.32733958","1"],["76369.3","0","0"],["76372.6","0","0"],["76391.5","0.11056284","1"],["76401.3","0","0"],["76406.7","0","0"],["76411.4","0","0"],["76462.1","0","0"],["76466.6","0","0"],["76466.7","0","0"]],"bids":[["76357.2","0","0"],["76356.5","0","0"],["76355.6","0","0"],["76355.1","0","0"],["76347.2","0","0"],["76346.9","0","0"],["76346.7","0","0"],["76346.4","0","0"],["76340.3","0","0"],["76340","0.0000812","1"],["76337.7","0","0"],["76337.5","0","0"],["76337.2","0","0"],["76336.3","0","0"],["76334.6","0","0"],["76334.4","0.0000168","1"],["76331.2","0","0"],["76331.1","0","0"],["76327.9","0","0"],["76326.7","0","0"],["76326.6","0.00023743","5"],["76324.7","0","0"],["76323.9","0.48765892","2"],["76322.6","0","0"],["76320.7","1.47731148","2"],["76320.5","0","0"],["76319.3","0.00040006","1"],["76317.6","0","0"],["76314.6","0.47152624","2"],["76313.4","0","0"],["76310.1","1.0057984","1"],["76307.2","0.47476518","2"],["76307","0","0"],["76303.8","0.47151308","1"],["76303.6","0","0"],["76303.4","0","0"],["76302.7","0","0"],["76254.2","0.00001316","1"],["76221","0.08378297","1"],["76212.1","0","0"],["76211.3","0.08378297","1"],["76200","1.01915437","52"],["76193.3","1.0057984","1"],["76184.3","1.0057984","1"],["76183.4","0.00005866","1"],["76183.3","0.00009283","1"],["76182.7","0.00002401","2"],["76182.2","0.00875","1"],["76181.6","0.00073364","2"],["76180","0.0000812","1"],["76179.9","0.47151308","1"],["76179.3","0.00040006","1"],["76178.9","0.0008637","1"],["76177.9","0.00004571","1"],["76177.8","0.00105547","4"],["76175.4","0.00003868","3"],["76175.1","0.47151308","1"],["76175","0.00029601","2"],["76173.9","0.00399999","1"],["76173.7","0.00070045","3"],["76173.6","0.00002308","1"],["76173.2","0.00001006","1"],["76173","0.00001059","1"],["76171.1","0.00001024","1"]]}
