{"instId":"BTC-USDT","action":"snapshot","ts":"1776816000000","asks":[["76329.7","0.13003527","6"],["76330.4","0.0128637","1"],["76333.3","0.00501033","3"],["76334.6","0.00001316","1"],["76337.2","0.00001501","1"],["76338","0.17764287","2"],["76338.1","0.47151308","1"],["76338.2","0.12356131","1"],["76338.5","0.14284888","1"],["76339.2","0.0471715","1"],["76339.3","0.00040006","1"],["76340","0.0000812","1"],["76341.3","0.00001316","1"],["76341.6","0.00654809","1"],["76341.7","0.47151308","1"],["76342.2","0.23708665","1"],["76342.4","0.11425593","1"],["76342.8","0.092076","1"],["76343.4","0.07996","1"],["76344.7","0.00001316","1"],["76344.8","0.00001501","1"],["76345","0.26532446","4"],["76345.7","0.47151308","1"],["76345.9","0.0001176","1"],["76346.3","0.036","1"],["76346.9","0.00466407","1"],["76347.5","0.41121276","2"],["76347.6","0.08017","1"],["76347.9","0.33453603","2"],["76348.1","0.00001316","1"],["76348.3","0.12086012","1"],["76349.1","0.01048184","4"],["76349.6","1.00616208","1"],["76349.7","0.31002424","2"],["76349.9","0.00654853","1"],["76350","0.51433992","3"],["76351.4","0.00001316","1"],["76352.4","0.00001501","1"],["76352.8","0.1305","1"],["76353","0.08378297","1"],["76353.2","0.1318474","1"],["76353.3","0.06550536","1"],["76353.4","0.00110723","2"],["76353.9","0.00041665","1"],["76354.6","0.00007242","1"],["76354.8","0.00001316","1"],["76355.2","0.00162963","1"],["76356.1","0.01598532","1"],["76356.5","0.00009101","2"],["76357.1","0.03854171","1"],["76357.2","0.12911797","2"],["76357.4","0.08378297","1"],["76357.5","0.53806248","1"],["76357.6","0.47151308","1"],["76358.1","0.00001316","1"],["76358.4","0.01191549","1"],["76358.7","0.00009428","2"],["76358.9","0.01614584","1"],["76359.3","0.00040006","1"],["76359.5","0.01343418","1"],["76360","0.00011122","3"],["76360.3","0.00013118","1"],["76360.5","1.00728137","3"],["76361.5","0.00001316","1"],["76361.8","0.1405697","2"],["76361.9","0.1305","1"],["76363.1","0.14008787","1"],["76363.2","0.08378297","1"],["76363.3","0.12631688","1"],["76364.9","0.00001316","1"],["76367.4","0.29343","1"],["76367.6","0.00001501","1"],["76367.9","0.0004915","1"],["76368","0.45309286","3"],["76368.2","1.00612779","2"],["76368.8","0.00019344","1"],["76369.1","0.06450074","1"],["76369.5","0.08378297","1"],["76369.6","0.31627447","2"],["76369.7","0.81732108","2"],["76370.7","0.1305","1"],["76371.2","0.01309664","1"],["76371.6","0.00001316","1"],["76372.7","0.70441203","1"],["76372.8","0.47151308","1"],["76374","0.06548111","1"],["76374.3","0.04647472","5"],["76374.4","0.00019121","1"],["76374.9","0.00001316","1"],["76375.2","0.12358895","2"],["76375.3","0.08378297","1"],["76375.4","1.00626755","1"],["76376","0.00001","1"],["76376.4","0.39656335","1"],["76376.5","0.47151308","1"],["76376.9","0.04827609","1"],["76378.1","0.03654","2"],["76378.3","0.00001316","1"],["76378.7","0.00130926","1"],["76379.3","0.00040006","1"],["76379.8","0.65986","1"],["76379.9","0.10955686","1"],["76380","0.0000812","1"],["76380.2","0.08378297","1"],["76380.5","0.01614584","1"],["76381.1","0.00130922","1"],["76381.6","0.64506946","2"],["76381.7","0.47152624","2"],["76381.8","1.66368079","2"],["76381.9","0.18783","1"],["76382.2","0.02618973","1"],["76382.7","0.0008","1"],["76382.8","0.000015","1"],["76384.1","0.37146119","4"],["76384.2","0.1305","1"],["76385","0.00001316","1"],["76385.4","0.00076482","1"],["76385.7","0.47151308","1"],["76386.6","0.14008787","1"],["76386.7","0.1","1"],["76386.9","0.19645473","1"],["76387.8","0.49341866","1"],["76388.1","0.08378297","1"],["76388.4","0.00001316","1"],["76388.9","1.00601579","1"],["76389","0.47151308","1"],["76390.4","0.000015","1"],["76391.2","0.345789","1"],["76391.7","0.00001316","1"],["76392","0.06396739","1"],["76392.1","0.08378297","1"],["76393.9","0.00004006","1"],["76394","0.1305","1"],["76395.1","0.00001316","1"],["76395.3","0.01907785","1"],["76395.4","0.47151308","1"],["76395.9","0.77808826","1"],["76396","1.00808","1"],["76397.3","0.02108","1"],["76397.9","0.08378297","1"],["76398","0.000015","1"],["76398.2","0.00001501","1"],["76398.3","1.00601579","1"],["76398.5","0.00001316","1"],["76398.6","0.01614584","1"],["76398.7","0.47151308","1"],["76399.3","0.00040006","1"],["76399.6","0.00615631","3"],["76399.7","0.17008181","1"],["76400","0.0144791","3"],["76401.8","0.08379613","2"],["76401.9","0.47151308","1"],["76402.8","0.09979188","1"],["76402.9","0.1305","1"],["76405.2","0.00001316","1"],["76405.6","0.00001501","1"],["76406","0.08378297","1"],["76406.4","0.12","1"],["76408.4","0.17725471","1"],["76408.5","0.47152624","2"],["76409.3","0.12","1"],["76409.9","0.0022919","1"],["76410.5","0.08378297","1"],["76410.8","0.44573859","1"],["76410.9","1.00557452","1"],["76411.6","0.47151308","1"],["76411.7","0.00001316","1"],["76412.8","0.01614584","1"],["76413.2","0.00001501","1"],["76414.4","0.61628941","2"],["76414.5","1.539751","1"],["76414.7","0.47151308","1"],["76415.3","0.00001316","1"],["76415.4","0.02618272","1"],["76416.6","0.1305","1"],["76417.5","0.08378297","1"],["76417.7","1.00540865","1"],["76417.8","0.47151308","1"],["76418.6","0.00001316","1"],["76418.8","0.00285576","1"],["76419.2","0.06554905","1"],["76419.3","0.00040006","1"],["76419.5","0.01197252","5"],["76419.6","0.97073","1"],["76420","0.0000812","1"],["76420.1","0.00001316","1"],["76420.3","0.015718","1"],["76420.8","0.000015","1"],["76421.4","0.08378297","1"],["76421.5","0.47151308","1"],["76422.4","0.00015119","1"],["76423","0.02408827","1"],["76423.1","0.00051072","2"],["76423.2","0.00057901","7"],["76423.3","0.00004221","2"],["76423.5","0.00005351","2"],["76424","0.00059452","2"],["76424.2","0.00124337","2"],["76424.4","0.00430613","1"],["76424.5","0.0001315","1"],["76424.6","0.00016335","2"],["76424.8","0.01904496","3"],["76425","0.01765762","10"],["76425.4","0.0004204","2"],["76425.5","0.00036659","1"],["76425.6","1.68798445","5"],["76425.7","1.03905224","3"],["76426","0.08378297","1"],["76426.1","0.47151308","1"],["76426.2","0.00006261","1"],["76426.4","0.00001026","1"],["76426.6","0.00002765","1"],["76426.7","0.00001229","1"],["76426.8","0.00004884","3"],["76427.1","0.13059998","5"],["76427.2","0.00053273","6"],["76427.4","0.00561292","2"],["76427.7","0.13230938","2"],["76427.8","0.00105178","9"],["76428.3","0.06012367","3"],["76428.4","0.00001501","1"],["76428.5","0.02469065","35"],["76428.7","0.00006306","4"],["76428.8","0.01598","1"],["76429.2","0.00009765","1"],["76429.3","0.00004352","2"],["76429.4","0.0004076","1"],["76429.6","0.00001048","1"],["76429.7","0.00001021","1"],["76430","0.00689082","5"],["76430.2","0.00001198","1"],["76430.3","0.01620403","2"],["76430.4","0.00011073","1"],["76430.5","0.06000407","1"],["76430.6","0.00003637","1"],["76430.7","0.47152498","2"],["76430.9","0.00021283","2"],["76431.2","0.00007378","1"],["76431.8","0.01115278","7"],["76432.2","0.00007195","1"],["76432.4","0.00159966","1"],["76432.5","0.08378297","1"],["76432.8","0.00002941","1"],["76432.9","0.00013582","5"],["76433","0.00006158","2"],["76433.1","0.00005361","1"],["76433.3","0.00524642","2"],["76433.8","0.00001252","1"],["76434","0.00001968","1"],["76434.2","0.00001051","1"],["76434.4","0.47152814","2"],["76434.5","0.00085432","2"],["76434.7","0.0008618","6"],["76435.1","0.00001253","1"],["76435.3","0.00006341","1"],["76435.5","0.00003647","1"],["76435.7","0.00014757","3"],["76436","0.00004959","2"],["76436.2","0.00001003","1"],["76436.4","1.00649979","4"],["76436.5","0.0001704","3"],["76436.6","0.00054","1"],["76436.7","0.00521668","7"],["76436.9","0.00001316","1"],["76437","0.00001091","1"],["76437.1","0.00001264","1"],["76437.3","0.08378297","1"],["76437.4","0.22843154","2"],["76437.5","0.40944268","6"],["76437.9","0.00001004","1"],["76438.2","0.00002942","1"],["76438.3","0.00005159","3"],["76438.4","0.13754939","4"],["76438.5","0.00115239","6"],["76438.6","0.00007644","1"],["76438.8","0.00044174","3"],["76439","0.00007251","1"],["76439.1","0.47155842","2"],["76439.2","0.01458129","2"],["76439.3","0.00040006","1"],["76439.6","0.00023181","1"],["76439.7","0.00005078","4"],["76439.8","0.00005849","3"],["76439.9","0.0000262","1"],["76440","0.01150708","9"],["76440.5","0.00001071","1"],["76440.6","0.00027189","1"],["76440.7","0.00093716","1"],["76440.8","0.00016313","4"],["76440.9","0.00005388","1"],["76441.1","0.00016","2"],["76441.4","0.01227017","6"],["76441.5","0.00009049","3"],["76441.6","0.01614584","1"],["76441.8","0.00014656","1"],["76442","0.00100116","1"],["76442.1","0.00001068","1"],["76442.2","0.08381054","2"],["76442.3","0.47170789","6"],["76442.4","0.56759583","2"],["76442.5","0.00136187","7"],["76442.6","0.00022069","3"],["76442.8","0.59991129","2"],["76443","0.00008096","1"],["76443.1","0.0004837","5"],["76443.3","0.00015859","1"],["76443.6","0.00001501","1"],["76444","0.00078619","1"],["76444.1","0.00033322","3"],["76444.4","0.00167389","9"],["76444.6","0.00066512","2"],["76444.9","0.00002274","1"],["76445","0.00001015","1"],["76445.1","0.00152413","5"],["76445.3","0.0003737","5"],["76445.5","0.00001146","1"],["76445.6","0.00018384","2"],["76445.8","0.00002809","1"],["76445.9","0.01209412","7"],["76446","0.01046488","4"],["76446.1","0.13054323","2"],["76446.3","0.00011017","1"],["76446.6","1.00642396","2"],["76446.7","0.08386191","3"],["76446.9","0.47153942","2"],["76447.2","0.00012939","4"],["76447.4","0.00007042","1"],["76447.5","0.00002945","1"],["76447.7","0.00038045","2"],["76447.8","0.02398134","1"],["76447.9","0.01242054","1"],["76448","0.0162339","4"],["76448.1","0.00069773","1"],["76448.2","0.00012531","1"],["76448.3","0.00015607","2"],["76448.5","0.00004244","1"],["76448.9","0.00005808","2"],["76449","0.00014225","2"],["76449.2","0.00001126","1"],["76449.4","0.00020378","1"],["76449.5","0.00001053","1"],["76449.6","0.00056676","3"],["76449.9","0.00006845","2"],["76450","0.52381874","29"],["76450.2","0.00003521","3"],["76450.5","0.00018441","6"],["76450.6","0.00001207","1"],["76451.2","0.00011166","3"],["76451.3","0.00002592","1"],["76451.4","0.00014455","1"],["76451.5","0.00051422","3"],["76451.6","0.00108047","16"],["76451.7","0.09250402","2"],["76451.9","0.00001249","1"],["76452","0.00005546","1"],["76452.1","0.08378297","1"],["76452.2","0.47151308","1"],["76452.3","0.00012963","1"],["76452.5","0.00004469","1"],["76452.8","0.00032341","2"],["76452.9","0.00028896","1"],["76453","0.00588293","1"],["76453.1","0.00107","1"],["76453.2","0.00252641","4"],["76453.4","0.00001152","1"],["76453.6","0.00041787","5"],["76453.8","0.1305","1"],["76454","0.00129878","1"],["76454.1","0.00005044","1"],["76454.4","0.00001199","1"],["76454.5","0.01443419","9"],["76454.6","0.00001058","1"],["76454.7","0.00017834","1"],["76455","0.00072315","1"],["76455.4","0.000028","2"],["76455.5","0.00029209","1"],["76455.6","0.00014024","3"],["76456","0.47151308","1"],["76456.1","0.0002254","1"],["76456.2","0.00007359","1"],["76456.3","0.00003643","1"],["76456.4","0.00002957","1"],["76456.7","0.00135308","2"],["76457.1","0.01564436","4"],["76457.2","0.00001568","1"],["76457.3","1.00617669","2"],["76457.4","0.00002231","1"],["76457.5","0.00001001","1"],["76457.6","0.00199545","1"],["76457.8","0.00026388","1"],["76457.9","0.00003026","1"],["76458.1","0.00001883","1"],["76458.3","0.00035006","7"],["76458.4","0.0000711","2"],["76458.7","0.01614584","1"],["76458.8","0.00001501","1"],["76459.1","0.00006716","3"],["76459.2","0.08410468","3"],["76459.3","0.02370703","3"],["76459.6","0.00072458","2"]],"bids":[["76329.6","0.51998617","11"],["76328.2","0.0000975","1"],["76325.4","0.33039108","2"],["76325.3","0.23397247","3"],["76325.2","0.1","1"],["76325.1","0.1","1"],["76325","0.12911378","1"],["76324.6","0.00001316","1"],["76323.7","0.09563","1"],["76323","0.0262","1"],["76322.5","0.01791841","1"],["76321.9","0.0065631","2"],["76321.8","0.036","1"],["76321.3","0.00001316","1"],["76320.1","0.024","1"],["76319.2","0.04366673","1"],["76318.4","0.00011192","2"],["76318.1","0.00261949","1"],["76317.9","0.0032721","2"],["76317.3","0.11886983","2"],["76317.2","0.00786192","3"],["76317","0.0001326","4"],["76316.6","0.01337303","1"],["76315.7","0.0000463","1"],["76315.3","0.00001681","1"],["76314.7","0.00654849","1"],["76314.6","0.32755487","4"],["76314.5","0.55138816","2"],["76314.3","0.000015","1"],["76314.1","0.1305","1"],["76313.3","0.08378297","1"],["76313.2","0.47162379","3"],["76313.1","1.00616208","1"],["76313","0.12082785","1"],["76312.5","0.00010586","1"],["76312.3","0.01603086","1"],["76311.8","0.00009288","5"],["76311.7","0.00001034","1"],["76311.5","0.00001681","1"],["76311.4","0.00001155","1"],["76311.2","0.00001316","1"],["76311","0.00305","1"],["76310.9","0.02508","1"],["76310.8","0.00011193","2"],["76309.4","0.0156931","3"],["76308.6","0.08378297","1"],["76308.5","0.17765122","1"],["76308.3","0.47151308","1"],["76308","0.12362023","2"],["76307.9","0.00001316","1"],["76307.7","0.00001681","1"],["76307.6","0.30279","1"],["76307.5","0.38363291","2"],["76307","0.00011193","2"],["76306.7","0.00001501","1"],["76306.5","1.00616208","1"],["76306.4","0.13051034","2"],["76306.1","0.06550536","1"],["76305.9","0.00001086","1"],["76305.8","0.00001155","1"],["76305.6","0.00012105","3"],["76304.5","0.00001316","1"],["76304.3","0.00738407","1"],["76304.2","0.00004629","1"],["76303.8","0.0000168","1"],["76303.5","0.34618162","1"],["76303.4","0.47151308","1"],["76303.3","0.08378297","1"],["76303.2","0.12444319","4"],["76302.8","0.00523898","1"],["76301.8","0.00011072","2"],["76301.1","0.00002351","2"],["76300.4","0.00309629","2"],["76300.3","0.47151308","1"],["76300.2","0.09208755","2"],["76300","0.00360919","5"],["76299.8","0.01614584","1"],["76299.4","0.00001033","1"],["76299.3","0.00051199","3"],["76299.1","0.24566059","3"],["76299","0.26189135","4"],["76298.6","0.00001456","1"],["76298","0.00001","1"],["76297.9","0.00011073","2"],["76297.8","0.00001316","1"],["76297.7","0.00683253","1"],["76296.7","0.14283469","1"],["76296.6","0.13054629","2"],["76296.3","0.98647666","2"],["76296.2","1.47769196","3"],["76295.8","0.00001035","1"],["76295.5","0.00011193","2"],["76295.2","0.08378297","1"],["76294.6","0.00001155","1"],["76294.4","0.00001316","1"],["76294.2","0.12083871","2"],["76294.1","0.00012159","3"],["76293.2","0.69341833","3"],["76293.1","0.2822","1"],["76292.8","0.00002863","1"],["76292.7","0.47155938","2"],["76292.6","0.06497758","1"],["76292.5","0.2053285","1"],["76292.4","0.0000168","1"],["76291.7","0.00011193","2"],["76291.5","0.000015","1"],["76291.1","0.66064016","2"],["76290.5","0.00132112","2"],["76290.3","0.00011073","2"],["76289.6","0.08378297","1"],["76289.5","0.47151308","1"],["76289.3","0.0015","1"],["76289","0.00001155","1"],["76288.9","0.1000463","2"],["76288.6","0.00132761","2"],["76288.5","0.00001934","1"],["76288.2","0.00001086","1"],["76287.9","0.00011193","2"],["76287.7","0.00001316","1"],["76287.3","0.12162551","2"],["76287","0.00001034","1"],["76286.5","0.12642918","3"],["76285.2","0.08379332","2"],["76285.1","0.0000463","1"],["76284.8","0.69740282","1"],["76284.7","0.47154922","3"],["76284.4","0.00001316","1"],["76284.1","1.00627402","3"],["76284","0.02618973","1"],["76283.9","0.000015","1"],["76283.8","0.00785886","1"],["76283.5","0.000015","1"],["76282.7","0.00011073","2"],["76282.3","0.00001087","1"],["76282.2","0.1305","1"],["76281.6","0.47151308","1"],["76281.3","0.0000463","1"],["76281.2","0.22226179","2"],["76281","0.00001316","1"],["76280.9","0.00003614","2"],["76280.8","0.00001034","1"],["76280.2","0.00011192","2"],["76280","0.0000812","1"],["76279.4","0.00325321","1"],["76279.3","0.00040006","1"],["76279.1","0.00001196","1"],["76278.8","0.0001326","4"],["76278.5","0.47151308","1"],["76277.7","0.11489615","1"],["76277.6","0.00001316","1"],["76277.5","0.0000463","1"],["76277.4","0.000012","1"],["76277.1","0.00003615","2"],["76276.5","0.00233681","1"],["76276.4","0.00011192","2"],["76276.3","0.00001501","1"],["76275","0.00011071","2"],["76274.9","0.01905406","1"],["76274.8","0.2871994","2"],["76274.7","0.47151308","1"],["76274.5","0.1305","1"],["76274.3","0.00346912","4"],["76274.1","0.01045","1"],["76274","0.0654833","1"],["76273.6","0.00004659","4"],["76273.5","0.00001034","1"],["76273.3","0.33242319","3"],["76273.2","1.00617363","2"],["76272.6","0.00011193","2"],["76272.1","0.00717416","1"],["76271.2","0.00011072","2"],["76270.9","0.00001316","1"],["76270.8","0.08378297","1"],["76270.5","0.01614584","1"],["76269.5","0.00001681","1"],["76269.4","0.00001934","1"],["76269.2","0.16589954","1"],["76268.8","0.00011193","2"],["76268.7","0.000015","1"],["76268.2","0.00001034","1"],["76267.7","0.00001086","1"],["76267.6","0.00002471","2"],["76267.4","0.00012105","3"],["76266.6","0.00323393","1"],["76266.5","0.01047876","1"],["76266.1","0.47151308","1"],["76266","0.08378297","1"],["76265.9","0.64408128","1"],["76265.6","0.00001935","1"],["76265","0.00011193","2"],["76264.2","0.00001316","1"],["76263.9","0.1305","1"],["76263.8","0.03102","1"],["76263.6","0.00011072","2"],["76263.1","0.00008046","1"],["76262.9","0.00001035","1"],["76262.5","1.47767516","2"],["76262.1","0.00019775","1"],["76262","0.00001155","1"],["76261.8","0.00003021","2"],["76261.3","0.08378297","1"],["76261.2","0.00001033","1"],["76261.1","0.00012694","3"],["76260.9","0.00001316","1"],["76260.7","0.37307174","1"],["76260.6","1.00127","1"],["76260.4","0.00001456","1"],["76260.3","0.00065564","1"],["76260","0.00012924","2"],["76259.7","0.00011073","2"],["76259.3","0.00040006","1"],["76259","0.47151308","1"],["76258.2","0.64421504","2"],["76258.1","0.345716","1"],["76258","0.00001935","1"],["76257.6","0.00001035","1"],["76257.5","0.00014429","2"],["76257.3","0.94658193","3"],["76256.7","0.08378297","1"],["76256.6","0.345752","1"],["76256.4","0.00001155","1"],["76256","0.00001086","1"],["76255.9","0.00012159","3"],["76255.4","0.00054","1"],["76255","0.00001033","1"],["76254.2","0.00003251","2"],["76253.5","0.52449808","4"],["76253.4","1.47767516","2"],["76253.3","0.1305","1"],["76252.3","0.06459369","2"],["76252.2","0.00001316","1"],["76252.1","0.00011073","2"],["76251.3","0.08378297","1"],["76250.8","0.00001155","1"],["76250.1","0.23245436","1"],["76250","0.73397677","5"],["76249.9","0.00144782","1"],["76249.7","0.00011193","2"],["76249.1","0.0130988","1"],["76248.9","0.00054219","1"],["76248.8","0.01328397","2"],["76248.3","0.00011073","2"],["76248.1","0.01614584","1"],["76247.4","0.00001316","1"],["76247","0.00001035","1"],["76246.3","0.66299503","2"],["76245.9","0.00012695","3"],["76245.8","0.01904","1"],["76245.7","0.08378297","1"],["76245.6","0.1305","1"],["76245.3","1.553421","2"],["76245.1","0.05510203","1"],["76244.5","0.00011073","2"],["76244.2","0.47151308","1"],["76244.1","0.00002403","2"],["76243.9","0.00001316","1"],["76243.1","0.9384457","1"],["76243","1.543211","1"],["76242.6","0.00001034","1"],["76242.1","0.03980678","1"],["76241.8","0.00006558","1"],["76241.3","0.08378297","1"],["76240","0.0000812","1"],["76239.9","1.00540075","1"],["76239.3","0.00040006","1"],["76238.3","0.00001501","1"],["76238","0.13396803","1"],["76237.9","0.14664584","2"],["76237.4","0.00001316","1"],["76237.3","0.12","1"],["76237.1","0.08378297","1"],["76236.9","0.09836215","2"],["76235.2","0.00010329","1"],["76235.1","0.27216828","1"],["76235","0.47151308","1"],["76234.7","0.01014439","1"],["76234","0.00001316","1"],["76233.8","0.12","1"],["76233.6","0.00548356","1"],["76233.3","0.29004237","1"],["76232.3","0.01458998","1"],["76230.9","0.47151308","1"],["76230.8","0.41122919","1"],["76230.7","1.00554607","3"],["76230.6","0.12","1"],["76230.3","0.00069843","2"],["76230.2","0.1305","1"],["76228.4","0.00090772","1"],["76227.9","0.01629251","2"],["76227.3","0.00001316","1"],["76225.8","0.47151308","1"],["76225.4","0.320657","1"],["76225.2","0.00007188","1"],["76224","0.00001897","1"],["76223.1","0.00001501","1"],["76222.5","0.1305","1"],["76221.3","0.00041462","1"],["76220.6","0.00001316","1"],["76220","0.00021363","2"],["76219.9","0.00002623","1"],["76219.7","1.00551791","1"],["76219.6","0.47151308","1"],["76219.3","0.00068651","2"],["76219","0.00002113","2"],["76218.3","0.01496","1"],["76216.2","0.00514629","1"],["76216.1","0.015717","1"],["76214.8","0.1305","1"],["76214","0.01614584","1"],["76213.9","0.00001316","1"],["76213.6","0.00001335","1"],["76213","0.0000158","1"],["76212.9","0.000655","1"],["76211.8","0.00001008","1"],["76211.6","0.00002399","1"],["76211.2","1.00595385","1"],["76211.1","7.15599","2"],["76210.8","0.00107","1"],["76210.4","0.47155961","2"],["76210.1","0.00008247","1"],["76210","0.00001041","1"],["76208.8","0.01614584","1"],["76207.8","0.0010915","1"],["76207.2","0.00285748","1"],["76207.1","0.130515","2"],["76206.9","0.014","1"],["76206.6","0.00021397","1"],["76205.7","0.00024241","1"],["76204.9","0.00124273","7"],["76204.2","0.00022727","1"],["76203.8","0.00001316","1"],["76203","0.09846","1"],["76202.4","0.47151308","1"],["76200.8","0.02500337","1"],["76200.5","0.00001319","1"],["76200.1","0.05812501","1"],["76200","1.01929665","52"],["76199.4","0.1305","1"],["76199.3","0.00040006","1"],["76198.2","0.04493904","1"],["76197.5","0.00107799","1"],["76196.9","0.00801205","1"],["76196.5","0.00034725","1"],["76195.4","0.00098504","2"],["76195.1","0.01457366","1"],["76194.3","0.0018792","9"],["76194.2","0.01173066","1"],["76193.7","0.00009338","1"],["76193.4","1.39953124","2"],["76193.3","1.00611463","1"],["76193.2","0.47151308","1"],["76193.1","0.00004445","1"],["76192.3","2.54203491","4"],["76192.2","0.00007834","2"],["76191.7","0.1305","1"],["76191.2","0.0000842","4"],["76191","0.00014147","1"],["76190.9","0.00015413","4"],["76190.4","0.00001319","1"],["76190","0.00001428","1"],["76188.9","0.00002109","2"],["76188.7","0.00047516","7"],["76188.3","0.00001061","1"],["76188","0.00303","1"],["76187.9","0.00001002","1"],["76187.7","0.47151308","1"],["76187.6","6.31502","1"],["76187.5","0.00032499","3"],["76187","0.00011911","5"],["76186.5","0.00001197","1"],["76186.4","0.00022771","1"],["76186","0.00170529","1"],["76185.3","0.00002512","1"],["76184.8","0.01614584","1"],["76184.3","1.00616208","1"],["76184.1","0.47151308","1"],["76184","0.1305","1"],["76183.9","0.00003806","1"],["76183.7","0.00001319","1"],["76183.4","0.00005866","1"],["76183.3","0.00009283","1"],["76183","0.01496","1"],["76182.7","0.00002401","2"],["76182.2","0.00875","1"],["76181.6","0.00073364","2"],["76180.1","0.00013128","1"],["76180","0.0000812","1"],["76179.9","0.47151308","1"],["76179.3","0.00040006","1"],["76178.9","0.0008637","1"],["76177.9","0.00004571","1"],["76177.8","0.00105547","4"],["76176.3","0.1305","1"],["76175.4","0.00003868","3"],["76175.1","0.47151308","1"],["76175","0.00029601","2"],["76173.7","0.00070045","3"],["76173.6","0.00002308","1"],["76173.2","0.00001006","1"],["76173","0.00001059","1"]]}
{"instId":"BTC-USDT","action":"update","ts":"1776816000010","asks":[["76347.4","0.32742987","1"],["76347.5","0.08378297","1"],["76349","0.00654853","1"],["76349.9","0","0"],["76353.3","0","0"],["76379.8","0","0"],["76381.8","1.00601579","1"],["76414.5","0","0"],["76425.6","0.13824145","4"],["76459.7","0.0000534","1"],["76459.8","0.00203787","4"]],"bids":[["76314.7","0","0"],["76314.6","0.3341034","5"],["76306.1","0","0"],["76293.2","0.03499033","2"],["76291.1","0.00001316","1"],["76278.6","0.17506449","1"],["76245.3","0.000015","1"],["76231","0.08378297","1"]]}
{"instId":"BTC-USDT","action":"update","ts":"1776816000020","asks":[["76376.4","0.19930538","1"],["76419.5","0.07752538","6"]],"bids":[["76314.6","0.32755487","4"],["76314.2","0.00654853","1"],["76246.3","0.21607451","1"],["76173","0","0"]]}
{"instId":"BTC-USDT","action":"update","ts":"1776816000030","asks":[["76351.4","0.06551848","2"]],"bids":[["76316.5","0.06550532","1"],["76173.2","0","0"]]}
{"instId":"BTC-USDT","action":"update","ts":"1776816000040","asks":[["76424.6","0.65746035","3"]],"bids":[["76321.9","0.00001501","1"],["76320.2","0.00654811","1"],["76314.2","0","0"],["76313.4","0.00654853","1"],["76274.8","0.9457864","3"],["76173.6","0","0"]]}
{"instId":"BTC-USDT","action":"update","ts":"1776816000050","asks":[["76420.8","0.659522","2"]],"bids":[["76271","0.660801","1"],["76225.2","1.55388688","2"],["76173.7","0","0"]]}
{"instId":"BTC-USDT","action":"update","ts":"1776816000060","asks":[],"bids":[["76321.9","0.00656318","2"],["76320.2","0","0"],["76314.2","0.00654854","1"],["76313.4","0","0"],["76173.7","0.00070045","3"]]}
{"instId":"BTC-USDT","action":"update","ts":"1776816000070","asks":[],"bids":[["76238","0.25396803","2"],["76230.6","0","0"],["76173.6","0.00002308","1"]]}
{"instId":"BTC-USDT","action":"update","ts":"1776816000080","asks":[],"bids":[["76321.9","0.00001501","1"],["76320.2","0.0065481","1"],["76314.2","0","0"],["76313.4","0.00654854","1"],["76173.6","0","0"]]}
{"instId":"BTC-USDT","action":"update","ts":"1776816000100","asks":[["76329.7","0.09383127","6"],["76349","0","0"],["76349.5","0.00654851","1"]],"bids":[["76321.9","0.00656307","2"],["76320.2","0","0"],["76316.6","0.34080163","2"],["76314.6","0.00667359","4"],["76313.4","0","0"],["76173.6","0.00002308","1"],["76173.2","0.00001006","1"]]}
{"instId":"BTC-USDT","action":"update","ts":"1776816000110","asks":[["76351.4","0.00001316","1"]],"bids":[["76319.2","0.1553748","2"]]}
{"instId":"BTC-USDT","action":"update","ts":"1776816000120","asks":[["76330.4","0","0"],["76333","0.01242366","1"],["76341.6","0","0"],["76342.7","0.00654807","1"],["76347.4","0","0"],["76348.2","0.32742862","1"],["76349.5","0","0"],["76352.7","0.00654851","1"]],"bids":[["76323.1","0.00654807","1"],["76321.9","0.00001501","1"],["76319.2","0.16997784","3"],["76317.4","0.32742862","1"],["76316.6","0","0"],["76314.7","0.00654851","1"],["76314.6","0.00012508","3"],["76173.6","0","0"],["76173.2","0","0"]]}
{"instId":"BTC-USDT","action":"update","ts":"1776816000130","asks":[["76342.7","0","0"],["76343.3","0.0065482","1"],["76348.2","0","0"],["76349.5","0.32742841","1"],["76352.6","0.00654851","1"],["76352.7","0","0"]],"bids":[]}
{"instId":"BTC-USDT","action":"update","ts":"1776816000140","asks":[["76329.7","0.064776","3"],["76343.3","0","0"],["76344.9","0.00654812","1"],["76355.2","0.06713495","2"],["76356.1","0","0"],["76459.9","6.5913112","2"]],"bids":[["76329.6","0.52618617","12"],["76323.8","0.00654812","1"],["76323.1","0","0"]]}
{"instId":"BTC-USDT","action":"update","ts":"1776816000150","asks":[["76344.9","0","0"],["76345","0.10612978","2"],["76347.4","0.00654812","1"],["76347.5","0","0"],["76349.5","0","0"],["76352.6","0","0"],["76352.7","0.32742836","1"],["76353","0","0"],["76355.1","0.06515707","2"],["76357.1","0","0"],["76460","0.03539391","5"],["76460.1","0.0022005","4"],["76460.2","0.00162671","12"]],"bids":[["76325.5","0.00654812","1"],["76325.1","0.1262","2"],["76323.8","0","0"],["76323","0","0"],["76321.9","0.32743832","2"],["76320.2","0.00654841","1"],["76317.4","0","0"],["76314.7","0","0"],["76299","0.2109919","3"],["76173.6","0.00002308","1"],["76173.2","0.00001006","1"]]}
{"instId":"BTC-USDT","action":"update","ts":"1776816000160","asks":[["76338.1","0","0"],["76349.6","0","0"],["76354.5","0.00654828","1"],["76355.1","0.05860866","1"],["76460.6","0.00002799","2"]],"bids":[["76322.5","0.11967714","2"],["76320.2","0","0"],["76319.3","0.00654828","1"],["76319.2","0.05826977","2"]]}
{"instId":"BTC-USDT","action":"update","ts":"1776816000170","asks":[["76338","0.00001316","1"],["76347.5","0.06314025","1"],["76347.9","0","0"],["76349.5","1.00616208","1"],["76352.7","0","0"],["76353.1","0.32741881","1"],["76360.3","0.15930912","3"],["76460.6","0","0"]],"bids":[["76322","0.32741881","1"],["76321.9","0.00001501","1"],["76314.3","0.05089213","2"],["76173.2","0","0"]]}
{"instId":"BTC-USDT","action":"update","ts":"1776816000180","asks":[["76346.2","0.00654796","1"],["76347.4","0","0"],["76347.5","0.35540727","2"],["76352.7","0.32741927","1"],["76353.1","0","0"],["76353.8","0.00654832","1"],["76354.5","0","0"]],"bids":[["76322","0","0"],["76319.3","0.33396759","2"],["76173.2","0.00001006","1"]]}
{"instId":"BTC-USDT","action":"update","ts":"1776816000190","asks":[],"bids":[["76328.2","0","0"],["76319.3","0.32741927","1"],["76318.5","0.00654833","1"]]}
{"instId":"BTC-USDT","action":"update","ts":"1776816000200","asks":[["76329.7","0.06337078","3"],["76330.9","0.00001036","1"],["76345","0.05306489","1"],["76352.6","0.08378297","1"],["76460.1","0","0"],["76460.2","0","0"]],"bids":[["76299","0.05306489","1"]]}
{"instId":"BTC-USDT","action":"update","ts":"1776816000210","asks":[["76329.7","0.09437078","5"],["76345","0","0"],["76360.3","0.21236843","4"],["76460.1","0.0022005","4"]],"bids":[["76314.3","0.20878566","4"],["76299.1","0.08379798","2"],["76259","0.47164421","2"],["76257.5","0.00001316","1"],["76250.5","0.00054218","1"],["76248.9","0","0"],["76197.5","0","0"],["76173","0.00001059","1"]]}
{"instId":"BTC-USDT","action":"update","ts":"1776816000220","asks":[["76360.3","0.26542774","5"]],"bids":[]}
{"instId":"BTC-USDT","action":"update","ts":"1776816000240","asks":[["76329.7","0.06327478","2"]],"bids":[]}
{"instId":"BTC-USDT","action":"update","ts":"1776816000250","asks":[["76346.2","0","0"],["76346.8","0.0065479","1"],["76353.8","0","0"],["76354.5","0.00654825","1"]],"bids":[["76319.4","0.00654825","1"],["76318.5","0","0"]]}
{"instId":"BTC-USDT","action":"update","ts":"1776816000260","asks":[["76329.7","0.06121478","2"],["76346.8","0","0"],["76347.4","0.00654782","1"],["76349.5","0","0"],["76352.5","0.32741447","1"],["76352.7","0","0"],["76460.2","0.00162671","12"]],"bids":[["76325.5","0.10654812","2"],["76325.1","0.0262","1"],["76319.4","0.33396272","2"],["76319.3","0","0"],["76299","0","0"],["76171.4","0.00683413","1"],["76171.1","0.00001024","1"]]}
{"instId":"BTC-USDT","action":"update","ts":"1776816000270","asks":[["76333","0","0"],["76338.5","0","0"],["76341.6","0.14074665","1"],["76345.6","0.0065476","1"],["76347.4","0","0"],["76347.5","0.06314025","1"],["76349.6","1.00616208","1"],["76352.4","0.32742978","2"],["76352.5","0","0"],["76352.6","0","0"],["76353.3","0.00654832","1"],["76354.5","0","0"],["76357.1","0.08378297","1"],["76357.4","0","0"],["76393.9","0.10789606","2"],["76460.6","0.00002799","2"],["76460.7","0.00167279","1"]],"bids":[["76326.9","0.0262","1"],["76325.6","0.0065476","1"],["76325.5","0.1","1"],["76325.1","0","0"],["76323.9","0.01614584","1"],["76321.9","0.13051501","2"],["76319.5","0.32741477","1"],["76319.4","0","0"],["76319.2","0.04366673","1"],["76318.5","0.00654832","1"],["76314.3","0.26184497","5"],["76312.3","0","0"],["76289.6","0.14925283","2"],["76274","0","0"],["76171.1","0","0"]]}
{"instId":"BTC-USDT","action":"update","ts":"1776816000280","asks":[["76339.2","0","0"],["76339.7","0.01242257","1"],["76345.6","0","0"],["76346.2","0.00654747","1"],["76347.5","0.35540727","2"],["76349.6","0","0"],["76357.1","0","0"],["76369.1","0","0"],["76373","0.06530317","1"],["76376.9","0","0"],["76408.4","0.23037738","2"],["76460.9","0.00030148","3"],["76461.1","0.00003024","1"],["76461.3","0.00027039","1"]],"bids":[["76326.9","0.1262","2"],["76325.4","0.27160026","2"],["76325.2","0","0"],["76296.5","0.06506378","1"],["76292.6","0","0"],["76171.1","0.00001024","1"]]}
{"instId":"BTC-USDT","action":"update","ts":"1776816000290","asks":[["76341.6","0","0"],["76341.7","0","0"],["76342.2","0","0"],["76342.3","0.0471715","1"],["76346.3","0","0"],["76347.5","0.06314025","1"],["76352.8","0","0"],["76397.3","0","0"],["76461.4","0.0312605","1"],["76461.5","0.01228943","9"],["76461.6","0.00332668","1"],["76461.7","0.00001025","1"],["76462","0.00002228","1"]],"bids":[["76327","0.0376707","1"],["76325","0","0"],["76324.7","0.01460199","1"],["76320.1","0.15860798","2"],["76317.8","0.00305","1"],["76317.4","0.47151308","1"],["76313.3","0.08683297","2"],["76311","0","0"],["76303.2","0.12139319","3"],["76277.7","0","0"],["76171.1","0","0"]]}
{"instId":"BTC-USDT","action":"update","ts":"1776816000300","asks":[["76338.2","0","0"],["76343.4","0","0"],["76346.2","0","0"],["76346.8","0.00654738","1"],["76352.4","0.00001501","1"],["76353.1","0.32740162","1"],["76355.2","0.00162963","1"],["76374","0","0"],["76382.2","0","0"],["76389.9","0.091655","2"],["76461.5","0.14278943","10"],["76462.1","0.00001316","1"],["76462.2","0.00551437","1"]],"bids":[["76329.6","0.76293822","14"],["76327","0.1376707","2"],["76326.9","0.1","1"],["76325.6","0.00654751","1"],["76325.4","0.20756849","2"],["76325.3","0.13397247","2"],["76324.7","0","0"],["76322.5","0.17948596","1"],["76320.2","1.00616208","1"],["76319.5","0","0"],["76319.3","0.32740162","1"],["76319.2","0.19725726","2"],["76317.4","0.55529605","2"],["76291.9","0.02618714","1"],["76286.5","0.00011073","2"],["76284","0","0"],["76231","0","0"],["76184.3","0","0"],["76171.1","0.00001024","1"],["76170.8","0.00003094","3"]]}
{"instId":"BTC-USDT","action":"update","ts":"1776816000310","asks":[["76329.7","0","0"],["76330.9","0","0"],["76337.2","0","0"],["76342.3","0","0"],["76342.4","0","0"],["76345.6","0.00654732","1"],["76346.8","0","0"],["76347.6","0","0"],["76353","0.00654783","1"],["76353.1","0","0"],["76353.3","0","0"],["76355","0.32739376","1"],["76355.1","0.03905533","1"],["76360.3","0.00013118","1"],["76420.8","0.000015","1"],["76424.6","0.00016335","2"],["76430.3","0.67345203","3"],["76432.1","0.00001316","1"],["76462.3","0.00027227","4"],["76462.4","0.00001316","1"],["76462.5","0.00001257","1"],["76462.6","0.47226231","9"],["76463","0.00004357","1"]],"bids":[["76333.2","0.96876076","12"],["76332.2","0.28514005","2"],["76332.1","0.19357596","2"],["76330.8","0.00261893","1"],["76330.1","0.1305","1"],["76329.6","0.44151635","6"],["76328","0.00001316","1"],["76327.6","0.01460142","1"],["76327.1","0.0597","1"],["76327","0.1","1"],["76325.6","0.1","1"],["76325.4","0.0733598","1"],["76324","0.00654732","1"],["76323.8","0.32739376","1"],["76322.5","0.47217498","2"],["76320.3","0.12087247","1"],["76320.1","0.024","1"],["76319.3","0","0"],["76318.5","0","0"],["76317.3","0.00916846","2"],["76314.3","0.000015","1"],["76296.3","0.86564881","1"],["76294.2","0.00001086","1"],["76287.3","0.00076539","1"],["76280.5","0.658537","1"],["76274.8","0.2871994","2"],["76271","0","0"],["76227.3","0","0"],["76175","0","0"],["76173.7","0","0"],["76173.6","0","0"],["76173.2","0","0"],["76173","0","0"],["76171.4","0","0"],["76171.1","0","0"],["76170.8","0","0"]]}
{"instId":"BTC-USDT","action":"update","ts":"1776816000320","asks":[["76333.3","0","0"],["76334.6","0","0"],["76338","0","0"],["76339.3","0","0"],["76345.6","0","0"],["76345.7","0","0"],["76347.5","0","0"],["76349.7","0.21472344","1"],["76352.9","0.00654725","1"],["76353","0","0"],["76354.9","0.14844038","1"],["76355","0","0"],["76355.1","0","0"],["76357.2","0.000062","1"],["76357.6","0.63163308","3"],["76358.9","0","0"],["76359.2","0.00654779","1"],["76360.4","0.12636071","1"],["76363","0.32738731","1"],["76363.1","0","0"],["76370.3","0.21223725","3"],["76395.3","0.12912459","2"],["76426.7","0.65946829","2"],["76438.8","0.00042858","2"],["76463.1","0.00001427","1"],["76463.2","0.00059244","1"],["76463.4","0.00010604","1"],["76463.9","0.00088649","6"],["76464.1","0.00005359","1"],["76464.2","0.0025747","2"]],"bids":[["76339.6","1.12393787","15"],["76339.2","0.00151431","1"],["76333.3","0.79303575","6"],["76333.2","0.23836654","5"],["76332.2","0.1","1"],["76332.1","0.136","2"],["76330.9","0.00654725","1"],["76330.8","0","0"],["76330.2","0.32738832","1"],["76329.7","0.19585508","1"],["76329.6","0.136","2"],["76329.5","0.00001501","1"],["76328","0.1393329","2"],["76327.6","0.11460142","2"],["76327.1","0","0"],["76326.9","0","0"],["76325.6","0","0"],["76325.5","0","0"],["76325.4","0.16366231","2"],["76324.3","0.26444925","5"],["76324.1","0.00654779","1"],["76324","0","0"],["76323.8","0","0"],["76322.6","0.47151308","1"],["76319.3","0.00040006","1"],["76318.1","0","0"],["76317.3","0.00262063","1"],["76314.6","0.13197974","4"],["76309","0.00523856","1"],["76302.8","0","0"],["76293.7","0.00785784","1"],["76290.5","0.13041798","3"],["76283.8","0","0"],["76276.9","0.66075","1"],["76260.6","1.00140113","2"],["76259","0.47151308","1"],["76252","0.00054218","1"],["76250.5","0","0"],["76230.7","1.00553291","2"],["76195.5","0.00652851","1"],["76177.9","0","0"],["76177.8","0","0"],["76176.3","0","0"],["76175.4","0","0"],["76175.1","0","0"]]}
{"instId":"BTC-USDT","action":"update","ts":"1776816000330","asks":[["76339.7","0.01362257","2"],["76352.9","0","0"],["76354.9","0","0"],["76357.4","0.12629477","2"],["76359.2","0","0"],["76365","0.06550532","1"],["76367.3","0.00654767","1"],["76419.5","0.46383496","7"],["76425.6","0.76509107","5"]],"bids":[["76339.6","1.17524252","18"],["76339.2","0","0"],["76333.4","0.34172916","2"],["76333.3","0.32031918","2"],["76333.2","0.05106804","2"],["76330.9","0.1","1"],["76330.3","0.28292954","1"],["76329.8","0.00654767","1"],["76329.7","0","0"],["76329.6","0.15563517","3"],["76327","0","0"],["76324.1","0","0"],["76299.2","0.12812328","1"],["76277","0.03648164","1"],["76274.8","0.08378297","1"],["76230.8","0","0"]]}
{"instId":"BTC-USDT","action":"update","ts":"1776816000340","asks":[["76339.7","0.03292257","3"],["76364.9","0.00656069","2"],["76365","0.0813697","2"],["76367.3","0","0"],["76424.7","0.04701694","1"]],"bids":[["76339.2","0.1","1"],["76333.5","0.46744317","2"],["76333.4","0.00654716","1"],["76329.8","0","0"],["76329.7","0.00654753","1"],["76329.6","0.136","2"],["76328","0.00001316","1"],["76327.6","0.01460142","1"],["76326.9","0.00261919","1"],["76324.3","0.20877066","3"],["76317.3","0.01828712","2"],["76296.8","0.12635012","1"],["76296.7","0","0"],["76285.3","0.02502613","1"],["76281.1","0.01047676","1"],["76278.6","0","0"],["76277","0.40790476","2"],["76266.5","0","0"],["76265.8","0.01309595","1"],["76249.1","0","0"],["76235.1","0","0"],["76179.3","0","0"],["76178.9","0","0"]]}
{"instId":"BTC-USDT","action":"update","ts":"1776816000350","asks":[["76339.7","0.04342257","3"],["76355","0.05305931","1"],["76464.2","0","0"]],"bids":[["76339.6","1.27524252","19"],["76333.5","0.16952574","1"],["76330.3","0","0"],["76329.6","0.036","1"],["76179.3","0.00040006","1"]]}
{"instId":"BTC-USDT","action":"update","ts":"1776816000360","asks":[["76339.7","0.01242257","1"],["76349.7","0","0"],["76350","0.04282684","2"],["76354.9","0.01637032","1"],["76355","0","0"],["76357.6","0.16012","2"],["76360","0.4716243","4"],["76360.5","0.00111929","2"],["76363","0","0"],["76364.9","0.33393752","3"],["76367.3","1.00616208","1"],["76368.2","0.00001316","1"],["76371.2","0","0"],["76394.4","0.01309279","1"],["76395.3","0.11004674","1"],["76439.2","0.00002792","1"],["76464.2","0.0025747","2"]],"bids":[["76333.5","0.26952574","2"],["76332.3","0.32737683","1"],["76330.9","0","0"],["76330.2","0","0"],["76178.9","0.0008637","1"]]}
{"instId":"BTC-USDT","action":"update","ts":"1776816000370","asks":[["76339.7","0","0"],["76340","0","0"],["76341.3","0","0"],["76354.9","0","0"],["76357.4","0.11974761","1"],["76357.5","0.23438598","1"],["76358.3","0.00654705","1"],["76361.7","0.32737683","1"],["76361.8","0.09409324","1"],["76363.2","0","0"],["76364.8","0.00654756","1"],["76364.9","0.44863852","2"],["76365","0.06550532","1"],["76368","0.12145107","2"],["76386.7","0","0"],["76389.9","0.06546786","1"],["76392","0.09190446","2"],["76398","0.02619936","2"],["76406.4","0","0"],["76430.2","0.3729508","2"],["76464.4","0.00019338","3"],["76464.6","0.00012165","3"],["76464.7","0.00497942","3"],["76465","0.00044","2"]],"bids":[["76342.7","0.14352742","3"],["76339.9","0.24862252","6"],["76339.7","0.18757652","2"],["76339.6","1.15933986","15"],["76333.6","0.00654705","1"],["76333.5","0.1","1"],["76333.4","0.1","1"],["76332.3","0","0"],["76332.1","0.036","1"],["76330.8","0.0262","1"],["76330.2","0.32737683","1"],["76329.7","0","0"],["76327.7","0.00654756","1"],["76300","0.02979355","6"],["76297.6","0.0130926","1"],["76291.9","0","0"],["76282.8","0.00325284","1"],["76280.3","0.00233651","1"],["76279.4","0","0"],["76276.5","0","0"],["76274.1","0","0"],["76180","0","0"],["76179.9","0","0"],["76179.3","0","0"],["76178.9","0","0"]]}
{"instId":"BTC-USDT","action":"update","ts":"1776816000380","asks":[["76342.8","0.121876","2"],["76344.6","0.01242178","1"],["76344.7","0","0"],["76359.9","0.08378297","1"],["76361.6","0.17633627","1"],["76361.7","0","0"],["76361.8","0","0"],["76363.1","0.32737157","1"],["76363.3","0","0"],["76364.8","0.09033053","2"],["76367.2","0.12415725","1"],["76370.3","0","0"],["76378.7","0","0"],["76381.1","0","0"],["76391.1","0.00130905","1"],["76392.9","0.00130902","1"],["76402.8","0.06397188","1"],["76418.1","0.00019321","1"],["76465","0","0"]],"bids":[["76342.7","1.00599407","17"],["76340","0.15757596","1"],["76339.9","0.3582324","3"],["76339.7","0","0"],["76339.6","0.32881263","4"],["76333.6","0.10654705","2"],["76333.3","0.16031918","1"],["76332.2","0","0"],["76330","0.01460098","1"],["76327.6","0","0"],["76325","0.00305","1"],["76324.3","0","0"],["76320","0.0000812","1"],["76317.8","0","0"],["76311.8","0.00314288","6"],["76300.4","0.00004629","1"],["76296.8","0.12766079","2"],["76290.5","0.00132112","2"],["76289.6","0.15250556","3"],["76288.6","0.0000168","1"],["76286.6","0.0023364","1"],["76282.8","0","0"],["76280.3","0","0"],["76180","0.0000812","1"],["76179.9","0.47151308","1"]]}
{"instId":"BTC-USDT","action":"update","ts":"1776816000390","asks":[["76342.8","0.142376","4"],["76356.7","0.47151308","1"],["76358.4","0","0"],["76359.8","1.00616208","1"],["76363.1","0","0"],["76364.7","0.32736783","1"],["76364.8","0.08378297","1"],["76367.1","0.00654727","1"],["76392.9","0.14138716","2"],["76393.6","0.00227957","1"],["76464.4","0","0"],["76464.6","0","0"],["76464.7","0","0"]],"bids":[["76342.7","1.10599407","18"],["76340","0","0"],["76339.9","0.09563","1"],["76333.4","0","0"],["76332.2","0.32736783","1"],["76330.9","0.00654727","1"],["76330.2","0","0"],["76327.7","0","0"],["76325.4","0.0733598","1"],["76254.9","0.01904","1"],["76245.8","0","0"],["76179.3","0.00040006","1"],["76178.9","0.0008637","1"]]}
{"instId":"BTC-USDT","action":"update","ts":"1776816000400","asks":[["76356.6","0.14076516","1"],["76357.5","0.52816631","2"],["76358.1","0.05307247","2"],["76358.3","0","0"],["76359.4","0.00654672","1"],["76373.4","0.15917794","2"],["76392","0.13121728","1"],["76430.2","0.00001198","1"],["76464.1","0","0"],["76464.2","0","0"]],"bids":[["76333.7","0.00654672","1"],["76333.6","0.1","1"],["76327.4","0.05087713","1"],["76312.1","0.0517749","1"],["76179.9","0","0"],["76179.3","0","0"],["76178.9","0","0"]]}
{"instId":"BTC-USDT","action":"update","ts":"1776816000410","asks":[["76390.3","0.1","1"],["76430.7","0.47151308","1"],["76445.9","0","0"],["76447","0.0000119","1"],["76449.9","0.00005654","1"],["76462.2","0.01760591","8"],["76463.9","0","0"]],"bids":[["76342.7","0.98660077","17"],["76339.9","0.19563","2"],["76333.5","0","0"],["76290.5","0.1300588","3"],["76288.5","0","0"],["76284.7","0.47152988","2"],["76280.9","0.0000168","1"],["76277.1","0.00001681","1"],["76274.1","0.00019775","1"],["76273.3","0.33240385","2"],["76269.4","0","0"],["76266.9","0.03898941","1"],["76265.6","0","0"],["76262.1","0","0"],["76261.8","0.00001086","1"],["76258","0","0"],["76254.2","0.00001316","1"],["76242.1","0","0"],["76179.9","0.47151308","1"],["76179.3","0.00040006","1"],["76178.9","0.0008637","1"],["76177.9","0.00004571","1"],["76177.8","0.00105547","4"]]}
{"instId":"BTC-USDT","action":"update","ts":"1776816000420","asks":[["76393.9","0.107856","1"],["76397.8","0.00004005","1"],["76463.4","0","0"]],"bids":[["76333.2","0.036","1"],["76270.9","0.00324681","2"],["76266.6","0","0"],["76265.1","0.00013112","1"],["76260.6","1.00127","1"],["76256.6","0.34629417","2"],["76252","0","0"],["76175.4","0.00003868","3"]]}
{"instId":"BTC-USDT","action":"update","ts":"1776816000430","asks":[["76342.8","0.093276","2"],["76357.3","0.00654656","1"],["76359.4","0","0"],["76361.8","0.32736722","1"],["76364.6","0.00654733","1"],["76364.7","0","0"],["76367.1","0","0"],["76397.8","0","0"],["76402.7","0.00004005","1"]],"bids":[["76332.2","0","0"],["76330.9","0","0"],["76330.2","0.32736722","1"],["76329.7","0.00654733","1"],["76312.1","0.10483421","2"],["76289.7","0.00233639","1"],["76286.6","0","0"],["76277.2","0.00323355","1"],["76270.9","0.00001316","1"],["76175.4","0","0"]]}
{"instId":"BTC-USDT","action":"update","ts":"1776816000440","asks":[["76342.8","0.092076","1"]],"bids":[["76340","0.18639613","1"],["76333.7","0.1028187","2"],["76330.8","0","0"],["76329.7","0","0"],["76327.5","0.00654733","1"],["76292.6","0.00325271","1"],["76289.6","0.14925283","2"],["76177.8","0","0"]]}
{"instId":"BTC-USDT","action":"update","ts":"1776816000450","asks":[["76342.8","0.112576","3"],["76390.3","0","0"],["76463.4","0.00010604","1"]],"bids":[["76340","0.28639613","2"],["76333.6","0","0"],["76330.3","0.1697092","1"]]}
{"instId":"BTC-USDT","action":"update","ts":"1776816000460","asks":[["76342.8","0.142376","4"]],"bids":[["76333.7","0.065148","2"]]}
{"instId":"BTC-USDT","action":"update","ts":"1776816000470","asks":[["76355.1","0.00654653","1"],["76357.3","0","0"],["76358.1","0.10613178","3"],["76360.3","0.32749712","2"],["76361.8","0","0"],["76397.3","0.01953721","1"],["76409.3","0","0"],["76441.2","0.01413038","1"],["76441.4","0.00232513","5"]],"bids":[["76333.8","0.00654653","1"],["76333.7","0.05860128","1"],["76331.3","0.0262","1"],["76330.2","0","0"],["76327.5","0.33391327","2"],["76327.4","0.15699576","2"],["76177.9","0","0"]]}
{"instId":"BTC-USDT","action":"update","ts":"1776816000480","asks":[["76342.8","0","0"],["76344.6","0","0"],["76344.8","0","0"],["76345.9","0","0"],["76346.9","0","0"],["76348.1","0","0"],["76348.3","0","0"],["76349.1","0","0"],["76350","0","0"],["76351.4","0","0"],["76352.4","0","0"],["76353.2","0","0"],["76353.4","0","0"],["76353.9","0","0"],["76354.6","0","0"],["76354.8","0","0"],["76356.6","0","0"],["76356.7","0","0"],["76357.5","0","0"],["76357.6","0.08","1"],["76358.1","0.00001316","1"],["76359.7","0.00654703","1"],["76359.8","0","0"],["76359.9","0","0"],["76360","0.0000812","1"],["76360.3","0.00013118","1"],["76360.4","0","0"],["76361.6","0","0"],["76364.6","0","0"],["76364.8","0","0"],["76364.9","0.00001316","1"],["76365","0","0"],["76367.3","0","0"],["76367.6","0","0"],["76369.5","0","0"],["76369.6","0.20829929","1"],["76369.7","0","0"],["76372.7","0","0"],["76372.8","0","0"],["76373.4","0","0"],["76375.3","0","0"],["76375.4","0","0"],["76376.5","0","0"],["76380.2","0","0"],["76381.7","0.00001316","1"],["76384.1","0.28767822","3"],["76385.7","0","0"],["76389","0","0"],["76391.2","0","0"],["76395.4","0","0"],["76398.7","0","0"],["76401.9","0","0"],["76402.7","0","0"],["76405.9","0.00004004","1"],["76408.5","0.00001316","1"],["76411.6","0","0"],["76414.7","0","0"],["76417.8","0","0"],["76421.5","0","0"],["76426.1","0","0"],["76430.7","0","0"],["76434.4","0.00001506","1"],["76463.9","0.00088649","6"],["76464.1","0.00005359","1"],["76464.2","0.0025747","2"],["76464.4","0.00019338","3"],["76464.6","0.00012165","3"],["76464.7","0.00497942","3"],["76465","0.00044","2"],["76465.1","0.00002105","1"],["76465.5","0.00119834","3"],["76465.8","0.00071318","6"],["76466","1.5446192","3"],["76466.2","0.00014238","2"],["76466.5","0.00028078","2"],["76466.6","0.00546094","15"],["76466.7","1.54916553","7"],["76467.1","0.00181702","1"],["76467.2","0.00011781","1"],["76467.3","0.00050101","1"],["76467.8","0.47151308","1"],["76467.9","0.00001035","1"],["76468","1.00618616","2"],["76468.2","0.00158724","2"],["76468.3","0.01147749","1"],["76468.4","0.00002034","1"],["76468.5","0.00040135","2"],["76468.6","0.00001531","1"],["76468.7","6.40679488","2"],["76468.8","0.01162259","2"],["76468.9","0.00002508","2"],["76469","0.00002028","2"],["76469.2","0.08378297","1"],["76469.4","0.00265436","2"],["76469.6","0.00441584","1"],["76469.7","0.00021564","6"],["76470","0.00007723","1"],["76470.2","0.05814278","2"],["76470.3","0.00003942","1"],["76470.5","0.00926628","18"],["76470.6","0.01580142","1"],["76470.8","0.0001444","7"],["76471.1","0.0010195","4"],["76471.2","0.00002013","1"],["76471.3","0.01047498","5"],["76471.4","0.00505207","2"],["76471.5","0.00004115","1"],["76471.7","0.00029028","5"],["76471.8","0.00007776","1"],["76471.9","0.0003932","1"]],"bids":[["76334.3","0.01614584","1"],["76333.8","0.07205185","2"],["76330.4","0.32735629","1"],["76327.6","0.47151308","1"],["76327.5","0","0"],["76327.4","0","0"],["76325.1","0.00654703","1"],["76316.5","0","0"],["76312.1","0","0"],["76290.5","0.00132112","2"],["76280.6","0.3375615","1"],["76280.3","0.00323353","1"],["76277.2","0","0"],["76237.1","0","0"],["76193.3","0","0"],["76177.9","0.00004571","1"]]}
{"instId":"BTC-USDT","action":"update","ts":"1776816000490","asks":[["76355.1","0.02133592","3"],["76357.4","0","0"],["76357.6","0","0"],["76359.7","0","0"],["76361.9","0","0"],["76367.1","0.00654642","1"],["76367.2","0","0"],["76368","0.00062322","1"],["76369.6","0","0"],["76370.7","0","0"],["76372.6","0.00654707","1"],["76373.8","0.01614584","1"],["76374.3","0.11912901","5"],["76375.1","0.08378297","1"],["76375.2","0.00001501","1"],["76376.2","0.47151308","1"],["76376.4","0","0"],["76378","0.0437575","1"],["76379.3","0.13733459","2"],["76379.4","0.47151308","1"],["76379.8","0.08378297","1"],["76379.9","0","0"],["76380.5","0","0"],["76381.5","0.13145715","1"],["76381.6","0.44128957","1"],["76381.8","0","0"],["76384","0.08378297","1"],["76384.1","0.17998356","2"],["76385.3","0.05812501","1"],["76385.8","0.05305931","1"],["76386.6","0","0"],["76386.9","0","0"],["76387.8","0","0"],["76388.1","0","0"],["76388.6","0.47151308","1"],["76388.8","0.21524012","2"],["76389.9","0","0"],["76391.1","0","0"],["76392.1","0","0"],["76392.9","0","0"],["76393.6","0.13099651","2"],["76393.8","0.08378297","1"],["76393.9","0","0"],["76394.9","0.47151308","1"],["76395.3","0","0"],["76395.8","0.12050238","1"],["76396","0","0"],["76398","0.000015","1"],["76399.7","0","0"],["76399.8","0.1","1"],["76402.7","0.13146619","1"],["76403.6","0.00130883","1"],["76404.1","0.47151308","1"],["76405.9","0.06549433","2"],["76407.5","0.00130877","1"],["76408.3","0.15337722","1"],["76408.4","0.05312267","1"],["76410.7","0.12050238","1"],["76410.8","0","0"],["76413.3","0.47151308","1"],["76414.4","0.17294512","1"],["76417.4","0.12872731","1"],["76417.6","0.47151308","1"],["76419.5","0.07752538","6"],["76419.6","0","0"],["76420.3","0","0"],["76425.5","0.47187967","2"],["76435.3","0.47157649","2"],["76451.7","0.00001402","1"],["76457.2","0.01573368","2"],["76459.9","0.0000212","1"],["76463.3","0.08378297","1"],["76468.7","0.00109488","1"],["76469.2","0.21428297","2"],["76471.8","0","0"],["76471.9","0","0"]],"bids":[["76355","0.49353625","10"],["76354.7","0.09563","1"],["76353.2","0.03551317","1"],["76353.1","0.036","1"],["76351.3","0.09563","1"],["76348.7","0.16996669","1"],["76345.8","0.47151308","1"],["76345","0.0496","1"],["76344.5","0.1305","1"],["76342.8","0.39978472","5"],["76342.7","0.15563517","3"],["76340.1","1.80503144","3"],["76339.9","0.1","1"],["76339.7","0.15917794","2"],["76339.6","0.1","1"],["76334.3","0.17686325","1"],["76333.9","0.09447652","2"],["76333.8","0.5370184","2"],["76333.7","0","0"],["76333.3","0","0"],["76331.3","0","0"],["76330.5","1.13487902","2"],["76330.4","0","0"],["76330","0","0"],["76325.3","0.0131","1"],["76325.1","0.11994166","1"],["76323.7","0","0"],["76320.4","0.13146619","1"],["76320.3","0","0"],["76315.7","0.12602458","2"],["76314.7","0.12324955","1"],["76314.6","0.00012508","3"],["76313","0","0"],["76310.4","0.02618072","1"],["76308","0.00004629","1"],["76305.3","0.06545637","1"],["76303.2","0.00011193","2"],["76300","0.00360919","5"],["76296.8","0.00131067","1"],["76289.6","0.08378297","1"],["76244.1","0.00001087","1"],["76243.9","0","0"],["76241.3","0","0"],["76200","0.01335597","51"],["76195.5","0","0"],["76181.6","0","0"],["76180.1","0","0"],["76180","0","0"],["76179.9","0","0"],["76179.3","0","0"],["76178.9","0","0"],["76177.9","0","0"]]}
{"instId":"BTC-USDT","action":"update","ts":"1776816000500","asks":[["76355.1","0.0205","2"],["76367.1","0","0"],["76367.6","0.000015","1"],["76371.6","0.18350327","2"],["76372.5","0.0065464","1"],["76372.6","0","0"],["76372.9","0.08378297","1"],["76373.1","0.47151308","1"],["76373.8","0","0"],["76374.2","0.20138435","1"],["76375.1","0","0"],["76377.9","0.00654702","1"],["76379.2","1.08994505","2"],["76379.8","0","0"],["76381.6","0","0"],["76384.1","0.00005043","1"],["76385.8","0.10611862","2"],["76388.4","0.18898058","2"],["76395.9","0","0"],["76398.2","0.47152809","2"],["76410.7","0","0"],["76414.1","0.345809","1"],["76419.5","0.01197252","5"],["76435","0.20208802","1"],["76471.7","0","0"]],"bids":[["76355","0.6225788","14"],["76354.8","0.06783711","1"],["76353.2","0","0"],["76348.8","0.0065464","1"],["76344.7","0.000015","1"],["76344.1","0.0026186","1"],["76342.9","0.33390104","2"],["76342.8","0.3292283","3"],["76342.7","0.136","2"],["76340.1","1.47767516","2"],["76340","0.1","1"],["76339.2","0","0"],["76337.1","0.000015","1"],["76333.9","0.08792945","1"],["76328.8","0.0052372","1"],["76327.7","0.08378297","1"],["76326.9","0","0"],["76325.4","0","0"],["76322.7","0.08378297","1"],["76313.5","0.0078558","1"],["76309","0","0"],["76308.7","0.12323962","1"],["76299.2","0","0"],["76298.2","0.0104744","1"],["76293.7","0","0"],["76283","0.013093","1"],["76281.1","0","0"],["76280.7","0.08378297","1"],["76265.8","0","0"],["76251.3","0","0"],["76245.7","0","0"],["76213.5","0.00107799","1"],["76183.3","0","0"],["76183","0","0"],["76182.7","0","0"],["76182.2","0","0"]]}
{"instId":"BTC-USDT","action":"update","ts":"1776816000510","asks":[["76355.1","0.06272006","4"],["76355.2","0.01471963","2"],["76370","0.47151308","1"],["76371.5","1.00616208","1"],["76373","0.38242496","2"],["76373.6","0.08","1"],["76374.2","0","0"],["76377.3","0.06550532","1"],["76407.5","0.10860057","2"],["76408.6","0.02031548","1"],["76417.4","0","0"],["76447","0","0"],["76462.2","0.00555009","4"],["76463.8","0.0000119","1"],["76471.3","0","0"],["76471.4","0","0"],["76471.5","0","0"]],"bids":[["76353.1","0","0"],["76348.8","0.34153523","3"],["76345.8","0","0"],["76342.9","0.32735402","1"],["76342.8","0.0049088","1"],["76340.2","0.00654695","1"],["76334.6","0.01460009","1"],["76334.4","0.14788755","1"],["76334.3","0","0"],["76330.6","0.12871694","1"],["76330.5","1.00616208","1"],["76328.4","0.0131","1"],["76325.3","0","0"],["76308.8","0.12323962","1"],["76308.7","0","0"],["76283.7","0.94639","1"],["76266.7","0.00013112","1"],["76265.1","0","0"],["76258.1","0.34625819","2"],["76257.3","0.00011193","2"],["76256.6","0.345752","1"],["76183.7","0","0"],["76183.4","0","0"]]}
{"instId":"BTC-USDT","action":"update","ts":"1776816000520","asks":[["76355.1","0.01242006","1"],["76369.9","0.13967157","1"],["76370","0","0"],["76371.4","0.00654636","1"],["76371.5","0","0"],["76372.5","0","0"],["76373.1","0","0"],["76374.3","0.01047472","4"],["76376.2","0","0"],["76377.3","0","0"],["76378","0.51243067","2"],["76379.1","0.1314556","1"],["76379.2","0.08378297","1"],["76379.4","0","0"],["76381.4","0.09555442","1"],["76381.5","0","0"],["76388.3","0.12050096","1"],["76388.4","0.00001316","1"],["76388.6","0","0"],["76388.9","0","0"],["76392.6","1.00616208","1"],["76393.6","0.00227957","1"],["76394.9","0","0"],["76397.8","0.47151308","1"],["76398.2","0.00001501","1"],["76398.3","0","0"],["76404.1","0","0"],["76409","1.00616208","1"],["76410.9","0","0"],["76413.3","0","0"],["76414.1","0","0"],["76417.4","0.12871694","1"],["76417.6","0","0"],["76417.7","0","0"],["76425.5","0.00036659","1"],["76425.7","0.03364359","2"],["76430.2","0","0"],["76435.3","0.00006341","1"],["76436.4","0.00006873","3"],["76439.1","0.00004534","1"],["76453.6","0.00042984","6"],["76462.2","0.00551437","1"],["76468.5","0.00038944","1"],["76471.1","0.47253258","5"],["76471.3","0.01047498","5"],["76471.4","0.00505207","2"],["76471.5","0.00004115","1"],["76471.7","0.00029028","5"],["76471.8","0.00007776","1"],["76471.9","0.0003932","1"],["76472","0.000059","1"],["76472.4","0.00002715","1"],["76472.5","0.00008103","2"],["76472.6","0.00002975","1"]],"bids":[["76348.9","0.15922968","2"],["76348.8","0.14350712","1"],["76340.2","0.12704791","2"],["76334.6","0.15427166","2"],["76330.7","0.47151308","1"],["76330.6","0","0"],["76327.7","0","0"],["76308.8","0","0"],["76258.2","0.26347233","1"],["76246.7","0.08378297","1"],["76188","0","0"],["76183.7","0.00001319","1"]]}
{"instId":"BTC-USDT","action":"update","ts":"1776816000530","asks":[["76355.1","0","0"],["76371.3","0.0065463","1"],["76371.4","0","0"],["76371.6","0.00001316","1"],["76372.8","0.07157739","1"],["76372.9","0","0"],["76373","0.06530317","1"],["76377.9","0","0"],["76378","0.0437575","1"],["76379.2","0","0"],["76379.3","0.00040006","1"],["76381.3","0.00654684","1"],["76381.4","0","0"],["76383.9","0.13419426","1"],["76384","0.47151308","1"],["76385.3","0","0"],["76388.8","0.13145715","1"],["76390.6","1.00616208","1"],["76392.5","0.47151308","1"],["76392.6","0","0"],["76393.8","0","0"],["76397.3","0","0"],["76397.7","1.00616208","1"],["76397.9","0","0"],["76399.8","0","0"],["76401.8","0.00001316","1"],["76403.6","0","0"],["76406","0","0"],["76407","0.47151308","1"],["76407.5","0.1072918","1"],["76410.5","0","0"],["76414.4","0","0"],["76414.5","0.00130865","1"],["76416.2","0.47151308","1"],["76417.1","0.0013086","1"],["76417.4","1.13487902","2"],["76422.4","0.1259336","2"],["76422.5","0.47151308","1"],["76425.4","1.00658248","3"],["76425.6","0.60975453","5"],["76426.7","0.00001229","1"],["76430.3","0.01620403","2"],["76434.8","0.47151308","1"],["76434.9","1.00616208","1"],["76435","0","0"],["76437.4","0.00196024","1"],["76441.2","0","0"],["76473","0.0001084","1"],["76473.2","0.00001599","1"],["76473.3","0.00564466","1"],["76473.6","0.0007428","8"]],"bids":[["76355.1","0.43678681","6"],["76355","0.5976688","13"],["76354.8","0.16783711","2"],["76354.7","0.19563","2"],["76353.7","0.01614584","1"],["76351.4","0.00654633","1"],["76349","0.62876091","3"],["76348.9","0","0"],["76348.7","0","0"],["76345.1","0.80540511","3"],["76342.9","0","0"],["76340.3","0.20428393","2"],["76340.2","0","0"],["76339.9","0","0"],["76339.6","0.01614584","1"],["76334.7","0.08378297","1"],["76334.6","0.13967157","1"],["76334.4","0","0"],["76331.7","0.00305","1"],["76330.8","0.12323962","1"],["76330.7","0.55529605","2"],["76327.3","0.00305","1"],["76325","0","0"],["76314.7","0","0"],["76313.4","0.12323962","1"],["76313.3","0.08378297","1"],["76309.4","0.00011072","2"],["76298.9","0.00131063","1"],["76294.7","0.00002863","1"],["76292.8","0","0"],["76290.5","0.00001035","1"],["76287","1.00131034","2"],["76280.5","0","0"],["76274.9","0","0"],["76261.3","0","0"],["76260.6","0","0"],["76256.7","0","0"],["76246.7","0","0"],["76245.1","0","0"],["76183.4","0.00005866","1"],["76183.3","0.00009283","1"],["76183","0.01496","1"]]}
{"instId":"BTC-USDT","action":"update","ts":"1776816000540","asks":[["76371.3","0","0"],["76372.8","0","0"],["76374.3","0.12910036","5"],["76379","0.00654426","1"],["76381.3","0","0"],["76381.8","0.05631053","1"],["76388.2","0.00654573","1"],["76393.6","0","0"],["76406.9","0.08378297","1"],["76417.8","0.345809","1"],["76435","0.19328654","1"],["76466","0.0059052","2"],["76473.3","0","0"],["76473.6","0","0"]],"bids":[["76355.1","1.05825213","18"],["76355","0.51674572","7"],["76354.9","0.12356472","1"],["76354.8","0.1","1"],["76354.7","0.1","1"],["76353.7","0.1","1"],["76351.5","0.00654573","1"],["76351.4","0","0"],["76349.5","0.01614584","1"],["76349.1","0.32735195","1"],["76349","0.47151308","1"],["76348.8","0","0"],["76347.3","0.00261849","1"],["76345.2","0.12323946","1"],["76345.1","0.47151308","1"],["76344.1","0","0"],["76340","0","0"],["76339.1","0.0061","2"],["76334.8","0.13434215","1"],["76331.7","0","0"],["76330.8","0","0"],["76327.3","0","0"],["76325.2","0.14241004","1"],["76325.1","0","0"],["76322.6","0.47456308","2"],["76314.6","0.12336454","4"],["76313.4","0","0"],["76311.8","0.00009288","5"],["76301.9","0.00236411","2"],["76294.7","0","0"],["76289.7","0","0"],["76280.6","0","0"],["76276.9","0","0"],["76260.7","0","0"],["76240.1","0.00652851","1"],["76234.7","0","0"],["76186.2","0.00652089","1"],["76182.7","0.00002401","2"],["76182.2","0.00875","1"],["76181.6","0.00073364","2"]]}
{"instId":"BTC-USDT","action":"update","ts":"1776816000550","asks":[["76378.6","0.08012","1"],["76379","0.12871677","1"],["76381.7","0.00655711","2"],["76383.9","0.21162459","1"],["76385.3","0.00654572","1"],["76385.8","0.21223725","3"],["76388.2","0","0"],["76394.4","0","0"],["76397.6","0.08378297","1"],["76408.6","0","0"],["76416.9","0.01164483","1"],["76417.4","1.14066281","3"],["76422.3","0.11909882","1"],["76422.4","0.00015119","1"],["76428.3","0.0001196","2"],["76428.8","0","0"],["76435","0","0"],["76466.7","0.00025453","6"]],"bids":[["76355.1","1.15825213","19"],["76353.8","0.32729096","1"],["76351.5","0","0"],["76349.5","0","0"],["76349.2","0.23924283","1"],["76349.1","0.00654572","1"],["76345.3","0.12050081","1"],["76345.2","0","0"],["76342.7","0.036","1"],["76340.3","0.12050096","1"],["76339.7","0.21095284","3"],["76314.7","0.12323946","1"],["76314.6","0.00012508","3"],["76304.4","0.00325178","1"],["76292.6","0","0"],["76277","0.03648164","1"],["76259.1","0.08378297","1"],["76225.2","0.00007188","1"],["76187.6","0","0"],["76181.6","0","0"]]}
{"instId":"BTC-USDT","action":"update","ts":"1776816000560","asks":[["76355.2","0.00053948","1"],["76367.4","0","0"],["76369.1","0.0153508","1"],["76372.5","0.01309","1"],["76378","0.10703774","2"],["76381.9","0","0"],["76384.7","0.06550532","1"],["76385.3","0","0"],["76385.8","0.26529656","4"],["76388.1","0.00654552","1"],["76393","0.29343","1"],["76407.5","0.2951218","2"],["76409.4","0.00227918","1"],["76435","0.19992692","1"],["76472.5","0","0"],["76472.6","0","0"],["76473","0","0"],["76473.2","0","0"]],"bids":[["76355.1","1.48554309","20"],["76354.9","0.2999944","3"],["76353.8","0","0"],["76353.7","0","0"],["76351.6","0.00654552","1"],["76349.7","0.0131","1"],["76349.2","0","0"],["76349.1","0","0"],["76347.2","0.00305","1"],["76339.1","0.00305","1"],["76332","0.30279","1"],["76328.4","0","0"],["76317.5","0.2822","1"],["76317.3","0.00262063","1"],["76307.6","0","0"],["76293.1","0","0"],["76282.5","0.00652851","1"],["76243","0","0"],["76240.1","0","0"],["76237.8","6.31452","1"],["76224.4","0.00652089","1"],["76188.1","0.00652277","1"],["76186.2","0","0"],["76181.6","0.00073364","2"]]}
{"instId":"BTC-USDT","action":"update","ts":"1776816000570","asks":[["76355.2","0","0"],["76356.5","0","0"],["76357.2","0","0"],["76358.1","0","0"],["76358.7","0","0"],["76359.3","0","0"],["76359.5","0.0636818","4"],["76361.5","0","0"],["76380.8","0.47151308","1"],["76383.8","1.00616208","1"],["76385.8","0","0"],["76388.1","0","0"],["76388.2","0.00654509","1"],["76435","0","0"],["76472.5","0.00008103","2"],["76472.6","0.00002975","1"],["76473","0.0001084","1"],["76473.2","0.00001599","1"],["76473.3","0.00564466","1"],["76473.5","0.08378297","1"],["76473.6","0.0007428","8"]],"bids":[["76359.4","0.81950288","14"],["76356.4","0.68846576","2"],["76355.1","0.21154875","6"],["76355","0.1831715","3"],["76354.9","0.1","1"],["76351.7","0.00654509","1"],["76351.6","0","0"],["76351.4","0.32725421","1"],["76351.3","0","0"],["76350.7","0.02619","1"],["76345.4","0.12049402","1"],["76345.3","0","0"],["76345","0","0"],["76340.4","0.13692502","1"],["76340.3","0","0"],["76339.7","0","0"],["76339.3","0.00040006","1"],["76334.6","0","0"],["76331.6","0.00305","1"],["76322.6","0.47151308","1"],["76314.7","0","0"],["76313.4","0.12323252","1"],["76288.9","0.0000463","1"],["76254.2","0","0"],["76252.2","0","0"]]}
{"instId":"BTC-USDT","action":"update","ts":"1776816000580","asks":[["76372.9","0.08197792","1"],["76388.2","0.45430239","3"],["76388.8","0","0"],["76390.1","0.05305931","1"],["76391.9","0.08378297","1"],["76418.1","0","0"],["76422.3","0","0"],["76430.5","0","0"],["76435","0.19874851","1"],["76443.2","0.00019321","1"],["76473.6","0","0"]],"bids":[["76359.4","0.87321849","16"],["76356.5","0.71028739","2"],["76356.4","0.1","1"],["76355.1","0.19563","2"],["76355","0.136","2"],["76354.7","0","0"],["76351.4","0","0"],["76349.7","0.12171283","2"],["76344.1","0.21005507","3"],["76342.8","0","0"],["76334.7","0","0"],["76330.8","0.12323252","1"],["76317","0.00004849","2"],["76315.7","0.12597828","1"],["76315.3","0","0"],["76313.2","0.47155002","2"],["76311.8","0.00004659","4"],["76311.7","0","0"],["76311.5","0","0"],["76309.4","0.00003694","1"],["76308","0","0"],["76307.7","0","0"],["76306.4","0.1305","1"],["76305.6","0.00004727","2"],["76304.2","0","0"],["76303.8","0","0"],["76301.8","0.00003694","1"],["76301.1","0.00001316","1"],["76300.4","0","0"],["76300","0.00359239","4"],["76297.9","0.00003695","1"],["76296.6","0.1305","1"],["76296.3","0","0"],["76296.2","1.47767516","2"],["76295.8","0","0"],["76294.1","0.00004781","2"],["76292.7","0.47151308","1"],["76292.4","0","0"],["76290.5","0","0"],["76290.3","0.00003695","1"],["76288.9","0","0"],["76288.6","0","0"],["76286.5","0.00003695","1"],["76285.2","0.08378297","1"],["76285.1","0","0"],["76284.7","0.47151308","1"],["76282.7","0.00003695","1"],["76281.3","0","0"],["76280.9","0","0"],["76278.8","0.00004849","2"],["76277.5","0","0"],["76277.1","0","0"],["76275","0.00003694","1"],["76273.5","0","0"],["76273.3","0.33238704","1"],["76271.2","0.00003694","1"],["76269.5","0","0"],["76268.2","0","0"],["76267.4","0.00004727","2"],["76263.6","0.00003694","1"],["76262.9","0","0"],["76259.7","0.00003695","1"],["76257.6","0","0"],["76255.9","0.00004781","2"],["76253.6","0.08378297","1"],["76252.3","0.06458334","1"],["76252.1","0.00003695","1"],["76248.3","0.00003695","1"],["76247","0","0"],["76244.5","0.00003695","1"],["76180.1","0.00013128","1"],["76180","0.0000812","1"],["76179.9","0.47151308","1"],["76179.3","0.00040006","1"],["76178.9","0.0008637","1"],["76177.9","0.00004571","1"],["76177.8","0.00105547","4"],["76175.4","0.00003868","3"],["76175.1","0.47151308","1"],["76175","0.00029601","2"],["76173.7","0.00070045","3"],["76173.6","0.00002308","1"],["76173.2","0.00001006","1"],["76173","0.00001059","1"],["76171.4","0.00683413","1"],["76171.1","0.00001024","1"],["76170.8","0.00003094","3"],["76170.4","0.02050516","1"],["76170.2","0.00001385","1"],["76170","0.001571","1"],["76169.2","0.0001094","1"],["76168.9","0.000015","1"],["76168.4","0.00011049","4"],["76167","0.00001319","1"],["76166.6","0.00248493","6"]]}
{"instId":"BTC-USDT","action":"update","ts":"1776816000590","asks":[["76377.7","0.47151308","1"],["76380.7","0.44328661","1"],["76381.8","0","0"],["76435","0","0"]],"bids":[["76359.4","0.97321849","17"],["76356.6","0.37071234","1"],["76356.5","0.32725637","1"],["76355","0.1","1"],["76354.8","0","0"],["76317","0.00001155","1"],["76313.2","0.47151308","1"],["76309.4","0","0"],["76305.6","0.00001033","1"],["76301.8","0","0"],["76297.9","0","0"],["76294.1","0.00001086","1"],["76290.3","0","0"],["76286.5","0","0"],["76282.7","0","0"],["76281.2","0.02952065","1"],["76278.8","0.00001155","1"],["76275","0","0"],["76271.2","0","0"],["76267.4","0.00001033","1"],["76263.6","0","0"],["76259.7","0","0"],["76255.9","0.00001086","1"],["76252.1","0","0"],["76248.3","0","0"],["76244.5","0","0"],["76243.1","0","0"],["76176.3","0.1305","1"],["76168.6","0.1305","1"],["76166.2","0.00026145","4"],["76165.9","0.47151308","1"],["76165.8","0.01614584","1"],["76165.2","0.00091086","3"],["76165.1","0.00001015","1"],["76164.3","0.00046091","2"],["76163.9","0.00005592","3"],["76162.2","0.00002057","1"],["76162.1","0.00004159","3"],["76162","0.00001017","1"],["76161.2","0.00007766","2"],["76161.1","0.0000827","1"]]}
{"instId":"BTC-USDT","action":"update","ts":"1776816000600","asks":[["76359.5","0.32695509","10"],["76362","0.01241895","1"],["76374.5","0.47151308","1"],["76377.6","1.25954078","2"],["76378","0","0"],["76383.7","0.32726917","1"],["76388.1","0.95927787","2"],["76388.2","0.12703911","2"],["76397.6","0.52970142","2"],["76405.9","0.06545429","1"],["76417.4","1.14070285","4"],["76435","0.19493323","1"],["76472.6","0","0"],["76473","0","0"],["76473.2","0","0"],["76473.3","0","0"],["76473.5","0","0"]],"bids":[["76359.4","0.53853783","11"],["76356.6","0.21578158","1"],["76356.5","0","0"],["76350.8","0.04414899","1"],["76349.8","0.32726917","1"],["76349.1","0.1424387","1"],["76349","0","0"],["76348.8","0.01459738","1"],["76344.1","0.10393644","2"],["76318.4","0.19923697","3"],["76306.7","0.1153721","2"],["76306","0.00002863","1"],["76301.9","0.00233548","1"],["76291.8","0.00323256","1"],["76280.3","0","0"],["76276.2","0.04237704","1"],["76162.1","0","0"],["76162","0","0"],["76161.2","0","0"],["76161.1","0","0"]]}
{"instId":"BTC-USDT","action":"update","ts":"1776816000610","asks":[["76359.5","0.32730701","12"],["76364.9","0.1408138","2"],["76372.9","0.21224386","2"],["76377.5","1.01270666","2"],["76377.6","0.2533787","1"],["76380.6","0.32727339","1"],["76381.7","0.00001316","1"],["76383.6","0.0065456","1"],["76383.7","0.08378297","1"],["76388","0.20210951","2"],["76388.2","0.12049402","1"],["76388.3","0","0"],["76406","0.1","1"],["76417.4","1.01198591","3"],["76435","0","0"],["76472","0","0"],["76472.4","0","0"],["76472.5","0","0"]],"bids":[["76359.4","0.4510894","9"],["76356.6","0.11809556","1"],["76355.2","0.00654458","1"],["76351.7","0","0"],["76349.8","0","0"],["76349.1","0","0"],["76348.8","0","0"],["76347.4","0.0065456","1"],["76345.5","0.32727339","1"],["76345.1","0","0"],["76340.5","0.47151308","1"],["76340.1","0","0"],["76330.7","0.47151308","1"],["76326.7","0.00001934","1"],["76322.9","0.00001934","1"],["76319.1","0.00001934","1"],["76315.3","0.00001934","1"],["76311.5","0.00001934","1"],["76307.6","0.00001934","1"],["76303.8","0.00001935","1"],["76301.9","0.11302437","2"],["76300","0.00361174","5"],["76296.2","1.47769451","3"],["76292.4","0.00001935","1"],["76285","0.00013109","1"],["76283.6","0.03660924","1"],["76276.4","0.00065412","3"],["76266.9","0","0"],["76266.7","0","0"],["76258.1","0.345716","1"],["76200","1.01951805","52"],["76165.8","0","0"],["76165.2","0","0"],["76165.1","0","0"],["76164.3","0","0"],["76163.9","0","0"],["76162.2","0","0"]]}
{"instId":"BTC-USDT","action":"update","ts":"1776816000620","asks":[["76362","0","0"],["76372.9","0.21878856","3"],["76374.8","0.10611863","1"],["76377.4","0.63130518","1"],["76377.5","1.00616208","1"],["76377.6","0","0"],["76380.5","0.00654573","1"],["76383.6","0","0"],["76388.1","0.47151308","1"],["76435","0.19873424","1"],["76471.9","0","0"]],"bids":[["76355.2","0","0"],["76350.9","0.0065447","1"],["76347.4","0","0"],["76345.6","0.21438833","1"],["76345.5","0.33381912","2"],["76344.1","0.15571134","3"],["76325","0.092101","1"],["76300.2","0.00001155","1"],["76217.6","0.00001197","1"],["76186.5","0","0"],["76165.9","0","0"]]}
{"instId":"BTC-USDT","action":"update","ts":"1776816000630","asks":[["76374.5","0","0"],["76377.5","0","0"],["76380.2","0.092101","1"],["76388","0.69500962","3"],["76390.1","0","0"],["76411.1","0.345807","1"],["76435","0","0"],["76459.3","0.00319921","2"],["76471.9","0.0003932","1"],["76472","0.000059","1"]],"bids":[["76359.4","0.49395423","9"],["76344.1","0.05087713","1"],["76330.6","0.492358","1"],["76330.3","0","0"],["76308.7","0.00325196","1"],["76306.6","0.00233565","1"],["76304.4","0","0"],["76301.9","0.11068889","1"],["76166.2","0","0"]]}
{"instId":"BTC-USDT","action":"update","ts":"1776816000640","asks":[["76372.9","0.08852262","2"],["76374.8","0.15917794","2"],["76377.3","0.47151308","1"],["76377.4","0.2533787","1"],["76377.7","0","0"],["76378","0.00654574","1"],["76380.2","0","0"],["76380.5","0","0"],["76383.6","1.00616208","1"],["76383.8","0","0"],["76390.1","0.05305931","1"],["76411.1","0","0"],["76417.8","0","0"],["76425.7","0.00089963","1"],["76435","0.20010457","1"],["76448.6","0.659267","1"],["76452.3","0.65718763","2"]],"bids":[["76345.5","0.32727339","1"],["76342.8","0.00654574","1"],["76340.6","1.00616208","1"],["76333.9","0.43937519","2"],["76302.5","0.658348","1"],["76298.7","0.660561","1"],["76261.1","1.54297294","4"],["76252.9","1.553251","1"],["76200","0.01335597","51"],["76168.9","0","0"],["76168.6","0","0"],["76168.4","0","0"],["76167","0","0"],["76166.6","0","0"]]}
{"instId":"BTC-USDT","action":"update","ts":"1776816000650","asks":[["76359.5","0.36414635","14"],["76372.4","0.00654481","1"],["76372.9","0.11901182","2"],["76376","0","0"],["76377.4","0","0"],["76379.3","0.0165459","2"],["76383.6","0","0"],["76435","0","0"],["76472.4","0.00002715","1"],["76472.5","0.00008103","2"],["76472.6","0.00002975","1"]],"bids":[["76359.4","0.21167464","6"],["76351","0.00654481","1"],["76350.9","0","0"],["76343.9","0.01459831","1"],["76340.7","0.482988","1"],["76339.6","0","0"],["76321","0.00001","1"],["76292.5","0.3053285","2"],["76170","0","0"],["76169.2","0","0"]]}
{"instId":"BTC-USDT","action":"update","ts":"1776816000660","asks":[["76370.8","0.0471715","1"],["76374.8","0.21223725","3"],["76377.2","0.34393511","2"],["76380.7","0","0"],["76419","0.345809","1"],["76435.9","1.00774","1"],["76441","0.19482857","1"],["76452","0.98021546","2"],["76472","0","0"],["76472.4","0","0"],["76472.5","0","0"],["76472.6","0","0"]],"bids":[["76359.4","0.33022656","8"],["76346.3","0.01459786","1"],["76344.6","0.47151308","1"],["76343.9","0","0"],["76328.8","0.16441514","3"],["76325.3","0.07482501","1"],["76311.8","0.00002488","2"],["76305.9","0","0"],["76300","0.00360088","4"],["76298","0","0"],["76294.2","0","0"],["76294.1","0","0"],["76288.2","0","0"],["76282.3","0","0"],["76273.6","0.00002488","2"],["76267.7","0","0"],["76261.8","0","0"],["76256","0","0"],["76255.9","0","0"],["76250","0.73396591","4"],["76244.1","0","0"],["76243.6","0.08378297","1"],["76170","0.001571","1"],["76169.2","0.0001094","1"],["76168.9","0.000015","1"],["76168.4","0.00011049","4"],["76167","0.00001319","1"],["76166.6","0.00248493","6"],["76166.2","0.00026145","4"],["76165.9","0.47151308","1"]]}
{"instId":"BTC-USDT","action":"update","ts":"1776816000670","asks":[["76359.5","0.36396301","14"],["76380.5","0.26369418","1"],["76383.6","1.00616208","1"],["76398","0.000025","2"],["76425.6","0.48975453","4"],["76432.8","0.00096651","2"],["76441","0","0"],["76471.9","0","0"]],"bids":[["76345.6","0.31384155","2"],["76325.4","0.1290835","1"],["76320.4","0","0"],["76317","0","0"],["76311.8","0","0"],["76311.4","0","0"],["76305.8","0","0"],["76305.6","0","0"],["76300.2","0","0"],["76299.4","0","0"],["76298.6","0","0"],["76294.6","0","0"],["76293.2","0.03498","1"],["76289","0","0"],["76287","1.0013","1"],["76280.8","0","0"],["76278.8","0","0"],["76273.6","0","0"],["76273.2","1.00616208","1"],["76267.6","0.00001316","1"],["76267.4","0","0"],["76262","0","0"],["76261.2","0","0"],["76260.4","0","0"],["76256.4","0","0"],["76255","0","0"],["76250.8","0","0"],["76248.8","0.01327363","1"],["76242.6","0","0"],["76168.6","0.1305","1"],["76165.8","0.01614584","1"],["76165.2","0.00091086","3"],["76165.1","0.00001015","1"],["76164.3","0.00046091","2"],["76163.9","0.00005592","3"],["76162.2","0.00002057","1"],["76162.1","0.00004159","3"],["76162","0.00001017","1"],["76161.2","0.00007766","2"],["76161.1","0.0000827","1"],["76160.4","0.01614584","1"],["76160.2","0.00705391","1"],["76160","0.00187493","7"],["76159.3","0.00040006","1"],["76159.1","0.00002078","1"],["76158.5","0.0002223","1"],["76157.8","0.00003012","1"],["76157.7","0.00011366","1"],["76157.6","0.47151308","1"],["76157.5","0.00012326","1"]]}
{"instId":"BTC-USDT","action":"update","ts":"1776816000680","asks":[["76374.2","0.47151308","1"],["76380.5","0.53032078","2"],["76406","0","0"],["76417.4","1.01194587","2"],["76422.3","0.00004004","1"],["76441","0.19550872","1"],["76471.7","0","0"],["76471.8","0","0"]],"bids":[["76359.4","0.43022656","9"],["76334.9","0.04010113","1"],["76296.9","0.00323278","1"],["76291.8","0","0"],["76160.9","0.1305","1"],["76157.6","0","0"],["76157.5","0","0"]]}
{"instId":"BTC-USDT","action":"update","ts":"1776816000690","asks":[["76360.8","0.00012564","1"],["76372.9","0.27085899","1"],["76377.2","0.26015214","1"],["76435.6","0.00002082","1"],["76441","0","0"],["76470.3","0.0205439","2"],["76471.5","0","0"]],"bids":[["76334.9","0.15842767","2"],["76330.8","0","0"],["76319.2","0.32596191","1"],["76157.6","0.47151308","1"]]}
{"instId":"BTC-USDT","action":"update","ts":"1776816000700","asks":[["76392","0.25051782","2"],["76422.3","0","0"],["76441","0.19952389","1"]],"bids":[["76335","0.0754216","1"],["76334.9","0.11832654","1"],["76328.8","0.21619004","4"],["76213.5","0","0"]]}
{"instId":"BTC-USDT","action":"update","ts":"1776816000710","asks":[["76359.5","0.36352881","14"],["76378.9","0.08378297","1"],["76402.6","0.03924266","1"],["76441","0","0"],["76471.4","0","0"]],"bids":[["76355.1","0.19570377","3"],["76351.3","0.00007377","1"],["76347.5","0.00012006","2"],["76343.7","0.00007377","1"],["76342","0.0000168","1"],["76339.9","0.00007377","1"],["76338.2","0.0000168","1"],["76336","0.00007377","1"],["76334.4","0.0000168","1"],["76332.2","0.00012007","2"],["76330.6","0.4923748","2"],["76328.4","0.00007378","1"],["76326.8","0.0000168","1"],["76324.6","0.00008694","2"],["76322.9","0.00003614","2"],["76320.8","0.00007378","1"],["76319.1","0.00003614","2"],["76318","0.00002863","1"],["76315.3","0.00003615","2"],["76311.5","0.00003615","2"],["76307.7","0.00001681","1"],["76306","0","0"],["76296.3","0.61732655","1"],["76162.1","0","0"],["76162","0","0"],["76161.2","0","0"],["76161.1","0","0"],["76160.9","0","0"],["76160.4","0","0"],["76160.2","0","0"],["76160","0","0"],["76159.3","0","0"],["76159.1","0","0"],["76158.5","0","0"],["76157.8","0","0"],["76157.7","0","0"],["76157.6","0","0"]]}
{"instId":"BTC-USDT","action":"update","ts":"1776816000720","asks":[["76378.8","0.12370502","1"],["76379.1","0","0"],["76402.6","0.17370464","2"],["76406.9","0.67597148","2"],["76408.3","0","0"],["76416.6","0.2305","2"],["76438.5","0.03389228","7"],["76441","0.19907753","1"]],"bids":[["76355.1","0.1957604","5"],["76351.3","0.00012006","2"],["76349.8","0.00001034","1"],["76344.5","0.13051035","2"],["76343.7","0.00012006","2"],["76339.9","0.00012006","2"],["76339.2","0.00001035","1"],["76336","0.00012006","2"],["76335.1","0.13177274","1"],["76334.8","0","0"],["76333.9","0.43938554","3"],["76328.6","0.00001035","1"],["76328.4","0.00012008","2"],["76324.6","0.00013324","3"],["76323.3","0.00001035","1"],["76320.8","0.00012008","2"],["76287.1","0.3239364","1"],["76285.3","0","0"],["76188.1","0.00955277","2"],["76165.1","0","0"],["76164.3","0","0"],["76163.9","0","0"],["76162.2","0","0"]]}
{"instId":"BTC-USDT","action":"update","ts":"1776816000730","asks":[["76377.1","1.00616208","1"],["76402.5","0.07937956","1"],["76402.6","0.13446198","1"],["76416.1","0.1202836","1"],["76441","0","0"],["76471.2","0","0"],["76471.3","0","0"]],"bids":[["76350.3","0.00261839","1"],["76349.8","0.1226934","2"],["76347.3","0","0"],["76340.8","0.12639426","1"],["76335.2","0.07465965","1"],["76335","0.00523678","1"],["76334.9","0","0"],["76330.8","0.1290835","1"],["76328.8","0.21095284","3"],["76325.2","0","0"],["76317.6","0.11832654","1"],["76313.4","0","0"],["76308.7","0.1215785","2"],["76306.7","0.00001501","1"],["76304.3","0.12571061","2"],["76301.9","0","0"]]}
{"instId":"BTC-USDT","action":"update","ts":"1776816000740","asks":[["76371.1","0.47151308","1"],["76377","0.6608426","1"],["76377.2","0","0"],["76402.4","0.13177274","1"],["76402.7","0","0"],["76416","0.11832654","1"],["76416.1","0","0"],["76441","0.19616394","1"],["76470.8","0","0"],["76471.1","0","0"]],"bids":[["76350.8","0.0759102","2"],["76350.3","0.12901265","2"],["76340.8","0","0"],["76335.2","0","0"],["76325.3","0","0"],["76304.4","0.10736118","1"],["76304.3","0.00738407","1"],["76170.4","0","0"],["76165.1","0.00001015","1"],["76164.3","0.00046091","2"],["76163.9","0.00005592","3"]]}
{"instId":"BTC-USDT","action":"update","ts":"1776816000750","asks":[["76369.1","0","0"],["76381.7","0.09211416","2"],["76402.3","0.07947106","1"],["76402.5","0","0"],["76412.5","0.345807","1"]],"bids":[["76350.8","0.10957828","1"]]}
{"instId":"BTC-USDT","action":"update","ts":"1776816000760","asks":[["76369.8","0.19847686","1"],["76402.6","0","0"]],"bids":[]}
{"instId":"BTC-USDT","action":"update","ts":"1776816000770","asks":[["76379","0","0"],["76402.3","0.03933416","1"],["76470.8","0.0001444","7"]],"bids":[]}
{"instId":"BTC-USDT","action":"update","ts":"1776816000780","asks":[["76402.3","0.14622675","2"],["76416.1","0.54049256","1"],["76427.4","0.00001013","1"],["76470.8","0","0"]],"bids":[["76297.7","0","0"],["76162.2","0.00002057","1"]]}
{"instId":"BTC-USDT","action":"update","ts":"1776816000790","asks":[["76412.4","0.1080474","1"],["76470.6","0","0"]],"bids":[["76325.5","0.04898807","1"],["76322.8","0.00002862","1"],["76318","0","0"],["76272.1","0","0"]]}
{"instId":"BTC-USDT","action":"update","ts":"1776816000800","asks":[["76359.5","0.36348953","14"],["76364.8","0.04237407","1"],["76453","0","0"],["76470.3","0.00003942","1"]],"bids":[["76335.2","0.03933918","1"],["76162.2","0","0"]]}
{"instId":"BTC-USDT","action":"update","ts":"1776816000810","asks":[["76402.2","0.05926074","1"],["76402.3","0.10689259","1"],["76434.8","1.0745614","2"],["76470.5","0","0"]],"bids":[["76298.8","0.26394814","1"],["76277","0.21398986","2"],["76163.9","0","0"]]}
{"instId":"BTC-USDT","action":"update","ts":"1776816000820","asks":[["76402.1","0.11352086","1"],["76418.9","0.15152545","1"],["76422.4","0.46189407","2"],["76424.7","0","0"],["76425.6","0.58107818","5"],["76470.3","0","0"]],"bids":[["76359.4","0.43031077","14"],["76357.3","0.0000168","1"],["76355.6","0.00003694","1"],["76353.8","0.00001155","1"],["76353.2","0.00001033","1"],["76351.8","0.00003694","1"],["76348.2","0.00001155","1"],["76348","0.00003694","1"],["76347","0.00001033","1"],["76346.2","0.00001456","1"],["76344.2","0.00003694","1"],["76342.6","0.00001155","1"],["76341.7","0.00001085","1"],["76340.8","0.00001033","1"],["76340.3","0.00003694","1"],["76337","0.00001155","1"],["76336.5","0.00003695","1"],["76334.6","0.00001033","1"],["76332.7","0.00003695","1"],["76331.4","0.00001155","1"],["76328.9","0.00003695","1"],["76328.4","0.00013042","3"],["76325.1","0.00003695","1"],["76278.6","0.14075416","1"],["76261.2","0.62669093","2"],["76253.5","0.73954563","5"],["76246.3","0","0"],["76175","0","0"],["76173.7","0","0"],["76173.6","0","0"],["76173.2","0","0"],["76173","0","0"],["76171.4","0","0"],["76171.1","0","0"],["76170.8","0","0"],["76170.2","0","0"],["76170","0","0"],["76169.2","0","0"],["76168.9","0","0"],["76168.6","0","0"],["76168.4","0","0"],["76167","0","0"],["76166.6","0","0"],["76166.2","0","0"],["76165.9","0","0"],["76165.8","0","0"],["76165.2","0","0"],["76165.1","0","0"],["76164.3","0","0"]]}
{"instId":"BTC-USDT","action":"update","ts":"1776816000830","asks":[["76374.8","0.15917794","2"],["76422.3","0.00004006","1"],["76431.7","0.02920465","1"],["76470","0","0"],["76470.2","0","0"]],"bids":[["76359.4","0.43032163","15"],["76353.5","0.00001086","1"],["76347.6","0.00001086","1"],["76341.7","0.00002171","2"],["76335.8","0.00001086","1"],["76329.9","0.00001087","1"],["76177.8","0","0"],["76176.3","0","0"],["76175.4","0","0"],["76175.1","0","0"]]}
{"instId":"BTC-USDT","action":"update","ts":"1776816000840","asks":[["76390.1","0.10611862","2"],["76442.2","0.574899","3"]],"bids":[]}
{"instId":"BTC-USDT","action":"update","ts":"1776816000850","asks":[["76437.4","0.17965236","2"]],"bids":[]}
{"instId":"BTC-USDT","action":"update","ts":"1776816000860","asks":[["76359.5","0.36395638","15"]],"bids":[]}
{"instId":"BTC-USDT","action":"update","ts":"1776816000870","asks":[["76390.1","0.05305931","1"]],"bids":[]}
{"instId":"BTC-USDT","action":"update","ts":"1776816000880","asks":[["76374.8","0.21223725","3"]],"bids":[["76359.4","0.45523163","16"]]}
{"instId":"BTC-USDT","action":"update","ts":"1776816000890","asks":[["76367.6","0.0471865","2"],["76370.8","0","0"],["76441","0","0"],["76470","0.00007723","1"],["76470.2","0.05814278","2"]],"bids":[]}
{"instId":"BTC-USDT","action":"update","ts":"1776816000900","asks":[["76402.8","0.26628551","2"],["76446.5","0.48239089","1"],["76470.2","0","0"]],"bids":[]}
{"instId":"BTC-USDT","action":"update","ts":"1776816000910","asks":[["76359.5","0.36385162","15"],["76388","0.55426297","3"]],"bids":[]}
{"instId":"BTC-USDT","action":"update","ts":"1776816000930","asks":[],"bids":[["76321.2","0.00001033","1"],["76315","0.00001033","1"],["76308.8","0.00001033","1"],["76302.6","0.00001033","1"],["76296.4","0.00001033","1"],["76290.2","0.00001034","1"],["76180.1","0","0"],["76180","0","0"],["76179.9","0","0"],["76179.3","0","0"],["76178.9","0","0"],["76177.9","0","0"]]}
{"instId":"BTC-USDT","action":"update","ts":"1776816000940","asks":[],"bids":[["76321.2","0.00002119","2"],["76315.3","0.00004701","3"],["76309.4","0.00001086","1"],["76303.5","0.34619248","2"],["76297.6","0.01310346","2"],["76291.7","0.0001228","3"],["76181.6","0","0"]]}
{"instId":"BTC-USDT","action":"update","ts":"1776816000960","asks":[["76359.5","0.24324743","7"],["76364.8","0","0"],["76466.8","0.00570341","1"]],"bids":[["76359.4","0.46143163","17"],["76355.2","0.11209653","1"],["76340.8","0.00672254","2"],["76330.9","0.08378297","1"],["76315.2","0.00704782","1"],["76304.4","0","0"],["76182.7","0","0"],["76182.2","0","0"]]}
{"instId":"BTC-USDT","action":"update","ts":"1776816000970","asks":[["76359.5","0.01262014","3"],["76364.9","0.00001316","1"],["76371.1","0","0"],["76374.8","0","0"],["76377.1","0","0"],["76378","0","0"],["76378.9","0","0"],["76380.7","0.00654558","1"],["76402.2","0.10033374","2"],["76417.2","0.01953406","1"],["76461.1","0.01477699","2"],["76470.2","0.05814278","2"],["76470.3","0.00003942","1"],["76470.5","0.00926628","18"]],"bids":[["76356.6","0.26636472","3"],["76355.3","0.16","1"],["76354.9","0","0"],["76345.7","0.00654558","1"],["76342.8","0","0"],["76340.9","0.01614584","1"],["76335.3","0.08378297","1"],["76328.8","0.05305931","1"],["76294.5","0.01931769","1"],["76243.6","0","0"],["76183.3","0","0"],["76183","0","0"]]}
{"instId":"BTC-USDT","action":"update","ts":"1776816000980","asks":[["76361.9","0.01241895","1"],["76369.8","0.04364952","1"],["76372.4","0","0"],["76376.9","0.00654518","1"],["76377","0","0"],["76379.3","0.00040006","1"],["76383.7","0","0"],["76387.2","0.015511","1"],["76388","0.47048","2"],["76390.1","0.26529656","4"],["76391.9","0","0"],["76470.6","0.01580142","1"]],"bids":[["76359.4","0.68179905","18"],["76355.3","0.26654518","3"],["76355","0","0"],["76354.7","0.02619","1"],["76351","0","0"],["76350.7","0","0"],["76350.4","0.47151308","1"],["76346.2","0.01583497","2"],["76344.1","0.20877066","3"],["76340.8","0.09050551","3"],["76335.4","0.06435148","1"],["76335.2","0","0"],["76328.8","0","0"],["76320.3","0.12101578","1"],["76317.6","0","0"],["76315.7","0","0"],["76308.7","0.00325196","1"],["76253.6","0","0"],["76183.3","0.00009283","1"],["76183","0.01496","1"],["76182.7","0.00002401","2"],["76182.2","0.00875","1"]]}
{"instId":"BTC-USDT","action":"update","ts":"1776816000990","asks":[["76377.2","0.21746273","1"],["76380.6","0","0"],["76380.7","0","0"],["76381.6","0.327276","1"],["76383.5","0.00654556","1"],["76388","0.62955734","3"],["76420.8","0.12640926","2"],["76470.6","0","0"]],"bids":[["76350.8","0.23820282","2"],["76350.5","0.327276","1"],["76347.6","0.00655642","2"],["76345.7","0","0"],["76345.5","0","0"],["76344.1","0.26182997","4"],["76330.8","0","0"],["76325.4","0","0"],["76322.9","0.1264304","3"],["76320.4","0.12101578","1"],["76320.3","0","0"],["76314.6","0.13189782","4"],["76238","0.12","1"],["76181.6","0.00073364","2"],["76180.1","0.00013128","1"],["76180","0.0000812","1"]]}
{"instId":"BTC-USDT","action":"update","ts":"1776816001000","asks":[["76381.6","0","0"],["76383.5","0.33381382","2"],["76470.6","0.01580142","1"]],"bids":[["76350.9","0.32726826","1"],["76350.5","0","0"],["76325.5","0.03236557","1"]]}
{"instId":"BTC-USDT","action":"update","ts":"1776816001010","asks":[],"bids":[["76351","0.35995169","1"],["76350.8","0","0"],["76289.5","0.47164416","2"],["76285","0","0"],["76281","0.00055534","2"],["76276.4","0.00011192","2"],["76250.1","0","0"],["76179.9","0.47151308","1"],["76179.3","0.00040006","1"]]}
{"instId":"BTC-USDT","action":"update","ts":"1776816001020","asks":[["76390.1","0.10611862","2"],["76392.4","0.08378297","1"],["76470.6","0","0"]],"bids":[["76344.1","0.10265203","2"],["76335.1","0","0"],["76330.8","0.12106302","1"]]}
{"instId":"BTC-USDT","action":"update","ts":"1776816001030","asks":[],"bids":[["76349.7","0.0131","1"],["76340.4","0","0"],["76336.5","0.11840968","2"],["76335.4","0.02501731","1"],["76332.1","0.15437273","2"],["76314.7","0.13182418","1"],["76314.6","0.00012508","3"]]}
{"instId":"BTC-USDT","action":"update","ts":"1776816001040","asks":[],"bids":[["76336.6","0.06196486","1"],["76335.4","0","0"]]}
{"instId":"BTC-USDT","action":"update","ts":"1776816001050","asks":[["76387.2","0","0"],["76387.9","0.08378297","1"]],"bids":[]}
{"instId":"BTC-USDT","action":"update","ts":"1776816001060","asks":[["76374.8","0.15917794","2"],["76387.8","0.11837273","1"],["76388.2","0","0"],["76420.7","0.1264436","1"],["76420.8","0.000015","1"],["76470.3","0","0"],["76470.5","0","0"]],"bids":[["76328.8","0.15917794","2"],["76179.3","0","0"]]}
{"instId":"BTC-USDT","action":"update","ts":"1776816001070","asks":[],"bids":[["76184.2","3.72","1"],["76179.9","0","0"]]}
{"instId":"BTC-USDT","action":"update","ts":"1776816001080","asks":[],"bids":[["76344.1","0.05087713","1"]]}
{"instId":"BTC-USDT","action":"update","ts":"1776816001100","asks":[],"bids":[["76328.8","0.21095284","3"]]}
{"instId":"BTC-USDT","action":"update","ts":"1776816001110","asks":[["76359.5","0.01263014","4"]],"bids":[]}
{"instId":"BTC-USDT","action":"update","ts":"1776816001120","asks":[["76380.7","0.32727098","1"],["76383.5","0.00654556","1"],["76390.1","0.05305931","1"],["76470.2","0","0"]],"bids":[["76350.9","0","0"],["76345.7","0.32727098","1"]]}
{"instId":"BTC-USDT","action":"update","ts":"1776816001130","asks":[["76359.5","0.04363014","6"],["76374.8","0.21223725","3"],["76402","0.1655182","1"],["76402.2","0","0"]],"bids":[["76355.3","0.10654518","2"],["76351","0.21979126","1"]]}
{"instId":"BTC-USDT","action":"update","ts":"1776816001140","asks":[["76401.9","0.11837273","1"],["76402.4","0","0"],["76420.7","0","0"],["76470.2","0.05814278","2"]],"bids":[]}
{"instId":"BTC-USDT","action":"update","ts":"1776816001150","asks":[["76444.2","0.01802","1"],["76470.2","0","0"]],"bids":[]}
{"instId":"BTC-USDT","action":"update","ts":"1776816001160","asks":[],"bids":[["76292.5","0.2053285","1"]]}
{"instId":"BTC-USDT","action":"update","ts":"1776816001170","asks":[["76420.8","0.11463442","2"]],"bids":[]}
{"instId":"BTC-USDT","action":"update","ts":"1776816001180","asks":[],"bids":[["76359.4","0.68105872","18"]]}
{"instId":"BTC-USDT","action":"update","ts":"1776816001200","asks":[["76359.5","0.01383014","5"]],"bids":[["76308.2","0.1","1"],["76180","0","0"]]}
{"instId":"BTC-USDT","action":"update","ts":"1776816001210","asks":[["76359.5","0.01263014","4"],["76373.5","0.00654481","1"],["76376.9","0","0"]],"bids":[["76355.3","0.1","1"],["76351.1","0.00654481","1"],["76180.1","0","0"]]}
{"instId":"BTC-USDT","action":"update","ts":"1776816001220","asks":[["76373.5","0","0"],["76374.1","0.00654482","1"]],"bids":[["76354.8","0.00654482","1"],["76351.1","0","0"]]}
{"instId":"BTC-USDT","action":"update","ts":"1776816001230","asks":[],"bids":[["76350.5","0.11427263","1"],["76349.8","0.00001034","1"],["76181.6","0","0"]]}
{"instId":"BTC-USDT","action":"update","ts":"1776816001240","asks":[],"bids":[["76354.8","0","0"],["76351.1","0.00654473","1"]]}
{"instId":"BTC-USDT","action":"update","ts":"1776816001250","asks":[],"bids":[["76351.1","0.00654476","1"],["76350.3","0.00261839","1"],["76345.8","0.12375331","1"],["76182.2","0","0"]]}
{"instId":"BTC-USDT","action":"update","ts":"1776816001260","asks":[],"bids":[["76346.3","0.05626496","2"],["76308.8","0.11209682","2"]]}
{"instId":"BTC-USDT","action":"update","ts":"1776816001270","asks":[["76374.8","0.10611862","2"]],"bids":[]}
{"instId":"BTC-USDT","action":"update","ts":"1776816001280","asks":[["76374.8","0.21223725","3"]],"bids":[]}
{"instId":"BTC-USDT","action":"update","ts":"1776816001310","asks":[],"bids":[["76344.8","0.00001316","1"],["76341.4","0.00001316","1"],["76183","0","0"],["76182.7","0","0"]]}
{"instId":"BTC-USDT","action":"update","ts":"1776816001330","asks":[["76374.8","0.15917794","2"]],"bids":[["76337","0.10867957","2"],["76330.8","0","0"],["76323","0.10861783","1"],["76322.9","0.00003614","2"],["76308.9","0.12480457","1"],["76308.8","0.00001033","1"],["76183.3","0","0"]]}
{"instId":"BTC-USDT","action":"update","ts":"1776816001340","asks":[["76361.9","0","0"],["76390.1","0.10611862","2"],["76470.2","0.05814278","2"]],"bids":[["76337.1","0.09442071","2"],["76336.6","0","0"],["76183.3","0.00009283","1"]]}
{"instId":"BTC-USDT","action":"update","ts":"1776816001350","asks":[],"bids":[["76325.5","0.06065012","2"]]}
{"instId":"BTC-USDT","action":"update","ts":"1776816001360","asks":[["76359.6","0.01241934","1"],["76470.2","0","0"]],"bids":[]}
{"instId":"BTC-USDT","action":"update","ts":"1776816001370","asks":[["76359.5","0.01251228","4"],["76383.9","0.29540756","2"]],"bids":[["76328.8","0.15917794","2"]]}
{"instId":"BTC-USDT","action":"update","ts":"1776816001380","asks":[["76374.8","0.05305931","1"],["76379.9","0.00654567","1"],["76383.5","0","0"]],"bids":[["76347.6","0.00001086","1"],["76344.7","0.00656067","2"],["76344.1","0.10265203","2"],["76316.8","0.00131032","1"],["76296.8","0","0"]]}
{"instId":"BTC-USDT","action":"update","ts":"1776816001390","asks":[["76388","0.5112308","2"],["76390.1","0.05305931","1"],["76390.5","0.11837273","1"],["76470","0","0"]],"bids":[["76344.1","0.05087713","1"]]}
{"instId":"BTC-USDT","action":"update","ts":"1776816001400","asks":[["76359.5","0.01215742","4"],["76374.8","0.15917794","2"]],"bids":[]}
{"instId":"BTC-USDT","action":"update","ts":"1776816001410","asks":[["76359.5","0.01180384","4"]],"bids":[]}
{"instId":"BTC-USDT","action":"update","ts":"1776816001420","asks":[["76374.8","0","0"],["76470","0.00007723","1"]],"bids":[["76344.1","0.10265203","2"],["76328.8","0","0"],["76183","0.01496","1"]]}
{"instId":"BTC-USDT","action":"update","ts":"1776816001440","asks":[["76374.8","0.05305931","1"],["76390.1","0.15917794","2"],["76470","0","0"]],"bids":[["76328.8","0.05305931","1"],["76183","0","0"]]}
{"instId":"BTC-USDT","action":"update","ts":"1776816001470","asks":[["76374.8","0","0"],["76390.1","0.21223725","3"],["76470","0.00007723","1"]],"bids":[["76328.8","0","0"],["76232.3","0","0"],["76194.2","0","0"],["76183","0.01496","1"],["76182.7","0.00002401","2"],["76182.2","0.00875","1"]]}
{"instId":"BTC-USDT","action":"update","ts":"1776816001490","asks":[["76387.4","0.01609683","1"],["76470","0","0"]],"bids":[]}
{"instId":"BTC-USDT","action":"update","ts":"1776816001500","asks":[["76359.5","0.07082384","5"]],"bids":[]}
{"instId":"BTC-USDT","action":"update","ts":"1776816001510","asks":[["76359.5","0.07056193","5"]],"bids":[]}
{"instId":"BTC-USDT","action":"update","ts":"1776816001520","asks":[["76390.1","0.10611862","2"]],"bids":[]}
{"instId":"BTC-USDT","action":"update","ts":"1776816001530","asks":[],"bids":[["76313.4","0.00131038","1"],["76298.9","0","0"]]}
{"instId":"BTC-USDT","action":"update","ts":"1776816001550","asks":[["76374.8","0.10611863","1"],["76469.7","0","0"]],"bids":[["76216.2","0","0"],["76181.6","0.00073364","2"]]}
{"instId":"BTC-USDT","action":"update","ts":"1776816001570","asks":[["76374.8","0","0"],["76469.7","0.00021564","6"]],"bids":[]}
{"instId":"BTC-USDT","action":"update","ts":"1776816001600","asks":[["76390.1","0.15917793","3"],["76417.2","0","0"],["76461.1","0.00003024","1"],["76470","0.00007723","1"]],"bids":[["76356.7","0.16","1"],["76344.1","0.20877066","3"],["76263.3","0.01480285","1"],["76225.1","0.01164598","1"],["76182.7","0","0"],["76182.2","0","0"],["76181.6","0","0"]]}
{"instId":"BTC-USDT","action":"update","ts":"1776816001610","asks":[],"bids":[["76359.4","0.5625068","16"]]}
{"instId":"BTC-USDT","action":"update","ts":"1776816001620","asks":[["76390.1","0.10611862","2"]],"bids":[]}
{"instId":"BTC-USDT","action":"update","ts":"1776816001630","asks":[["76374.8","0.10611863","1"],["76387.4","0","0"],["76389.8","0.01574948","1"],["76390.1","0.05305931","1"],["76470","0","0"]],"bids":[["76346.2","0.00001456","1"],["76344.1","0.05087713","1"],["76342.4","0.01534896","1"],["76263.3","0","0"],["76225.1","0","0"],["76196.9","0","0"],["76182.7","0.00002401","2"],["76182.2","0.00875","1"]]}
{"instId":"BTC-USDT","action":"update","ts":"1776816001640","asks":[["76374.8","0.15917794","2"]],"bids":[["76328.8","0.0517749","1"],["76182.2","0","0"]]}
{"instId":"BTC-USDT","action":"update","ts":"1776816001680","asks":[["76374.8","0.21223725","3"]],"bids":[["76356.7","0","0"],["76328.8","0.21095284","3"],["76182.2","0.00875","1"]]}
{"instId":"BTC-USDT","action":"update","ts":"1776816001710","asks":[["76359.5","0.07046373","5"],["76374.8","0.05305931","1"]],"bids":[]}
{"instId":"BTC-USDT","action":"update","ts":"1776816001720","asks":[["76373","0","0"],["76390.1","0.15917794","2"],["76470","0.00007723","1"]],"bids":[["76296.5","0","0"],["76181.6","0.00073364","2"]]}
{"instId":"BTC-USDT","action":"update","ts":"1776816001760","asks":[["76374.8","0.10611862","2"]],"bids":[]}
{"instId":"BTC-USDT","action":"update","ts":"1776816001780","asks":[],"bids":[["76300.8","0.06310997","1"],["76181.6","0","0"]]}
{"instId":"BTC-USDT","action":"update","ts":"1776816001790","asks":[],"bids":[["76303.5","0.47765037","3"]]}
{"instId":"BTC-USDT","action":"update","ts":"1776816001820","asks":[["76374.8","0.05305931","1"]],"bids":[["76248.2","0.00514413","1"],["76182.2","0","0"]]}
{"instId":"BTC-USDT","action":"update","ts":"1776816001840","asks":[["76374.8","0.10611862","2"]],"bids":[]}
{"instId":"BTC-USDT","action":"update","ts":"1776816001850","asks":[["76374.8","0.05305931","1"]],"bids":[]}
{"instId":"BTC-USDT","action":"update","ts":"1776816001860","asks":[["76390.1","0.21223725","3"]],"bids":[]}
{"instId":"BTC-USDT","action":"update","ts":"1776816001870","asks":[["76390.1","0.15917794","2"],["76454.1","0.12005044","2"]],"bids":[["76264.9","0.12","1"],["76182.7","0","0"]]}
{"instId":"BTC-USDT","action":"update","ts":"1776816001880","asks":[],"bids":[["76300.8","0","0"],["76182.7","0.00002401","2"]]}
{"instId":"BTC-USDT","action":"update","ts":"1776816001920","asks":[["76359.5","0.26899017","9"],["76369.8","0.15345977","2"],["76374.8","0.10611862","2"],["76377.1","1.00576942","1"],["76390.1","0.05305931","1"],["76470","0","0"]],"bids":[["76359.4","0.34213938","15"]]}
{"instId":"BTC-USDT","action":"update","ts":"1776816001930","asks":[["76367.5","0.01442184","1"],["76372.4","0.00654493","1"],["76374.1","0","0"],["76377","0.32728492","1"],["76377.2","0.22400839","2"],["76379.9","0","0"],["76380.7","0","0"],["76390.6","1.02163746","2"],["76395.5","0.06354858","1"],["76420.8","0.000015","1"],["76469.7","0","0"]],"bids":[["76351.1","0","0"],["76350.6","0.00654493","1"],["76345.7","0","0"],["76344.7","0.000015","1"],["76343.2","0.0156355","1"],["76342.8","0.32728492","1"],["76342.5","0.00654566","1"],["76340.8","0.00672254","2"],["76304.5","0.11225868","2"],["76183","0","0"],["76182.7","0","0"]]}
{"instId":"BTC-USDT","action":"update","ts":"1776816001940","asks":[["76369.7","0.08297284","2"],["76369.8","0.10981025","1"],["76372.4","0","0"],["76374.8","0.21223725","3"]],"bids":[["76350.6","0","0"],["76347.3","0.00654493","1"]]}
{"instId":"BTC-USDT","action":"update","ts":"1776816001950","asks":[["76359.5","0.33874025","10"],["76369.6","0.12913389","1"],["76371","0.47151308","1"],["76469.4","0","0"],["76469.6","0","0"]],"bids":[]}
{"instId":"BTC-USDT","action":"update","ts":"1776816001960","asks":[["76359.5","0.34135821","11"],["76369.7","0.21199468","3"],["76369.9","0","0"],["76469.4","0.00265436","2"]],"bids":[]}
{"instId":"BTC-USDT","action":"update","ts":"1776816001970","asks":[["76377","0.84210417","2"],["76377.2","0.00654566","1"]],"bids":[["76233.8","0","0"],["76183","0.01496","1"]]}
{"instId":"BTC-USDT","action":"update","ts":"1776816001980","asks":[["76359.5","0.34310821","12"]],"bids":[["76359.4","0.33593938","14"],["76350.4","0","0"],["76344.1","0","0"],["76182.7","0.00002401","2"],["76182.2","0.00875","1"]]}
{"instId":"BTC-USDT","action":"update","ts":"1776816001990","asks":[],"bids":[["76351","0.03880541","1"],["76346.3","0.0416671","1"],["76328.8","0.26182997","4"]]}
{"instId":"BTC-USDT","action":"update","ts":"1776816002000","asks":[["76359.5","0.33745985","11"]],"bids":[["76343.9","0.01134391","1"],["76182.2","0","0"]]}
{"instId":"BTC-USDT","action":"update","ts":"1776816002010","asks":[["76369.5","0.00654513","1"],["76369.7","0.20544975","2"],["76376.9","0.32730009","1"],["76377","0.52136527","2"],["76377.2","0","0"],["76469.4","0","0"]],"bids":[["76349.8","0.00655547","2"],["76347.3","0","0"],["76328.8","0.21095284","3"],["76182.2","0.00875","1"]]}
{"instId":"BTC-USDT","action":"update","ts":"1776816002020","asks":[["76369.5","0.13029844","2"],["76369.8","0","0"],["76469.4","0.00265436","2"]],"bids":[["76344.1","0.05087713","1"],["76182.2","0","0"]]}
{"instId":"BTC-USDT","action":"update","ts":"1776816002030","asks":[["76369.4","0.00654512","1"],["76369.5","0.32586409","2"],["76369.7","0","0"],["76376.8","0.09032899","2"],["76377","0.51481925","1"],["76380.4","0.01614584","1"],["76390.1","0","0"],["76469.4","0","0"]],"bids":[["76344.1","0","0"],["76342.9","0.32730319","1"],["76342.8","0","0"],["76342.5","0","0"],["76341","0.00654602","1"],["76296.9","0","0"],["76296.7","0.00323281","1"],["76182.2","0.00875","1"]]}
{"instId":"BTC-USDT","action":"update","ts":"1776816002040","asks":[["76369.4","0.12760814","2"],["76369.6","0","0"],["76374.7","0.32730405","1"],["76376.9","0","0"],["76395.5","0","0"],["76469.4","0.00265436","2"],["76469.6","0.00441584","1"]],"bids":[["76359.4","0.23593938","13"],["76349.8","0.00001034","1"],["76347.3","0.00654516","1"],["76344.6","0","0"],["76342.9","0","0"],["76342.8","0.32730405","1"],["76309","0.0032519","1"],["76308.7","0","0"]]}
{"instId":"BTC-USDT","action":"update","ts":"1776816002050","asks":[["76359.5","0.34007792","12"],["76369.4","0.36562915","3"],["76369.5","0.12375331","1"]],"bids":[["76345.6","0.21438833","1"],["76309","0.12431492","2"],["76304.5","0.00001316","1"]]}
{"instId":"BTC-USDT","action":"update","ts":"1776816002060","asks":[["76369.4","0.30529909","3"],["76374.8","0.26529656","4"]],"bids":[]}
{"instId":"BTC-USDT","action":"update","ts":"1776816002070","asks":[],"bids":[["76344.6","0.47151308","1"],["76182.2","0","0"]]}
{"instId":"BTC-USDT","action":"update","ts":"1776816002080","asks":[["76374.1","0.32730952","1"],["76374.7","0","0"],["76376.7","0.00654615","1"],["76376.8","0.08378297","1"],["76469.6","0","0"]],"bids":[["76345.6","0.30940734","2"],["76341","0","0"],["76340.9","0.02269199","2"],["76182.2","0.00875","1"]]}
{"instId":"BTC-USDT","action":"update","ts":"1776816002090","asks":[],"bids":[["76328.8","0.26182997","4"]]}
{"instId":"BTC-USDT","action":"update","ts":"1776816002120","asks":[["76365.1","0.0471715","1"],["76367.6","0.000015","1"],["76469.4","0","0"]],"bids":[]}
{"instId":"BTC-USDT","action":"update","ts":"1776816002130","asks":[["76365","0.01442184","1"],["76367.5","0","0"],["76428.5","0.0438184","36"]],"bids":[["76223.1","0.01440713","2"]]}
{"instId":"BTC-USDT","action":"update","ts":"1776816002140","asks":[["76367.8","0.47151308","1"],["76469.2","0","0"]],"bids":[]}
{"instId":"BTC-USDT","action":"update","ts":"1776816002150","asks":[["76365","0.15332469","2"],["76374.9","0.03274252","2"],["76378.8","0.17279906","2"]],"bids":[]}
{"instId":"BTC-USDT","action":"update","ts":"1776816002160","asks":[],"bids":[["76308.2","0","0"],["76181.6","0.00073364","2"]]}
{"instId":"BTC-USDT","action":"update","ts":"1776816002170","asks":[["76359.5","0.34005173","12"],["76364.9","0.00011892","2"]],"bids":[]}
{"instId":"BTC-USDT","action":"update","ts":"1776816002190","asks":[["76374.8","0.21223725","3"]],"bids":[["76328.8","0.21095284","3"]]}
{"instId":"BTC-USDT","action":"update","ts":"1776816002200","asks":[["76359.5","0.33996007","12"],["76390.1","0.05305931","1"],["76469","0","0"]],"bids":[["76328.8","0.26182997","4"],["76318.7","0.1","1"],["76181.6","0","0"]]}
{"instId":"BTC-USDT","action":"update","ts":"1776816002230","asks":[["76374.1","0","0"],["76374.7","0.32730994","1"]],"bids":[]}
{"instId":"BTC-USDT","action":"update","ts":"1776816002240","asks":[["76390.6","1.00616208","1"]],"bids":[]}
{"instId":"BTC-USDT","action":"update","ts":"1776816002310","asks":[],"bids":[["76348.2","0.00002471","2"],["76338.1","0.00001316","1"],["76182.2","0","0"]]}
{"instId":"BTC-USDT","action":"update","ts":"1776816002330","asks":[["76359.5","0.36438007","13"]],"bids":[["76359.4","0.21102938","12"]]}
{"instId":"BTC-USDT","action":"update","ts":"1776816002340","asks":[],"bids":[["76356.6","0.16636472","2"],["76356.4","0","0"],["76182.2","0.00875","1"]]}
{"instId":"BTC-USDT","action":"update","ts":"1776816002370","asks":[["76388.3","0.01603581","1"],["76468.9","0","0"]],"bids":[]}
{"instId":"BTC-USDT","action":"update","ts":"1776816002380","asks":[["76364.9","0.00001316","1"]],"bids":[]}
{"instId":"BTC-USDT","action":"update","ts":"1776816002400","asks":[["76359.5","0.36435388","13"]],"bids":[]}
{"instId":"BTC-USDT","action":"update","ts":"1776816002410","asks":[["76364.9","0.14528879","2"],["76373.5","0.3273188","1"],["76374.7","0","0"],["76390.1","0","0"],["76416","0","0"],["76468.9","0.00002508","2"],["76469","0.00002028","2"]],"bids":[["76359.4","0.14852938","11"],["76355.2","0","0"],["76354.7","0","0"],["76344.6","0","0"],["76343.9","0","0"],["76342.8","0","0"],["76340.8","0.33404134","3"],["76340.6","0","0"],["76340.5","0","0"],["76181.6","0.00073364","2"],["76180.1","0.00013128","1"],["76180","0.0000812","1"],["76179.9","0.47151308","1"],["76179.3","0.00040006","1"],["76178.9","0.0008637","1"],["76177.9","0.00004571","1"]]}
{"instId":"BTC-USDT","action":"update","ts":"1776816002420","asks":[["76356.7","0.28581799","4"],["76357.4","0.097456","1"],["76361.9","0.0471715","1"],["76365.1","0","0"],["76367.7","0.00654569","1"],["76369.4","0.29875397","2"],["76372.8","0.4111071","2"],["76373.5","0","0"],["76374.1","0.00654648","1"],["76374.8","0.26529656","4"],["76374.9","0.16324252","3"],["76376.7","0","0"],["76408.3","0.01004866","1"],["76416.9","0","0"],["76468.8","0","0"],["76468.9","0","0"],["76469","0","0"]],"bids":[["76359.4","0","0"],["76357.3","0","0"],["76356.6","0","0"],["76356.4","0.0471715","1"],["76355.3","0","0"],["76355.1","0.0957604","4"],["76347.3","0","0"],["76346.4","0.00654569","1"],["76345.6","0.09501901","1"],["76345.4","0","0"],["76343.2","0","0"],["76342.4","0","0"],["76340.9","0.11694199","2"],["76340.8","0.00672254","2"],["76340.7","0","0"],["76339.4","0.00654643","1"],["76339.3","0.11877279","2"],["76337.2","0.32732173","1"],["76336.5","0.00003695","1"],["76335.3","0","0"],["76334","1.00576942","1"],["76333.8","0.06550532","1"],["76332.2","0.47163315","3"],["76330.7","0","0"],["76330.5","0","0"],["76325.6","0.12375331","1"],["76308.9","0","0"],["76303.6","0.14527563","1"],["76253.6","0.08378297","1"],["76200","1.01912539","52"],["76177.8","0.00105547","4"],["76175.4","0.00003868","3"],["76175.1","0.47151308","1"],["76175","0.00029601","2"],["76173.7","0.00070045","3"]]}
{"instId":"BTC-USDT","action":"update","ts":"1776816002430","asks":[["76355.2","0.91415146","16"],["76355.6","0.23259053","2"],["76355.7","0.06068714","2"],["76356.5","0.00634125","2"],["76356.6","0.2516836","2"],["76356.7","0.18836199","3"],["76357.4","0","0"],["76358.2","0.0471715","1"],["76358.4","0.47151308","1"],["76359.5","0.10328929","6"],["76359.6","0","0"],["76361.8","0.01408069","1"],["76361.9","0","0"],["76364.8","0.12375947","1"],["76364.9","0.00001316","1"],["76367.7","0.33387396","2"],["76369.3","0.12106905","1"],["76369.4","0.17769095","1"],["76369.5","0","0"],["76372.8","0.08378297","1"],["76374.1","0","0"],["76374.3","0.01047472","4"],["76374.8","0","0"],["76376.7","0.00654684","1"],["76388.3","0","0"],["76389.8","0","0"],["76402.3","0","0"],["76407.5","0.18783","1"],["76468.6","0","0"],["76468.7","0","0"]],"bids":[["76356.4","0","0"],["76355.6","0","0"],["76355.1","0.1389604","5"],["76353.2","0.04718183","2"],["76347.3","0.00654596","1"],["76346.4","0","0"],["76345.6","0.04976707","1"],["76340.9","0.01614584","1"],["76340","0.00654652","1"],["76339.4","0","0"],["76337.2","0.47151308","1"],["76337.1","0.000015","1"],["76335.5","0.01134516","1"],["76334.1","0.43478299","2"],["76330.6","0.0000168","1"],["76328.8","0","0"],["76323","0","0"],["76309.1","0.12106984","1"],["76309","0.0032519","1"],["76304.5","0.121083","2"],["76303.6","0","0"],["76176.3","0.1305","1"],["76173.6","0.00002308","1"]]}
{"instId":"BTC-USDT","action":"update","ts":"1776816002440","asks":[["76355.2","0.89515744","17"],["76355.5","0.0471715","1"],["76355.6","0.10502644","1"],["76355.7","0","0"],["76356.5","0","0"],["76356.6","0.26511467","2"],["76356.7","0.07073642","2"],["76358.2","0","0"],["76361.8","0.03514201","2"],["76364.7","0.00654585","1"],["76367.6","0.3273566","2"],["76367.7","0","0"],["76370.5","0.26529656","4"],["76372.4","0.00654679","1"],["76374.1","0.12645072","1"],["76376.7","0","0"],["76376.9","0.1183794","1"],["76402","0","0"],["76405.3","0.0013088","1"],["76407.7","0.00130876","1"],["76414.5","0","0"],["76417.1","0","0"]],"bids":[["76355.1","0.14781871","7"],["76353.2","0.00001033","1"],["76350.7","0.02619","1"],["76350.3","0","0"],["76350","0.0471715","1"],["76347.3","0","0"],["76345.2","0.00261856","1"],["76344.6","0.00654583","1"],["76341.4","0.11839256","2"],["76340","0","0"],["76339.4","0.03637221","1"],["76337","0.00001155","1"],["76336.1","0.00654679","1"],["76335","0","0"],["76334.2","0.3273416","1"],["76334.1","0.10745499","1"],["76325.5","0.03236557","1"],["76324.9","0.00523746","1"],["76324.5","0.21095284","3"],["76310.4","0","0"],["76302.1","0.01007589","1"],["76175.4","0","0"],["76175.1","0","0"],["76175","0","0"],["76173.7","0","0"],["76173.6","0","0"]]}
{"instId":"BTC-USDT","action":"update","ts":"1776816002450","asks":[["76364.6","0.00654578","1"],["76364.7","0","0"],["76365","0.21919701","1"],["76367.6","0.000015","1"],["76369.2","0.32734525","1"],["76369.3","0","0"],["76370.4","0.00654687","1"],["76372.4","0","0"],["76406.8","0.12914116","1"],["76468.5","0","0"]],"bids":[["76355.1","0.17610504","7"],["76351","0.05496103","2"],["76344.6","0","0"],["76344.5","0.00001035","1"],["76342.8","0.00654578","1"],["76337.3","0.32734525","1"],["76336.1","0","0"],["76334.3","0.00654683","1"],["76334.2","0","0"],["76309.4","0.13184246","2"]]}
{"instId":"BTC-USDT","action":"update","ts":"1776816002460","asks":[["76355.6","0","0"],["76364.5","0.00654578","1"],["76364.6","0","0"],["76365","0.1410878","1"],["76369.1","0.32734081","1"],["76369.2","0","0"],["76369.3","0.00654678","1"],["76370.4","0","0"],["76373.5","0.1183794","1"],["76376.9","0","0"],["76468.5","0.00038944","1"]],"bids":[["76355.1","0.14630504","6"],["76345.6","0.01354838","1"],["76342.9","0.00654578","1"],["76342.8","0","0"],["76341.5","1.00576942","1"],["76339.3","0.00040006","1"],["76337.3","0","0"],["76334.3","0","0"],["76334.2","0.33388759","2"],["76300.4","0.12106984","1"],["76200","0.01335597","51"],["76188.7","0.0104986","8"],["76176.3","0","0"]]}
{"instId":"BTC-USDT","action":"update","ts":"1776816002470","asks":[["76364.4","0.00654581","1"],["76364.5","0","0"],["76369","0.31960705","1"],["76369.1","0","0"],["76369.3","0.32734234","1"],["76369.4","0","0"],["76370.4","0.00654681","1"],["76373.1","0.08005","1"],["76468.5","0","0"]],"bids":[["76355.1","0.14628594","6"],["76343","0.00654581","1"],["76342.9","0","0"],["76341.6","0.34347337","1"],["76339.4","0","0"],["76337.3","0.32734234","1"],["76335.6","0.00654681","1"],["76334.2","0","0"],["76318.7","0","0"],["76188.7","0.00047516","7"]]}
{"instId":"BTC-USDT","action":"update","ts":"1776816002480","asks":[["76356.7","0.00000001","1"],["76361.7","0.00654583","1"],["76364.4","0","0"],["76368.9","0.32734234","1"],["76369.3","0","0"],["76401.8","0.12962402","2"],["76429.9","0.00093682","1"],["76432.7","0.00002072","1"],["76432.8","0.00002941","1"],["76435.6","0","0"],["76468.4","0","0"]],"bids":[["76355.1","0.17608594","7"],["76343","0","0"],["76341.7","0.00656752","3"],["76338.4","0.01134474","1"],["76337.4","0.24386523","1"],["76337.3","0","0"],["76335.6","0","0"],["76335.5","0","0"],["76334.2","0.33388931","2"],["76329.7","0.01532975","1"],["76309.1","0","0"],["76309","0","0"],["76306.6","0","0"],["76306.5","1.00941417","2"],["76303.3","0.086119","2"],["76175.4","0.00003868","3"],["76175.1","0.47151308","1"],["76175","0.00029601","2"]]}
{"instId":"BTC-USDT","action":"update","ts":"1776816002490","asks":[["76356.6","0.01474107","1"],["76356.7","0","0"],["76361.7","0.00654622","1"],["76369","0.22189583","1"],["76370.4","0.12743037","2"],["76374.1","0","0"],["76428.6","0.00093682","1"],["76429.9","0","0"],["76431.6","0.00002072","1"],["76432.7","0","0"],["76468.4","0.00002034","1"],["76468.5","0.00038944","1"]],"bids":[["76341.7","0.00656793","3"],["76337.4","0.14081279","1"],["76336","0.00351887","3"],["76306.5","1.00616208","1"],["76304.4","0.00325219","1"],["76303.3","0.08378297","1"],["76300.4","0.12340588","2"],["76294.5","0","0"],["76223.1","0.00001501","1"],["76176.3","0.1305","1"],["76175","0","0"]]}
{"instId":"BTC-USDT","action":"update","ts":"1776816002500","asks":[["76358.3","0.17201351","1"],["76360.8","0","0"],["76361.7","0","0"],["76364.7","0.00654614","1"],["76383.5","0.11847545","1"],["76468.5","0","0"]],"bids":[["76336","0.00012006","2"],["76329.8","0.15613506","1"],["76324.5","0.26182997","4"],["76316.3","0.06647683","1"],["76302.2","0.00233607","1"],["76300.4","0.12106984","1"],["76176.3","0","0"],["76175.4","0","0"],["76175.1","0","0"]]}
{"instId":"BTC-USDT","action":"update","ts":"1776816002510","asks":[["76361.7","0.00654614","1"],["76364.7","0","0"],["76368.8","0.3558847","2"],["76369","0","0"],["76468.5","0.00038944","1"]],"bids":[["76353.4","0.00007158","1"],["76350.7","0","0"],["76325.5","0.10794733","2"],["76316.3","0","0"],["76315.8","0.1","1"],["76281","0.00001316","1"],["76276.4","0.0006541","3"]]}
{"instId":"BTC-USDT","action":"update","ts":"1776816002520","asks":[["76361.7","0","0"],["76363.3","0.00003694","1"],["76364.6","0.00654616","1"],["76368.1","0.00001086","1"],["76378.6","0","0"],["76379.9","0.00001085","1"],["76384.1","0","0"],["76468.5","0","0"]],"bids":[["76337.5","0.1183794","1"],["76289.5","0.47151308","1"],["76285","0.00013109","1"],["76177.9","0","0"],["76177.8","0","0"]]}
{"instId":"BTC-USDT","action":"update","ts":"1776816002530","asks":[["76366.6","0.00001033","1"],["76368.7","0.32734545","1"],["76368.9","0","0"],["76369.6","0.00001154","1"],["76372.8","0.08381991","2"],["76384.4","0.00001455","1"],["76419.4","0.00003969","1"],["76422.3","0","0"],["76468.2","0","0"],["76468.3","0","0"],["76468.4","0","0"]],"bids":[["76337.3","0.32734545","1"],["76334.2","0.00654681","1"],["76296.7","0","0"],["76293.3","0.00323311","1"],["76250.1","0.22987557","1"],["76179.3","0","0"],["76178.9","0","0"]]}
{"instId":"BTC-USDT","action":"update","ts":"1776816002540","asks":[["76368.8","0.25817646","2"]],"bids":[["76350.7","0.02619","1"],["76337.4","0.22052277","2"],["76179.9","0","0"]]}
{"instId":"BTC-USDT","action":"update","ts":"1776816002550","asks":[["76374.9","0.13051316","2"]],"bids":[["76337.5","0","0"],["76316.8","0","0"],["76315.8","0","0"],["76308.7","0.00131046","1"],["76179.9","0.47151308","1"],["76179.3","0.00040006","1"]]}
{"instId":"BTC-USDT","action":"update","ts":"1776816002580","asks":[],"bids":[["76314.4","0.1","1"],["76179.3","0","0"]]}
{"instId":"BTC-USDT","action":"update","ts":"1776816002590","asks":[["76355.2","0.96034744","18"],["76359.5","0.04426929","5"],["76381.7","0.10810444","3"]],"bids":[["76337.1","0.01569446","2"]]}
{"instId":"BTC-USDT","action":"update","ts":"1776816002600","asks":[["76356.9","0.00012564","1"],["76468","0","0"]],"bids":[["76355.1","0.14628594","6"]]}
{"instId":"BTC-USDT","action":"update","ts":"1776816002610","asks":[["76384.1","0.00006723","1"],["76467.9","0","0"]],"bids":[["76350.7","0","0"],["76321.2","0.00003273","3"],["76315.6","0.00001155","1"],["76310","0.00001155","1"],["76304.4","0.00326374","2"],["76298.8","0.26395969","2"],["76293.2","0.03499155","2"],["76179.9","0","0"]]}
{"instId":"BTC-USDT","action":"update","ts":"1776816002620","asks":[["76368.7","0","0"],["76370.3","0.32734384","1"],["76370.4","0.12088356","1"],["76370.9","0.00654687","1"],["76467.8","0","0"]],"bids":[["76337.5","0.44274399","2"],["76337.3","0","0"],["76337.1","0.000015","1"],["76336.1","0.00654687","1"],["76334.2","0","0"],["76321.2","0.00009507","6"],["76317.4","0.55533299","3"],["76313.6","0.00003694","1"],["76309.8","0.00003694","1"],["76308","0.00001456","1"],["76306","0.00003694","1"],["76303.5","0.47766122","4"],["76302.1","0.01011283","2"],["76298.3","0.00003695","1"],["76294.5","0.00003695","1"],["76290.7","0.00003695","1"],["76286.9","0.00003695","1"],["76183.4","0","0"],["76183.3","0","0"],["76183","0","0"],["76182.7","0","0"],["76182.2","0","0"],["76181.6","0","0"],["76180.1","0","0"],["76180","0","0"]]}
{"instId":"BTC-USDT","action":"update","ts":"1776816002630","asks":[],"bids":[["76337.6","0.27492611","1"],["76337.4","0","0"]]}
{"instId":"BTC-USDT","action":"update","ts":"1776816002640","asks":[["76364.6","0.12471889","2"],["76406.8","0","0"],["76467.8","0.47151308","1"]],"bids":[["76334.9","0.00769477","1"],["76183.7","0","0"]]}
{"instId":"BTC-USDT","action":"update","ts":"1776816002650","asks":[["76361.8","0.06968898","1"]],"bids":[["76334.9","0","0"],["76322.8","0","0"],["76319.4","0.00002864","1"],["76318.2","0.05528073","1"]]}
{"instId":"BTC-USDT","action":"update","ts":"1776816002660","asks":[],"bids":[["76319.4","0","0"],["76183.7","0.00001319","1"]]}
{"instId":"BTC-USDT","action":"update","ts":"1776816002670","asks":[["76370.2","0.0065469","1"],["76370.5","0.21223725","3"],["76370.9","0","0"]],"bids":[["76355.1","0.17608594","7"],["76336.1","0","0"],["76334.2","0.0065469","1"]]}
{"instId":"BTC-USDT","action":"update","ts":"1776816002680","asks":[["76368.3","0.03273142","1"],["76370.2","0","0"],["76370.9","0.00654683","1"],["76467.8","0","0"]],"bids":[["76336.1","0.00654683","1"],["76334.2","0","0"]]}
{"instId":"BTC-USDT","action":"update","ts":"1776816002690","asks":[["76370.9","0","0"],["76372.4","0.00654687","1"],["76385.8","0.05305931","1"],["76467.3","0","0"]],"bids":[]}
{"instId":"BTC-USDT","action":"update","ts":"1776816002700","asks":[["76355.2","0.96029506","17"]],"bids":[["76355.1","0.14628594","6"],["76188.1","0.00652277","1"]]}
{"instId":"BTC-USDT","action":"update","ts":"1776816002710","asks":[["76355.2","0.9601641","17"],["76402.1","0","0"],["76406.8","0.11402118","1"]],"bids":[["76355.1","0.17608594","7"]]}
{"instId":"BTC-USDT","action":"update","ts":"1776816002720","asks":[["76359.5","0.04380244","4"],["76401.8","0.09573804","2"]],"bids":[["76355.1","0.30365003","8"],["76316.9","0.00004629","1"],["76313.1","1.00620837","2"],["76309.3","0.00004629","1"],["76305.5","0.00004629","1"],["76301.7","0.00004629","1"],["76297.8","0.00005945","2"],["76294","0.00004629","1"],["76290.2","0.00005664","2"],["76286.4","0.0000463","1"],["76282.6","0.0000463","1"],["76185.3","0","0"],["76184.8","0","0"],["76184.2","0","0"],["76184.1","0","0"],["76184","0","0"],["76183.9","0","0"],["76183.7","0","0"]]}
{"instId":"BTC-USDT","action":"update","ts":"1776816002730","asks":[["76355.2","0.84284233","17"],["76412.3","0.10887477","1"],["76467.2","0","0"]],"bids":[["76339.7","0.1305","1"],["76318.2","0","0"]]}
{"instId":"BTC-USDT","action":"update","ts":"1776816002750","asks":[["76355.2","0.84144233","16"]],"bids":[]}
{"instId":"BTC-USDT","action":"update","ts":"1776816002770","asks":[],"bids":[["76318.5","0.00002864","1"],["76186","0","0"]]}
{"instId":"BTC-USDT","action":"update","ts":"1776816002790","asks":[],"bids":[["76347.2","0","0"],["76340.4","0.00305","1"]]}
{"instId":"BTC-USDT","action":"update","ts":"1776816002800","asks":[],"bids":[["76352.8","0.0471715","1"],["76350","0","0"]]}
{"instId":"BTC-USDT","action":"update","ts":"1776816002810","asks":[],"bids":[["76351","0.03880541","1"]]}
{"instId":"BTC-USDT","action":"update","ts":"1776816002830","asks":[],"bids":[["76350.7","0.02619","1"],["76344.9","0.00305","1"],["76340.4","0","0"],["76186.4","0","0"]]}
{"instId":"BTC-USDT","action":"update","ts":"1776816002840","asks":[],"bids":[["76352.9","0.05996909","1"],["76351","0","0"]]}
{"instId":"BTC-USDT","action":"update","ts":"1776816002880","asks":[["76370.5","0.15917794","2"]],"bids":[]}
{"instId":"BTC-USDT","action":"update","ts":"1776816002900","asks":[["76370.9","0.00654664","1"],["76372.4","0","0"],["76385.8","0.10611862","2"]],"bids":[["76350.7","0","0"],["76336.1","0","0"],["76334.2","0.00654664","1"],["76187.8","0.00303","1"]]}
{"instId":"BTC-USDT","action":"update","ts":"1776816002920","asks":[["76385.8","0.05305931","1"]],"bids":[]}
{"instId":"BTC-USDT","action":"update","ts":"1776816002930","asks":[["76370.5","0.21223725","3"],["76385.8","0","0"],["76467.2","0.00011781","1"]],"bids":[]}
{"instId":"BTC-USDT","action":"update","ts":"1776816002950","asks":[["76370.5","0.26529656","4"]],"bids":[]}
{"instId":"BTC-USDT","action":"update","ts":"1776816002970","asks":[["76355.2","0.83871824","16"]],"bids":[]}
{"instId":"BTC-USDT","action":"update","ts":"1776816002980","asks":[["76370.5","0.21223725","3"],["76370.9","0","0"],["76372.4","0.0065465","1"]],"bids":[["76336.1","0.0065465","1"],["76334.2","0","0"]]}
{"instId":"BTC-USDT","action":"update","ts":"1776816002990","asks":[["76385.8","0.05305931","1"],["76467.2","0","0"]],"bids":[["76308.2","0.01938907","1"],["76217.5","0.01466368","1"],["76187.5","0","0"],["76187","0","0"]]}
{"instId":"BTC-USDT","action":"update","ts":"1776816003000","asks":[["76355.2","0.83822713","16"],["76385.8","0","0"],["76467.2","0.00011781","1"]],"bids":[]}
{"instId":"BTC-USDT","action":"update","ts":"1776816003010","asks":[["76355.2","0.83778187","16"]],"bids":[["76355.1","0.34387647","9"],["76350.7","0.02619","1"],["76187.7","0","0"]]}
{"instId":"BTC-USDT","action":"update","ts":"1776816003020","asks":[["76381.7","0.09211416","2"],["76385.8","0.05305931","1"],["76467.2","0","0"]],"bids":[["76336.3","0.01571556","1"],["76187.8","0","0"]]}
{"instId":"BTC-USDT","action":"update","ts":"1776816003030","asks":[["76418.7","0.00003968","1"],["76419.4","0","0"]],"bids":[["76293.3","0","0"],["76292.8","0.00323327","1"]]}
{"instId":"BTC-USDT","action":"update","ts":"1776816003050","asks":[["76355.2","0.73952187","15"],["76359.5","0.00780244","3"],["76370.5","0.15917794","2"]],"bids":[["76355.1","0.34677663","11"]]}
{"instId":"BTC-USDT","action":"update","ts":"1776816003060","asks":[["76364.6","0.11817273","1"],["76367.7","0.00654623","1"],["76370.3","0","0"],["76372.7","0.32732103","1"],["76385.8","0.10611862","2"],["76467.1","0","0"]],"bids":[["76355.1","0.34939512","12"],["76345.9","0.00654623","1"],["76341.7","0.00002171","2"],["76339.8","0.32732103","1"],["76337.5","0.11540015","1"],["76188.1","0","0"],["76187.9","0","0"]]}
{"instId":"BTC-USDT","action":"update","ts":"1776816003070","asks":[["76358.3","0","0"],["76364.9","0.00655933","2"],["76367.7","0","0"],["76467.1","0.00181702","1"],["76467.2","0.00011781","1"]],"bids":[["76345.9","0","0"],["76345.3","0.00654617","1"],["76338.4","0","0"],["76337.6","0.18190496","1"],["76188.1","0.00652277","1"]]}
{"instId":"BTC-USDT","action":"update","ts":"1776816003080","asks":[],"bids":[["76341.5","1.0171137","2"]]}
{"instId":"BTC-USDT","action":"update","ts":"1776816003090","asks":[["76355.2","0.55945233","12"],["76358.4","0","0"],["76364.7","0.47151308","1"],["76364.9","0.00001316","1"],["76367.7","0.00654614","1"],["76467.2","0","0"]],"bids":[["76345.9","0.00654614","1"],["76345.3","0","0"]]}
{"instId":"BTC-USDT","action":"update","ts":"1776816003100","asks":[["76355.2","0.55934363","12"],["76355.5","0","0"],["76359.9","0.0471715","1"],["76361.8","0.20406484","2"],["76372.4","0","0"],["76373.4","0.0065462","1"]],"bids":[["76337.7","0.0065462","1"],["76336.1","0","0"]]}
{"instId":"BTC-USDT","action":"update","ts":"1776816003110","asks":[["76355.2","0.48070049","11"],["76370.5","0.10611863","1"]],"bids":[["76324.5","0.15917794","2"]]}
{"instId":"BTC-USDT","action":"update","ts":"1776816003120","asks":[],"bids":[["76339.8","0.37819816","2"]]}
{"instId":"BTC-USDT","action":"update","ts":"1776816003130","asks":[["76370.5","0.15917794","2"]],"bids":[["76324.5","0.21095284","3"]]}
{"instId":"BTC-USDT","action":"update","ts":"1776816003140","asks":[["76385.8","0.05305931","1"]],"bids":[]}
{"instId":"BTC-USDT","action":"update","ts":"1776816003150","asks":[["76370.5","0.10611863","1"],["76385.8","0.10611862","2"]],"bids":[["76324.5","0.15917794","2"]]}
{"instId":"BTC-USDT","action":"update","ts":"1776816003160","asks":[["76355.2","0.47450049","10"],["76385.8","0.15917793","3"],["76386.4","0.01536863","1"],["76416.6","0.1305","1"],["76467.1","0","0"]],"bids":[["76355.1","0.35559512","13"],["76336.3","0","0"],["76324.5","0.10611863","1"],["76187.9","0.00001002","1"]]}
{"instId":"BTC-USDT","action":"update","ts":"1776816003170","asks":[["76355.2","0.37923049","9"],["76373.4","0","0"],["76374.8","0.00654619","1"]],"bids":[["76339.9","0.00666625","3"],["76337.7","0","0"],["76325.7","0.10254573","1"],["76325.5","0","0"],["76187.8","0.00303","1"]]}
{"instId":"BTC-USDT","action":"update","ts":"1776816003200","asks":[["76356.6","0","0"],["76386.4","0","0"],["76413.7","0.1","1"],["76467.1","0.00181702","1"]],"bids":[]}
{"instId":"BTC-USDT","action":"update","ts":"1776816003210","asks":[["76355.2","0.37911002","8"],["76362.1","0.01474002","1"],["76467.1","0","0"]],"bids":[["76355.1","0.37822512","14"],["76341.5","1.00576942","1"],["76339.8","0.42997306","3"]]}
{"instId":"BTC-USDT","action":"update","ts":"1776816003220","asks":[["76385.8","0.05305931","1"]],"bids":[["76355.1","0.47822512","15"],["76343.8","0.01134393","1"],["76339.8","0.37819816","2"],["76187.8","0","0"]]}
{"instId":"BTC-USDT","action":"update","ts":"1776816003230","asks":[["76368.3","0","0"],["76370.5","0.15917794","2"],["76467.1","0.00181702","1"]],"bids":[["76341.6","0.81498645","2"]]}
{"instId":"BTC-USDT","action":"update","ts":"1776816003240","asks":[],"bids":[["76341.7","0.63804218","3"],["76341.6","0.47151308","1"]]}
{"instId":"BTC-USDT","action":"update","ts":"1776816003250","asks":[["76374.8","0","0"],["76376.7","0.00654613","1"]],"bids":[["76340","0.00654613","1"],["76339.9","0.00012006","2"],["76187.9","0","0"]]}
{"instId":"BTC-USDT","action":"update","ts":"1776816003260","asks":[["76355.2","0.35508002","6"]],"bids":[]}
{"instId":"BTC-USDT","action":"update","ts":"1776816003270","asks":[["76368.8","0.29090902","3"]],"bids":[["76355.1","0.47815135","14"],["76351.3","0.00004629","1"],["76347.5","0.00004629","1"],["76343.7","0.00004629","1"],["76339.9","0.00004629","1"],["76336","0.00004629","1"],["76332.2","0.47155937","2"],["76328.4","0.00005664","2"],["76324.6","0.00005946","2"],["76320.8","0.0000463","1"]]}
{"instId":"BTC-USDT","action":"update","ts":"1776816003280","asks":[],"bids":[["76355.1","0.47814101","13"],["76349.8","0","0"],["76344.5","0","0"],["76339.2","0","0"],["76333.9","0.43937519","2"],["76328.6","0","0"],["76323.3","0","0"],["76187.9","0.00001002","1"],["76187.8","0.00303","1"],["76187.7","0.47151308","1"],["76187.5","0.00032499","3"],["76187","0.00011911","5"]]}
{"instId":"BTC-USDT","action":"update","ts":"1776816003290","asks":[],"bids":[["76324.5","0.21095284","3"]]}
{"instId":"BTC-USDT","action":"update","ts":"1776816003300","asks":[],"bids":[["76339.8","0.32732103","1"]]}
{"instId":"BTC-USDT","action":"update","ts":"1776816003310","asks":[["76355.2","0.35491632","6"],["76359.5","0.00779244","2"],["76370.5","0.21223725","3"]],"bids":[]}
{"instId":"BTC-USDT","action":"update","ts":"1776816003320","asks":[["76442.2","0.57491216","4"],["76445.5","0.00002462","2"]],"bids":[["76339.8","0.37819816","2"]]}
{"instId":"BTC-USDT","action":"update","ts":"1776816003340","asks":[["76359.9","0.06191196","2"],["76362.1","0","0"],["76467.2","0.00011781","1"]],"bids":[]}
{"instId":"BTC-USDT","action":"update","ts":"1776816003350","asks":[["76355.2","0.34857498","4"]],"bids":[]}
{"instId":"BTC-USDT","action":"update","ts":"1776816003370","asks":[],"bids":[["76355.1","0.47821478","14"],["76351.3","0.00012007","2"],["76347.5","0.00012007","2"],["76343.7","0.00012007","2"],["76339.9","0.00012007","2"],["76336","0.00012007","2"],["76332.2","0.47163315","3"],["76328.4","0.00013042","3"],["76324.6","0.00013324","3"],["76320.8","0.00012008","2"]]}
{"instId":"BTC-USDT","action":"update","ts":"1776816003380","asks":[["76388.1","0.48693352","2"]],"bids":[["76355.1","0.47822512","15"],["76349.8","0.00001034","1"],["76344.5","0.00001035","1"],["76339.8","0.39377872","3"],["76339.2","0.00001035","1"],["76333.9","0.43938554","3"],["76328.6","0.00001035","1"],["76323.3","0.00001035","1"],["76187.9","0","0"],["76187.8","0","0"],["76187.7","0","0"],["76187.5","0","0"],["76187","0","0"]]}
{"instId":"BTC-USDT","action":"update","ts":"1776816003400","asks":[["76370.5","0.05305931","1"]],"bids":[["76324.5","0.15917794","2"]]}
{"instId":"BTC-USDT","action":"update","ts":"1776816003410","asks":[["76368.8","0.22560197","3"]],"bids":[]}
{"instId":"BTC-USDT","action":"update","ts":"1776816003420","asks":[["76385.8","0.21223725","3"]],"bids":[["76339.8","0.44555362","4"]]}
{"instId":"BTC-USDT","action":"update","ts":"1776816003440","asks":[["76370.5","0","0"],["76467.3","0.00050101","1"]],"bids":[]}
{"instId":"BTC-USDT","action":"update","ts":"1776816003450","asks":[],"bids":[["76324.5","0.10611863","1"]]}
{"instId":"BTC-USDT","action":"update","ts":"1776816003460","asks":[["76385.8","0.26529656","4"]],"bids":[["76339.8","0.49861293","5"]]}
{"instId":"BTC-USDT","action":"update","ts":"1776816003470","asks":[["76355.2","0.06519","1"],["76359.9","0.01474046","1"],["76361.8","0","0"],["76364.8","0","0"],["76367.7","0","0"],["76368.7","0.00654579","1"],["76372.7","0","0"],["76372.8","0.00003694","1"],["76373.5","0","0"],["76374.9","0.00001316","1"],["76376.7","0.33385129","2"],["76376.8","0","0"],["76467.8","0.47151308","1"],["76467.9","0.00001035","1"],["76468","1.00618616","2"],["76468.2","0.00158724","2"],["76468.3","0.01147749","1"]],"bids":[["76350.7","0.1445694","2"],["76347.4","0.1305","1"],["76346.4","0.00654579","1"],["76345.9","0","0"],["76342.8","0.32730516","1"],["76341.7","0.72182515","4"],["76339.8","0.1712919","4"],["76337.7","0.08378297","1"],["76324.5","0","0"],["76300.4","0","0"],["76253.6","0","0"]]}
{"instId":"BTC-USDT","action":"update","ts":"1776816003480","asks":[["76365","0","0"],["76367.7","0.14108657","1"],["76368.6","0.00654579","1"],["76368.7","0","0"],["76372.9","0","0"],["76416","0.13721249","1"]],"bids":[["76352.9","0.08763841","2"],["76347.5","0.00666586","3"],["76346.4","0","0"],["76339.8","0.27741053","5"],["76325.7","0","0"],["76187.9","0.00001002","1"],["76187.8","0.00303","1"]]}
{"instId":"BTC-USDT","action":"update","ts":"1776816003490","asks":[["76373.5","0.16781884","1"],["76402.8","0.06397188","1"],["76468.3","0","0"]],"bids":[["76349.1","0.01614584","1"],["76347.5","0.0825679","4"],["76346.3","0","0"]]}
{"instId":"BTC-USDT","action":"update","ts":"1776816003500","asks":[["76368.6","0","0"],["76370.3","0.00654579","1"],["76401.8","0.00001316","1"],["76424.8","0.21580626","4"]],"bids":[["76349.8","0.00655613","2"],["76347.5","0.07602211","3"]]}
{"instId":"BTC-USDT","action":"update","ts":"1776816003510","asks":[["76355.2","0.08569","3"],["76364.7","0","0"],["76367.7","0.61259965","2"],["76367.8","0","0"],["76370.9","0.47151308","1"],["76371","0","0"],["76376.7","0.32730516","1"],["76377.1","0","0"],["76378","0.00654608","1"],["76383.4","1.00582606","1"],["76383.6","0","0"],["76468.3","0.01147749","1"],["76468.4","0.00002034","1"]],"bids":[["76342.8","0.33385124","2"],["76340","0","0"],["76187.7","0.47151308","1"]]}
{"instId":"BTC-USDT","action":"update","ts":"1776816003520","asks":[["76355.2","0.09619","3"],["76364.5","0.03527456","1"],["76367.7","0.47151308","1"],["76369.6","0.10871787","2"],["76377","0","0"],["76383.3","0.12376028","1"],["76387.8","0","0"]],"bids":[["76345.6","0.11381351","2"]]}
{"instId":"BTC-USDT","action":"update","ts":"1776816003530","asks":[["76355.2","0.11549","4"],["76367.6","0.14110157","2"],["76388.1","0.47151308","1"]],"bids":[["76341.6","0","0"],["76187.5","0.00032499","3"]]}
{"instId":"BTC-USDT","action":"update","ts":"1776816003540","asks":[["76376.6","0.30303978","1"],["76468.4","0","0"]],"bids":[["76341.7","0.54903935","4"],["76339.8","0.26182997","4"]]}
{"instId":"BTC-USDT","action":"update","ts":"1776816003550","asks":[["76368.7","0.00654597","1"],["76370.3","0","0"],["76376.5","0.00654604","1"],["76378","0","0"]],"bids":[["76349.8","0.00001034","1"],["76347.6","0.00655683","2"],["76343.8","0","0"],["76342.8","0.32730516","1"],["76341.6","0.47151308","1"],["76341.5","1.02365974","3"]]}
{"instId":"BTC-USDT","action":"update","ts":"1776816003560","asks":[["76377.2","1.00582606","1"],["76416","0","0"]],"bids":[]}
{"instId":"BTC-USDT","action":"update","ts":"1776816003580","asks":[["76368.7","0","0"],["76370.3","0.00654586","1"]],"bids":[["76349.8","0.0065562","2"],["76347.6","0.00001086","1"]]}
{"instId":"BTC-USDT","action":"update","ts":"1776816003590","asks":[["76376.5","0","0"],["76378","0.00654611","1"],["76416","0.11447725","1"],["76468.3","0","0"]],"bids":[["76342.9","0.00654611","1"],["76341.5","1.0171137","2"],["76187.5","0","0"]]}
{"instId":"BTC-USDT","action":"update","ts":"1776816003620","asks":[["76360.8","0.0471715","1"],["76468.2","0","0"]],"bids":[]}
{"instId":"BTC-USDT","action":"update","ts":"1776816003650","asks":[["76368.8","0.19286941","2"]],"bids":[]}
{"instId":"BTC-USDT","action":"update","ts":"1776816003670","asks":[["76355.2","0.06639","2"],["76359.9","0","0"],["76387.8","0.01579405","1"],["76447.5","0.12002945","2"]],"bids":[["76341.5","1.00576942","1"]]}
{"instId":"BTC-USDT","action":"update","ts":"1776816003680","asks":[["76357.5","0.01474091","1"],["76468","0","0"]],"bids":[["76344.4","0.01134384","1"],["76336.4","0.01551306","1"],["76187.8","0","0"],["76187.7","0","0"]]}
{"instId":"BTC-USDT","action":"update","ts":"1776816003700","asks":[["76355.2","0.06632583","2"],["76386.9","0.20834731","1"],["76467.9","0","0"]],"bids":[["76355.1","0.63822512","16"]]}
{"instId":"BTC-USDT","action":"update","ts":"1776816003730","asks":[["76360.8","0","0"],["76364.7","0.0471715","1"]],"bids":[]}
{"instId":"BTC-USDT","action":"update","ts":"1776816003740","asks":[],"bids":[["76355.1","0.47822512","15"]]}
{"instId":"BTC-USDT","action":"update","ts":"1776816003770","asks":[["76355.2","0.06624726","2"]],"bids":[["76355.1","0.63822512","16"]]}
{"instId":"BTC-USDT","action":"update","ts":"1776816003780","asks":[["76364.4","0.0000175","1"],["76467.8","0","0"]],"bids":[["76350.8","0.16","1"],["76187.9","0","0"]]}
{"instId":"BTC-USDT","action":"update","ts":"1776816003790","asks":[["76376.5","0.12106984","1"],["76376.6","0.56453583","2"],["76467.3","0","0"]],"bids":[["76352.9","0.13381488","1"]]}
{"instId":"BTC-USDT","action":"update","ts":"1776816003800","asks":[["76355.2","0.06612285","2"]],"bids":[["76345.7","0.47151308","1"],["76310.1","0.01155062","1"],["76302.1","0.00003694","1"],["76188.3","0","0"],["76188.1","0","0"]]}
{"instId":"BTC-USDT","action":"update","ts":"1776816003810","asks":[["76355.2","0.06609666","2"]],"bids":[["76345.8","0.3800456","2"],["76345.6","0","0"],["76188.3","0.00001061","1"]]}
{"instId":"BTC-USDT","action":"update","ts":"1776816003840","asks":[["76355.2","0","0"],["76356.9","0","0"],["76364.5","0","0"],["76364.6","0","0"],["76364.7","0","0"],["76367.6","0.000015","1"],["76367.7","0","0"],["76368.8","0.00019344","1"],["76370.4","0","0"],["76370.9","0","0"],["76374.2","0","0"],["76375.6","0.47151308","1"],["76377.2","0","0"],["76377.3","0","0"],["76380.4","0","0"],["76380.8","0","0"],["76383.2","1.47733914","2"],["76383.4","0","0"],["76383.5","0","0"],["76383.9","0.21162459","1"],["76384","0","0"],["76385.8","0","0"],["76387.9","0","0"],["76390.4","1.00584106","2"],["76390.5","0","0"],["76390.6","0","0"],["76408.3","0","0"],["76416.8","0.01160254","1"],["76422.3","0.10890011","1"],["76467.3","0.00050101","1"],["76467.8","0.47151308","1"],["76467.9","0.00001035","1"],["76468","1.00618616","2"],["76468.2","0.00158724","2"],["76468.3","0.01147749","1"],["76468.4","0.00002034","1"],["76468.5","0.00038944","1"],["76468.6","0.00001531","1"],["76468.7","0.00109488","1"],["76468.8","0.01162259","2"],["76468.9","0.00002508","2"],["76469","0.00002028","2"],["76469.2","0.08378297","1"],["76469.4","0.00265436","2"],["76469.6","0.00441584","1"],["76469.7","0.00021564","6"]],"bids":[["76357.4","0.46948057","6"],["76356.8","1.13414467","15"],["76355.2","0.63271657","5"],["76355.1","0.24170443","8"],["76355","0.01048255","4"],["76354.2","0.01614584","1"],["76352.9","0.23381488","2"],["76351.8","0.13455749","2"],["76350.7","0.1183794","1"],["76350.5","0","0"],["76339.8","0","0"],["76317.3","0","0"],["76317.2","0","0"],["76310.1","0.13530952","2"],["76309.4","0.00001086","1"],["76304.5","0.00001316","1"],["76259.1","0","0"]]}
{"instId":"BTC-USDT","action":"update","ts":"1776816003850","asks":[["76357.5","0","0"],["76362.5","0.01473994","1"],["76364.4","0","0"],["76370.3","0","0"],["76372.4","0.00654548","1"],["76376.4","0.14411856","1"],["76376.5","0","0"],["76376.6","0.16229314","1"],["76376.7","0","0"],["76378","0","0"],["76380.4","0.33385351","2"],["76383.9","0","0"],["76387.8","0","0"],["76390.1","0.26529656","4"],["76390.3","0.12375655","1"],["76391.9","0.08378297","1"],["76392.4","0","0"],["76405.3","0","0"],["76407.7","0","0"],["76413.6","0.00130866","1"],["76416.4","0.00130861","1"],["76421.3","0.11240776","1"],["76422.3","0","0"],["76448.6","0","0"],["76452.3","0.00012963","1"],["76469.2","0.21428297","2"],["76470","0.00007723","1"],["76470.2","0.05814278","2"],["76470.3","0.00003942","1"]],"bids":[["76359.4","0.73750778","12"],["76357.4","0.29305686","7"],["76356.9","0.09816034","1"],["76356.8","0.16219","3"],["76355.2","0","0"],["76355.1","0.2317413","6"],["76352.8","0","0"],["76350.9","0.00654548","1"],["76350.8","0","0"],["76350.7","0","0"],["76349.8","0.00001034","1"],["76349.2","0.01134313","1"],["76347.6","0.41110187","3"],["76345.9","0.1303004","2"],["76345.8","0.25629229","1"],["76344.4","0","0"],["76344.1","0.15571134","3"],["76342.9","0","0"],["76342.8","0","0"],["76336.4","0","0"],["76332.1","0.036","1"],["76328.8","0.10611863","1"],["76327.7","0.11837428","1"],["76322.8","0.11431178","1"],["76320.4","0","0"],["76316.8","0.00131032","1"],["76314.8","0.11837273","1"],["76314.7","0","0"],["76310.1","0.01155062","1"],["76309.4","0.10627869","2"],["76308.7","0","0"],["76302.5","0","0"],["76298.7","0","0"],["76268.4","0.31924","1"],["76249.6","0.09837","1"],["76225.4","0","0"],["76188.1","0.00652277","1"]]}
{"instId":"BTC-USDT","action":"update","ts":"1776816003860","asks":[["76376.3","0.10565792","1"],["76376.6","0","0"],["76378.8","0.04909404","1"],["76383.1","0.11837273","1"],["76470.3","0","0"]],"bids":[["76359.4","0.84160902","15"],["76357.4","0.2889554","5"],["76352.9","0.1","1"],["76347.5","0.00012007","2"],["76333.9","0.0879398","2"],["76322.8","0","0"],["76309.4","0.00001086","1"],["76303.5","0.34620333","3"],["76298.8","0.00001155","1"],["76187.9","0.00001002","1"]]}
{"instId":"BTC-USDT","action":"update","ts":"1776816003870","asks":[["76372.4","0","0"],["76374.2","0.00654505","1"],["76374.3","0.12513077","5"],["76376.3","0.06873197","1"],["76384.1","0.12100306","2"],["76388","0.59501377","3"]],"bids":[["76354.3","0.00654505","1"],["76350.9","0","0"],["76349.9","0.0026184","1"],["76345.2","0","0"],["76334.6","0.00524713","2"],["76324.9","0","0"],["76317.6","0.10978705","1"],["76308.7","0.12106302","1"],["76187.9","0","0"]]}
{"instId":"BTC-USDT","action":"update","ts":"1776816003880","asks":[["76373.4","0.00654502","1"],["76374.2","0","0"],["76376.4","0","0"],["76470.3","0.00003942","1"]],"bids":[["76354.3","0","0"],["76353","0.00654502","1"]]}
{"instId":"BTC-USDT","action":"update","ts":"1776816003890","asks":[["76373.4","0","0"],["76375.5","0.00654506","1"],["76376.3","0.02571258","1"],["76378.8","0.17015706","2"],["76380.4","0.32730804","1"],["76382.6","0.00654557","1"],["76413.7","0","0"]],"bids":[["76355.2","0.00654506","1"],["76353","0","0"],["76347.6","0.41764744","4"],["76345.9","0.12375493","1"]]}
{"instId":"BTC-USDT","action":"update","ts":"1776816003900","asks":[["76359.5","0.00537985","2"],["76376.3","0.05856259","2"],["76428.6","0","0"],["76431.6","0","0"],["76432.8","0.00096623","2"],["76470.5","0.00926628","18"],["76470.6","0.01580142","1"]],"bids":[["76328.8","0","0"],["76307.1","0.00325175","1"],["76306.6","0.00233568","1"],["76304.4","0.00001155","1"],["76302.2","0","0"]]}
{"instId":"BTC-USDT","action":"update","ts":"1776816003910","asks":[["76383.2","0.47151308","1"],["76453.6","0.00041787","5"],["76455.4","0.659237","3"],["76459","0.657668","1"],["76463.7","0.00001197","1"],["76470.5","0","0"],["76470.6","0","0"]],"bids":[["76353.4","0","0"],["76317.8","0.01168048","1"],["76310.1","0","0"],["76309.4","0.66221861","3"],["76307.1","0","0"],["76305.5","0.66054929","2"],["76291.1","0.00014424","2"],["76285","0","0"],["76282.5","0.00707068","2"],["76276.4","0.00011192","2"],["76187.9","0.00001002","1"],["76187.8","0.00303","1"],["76187.7","0.47151308","1"]]}
{"instId":"BTC-USDT","action":"update","ts":"1776816003920","asks":[["76369.6","0.00001154","1"],["76373.1","0","0"],["76373.6","0","0"],["76378.1","0.00054","1"],["76380.4","0","0"],["76380.5","0.26369418","1"],["76383","0.3272778","1"],["76384.2","0","0"],["76392.3","0.01555701","1"],["76405.9","0","0"],["76421.4","0.11301554","2"],["76425.3","0.11837273","1"],["76470.5","0.00926628","18"],["76470.6","0.01580142","1"]],"bids":[["76359.4","0.94856816","16"],["76357.4","0.3889554","6"],["76351.9","0.3272778","1"],["76347.6","0.08379383","2"],["76346","0.00654553","1"],["76344.7","0.01560341","2"],["76308.7","0","0"],["76187.7","0","0"]]}
{"instId":"BTC-USDT","action":"update","ts":"1776816003930","asks":[["76362.5","0","0"],["76366.3","0.01473921","1"],["76375.4","0.00654483","1"],["76375.5","0","0"],["76375.6","0","0"],["76377.3","0.0471715","1"],["76383","0","0"],["76383.2","0.79879158","2"],["76384.1","0.08204881","2"],["76384.7","0","0"],["76388","0.5112308","2"],["76391.9","0","0"],["76392.3","0","0"],["76397.6","0.44591845","1"],["76402.8","0","0"],["76414.6","0.1","1"],["76416.8","0","0"],["76424.6","0.01186339","3"],["76430.3","0.12217184","3"],["76470.8","0.0001444","7"],["76471.1","0.47253258","5"],["76471.2","0.00002013","1"],["76471.3","0.01047498","5"],["76471.4","0.00505207","2"]],"bids":[["76359.4","0.98318007","17"],["76356.9","0.19816034","2"],["76356.8","0.136","2"],["76355.2","0","0"],["76355.1","0.23828613","7"],["76353","0.08378297","1"],["76352.9","0","0"],["76352","0.47151308","1"],["76351.9","0.3272785","1"],["76351.2","0.06550532","1"],["76349.1","1.0219719","2"],["76344.1","0.26182997","4"],["76333.8","0","0"],["76321.8","0.07108441","3"],["76314.8","0","0"],["76312.3","0.94615","1"],["76305.3","0","0"],["76297.6","0.00001086","1"],["76283.7","0","0"],["76266","0","0"],["76211.2","0","0"],["76187.7","0.47151308","1"],["76187.5","0.00032499","3"],["76187","0.00011911","5"],["76186.4","0.00022771","1"]]}
{"instId":"BTC-USDT","action":"update","ts":"1776816003940","asks":[["76373.5","0.03937065","1"],["76375.4","0","0"],["76377.3","0","0"],["76381.4","0.0471715","1"],["76381.6","0.00654462","1"],["76382.6","0","0"],["76383.2","0.47151308","1"],["76383.8","0.15976","2"],["76387.9","0.32726276","1"],["76390.3","0.13030178","2"],["76390.4","0.000015","1"],["76409.4","0","0"],["76413.6","0","0"],["76416.4","0","0"],["76424.3","0.00130848","1"],["76425.4","1.00789094","4"],["76471.5","0.00004115","1"]],"bids":[["76359.4","1.14972469","19"],["76356.8","0.13861816","3"],["76355.2","0.33380799","2"],["76355.1","0.2317413","6"],["76351.9","0","0"],["76349.9","0","0"],["76346","0","0"],["76341.5","1.01100574","2"],["76334.6","0.00001033","1"],["76326.2","0.00785448","1"],["76316.3","0.00652851","1"],["76316.1","1.00104","1"],["76313.5","0","0"],["76310.9","0.03555264","2"],["76305.3","0.345778","1"],["76298.2","0","0"],["76295.3","0.00652089","1"],["76287","0","0"],["76282.5","0.00054217","1"],["76258.1","0","0"],["76249.1","0.00652277","1"],["76224.4","0","0"],["76188.7","0.0108121","8"],["76188.1","0","0"],["76186","0.00170529","1"],["76185.3","0.00002512","1"]]}
{"instId":"BTC-USDT","action":"update","ts":"1776816003950","asks":[["76388","0.15907734","1"],["76394.4","0.06550532","1"],["76418.7","0","0"],["76422.4","0.64195524","3"]],"bids":[["76359.4","5.73972469","20"],["76357.8","0.02619","1"],["76357.5","0.11610319","1"],["76294.6","0.00323291","1"],["76292.8","0","0"],["76287.1","0","0"],["76258.2","0","0"]]}
{"instId":"BTC-USDT","action":"update","ts":"1776816003960","asks":[["76359.5","0","0"],["76360","0","0"],["76360.3","0","0"],["76360.5","0","0"],["76363.3","0","0"],["76364.9","0","0"],["76368.2","0","0"],["76374.3","0.01047472","4"],["76381.4","0","0"],["76381.6","0","0"],["76385.3","0.00654454","1"],["76387.9","0","0"],["76390","0.32726378","1"],["76390.1","0","0"],["76390.3","0.12375655","1"],["76391.9","0.00654526","1"],["76462.4","0","0"],["76471.7","0.00029028","5"],["76471.8","0.00007776","1"],["76471.9","0.0003932","1"],["76472","0.000059","1"],["76472.4","0.00002715","1"],["76472.5","0.00008103","2"],["76472.6","0.00002975","1"],["76473","0.0001084","1"],["76473.2","0.00001599","1"]],"bids":[["76366.2","1.2650235","19"],["76364.8","0.0041007","2"],["76359.5","0.27241221","2"],["76359.4","4.88652294","9"],["76358.5","0.1305","1"],["76357.8","0.1","1"],["76357.6","0.32726378","1"],["76357.4","0.1591834","3"],["76357","0.00654526","1"],["76356.9","0.26422212","3"],["76355.2","0","0"],["76355.1","0.1317413","5"],["76351.8","0.00003694","1"],["76349.2","0","0"],["76345.7","0.56360608","2"],["76344.1","0","0"],["76340","0.0000812","1"],["76325","0","0"],["76317.6","0","0"],["76309.9","0.345778","1"],["76296.7","0.00323289","1"],["76294.6","0","0"],["76260.9","0","0"],["76256.6","0","0"],["76185.3","0","0"]]}
{"instId":"BTC-USDT","action":"update","ts":"1776816003970","asks":[["76366.3","0","0"],["76373.5","0","0"],["76385.3","0","0"],["76386.8","0.00654462","1"],["76388","0.2550469","2"],["76392.9","0.08378297","1"],["76394.3","0.01572498","1"],["76396.9","0.15917793","3"],["76397.5","0.08378297","1"],["76414.6","0","0"],["76415.4","0","0"],["76419.2","0","0"],["76427.7","0.00003295","1"],["76473.3","0.00564466","1"]],"bids":[["76366.5","0.10714","1"],["76366.2","1.32796496","24"],["76364.8","0","0"],["76359.5","0.75938866","3"],["76359.4","0.26624191","4"],["76358.5","0.2305","2"],["76357.5","0","0"],["76357.4","0.1","1"],["76356.9","0.1","1"],["76356.8","0.03861816","2"],["76351.5","0.01134279","1"],["76350.9","0.26182997","4"],["76345.8","0","0"],["76344.7","0.000015","1"]]}
{"instId":"BTC-USDT","action":"update","ts":"1776816003980","asks":[["76366.6","0","0"],["76367.6","0","0"],["76367.9","0","0"],["76368","0","0"],["76368.1","0","0"],["76368.8","0","0"],["76369.6","0","0"],["76371.6","0","0"],["76372.5","0.10659","4"],["76390","0","0"],["76391.9","0","0"],["76392.8","0.32726458","1"],["76393.9","0.00654523","1"],["76396.9","0","0"],["76401.8","0.13182508","2"],["76425.6","0.48975453","4"],["76429.7","0.10913496","2"],["76430.3","0.04238106","3"],["76434.3","0.0655348","1"],["76436.6","0.13279686","2"],["76449.9","0.61540392","2"],["76473.5","0.08378297","1"],["76473.6","0.0007428","8"],["76473.7","0.00015227","1"],["76474","0.00001017","1"],["76474.2","0.00031344","3"],["76474.6","0.00039634","2"],["76474.8","0.00014553","1"],["76475","0.01748409","6"]],"bids":[["76372.4","0.53394938","10"],["76371.5","0.00410078","2"],["76366.6","0.15757596","1"],["76366.5","0.49779237","6"],["76366.2","0.20597178","5"],["76359.6","0.33380839","2"],["76359.5","0.3056657","1"],["76359.4","0.136","2"],["76358.6","1.48388437","3"],["76357.6","0","0"],["76357","0","0"],["76356.9","0","0"],["76355.2","0.11835258","1"],["76355.1","0.0361304","4"],["76353","0","0"],["76352.3","0.000015","1"],["76350.9","0","0"],["76349.8","0.14258242","2"],["76325.6","0","0"],["76322.8","0.13180174","1"],["76321.7","0.000015","1"],["76285.9","0.01394","1"],["76264.2","0","0"],["76242.5","1.623209","1"],["76219.7","0","0"],["76193.4","0.00002624","1"],["76187","0","0"],["76186.4","0","0"],["76186","0","0"]]}
{"instId":"BTC-USDT","action":"update","ts":"1776816003990","asks":[["76372.5","0.2223676","6"],["76386.8","0.00654398","1"],["76388","0.15907734","1"],["76392","0.38416417","1"],["76394.3","0","0"],["76401.7","0.07468405","1"],["76401.9","0","0"],["76411.7","0.1318149","2"],["76429.7","0.00001021","1"],["76440","0.01149708","8"],["76475.1","0.00001171","1"]],"bids":[["76372.4","0.58522107","13"],["76371.5","0","0"],["76366.7","0.00654398","1"],["76366.6","0","0"],["76366.5","0.33611563","3"],["76366.2","0.12280028","3"],["76359.6","0.32726458","1"],["76333.9","0.00001035","1"],["76317.6","0.10624634","1"],["76307.5","0","0"],["76300","0.00361088","5"],["76187","0.00011911","5"]]}
{"instId":"BTC-USDT","action":"update","ts":"1776816004000","asks":[["76383.2","0","0"],["76401.7","0.03934979","1"],["76403.1","0.10611863","1"],["76412.3","0","0"],["76416.6","0.2305","2"],["76475.6","0.00023531","5"]],"bids":[]}
{"instId":"BTC-USDT","action":"update","ts":"1776816004010","asks":[["76380.5","0.14770442","1"],["76385.3","0.00654408","1"],["76386.8","0","0"],["76390.2","0.3272536","1"],["76391.9","0.00654504","1"],["76392.8","0","0"],["76393.9","0","0"],["76402.8","0.06565777","2"],["76408.4","0","0"],["76463.8","0","0"],["76475.7","0.00004093","2"]],"bids":[["76370.5","0.00006973","1"],["76366.7","0","0"],["76359.7","0.00654408","1"],["76359.6","0","0"],["76358.7","0.3272536","1"],["76358.6","1.47733914","2"],["76356.9","0.00654504","1"],["76325.6","0.01179034","1"],["76317.8","0","0"],["76187.5","0","0"],["76187","0","0"]]}
{"instId":"BTC-USDT","action":"update","ts":"1776816004020","asks":[["76384","0.00654382","1"],["76385.3","0","0"],["76388","0.25504387","2"],["76403.1","0","0"],["76432.8","0.00002941","1"],["76440.5","0.05936187","2"],["76475.8","0.00016917","1"]],"bids":[["76359.7","0","0"],["76359.6","0.00654397","1"],["76352","0.47456308","2"],["76344.9","0","0"],["76316.2","0.00325142","1"],["76313.5","0.00233529","1"],["76309.4","0.65896686","2"],["76306.6","0","0"],["76292.6","0.00013107","1"],["76291.1","0.00001316","1"],["76284","0.00054218","1"],["76282.5","0","0"],["76187.7","0","0"]]}
{"instId":"BTC-USDT","action":"update","ts":"1776816004030","asks":[["76384","0.00654393","1"],["76387.9","0.08378297","1"],["76402.8","0.03896266","1"],["76425.6","0.5473033","5"],["76475.8","0","0"]],"bids":[["76347.6","0.00001086","1"],["76322","0.00325145","1"],["76319.4","0.00233532","1"],["76316.2","0","0"],["76313.5","0","0"],["76266.2","0.08378297","1"],["76187.8","0","0"]]}
{"instId":"BTC-USDT","action":"update","ts":"1776816004040","asks":[["76416.6","0.1305","1"],["76438.5","0.00115239","6"],["76448.8","0.00002073","1"],["76475.7","0","0"]],"bids":[["76358.7","0","0"],["76357.9","0.32724513","1"],["76356.9","0","0"],["76355.3","0.00654488","1"]]}
{"instId":"BTC-USDT","action":"update","ts":"1776816004050","asks":[["76372.5","0.2092776","5"],["76377.6","0.01309","1"],["76383.2","0.00654402","1"],["76383.3","0.17093178","2"],["76384","0","0"],["76387.8","0.21223725","3"],["76390.1","1.00559822","1"],["76403.1","0.05305931","1"],["76474.8","0","0"],["76475","0","0"],["76475.1","0","0"],["76475.6","0","0"]],"bids":[["76358.5","0.25669","3"],["76357.2","0.0131","1"],["76357.1","0.05087713","1"],["76349.7","0","0"],["76341.8","0.10483421","2"],["76339.8","0.30279","1"],["76332","0","0"],["76318.4","0.19917465","2"],["76314.6","0.00006276","2"],["76310.8","0.00004961","1"],["76307","0.00004961","1"],["76303.2","0.00004961","1"],["76299.3","0.00044967","2"],["76295.5","0.00004961","1"],["76291.7","0.00006048","2"],["76287.9","0.00004961","1"],["76284.1","1.00621169","2"],["76280.2","0.0000496","1"],["76276.4","0.0000496","1"],["76272.6","0.00004961","1"],["76268.8","0.00004961","1"],["76265","0.00004961","1"],["76261.1","1.54291062","3"],["76257.3","0.00004961","1"],["76253.5","0.73948331","4"],["76249.7","0.00004961","1"],["76245.9","0.00006462","2"],["76188.3","0","0"],["76187.9","0","0"]]}
{"instId":"BTC-USDT","action":"update","ts":"1776816004060","asks":[["76372.8","0","0"],["76385","0.47152624","2"],["76388","0.5429458","1"],["76474.8","0.00014553","1"]],"bids":[["76358.5","0.2305","2"],["76354.2","0.01919584","2"],["76351.8","0","0"],["76348","0","0"],["76345.3","0.00305","1"],["76344.2","0","0"],["76340.3","0","0"],["76339.1","0","0"],["76336.5","0","0"],["76332.7","0","0"],["76331.6","0","0"],["76328.9","0","0"],["76325.1","0","0"],["76321.2","0.00005813","5"],["76318.4","0.19912505","1"],["76317.4","0.55529605","2"],["76314.6","0.00001316","1"],["76313.6","0","0"],["76310.8","0","0"],["76309.8","0","0"],["76307","0","0"],["76306","0","0"],["76303.2","0","0"],["76302.1","0","0"],["76299.3","0.00040006","1"],["76298.3","0","0"],["76295.5","0","0"],["76294.5","0","0"],["76291.7","0.00001087","1"],["76290.7","0","0"],["76287.9","0","0"],["76286.9","0","0"],["76284.1","1.00616208","1"],["76280.2","0","0"],["76276.4","0","0"],["76272.6","0","0"],["76268.8","0","0"],["76265","0","0"],["76261.1","1.54286101","2"],["76257.3","0","0"],["76253.5","0.7394337","3"],["76249.7","0","0"],["76245.9","0.00001501","1"],["76188.3","0.00001061","1"],["76187.9","0.00001002","1"],["76187.8","0.00303","1"],["76187.7","0.47151308","1"],["76187.5","0.00032499","3"],["76187","0.00011911","5"],["76186.4","0.00022771","1"],["76186","0.00170529","1"],["76185.3","0.00002512","1"],["76184.8","0.01614584","1"],["76184.2","3.72","1"],["76184.1","0.47151308","1"],["76183.9","0.00003806","1"],["76183.7","0.00001319","1"],["76183.4","0.00005866","1"],["76183.3","0.00009283","1"],["76183","0.01496","1"],["76182.7","0.00002401","2"],["76182.2","0.00875","1"],["76181.6","0.00073364","2"],["76180.1","0.00013128","1"],["76180","0.0000812","1"],["76179.9","0.47151308","1"],["76179.3","0.00040006","1"],["76178.9","0.0008637","1"],["76177.9","0.00004571","1"],["76177.8","0.00105547","4"],["76175.4","0.00003868","3"],["76175.1","0.47151308","1"]]}
{"instId":"BTC-USDT","action":"update","ts":"1776816004070","asks":[["76383","0.00654393","1"],["76383.2","0","0"],["76384.1","0.19276094","3"],["76387.9","0","0"],["76391.8","0.0065449","1"],["76391.9","0","0"],["76417.4","1.01422461","3"],["76429.1","0.00003971","1"]],"bids":[["76358.6","1.48038914","3"],["76353.5","0","0"],["76352","0.47151308","1"],["76347.6","0","0"],["76341.7","0.54902849","3"],["76335.8","0","0"],["76329.9","0","0"],["76326.7","0","0"],["76325.6","0.07708523","2"],["76322.9","0.0000168","1"],["76321.2","0.00004727","4"],["76320.5","0.00002865","1"],["76319.1","0.0000168","1"],["76318.5","0","0"],["76315.3","0.00001681","1"],["76311.5","0.00001681","1"],["76309.4","0.658956","1"],["76307.6","0","0"],["76303.8","0","0"],["76303.6","0.0032326","1"],["76303.5","0.34619247","2"],["76300","0.00359153","4"],["76297.6","0","0"],["76296.7","0","0"],["76296.2","1.47767516","2"],["76292.4","0","0"],["76291.7","0","0"],["76184","0.1305","1"],["76176.3","0.1305","1"],["76175","0.00029601","2"],["76173.7","0.00070045","3"],["76173.6","0.00002308","1"],["76173.2","0.00001006","1"],["76173","0.00001059","1"],["76171.4","0.00683413","1"],["76171.1","0.00001024","1"],["76170.8","0.00003094","3"]]}
{"instId":"BTC-USDT","action":"update","ts":"1776816004080","asks":[["76374.7","0.00001154","1"],["76474.8","0","0"]],"bids":[["76366.6","0.1369864","1"],["76353.8","0","0"],["76353.2","0","0"],["76348.2","0.00001316","1"],["76347","0","0"],["76342.6","0","0"],["76341.8","0.21095284","3"],["76340.8","0.00671221","1"],["76337","0","0"],["76334.6","0","0"],["76331.4","0","0"],["76328.4","0.00012008","2"],["76322.8","0.13183039","2"],["76321.2","0.0000254","2"],["76320.5","0","0"],["76315.6","0","0"],["76315","0","0"],["76314.4","0","0"],["76310","0","0"],["76308.8","0","0"],["76304.4","0","0"],["76302.6","0","0"],["76298.8","0","0"],["76296.4","0","0"],["76293.2","0.03498","1"],["76290.2","0.0000463","1"],["76170.2","0.00001385","1"],["76170","0.001571","1"],["76169.2","0.0001094","1"],["76168.9","0.000015","1"],["76168.4","0.00011049","4"],["76167","0.00001319","1"],["76166.6","0.00248493","6"],["76166.2","0.00026145","4"],["76165.9","0.47151308","1"],["76165.8","0.01614584","1"],["76165.2","0.00091086","3"],["76165.1","0.00001015","1"],["76164.3","0.00046091","2"],["76163.9","0.00005592","3"],["76162.2","0.00002057","1"],["76162.1","0.00004159","3"]]}
{"instId":"BTC-USDT","action":"update","ts":"1776816004090","asks":[["76387.9","0.08378297","1"],["76429.1","0","0"],["76435.4","0.00003971","1"],["76474.6","0","0"]],"bids":[["76359.9","0.00001501","1"],["76359.5","0.67351067","2"],["76310","0.0032326","1"],["76303.6","0","0"],["76168.6","0.1305","1"],["76162.2","0","0"],["76162.1","0","0"]]}
{"instId":"BTC-USDT","action":"update","ts":"1776816004100","asks":[["76387.9","0.41103002","2"],["76390.2","0","0"],["76474.6","0.00039634","2"]],"bids":[["76359.6","0.12908483","2"],["76357.9","0","0"],["76357.2","0.41245946","3"],["76317.6","0","0"],["76162.2","0.00002057","1"],["76162.1","0.00004159","3"]]}
{"instId":"BTC-USDT","action":"update","ts":"1776816004110","asks":[["76387.8","0.5394843","4"],["76387.9","0.08378297","1"],["76390.2","0.00654491","1"],["76391.8","0","0"],["76402.2","0.06393614","1"],["76474.6","0","0"]],"bids":[["76357.2","0.08521264","2"],["76356.9","0.32724705","1"],["76349.2","0.38099782","1"],["76284","0.0005422","1"],["76162.2","0","0"],["76162.1","0","0"]]}
{"instId":"BTC-USDT","action":"update","ts":"1776816004120","asks":[["76381.6","0.00654397","1"],["76383","0","0"],["76387.8","0.15917794","2"],["76390","0.33379251","2"],["76390.2","0","0"],["76401.7","0.06503429","2"],["76420.8","0.12255586","2"],["76429.6","0.10001048","2"],["76449.3","0.03273432","1"],["76474.2","0","0"]],"bids":[["76368.8","0.0000168","1"],["76365","0.0000168","1"],["76361.1","0.0000168","1"],["76359.7","0.00654397","1"],["76359.6","0.12254086","1"],["76358.7","0.32724759","1"],["76357.2","0.17367642","3"],["76356.9","0","0"],["76355.3","0","0"],["76352.1","0.00654492","1"],["76316.7","0.1","1"],["76165.8","0","0"],["76165.2","0","0"],["76165.1","0","0"],["76164.3","0","0"],["76163.9","0","0"]]}
{"instId":"BTC-USDT","action":"update","ts":"1776816004130","asks":[["76381.6","0","0"],["76383.7","0.00654396","1"],["76390","0.32724759","1"],["76391.9","0.00654493","1"],["76429.5","0.07361823","1"],["76431.7","0","0"],["76474","0","0"]],"bids":[["76359.6","0.12515893","2"],["76358.7","0","0"],["76357.9","0.32724759","1"],["76357.2","0.08521264","2"],["76356.9","0.00654493","1"],["76356.8","0.036","1"],["76352.1","0.20628251","1"],["76298.5","0.01309035","1"],["76283","0","0"],["76165.9","0","0"]]}
{"instId":"BTC-USDT","action":"update","ts":"1776816004140","asks":[["76383.7","0","0"],["76384.9","0.00654391","1"],["76387.8","0.21223725","3"],["76390","0","0"],["76390.2","0.32724606","1"],["76391.9","0","0"],["76392.4","0.00654489","1"],["76428.5","0.02469065","35"]],"bids":[["76359.5","1.00075673","3"],["76357.9","0","0"],["76357.5","0.00654489","1"],["76356.9","0","0"],["76345.8","0.17994519","1"]]}
{"instId":"BTC-USDT","action":"update","ts":"1776816004150","asks":[["76384.9","0","0"],["76386.8","0.00654384","1"],["76390.2","0","0"],["76391.9","0.32724639","1"],["76392.4","0","0"],["76393.9","0.00654491","1"],["76399.5","0.01515268","1"],["76473.7","0","0"]],"bids":[["76366.3","0.00654384","1"],["76359.7","0.35343639","2"],["76359.5","0.67351067","2"],["76358.7","0.00654491","1"],["76357.5","0","0"],["76329.7","0","0"]]}
{"instId":"BTC-USDT","action":"update","ts":"1776816004160","asks":[],"bids":[["76345.8","0.26372816","2"],["76334.1","0.59496898","2"],["76316.7","0","0"],["76165.9","0.47151308","1"]]}
{"instId":"BTC-USDT","action":"update","ts":"1776816004170","asks":[["76372.5","0.20951828","6"],["76385.3","0.00654373","1"],["76386.8","0","0"],["76445.9","0.00093683","1"],["76473.6","0","0"]],"bids":[["76366.3","0","0"],["76359.8","0.00654373","1"],["76358.7","0","0"],["76357.9","0.00654491","1"],["76319.2","0.5699037","2"],["76293.2","0","0"],["76263.8","0","0"],["76165.8","0.01614584","1"],["76165.2","0.00091086","3"]]}
{"instId":"BTC-USDT","action":"update","ts":"1776816004180","asks":[["76372.5","0.20975694","8"],["76383","0.04909135","1"],["76392.9","0.09032789","2"],["76393.9","0","0"]],"bids":[["76325.7","0.02787234","1"],["76322.8","0.13180174","1"],["76165.2","0","0"]]}
{"instId":"BTC-USDT","action":"update","ts":"1776816004190","asks":[],"bids":[["76306.6","0.6418904","2"],["76253.5","0.52438615","2"],["76250.1","0","0"]]}
{"instId":"BTC-USDT","action":"update","ts":"1776816004200","asks":[["76372.5","0.2106955","9"],["76381.9","0.47151308","1"],["76390.2","0.32724774","1"],["76391.9","0","0"],["76473.5","0","0"]],"bids":[["76359.7","0.02619","1"],["76358.7","0.32724774","1"],["76325.5","0.1","1"],["76310","0.06407532","2"],["76308.5","0","0"],["76253.5","0.000015","1"],["76165.8","0","0"]]}
{"instId":"BTC-USDT","action":"update","ts":"1776816004210","asks":[["76380.5","0.29830181","2"],["76391.9","0.00654494","1"],["76392.9","0.08378297","1"],["76473.3","0","0"]],"bids":[["76357.9","0","0"],["76357.3","0.00654494","1"],["76325.7","0.05415891","2"]]}
{"instId":"BTC-USDT","action":"update","ts":"1776816004220","asks":[],"bids":[["76372.4","0.58399027","17"],["76368.6","0.00010133","3"],["76366.8","0.00001155","1"],["76366.2","0.12281061","4"],["76364.8","0.00010133","3"],["76361.2","0.00001155","1"],["76361","0.00010134","3"],["76360","0.00001033","1"],["76357.2","0.08531398","5"],["76355.6","0.00001155","1"],["76353.8","0.00001033","1"],["76353.3","0.00010134","3"],["76350","0.00001155","1"],["76349.5","0.00010134","3"],["76347.6","0.00001033","1"],["76345.7","0.56370743","5"],["76344.4","0.00001155","1"],["76341.9","0.00010136","3"],["76341.4","0.11840289","3"],["76338.1","0.00011452","4"],["76328.6","0.00132047","2"],["76313.4","0","0"],["76294.1","0.00013107","1"],["76292.6","0","0"],["76285.5","0.00054219","1"],["76284","0","0"],["76171.4","0","0"],["76171.1","0","0"],["76170.8","0","0"],["76170.2","0","0"],["76170","0","0"],["76169.2","0","0"],["76168.9","0","0"],["76168.6","0","0"],["76168.4","0","0"],["76167","0","0"],["76166.6","0","0"],["76166.2","0","0"],["76165.9","0","0"]]}
{"instId":"BTC-USDT","action":"update","ts":"1776816004230","asks":[["76384","0.00654397","1"],["76385.3","0","0"],["76390","0.32724872","1"],["76390.2","0","0"]],"bids":[["76372.4","0.58406347","19"],["76368.6","0.00016367","4"],["76366.5","0.33612649","4"],["76364.8","0.00016367","4"],["76361","0.00016368","4"],["76360.6","0.00001086","1"],["76358.7","0","0"],["76357.9","0.32724872","1"],["76357.3","0","0"],["76357.2","0.08537632","6"],["76355.3","0.00654495","1"],["76354.7","0.00001086","1"],["76353.3","0.00016368","4"],["76349.5","0.00016368","4"],["76348.8","0.00001086","1"],["76345.9","0","0"],["76345.7","0.56376978","6"],["76342.9","0.00001086","1"],["76341.9","0.00016371","4"],["76338.1","0.00017687","5"],["76320.3","0.12786872","1"],["76310","0.46693268","3"],["76173.7","0","0"],["76173.6","0","0"],["76173.2","0","0"],["76173","0","0"]]}
{"instId":"BTC-USDT","action":"update","ts":"1776816004240","asks":[],"bids":[["76299.2","0.06789316","1"],["76175","0","0"]]}
{"instId":"BTC-USDT","action":"update","ts":"1776816004250","asks":[["76372.5","0.29324558","10"]],"bids":[["76372.4","0.44056017","17"],["76359.7","0","0"],["76285.3","0.02500922","1"]]}
{"instId":"BTC-USDT","action":"update","ts":"1776816004260","asks":[["76372.5","0.32600967","11"],["76382.6","0.00654398","1"],["76384","0","0"]],"bids":[["76372.4","0.28319608","15"],["76361.1","0.0262068","2"],["76359.8","0","0"],["76359.7","0.00654398","1"],["76358.6","0.47456308","2"],["76219.7","1.00559822","1"],["76175.1","0","0"]]}
{"instId":"BTC-USDT","action":"update","ts":"1776816004270","asks":[["76372.5","0.32559269","9"],["76382.5","0.00654406","1"],["76382.6","0","0"],["76383.7","0.08378297","1"],["76387.7","0.32724779","1"],["76389.9","0.00654494","1"],["76390","0","0"],["76391.9","0","0"],["76473.2","0","0"]],"bids":[["76372.4","0.32632156","17"],["76366.6","0.10038763","1"],["76361.2","0.00655552","2"],["76359.7","0","0"],["76359.5","0.3056657","1"],["76357.9","0","0"],["76357.1","0","0"],["76355.3","0.32724779","1"],["76354.3","0.00654494","1"],["76345.8","0.17994519","1"],["76341.7","0.46524552","2"],["76261.3","0.08378297","1"],["76175.1","0.47151308","1"]]}
{"instId":"BTC-USDT","action":"update","ts":"1776816004280","asks":[["76372.5","0.32821033","10"]],"bids":[["76372.4","0.28312156","16"],["76366.6","0.0506804","1"],["76361.1","0.0000168","1"],["76357.1","0.05087713","1"],["76355.4","0.47151308","1"],["76175.4","0","0"],["76175.1","0","0"]]}
{"instId":"BTC-USDT","action":"update","ts":"1776816004290","asks":[["76372.5","0.32814797","9"],["76381.6","0.00654397","1"],["76382.5","0","0"]],"bids":[["76366.6","0.13056721","2"],["76361.3","0.00654407","1"],["76361.2","0.00001155","1"],["76341.7","0.54902849","3"],["76176.3","0","0"]]}
{"instId":"BTC-USDT","action":"update","ts":"1776816004300","asks":[["76389.9","0","0"],["76390","0.00654497","1"]],"bids":[["76372.4","0.28088001","15"],["76361.3","0","0"],["76359.7","0.00654408","1"],["76357.2","0.32534277","7"],["76354.3","0","0"],["76353.4","0.00654497","1"],["76342.9","0.12521565","2"],["76320.3","0","0"],["76175.4","0.00003868","3"]]}
{"instId":"BTC-USDT","action":"update","ts":"1776816004310","asks":[["76372.5","0.32909797","10"],["76378.7","0.47151308","1"],["76473","0","0"]],"bids":[["76341.4","0.00002349","2"],["76320.3","0.12786872","1"],["76295.6","0.00013107","1"],["76294.1","0","0"],["76287.1","0.00054219","1"],["76285.5","0","0"],["76269.2","0.23984749","2"],["76175.4","0","0"]]}
{"instId":"BTC-USDT","action":"update","ts":"1776816004320","asks":[["76376.3","0.1882708","1"],["76379.9","0.04718235","2"],["76383.3","0.12376028","1"],["76389.9","0.00654509","1"],["76390","0","0"],["76397.3","0.01596674","1"],["76472.6","0","0"]],"bids":[["76366.6","0","0"],["76359.5","0","0"],["76358.6","0.00305","1"],["76358.2","0.00001316","1"],["76355.4","0","0"],["76354.9","0.00001316","1"],["76352.2","1.4771113","2"],["76352","0","0"],["76351.5","0","0"],["76349.4","0.01547224","1"],["76349.1","0.01614584","1"],["76175.4","0.00003868","3"]]}
{"instId":"BTC-USDT","action":"update","ts":"1776816004330","asks":[["76372.5","0.35192797","11"]],"bids":[["76372.4","0.27468001","14"],["76358.6","0","0"],["76357.2","0.18460005","6"],["76357.1","0","0"],["76354.2","0.00305","1"],["76352.1","0","0"],["76349.2","0","0"],["76349","0.0125291","1"],["76348.9","0.00305","1"],["76345.3","0","0"],["76329","0.00305","1"],["76176.3","0.1305","1"],["76175.1","0.47151308","1"]]}
{"instId":"BTC-USDT","action":"update","ts":"1776816004340","asks":[["76376.4","0.0471715","1"],["76379.8","0.00654426","1"],["76379.9","0.00001085","1"],["76381.6","0","0"],["76386.8","0.32726849","1"],["76387.6","0.00654533","1"],["76387.7","0","0"],["76389.9","0","0"],["76425.3","0","0"]],"bids":[["76366.6","0.13704659","1"],["76355.3","0","0"],["76353.4","0","0"],["76352.3","0.83690002","4"],["76349.1","0.05980089","2"],["76341.8","0.26182997","4"],["76341","0.00305","1"],["76329","0","0"],["76320.3","0","0"],["76317.6","0.12786872","1"],["76175","0.00029601","2"]]}
{"instId":"BTC-USDT","action":"update","ts":"1776816004350","asks":[["76377.6","0.14148862","2"],["76384.1","0.27825004","2"],["76384.9","0.32726566","1"],["76386.8","0","0"]],"bids":[["76372.4","0.24794982","11"],["76366.2","0.00518504","3"],["76359.5","0.16910418","1"],["76357.2","0.07417602","6"],["76354.3","0.00305","1"],["76352.4","0.32726566","1"],["76352.3","0.50963153","3"],["76348.9","0","0"],["76334.2","0.0000666","3"],["76330.4","0.00005627","2"],["76328","0.00002349","2"],["76326.6","0.00005627","2"],["76322.8","0.13185802","3"],["76321.8","0.07109474","4"],["76319","0.00005628","2"],["76315.6","0.00001033","1"],["76315.1","0.00005628","2"],["76311.3","0.00005628","2"],["76309.4","0.65896633","2"],["76307.5","0.00005629","2"],["76303.7","0.00005629","2"],["76303.2","0.00001033","1"],["76299.9","0.00005629","2"],["76182.2","0","0"],["76181.6","0","0"],["76180.1","0","0"],["76180","0","0"],["76179.9","0","0"],["76179.3","0","0"],["76178.9","0","0"],["76177.9","0","0"],["76177.8","0","0"],["76176.3","0","0"],["76175.4","0","0"],["76175.1","0","0"],["76175","0","0"]]}
{"instId":"BTC-USDT","action":"update","ts":"1776816004360","asks":[["76378.6","0.00654432","1"],["76379.8","0","0"],["76386.8","0.00654525","1"],["76387.6","0","0"]],"bids":[["76366.6","0.10193536","1"],["76361.2","0.02620155","2"],["76359.7","0","0"],["76358.6","0.00654432","1"],["76352.3","0.5030862","2"],["76351.4","0.00654525","1"],["76334.2","0.00007746","4"],["76328.3","0.00001086","1"],["76322.4","0.00001086","1"],["76316.5","0.00001086","1"],["76310.6","0.00001086","1"],["76304.7","0.00001086","1"],["76183.9","0","0"],["76183.7","0","0"],["76183.4","0","0"],["76183.3","0","0"],["76183","0","0"],["76182.7","0","0"]]}
{"instId":"BTC-USDT","action":"update","ts":"1776816004390","asks":[["76383.6","1.00559822","1"],["76472.5","0","0"]],"bids":[["76359.4","0.1","1"],["76358.5","0.1","1"],["76351.4","0","0"],["76349.9","0.00654515","1"]]}
{"instId":"BTC-USDT","action":"update","ts":"1776816004400","asks":[["76372.5","0.35193797","12"],["76380.5","0.59014783","1"],["76403.1","0","0"],["76472.5","0.00008103","2"]],"bids":[["76372.4","0.20077832","10"],["76369.2","0.0471715","1"],["76359.5","0.12135741","1"],["76184","0","0"]]}
{"instId":"BTC-USDT","action":"update","ts":"1776816004410","asks":[["76403.1","0.05305931","1"],["76472.5","0","0"]],"bids":[["76369.3","0.01413456","1"],["76366.2","0.00006044","2"],["76184.1","0","0"]]}
{"instId":"BTC-USDT","action":"update","ts":"1776816004420","asks":[["76397.3","0","0"],["76472.5","0.00008103","2"]],"bids":[["76349.4","0","0"],["76184.1","0.47151308","1"]]}
{"instId":"BTC-USDT","action":"update","ts":"1776816004430","asks":[["76378.6","0","0"],["76380.4","0.00654466","1"]],"bids":[["76359.7","0.00654466","1"],["76358.6","0","0"]]}
{"instId":"BTC-USDT","action":"update","ts":"1776816004440","asks":[],"bids":[["76352.3","0.50963143","3"],["76349.9","0","0"],["76183.9","0.00003806","1"]]}
{"instId":"BTC-USDT","action":"update","ts":"1776816004450","asks":[["76373.6","0.0471715","1"],["76376.4","0","0"],["76384.9","0","0"],["76386.8","0.32726287","1"],["76387.7","0.00654523","1"],["76435.4","0","0"],["76472.6","0.00002975","1"]],"bids":[["76352.4","0.33381089","2"],["76352.3","0.5030862","2"],["76341.8","0.21095284","3"],["76184","0.1305","1"],["76183.9","0","0"]]}
{"instId":"BTC-USDT","action":"update","ts":"1776816004460","asks":[["76372.5","0.35167597","12"],["76373.5","0.01727633","1"],["76387.8","0.15917794","2"],["76390.3","0","0"]],"bids":[["76357.1","0.05087713","1"],["76355.3","0.32726282","1"],["76352.4","0.00654523","1"],["76184.1","0","0"],["76184","0","0"]]}
{"instId":"BTC-USDT","action":"update","ts":"1776816004470","asks":[["76384.9","0.32726281","1"],["76386.7","0.00654518","1"],["76386.8","0","0"],["76387.7","0","0"],["76403.1","0.10611862","2"]],"bids":[["76372.4","0.24397832","11"],["76357.2","0.18017369","7"],["76355.3","0","0"],["76352.4","0.32726281","1"],["76351.4","0.00654518","1"]]}
{"instId":"BTC-USDT","action":"update","ts":"1776816004480","asks":[["76380.4","0.00654463","1"],["76402.8","0.06565777","2"]],"bids":[["76359.7","0","0"],["76359.6","0.13170356","3"],["76357.2","0.07417602","6"],["76184.1","0.47151308","1"]]}
{"instId":"BTC-USDT","action":"update","ts":"1776816004500","asks":[],"bids":[["76372.4","0.20077832","10"]]}
{"instId":"BTC-USDT","action":"update","ts":"1776816004510","asks":[["76403.1","0.05305931","1"]],"bids":[]}
{"instId":"BTC-USDT","action":"update","ts":"1776816004520","asks":[["76378.6","0.00654437","1"],["76380.4","0","0"],["76385.8","0.01614584","1"],["76387.8","0.21223725","3"],["76472.6","0","0"]],"bids":[["76359.6","0.12515893","2"],["76358.6","0.00654437","1"],["76184.1","0","0"]]}
{"instId":"BTC-USDT","action":"update","ts":"1776816004530","asks":[],"bids":[["76340.2","0.0429","1"],["76184.2","0","0"]]}
{"instId":"BTC-USDT","action":"update","ts":"1776816004540","asks":[["76378.8","0.12106302","1"],["76385.7","0.00654522","1"],["76386.7","0","0"]],"bids":[["76357.1","0","0"],["76351.4","0","0"],["76349.9","0.00654522","1"],["76184.2","3.72","1"]]}
{"instId":"BTC-USDT","action":"update","ts":"1776816004550","asks":[["76435.4","0.00003969","1"],["76472.5","0","0"]],"bids":[["76341.8","0.26182997","4"]]}
{"instId":"BTC-USDT","action":"update","ts":"1776816004590","asks":[],"bids":[["76372.4","0.24397832","11"]]}
{"instId":"BTC-USDT","action":"update","ts":"1776816004600","asks":[["76372.5","0.35150576","12"],["76385.7","0","0"],["76386.8","0.00654519","1"]],"bids":[["76361.2","0.12620155","3"],["76357.4","0","0"],["76351.4","0.00654519","1"],["76349.9","0","0"],["76184.1","0.47151308","1"]]}
{"instId":"BTC-USDT","action":"update","ts":"1776816004610","asks":[["76372.5","0.35125701","12"],["76387.8","0.15917794","2"]],"bids":[["76361.3","0.03772504","1"],["76359.6","0.22515893","3"],["76357.8","0","0"],["76341.8","0.21095284","3"]]}
{"instId":"BTC-USDT","action":"update","ts":"1776816004620","asks":[["76378.6","0","0"],["76380.4","0.00654457","1"],["76384.9","0","0"],["76386.8","0.33380557","2"],["76395.3","0.01596988","1"],["76403.1","0.10611862","2"]],"bids":[["76361.3","0.13772504","2"],["76359.7","0.13541193","2"],["76359.5","0","0"],["76358.6","0","0"],["76358.5","0","0"],["76357.1","0.05087713","1"],["76351.2","0.08117379","2"],["76341.9","0.1253685","5"],["76328.6","0.12386133","3"],["76183.9","0.00003806","1"]]}
{"instId":"BTC-USDT","action":"update","ts":"1776816004630","asks":[["76372.5","0.35030701","11"],["76373.5","0","0"],["76386.8","0.32726038","1"],["76387.8","0.16572311","3"],["76472.5","0.00008103","2"]],"bids":[["76372.4","0.34633885","14"],["76361.4","0.06757504","1"],["76361.3","0.1","1"],["76359.7","0.23541193","3"],["76359.4","0","0"],["76357","0.1305","1"],["76355.2","0.4456125","2"],["76353.4","0.00654517","1"],["76352.4","0","0"],["76351.4","0","0"],["76184","0.1305","1"],["76183.9","0","0"]]}
{"instId":"BTC-USDT","action":"update","ts":"1776816004640","asks":[["76372.5","0.35660701","12"],["76373.6","0","0"],["76380.4","0","0"],["76381.6","0.00654458","1"],["76383.3","0","0"],["76383.6","0","0"],["76383.7","0","0"],["76385.8","0","0"],["76386.8","0","0"],["76387.7","0.32725958","1"],["76387.8","0.15917794","2"],["76390","0.00654514","1"],["76395.3","0","0"],["76435.4","0","0"],["76472.6","0.00002975","1"],["76473","0.0001084","1"],["76473.2","0.00001599","1"],["76473.3","0.00564466","1"],["76473.5","0.08378297","1"],["76473.6","0.0007428","8"]],"bids":[["76372.4","0.34646529","15"],["76361.4","0.17411962","3"],["76359.8","0.13748433","1"],["76359.7","0.1","1"],["76359.6","0.12515893","2"],["76355.3","0.79877266","2"],["76355.2","0.11835258","1"],["76354.4","0.00654514","1"],["76353.4","0","0"],["76345.9","0.08378297","1"],["76317.6","0","0"],["76261.3","0","0"],["76184","0","0"]]}
{"instId":"BTC-USDT","action":"update","ts":"1776816004650","asks":[["76380.5","0.26811595","1"],["76381.6","0","0"],["76382.6","0.00654456","1"],["76383","0","0"],["76384.1","0.00006723","1"],["76387.9","0","0"],["76432.7","0.0196484","1"],["76473.7","0.00015227","1"]],"bids":[["76361.5","0.00654456","1"],["76361.4","0.16757504","2"],["76359.8","0.06721387","1"],["76352.1","0.01576037","1"],["76349","0","0"],["76184.1","0","0"]]}
{"instId":"BTC-USDT","action":"update","ts":"1776816004660","asks":[["76384.9","0.20317055","1"],["76430","0.12943168","6"],["76473.7","0","0"]],"bids":[["76361.5","0.10654456","2"],["76359.7","0","0"],["76357.2","0.36182736","7"],["76351.8","0.01252863","1"],["76334.5","0.00002864","1"],["76184.2","0","0"]]}
{"instId":"BTC-USDT","action":"update","ts":"1776816004670","asks":[["76372.5","0.33102844","10"],["76378.7","0","0"],["76387.7","0","0"],["76390","0.32725431","1"],["76390.1","0","0"],["76391.9","0.00654506","1"],["76429.5","0.10664977","2"],["76473.7","0.00015227","1"],["76474","0.00001017","1"]],"bids":[["76372.4","0.36909529","16"],["76361.6","0.12922859","1"],["76361.4","0.1","1"],["76361.2","0.10001155","2"],["76359.8","0","0"],["76357.3","0.32725431","1"],["76355.4","0.00654506","1"],["76355.3","0.47151308","1"],["76354.4","0","0"],["76184.8","0","0"]]}
{"instId":"BTC-USDT","action":"update","ts":"1776816004680","asks":[["76376.3","0","0"],["76377.5","0.07868368","1"],["76382.6","0","0"],["76383.7","0.00654449","1"],["76387.8","0.10611863","1"],["76388","0","0"],["76390","1.00559822","1"],["76391.9","0.33379941","2"],["76474.2","0.00031344","3"]],"bids":[["76372.4","0.47171307","18"],["76366.2","0.00001033","1"],["76361.6","0.13577308","2"],["76361.5","0.12619","2"],["76361.2","0.00001155","1"],["76359.7","0.13900849","1"],["76357.2","0.07417602","6"],["76341.8","0.15917794","2"],["76185.3","0","0"]]}
{"instId":"BTC-USDT","action":"update","ts":"1776816004690","asks":[["76388","0.44092613","1"],["76474.2","0","0"]],"bids":[["76357.2","0.26414035","7"]]}
{"instId":"BTC-USDT","action":"update","ts":"1776816004700","asks":[["76372.5","0.33096298","10"],["76388","0.5247091","2"],["76403.1","0.15917793","3"],["76435.4","0.00003969","1"],["76474","0","0"]],"bids":[["76357.1","0.10265203","2"]]}
{"instId":"BTC-USDT","action":"update","ts":"1776816004710","asks":[["76372.5","0.33089752","10"]],"bids":[]}
{"instId":"BTC-USDT","action":"update","ts":"1776816004730","asks":[["76377.4","0.00011311","1"],["76473.7","0","0"]],"bids":[]}
{"instId":"BTC-USDT","action":"update","ts":"1776816004740","asks":[["76378.8","0","0"],["76473.7","0.00015227","1"]],"bids":[]}
{"instId":"BTC-USDT","action":"update","ts":"1776816004750","asks":[["76377.5","0.04254637","1"],["76403.1","0.10611862","2"]],"bids":[["76357.1","0.05087713","1"]]}
{"instId":"BTC-USDT","action":"update","ts":"1776816004760","asks":[["76387.8","0.15917794","2"]],"bids":[["76341.8","0.21095284","3"]]}
{"instId":"BTC-USDT","action":"update","ts":"1776816004770","asks":[["76372.5","0.35372752","11"],["76375.5","0.0471715","1"],["76388","0.85196335","3"],["76391.9","0.00654506","1"],["76435.4","0","0"]],"bids":[]}
{"instId":"BTC-USDT","action":"update","ts":"1776816004780","asks":[["76372.5","0.35634522","12"],["76375.4","0.00014253","1"],["76377.4","0","0"],["76391.7","0.11523128","2"]],"bids":[]}
{"instId":"BTC-USDT","action":"update","ts":"1776816004790","asks":[["76372.5","0.40104155","13"],["76375.4","0.01408069","1"],["76375.5","0","0"],["76388","0.5247091","2"],["76389.9","0.3272559","1"]],"bids":[]}
{"instId":"BTC-USDT","action":"update","ts":"1776816004800","asks":[["76372.5","0.40365931","14"],["76375.4","0","0"],["76382.6","0.00654445","1"],["76383.7","0","0"],["76474","0.00001017","1"]],"bids":[["76361.7","0.00654445","1"],["76361.6","0.12922859","1"],["76186","0","0"]]}
{"instId":"BTC-USDT","action":"update","ts":"1776816004830","asks":[],"bids":[["76372.4","0.44908307","17"]]}
{"instId":"BTC-USDT","action":"update","ts":"1776816004840","asks":[["76387.7","0.32725772","1"],["76389.9","0","0"]],"bids":[["76357.3","0","0"],["76355.4","0.33380278","2"],["76186","0.00170529","1"]]}
{"instId":"BTC-USDT","action":"update","ts":"1776816004850","asks":[["76372.5","0.40351678","13"]],"bids":[["76359.7","0.04132308","1"],["76326.3","0.00131016","1"],["76316.8","0","0"]]}
{"instId":"BTC-USDT","action":"update","ts":"1776816004860","asks":[["76403.1","0.05305931","1"]],"bids":[]}
{"instId":"BTC-USDT","action":"update","ts":"1776816004870","asks":[],"bids":[["76372.4","0.44646529","16"]]}
{"instId":"BTC-USDT","action":"update","ts":"1776816004880","asks":[["76377.6","0.14199626","3"]],"bids":[["76248.2","0","0"],["76185.3","0.00002512","1"]]}
{"instId":"BTC-USDT","action":"update","ts":"1776816004890","asks":[["76387.8","0.21223725","3"]],"bids":[]}
{"instId":"BTC-USDT","action":"update","ts":"1776816004900","asks":[["76435.4","0.00003969","1"],["76474","0","0"]],"bids":[]}
{"instId":"BTC-USDT","action":"update","ts":"1776816004910","asks":[],"bids":[["76357.1","0","0"],["76184.8","0.01614584","1"]]}
{"instId":"BTC-USDT","action":"update","ts":"1776816004920","asks":[],"bids":[["76341.8","0.26182997","4"]]}
{"instId":"BTC-USDT","action":"update","ts":"1776816004960","asks":[["76377.6","0.14301154","5"]],"bids":[]}
{"instId":"BTC-USDT","action":"update","ts":"1776816004970","asks":[],"bids":[["76341.8","0.21095284","3"]]}
{"instId":"BTC-USDT","action":"update","ts":"1776816004980","asks":[],"bids":[["76357.1","0.05087713","1"],["76184.8","0","0"]]}
{"instId":"BTC-USDT","action":"update","ts":"1776816004990","asks":[],"bids":[["76357.1","0","0"],["76184.8","0.01614584","1"]]}
{"instId":"BTC-USDT","action":"update","ts":"1776816005000","asks":[["76372.5","0.39715132","12"]],"bids":[["76357.1","0.05087713","1"],["76184.8","0","0"]]}
{"instId":"BTC-USDT","action":"update","ts":"1776816005010","asks":[["76372.5","0.39702039","12"]],"bids":[["76357.1","0","0"],["76192.7","0.00013126","1"]]}
{"instId":"BTC-USDT","action":"update","ts":"1776816005040","asks":[["76389.9","0.00654518","1"],["76391.9","0","0"],["76397.1","0.01531994","1"],["76473.7","0","0"]],"bids":[["76355.4","0.32725772","1"],["76353.4","0.00654518","1"],["76185.3","0","0"]]}
{"instId":"BTC-USDT","action":"update","ts":"1776816005050","asks":[["76372.5","0.39913039","13"],["76401.6","0.12256172","1"],["76473.6","0","0"]],"bids":[["76372.4","0.34646529","15"],["76317.6","0.11169469","1"],["76186","0","0"]]}
{"instId":"BTC-USDT","action":"update","ts":"1776816005060","asks":[],"bids":[["76372.4","0.33271241","13"],["76361.7","0.10654445","2"],["76341.8","0.26182997","4"]]}
{"instId":"BTC-USDT","action":"update","ts":"1776816005070","asks":[["76381.6","0.00654447","1"],["76382.6","0","0"]],"bids":[["76361.7","0.1","1"],["76361.6","0.22922859","2"],["76361.3","0","0"],["76359.8","0.00654447","1"]]}
{"instId":"BTC-USDT","action":"update","ts":"1776816005080","asks":[],"bids":[["76361.8","0.12727504","1"],["76361.6","0.1","1"],["76186.4","0","0"]]}
{"instId":"BTC-USDT","action":"update","ts":"1776816005090","asks":[["76372.5","0.46414039","14"]],"bids":[["76361.8","0.22727504","2"],["76361.4","0","0"],["76186.4","0.00022771","1"]]}
{"instId":"BTC-USDT","action":"update","ts":"1776816005100","asks":[["76372.5","0.46400946","14"],["76377.6","0.14351919","6"]],"bids":[["76351.8","0","0"],["76186","0.00170529","1"]]}
{"instId":"BTC-USDT","action":"update","ts":"1776816005110","asks":[],"bids":[["76349.4","0.01252903","1"],["76186","0","0"]]}
{"instId":"BTC-USDT","action":"update","ts":"1776816005130","asks":[["76372.9","0.00013117","1"],["76473.5","0","0"]],"bids":[]}
{"instId":"BTC-USDT","action":"update","ts":"1776816005140","asks":[["76383.7","0.08378297","1"],["76473.3","0","0"]],"bids":[]}
{"instId":"BTC-USDT","action":"update","ts":"1776816005160","asks":[["76403.1","0","0"],["76473.3","0.00564466","1"]],"bids":[["76372.4","0.32814241","12"],["76325.5","0","0"],["76186","0.00170529","1"]]}
{"instId":"BTC-USDT","action":"update","ts":"1776816005170","asks":[["76402.8","0.03896266","1"]],"bids":[["76325.7","0.02787234","1"]]}
{"instId":"BTC-USDT","action":"update","ts":"1776816005180","asks":[["76372.5","0.41441484","12"],["76403.1","0.05305931","1"],["76473.3","0","0"]],"bids":[["76372.4","0.32804241","13"],["76341.8","0.21095284","3"]]}
{"instId":"BTC-USDT","action":"update","ts":"1776816005200","asks":[],"bids":[["76361.9","0.00654454","1"],["76359.8","0","0"],["76331.7","0.1","1"],["76250.1","0.005144","1"],["76186.4","0","0"],["76186","0","0"]]}
{"instId":"BTC-USDT","action":"update","ts":"1776816005210","asks":[["76397.1","0","0"],["76473.3","0.00564466","1"]],"bids":[["76372.4","0.32714849","13"],["76361.9","0.10654454","2"],["76361.5","0.02619","1"]]}
{"instId":"BTC-USDT","action":"update","ts":"1776816005220","asks":[["76401.8","0.00001316","1"]],"bids":[["76362","0.12922858","1"],["76361.8","0.1","1"],["76187","0","0"]]}
{"instId":"BTC-USDT","action":"update","ts":"1776816005230","asks":[["76401.5","0.05567354","1"],["76401.7","0","0"]],"bids":[["76362","0.22922858","2"],["76361.6","0","0"],["76187","0.00011911","5"]]}
{"instId":"BTC-USDT","action":"update","ts":"1776816005240","asks":[["76403.1","0","0"],["76473.5","0.08378297","1"]],"bids":[]}
{"instId":"BTC-USDT","action":"update","ts":"1776816005250","asks":[],"bids":[["76341.8","0.26182997","4"]]}
{"instId":"BTC-USDT","action":"update","ts":"1776816005260","asks":[["76372.5","0.36724334","11"],["76377.6","0.01512057","5"],["76381.9","0","0"],["76383.7","0","0"],["76385","0.00001316","1"],["76387.7","0","0"],["76388.1","0","0"],["76388.7","0.47151308","1"],["76390","0","0"],["76392.5","0","0"],["76397.4","1.4771113","2"],["76397.7","0","0"],["76397.8","0","0"],["76401.5","0.52718662","2"],["76473.6","0.0007428","8"],["76473.7","0.00015227","1"],["76474","0.00001017","1"],["76474.2","0.00031344","3"],["76474.6","0.00039634","2"],["76474.8","0.00014553","1"]],"bids":[["76366.8","0.10620595","2"],["76361.9","0.1","1"],["76361.5","0","0"],["76359.8","0.47805759","2"],["76341.8","0.21095284","3"],["76317.6","0","0"],["76186.4","0.00022771","1"]]}
{"instId":"BTC-USDT","action":"update","ts":"1776816005270","asks":[["76377.5","0","0"],["76380.5","0.1127155","1"],["76381.6","0","0"],["76382.6","0.00654451","1"],["76382.7","0.13666945","2"],["76384.9","0","0"],["76385.4","0.4722779","2"],["76388","0.08378297","1"],["76389.9","0","0"],["76391.6","0.00654502","1"],["76392","0","0"],["76397.6","0","0"],["76403.1","0.05305931","1"],["76455.4","0.000028","2"],["76459","0","0"],["76475","0.01748409","6"],["76475.1","0.00001171","1"],["76475.6","0.00023531","5"],["76475.7","0.00004093","2"]],"bids":[["76364.7","0.02619","1"],["76362.1","0.00654451","1"],["76362","0.18960732","2"],["76359.8","0.47151308","1"],["76355.4","0.33380274","2"],["76353.4","0","0"],["76352.2","1.48963988","3"],["76349.4","0","0"],["76309.4","0.00001033","1"],["76305.5","0.00004629","1"],["76219.8","1.00559822","1"],["76219.7","0","0"]]}
{"instId":"BTC-USDT","action":"update","ts":"1776816005280","asks":[["76382.6","0.13976378","2"],["76385.3","0.20316663","1"],["76402.2","0","0"]],"bids":[["76364.7","0.12619","2"],["76361.7","0","0"],["76359.9","0.18208474","2"],["76359.7","0","0"],["76325.6","0.01179034","1"],["76310","0.06407532","2"],["76306.6","0.41029156","1"],["76186","0.00170529","1"],["76185.3","0.00002512","1"]]}
{"instId":"BTC-USDT","action":"update","ts":"1776816005290","asks":[["76380.5","0.17862804","2"],["76382.1","0.47151308","1"],["76425.3","0.12522611","1"],["76430","0.00689082","5"],["76475.6","0","0"],["76475.7","0","0"]],"bids":[["76364.8","0.1175653","5"],["76362.1","0.10654451","2"],["76362","0.1","1"],["76361.8","0","0"],["76325.7","0","0"],["76184.8","0.01614584","1"],["76184.2","3.72","1"]]}
{"instId":"BTC-USDT","action":"update","ts":"1776816005300","asks":[["76380.5","0.3109479","1"],["76382","0.11989734","1"],["76382.7","0.0008","1"],["76383.1","0","0"],["76391.6","0.13177113","2"],["76395.8","0","0"],["76425.2","0.12522611","1"],["76425.3","0","0"],["76429.5","0.07361823","1"],["76475.6","0.00023531","5"]],"bids":[["76364.8","0.2175653","6"],["76361.9","0","0"],["76310","0.27023739","3"],["76184.1","0.47151308","1"]]}
{"instId":"BTC-USDT","action":"update","ts":"1776816005310","asks":[["76387.7","0.55637119","2"],["76475.6","0","0"]],"bids":[["76371.8","0.0471715","1"],["76369.2","0","0"],["76364.8","0.16969224","6"],["76298.7","0.00013106","1"],["76295.6","0","0"],["76290.1","0.00054218","1"],["76287.1","0","0"]]}
{"instId":"BTC-USDT","action":"update","ts":"1776816005320","asks":[["76387.6","1.40079212","2"],["76387.7","0.32725409","1"],["76475.1","0","0"]],"bids":[["76372.4","0.34977849","14"],["76371.9","0.01415538","1"],["76369.3","0","0"],["76361.6","0.00001316","1"],["76351.5","0.00001316","1"],["76184.2","0","0"],["76184.1","0","0"]]}
{"instId":"BTC-USDT","action":"update","ts":"1776816005330","asks":[["76375","0.0471715","1"],["76381.6","0.00654435","1"],["76382.6","0.13321927","1"],["76385.3","0.59532862","2"],["76474.8","0","0"],["76475","0","0"]],"bids":[["76362.1","0.1","1"],["76360","0.00655468","2"],["76357.1","0.05087713","1"],["76184.8","0","0"]]}
{"instId":"BTC-USDT","action":"update","ts":"1776816005340","asks":[["76374.9","0.01409833","2"],["76387.8","0.15917794","2"],["76391.5","0.00654516","1"],["76391.6","0.12522611","1"],["76435.4","0","0"]],"bids":[["76355.4","0.32725772","1"],["76353.4","0.00654516","1"],["76185.3","0","0"]]}
{"instId":"BTC-USDT","action":"update","ts":"1776816005350","asks":[["76387.5","0.11193526","1"],["76387.8","0.21223725","3"],["76397.1","0.01587874","1"],["76397.3","0.47076234","1"],["76474","0","0"],["76474.2","0","0"],["76474.6","0","0"]],"bids":[]}
{"instId":"BTC-USDT","action":"update","ts":"1776816005360","asks":[["76391.6","0.33073223","2"]],"bids":[]}
{"instId":"BTC-USDT","action":"update","ts":"1776816005370","asks":[["76372.5","0.36679817","11"]],"bids":[["76212.9","0","0"],["76185.3","0.00002512","1"]]}
{"instId":"BTC-USDT","action":"update","ts":"1776816005380","asks":[],"bids":[["76372.4","0.30657849","13"]]}
{"instId":"BTC-USDT","action":"update","ts":"1776816005390","asks":[["76372.5","0.37173817","12"],["76387.8","0.15917794","2"],["76387.9","0.00654518","1"],["76391.5","0","0"]],"bids":[["76372.4","0.30037849","12"],["76366.9","0.16","1"],["76185.3","0","0"]]}
{"instId":"BTC-USDT","action":"update","ts":"1776816005400","asks":[["76372.5","0.37036335","12"],["76386.8","0.32725979","1"],["76387.7","0","0"],["76387.8","0.21223725","3"]],"bids":[["76367","0.19541308","1"],["76366.6","0","0"],["76366.5","0.19564086","3"],["76357.1","0","0"],["76355.4","0","0"],["76352.4","0.32725979","1"],["76317.6","0.11016887","1"]]}
{"instId":"BTC-USDT","action":"update","ts":"1776816005410","asks":[["76372.5","0.32107294","9"],["76387.8","0.10611863","1"],["76462.7","0.659145","1"],["76466.4","0.657604","1"],["76473.6","0","0"],["76473.7","0","0"]],"bids":[["76372.4","0.30687849","14"],["76357.1","0.05087713","1"],["76316.7","0.658892","1"],["76312.8","0.660439","1"],["76187","0","0"],["76186.4","0","0"],["76186","0","0"]]}
{"instId":"BTC-USDT","action":"update","ts":"1776816005420","asks":[["76372.5","0.34047294","10"],["76387.6","1.20499264","2"]],"bids":[["76314.5","0.93238238","3"]]}
{"instId":"BTC-USDT","action":"update","ts":"1776816005430","asks":[["76372.5","0.34245294","11"],["76387.8","0.15917794","2"],["76403.1","0.10611862","2"]],"bids":[["76372.4","0.28424849","13"],["76371.9","0","0"],["76187","0.00011911","5"]]}
{"instId":"BTC-USDT","action":"update","ts":"1776816005440","asks":[["76401.4","0.17733526","1"],["76401.5","0.47151308","1"],["76473.5","0","0"]],"bids":[["76372.4","0.27804849","12"],["76366.9","0","0"],["76186.4","0.00022771","1"]]}
{"instId":"BTC-USDT","action":"update","ts":"1776816005450","asks":[["76402.8","0.06565777","2"]],"bids":[["76372.4","0.27774849","11"],["76371.8","0","0"],["76368.8","0.0471883","2"],["76367","0.10571812","1"],["76186","0.00170529","1"]]}
{"instId":"BTC-USDT","action":"update","ts":"1776816005460","asks":[],"bids":[["76368.9","0.01413456","1"],["76352.2","1.4771113","2"],["76349.8","0.15511138","3"],["76334.5","0","0"]]}
{"instId":"BTC-USDT","action":"update","ts":"1776816005470","asks":[["76387.8","0.10611863","1"]],"bids":[["76341.8","0.15917794","2"],["76274.8","0.20378297","2"]]}
{"instId":"BTC-USDT","action":"update","ts":"1776816005480","asks":[["76403.1","0.15917793","3"]],"bids":[["76341.8","0.21095284","3"]]}
{"instId":"BTC-USDT","action":"update","ts":"1776816005490","asks":[["76387.8","0","0"],["76435.4","0.00003966","1"]],"bids":[]}
{"instId":"BTC-USDT","action":"update","ts":"1776816005500","asks":[],"bids":[["76372.4","0.32084849","12"],["76341.8","0.15917794","2"]]}
{"instId":"BTC-USDT","action":"update","ts":"1776816005510","asks":[["76403.1","0.26529656","4"]],"bids":[]}
{"instId":"BTC-USDT","action":"update","ts":"1776816005520","asks":[["76402.8","0.10975947","1"],["76403.1","0.15917793","3"]],"bids":[["76372.4","0.32032977","12"],["76357.1","0.10265203","2"]]}
{"instId":"BTC-USDT","action":"update","ts":"1776816005530","asks":[["76375","0","0"],["76387.8","0.10611863","1"]],"bids":[["76334.5","0.00002865","1"],["76186","0","0"]]}
{"instId":"BTC-USDT","action":"update","ts":"1776816005540","asks":[["76372.5","0.38583444","12"],["76374.9","0.00001316","1"],["76403.1","0.10611862","2"]],"bids":[["76357.1","0","0"],["76352.4","0.32726299","1"],["76186","0.00170529","1"]]}
{"instId":"BTC-USDT","action":"update","ts":"1776816005550","asks":[["76387.8","0.15917794","2"],["76402.8","0.07063907","1"]],"bids":[["76357.1","0.05087713","1"],["76341.8","0.21095284","3"],["76186","0","0"]]}
{"instId":"BTC-USDT","action":"update","ts":"1776816005560","asks":[],"bids":[["76355.4","0.32726318","1"],["76352.4","0","0"]]}
{"instId":"BTC-USDT","action":"update","ts":"1776816005570","asks":[],"bids":[["76334.5","0","0"],["76331.3","0.0649328","1"],["76310","0.26700479","2"]]}
{"instId":"BTC-USDT","action":"update","ts":"1776816005580","asks":[],"bids":[["76337.7","0.08381571","2"],["76306.7","0.00037535","2"],["76237.3","0","0"],["76186","0.00170529","1"]]}
{"instId":"BTC-USDT","action":"update","ts":"1776816005590","asks":[["76407.8","0.06394599","1"],["76473.3","0","0"]],"bids":[]}
{"instId":"BTC-USDT","action":"update","ts":"1776816005630","asks":[],"bids":[["76310.1","0.00323266","1"],["76186","0","0"]]}
{"instId":"BTC-USDT","action":"update","ts":"1776816005640","asks":[],"bids":[["76355.1","0.03605663","3"],["76351.3","0.00004629","1"],["76347.5","0.00004629","1"],["76343.7","0.00004629","1"],["76339.9","0.00004629","1"],["76336","0.00004629","1"],["76332.2","0.47155937","2"],["76328.4","0.0000463","1"],["76324.6","0.00005946","2"],["76320.8","0.0000463","1"]]}
{"instId":"BTC-USDT","action":"update","ts":"1776816005660","asks":[],"bids":[["76355.1","0.03604629","2"],["76349.8","0.15510104","2"],["76344.5","0","0"],["76339.2","0","0"],["76334.5","0.00002865","1"],["76333.9","0","0"],["76328.6","0.12385098","2"],["76323.3","0","0"],["76186","0.00170529","1"],["76185.3","0.00002512","1"],["76184.8","0.01614584","1"]]}
{"instId":"BTC-USDT","action":"update","ts":"1776816005680","asks":[],"bids":[["76337.7","0.08378297","1"]]}
{"instId":"BTC-USDT","action":"update","ts":"1776816005690","asks":[],"bids":[["76306.7","0.00001501","1"]]}
{"instId":"BTC-USDT","action":"update","ts":"1776816005710","asks":[],"bids":[["76334.5","0","0"],["76310.1","0","0"],["76184.2","3.72","1"],["76184.1","0.47151308","1"]]}
{"instId":"BTC-USDT","action":"update","ts":"1776816005740","asks":[["76403.1","0.05305931","1"]],"bids":[["76357.1","0","0"],["76183.9","0.00003806","1"]]}
{"instId":"BTC-USDT","action":"update","ts":"1776816005750","asks":[["76387.8","0.21223725","3"]],"bids":[["76341.8","0.26182997","4"],["76339.3","0.0004328","2"],["76308.6","0.08411055","2"],["76184","0.1305","1"],["76183.9","0","0"]]}
{"instId":"BTC-USDT","action":"update","ts":"1776816005760","asks":[],"bids":[["76372.4","0.32040353","13"],["76368.6","0.00023743","5"],["76364.8","0.169766","7"],["76361","0.00023744","5"],["76357.2","0.26421411","8"],["76353.3","0.00023744","5"],["76349.5","0.00023744","5"],["76345.7","0.56384355","7"],["76341.9","0.12544227","6"],["76338.1","0.00025064","6"],["76310.1","0.00323266","1"],["76184","0","0"]]}
{"instId":"BTC-USDT","action":"update","ts":"1776816005770","asks":[],"bids":[["76372.4","0.32041387","14"],["76367.1","0.00001034","1"],["76361.8","0.00001034","1"],["76356.5","0.00001034","1"],["76351.2","0.08118414","3"],["76345.9","0.08379332","2"],["76340.6","0.00001035","1"],["76185.3","0","0"],["76184.8","0","0"],["76184.2","0","0"],["76184.1","0","0"]]}
{"instId":"BTC-USDT","action":"update","ts":"1776816005790","asks":[["76403.1","0","0"],["76473.3","0.00564466","1"]],"bids":[]}
{"instId":"BTC-USDT","action":"update","ts":"1776816005800","asks":[["76372.5","0.38563804","12"],["76402.8","0.03896266","1"],["76403.1","0.05305931","1"],["76473.3","0","0"]],"bids":[]}
{"instId":"BTC-USDT","action":"update","ts":"1776816005830","asks":[],"bids":[["76334.5","0.00002865","1"],["76186","0","0"]]}
{"instId":"BTC-USDT","action":"update","ts":"1776816005850","asks":[["76399.5","0","0"],["76473.3","0.00564466","1"]],"bids":[]}
{"instId":"BTC-USDT","action":"update","ts":"1776816005860","asks":[],"bids":[["76244.9","0.00006816","1"],["76186.4","0","0"]]}
{"instId":"BTC-USDT","action":"update","ts":"1776816005870","asks":[],"bids":[["76277.6","0.00004592","2"]]}
{"instId":"BTC-USDT","action":"update","ts":"1776816005900","asks":[],"bids":[["76352.1","0","0"],["76186.4","0.00022771","1"]]}
{"instId":"BTC-USDT","action":"update","ts":"1776816005910","asks":[["76399.5","0.01521695","1"],["76473.3","0","0"]],"bids":[]}
{"instId":"BTC-USDT","action":"update","ts":"1776816005920","asks":[],"bids":[["76367.1","0.12001034","2"]]}
{"instId":"BTC-USDT","action":"update","ts":"1776816005960","asks":[["76372.5","0.36623804","11"]],"bids":[["76372.4","0.35262876","15"]]}
{"instId":"BTC-USDT","action":"update","ts":"1776816005970","asks":[["76387.8","0.15917794","2"],["76387.9","0","0"],["76391.5","0.00654521","1"],["76397.1","0","0"],["76473.3","0.00564466","1"]],"bids":[["76362.2","0.00654457","1"],["76360","0.00001033","1"],["76354.4","0.00654521","1"],["76353.4","0","0"],["76341.8","0.21095284","3"],["76186.4","0","0"]]}
{"instId":"BTC-USDT","action":"update","ts":"1776816005980","asks":[["76403.1","0.10611862","2"]],"bids":[["76362.2","0.10654457","2"],["76362","0","0"],["76357.1","0.05087713","1"]]}
{"instId":"BTC-USDT","action":"update","ts":"1776816005990","asks":[["76402.8","0.06565777","2"]],"bids":[["76362.2","0.1","1"],["76360","0.00655481","2"]]}
{"instId":"BTC-USDT","action":"update","ts":"1776816006000","asks":[["76372.5","0.36492867","11"]],"bids":[]}
{"instId":"BTC-USDT","action":"update","ts":"1776816006010","asks":[["76372.5","0.31769171","10"],["76386.8","0","0"],["76387.4","0.32725932","1"]],"bids":[["76354.4","0","0"],["76354.3","0.00959517","2"],["76186.4","0.00022771","1"]]}
{"instId":"BTC-USDT","action":"update","ts":"1776816006030","asks":[["76380.4","0.0005985","1"],["76473.3","0","0"]],"bids":[["76357.1","0","0"],["76186","0.00170529","1"]]}
{"instId":"BTC-USDT","action":"update","ts":"1776816006040","asks":[["76403.1","0.05305931","1"]],"bids":[["76341.8","0.26182997","4"]]}
{"instId":"BTC-USDT","action":"update","ts":"1776816006050","asks":[["76386.8","0.32725782","1"],["76387.4","0","0"],["76403.1","0","0"],["76473.3","0.00564466","1"]],"bids":[]}
{"instId":"BTC-USDT","action":"update","ts":"1776816006060","asks":[["76386.8","0","0"],["76387.3","0.32725786","1"],["76387.8","0.26529656","4"],["76402.8","0.03896266","1"]],"bids":[]}
{"instId":"BTC-USDT","action":"update","ts":"1776816006070","asks":[["76372.5","0.31571171","9"],["76372.8","0.0471715","1"],["76473.3","0","0"]],"bids":[["76372.4","0.37535892","18"],["76362.3","0.00654441","1"],["76360","0.00001033","1"],["76186","0","0"]]}
{"instId":"BTC-USDT","action":"update","ts":"1776816006080","asks":[["76381.6","0","0"],["76381.9","0.00654441","1"]],"bids":[["76362.3","0.10654441","2"],["76362.1","0","0"],["76186","0.00170529","1"]]}
