{"instId":"BTC-USDT","action":"update","ts":"1776816034510","asks":[["76330.5","0","0"],["76341","0.00045056","1"],["76343","0","0"],["76343.7","0","0"],["76347.5","0","0"],["76348.1","0.00001316","1"],["76348.2","0","0"],["76350.2","0.01309","1"],["76352.2","0","0"],["76353.8","0.47151308","1"],["76353.9","0.55215394","1"],["76354","0","0"],["76355.5","0","0"],["76355.6","0","0"],["76356.3","0","0"],["76359.5","0.16032871","1"],["76361.8","0","0"],["76365.6","1.00615154","1"],["76369.1","0","0"],["76377.5","0","0"],["76386.6","0.02618885","1"],["76395.9","0.10672476","1"],["76462.5","0.00001257","1"],["76462.6","0.47226231","9"],["76463","0.00004357","1"],["76463.1","0.00001427","1"],["76463.2","0.00059244","1"],["76463.3","0.08378297","1"],["76463.4","0.00010604","1"],["76463.9","0.00088649","6"]],"bids":[["76331.7","1.00971954","15"],["76330.5","0.71523084","1"],["76330.4","4.92306415","7"],["76329.4","0.1","1"],["76329.3","0.00654836","1"],["76329.2","0.19563","2"],["76328.2","0","0"],["76325.8","0.23131586","2"],["76323.8","0.03","2"],["76323.3","0.00003373","1"],["76323.2","0.327432","1"],["76322.5","0.12185618","1"],["76322.4","0.00001086","1"],["76322.3","0","0"],["76321.7","0.00656358","2"],["76320.2","0","0"],["76318.1","0.47151308","1"],["76293.7","0","0"],["76285.5","0.11931305","1"],["76257.5","0","0"],["76256","0.00013114","1"],["76248.9","0","0"],["76247.4","0.00055534","2"],["76164.3","0","0"]]}
{"instId":"BTC-USDT","action":"update","ts":"1776816034520","asks":[["76331.8","0","0"],["76337.2","0","0"],["76338","0","0"],["76339.3","0.10275964","7"],["76341.3","0","0"],["76342","0","0"],["76347.4","0","0"],["76349.6","0.0608146","1"],["76353.5","0","0"],["76353.9","0","0"],["76354.1","0","0"],["76356.4","0.1305","1"],["76361.7","0","0"],["76364.5","0.15641463","1"],["76368.8","0","0"],["76369","0","0"],["76372.9","0.00013117","1"],["76375.4","0.11666164","1"],["76384.4","0.14411024","1"],["76385.8","0.05240372","1"],["76464.1","0.00005359","1"],["76464.2","0.0025747","2"],["76464.4","0.00019338","3"],["76464.6","0.00012165","3"],["76464.7","0.00497942","3"],["76464.8","0.000655","1"],["76465","0.00044","2"],["76465.1","0.00002105","1"],["76465.5","0.01327746","9"]],"bids":[["76339.2","0.86595389","15"],["76337.9","0.00411249","2"],["76337.1","0.25314631","2"],["76331.7","5.13957158","9"],["76330.5","0.1","1"],["76330.4","0.1","1"],["76329.4","0.15896264","2"],["76329.3","0","0"],["76328.2","0.32743202","1"],["76328.1","0.036","1"],["76325.7","0.53665191","3"],["76323.9","0.00654793","1"],["76323.2","0","0"],["76323.1","0","0"],["76322.5","0","0"],["76321.7","0.000015","1"],["76319.7","0","0"],["76317.2","0","0"],["76309.9","0.01550307","1"],["76308.1","0","0"],["76307.8","0","0"],["76301.9","0.00305","1"],["76296.4","0","0"],["76293.6","0.02618711","1"],["76290.7","0.00001034","1"],["76285.9","0.00652851","1"],["76280.5","0.01917448","1"],["76245.7","0.20472245","1"],["76240.2","0","0"],["76237.9","0.14664584","2"],["76235.5","0","0"],["76189.8","0.01468486","1"],["76164.3","0.00046091","2"],["76163.9","0.00005592","3"]]}
{"instId":"BTC-USDT","action":"update","ts":"1776816034530","asks":[["76339.3","0.41789973","10"],["76342.9","0.00002172","1"],["76343.4","0","0"],["76345.9","0.000084","1"],["76349.5","0.103579","1"],["76356","0","0"],["76359","0.07938033","2"],["76364.6","0","0"],["76364.8","0.0016956","2"],["76368.9","0","0"],["76375.8","0.08378297","1"],["76375.9","0.53871552","1"],["76416.8","0.00019321","1"],["76465","0","0"],["76465.1","0","0"],["76465.5","0","0"]],"bids":[["76339.2","0.75359068","15"],["76337.9","0.1","1"],["76335.8","0.0118827","1"],["76331.7","0.56509426","7"],["76331.5","0.01614584","1"],["76329.5","0.32739981","1"],["76329.2","0.09563","1"],["76328.3","0.00654774","1"],["76328.2","0","0"],["76325.9","0.47151308","1"],["76323.9","0","0"],["76321.4","0.47151308","1"],["76308.1","0.13255477","1"],["76307.8","0.11929929","1"],["76300.6","0.1166482","1"],["76296.4","0.12460148","1"],["76290","0.11929929","1"],["76278.7","0.00325279","1"],["76275.8","0.00233664","1"],["76275.7","0","0"],["76271","0","0"],["76167","0","0"],["76166.6","0","0"],["76166.2","0","0"],["76165.9","0","0"],["76165.8","0","0"],["76165.2","0","0"],["76165.1","0","0"],["76164.3","0","0"],["76163.9","0","0"]]}
{"instId":"BTC-USDT","action":"update","ts":"1776816034540","asks":[["76340.6","0.00002068","1"],["76344","0.01268627","1"],["76349.4","0.03091833","1"],["76353.7","0.18283387","1"],["76359.4","1.00615154","1"],["76364.8","0.00223634","3"],["76365.2","0.08378297","1"],["76366.3","0.00007241","1"],["76367","0.09838042","2"],["76369.2","0.08378297","1"],["76463.4","0","0"],["76463.9","0","0"],["76464.1","0","0"],["76464.2","0","0"],["76464.4","0","0"],["76464.6","0","0"],["76464.7","0","0"],["76464.8","0","0"]],"bids":[["76339.2","0.87631068","17"],["76337.1","0.09563","1"],["76331.8","0.00654707","1"],["76331.7","0.36615152","4"],["76331.5","0","0"],["76329.4","0.05896264","1"],["76328.3","0","0"],["76326.5","0.0065477","1"],["76325.8","0","0"],["76321.9","0.10851001","3"],["76318.2","0.11929929","1"],["76315.7","0","0"],["76314.8","0.1166482","1"],["76314.1","0.13355","2"],["76309.9","0","0"],["76304.2","0","0"],["76280.4","0.00325279","1"],["76278.7","0","0"],["76277.7","0.00233664","1"],["76275.8","0","0"],["76211.3","0.00514662","1"],["76167","0.00001319","1"],["76166.6","0.00248493","6"]]}
{"instId":"BTC-USDT","action":"update","ts":"1776816034550","asks":[["76341.4","0.00002066","1"],["76344.4","0.00002309","1"],["76349.4","0.17407748","2"],["76359.3","0.46106501","2"],["76359.5","0","0"],["76365","0.00040631","1"],["76367","0.0984728","3"],["76463.2","0","0"],["76463.3","0","0"]],"bids":[["76337.1","0.19563","2"],["76331.8","0.006547","1"],["76330.4","0","0"],["76329.6","0.32738818","1"],["76329.5","0","0"],["76327.8","0.0262","1"]]}
{"instId":"BTC-USDT","action":"update","ts":"1776816034560","asks":[["76339.3","0.32559973","8"],["76349.3","0.07365134","1"],["76349.4","0.14315915","1"],["76354.6","0.26517365","4"],["76388.5","0.00227956","1"],["76462.6","0","0"],["76463","0","0"],["76463.1","0","0"]],"bids":[["76335.8","0.1118827","2"],["76330.5","0","0"],["76330.4","0.13354324","1"],["76308.6","0.26155956","4"],["76166.6","0","0"]]}
{"instId":"BTC-USDT","action":"update","ts":"1776816034570","asks":[["76339.3","0.38809973","9"],["76347.6","0.01","1"],["76349.2","0.14050806","1"],["76349.5","0","0"],["76350.7","0.47151308","1"],["76351.1","0","0"],["76355","0.00654686","1"],["76357.2","0.07888","1"],["76358.1","0.11666136","2"],["76358.6","0.32737167","1"],["76360","0.05905885","3"],["76362.6","0.00654737","1"],["76367.6","0.00001501","1"],["76372.9","0.14063923","2"],["76378.2","0.11200364","1"],["76384.4","0","0"],["76395.8","0.10473368","1"],["76395.9","0","0"],["76461.7","0","0"],["76462","0","0"],["76462.2","0","0"],["76462.3","0","0"],["76462.5","0","0"]],"bids":[["76339.2","0.76628524","13"],["76329.6","0.0026191","1"],["76329.4","0","0"],["76326.4","0","0"],["76326","0.32737167","1"],["76308.7","0.1166482","1"],["76307.8","0","0"],["76288.7","0.00002864","1"],["76284.2","0.0023475","2"],["76277.7","0","0"],["76166.6","0.00248493","6"]]}
{"instId":"BTC-USDT","action":"update","ts":"1776816034580","asks":[["76349.1","0.08467466","1"],["76349.3","0","0"],["76359.5","0.00654765","1"],["76362.6","0","0"],["76371.2","0.12195039","1"],["76373.6","0","0"],["76375.4","0","0"],["76380.4","0.11929929","1"],["76384.5","0","0"],["76387.5","0","0"],["76390.4","0.14317415","2"],["76391.4","0","0"],["76395.8","0","0"],["76461.7","0.00001025","1"],["76462","0.00002228","1"],["76462.2","0.00551437","1"],["76462.3","0.00027227","4"]],"bids":[["76335.8","0.1","1"],["76329.6","0","0"],["76327.3","0.00261918","1"],["76326.5","0","0"],["76323.9","0.00654765","1"],["76288.5","0.00325279","1"],["76286.5","0.00233666","1"],["76284.2","0.00001086","1"],["76280.4","0","0"],["76166.6","0","0"]]}
{"instId":"BTC-USDT","action":"update","ts":"1776816034590","asks":[["76339.3","0.54809973","10"],["76345.8","0.16","1"],["76349","0.13520586","1"],["76349.4","0","0"],["76349.6","0.1565884","2"],["76372.9","0.00013117","1"],["76375.7","0.13520586","1"],["76381.9","0","0"],["76384.5","0.1166482","1"],["76388.6","0","0"],["76393.9","0.00003978","1"],["76395.9","0.1064453","1"],["76462","0","0"],["76462.2","0","0"],["76462.3","0","0"]],"bids":[["76330.8","0.01188347","1"],["76322.9","0.116665","2"],["76291.4","0.00131076","1"],["76283.6","0.00001033","1"],["76266.2","0.00323383","1"],["76263.2","0","0"],["76168.4","0","0"],["76167","0","0"]]}
{"instId":"BTC-USDT","action":"update","ts":"1776816034600","asks":[["76345.7","0.04776","1"],["76349.1","0","0"]],"bids":[["76323.3","0","0"],["76168.4","0.00011049","4"]]}
{"instId":"BTC-USDT","action":"update","ts":"1776816034610","asks":[["76348.9","0.08230061","1"],["76359.5","0.09033062","2"],["76416.8","0","0"]],"bids":[["76336.8","0.00003958","1"],["76330.4","0","0"],["76280.6","0.00001199","1"],["76274.2","0.00019775","1"],["76273.5","0","0"],["76263.7","0","0"],["76247.4","0.00055536","2"]]}
{"instId":"BTC-USDT","action":"update","ts":"1776816034620","asks":[["76339.3","0.48821961","10"],["76348.8","0.1298807","1"],["76349.2","0","0"],["76353.7","0.26411318","2"],["76393.9","0","0"],["76395.9","0.00003978","1"],["76462","0.00002228","1"]],"bids":[["76338","0.11810737","1"],["76269.3","0.07475238","7"],["76266.2","0","0"]]}
{"instId":"BTC-USDT","action":"update","ts":"1776816034630","asks":[["76348.7","0.07912834","1"],["76348.9","0","0"],["76364.8","0.00054074","1"],["76395.9","0.10566854","1"],["76402.7","0.00003978","1"],["76462","0","0"]],"bids":[["76331.8","0.11939044","2"],["76290.7","0.11472616","2"],["76285.5","0","0"],["76276.3","0.00324892","2"],["76269.3","0.07151847","6"],["76167","0.00001319","1"]]}
{"instId":"BTC-USDT","action":"update","ts":"1776816034640","asks":[["76349","0","0"],["76364.8","0","0"],["76365.5","0.47728158","1"],["76365.7","0","0"],["76366.4","0.01532717","1"],["76462","0.00002228","1"]],"bids":[["76329.3","0.04789408","1"],["76315.5","0.08158165","2"],["76167","0","0"]]}
{"instId":"BTC-USDT","action":"update","ts":"1776816034650","asks":[["76348.7","0.03876939","1"],["76353.6","0.00654716","1"],["76355","0","0"],["76367","0.09838042","2"]],"bids":[["76331.8","0.11284344","1"],["76331.3","0.05896264","1"],["76330.9","0.00654716","1"],["76326.1","0.40958752","1"],["76168.9","0","0"],["76168.6","0","0"],["76168.4","0","0"]]}
{"instId":"BTC-USDT","action":"update","ts":"1776816034660","asks":[["76350.6","0.00654716","1"],["76353.6","0","0"],["76356.3","0.32739172","1"],["76358.5","0.00654778","1"],["76358.6","0","0"],["76359.5","0.08378297","1"],["76462","0","0"]],"bids":[["76326","0","0"],["76323.9","0","0"],["76323","0.33395105","3"],["76322","0.18014451","1"],["76168.9","0.000015","1"]]}
{"instId":"BTC-USDT","action":"update","ts":"1776816034670","asks":[["76339.3","0.39071961","10"],["76349.9","0.04254716","2"],["76350.6","0","0"],["76396.3","0.1","1"],["76412.7","0.00093689","1"],["76416.4","0.97422782","1"],["76461.6","0","0"],["76461.7","0","0"]],"bids":[["76330.9","0","0"],["76329.5","0.00001501","1"],["76329.4","0.00654716","1"],["76168.9","0","0"]]}
{"instId":"BTC-USDT","action":"update","ts":"1776816034680","asks":[["76348.7","0.14328138","2"],["76371.7","0","0"],["76400.9","1.92329975","1"],["76416.1","0.00002075","1"],["76416.5","0","0"],["76437.4","0.16987951","2"]],"bids":[["76295.2","0.08378297","1"]]}
{"instId":"BTC-USDT","action":"update","ts":"1776816034690","asks":[["76402.7","0","0"],["76416.4","0","0"],["76461.6","0.00332668","1"],["76461.7","0.00001025","1"]],"bids":[["76314.7","0","0"],["76168.9","0.000015","1"]]}
{"instId":"BTC-USDT","action":"update","ts":"1776816034700","asks":[],"bids":[["76336.8","0.00005265","2"],["76291.6","0.00002864","1"],["76288.7","0","0"]]}
{"instId":"BTC-USDT","action":"update","ts":"1776816034710","asks":[],"bids":[["76292.8","0.00002864","1"],["76291.6","0","0"],["76262.1","0.00013113","1"],["76256","0","0"],["76253.5","0.49987952","3"],["76247.4","0.00001316","1"]]}
{"instId":"BTC-USDT","action":"update","ts":"1776816034720","asks":[["76364.8","0.00136106","2"],["76461.7","0","0"]],"bids":[]}
{"instId":"BTC-USDT","action":"update","ts":"1776816034730","asks":[["76364.8","0.00181168","3"]],"bids":[["76293.8","0.00002864","1"],["76292.8","0","0"]]}
{"instId":"BTC-USDT","action":"update","ts":"1776816034740","asks":[],"bids":[["76298.9","0.00002864","1"],["76293.8","0","0"]]}
{"instId":"BTC-USDT","action":"update","ts":"1776816034750","asks":[["76344.4","0","0"],["76367","0.09844971","3"],["76461.7","0.00001025","1"]],"bids":[["76298.9","0","0"],["76276.3","0.00001501","1"],["76168.4","0.00011049","4"]]}
{"instId":"BTC-USDT","action":"update","ts":"1776816034760","asks":[],"bids":[["76168.6","0.1305","1"],["76168.4","0","0"]]}
{"instId":"BTC-USDT","action":"update","ts":"1776816034770","asks":[["76395.7","1.92417962","1"],["76400.9","0","0"]],"bids":[]}
{"instId":"BTC-USDT","action":"update","ts":"1776816034780","asks":[["76402.7","0.00003978","1"],["76461.7","0","0"]],"bids":[]}
{"instId":"BTC-USDT","action":"update","ts":"1776816034800","asks":[["76402.7","0","0"],["76461.7","0.00001025","1"]],"bids":[["76276.3","0.00324889","2"]]}
{"instId":"BTC-USDT","action":"update","ts":"1776816034820","asks":[["76339.3","0.32862791","11"],["76364.8","0.00045062","1"]],"bids":[]}
{"instId":"BTC-USDT","action":"update","ts":"1776816034830","asks":[["76339.3","0.32868593","12"],["76364.8","0","0"],["76462","0.00002228","1"]],"bids":[]}
{"instId":"BTC-USDT","action":"update","ts":"1776816034840","asks":[["76339.3","0.32882111","13"]],"bids":[]}
{"instId":"BTC-USDT","action":"update","ts":"1776816034850","asks":[["76339.3","0.3289319","14"],["76344.4","0.00002309","1"],["76365","0","0"],["76402.7","0.00003978","1"],["76462","0","0"]],"bids":[]}
{"instId":"BTC-USDT","action":"update","ts":"1776816034860","asks":[],"bids":[["76302.5","0.00002863","1"],["76168.6","0","0"]]}
{"instId":"BTC-USDT","action":"update","ts":"1776816034870","asks":[],"bids":[["76315.5","0.06550532","1"]]}
{"instId":"BTC-USDT","action":"update","ts":"1776816034900","asks":[["76339.3","0.32863991","14"]],"bids":[]}
{"instId":"BTC-USDT","action":"update","ts":"1776816034910","asks":[["76419.8","0.00019321","1"],["76461.7","0","0"]],"bids":[]}
{"instId":"BTC-USDT","action":"update","ts":"1776816034920","asks":[["76339.3","0.32845289","13"],["76419.8","0","0"],["76461.7","0.00001025","1"]],"bids":[["76293.9","0.00131072","1"],["76277.6","0.00001316","1"],["76168.9","0","0"]]}
{"instId":"BTC-USDT","action":"update","ts":"1776816034950","asks":[["76339.3","0.3283421","12"]],"bids":[]}
{"instId":"BTC-USDT","action":"update","ts":"1776816034970","asks":[["76377.7","0.06507037","1"],["76461.7","0","0"]],"bids":[]}
{"instId":"BTC-USDT","action":"update","ts":"1776816034980","asks":[["76348.6","0.06996622","1"],["76348.7","0.10451199","1"],["76461.6","0","0"]],"bids":[]}
{"instId":"BTC-USDT","action":"update","ts":"1776816035010","asks":[["76339.3","0.32852912","13"],["76425.1","0","0"],["76461.6","0.00332668","1"]],"bids":[]}
{"instId":"BTC-USDT","action":"update","ts":"1776816035050","asks":[["76339.3","0.32863991","14"]],"bids":[]}
{"instId":"BTC-USDT","action":"update","ts":"1776816035080","asks":[],"bids":[["76208.4","0","0"],["76181.4","0.001571","1"]]}
{"instId":"BTC-USDT","action":"update","ts":"1776816035130","asks":[],"bids":[["76301.3","0.06409442","1"],["76170.2","0","0"]]}
{"instId":"BTC-USDT","action":"update","ts":"1776816035170","asks":[],"bids":[["76280.3","0.00346789","4"],["76265.1","0.00005018","1"],["76170.8","0","0"]]}
{"instId":"BTC-USDT","action":"update","ts":"1776816035190","asks":[],"bids":[["76285","0","0"],["76170.8","0.00003094","3"]]}
{"instId":"BTC-USDT","action":"update","ts":"1776816035200","asks":[["76339.3","0.32864991","15"],["76357.1","0.00654754","1"],["76358.5","0","0"]],"bids":[["76323","0.32740327","2"],["76322.1","0.00654754","1"],["76286","0.04456141","1"],["76170.8","0","0"]]}
{"instId":"BTC-USDT","action":"update","ts":"1776816035210","asks":[["76339.3","0.33126875","16"]],"bids":[]}
{"instId":"BTC-USDT","action":"update","ts":"1776816035250","asks":[["76345.8","0","0"],["76461.7","0.00001025","1"]],"bids":[["76339.2","0.7662738","12"],["76331.4","0.00001316","1"],["76328","0.00001316","1"],["76173","0","0"],["76171.1","0","0"]]}
{"instId":"BTC-USDT","action":"update","ts":"1776816035260","asks":[["76345.7","0","0"],["76462","0.00002228","1"]],"bids":[["76237.9","2.06087373","4"]]}
{"instId":"BTC-USDT","action":"update","ts":"1776816035280","asks":[],"bids":[["76288","0.1","1"],["76173.2","0","0"]]}
{"instId":"BTC-USDT","action":"update","ts":"1776816035290","asks":[],"bids":[["76330.8","0","0"],["76173.2","0.00001006","1"]]}
{"instId":"BTC-USDT","action":"update","ts":"1776816035300","asks":[],"bids":[["76333.3","0.01188309","1"],["76173.2","0","0"]]}
{"instId":"BTC-USDT","action":"update","ts":"1776816035310","asks":[["76430.3","0.70029606","4"]],"bids":[["76323.6","0.11928853","2"],["76314.8","0","0"],["76309.4","0.13784291","2"],["76308.1","0","0"],["76290","0","0"],["76253.5","0.49987953","3"],["76173.2","0.00001006","1"],["76173","0.00001059","1"],["76171.1","0.00001024","1"]]}
{"instId":"BTC-USDT","action":"update","ts":"1776816035500","asks":[["76339.3","0.39376875","17"]],"bids":[]}
{"instId":"BTC-USDT","action":"update","ts":"1776816035510","asks":[["76344","0","0"],["76462.2","0.00551437","1"]],"bids":[]}
{"instId":"BTC-USDT","action":"update","ts":"1776816035520","asks":[["76341.8","0.01268664","1"],["76348.8","0","0"],["76353.6","0.1298807","1"],["76462.2","0","0"]],"bids":[]}
{"instId":"BTC-USDT","action":"update","ts":"1776816035530","asks":[["76348.6","0.03119683","1"],["76358.7","0","0"],["76369.1","0.12457945","1"]],"bids":[]}
{"instId":"BTC-USDT","action":"update","ts":"1776816035560","asks":[],"bids":[["76321","0.01577949","1"],["76171.1","0","0"]]}
{"instId":"BTC-USDT","action":"update","ts":"1776816035580","asks":[],"bids":[["76331.9","0.16","1"],["76173","0","0"]]}
{"instId":"BTC-USDT","action":"update","ts":"1776816035590","asks":[["76339.3","0.45816875","18"]],"bids":[["76332","0.17466051","1"],["76331.9","0","0"],["76331.8","0","0"],["76173","0.00001059","1"]]}
{"instId":"BTC-USDT","action":"update","ts":"1776816035600","asks":[],"bids":[["76332","0.12690051","1"]]}
{"instId":"BTC-USDT","action":"update","ts":"1776816035630","asks":[["76348.5","0.00654689","1"],["76349.9","0.036","1"],["76462","0","0"]],"bids":[["76329.4","0","0"],["76328.2","0.00654689","1"]]}
{"instId":"BTC-USDT","action":"update","ts":"1776816035640","asks":[["76369.2","0.3485246","2"]],"bids":[["76322.9","0.0000168","1"]]}
{"instId":"BTC-USDT","action":"update","ts":"1776816035660","asks":[],"bids":[["76291.4","0.10662322","2"]]}
{"instId":"BTC-USDT","action":"update","ts":"1776816035670","asks":[],"bids":[["76326.2","0.11213725","1"],["76173","0","0"]]}
{"instId":"BTC-USDT","action":"update","ts":"1776816035690","asks":[["76348.5","0","0"],["76349.5","0.0065469","1"]],"bids":[["76329.4","0.0065469","1"],["76328.2","0","0"]]}
{"instId":"BTC-USDT","action":"update","ts":"1776816035700","asks":[["76348.4","0.00654689","1"],["76349.5","0","0"],["76354.5","0.32738135","1"],["76356.3","0","0"]],"bids":[["76329.4","0","0"],["76328.3","0.00654689","1"],["76323","0.00001155","1"],["76322.1","0.33392889","2"]]}
{"instId":"BTC-USDT","action":"update","ts":"1776816035710","asks":[],"bids":[["76322.2","0.28453246","1"],["76322","0","0"],["76302.5","0","0"],["76173","0.00001059","1"]]}
{"instId":"BTC-USDT","action":"update","ts":"1776816035750","asks":[],"bids":[["76211.3","0","0"],["76171.1","0.00001024","1"]]}
{"instId":"BTC-USDT","action":"update","ts":"1776816035820","asks":[],"bids":[["76302.5","0.00002864","1"],["76171.1","0","0"]]}
{"instId":"BTC-USDT","action":"update","ts":"1776816035890","asks":[],"bids":[["76339.2","0.76587604","12"]]}
{"instId":"BTC-USDT","action":"update","ts":"1776816036010","asks":[["76348.4","0","0"],["76348.5","0.00654691","1"],["76356.3","0.00654758","1"],["76357.1","0","0"]],"bids":[["76329.3","0.05444099","2"],["76328.3","0","0"],["76322.3","0.32738203","1"],["76322.1","0","0"],["76321.7","0.00656258","2"],["76171.1","0.00001024","1"]]}
{"instId":"BTC-USDT","action":"update","ts":"1776816036020","asks":[],"bids":[["76322.4","0.28454353","2"],["76322.2","0","0"],["76225.9","0.00514563","1"]]}
{"instId":"BTC-USDT","action":"update","ts":"1776816036030","asks":[],"bids":[["76322.5","0.32738206","1"],["76322.3","0","0"]]}
{"instId":"BTC-USDT","action":"update","ts":"1776816036040","asks":[],"bids":[["76322.6","0.28453592","1"],["76322.4","0.00001086","1"],["76171.1","0","0"]]}
{"instId":"BTC-USDT","action":"update","ts":"1776816036070","asks":[],"bids":[["76246.4","0.12","1"],["76173","0","0"]]}
{"instId":"BTC-USDT","action":"update","ts":"1776816036080","asks":[],"bids":[["76275.6","0","0"],["76173","0.00001059","1"]]}
{"instId":"BTC-USDT","action":"update","ts":"1776816036090","asks":[["76348.5","0","0"],["76349.5","0.00654694","1"],["76354.5","0","0"],["76356.3","0.32738217","1"],["76357.1","0.00654758","1"]],"bids":[["76329.4","0.00654694","1"],["76329.3","0.04789408","1"],["76323.7","0.32738217","1"],["76322.5","0","0"],["76322","0.00654758","1"],["76321.7","0.000015","1"],["76173.2","0","0"],["76173","0","0"]]}
{"instId":"BTC-USDT","action":"update","ts":"1776816036100","asks":[],"bids":[["76322.6","0.18681238","1"],["76321.9","0.00306501","2"]]}
{"instId":"BTC-USDT","action":"update","ts":"1776816036190","asks":[["76393.1","1.92417962","1"],["76395.7","0","0"]],"bids":[["76288","0","0"],["76173.2","0.00001006","1"]]}
{"instId":"BTC-USDT","action":"update","ts":"1776816036200","asks":[["76392.7","0.68162855","2"]],"bids":[]}
{"instId":"BTC-USDT","action":"update","ts":"1776816036210","asks":[],"bids":[["76339.2","0.76613455","13"]]}
{"instId":"BTC-USDT","action":"update","ts":"1776816036220","asks":[],"bids":[["76280.8","0.65944044","6"]]}
{"instId":"BTC-USDT","action":"update","ts":"1776816036260","asks":[],"bids":[["76334.7","0.00001316","1"],["76324.6","0.00005946","2"],["76173.2","0","0"]]}
{"instId":"BTC-USDT","action":"update","ts":"1776816036270","asks":[],"bids":[["76318.2","0.60594505","2"],["76311.2","0.11665417","2"],["76308.7","0","0"],["76301.9","0.13029474","2"],["76290.7","0.00001034","1"],["76173.2","0.00001006","1"]]}
{"instId":"BTC-USDT","action":"update","ts":"1776816036280","asks":[],"bids":[["76298.5","0.1","1"],["76280.9","0.37266583","2"],["76278.6","0","0"]]}
{"instId":"BTC-USDT","action":"update","ts":"1776816036300","asks":[],"bids":[["76271.7","1.01006","1"],["76173.2","0","0"]]}
{"instId":"BTC-USDT","action":"update","ts":"1776816036310","asks":[],"bids":[["76245.7","0.77045041","3"],["76237.9","0.22027808","3"]]}
{"instId":"BTC-USDT","action":"update","ts":"1776816036370","asks":[["76347.5","0.47151308","1"],["76392.6","0.47151308","1"],["76461.6","0","0"],["76461.7","0","0"]],"bids":[]}
{"instId":"BTC-USDT","action":"update","ts":"1776816036380","asks":[["76347.4","0.18285667","1"],["76348.6","0","0"]],"bids":[["76339.2","0.70363455","12"],["76322.1","0.00654766","1"],["76322","0","0"],["76321","0","0"],["76284.9","0.1051395","1"]]}
{"instId":"BTC-USDT","action":"update","ts":"1776816036390","asks":[["76341.8","0","0"],["76354.5","0.32738588","1"],["76356.3","0","0"],["76461.6","0.00332668","1"]],"bids":[["76339.2","0.57424374","10"],["76333.3","0","0"],["76322.2","0.00654777","1"],["76322.1","0","0"],["76173.2","0.00001006","1"]]}
{"instId":"BTC-USDT","action":"update","ts":"1776816036400","asks":[["76339.3","0.47326439","19"],["76348.6","0.00654697","1"],["76349.5","0","0"],["76356.3","0.00654778","1"],["76357.1","0","0"]],"bids":[["76329.4","0","0"],["76328.6","0.01319495","1"],["76328.2","0.00654697","1"],["76323.7","0","0"],["76322.7","0.32738985","1"],["76322.2","0","0"],["76321.5","0.00654778","1"],["76173.2","0","0"]]}
{"instId":"BTC-USDT","action":"update","ts":"1776816036410","asks":[["76339.3","0.47064555","18"],["76347.4","0","0"],["76348.6","0","0"],["76350.1","0.00654702","1"],["76354.4","0.32739198","1"],["76354.5","0","0"],["76354.6","0.15910419","3"],["76356.3","0","0"],["76358","0.00654778","1"],["76359.8","0","0"],["76393.1","0","0"],["76408.7","1.92417962","1"],["76461.7","0.00001025","1"],["76462","0.00002228","1"]],"bids":[["76339.2","0.63674374","11"],["76332","0.22690051","2"],["76329.5","0.00656203","2"],["76328.2","0","0"],["76322.9","0.00656458","2"],["76322.8","0.32762946","6"],["76322.7","0","0"],["76321.5","0","0"],["76308.6","0.1554901","3"],["76173.2","0.00001006","1"],["76173","0.00001059","1"],["76171.1","0.00001024","1"]]}
{"instId":"BTC-USDT","action":"update","ts":"1776816036420","asks":[["76347.4","0.18744949","2"],["76350.1","0","0"],["76353.5","0.32739195","1"],["76354.4","0","0"],["76354.6","0.26517365","4"],["76355","0.00654778","1"],["76358","0","0"],["76392.7","0.12298422","1"]],"bids":[["76329.5","0.00001501","1"],["76327.9","0.00654708","1"],["76322.9","0.0000168","1"],["76322.8","0.00023744","5"],["76321.5","0.32739195","1"],["76320.1","0.00654778","1"],["76308.6","0.26155956","4"],["76173.2","0","0"],["76173","0","0"],["76171.1","0","0"]]}
{"instId":"BTC-USDT","action":"update","ts":"1776816036430","asks":[["76347.4","0.18090241","1"],["76348.6","0.00654709","1"],["76353.4","0.42398429","1"],["76353.5","0","0"],["76353.7","0","0"],["76354.3","0.32739191","1"],["76355","0","0"],["76356.3","0.00654778","1"],["76362.7","0.5370184","2"],["76462","0","0"]],"bids":[["76328.7","0.00654709","1"],["76327.9","0","0"],["76322.9","0.32740871","2"],["76321.5","0.00654778","1"],["76320.1","0","0"],["76173.2","0.00001006","1"]]}
{"instId":"BTC-USDT","action":"update","ts":"1776816036440","asks":[],"bids":[["76328.7","0","0"],["76328.2","0.00654713","1"]]}
{"instId":"BTC-USDT","action":"update","ts":"1776816036450","asks":[],"bids":[["76321.5","0","0"],["76321.2","0.00657312","3"],["76173","0.00001059","1"]]}
{"instId":"BTC-USDT","action":"update","ts":"1776816036460","asks":[["76339.3","0.43087555","18"],["76347.5","0","0"],["76347.6","0","0"],["76347.7","0","0"],["76350.6","0.03","2"],["76350.7","0","0"],["76354.6","0.21213892","3"],["76356.4","0","0"],["76360","0.00009621","2"],["76366.4","0","0"],["76408.7","0","0"],["76411.4","1.92417962","1"],["76462","0.00002228","1"],["76462.2","0.00551437","1"],["76462.3","0.00027227","4"],["76462.5","0.00001257","1"],["76462.6","0.47226231","9"]],"bids":[["76339.2","0.73674374","12"],["76331.7","0.26615152","3"],["76327.8","0","0"],["76308.6","0.21078076","3"],["76171.1","0.00001024","1"]]}
{"instId":"BTC-USDT","action":"update","ts":"1776816036470","asks":[["76339.3","0.39304991","16"],["76347.3","0.08715443","1"],["76347.4","0","0"],["76348.6","0","0"],["76349.6","0","0"],["76350.1","0.00654721","1"],["76354.3","0","0"],["76356.3","0","0"],["76357.1","0.3273896","1"],["76358","0.00654751","1"],["76369.9","0.05303473","1"],["76380.3","0","0"],["76386.6","0","0"],["76388.4","0.00132225","2"],["76394.6","0.21401607","2"],["76400.2","0","0"],["76411.3","0.47151308","1"],["76420.8","0.000015","1"],["76463","0.00004357","1"],["76463.1","0.00001427","1"]],"bids":[["76331.9","0.03","2"],["76329.4","0.00654721","1"],["76328.6","0","0"],["76328.2","0","0"],["76325.8","0.32738983","1"],["76323.8","0","0"],["76323","0.00655906","2"],["76322.9","0.0000168","1"],["76321.2","0.0000254","2"],["76319.4","0.01610326","1"],["76308.6","0.26155956","4"],["76270.9","0.00001316","1"],["76171.1","0","0"]]}
{"instId":"BTC-USDT","action":"update","ts":"1776816036480","asks":[["76344.6","0.0150946","1"],["76347.3","0.03120076","1"],["76350.1","0","0"],["76353.3","0.00654688","1"],["76358","0","0"],["76358.9","0.00654748","1"],["76463.1","0","0"]],"bids":[["76334.8","0.01319388","1"],["76331.4","0.00656004","2"],["76329.4","0","0"],["76323.7","0.00654748","1"],["76323","0.00001155","1"],["76173","0","0"]]}
{"instId":"BTC-USDT","action":"update","ts":"1776816036490","asks":[["76349.8","0.03452602","1"],["76358","0.00654745","1"],["76358.9","0","0"],["76463","0","0"]],"bids":[["76323.7","0","0"],["76322.9","0.00656425","2"],["76173","0.00001059","1"]]}
{"instId":"BTC-USDT","action":"update","ts":"1776816036500","asks":[["76349.7","0.00654689","1"],["76350.7","0.47151308","1"],["76353.3","0","0"],["76357","0.3273756","1"],["76357.1","0","0"],["76358","0","0"],["76358.9","0.00654746","1"],["76462.6","0","0"]],"bids":[["76331.4","0.00001316","1"],["76329.4","0.00654689","1"],["76325.8","0","0"],["76323.7","0.33392306","2"],["76322.9","0.0000168","1"],["76173","0","0"]]}
{"instId":"BTC-USDT","action":"update","ts":"1776816036510","asks":[["76349.7","0","0"],["76349.8","0.16890434","2"],["76353.3","0.00654689","1"],["76357","0","0"],["76358.9","0.32737628","1"],["76359.9","0.00654747","1"],["76369.6","0.01552216","1"],["76383.2","0","0"],["76392","0.00130903","1"],["76462.5","0","0"]],"bids":[["76331.8","0.00654689","1"],["76329.4","0","0"],["76326.3","0.32737628","1"],["76323.8","0.00654747","1"],["76323.7","0","0"],["76308.6","0.21078076","3"],["76173.2","0","0"]]}
{"instId":"BTC-USDT","action":"update","ts":"1776816036520","asks":[["76353.4","0.26951816","1"],["76369.9","0","0"],["76462.5","0.00001257","1"]],"bids":[]}
{"instId":"BTC-USDT","action":"update","ts":"1776816036530","asks":[["76359.9","0","0"],["76360.4","0.05896264","1"],["76362.6","0.00654759","1"],["76462.5","0","0"]],"bids":[["76323.8","0","0"],["76323.7","0.00654759","1"]]}
{"instId":"BTC-USDT","action":"update","ts":"1776816036540","asks":[["76360.3","0.00654747","1"],["76362.6","0","0"],["76401","1.92417962","1"],["76411.4","0","0"]],"bids":[]}
{"instId":"BTC-USDT","action":"update","ts":"1776816036550","asks":[["76350.2","0","0"],["76353","0.01309","1"],["76354.6","0.26517365","4"]],"bids":[["76330.5","0.0131","1"],["76325.7","0.52355191","2"],["76308.6","0.26155956","4"],["76173.6","0","0"]]}
{"instId":"BTC-USDT","action":"update","ts":"1776816036570","asks":[],"bids":[["76330.8","0.0262","1"],["76173.7","0","0"]]}
{"instId":"BTC-USDT","action":"update","ts":"1776816036590","asks":[["76358.8","0.32737469","1"],["76358.9","0","0"],["76360.3","0","0"],["76362.6","0.00654744","1"]],"bids":[["76326.4","0.33392213","2"],["76326.3","0","0"],["76323.7","0","0"],["76173.7","0.00070045","3"]]}
{"instId":"BTC-USDT","action":"update","ts":"1776816036600","asks":[["76359.9","0.00654751","1"],["76362.6","0","0"]],"bids":[["76326.4","0.32737469","1"],["76323.7","0.00654751","1"],["76173.7","0","0"]]}
{"instId":"BTC-USDT","action":"update","ts":"1776816036610","asks":[["76393.1","1.92417962","1"],["76401","0","0"]],"bids":[["76265.1","0.0001813","2"],["76262.1","0","0"],["76256.6","0.00054218","1"],["76253.5","0.49933734","2"]]}
{"instId":"BTC-USDT","action":"update","ts":"1776816036640","asks":[["76402.7","0","0"],["76462.5","0.00001257","1"]],"bids":[]}
{"instId":"BTC-USDT","action":"update","ts":"1776816036650","asks":[["76362.6","0.20698976","1"],["76462.5","0","0"]],"bids":[]}
{"instId":"BTC-USDT","action":"update","ts":"1776816036660","asks":[["76416.1","0.54089025","2"]],"bids":[]}
{"instId":"BTC-USDT","action":"update","ts":"1776816036680","asks":[["76352.9","0.00654703","1"],["76353.3","0","0"]],"bids":[["76332.1","0.00654703","1"],["76331.8","0","0"]]}
{"instId":"BTC-USDT","action":"update","ts":"1776816036710","asks":[["76369.4","0.01607304","1"],["76462.3","0","0"]],"bids":[["76319.4","0","0"],["76173.7","0.00070045","3"]]}
{"instId":"BTC-USDT","action":"update","ts":"1776816036740","asks":[["76402.7","0.00003978","1"],["76462.2","0","0"]],"bids":[]}
{"instId":"BTC-USDT","action":"update","ts":"1776816036850","asks":[["76339.3","0.45554991","17"]],"bids":[]}
{"instId":"BTC-USDT","action":"update","ts":"1776816036860","asks":[["76428.9","0.659437","1"],["76462","0","0"]],"bids":[["76279.1","0.660731","1"],["76173.7","0","0"]]}
{"instId":"BTC-USDT","action":"update","ts":"1776816036920","asks":[["76339.3","0.39304991","16"]],"bids":[["76322.2","0.01579627","1"],["76175","0","0"]]}
{"instId":"BTC-USDT","action":"update","ts":"1776816037010","asks":[["76402.7","0.01942427","2"]],"bids":[]}
{"instId":"BTC-USDT","action":"update","ts":"1776816037170","asks":[["76350.5","0.00654706","1"],["76352.9","0","0"],["76357.1","0.32738361","1"],["76358.8","0","0"]],"bids":[["76332.1","0","0"],["76330.9","0.00654706","1"],["76326.4","0","0"],["76323.7","0.33393112","2"],["76175","0.00029601","2"]]}
{"instId":"BTC-USDT","action":"update","ts":"1776816037190","asks":[["76350.5","0","0"],["76352.9","0.00654707","1"]],"bids":[["76331.4","0.00656023","2"],["76330.9","0","0"],["76173.7","0.00070045","3"]]}
{"instId":"BTC-USDT","action":"update","ts":"1776816037200","asks":[],"bids":[["76326","0.32738423","1"],["76323.7","0.00654751","1"],["76173.7","0","0"]]}
{"instId":"BTC-USDT","action":"update","ts":"1776816037270","asks":[["76432.1","0.00001316","1"],["76435.4","0.00001316","1"],["76461.6","0","0"],["76461.7","0","0"]],"bids":[]}
{"instId":"BTC-USDT","action":"update","ts":"1776816037640","asks":[["76339.3","0.45554991","17"]],"bids":[["76314.7","0.28055207","1"],["76175","0","0"]]}
{"instId":"BTC-USDT","action":"update","ts":"1776816037650","asks":[],"bids":[["76280.9","0.52225159","3"]]}
{"instId":"BTC-USDT","action":"update","ts":"1776816037720","asks":[["76369.6","0","0"],["76461.6","0.00332668","1"]],"bids":[]}
{"instId":"BTC-USDT","action":"update","ts":"1776816037730","asks":[["76392.7","0.68944509","2"]],"bids":[]}
{"instId":"BTC-USDT","action":"update","ts":"1776816037750","asks":[],"bids":[["76332.1","0.08","1"],["76175.1","0","0"]]}
{"instId":"BTC-USDT","action":"update","ts":"1776816037760","asks":[],"bids":[["76240.2","0.46589223","1"],["76175.4","0","0"]]}
{"instId":"BTC-USDT","action":"update","ts":"1776816037790","asks":[["76339.3","0.39304991","16"]],"bids":[]}
{"instId":"BTC-USDT","action":"update","ts":"1776816037830","asks":[],"bids":[["76332.1","0","0"],["76175.4","0.00003868","3"]]}
{"instId":"BTC-USDT","action":"update","ts":"1776816037970","asks":[],"bids":[["76233","0","0"],["76175.1","0.47151308","1"]]}
{"instId":"BTC-USDT","action":"update","ts":"1776816038010","asks":[["76357.1","0","0"],["76358","0.32737532","1"],["76359.3","0.46761246","3"],["76359.9","0","0"],["76461.7","0.00001025","1"]],"bids":[["76332.1","0.00654704","1"],["76331.4","0.00001316","1"],["76326.3","0.32737532","1"],["76326","0","0"],["76175.1","0","0"]]}
{"instId":"BTC-USDT","action":"update","ts":"1776816038020","asks":[["76422.4","0.60264703","2"]],"bids":[]}
{"instId":"BTC-USDT","action":"update","ts":"1776816038030","asks":[["76339.3","0.07650982","12"],["76349.9","0","0"],["76350.6","0.50151308","3"],["76350.7","0","0"],["76354.6","0.15910419","3"],["76358","0","0"],["76358.9","0.32737527","1"],["76359.2","1.00603555","1"],["76359.3","0.46106501","2"],["76359.4","0","0"],["76360.3","0.00654742","1"],["76360.4","0","0"],["76402.6","0.00003978","1"],["76402.7","0.01938449","1"],["76462","0.00002228","1"]],"bids":[["76284.9","0","0"],["76175.1","0.47151308","1"]]}
{"instId":"BTC-USDT","action":"update","ts":"1776816038040","asks":[["76344.6","0","0"],["76347.3","0","0"],["76349.8","0","0"],["76350.6","0.03","2"],["76352.9","0","0"],["76353.7","0.00654701","1"],["76358.8","0.58957657","1"],["76358.9","0","0"],["76359.2","0","0"],["76359.3","0.00040006","1"],["76359.4","0.32737527","1"],["76359.5","0","0"],["76360.3","0","0"],["76362.5","0.00654741","1"],["76369.9","0.10606946","1"],["76416","0.00002075","1"],["76416.1","0.5408695","1"],["76462.2","0.00551437","1"],["76462.3","0.00027227","4"]],"bids":[["76338","0.21810737","2"],["76332","0.12690051","1"],["76328.2","0.32737527","1"],["76326.4","1.01258296","2"],["76326.3","0","0"],["76323.7","0","0"],["76321.5","0.08378297","1"],["76184.4","0","0"]]}
{"instId":"BTC-USDT","action":"update","ts":"1776816038050","asks":[["76344.8","0","0"],["76347.7","0.01313175","1"],["76353.7","0","0"],["76354.5","0.006547","1"],["76358.8","0.26231134","1"],["76359.4","0","0"],["76362.5","0.33392069","2"],["76365.2","0","0"],["76369.2","0.26474163","1"],["76462.5","0.00001257","1"],["76462.6","0.47226231","9"]],"bids":[["76334.9","0.006547","1"],["76334.8","0.11750821","2"],["76332.1","0","0"],["76329.3","0.13167566","2"],["76325.8","0.08378297","1"],["76221","0","0"]]}
{"instId":"BTC-USDT","action":"update","ts":"1776816038060","asks":[["76358.8","0.16458982","1"],["76369","0.08378297","1"],["76369.9","0","0"]],"bids":[["76330.4","0.00305","1"],["76329.4","0.32737335","1"],["76328.2","0","0"],["76326.5","0.69339392","1"],["76326.1","0","0"],["76321.9","0.00001501","1"],["76317.1","1.09298451","3"],["76301.9","0.12724474","1"],["76175.1","0","0"]]}
{"instId":"BTC-USDT","action":"update","ts":"1776816038070","asks":[["76354.6","0.26517365","4"],["76362.4","0.00654741","1"],["76362.5","0.32737328","1"],["76365.2","0.11929194","1"],["76462.5","0","0"],["76462.6","0","0"]],"bids":[["76329.5","0.13781326","2"],["76329.4","0","0"],["76329.3","0","0"],["76328.3","0.32737339","1"],["76326.6","0.00654741","1"],["76326.4","1.00603555","1"],["76312.5","0.13566174","3"],["76309.4","0.00001033","1"],["76300.6","0","0"],["76291.4","0.00131076","1"],["76175.1","0.47151308","1"]]}
{"instId":"BTC-USDT","action":"update","ts":"1776816038080","asks":[],"bids":[["76307.8","0.11929194","1"],["76175.1","0","0"]]}
{"instId":"BTC-USDT","action":"update","ts":"1776816038100","asks":[["76358.7","1.00603555","1"],["76462.3","0","0"]],"bids":[]}
{"instId":"BTC-USDT","action":"update","ts":"1776816038110","asks":[["76354.6","0.15910419","3"],["76358.6","0.46489143","1"],["76358.8","0","0"]],"bids":[]}
{"instId":"BTC-USDT","action":"update","ts":"1776816038120","asks":[["76365.1","0.08378297","1"],["76462.2","0","0"]],"bids":[]}
{"instId":"BTC-USDT","action":"update","ts":"1776816038130","asks":[["76339.3","0.10630982","13"],["76354.6","0.26517365","4"]],"bids":[]}
{"instId":"BTC-USDT","action":"update","ts":"1776816038140","asks":[["76339.3","0.07650982","12"]],"bids":[["76337.3","0.01077933","1"],["76334.9","0","0"],["76334.8","0.10431433","1"],["76332.1","0.00654701","1"],["76290","0.1192563","1"],["76176.3","0","0"],["76175.4","0","0"]]}
{"instId":"BTC-USDT","action":"update","ts":"1776816038150","asks":[["76350.3","0.47151308","1"],["76354.5","0","0"],["76355","0.006547","1"],["76359.2","0.00654735","1"],["76362","0.05896264","1"],["76362.4","0","0"],["76362.5","0.32737028","1"],["76402.7","0","0"],["76462","0","0"]],"bids":[["76337.3","0.11077933","2"],["76335.8","0","0"],["76334.9","0.006547","1"],["76332.1","0","0"],["76329.6","0.32737028","1"],["76328.3","0","0"],["76326.6","0","0"],["76326.4","0","0"],["76325.9","0","0"],["76323.7","0.00654735","1"],["76321.6","0.48765892","2"],["76321.4","0","0"],["76318.3","1.47755897","3"],["76318.1","0","0"],["76317.1","0.08683297","2"],["76184.3","1.00603555","1"],["76175.4","0.00003868","3"],["76175.1","0.47151308","1"],["76175","0.00029601","2"],["76173.7","0.00070045","3"]]}
{"instId":"BTC-USDT","action":"update","ts":"1776816038160","asks":[["76339.3","0.53637676","17"],["76347.7","0","0"],["76348.6","0.03119683","1"],["76354.5","0.00654686","1"],["76355","0","0"],["76358.5","0.32737046","1"],["76359.2","0","0"],["76361.9","0.00654737","1"],["76362.5","0","0"]],"bids":[["76339.2","0.67424374","11"],["76337.3","0.1","1"],["76334.9","0.00654686","1"],["76329.7","0.13780182","1"],["76329.6","0","0"],["76329.5","0.00001501","1"],["76326.6","0.33391783","2"],["76326.5","0","0"],["76325.8","0","0"],["76323.7","0","0"],["76322.2","0","0"],["76321.5","0","0"],["76318.2","0.11929929","1"],["76285.5","0.10615019","1"],["76176.3","0.1305","1"],["76173.6","0.00002308","1"],["76173.2","0.00001006","1"]]}
{"instId":"BTC-USDT","action":"update","ts":"1776816038170","asks":[["76345.3","0.01313217","1"],["76350.2","0.15361743","1"],["76352.9","0.00654679","1"],["76354.5","0","0"],["76359.5","0.08378297","1"],["76461.5","0","0"],["76461.6","0","0"],["76461.7","0","0"]],"bids":[["76334.9","0","0"],["76334.3","0.01077975","1"],["76332.1","0.00654679","1"],["76330.4","0","0"],["76329.7","0.04008179","1"],["76326.6","0.32737046","1"],["76323.7","0.00654749","1"],["76321","0.00305","1"],["76317.1","0.08378297","1"],["76304.4","0.00305","1"],["76292.4","0.0000168","1"],["76221","0.08378297","1"],["76175","0","0"],["76173.7","0","0"],["76173.6","0","0"],["76173.2","0","0"]]}
{"instId":"BTC-USDT","action":"update","ts":"1776816038180","asks":[["76361.8","0.00654748","1"],["76361.9","0","0"]],"bids":[["76326.7","0.32505655","1"],["76326.6","0.33042046","2"],["76321","0","0"],["76311.2","0.00001316","1"],["76307.9","0.11056388","2"],["76307.8","0","0"],["76296.7","0.12458434","1"],["76285.5","0","0"],["76175","0.00029601","2"]]}
{"instId":"BTC-USDT","action":"update","ts":"1776816038190","asks":[["76345.3","0","0"],["76361.7","0.00654747","1"],["76361.8","0","0"],["76461.5","0.01228943","9"]],"bids":[["76331.3","0","0"],["76325.8","0.47151308","1"]]}
{"instId":"BTC-USDT","action":"update","ts":"1776816038200","asks":[["76342.9","0.01315429","2"],["76353.3","0.05896264","1"],["76361.7","0","0"],["76361.9","0.00654748","1"],["76362","0","0"],["76461.5","0.14278943","10"]],"bids":[["76324.5","0.05896264","1"],["76323.8","0.00654748","1"],["76323.7","0","0"],["76323.4","0.00305","1"],["76314.5","0.00305","1"],["76314.1","0.1305","1"],["76304.4","0","0"],["76284.9","0.10694808","1"],["76175.4","0","0"],["76175.1","0","0"],["76175","0","0"]]}
{"instId":"BTC-USDT","action":"update","ts":"1776816038210","asks":[["76359.5","0.09033046","2"],["76361.9","0","0"],["76461.6","0.00332668","1"]],"bids":[["76324.6","0.00660695","3"],["76323.8","0","0"],["76175.4","0.00003868","3"]]}
{"instId":"BTC-USDT","action":"update","ts":"1776816038250","asks":[],"bids":[["76319.8","0.01610912","1"],["76175.4","0","0"]]}
{"instId":"BTC-USDT","action":"update","ts":"1776816038270","asks":[["76438.8","0.00044174","3"]],"bids":[]}
{"instId":"BTC-USDT","action":"update","ts":"1776816038340","asks":[["76357.1","0.3273838","1"],["76358.5","0","0"]],"bids":[["76326.6","0.00305","1"],["76326.3","0.3273838","1"],["76176.3","0","0"]]}
{"instId":"BTC-USDT","action":"update","ts":"1776816038370","asks":[["76357.1","0","0"],["76358","0.32738384","1"]],"bids":[]}
{"instId":"BTC-USDT","action":"update","ts":"1776816038420","asks":[],"bids":[["76319.8","0","0"],["76175.4","0.00003868","3"]]}
{"instId":"BTC-USDT","action":"update","ts":"1776816038430","asks":[["76358.9","0.00654766","1"],["76359.5","0.08378297","1"],["76461.6","0","0"]],"bids":[["76324.6","0.00005946","2"],["76323.7","0.00654766","1"],["76175.4","0","0"]]}
{"instId":"BTC-USDT","action":"update","ts":"1776816038440","asks":[["76350.5","0.00654715","1"],["76352.9","0","0"],["76357.1","0.32738579","1"],["76358","0","0"]],"bids":[["76332.1","0","0"],["76330.9","0.00654715","1"],["76326.3","0","0"],["76324.6","0.32744525","3"],["76175.4","0.00003868","3"]]}
{"instId":"BTC-USDT","action":"update","ts":"1776816038450","asks":[],"bids":[["76339.2","0.56804374","9"],["76331.7","0.23015152","2"],["76176.3","0.1305","1"],["76175.4","0","0"]]}
{"instId":"BTC-USDT","action":"update","ts":"1776816038460","asks":[["76347.2","0.47151308","1"],["76461.5","0","0"]],"bids":[["76332","0.08743418","1"]]}
{"instId":"BTC-USDT","action":"update","ts":"1776816038470","asks":[["76340.5","0.01313299","1"],["76342.9","0.00002172","1"],["76347.1","0.17194741","1"],["76348.6","0","0"],["76358","0.00654769","1"],["76358.9","0","0"],["76461.4","0","0"]],"bids":[["76334.3","0","0"],["76329","0.0107805","1"],["76323.7","0","0"],["76322.9","0.00656449","2"],["76175.4","0.00003868","3"]]}
{"instId":"BTC-USDT","action":"update","ts":"1776816038480","asks":[["76387.9","1.92417977","1"],["76393.1","0","0"]],"bids":[["76329","0","0"],["76175.1","0.47151308","1"]]}
{"instId":"BTC-USDT","action":"update","ts":"1776816038490","asks":[["76392.7","0.12298422","1"]],"bids":[["76338","0.11810737","1"],["76337.9","0","0"],["76331.4","0.01079332","2"],["76314.5","0","0"],["76300","0.00664833","5"],["76175","0.00029601","2"],["76173.7","0.00070045","3"]]}
{"instId":"BTC-USDT","action":"update","ts":"1776816038500","asks":[],"bids":[["76326.6","0","0"],["76319.9","0.00305","1"],["76311","0.23277023","2"],["76300","0.00359833","4"]]}
{"instId":"BTC-USDT","action":"update","ts":"1776816038520","asks":[["76350.5","0.00654722","1"]],"bids":[["76330.9","0.00654722","1"],["76324.7","0.32738543","1"],["76324.6","0.00005946","2"],["76173.7","0","0"]]}
{"instId":"BTC-USDT","action":"update","ts":"1776816038530","asks":[["76350.5","0","0"],["76352.9","0.00654721","1"],["76357.1","0","0"],["76358","0.3273854","1"],["76359.2","0.00654765","1"]],"bids":[["76331.5","0.00654721","1"],["76330.9","0","0"],["76326.3","0.3273854","1"],["76324.7","0","0"],["76324.6","0.00660711","3"],["76322.9","0.0000168","1"]]}
{"instId":"BTC-USDT","action":"update","ts":"1776816038550","asks":[["76347","0.16","1"],["76461.3","0","0"]],"bids":[["76324.6","0.00005946","2"],["76324.3","0.00305","1"],["76323.7","0.00654767","1"],["76319.9","0","0"],["76175","0","0"]]}
{"instId":"BTC-USDT","action":"update","ts":"1776816038570","asks":[["76339.3","0.53940676","18"]],"bids":[]}
{"instId":"BTC-USDT","action":"update","ts":"1776816038580","asks":[["76366.5","0.01","1"],["76461.1","0","0"]],"bids":[]}
{"instId":"BTC-USDT","action":"update","ts":"1776816038600","asks":[["76341.7","0.00001266","1"],["76460.9","0","0"]],"bids":[["76336.8","0.00003958","1"]]}
{"instId":"BTC-USDT","action":"update","ts":"1776816038650","asks":[["76403.5","0.01969859","1"],["76460.7","0","0"]],"bids":[]}
{"instId":"BTC-USDT","action":"update","ts":"1776816038660","asks":[],"bids":[["76318.4","0.52222506","1"],["76175.1","0","0"]]}
{"instId":"BTC-USDT","action":"update","ts":"1776816038710","asks":[["76357.1","0.32739625","1"],["76358","0","0"]],"bids":[["76326.3","0","0"],["76324.6","0.32745571","3"],["76175.1","0.47151308","1"]]}
{"instId":"BTC-USDT","action":"update","ts":"1776816038720","asks":[],"bids":[["76321.1","0.02304035","2"]]}
{"instId":"BTC-USDT","action":"update","ts":"1776816038730","asks":[],"bids":[["76331.5","0","0"],["76330.9","0.00654723","1"]]}
{"instId":"BTC-USDT","action":"update","ts":"1776816038780","asks":[["76350.5","0.00654724","1"],["76352.9","0","0"]],"bids":[["76323.2","0.00262043","1"],["76175.1","0","0"]]}
{"instId":"BTC-USDT","action":"update","ts":"1776816038860","asks":[["76339.3","0.53938768","18"]],"bids":[]}
{"instId":"BTC-USDT","action":"update","ts":"1776816038870","asks":[["76416.3","0.00017043","1"],["76460.6","0","0"]],"bids":[]}
{"instId":"BTC-USDT","action":"update","ts":"1776816038880","asks":[["76387.8","0.74093168","2"]],"bids":[]}
{"instId":"BTC-USDT","action":"update","ts":"1776816038890","asks":[],"bids":[["76337.3","0","0"],["76175.1","0.47151308","1"]]}
{"instId":"BTC-USDT","action":"update","ts":"1776816038900","asks":[["76341.7","0","0"],["76460.6","0.00002799","2"]],"bids":[]}
{"instId":"BTC-USDT","action":"update","ts":"1776816038910","asks":[["76411.2","0.24907765","1"],["76411.5","0","0"],["76416.3","0","0"],["76460.7","0.00167279","1"]],"bids":[]}
{"instId":"BTC-USDT","action":"update","ts":"1776816038950","asks":[],"bids":[["76323.2","0.00524086","2"]]}
{"instId":"BTC-USDT","action":"update","ts":"1776816039030","asks":[["76402.6","0","0"],["76402.7","0.00003978","1"]],"bids":[]}
{"instId":"BTC-USDT","action":"update","ts":"1776816039040","asks":[],"bids":[["76321.1","0.0067388","1"]]}
{"instId":"BTC-USDT","action":"update","ts":"1776816039080","asks":[["76353.2","0.08378297","1"],["76460.7","0","0"]],"bids":[["76317.1","0","0"],["76175","0.00029601","2"]]}
{"instId":"BTC-USDT","action":"update","ts":"1776816039090","asks":[["76339.3","0.56211768","19"],["76349.9","0.00654725","1"],["76350.1","1.00603555","1"],["76350.5","0","0"],["76354.7","0.1305","1"],["76358","0.00654789","1"],["76359.2","0","0"],["76369.4","0","0"],["76375.6","0.05239768","1"],["76385.8","0","0"],["76395.9","0","0"]],"bids":[["76339.2","0.54532374","8"],["76338","0","0"],["76336.8","0.00005195","2"],["76330.9","0","0"],["76329.8","0.00654725","1"],["76325.8","0","0"],["76323.7","0","0"],["76322.9","0.00656469","2"],["76321.6","0.01614584","1"],["76318.7","0.01580217","1"],["76318.3","0.47152342","2"],["76314.8","1.00603555","1"],["76184.4","1.00603555","1"],["76184.3","0","0"],["76173.7","0.00070045","3"]]}
{"instId":"BTC-USDT","action":"update","ts":"1776816039100","asks":[["76344.4","0.10858179","2"],["76350","0.5265286","2"],["76350.2","0","0"],["76353.7","0.32740331","1"],["76357.1","0","0"],["76386.4","0.0261888","1"],["76390.4","0.000015","1"],["76394.6","0.18783","1"]],"bids":[["76339.2","0.11497851","2"],["76337.1","0","0"],["76334.8","0","0"],["76331.9","0","0"],["76331.7","0.11507576","1"],["76331.4","0.00001316","1"],["76330.8","0","0"],["76329.8","0","0"],["76329","0.03","2"],["76328.1","0","0"],["76326.2","0","0"],["76325.7","0.39305191","1"],["76324.6","0.00005946","2"],["76322.9","0.0000168","1"],["76322.6","0","0"],["76318.4","0","0"],["76318.3","0.00001034","1"],["76314.9","0.47151308","1"],["76314.8","0","0"],["76314.6","0.00001316","1"],["76173.6","0.00002308","1"],["76173.2","0.00001006","1"],["76173","0.00001059","1"],["76171.1","0.00001024","1"],["76170.8","0.00003094","3"],["76170.2","0.00001385","1"],["76168.9","0.000015","1"],["76168.4","0.00011049","4"]]}
{"instId":"BTC-USDT","action":"update","ts":"1776816039110","asks":[["76330.6","0.82174924","18"],["76331.4","0.34515585","3"],["76331.5","0.4726564","4"],["76331.8","0.11506867","1"],["76332.1","0.05822172","2"],["76334.8","0.00261895","1"],["76335.4","0.09563","1"],["76339.1","0.47151308","1"],["76339.2","0.16","1"],["76339.3","0.11390964","13"],["76344.3","0.16762853","2"],["76344.4","0.00002309","1"],["76344.8","0.00001501","1"],["76346.1","0.05896264","1"],["76346.9","0.00654744","1"],["76348.6","0.08378297","1"],["76349.9","0","0"],["76350.1","0","0"],["76353.3","0","0"],["76353.4","0.285664","2"],["76354.5","0.00654824","1"],["76354.6","0","0"],["76358","0","0"],["76369.6","0.01526273","1"],["76371.2","0","0"],["76375.6","0.18495861","2"],["76375.7","0","0"],["76380.4","0","0"],["76383.9","0.00130917","1"],["76384.5","0","0"],["76392","0","0"],["76442.2","0.08381054","2"],["76459.7","0","0"],["76459.8","0","0"],["76459.9","0","0"],["76460","0","0"],["76460.1","0","0"],["76460.2","0","0"],["76460.6","0","0"]],"bids":[["76339.2","0","0"],["76336.8","0","0"],["76334.7","0","0"],["76332","0","0"],["76331.7","0","0"],["76331.4","0","0"],["76330.5","0.0429","2"],["76329.2","0","0"],["76328","0","0"],["76326.7","0","0"],["76325.7","0","0"],["76324.5","0","0"],["76323.6","0.00001034","1"],["76321.6","0","0"],["76318.7","0","0"],["76317.1","0.05896264","1"],["76315","0.11407756","1"],["76314.9","0","0"],["76314.7","0","0"],["76314.5","0.47151308","1"],["76312.5","0.0162517","2"],["76311.1","0.4767515","2"],["76310.7","0","0"],["76308.6","0","0"],["76308.1","1.12534109","2"],["76308","0.00001456","1"],["76307.6","0.47151308","1"],["76296.4","0","0"],["76293.6","0","0"],["76285.6","0.02618984","1"],["76285.5","0.12195438","1"],["76281.7","0.11929194","1"],["76273.6","0.11681965","2"],["76235.5","0.00001316","1"],["76211.3","0.08378297","1"],["76201.3","0.08378297","1"],["76173.2","1.00604561","2"],["76168.6","0.1305","1"],["76167","0.00001319","1"],["76166.6","0.00248493","6"],["76166.2","0.00026145","4"],["76165.9","0.47151308","1"],["76165.8","0.01614584","1"],["76165.2","0.00091086","3"],["76165.1","0.00001015","1"],["76164.3","0.00046091","2"]]}
{"instId":"BTC-USDT","action":"update","ts":"1776816039120","asks":[["76330.6","0.93435857","17"],["76331.4","0","0"],["76331.5","0","0"],["76331.8","0","0"],["76332.1","0","0"],["76333.2","0.01313425","1"],["76334.8","0","0"],["76338.3","0.05303473","1"],["76339","0.22657571","1"],["76339.1","0.47806075","2"],["76339.2","0","0"],["76339.3","0.11129074","12"],["76340.5","0.11743449","1"],["76344.2","0.32741517","1"],["76344.3","0.03241559","1"],["76345.9","0.34044824","5"],["76346","0.1305","1"],["76346.9","0","0"],["76348.5","0.00654836","1"],["76349.9","1.00603555","1"],["76350","0.03","1"],["76353.7","0","0"],["76354.5","0","0"],["76383.9","0.12326594","2"],["76391.4","0.09327848","4"],["76392.5","0.02331962","1"],["76395.9","0.02331962","1"],["76398.5","0.02333278","2"],["76399.9","0.02331962","1"],["76401.3","0.02331962","1"],["76402.7","0.0233594","2"],["76403.2","1.02151962","2"],["76459.2","0","0"],["76459.3","0","0"],["76459.6","0","0"]],"bids":[["76330.5","4.60387186","3"],["76329.7","0","0"],["76324","0.01078122","1"],["76323.2","0.00786129","3"],["76318.3","0.07377518","2"],["76317.1","0","0"],["76307.7","0.00002716","2"],["76299.9","0.26179704","9"],["76296.4","0.11930554","1"],["76274.9","0.04663392","2"],["76271.8","0.02331696","1"],["76270.6","0.02331696","1"],["76266.2","0.02331696","1"],["76262.7","0.02331696","1"],["76260.5","0.02331696","1"],["76259.1","0.02331696","1"],["76258.8","0.02983785","2"],["76255","0.04663392","2"],["76254.9","0.35180041","4"],["76252.4","0.04663392","2"],["76250.2","0.02331696","1"],["76249.9","0.06457156","3"],["76248.9","0.02331696","1"],["76246.5","0.02331696","1"],["76245.8","0.02331696","1"],["76245","0.33991596","2"],["76240.3","0.04663392","2"],["76171.1","0","0"],["76170.8","0","0"],["76170.2","0","0"],["76168.9","0","0"],["76168.6","0","0"],["76168.4","0","0"],["76167","0","0"],["76166.6","0","0"],["76166.2","0","0"],["76165.9","0","0"],["76165.8","0","0"],["76165.2","0","0"],["76165.1","0","0"],["76164.3","0","0"]]}
{"instId":"BTC-USDT","action":"update","ts":"1776816039130","asks":[["76330.6","0.82225763","17"],["76335.3","0.13289564","2"],["76338.2","0.00654763","1"],["76339.1","0.47151308","1"],["76344.1","0.32742016","1"],["76344.2","0","0"],["76344.3","0","0"],["76345.8","0.00654834","1"],["76348.5","0.07887","1"],["76348.6","0","0"],["76358.2","0.01","1"],["76458.8","0","0"],["76459.1","0","0"]],"bids":[["76330.5","0.01387186","2"],["76327.3","0","0"],["76315.4","0.00261958","1"],["76314.6","0.27965087","2"],["76314.5","0","0"],["76311.1","0","0"],["76308.2","1.47754863","2"],["76308.1","0.11930554","1"],["76307.6","0","0"],["76306.9","0","0"],["76305.4","0","0"],["76304","0","0"],["76300.1","0.00523916","1"],["76297.5","0.14411005","1"],["76296.3","0.6697302","2"],["76295.8","0","0"],["76293.9","0","0"],["76291.4","0","0"],["76284.8","0.70527311","3"],["76283.4","0.0013109","1"],["76281.9","0.00131092","1"],["76249.6","0","0"],["76171.1","0.00001024","1"],["76170.8","0.00003094","3"],["76170.2","0.00001385","1"],["76168.9","0.000015","1"],["76168.4","0.00011049","4"]]}
{"instId":"BTC-USDT","action":"update","ts":"1776816039140","asks":[["76335.2","0.07671697","2"],["76335.3","0.10435008","1"],["76338.2","0","0"],["76344","0.3339681","2"],["76344.1","0","0"],["76345.8","0.14051541","1"],["76348.7","0","0"],["76380.7","0.00130923","1"],["76388.4","0.00001316","1"]],"bids":[["76327.8","0.0262","1"],["76314.6","0.13890422","2"],["76297.6","0.1166543","1"],["76296.4","0","0"],["76284.9","0","0"],["76283.4","0","0"],["76275","0.00131104","1"],["76273.4","0.10414623","1"],["76168.4","0","0"]]}
{"instId":"BTC-USDT","action":"update","ts":"1776816039150","asks":[["76333.1","0.00654755","1"],["76335.1","0.12195677","1"],["76335.2","0.07016937","1"],["76340.4","0.32741865","1"],["76340.9","0.00654831","1"],["76343.9","0.14164863","1"],["76344","0","0"],["76345.9","0.23437878","3"],["76375.6","0.25043987","3"],["76377.9","0.02619169","1"],["76386.4","0","0"],["76391.5","0","0"],["76458.3","0","0"],["76458.4","0","0"],["76458.7","0","0"]],"bids":[["76329","0","0"],["76327.8","0","0"],["76285.6","0","0"],["76281.9","0","0"],["76277.8","0.0261925","1"],["76273.6","0.11813071","3"],["76168.4","0.00011049","4"],["76167","0.00001319","1"],["76166.6","0.00248493","6"]]}
{"instId":"BTC-USDT","action":"update","ts":"1776816039160","asks":[["76330.6","0.83539232","18"],["76333.1","0","0"],["76333.2","0","0"],["76335","0.12359124","2"],["76335.2","0","0"],["76338.2","0.32741865","1"],["76340.4","0","0"],["76340.9","0","0"],["76343.8","0.00654865","1"],["76343.9","0","0"],["76345.9","0.10615346","2"],["76359","0.00037033","1"],["76361.8","0.05896264","1"],["76365.2","0.13516568","2"],["76380.1","1.92417977","1"],["76383.9","0.00130917","1"],["76387.9","0","0"],["76458.3","0.00035006","7"],["76458.4","0.0000711","2"]],"bids":[["76324","0","0"],["76319.8","0.0107818","1"],["76314.7","0.00654753","1"],["76312","0.01598666","1"],["76311","0.49085588","3"],["76308.3","0.00654865","1"],["76306.5","0.32741865","1"],["76298.5","0","0"],["76168.4","0","0"],["76167","0","0"],["76166.6","0","0"]]}
{"instId":"BTC-USDT","action":"update","ts":"1776816039170","asks":[["76334.9","0.12320312","2"],["76335","0.17886881","2"],["76337.9","0.05896264","1"],["76338.9","0.00654896","1"],["76340.5","0","0"],["76343.8","0","0"],["76346.1","0","0"],["76347","0.24378297","2"],["76348.5","0.15772","2"],["76349.8","0.11930554","1"],["76387.8","0.14075506","1"],["76400","0.0144791","3"],["76406.8","0.00095764","2"],["76412.7","0","0"],["76416","0","0"],["76428.9","0","0"],["76458.7","0.01614584","1"]],"bids":[["76330.5","0.0131","1"],["76329.5","0","0"],["76328","0.00064471","1"],["76324.3","0","0"],["76323.4","0","0"],["76315.8","0.00305","1"],["76314.7","0","0"],["76312.6","0.00654882","1"],["76312","0","0"],["76311","0.48780588","2"],["76310.3","0.00305","1"],["76308.3","0","0"],["76308.2","0","0"],["76306.5","0","0"],["76304.2","0.32745105","1"],["76304.1","0","0"],["76303.8","0.00656576","2"],["76303.6","0.00305","1"],["76303.2","1.09811288","3"],["76298.8","0","0"],["76291.1","0.00001316","1"],["76288.5","0","0"],["76286.5","0","0"],["76286","0.07526771","2"],["76281.4","0","0"],["76280.4","0.00325318","1"],["76279.1","0","0"],["76277.2","0.00233689","1"],["76275","0.01440778","2"],["76193.5","0.08378297","1"],["76173.3","1.00603555","1"],["76173.2","0.00001006","1"],["76168.4","0.00011049","4"],["76167","0.00001319","1"],["76166.6","0.00248493","6"],["76166.2","0.00026145","4"]]}
{"instId":"BTC-USDT","action":"update","ts":"1776816039180","asks":[["76337.8","0.32745788","1"],["76338.2","0","0"],["76338.9","0","0"],["76340.9","0.00654898","1"],["76341.6","0.03","2"],["76345.7","0.04194385","1"],["76350.6","0","0"],["76370.5","0.14411005","1"],["76378.2","0","0"],["76423.1","0.65999672","3"],["76458.7","0","0"]],"bids":[["76319.8","0","0"],["76312.6","0","0"],["76311.1","0.00654882","1"],["76311","0.07703732","1"],["76310.8","0.05896264","1"],["76308.3","0.47151308","1"],["76306.5","0.32745788","1"],["76304.4","0.00654898","1"],["76304.3","0.47889715","2"],["76304.2","0","0"],["76303.8","0.0000168","1"],["76288.3","0.06637451","1"],["76280.9","0.37266583","2"],["76273.3","1.12078472","4"],["76168.6","0.1305","1"],["76168.4","0","0"],["76167","0","0"],["76166.6","0","0"],["76166.2","0","0"]]}
{"instId":"BTC-USDT","action":"update","ts":"1776816039190","asks":[["76330.6","0.95698818","19"],["76334.8","0.0065487","1"],["76334.9","0.1166543","1"],["76337.7","0.32745739","1"],["76337.8","0","0"],["76345.7","0.17715679","2"],["76345.9","0.40570693","3"],["76347.1","0","0"],["76349.8","0","0"],["76375.5","0.10449707","1"],["76375.6","0.11787894","2"],["76430.3","0.04238106","3"]],"bids":[["76328.1","0.0000143","1"],["76323","0.03001155","3"],["76317","0.0107822","1"],["76315.5","0","0"],["76314.1","0","0"],["76312.6","0.0065487","1"],["76312.5","0.00010586","1"],["76311.1","0","0"],["76311","0.22553525","2"],["76310.8","0","0"],["76306.5","0","0"],["76304.4","0.33400637","2"],["76280.8","0.00023744","5"],["76280.5","0","0"],["76273.4","0","0"],["76189.8","0","0"],["76168.4","0.00011049","4"],["76167","0.00001319","1"],["76166.6","0.00248493","6"],["76166.2","0.00026145","4"],["76165.9","0.47151308","1"]]}
{"instId":"BTC-USDT","action":"update","ts":"1776816039200","asks":[["76330.6","0.96353707","20"],["76334.8","0","0"],["76337.6","0.00654912","1"],["76338.3","0.15910419","3"],["76340.9","0","0"],["76345.6","0.08230491","1"],["76345.7","0.13521294","1"]],"bids":[["76328","0","0"],["76327.7","0.0006455","1"],["76318.3","0.04153235","2"],["76314.6","0.00001316","1"],["76312.6","0","0"],["76308.4","0.00654895","1"],["76304.4","0.32745739","1"],["76302","0.00654912","1"],["76297.5","0","0"],["76293.7","0.1132129","1"],["76280.9","0.0000168","1"],["76274.9","0.16268659","3"],["76165.9","0","0"]]}
{"instId":"BTC-USDT","action":"update","ts":"1776816039210","asks":[["76345.5","0.13257682","1"],["76345.8","0","0"],["76364.4","0.1378799","1"],["76364.5","0","0"],["76404.7","0.01904","1"],["76458.4","0","0"]],"bids":[["76328.1","0.0000514","2"],["76327.7","0","0"],["76327.5","0.00081999","1"],["76315.8","0","0"],["76315.1","0.12940687","6"],["76310.9","0","0"],["76308.8","0.06550532","1"],["76306.1","0.00305","1"],["76304.5","0.10624395","2"],["76303.6","0","0"],["76300.2","0","0"],["76297.6","0","0"],["76290","0","0"],["76288.4","0.11690503","6"],["76284","0.00305","1"],["76280.3","0.00330523","2"],["76273.2","1.00632474","3"],["76265.1","0.00005018","1"],["76262.1","0.00013113","1"],["76256.6","0","0"],["76253.5","0.49987951","3"],["76184.2","0","0"],["76165.9","0.47151308","1"],["76165.8","0.01614584","1"],["76165.2","0.00091086","3"],["76165.1","0.00001015","1"]]}
{"instId":"BTC-USDT","action":"update","ts":"1776816039220","asks":[["76330.6","1.02052818","20"],["76334.8","0.00654908","1"],["76337.6","0","0"],["76339.3","0.04689074","11"],["76340.9","0.00654909","1"],["76345.4","0.07993524","1"],["76345.5","0.19808214","2"],["76345.6","0","0"],["76345.9","0.29963747","2"],["76362.7","0.47151308","1"],["76367.7","0.05240365","1"],["76375.6","0.06548126","1"],["76393.9","0.00003978","1"],["76402.7","0.02331962","1"],["76457.9","0","0"],["76458.1","0","0"],["76458.3","0","0"]],"bids":[["76327.5","0","0"],["76327","0.00082036","1"],["76311.1","0.00654908","1"],["76308.4","0","0"],["76304.6","0.27895974","2"],["76302","0","0"],["76300.5","0","0"],["76295.1","0.00305","1"],["76284","0","0"],["76280.6","0.20020603","1"],["76280.3","0","0"],["76276.3","0.00001501","1"],["76274.2","0","0"],["76273.2","1.00962997","5"],["76270.8","0.000012","1"],["76266.2","0.13198845","3"],["76261","0.00019775","1"],["76164.3","0.00046091","2"]]}
{"instId":"BTC-USDT","action":"update","ts":"1776816039230","asks":[["76330.6","1.02707726","21"],["76334.8","0","0"],["76337.6","0.00654907","1"],["76338.3","0.26517365","4"],["76339","0.16580028","1"],["76340.9","0","0"],["76345.3","0.12727375","1"],["76345.7","0","0"],["76353.3","0.12727375","1"],["76353.6","0","0"],["76457.9","0.02053416","2"]],"bids":[["76327","0","0"],["76326.5","0.00081939","1"],["76311.1","0","0"],["76308.9","0.00654908","1"],["76304.6","0.27241065","1"],["76302","0.00654907","1"],["76289.9","0","0"],["76274.2","0.065484","1"],["76164.3","0","0"]]}
{"instId":"BTC-USDT","action":"update","ts":"1776816039240","asks":[["76330.6","1.02052818","20"],["76334.8","0.00654878","1"],["76345.2","0.09711873","1"],["76345.4","0","0"],["76457.9","0","0"]],"bids":[["76311.1","0.00654878","1"],["76308.9","0","0"],["76296.7","0","0"],["76296.4","0.11931914","1"],["76292.5","0","0"],["76164.3","0.00046091","2"]]}
{"instId":"BTC-USDT","action":"update","ts":"1776816039250","asks":[["76328.2","1.19302257","16"],["76330.5","0.30462766","1"],["76330.6","0.20090278","5"],["76335.1","0","0"],["76335.3","0","0"],["76337.2","0.000015","1"],["76337.6","0","0"],["76338.3","0","0"],["76338.9","0.00654915","1"],["76343.8","0.01309","1"],["76344.4","0.1352557","2"],["76345.1","0.12197068","1"],["76345.5","0.06550532","1"],["76349.8","0.521739","1"],["76353","0","0"],["76364.5","0.29343","1"],["76371.3","0","0"],["76375.5","0","0"],["76379","0.18783","1"],["76394.6","0","0"],["76435.4","0","0"]],"bids":[["76330.5","0","0"],["76328.1","0.06162114","1"],["76319.9","0.0131","1"],["76314.4","0","0"],["76309.4","0.13789456","2"],["76303.8","0.00656595","2"],["76302.4","0.30280035","2"],["76302","0","0"],["76301.9","0","0"],["76299.9","0.00023748","5"],["76296.4","0","0"],["76290.7","0.12463647","2"],["76289.8","0.10001033","2"],["76281.7","0","0"],["76277.2","0.11900816","2"],["76273.6","0.00132261","2"],["76268","0.10411042","2"],["76266.2","0.02655115","2"],["76163.9","0.00005592","3"],["76162.2","0.00002057","1"],["76162.1","0.00004159","3"],["76162","0.00001017","1"],["76161.2","0.00007766","2"]]}
{"instId":"BTC-USDT","action":"update","ts":"1776816039260","asks":[["76328.2","1.20877723","18"],["76330.5","0.05996948","1"],["76330.6","0.18514903","3"],["76335.9","0.10606946","2"],["76343.5","0.15910419","2"],["76343.8","0.13241289","2"],["76345.1","0","0"],["76345.2","0","0"],["76345.3","0","0"],["76346.1","0.07887","1"],["76349.7","0.13662613","2"],["76358.1","0.00001316","1"],["76358.2","0","0"],["76362.5","0.11932289","1"],["76365.2","0.01587374","1"],["76369.1","0","0"],["76369.2","0","0"],["76371.6","0.12198767","2"],["76375.7","0.11667127","1"],["76379.9","0.10871836","1"],["76392.7","0","0"]],"bids":[["76328.1","0.09142114","2"],["76315.1","0.03902405","6"],["76308.9","0.05896264","1"],["76299.2","0.07347187","1"],["76297.5","0.05303473","1"],["76296.4","0.10682506","1"],["76268.1","0.10386539","1"],["76268","0.00001155","1"],["76162.2","0","0"],["76162.1","0","0"],["76162","0","0"],["76161.2","0","0"]]}
{"instId":"BTC-USDT","action":"update","ts":"1776816039270","asks":[["76337.7","0","0"],["76338","0.00001316","1"],["76338.9","0.32746061","1"],["76340.9","0.00654917","1"],["76343.4","1.15298897","2"],["76346.1","0.15772","2"],["76357.2","0","0"],["76404.6","0.00093689","1"],["76406.8","0.00002075","1"],["76457.6","0","0"],["76457.8","0","0"]],"bids":[["76306.5","0.32746061","1"],["76304.7","0.00656003","2"],["76304.4","0","0"],["76303.8","0.0000168","1"],["76297.5","0.1554901","3"],["76292","0.02904","1"],["76268.1","0","0"],["76268","0.10781564","2"]]}
{"instId":"BTC-USDT","action":"update","ts":"1776816039280","asks":[["76334.8","0.17257847","2"],["76335","0","0"],["76353.4","0.01614584","1"],["76457.6","0.00199545","1"]],"bids":[["76304.6","0","0"],["76302.5","0","0"],["76266.2","0.02331696","1"],["76162.2","0.00002057","1"],["76162.1","0.00004159","3"]]}
{"instId":"BTC-USDT","action":"update","ts":"1776816039290","asks":[["76334.8","0.11918613","2"]],"bids":[["76323.2","0.01048172","4"]]}
{"instId":"BTC-USDT","action":"update","ts":"1776816039300","asks":[["76333","0.00001738","1"],["76377.5","1.92417977","1"],["76380.1","0","0"],["76457.6","0","0"]],"bids":[]}
{"instId":"BTC-USDT","action":"update","ts":"1776816039310","asks":[["76338.8","0.26354729","1"],["76339","0","0"],["76342.9","0.13260271","2"],["76344.4","0.00002309","1"],["76401.4","0.26205512","3"],["76404.6","0.00002075","1"],["76406.8","0","0"],["76438.8","0.00045364","4"],["76450.2","0.00003521","3"],["76457.6","0.00199545","1"]],"bids":[["76325.7","0.00003597","1"],["76311.1","1.01258433","2"],["76297.5","0.26155956","4"],["76280.4","0","0"],["76278.3","0.00347875","5"],["76277.9","0.0032533","1"],["76277.2","0.11667127","1"],["76275.1","0.00233712","1"],["76273.2","1.00616208","1"],["76262.1","0","0"],["76256","0.00013114","1"],["76253.5","0.49933734","2"],["76247.4","0.00055532","2"],["76187.8","0","0"],["76173.3","0","0"]]}
{"instId":"BTC-USDT","action":"update","ts":"1776816039320","asks":[["76343.3","0.4507537","1"],["76343.4","1.00603555","1"],["76343.5","0.19814746","2"],["76367","0.00637771","2"],["76457.6","0","0"]],"bids":[["76311.2","0.5908793","2"],["76311","0","0"],["76162","0.00001017","1"]]}
{"instId":"BTC-USDT","action":"update","ts":"1776816039330","asks":[["76328.2","1.20828463","18"]],"bids":[["76282","0.03372278","2"],["76222.6","0.000655","1"],["76162.1","0","0"],["76162","0","0"]]}
{"instId":"BTC-USDT","action":"update","ts":"1776816039340","asks":[["76334.7","0.00654869","1"],["76334.8","0.11263735","1"],["76338.9","0","0"],["76342.8","0.32745987","1"],["76343.5","0.25118219","3"],["76365.2","0","0"]],"bids":[["76314.3","0.00656369","2"],["76311.1","1.00603555","1"],["76308.4","0.32745987","1"],["76306.5","0","0"],["76305.8","0.01553816","1"],["76162.2","0","0"]]}
{"instId":"BTC-USDT","action":"update","ts":"1776816039350","asks":[["76338.8","0.1658003","1"],["76342.7","0.12992937","1"],["76342.8","0.32745933","1"],["76343.8","0.01309","1"],["76396.3","0","0"]],"bids":[["76314.3","0.000015","1"],["76311.3","0.00678613","6"],["76289.8","0.00001033","1"]]}
{"instId":"BTC-USDT","action":"update","ts":"1776816039360","asks":[["76348.5","0.07885","1"],["76391.3","0.00003978","1"],["76393.9","0","0"]],"bids":[]}
{"instId":"BTC-USDT","action":"update","ts":"1776816039370","asks":[["76323.3","0.05420526","2"],["76325.8","0.11472","1"],["76326.6","0.69733487","15"],["76328.1","0.18763954","2"],["76328.2","1.11091989","13"],["76335.9","0.05303473","1"],["76348.5","0","0"],["76457.3","0","0"],["76457.4","0","0"],["76457.5","0","0"]],"bids":[["76328.1","0","0"],["76326.5","0","0"],["76325.7","0","0"],["76324.6","0","0"],["76323.6","0","0"],["76307.9","0.00001316","1"],["76297.5","0","0"],["76162.2","0.00002057","1"],["76162.1","0.00004159","3"],["76162","0.00001017","1"],["76161.2","0.00007766","2"],["76161.1","0.0000827","1"],["76160.4","0.01614584","1"]]}
{"instId":"BTC-USDT","action":"update","ts":"1776816039380","asks":[["76323.3","1.06199642","19"],["76323.7","0.00362","1"],["76325.8","0","0"],["76326.5","0.10508946","1"],["76326.6","0","0"],["76328.1","0.41593995","1"],["76328.2","0.48464818","2"],["76330.5","0","0"],["76335.9","0","0"],["76338.6","0.05303473","1"],["76338.7","0.32745873","1"],["76342.8","0","0"],["76343.5","0.092078","1"],["76353.7","0.18283387","1"],["76379.9","0","0"],["76432.1","0","0"],["76457.3","1.00617669","2"],["76457.4","0.00002231","1"]],"bids":[["76323.2","0.13525191","13"],["76323.1","0.01514049","1"],["76321.3","0","0"],["76308.4","0","0"],["76306.5","0.32745873","1"],["76304.6","0.08378297","1"],["76304.5","0.00001316","1"],["76292.6","0.05303473","1"],["76285.5","0","0"],["76284.9","0.11667372","1"],["76161.1","0","0"],["76160.4","0","0"]]}
{"instId":"BTC-USDT","action":"update","ts":"1776816039390","asks":[["76328","0.32409254","1"],["76328.1","0","0"],["76334.8","0","0"],["76338.6","0.26517365","4"],["76457.5","0.00001001","1"]],"bids":[["76306.6","0.31218862","1"],["76292.8","0.00002864","1"],["76292.6","0.20988299","3"],["76286","0.04456141","1"],["76265.6","0.00323436","1"],["76162.1","0","0"],["76162","0","0"],["76161.2","0","0"]]}
{"instId":"BTC-USDT","action":"update","ts":"1776816039400","asks":[["76323.3","1.06263642","20"],["76323.7","0","0"],["76326.5","0","0"],["76328","0.19993447","1"],["76333","0","0"],["76457.6","0.00199545","1"],["76457.8","0.00026388","1"],["76457.9","0.02053416","2"]],"bids":[["76303.3","0.57807217","1"],["76162.2","0","0"]]}
{"instId":"BTC-USDT","action":"update","ts":"1776816039410","asks":[["76334.8","0.08097562","1"],["76341.2","0.07887","1"],["76342.6","0.47151308","1"],["76342.9","0.00002172","1"],["76346.9","0.12199401","1"],["76375.5","0.11668993","1"],["76375.7","0","0"],["76457.5","0","0"],["76457.6","0","0"],["76457.8","0","0"],["76457.9","0","0"]],"bids":[["76323.2","0.13265191","11"],["76320.8","0.00008117","2"],["76311.1","0","0"],["76309","0.47151308","1"],["76308.3","0","0"],["76290.8","0.2034312","1"],["76173.2","1.00604561","2"]]}
{"instId":"BTC-USDT","action":"update","ts":"1776816039420","asks":[["76323.3","1.0827469","20"],["76328.2","0.47151308","1"],["76334.7","0.00654864","1"],["76337.8","0.3274607","1"],["76338.5","0.36624376","1"],["76338.7","0","0"],["76338.8","0","0"],["76341.2","0.15772","2"],["76369.2","0.02332513","1"],["76371.1","0.01166129","1"],["76372.3","1.92417977","1"],["76373.7","0.06407546","1"],["76377.5","0","0"],["76377.7","0","0"],["76377.9","0","0"],["76394.2","0","0"]],"bids":[["76323.2","0.11113191","11"],["76323.1","0","0"],["76323","0.00001155","1"],["76318.2","0","0"],["76317","0","0"],["76314.2","0","0"],["76311.3","0.00678608","6"],["76311.2","0.25562349","2"],["76309","0","0"],["76308.1","0","0"],["76306.7","0.32747571","2"],["76306.5","0","0"],["76305.8","0","0"],["76304.6","0","0"],["76304.4","0.11668993","1"],["76303.4","0.11668993","1"],["76301.3","0","0"],["76292.6","0.26155956","4"],["76277.8","0","0"],["76276.2","0","0"],["76270.1","0.02332513","1"],["76262.7","0.13241117","2"],["76162.2","0.00002057","1"],["76162.1","0.00004159","3"],["76162","0.00001017","1"],["76161.2","0.00007766","2"],["76161.1","0.0000827","1"],["76160.4","0.01614584","1"],["76160.2","0.00705391","1"],["76160","0.00187493","7"],["76159.3","0.00040006","1"]]}
{"instId":"BTC-USDT","action":"update","ts":"1776816039430","asks":[["76323.5","0.01313591","1"],["76334.8","0.16837006","2"],["76337.8","0.32747129","1"],["76340.9","0","0"],["76342.5","0.00654939","1"],["76397.2","0.00093689","1"],["76399.5","0.00002075","1"],["76401.4","0.26111823","2"],["76404.6","0","0"],["76423.1","0.00051072","2"],["76457.3","0","0"],["76457.4","0","0"]],"bids":[["76323.2","0.01763191","8"],["76318.3","0.00001034","1"],["76315.4","0","0"],["76315.2","0.00654912","1"],["76312.7","0.00261968","1"],["76311.8","0.01079449","2"],["76311.3","0.00023744","5"],["76311.2","0.07926413","2"],["76306.8","0.00654939","1"],["76306.7","0.3274863","2"],["76306.6","0","0"],["76304.7","0.00001086","1"],["76293.8","0.00002864","1"],["76292.8","0","0"],["76277.9","0","0"],["76275.1","0","0"],["76273.3","0.46000372","3"],["76273.2","1.00941548","2"],["76269.4","0.00233727","1"],["76244.9","0.18168774","2"],["76160.9","0.1305","1"],["76159.3","0","0"]]}
{"instId":"BTC-USDT","action":"update","ts":"1776816039440","asks":[["76334.7","0.00654917","1"],["76335.3","0.32747272","1"],["76337.7","0.00654938","1"],["76337.8","0","0"],["76342.5","0","0"],["76362.5","0.26344673","2"],["76369.2","0.82590644","2"],["76370.5","0","0"],["76387.6","0.1","1"],["76422.4","0.00015119","1"],["76437.4","0.00196024","1"]],"bids":[["76323.2","0.01127614","5"],["76315.2","0","0"],["76312.7","0","0"],["76311.3","0.00678661","6"],["76306.8","0.31542651","1"],["76306.7","0.00001501","1"],["76304.5","0.32748588","2"],["76304.2","0.00261997","1"],["76300.4","0.00654938","1"],["76300.1","0","0"],["76288.9","0.00523994","1"],["76288.3","0","0"],["76287.4","0.1","1"],["76284.8","0.69741437","2"],["76278.4","0","0"],["76273.6","0.00918252","3"],["76260.3","0.34635264","2"],["76258.4","0.01047988","1"],["76243.1","0.01309985","1"],["76237.8","0","0"],["76186.1","6.4292","1"],["76160","0","0"]]}
{"instId":"BTC-USDT","action":"update","ts":"1776816039450","asks":[["76330.5","0.00654915","1"],["76334.7","0","0"],["76362.4","0.34813151","1"],["76362.6","0","0"],["76416.1","0","0"],["76457.3","1.00617669","2"]],"bids":[["76323.2","0.04028172","5"],["76323.1","0.00079015","1"],["76311.3","0.00023744","5"],["76309.3","0.00266608","2"],["76309","0.00654915","1"],["76304.2","0","0"],["76294","0.00528587","2"],["76288.9","0","0"],["76288.5","0.10955378","1"],["76286","0","0"],["76263.5","0.01047916","1"],["76258.4","0","0"],["76237.9","0.14664584","2"]]}
{"instId":"BTC-USDT","action":"update","ts":"1776816039460","asks":[["76346.1","0.07885","1"],["76358.5","0.12199401","1"],["76364.4","0","0"],["76378.9","0.05622941","1"],["76457.3","0","0"]],"bids":[["76319","0.01023744","6"],["76316.9","0.02004629","2"],["76280.7","0.28548673","2"]]}
{"instId":"BTC-USDT","action":"update","ts":"1776816039470","asks":[["76340.6","0","0"],["76346.1","0","0"],["76359","0","0"],["76366.3","0","0"],["76392.5","0.22803367","2"],["76457.3","1.00617669","2"],["76457.4","0.00002231","1"],["76457.5","0.00001001","1"],["76457.6","0.00199545","1"]],"bids":[["76293.8","0","0"],["76291.6","0.00002864","1"]]}
{"instId":"BTC-USDT","action":"update","ts":"1776816039480","asks":[],"bids":[["76265.6","0","0"],["76264","0.00323453","1"]]}
{"instId":"BTC-USDT","action":"update","ts":"1776816039490","asks":[["76386.8","0.00003978","1"],["76391.3","0","0"]],"bids":[["76264","0","0"],["76260.6","0.00324771","2"],["76160","0.00187493","7"]]}
{"instId":"BTC-USDT","action":"update","ts":"1776816039500","asks":[],"bids":[["76320.8","0.00012837","3"],["76235.3","0.91539358","2"]]}
{"instId":"BTC-USDT","action":"update","ts":"1776816039510","asks":[["76416","0.659548","1"],["76420.5","0.657999","1"],["76450.4","0.0120815","6"],["76456.7","0.00136499","3"],["76457.4","0","0"],["76457.5","0","0"],["76457.6","0","0"]],"bids":[["76271","0.659288","1"],["76266.2","0.68415996","2"],["76238","0.07311746","1"],["76160.2","0","0"],["76160","0","0"]]}
{"instId":"BTC-USDT","action":"update","ts":"1776816039520","asks":[["76335.3","0","0"],["76337.8","0.32746875","1"]],"bids":[["76273.3","0.76661066","2"]]}
{"instId":"BTC-USDT","action":"update","ts":"1776816039530","asks":[["76353.5","0.01592463","1"],["76457.3","0","0"]],"bids":[["76303.4","0.13225672","2"],["76187.7","0.47454308","2"]]}
{"instId":"BTC-USDT","action":"update","ts":"1776816039540","asks":[["76334.7","0.16","1"],["76347","0.08378297","1"],["76387.6","0","0"]],"bids":[["76287.4","0","0"],["76269.2","0.35595309","2"],["76160.2","0.00705391","1"]]}
{"instId":"BTC-USDT","action":"update","ts":"1776816039550","asks":[["76362.5","0.14412384","1"],["76365.2","0.11668993","1"],["76457.2","0","0"]],"bids":[["76323.2","0.04148172","6"],["76291.6","0","0"],["76288.5","0.07970378","1"],["76260.6","0.00001316","1"],["76160","0.00187493","7"]]}
{"instId":"BTC-USDT","action":"update","ts":"1776816039560","asks":[["76323.3","0.96766511","19"],["76330.5","0","0"],["76334.6","0.00654909","1"],["76334.7","0","0"],["76359","0.00041663","1"],["76372.3","0","0"],["76387.9","1.92417977","1"]],"bids":[["76323.2","0.16898227","7"],["76311.3","0.00678653","6"],["76309","0","0"],["76262.7","0.02331696","1"],["76231","0.74318503","2"],["76159.3","0.00040006","1"]]}
{"instId":"BTC-USDT","action":"update","ts":"1776816039570","asks":[["76323.3","0.97028473","20"],["76337.7","0","0"],["76339.2","0.00654926","1"],["76340.6","0.00003102","1"],["76363.5","0.00007241","1"],["76369.2","0.20852192","2"],["76456.7","0","0"],["76457.1","0","0"]],"bids":[["76304.6","0.00654926","1"],["76300.4","0","0"],["76225.9","0.14591374","2"]]}
{"instId":"BTC-USDT","action":"update","ts":"1776816039580","asks":[["76339.2","0","0"],["76340.9","0.00654926","1"],["76342.5","0.48693436","1"],["76343.3","0","0"]],"bids":[]}
{"instId":"BTC-USDT","action":"update","ts":"1776816039600","asks":[],"bids":[["76293.6","0.06450709","1"],["76159.3","0","0"]]}
{"instId":"BTC-USDT","action":"update","ts":"1776816039610","asks":[["76339.3","0.04688074","10"],["76373.7","0","0"],["76456.7","0.00136499","3"]],"bids":[["76256","0","0"],["76252.9","0.00013114","1"],["76247.4","0.00001316","1"],["76244.4","0.00054217","1"],["76222.6","0.06474616","2"],["76160","0","0"]]}
{"instId":"BTC-USDT","action":"update","ts":"1776816039620","asks":[["76385.4","2.39485775","3"],["76387.8","0.72565154","2"],["76387.9","0","0"],["76457.1","0.01564436","4"]],"bids":[["76323.2","0.43158804","9"],["76319","0.00023744","5"],["76318","0.01","1"],["76275","0.03404822","3"],["76244.2","0.47151308","1"],["76184.4","1.02016436","2"],["76160.2","0","0"]]}
{"instId":"BTC-USDT","action":"update","ts":"1776816039630","asks":[["76323.3","0.91607948","19"],["76343.5","0.104078","2"],["76366.5","0","0"],["76380.4","0.11334017","1"],["76384.6","1.03280613","2"],["76387.8","0.14075506","1"]],"bids":[["76282.5","0.1","1"],["76245.7","0.31845879","2"],["76160.4","0","0"]]}
{"instId":"BTC-USDT","action":"update","ts":"1776816039640","asks":[["76385.2","0.1","1"],["76385.4","0.4722779","2"],["76390.5","1.92257985","1"],["76456.7","0","0"],["76457.1","0","0"]],"bids":[]}
{"instId":"BTC-USDT","action":"update","ts":"1776816039650","asks":[["76384.6","0.5441043","1"],["76387.8","0.72517396","2"]],"bids":[["76260.6","0.0032477","2"]]}
{"instId":"BTC-USDT","action":"update","ts":"1776816039670","asks":[["76323.3","0.91607947","18"]],"bids":[["76311.8","0.00001155","1"],["76286.5","0.00002864","1"],["76160.9","0","0"]]}
{"instId":"BTC-USDT","action":"update","ts":"1776816039680","asks":[],"bids":[["76323.2","0.49670755","11"],["76318","0","0"],["76316.9","0.00004629","1"],["76316.5","0.01001086","2"],["76315.8","0.02","1"],["76314.3","0.01079759","2"],["76304.5","0.79899896","3"],["76304.3","0.00738407","1"],["76275","0.01440778","2"],["76184.4","1.00603555","1"]]}
{"instId":"BTC-USDT","action":"update","ts":"1776816039690","asks":[],"bids":[["76323.2","0.49408804","10"]]}
{"instId":"BTC-USDT","action":"update","ts":"1776816039710","asks":[],"bids":[["76252.9","0","0"],["76251.4","0.00013115","1"],["76244.4","0","0"],["76242.8","0.00054218","1"]]}
{"instId":"BTC-USDT","action":"update","ts":"1776816039720","asks":[["76397","0.01904","1"],["76404.7","0","0"]],"bids":[]}
{"instId":"BTC-USDT","action":"update","ts":"1776816039730","asks":[["76377.5","1.92257985","1"],["76390.5","0","0"]],"bids":[]}
{"instId":"BTC-USDT","action":"update","ts":"1776816039740","asks":[["76377.4","0.6302876","1"],["76378.9","0","0"],["76387.8","0.14075506","1"]],"bids":[]}
{"instId":"BTC-USDT","action":"update","ts":"1776816039800","asks":[["76386.8","0","0"],["76456.7","0.00136499","3"]],"bids":[["76198.5","0.0068361","1"],["76161.1","0","0"]]}
{"instId":"BTC-USDT","action":"update","ts":"1776816039810","asks":[],"bids":[["76251.4","0","0"],["76249.9","0.06470271","4"],["76242.8","0","0"],["76241.3","0.00054218","1"],["76161.1","0.0000827","1"]]}
{"instId":"BTC-USDT","action":"update","ts":"1776816039840","asks":[["76454.1","0.00070544","2"]],"bids":[]}
{"instId":"BTC-USDT","action":"update","ts":"1776816039890","asks":[["76386.8","0.00004003","1"],["76456.7","0","0"]],"bids":[]}
{"instId":"BTC-USDT","action":"update","ts":"1776816039900","asks":[["76323.3","0.85357947","17"],["76353.5","0","0"],["76456.7","0.00136499","3"]],"bids":[]}
{"instId":"BTC-USDT","action":"update","ts":"1776816039910","asks":[],"bids":[["76323.2","0.49670758","11"],["76227.6","1.546657","1"],["76161.1","0","0"]]}
{"instId":"BTC-USDT","action":"update","ts":"1776816039920","asks":[],"bids":[["76315.9","0.0262","1"],["76227.7","0.60398512","1"],["76225.9","0.00514563","1"],["76162","0","0"],["76161.2","0","0"]]}
{"instId":"BTC-USDT","action":"update","ts":"1776816039930","asks":[],"bids":[["76316.6","0.01678203","1"],["76162.1","0","0"]]}
{"instId":"BTC-USDT","action":"update","ts":"1776816039940","asks":[["76328.2","0","0"],["76334.1","0.47151308","1"]],"bids":[]}
{"instId":"BTC-USDT","action":"update","ts":"1776816039950","asks":[["76323.3","0.84796398","15"],["76323.5","0","0"],["76328","0.05526699","1"],["76337.8","0","0"],["76341.1","0.32745962","1"],["76369.9","0.345725","1"],["76412.5","0","0"],["76457.1","0.01564436","4"]],"bids":[["76306.9","0.32745962","1"],["76304.5","0.47152624","2"],["76162.2","0","0"]]}
{"instId":"BTC-USDT","action":"update","ts":"1776816039960","asks":[["76323.3","0.84732398","14"],["76326.7","0.01313538","1"],["76334","0.14074665","1"],["76334.8","0.08097562","1"],["76340.9","0","0"],["76342.4","0.00654911","1"],["76411.2","0","0"],["76457.1","0","0"]],"bids":[["76323.2","0.50290758","12"],["76307","0.00654911","1"],["76306.8","0.21963129","1"],["76304.6","0","0"]]}
{"instId":"BTC-USDT","action":"update","ts":"1776816039970","asks":[["76369.2","0.28804379","3"]],"bids":[]}
{"instId":"BTC-USDT","action":"update","ts":"1776816039980","asks":[],"bids":[["76309.5","0.47151308","1"],["76163.9","0","0"]]}
{"instId":"BTC-USDT","action":"update","ts":"1776816039990","asks":[],"bids":[["76311.2","0.21066071","3"]]}
{"instId":"BTC-USDT","action":"update","ts":"1776816040010","asks":[["76333.9","0.00654859","1"],["76334.6","0","0"]],"bids":[["76314.4","0.00654859","1"],["76311.3","0.00023744","5"],["76309","0.32745676","1"],["76306.9","0","0"],["76164.3","0","0"]]}
{"instId":"BTC-USDT","action":"update","ts":"1776816040020","asks":[["76333.9","0","0"],["76334","0.14729523","2"],["76457.1","0.01564436","4"]],"bids":[["76311.2","0.29160776","2"],["76307.1","0.00654903","1"],["76307","0","0"]]}
{"instId":"BTC-USDT","action":"update","ts":"1776816040030","asks":[["76334","0.14074665","1"],["76334.7","0.00654857","1"],["76396.9","0.00093689","1"],["76397.2","0","0"],["76411.2","0.04251812","1"],["76456.7","0","0"],["76457.1","0","0"]],"bids":[["76307.1","0","0"],["76306.9","0.00654901","1"],["76270.2","0.00233718","1"],["76269.4","0","0"]]}
{"instId":"BTC-USDT","action":"update","ts":"1776816040060","asks":[["76334","0.14729519","2"],["76334.7","0","0"],["76456.7","0.00136499","3"]],"bids":[]}
{"instId":"BTC-USDT","action":"update","ts":"1776816040070","asks":[["76334","0.14074665","1"],["76334.7","0.00654854","1"],["76456.7","0","0"]],"bids":[]}
{"instId":"BTC-USDT","action":"update","ts":"1776816040080","asks":[],"bids":[["76248.2","0.02349036","1"],["76246.6","0.02349036","1"],["76245.6","0.15399036","2"],["76244.3","0.02349036","1"],["76243.2","0.02349036","1"],["76240.4","0.04698072","2"],["76239.9","1.02889111","2"],["76237","0.02349036","1"],["76235.2","1.57720565","3"],["76233.4","0.02349036","1"],["76231.1","0.02349036","1"],["76228.5","0.02349036","1"],["76228","0.02349036","1"],["76226","0.02349036","1"],["76222.7","0.02349036","1"],["76221.1","0.02349036","1"],["76220","0.02370399","3"],["76219.6","0.49500344","2"],["76215.3","0.02349036","1"],["76211.4","0.02349036","1"],["76173.2","0","0"],["76173","0","0"],["76171.1","0","0"],["76170.8","0","0"],["76170.2","0","0"],["76168.9","0","0"],["76168.6","0","0"],["76168.4","0","0"],["76167","0","0"],["76166.6","0","0"],["76166.2","0","0"],["76165.9","0","0"],["76165.8","0","0"],["76165.2","0","0"],["76165.1","0","0"]]}
{"instId":"BTC-USDT","action":"update","ts":"1776816040100","asks":[["76334","0.14729514","2"],["76334.7","0","0"],["76456.7","0.00136499","3"]],"bids":[]}
{"instId":"BTC-USDT","action":"update","ts":"1776816040110","asks":[["76323.3","0.75436398","12"],["76334.6","0.00001316","1"],["76341.5","0.00654898","1"],["76342.4","0","0"],["76372.1","0.00130937","1"],["76383.9","0","0"],["76456.7","0","0"]],"bids":[["76323.2","0.52562758","13"],["76309","0","0"],["76306.9","0.33400181","2"],["76173.2","1.00604561","2"]]}
{"instId":"BTC-USDT","action":"update","ts":"1776816040120","asks":[],"bids":[["76308.9","0.38641528","2"],["76306.9","0.00654901","1"]]}
{"instId":"BTC-USDT","action":"update","ts":"1776816040130","asks":[["76334","0.14074665","1"],["76334.7","0.00654848","1"],["76341.5","0","0"],["76342.4","0.00654898","1"],["76352.7","0.01551113","1"],["76456.3","0","0"],["76456.4","0","0"]],"bids":[["76303.4","0.11668993","1"]]}
{"instId":"BTC-USDT","action":"update","ts":"1776816040140","asks":[["76369.3","0.4728225","2"],["76380.7","0","0"],["76456.3","0.00003643","1"]],"bids":[]}
{"instId":"BTC-USDT","action":"update","ts":"1776816040150","asks":[["76323.3","0.73163398","11"]],"bids":[]}
{"instId":"BTC-USDT","action":"update","ts":"1776816040160","asks":[["76341.5","0.006549","1"],["76342.4","0","0"]],"bids":[]}
{"instId":"BTC-USDT","action":"update","ts":"1776816040180","asks":[],"bids":[["76274.6","0.01973771","1"],["76184","0.14515712","2"],["76173.2","0","0"]]}
{"instId":"BTC-USDT","action":"update","ts":"1776816040190","asks":[["76385.2","0","0"],["76456.4","0.00002957","1"]],"bids":[]}
{"instId":"BTC-USDT","action":"update","ts":"1776816040200","asks":[],"bids":[["76308.9","0.3864163","2"]]}
{"instId":"BTC-USDT","action":"update","ts":"1776816040210","asks":[],"bids":[["76308.9","0.05896264","1"],["76306.9","0.33400305","2"],["76282","0","0"],["76173.2","1.00604561","2"]]}
{"instId":"BTC-USDT","action":"update","ts":"1776816040220","asks":[["76323.3","0.79710398","12"],["76330.6","0.12160903","2"]],"bids":[]}
{"instId":"BTC-USDT","action":"update","ts":"1776816040230","asks":[["76328","0.0363003","1"]],"bids":[["76306.9","0.32745404","1"],["76306.5","0.00654902","1"],["76173.2","0","0"]]}
{"instId":"BTC-USDT","action":"update","ts":"1776816040260","asks":[["76339.2","0.32745441","1"],["76341.1","0","0"]],"bids":[["76317.7","0.01468376","1"],["76314.3","0.000015","1"],["76173.6","0","0"]]}
{"instId":"BTC-USDT","action":"update","ts":"1776816040270","asks":[["76333.9","0.00654856","1"],["76334.7","0","0"]],"bids":[["76314.4","0","0"],["76311.3","0.006786","6"],["76173.6","0.00002308","1"]]}
{"instId":"BTC-USDT","action":"update","ts":"1776816040280","asks":[["76331.3","0.00001316","1"],["76456.4","0","0"]],"bids":[]}
{"instId":"BTC-USDT","action":"update","ts":"1776816040290","asks":[["76380.3","0.1","1"],["76411.2","0.06148481","2"],["76456.3","0","0"]],"bids":[]}
{"instId":"BTC-USDT","action":"update","ts":"1776816040390","asks":[],"bids":[["76303.3","0.66185514","2"]]}
{"instId":"BTC-USDT","action":"update","ts":"1776816040400","asks":[["76339.2","0","0"],["76341.1","0.32745662","1"]],"bids":[]}
{"instId":"BTC-USDT","action":"update","ts":"1776816040410","asks":[["76326.7","0","0"],["76339","0.32745662","1"],["76340.9","0.00654916","1"],["76341.1","0","0"],["76341.5","0","0"],["76456.3","0.00003643","1"]],"bids":[["76323.2","0.51942758","12"],["76317.7","0","0"],["76315.9","0","0"],["76306.5","0","0"],["76304.6","0.00654916","1"],["76303.2","1.11380849","4"],["76274.6","0","0"],["76184","0.1305","1"],["76173.2","1.00604561","2"],["76173","0.00001059","1"],["76171.1","0.00001024","1"]]}
{"instId":"BTC-USDT","action":"update","ts":"1776816040420","asks":[["76323.3","0.79972345","13"],["76324.2","0.01258468","1"],["76456.3","0","0"]],"bids":[["76323.2","0.51680804","11"],["76316.6","0","0"],["76315.2","0.01468426","1"]]}
{"instId":"BTC-USDT","action":"update","ts":"1776816040430","asks":[["76323.3","0.82245345","14"],["76339.2","0.0065492","1"],["76340.9","0","0"],["76349.7","0.12462613","1"]],"bids":[["76323.2","0.41171858","10"],["76281.2","0.06293305","3"]]}
{"instId":"BTC-USDT","action":"update","ts":"1776816040440","asks":[["76323.3","0.82822345","15"],["76337.8","0.32746231","1"],["76339","0","0"],["76339.2","0","0"],["76340.9","0.00654922","1"]],"bids":[["76323.2","0.38899858","9"],["76323.1","0","0"],["76323","0.00091471","2"],["76306.9","0","0"],["76306.5","0.32746294","1"],["76225.9","0","0"],["76170.8","0.00003094","3"],["76170.2","0.00001385","1"]]}
{"instId":"BTC-USDT","action":"update","ts":"1776816040450","asks":[["76334.8","0.16837054","2"],["76338.7","0.01309","1"],["76343.8","0","0"],["76380.4","0","0"],["76456.3","0.00003643","1"]],"bids":[["76319.9","0","0"],["76313.5","0.0131","1"],["76303.2","1.09811288","3"],["76302.4","0.00001035","1"],["76296","0.3030705","10"],["76294.1","0","0"],["76281.5","0.2822","1"]]}
{"instId":"BTC-USDT","action":"update","ts":"1776816040460","asks":[["76331","0.47151308","1"],["76456.3","0","0"]],"bids":[["76323.2","0.38779858","8"],["76308.2","0.01571346","1"],["76306.5","0","0"],["76304.6","0.45068172","3"],["76288.4","0.00023743","5"],["76274","0.01937833","1"],["76183.4","0.01452486","2"],["76170.2","0","0"]]}
{"instId":"BTC-USDT","action":"update","ts":"1776816040470","asks":[["76330.9","0.28345198","1"],["76334","0","0"],["76339","0.00654936","1"],["76340.9","0","0"]],"bids":[["76315.2","0","0"],["76312.7","0.01468472","1"],["76306.8","0.3241254","2"],["76306.6","0.32746706","1"],["76304.6","0.11666546","1"],["76304.4","0.12323929","2"],["76288.5","0","0"]]}
{"instId":"BTC-USDT","action":"update","ts":"1776816040480","asks":[],"bids":[["76285.5","0.04261265","1"],["76170.8","0","0"]]}
{"instId":"BTC-USDT","action":"update","ts":"1776816040490","asks":[],"bids":[["76306.6","0","0"],["76304.7","0.3274874","2"],["76170.8","0.00003094","3"]]}
{"instId":"BTC-USDT","action":"update","ts":"1776816040500","asks":[],"bids":[["76286.5","0","0"],["76170.2","0.00001385","1"]]}
{"instId":"BTC-USDT","action":"update","ts":"1776816040510","asks":[["76422.3","0.00001198","1"],["76433.4","0","0"]],"bids":[]}
{"instId":"BTC-USDT","action":"update","ts":"1776816040550","asks":[["76339","0","0"],["76340.9","0.00654942","1"],["76374.9","1.90675829","2"],["76377.5","0","0"],["76456.3","0.00003643","1"]],"bids":[["76304.8","0.00654942","1"],["76304.4","0.11668993","1"],["76170.2","0","0"]]}
{"instId":"BTC-USDT","action":"update","ts":"1776816040560","asks":[["76374.8","1.08956572","1"],["76375.9","0","0"],["76377.4","0","0"],["76456.4","0.00002957","1"]],"bids":[]}
{"instId":"BTC-USDT","action":"update","ts":"1776816040570","asks":[["76339.2","0.00654942","1"],["76340.9","0","0"],["76378.9","0.05622941","1"],["76456.4","0","0"]],"bids":[]}
{"instId":"BTC-USDT","action":"update","ts":"1776816040580","asks":[],"bids":[["76286.5","0.00002863","1"],["76170.8","0","0"]]}
{"instId":"BTC-USDT","action":"update","ts":"1776816040590","asks":[["76333.8","0.00654887","1"],["76333.9","0","0"],["76338.4","0.00654942","1"],["76339.2","0","0"]],"bids":[["76304.8","0","0"],["76303.8","0.00656622","2"],["76170.8","0.00003094","3"]]}
{"instId":"BTC-USDT","action":"update","ts":"1776816040620","asks":[["76342.5","0.57071733","2"]],"bids":[]}
{"instId":"BTC-USDT","action":"update","ts":"1776816040630","asks":[],"bids":[["76175.1","0.49202146","2"]]}
{"instId":"BTC-USDT","action":"update","ts":"1776816040670","asks":[["76386.8","0","0"],["76456.4","0.00002957","1"]],"bids":[]}
{"instId":"BTC-USDT","action":"update","ts":"1776816040680","asks":[["76323.3","0.82912345","16"]],"bids":[]}
{"instId":"BTC-USDT","action":"update","ts":"1776816040700","asks":[["76323.3","0.82913345","17"]],"bids":[]}
{"instId":"BTC-USDT","action":"update","ts":"1776816040740","asks":[],"bids":[["76190.2","0","0"],["76170.6","0.0001094","1"]]}
{"instId":"BTC-USDT","action":"update","ts":"1776816040750","asks":[["76386.8","0.00004003","1"],["76456.4","0","0"]],"bids":[]}
{"instId":"BTC-USDT","action":"update","ts":"1776816040760","asks":[],"bids":[["76211.5","0.0051466","1"],["76170.6","0","0"]]}
{"instId":"BTC-USDT","action":"update","ts":"1776816040790","asks":[],"bids":[["76175.1","0.47151308","1"]]}
{"instId":"BTC-USDT","action":"update","ts":"1776816040920","asks":[["76366.8","0.06410776","1"],["76456.3","0","0"]],"bids":[]}
{"instId":"BTC-USDT","action":"update","ts":"1776816041010","asks":[["76338.4","0","0"],["76339","0.00654932","1"]],"bids":[]}
{"instId":"BTC-USDT","action":"update","ts":"1776816041030","asks":[["76333.7","0.00654878","1"],["76333.8","0","0"]],"bids":[["76306.5","0.32746909","1"],["76304.7","0.00001086","1"],["76170.8","0","0"]]}
{"instId":"BTC-USDT","action":"update","ts":"1776816041040","asks":[["76333.7","0","0"],["76334","0.0065488","1"]],"bids":[["76306.5","0","0"],["76304.8","0.32746908","1"]]}
{"instId":"BTC-USDT","action":"update","ts":"1776816041080","asks":[],"bids":[["76237.1","0.02349036","1"],["76234.2","0.02349036","1"],["76231.2","0.02349036","1"],["76230.7","1.02902327","3"],["76228.6","0.02349036","1"],["76226.1","0.02349036","1"],["76222.8","0.04698072","2"],["76221.2","0.02349036","1"],["76218.4","0.02349036","1"],["76215.4","0.04698072","2"],["76214","0.04071419","3"],["76210.8","0.02456036","2"],["76176.3","0","0"],["76175.4","0","0"],["76175.1","0","0"],["76175","0","0"],["76173.7","0","0"],["76173.6","0","0"],["76173.2","0","0"],["76173","0","0"],["76171.1","0","0"]]}
{"instId":"BTC-USDT","action":"update","ts":"1776816041090","asks":[],"bids":[["76281.2","0.02952065","1"]]}
{"instId":"BTC-USDT","action":"update","ts":"1776816041110","asks":[],"bids":[["76304.8","0","0"],["76304.7","0.32748056","2"],["76235.6","0.00548357","1"],["76235","0.47151308","1"],["76208.8","0.01635981","2"],["76208.2","0","0"],["76175.4","0.00003868","3"]]}
{"instId":"BTC-USDT","action":"update","ts":"1776816041120","asks":[["76341.3","0.00001316","1"],["76456.2","0","0"]],"bids":[["76176.3","0.1305","1"],["76175.4","0","0"]]}
{"instId":"BTC-USDT","action":"update","ts":"1776816041130","asks":[],"bids":[["76306.5","0.32746969","1"],["76304.7","0.00001086","1"],["76176.3","0","0"]]}
{"instId":"BTC-USDT","action":"update","ts":"1776816041140","asks":[],"bids":[["76308.2","0","0"],["76175.4","0.00003868","3"]]}
{"instId":"BTC-USDT","action":"update","ts":"1776816041150","asks":[],"bids":[["76176.3","0.1305","1"],["76175.4","0","0"]]}
{"instId":"BTC-USDT","action":"update","ts":"1776816041160","asks":[["76352.7","0","0"],["76456.2","0.00007359","1"]],"bids":[["76303.3","0.67781777","3"]]}
{"instId":"BTC-USDT","action":"update","ts":"1776816041200","asks":[],"bids":[["76315.9","0.0262","1"],["76290.9","0.12196844","1"],["76177.8","0","0"],["76176.3","0","0"]]}
{"instId":"BTC-USDT","action":"update","ts":"1776816041210","asks":[["76339","0","0"],["76340.9","0.00654933","1"]],"bids":[["76323.1","0.0009212","1"],["76323","0.00001155","1"],["76316.7","0.01468396","1"],["76316.6","0.01678203","1"],["76312.7","0","0"],["76308.2","0.0157782","1"],["76304.7","0.00656019","2"],["76303.8","0.0000168","1"],["76179.3","0","0"],["76178.9","0","0"],["76177.9","0","0"]]}
{"instId":"BTC-USDT","action":"update","ts":"1776816041230","asks":[["76337.8","0","0"],["76338.4","0.32746662","1"]],"bids":[["76306.9","0.32746662","1"],["76306.5","0","0"],["76274","0","0"],["76183.4","0.00005866","1"],["76179.3","0.00040006","1"]]}
{"instId":"BTC-USDT","action":"update","ts":"1776816041240","asks":[["76334.8","0.08097562","1"],["76338.4","0","0"],["76339","0.32746672","1"]],"bids":[["76311.4","0.00654859","1"],["76311.3","0.00023744","5"],["76304.8","0.00654927","1"],["76304.7","0.00001086","1"],["76179.9","0","0"],["76179.3","0","0"]]}
{"instId":"BTC-USDT","action":"update","ts":"1776816041250","asks":[["76337.8","0.32746662","1"],["76339","0","0"]],"bids":[]}
{"instId":"BTC-USDT","action":"update","ts":"1776816041260","asks":[["76334.8","0.16837183","2"],["76339","0.00654928","1"],["76340.9","0","0"]],"bids":[["76304.8","0","0"],["76304.6","0.12321474","2"],["76179.9","0.47151308","1"]]}
{"instId":"BTC-USDT","action":"update","ts":"1776816041280","asks":[["76323.3","0.82823345","16"],["76327.9","0.00001316","1"],["76456.2","0","0"]],"bids":[["76323.2","0.38770158","8"]]}
{"instId":"BTC-USDT","action":"update","ts":"1776816041290","asks":[["76330.9","0.29000059","2"],["76334","0","0"],["76338.5","0.37279307","2"],["76339","0","0"],["76456.2","0.00007359","1"],["76456.3","0.00003643","1"]],"bids":[["76311.4","0","0"],["76311.3","0.00678605","6"],["76306.9","0","0"],["76304.7","0.32747921","2"],["76304.6","0.11666546","1"],["76303.8","0.00656611","2"],["76303.3","0.66185514","2"],["76179.3","0.00040006","1"],["76178.9","0.0008637","1"]]}
{"instId":"BTC-USDT","action":"update","ts":"1776816041300","asks":[["76330.9","0.28345198","1"],["76333.9","0.00654862","1"],["76352.7","0.01580674","1"],["76456.2","0","0"],["76456.3","0","0"]],"bids":[["76311.5","0.00656543","2"],["76311.3","0.00023744","5"]]}
{"instId":"BTC-USDT","action":"update","ts":"1776816041310","asks":[],"bids":[["76306.5","0.3274583","1"],["76304.7","0.00001086","1"],["76178.9","0","0"]]}
{"instId":"BTC-USDT","action":"update","ts":"1776816041320","asks":[["76338.5","0.36624376","1"],["76339.2","0.00654911","1"],["76456.1","0","0"]],"bids":[["76304.7","0.00655997","2"],["76303.8","0.0000168","1"]]}
{"instId":"BTC-USDT","action":"update","ts":"1776816041330","asks":[["76339.2","0","0"],["76340.9","0.00654911","1"]],"bids":[]}
{"instId":"BTC-USDT","action":"update","ts":"1776816041350","asks":[],"bids":[["76323.2","0.41009104","9"]]}
{"instId":"BTC-USDT","action":"update","ts":"1776816041390","asks":[["76339.2","0.00654907","1"],["76340.9","0","0"]],"bids":[]}
{"instId":"BTC-USDT","action":"update","ts":"1776816041470","asks":[["76339.1","0.47806217","2"],["76339.2","0","0"],["76456.1","0.0002254","1"]],"bids":[["76306.5","0.32745734","1"]]}
{"instId":"BTC-USDT","action":"update","ts":"1776816041480","asks":[["76339.1","0.47151308","1"],["76340.9","0.00654909","1"],["76456.1","0","0"]],"bids":[]}
{"instId":"BTC-USDT","action":"update","ts":"1776816041490","asks":[],"bids":[["76323.2","0.43374112","10"],["76281.7","0.0334124","2"],["76179.3","0","0"]]}
{"instId":"BTC-USDT","action":"update","ts":"1776816041510","asks":[],"bids":[["76304.7","0.02217265","3"]]}
{"instId":"BTC-USDT","action":"update","ts":"1776816041520","asks":[],"bids":[["76321.3","0.16","1"],["76179.9","0","0"]]}
{"instId":"BTC-USDT","action":"update","ts":"1776816041530","asks":[],"bids":[["76321.4","0.04996109","1"],["76180","0","0"]]}
{"instId":"BTC-USDT","action":"update","ts":"1776816041570","asks":[],"bids":[["76323.2","0.45646112","11"]]}
{"instId":"BTC-USDT","action":"update","ts":"1776816041620","asks":[],"bids":[["76321.3","0","0"],["76180","0.0000812","1"]]}
{"instId":"BTC-USDT","action":"update","ts":"1776816041630","asks":[],"bids":[["76321.4","0","0"],["76179.9","0.47151308","1"]]}
{"instId":"BTC-USDT","action":"update","ts":"1776816041720","asks":[["76340.8","0.00654914","1"],["76340.9","0","0"]],"bids":[["76304.8","0.00654914","1"],["76304.7","0.01562354","2"],["76179.9","0","0"]]}
{"instId":"BTC-USDT","action":"update","ts":"1776816041730","asks":[["76323.3","0.80550345","15"],["76339","0.00654914","1"],["76340.8","0","0"]],"bids":[["76306.5","0","0"],["76304.8","0","0"],["76304.7","0.34308387","3"],["76304.5","0.47807538","3"],["76273.9","0.01988968","1"],["76183.3","0.01446946","2"],["76179.9","0.47151308","1"]]}
{"instId":"BTC-USDT","action":"update","ts":"1776816041740","asks":[["76339","0","0"],["76340.7","0.0065491","1"]],"bids":[["76304.8","0.0065491","1"],["76304.5","0.47152624","2"],["76179.9","0","0"]]}
{"instId":"BTC-USDT","action":"update","ts":"1776816041810","asks":[["76433.3","0.02575447","3"]],"bids":[]}
{"instId":"BTC-USDT","action":"update","ts":"1776816041820","asks":[],"bids":[["76306.9","0.32746047","1"],["76304.7","0.01562354","2"],["76180","0","0"]]}
{"instId":"BTC-USDT","action":"update","ts":"1776816041870","asks":[["76433.3","0.00524642","2"]],"bids":[["76306.9","0","0"],["76304.7","0.3430833","3"],["76180","0.0000812","1"]]}
{"instId":"BTC-USDT","action":"update","ts":"1776816041900","asks":[["76323.3","0.79973345","14"],["76374.9","0.00001316","1"],["76380.1","1.90674513","1"],["76456","0","0"]],"bids":[["76265.1","0","0"],["76249.9","0.06475289","5"],["76179.9","0.47151308","1"]]}
{"instId":"BTC-USDT","action":"update","ts":"1776816041910","asks":[["76323.3","0.58968282","12"],["76324.2","0","0"],["76331","0","0"],["76334.1","0","0"],["76339.1","0","0"],["76343.4","0","0"],["76349.9","0","0"],["76374.8","0.5204023","1"],["76456","0.47151308","1"],["76456.1","0.0002254","1"],["76456.2","0.00007359","1"],["76456.3","0.00003643","1"],["76456.4","0.00002957","1"],["76456.7","0.00136499","3"]],"bids":[["76323.2","0.46266112","12"]]}
{"instId":"BTC-USDT","action":"update","ts":"1776816041920","asks":[["76323.3","0.07862258","4"],["76328","0","0"],["76330.9","0","0"],["76333.9","0","0"],["76334.7","0.00654853","1"],["76335.4","0","0"],["76337.8","0","0"],["76338.3","0.47151308","1"],["76338.5","0.15519877","1"],["76338.6","0.15910419","3"],["76340.7","0","0"],["76342.4","0.33400438","2"],["76342.5","0","0"],["76345.5","0","0"],["76349.6","1.00624645","1"],["76349.8","0","0"],["76352.7","0","0"],["76369.2","0.26471866","2"],["76377.3","0.02507727","1"],["76379.9","0.11931695","1"],["76457.1","0.01564436","4"],["76457.2","0.01573368","2"],["76457.3","1.00617669","2"],["76457.4","0.00002231","1"]],"bids":[["76318.3","0.11887711","2"],["76316.7","0","0"],["76313.6","0.0065485","1"],["76311.5","0.00001681","1"],["76311.3","1.00648389","6"],["76309.6","0.32745538","1"],["76306.9","0.006549","1"],["76304.8","0","0"],["76304.7","0.00001086","1"],["76277.9","0.02507547","1"],["76270.1","0","0"],["76268","0.00001155","1"],["76179.9","0","0"]]}
{"instId":"BTC-USDT","action":"update","ts":"1776816041930","asks":[["76323.3","0.07487687","3"],["76331.6","0.01258345","1"],["76334.7","0","0"],["76334.8","0","0"],["76337.8","0.00654848","1"],["76338.2","0.26232879","1"],["76338.5","0","0"],["76342.4","0.32745538","1"],["76345.8","0.00654891","1"],["76347","0","0"],["76353.3","0","0"],["76353.9","0.10606946","1"],["76364.4","0.13787736","1"],["76457.4","0","0"]],"bids":[["76323.2","0.56528053","14"],["76321.3","0.01468308","1"],["76318.4","0.05326083","1"],["76316.7","0.00654848","1"],["76316.6","0","0"],["76313.6","0","0"],["76312.5","0.0162517","2"],["76309.5","0.47806199","2"],["76306.9","0","0"]]}
{"instId":"BTC-USDT","action":"update","ts":"1776816041940","asks":[["76330.6","0","0"],["76331.6","0","0"],["76334.7","0.01258294","1"],["76334.9","0","0"],["76337.8","0","0"],["76337.9","0","0"],["76338.3","0","0"],["76338.6","0","0"],["76339.3","0.01088074","9"],["76341.1","0.0065485","1"],["76341.2","0.07885","1"],["76342.3","0.31031992","1"],["76342.4","0","0"],["76345.8","0","0"],["76346","0","0"],["76349.5","1.34024406","3"],["76349.6","0","0"],["76353.2","0","0"],["76380.1","0","0"],["76395.8","1.90674513","1"],["76457.4","0.00002231","1"],["76457.5","0.00001001","1"],["76457.6","0.00199545","1"],["76457.8","0.00026388","1"],["76457.9","0.00003026","1"],["76458.1","0.00001883","1"],["76458.3","0.00035006","7"],["76458.4","0.0000711","2"]],"bids":[["76323.2","0.79541787","16"],["76321.3","0.11468308","2"],["76320.2","0.01614584","1"],["76318.9","0.0262","1"],["76318.5","0.00654851","1"],["76318.4","0.16585954","2"],["76316.7","0","0"],["76315.9","0","0"],["76315.5","0.1305","1"],["76315.2","0.32744869","1"],["76312.6","0.00654892","1"],["76311.2","0.00001316","1"],["76309.6","0","0"],["76309.5","0.47151308","1"],["76303.4","0","0"],["76296.7","0.10373823","1"],["76296.4","0","0"],["76292.6","0","0"],["76290.7","0.00001034","1"],["76286.5","0.11669409","2"],["76277.3","0.10384976","1"],["76277.2","0","0"],["76274.9","0.04663392","2"],["76193.5","0","0"]]}
{"instId":"BTC-USDT","action":"update","ts":"1776816041950","asks":[["76334.7","0","0"],["76338.2","0","0"],["76338.9","0.01258224","1"],["76341.1","0","0"],["76341.2","0","0"],["76342.3","0.21061964","1"],["76346.8","0.0065485","1"],["76349.5","1.00624645","1"],["76353.4","0","0"],["76353.6","0.32745106","1"],["76353.9","0.26517365","4"],["76354.6","0.00654898","1"],["76355.5","0.06550532","1"],["76359.5","0","0"],["76361.8","0","0"],["76362.3","0.13257439","1"],["76365.2","0","0"],["76377.3","0","0"],["76384.5","0.13522588","1"],["76385.2","0.02509134","1"],["76395.8","0","0"],["76400","0.07344174","4"],["76401","1.90674513","1"],["76458.7","0.01614584","1"]],"bids":[["76323.2","0.80292201","18"],["76323.1","0","0"],["76321.4","0.04125352","1"],["76321.1","0.1067388","2"],["76319.4","0.00654898","1"],["76318.9","0","0"],["76318.5","0.45207098","2"],["76315.6","0.55530638","3"],["76315.4","0.05896264","1"],["76315.2","0","0"],["76315","0","0"],["76312.6","0","0"],["76312.4","0.00305","1"],["76311.4","0.08378297","1"],["76309.4","0.00001033","1"],["76308.9","0","0"],["76307.9","0.26157272","5"],["76306.1","0","0"],["76291","0.11433661","1"],["76290.9","0","0"],["76286.6","0.11655072","1"],["76286.5","0.00002863","1"],["76286.4","0.02513764","2"],["76285","0.10392601","1"],["76284.9","0","0"],["76282","0.00131092","1"],["76277.9","0","0"],["76277.4","0.11667579","2"],["76277.3","0","0"],["76273.6","0.00787146","2"],["76201.3","0","0"],["76179.9","0.47151308","1"],["76179.3","0.00040006","1"],["76178.9","0.0008637","1"]]}
{"instId":"BTC-USDT","action":"update","ts":"1776816041960","asks":[["76345.9","0.44127177","3"],["76346.7","0.00654795","1"],["76346.8","0","0"],["76362.5","0","0"],["76367.7","0","0"],["76376.3","0.14431727","2"],["76378","0.05241866","2"],["76458.8","0.00001501","1"],["76459.1","0.00006716","3"]],"bids":[["76321.4","0.16778421","3"],["76318.5","0.4520509","2"],["76317.1","0.00261953","1"],["76315.1","0.00023744","5"],["76309.3","0.00004629","1"],["76304.4","0","0"],["76303.4","0.11666546","1"],["76301.8","0.00523906","1"],["76294","0.00004629","1"],["76286.5","0.00788722","2"],["76277.6","0.1219816","2"],["76273.6","0.00001155","1"],["76179.3","0","0"],["76178.9","0","0"]]}
{"instId":"BTC-USDT","action":"update","ts":"1776816041970","asks":[["76341.2","0.07865","1"],["76343.4","0.0065479","1"],["76343.5","0.092078","1"],["76346.7","0","0"],["76349.4","0.32741393","1"],["76349.9","0.14971006","1"],["76353.5","0.00654824","1"],["76353.6","0","0"],["76354.6","0","0"],["76458.8","0","0"],["76459.1","0","0"]],"bids":[["76321.5","0.1108278","1"],["76321.4","0.1","1"],["76319.4","0","0"],["76318.5","0.12461992","1"],["76316.6","0.00654824","1"],["76315.7","0.32741393","1"],["76306.8","0.21963129","1"],["76180","0","0"],["76179.9","0","0"]]}
{"instId":"BTC-USDT","action":"update","ts":"1776816041980","asks":[["76343.4","0","0"],["76345.8","0.00654804","1"],["76349.4","0","0"],["76350.2","0.32741489","1"],["76353.7","0.2581666","2"]],"bids":[["76323.2","0.80500004","19"],["76318.6","0.32741489","1"],["76318.4","0.47400965","3"],["76315.7","0","0"],["76270.2","0","0"],["76269.4","0.00233684","1"]]}
{"instId":"BTC-USDT","action":"update","ts":"1776816041990","asks":[["76341.2","0.07867","1"],["76342.3","0","0"],["76349.4","0.32741617","1"],["76349.9","0.22830327","2"],["76350.2","0","0"],["76401","0","0"],["76403.5","1.92644372","2"],["76458.8","0.00001501","1"],["76459.1","0.00006716","3"]],"bids":[["76318.7","0.59348152","2"],["76318.3","0.00001034","1"],["76311.4","0.38535479","2"],["76181.4","0","0"]]}
{"instId":"BTC-USDT","action":"update","ts":"1776816042000","asks":[["76339.3","0.11751551","10"],["76349.4","0","0"],["76349.8","0.3274176","1"],["76349.9","0.14971006","1"],["76369.3","0.47151308","1"],["76376.2","0.6222494","2"],["76377","0.00130929","1"],["76378.9","0","0"]],"bids":[["76318.8","0.3274176","1"],["76318.6","0","0"],["76318.4","0","0"],["76311.5","0.12431429","2"],["76304.7","0.12728227","2"],["76303.4","0","0"],["76296.7","0","0"],["76296.4","0.1299229","1"],["76284.7","0.47284075","3"],["76277.7","0.11820934","1"],["76277.6","0.00001316","1"],["76277.4","0.00001033","1"],["76275","0.01309674","1"],["76181.4","0.001571","1"]]}
{"instId":"BTC-USDT","action":"update","ts":"1776816042010","asks":[["76342.5","0.20899223","1"],["76349.8","0","0"],["76350.2","0.32741731","1"],["76353.5","0","0"],["76353.6","0.00654828","1"],["76459.1","0","0"]],"bids":[["76318.5","0","0"],["76317.2","0.00654828","1"],["76316.6","0","0"],["76285.5","0","0"],["76256","0.00013114","1"],["76249.9","0.06462174","4"],["76247.4","0.00055534","2"],["76241.3","0","0"],["76180","0.0000812","1"],["76179.9","0.47151308","1"]]}
{"instId":"BTC-USDT","action":"update","ts":"1776816042020","asks":[["76345","0.07865","1"],["76349.4","0.32740158","1"],["76349.9","0.22830399","2"],["76350.2","0","0"],["76353.5","0.00654797","1"],["76353.6","0","0"],["76458.8","0","0"]],"bids":[["76318.8","0","0"],["76317.2","0","0"],["76316.6","0.00654797","1"],["76315.7","0.32740158","1"]]}
{"instId":"BTC-USDT","action":"update","ts":"1776816042030","asks":[["76344.9","0.00654763","1"],["76345.8","0","0"],["76349.3","0.32740123","1"],["76349.4","0","0"],["76349.9","0.14971006","1"],["76353.5","0","0"],["76353.6","0.00654789","1"],["76402.8","0.87649132","1"]],"bids":[["76316.6","0.00654789","1"],["76315.8","0.46406669","3"],["76315.7","0","0"],["76179.3","0.00040006","1"]]}
{"instId":"BTC-USDT","action":"update","ts":"1776816042040","asks":[["76343.4","0.00654763","1"],["76344.9","0","0"],["76358.1","0.11667862","2"],["76362.3","0","0"],["76401.4","0.37136985","3"],["76458.8","0.00001501","1"]],"bids":[["76321.6","0.0262","1"],["76316.6","0","0"],["76315.9","0.00654791","1"],["76286.5","0.00785859","1"],["76269.4","0.00233674","1"],["76179.3","0","0"]]}
{"instId":"BTC-USDT","action":"update","ts":"1776816042050","asks":[["76338.7","0","0"],["76341.7","0.01309","1"],["76366.8","0","0"],["76411.2","0.13771388","1"],["76459.1","0.00006716","3"]],"bids":[["76318.8","0.54471349","1"],["76318.5","0.0131","1"],["76313.5","0","0"],["76179.9","0","0"]]}
{"instId":"BTC-USDT","action":"update","ts":"1776816042060","asks":[["76343.4","0.00654762","1"],["76349.3","0","0"],["76349.4","0.32739949","1"],["76415.9","0.73774458","1"],["76459.1","0","0"]],"bids":[["76318.9","0.11666546","1"],["76316","0.00654784","1"],["76315.9","0.32739949","1"],["76315.8","0.02","1"],["76311.4","0.58969113","3"],["76227.7","0","0"],["76180","0","0"]]}
{"instId":"BTC-USDT","action":"update","ts":"1776816042070","asks":[["76341.2","0.15732","2"],["76348.3","0.05896264","1"],["76362.3","0.11560749","1"],["76419.6","0.07573329","1"],["76458.4","0","0"],["76458.7","0","0"],["76458.8","0","0"]],"bids":[["76286.7","0.12022309","1"],["76181.4","0","0"]]}
{"instId":"BTC-USDT","action":"update","ts":"1776816042080","asks":[["76386.8","0","0"],["76458.4","0.0000711","2"]],"bids":[]}
{"instId":"BTC-USDT","action":"update","ts":"1776816042090","asks":[["76360.3","0.01557609","1"],["76458.4","0","0"]],"bids":[["76312","0.01593877","1"],["76181.6","0","0"]]}
{"instId":"BTC-USDT","action":"update","ts":"1776816042110","asks":[["76342.6","0.47806068","2"],["76343.4","0","0"],["76348.2","0.32739808","1"],["76349.4","0","0"],["76350.2","0.0065479","1"],["76353.6","0","0"],["76458.4","0.0000711","2"]],"bids":[["76316","0","0"],["76315.9","0","0"],["76315.7","0.33394598","2"],["76181.6","0.00073364","2"]]}
{"instId":"BTC-USDT","action":"update","ts":"1776816042120","asks":[["76336","0.01218544","1"],["76338.9","0","0"],["76339.2","0.09505461","1"],["76342.4","0.0065476","1"],["76342.6","0.47151308","1"],["76349.6","0.00654795","1"],["76350.2","0","0"],["76358.5","0","0"],["76458.4","0","0"]],"bids":[["76323.2","0.79845154","18"],["76321.7","0.0065626","2"],["76315.7","0.32739808","1"],["76312.6","0.00654795","1"],["76227.3","0.00001316","1"],["76182.2","0","0"],["76181.6","0","0"]]}
{"instId":"BTC-USDT","action":"update","ts":"1776816042130","asks":[["76339.1","0.12196844","1"],["76358.4","0.08378297","1"],["76458.1","0","0"],["76458.3","0","0"]],"bids":[["76312","0","0"],["76255.1","0.02332185","1"],["76253.6","0.02332185","1"],["76252.5","0.02332185","1"],["76250.3","0.06996555","3"],["76249","0.02332185","1"],["76248.3","0.02332185","1"],["76246.3","0.02332185","1"],["76245","0.36323781","3"],["76244.3","0.04681221","2"],["76243.2","0.04681221","2"],["76240.5","0.02332185","1"],["76184.1","0","0"],["76184","0","0"],["76183.9","0","0"],["76183.7","0","0"],["76183.4","0","0"],["76183.3","0","0"],["76182.7","0","0"]]}
{"instId":"BTC-USDT","action":"update","ts":"1776816042140","asks":[["76342.3","0.00654767","1"],["76342.4","0","0"],["76342.7","0","0"],["76347.1","0.32740201","1"],["76348.2","0","0"],["76382.7","1.90754513","2"],["76403.5","0.01969859","1"],["76458.1","0.00001883","1"]],"bids":[["76307.9","0.20853799","4"]]}
{"instId":"BTC-USDT","action":"update","ts":"1776816042150","asks":[["76342.3","0.00654766","1"],["76347.1","0","0"],["76348.1","0.32741523","2"],["76380","0.77681852","3"],["76402.8","0","0"],["76458.3","0.00035006","7"],["76458.4","0.0000711","2"]],"bids":[["76292.6","0.05303473","1"],["76184.4","0","0"]]}
{"instId":"BTC-USDT","action":"update","ts":"1776816042160","asks":[["76401.4","0.26111823","2"],["76403.1","0.31081204","1"],["76458.4","0","0"]],"bids":[["76281.7","0","0"],["76184.4","1.00603555","1"]]}
{"instId":"BTC-USDT","action":"update","ts":"1776816042170","asks":[["76339","0.47151308","1"],["76345","0","0"],["76386.8","0.00004003","1"],["76419.6","0.13073584","2"],["76458.3","0","0"]],"bids":[["76323.2","0.7982185","18"],["76318.7","0.12196844","1"]]}
{"instId":"BTC-USDT","action":"update","ts":"1776816042180","asks":[["76338.9","0.38887431","2"],["76339.2","0","0"],["76339.3","0.01088074","9"],["76342.2","0.00654763","1"],["76342.3","0","0"],["76348","0.32740474","1"],["76348.1","0.00001316","1"],["76349.6","0","0"],["76353.6","0.00654803","1"],["76458.1","0","0"]],"bids":[["76321.8","0.00655796","2"],["76321.7","0.000015","1"],["76318.8","0.37109705","1"],["76315.9","0.00654803","1"],["76312.6","0","0"],["76286.6","0.11657935","2"]]}
{"instId":"BTC-USDT","action":"update","ts":"1776816042190","asks":[["76349.9","0.15625824","2"],["76353.6","0","0"],["76458.1","0.00001883","1"]],"bids":[["76315.9","0","0"],["76315.5","0.13704818","2"],["76184.1","0.47151308","1"]]}
{"instId":"BTC-USDT","action":"update","ts":"1776816042200","asks":[["76349.6","0.00654826","1"],["76349.9","0.14971006","1"],["76458.1","0","0"]],"bids":[["76315.5","0.1305","1"],["76312.6","0.00654826","1"],["76184.1","0","0"]]}
{"instId":"BTC-USDT","action":"update","ts":"1776816042210","asks":[["76349.6","0","0"],["76349.8","0.00654826","1"]],"bids":[["76315.2","0.00654826","1"],["76312.6","0","0"]]}
{"instId":"BTC-USDT","action":"update","ts":"1776816042220","asks":[],"bids":[["76318.8","0.84261013","2"]]}
{"instId":"BTC-USDT","action":"update","ts":"1776816042230","asks":[["76349.6","0.00654833","1"],["76349.8","0","0"]],"bids":[["76315.2","0","0"],["76312.6","0.00654833","1"]]}
{"instId":"BTC-USDT","action":"update","ts":"1776816042240","asks":[["76347.1","0.32741922","1"],["76348","0","0"]],"bids":[]}
{"instId":"BTC-USDT","action":"update","ts":"1776816042260","asks":[["76341.1","0.00654763","1"],["76342.2","0","0"],["76353.9","0.21213892","3"]],"bids":[["76321.8","0.00001033","1"],["76321.7","0.00656263","2"],["76307.9","0.15686142","3"]]}
{"instId":"BTC-USDT","action":"update","ts":"1776816042270","asks":[["76338.6","0.05303473","1"],["76457.9","0","0"]],"bids":[["76321.5","0.08071993","1"],["76292.6","0.1047113","2"]]}
{"instId":"BTC-USDT","action":"update","ts":"1776816042280","asks":[],"bids":[["76230.7","1.02903643","4"]]}
{"instId":"BTC-USDT","action":"update","ts":"1776816042300","asks":[["76341.1","0","0"],["76341.5","0.00654768","1"],["76346.8","0.32742284","1"],["76347.1","0","0"]],"bids":[]}
{"instId":"BTC-USDT","action":"update","ts":"1776816042330","asks":[["76341.1","0.00654769","1"],["76341.5","0","0"]],"bids":[["76321.7","0.000015","1"],["76321.2","0.00657309","3"]]}
{"instId":"BTC-USDT","action":"update","ts":"1776816042360","asks":[],"bids":[["76321.2","0.0000254","2"],["76320.3","0.00654775","1"],["76315.7","0","0"],["76311.6","0.32742222","1"],["76184.4","0","0"]]}
{"instId":"BTC-USDT","action":"update","ts":"1776816042370","asks":[],"bids":[["76318.8","0.74488181","2"]]}
{"instId":"BTC-USDT","action":"update","ts":"1776816042390","asks":[],"bids":[["76282.3","0.03298463","2"],["76184.8","0","0"]]}
{"instId":"BTC-USDT","action":"update","ts":"1776816042400","asks":[],"bids":[["76311.7","0.09773553","1"],["76185.3","0","0"]]}
{"instId":"BTC-USDT","action":"update","ts":"1776816042410","asks":[],"bids":[["76310.3","0.01902535","2"]]}
{"instId":"BTC-USDT","action":"update","ts":"1776816042430","asks":[["76338.6","0","0"],["76457.9","0.00003026","1"]],"bids":[["76292.6","0.05303473","1"]]}
{"instId":"BTC-USDT","action":"update","ts":"1776816042450","asks":[["76353.9","0.26517365","4"]],"bids":[["76307.9","0.20853799","4"]]}
{"instId":"BTC-USDT","action":"update","ts":"1776816042460","asks":[["76353.9","0.21213892","3"]],"bids":[["76307.9","0.15686142","3"]]}
{"instId":"BTC-USDT","action":"update","ts":"1776816042470","asks":[["76338.6","0.05303473","1"],["76457.9","0","0"]],"bids":[["76292.6","0.1047113","2"]]}
{"instId":"BTC-USDT","action":"update","ts":"1776816042480","asks":[["76345.8","0.32742121","1"],["76346.8","0","0"]],"bids":[["76311.8","0.32743276","2"],["76311.6","0","0"],["76185.3","0.00002512","1"]]}
{"instId":"BTC-USDT","action":"update","ts":"1776816042490","asks":[],"bids":[["76311.9","0.09773868","1"],["76311.7","0","0"]]}
{"instId":"BTC-USDT","action":"update","ts":"1776816042510","asks":[["76338.8","0.16","1"],["76457.8","0","0"]],"bids":[["76323.2","0.9582185","19"],["76321.6","0.1862","2"]]}
{"instId":"BTC-USDT","action":"update","ts":"1776816042520","asks":[],"bids":[["76321.7","0.15850372","2"],["76321.5","0","0"],["76184.8","0.01614584","1"]]}
{"instId":"BTC-USDT","action":"update","ts":"1776816042540","asks":[["76338.6","0","0"],["76457.8","0.00026388","1"]],"bids":[["76292.6","0","0"],["76184.4","1.00603555","1"]]}
{"instId":"BTC-USDT","action":"update","ts":"1776816042550","asks":[["76353.9","0.26517365","4"]],"bids":[["76307.9","0.20853799","4"]]}
{"instId":"BTC-USDT","action":"update","ts":"1776816042580","asks":[],"bids":[["76310.3","0.00305","1"]]}
{"instId":"BTC-USDT","action":"update","ts":"1776816042620","asks":[],"bids":[["76292.6","0.05303473","1"],["76184.4","0","0"]]}
{"instId":"BTC-USDT","action":"update","ts":"1776816042640","asks":[["76338.8","0","0"],["76457.9","0.00003026","1"]],"bids":[]}
{"instId":"BTC-USDT","action":"update","ts":"1776816042660","asks":[],"bids":[["76211.5","0","0"],["76184.4","1.00603555","1"]]}
{"instId":"BTC-USDT","action":"update","ts":"1776816042730","asks":[["76345.8","0","0"],["76346.8","0.32741541","1"]],"bids":[["76315.5","0.45791541","2"],["76311.8","0.00001155","1"]]}
{"instId":"BTC-USDT","action":"update","ts":"1776816042740","asks":[],"bids":[["76318.9","0.62851434","2"],["76318.8","0.47151308","1"],["76311.9","0","0"],["76184.1","0.47151308","1"]]}
{"instId":"BTC-USDT","action":"update","ts":"1776816042760","asks":[],"bids":[["76315.5","0.1305","1"],["76311.6","0.32741592","1"],["76184.1","0","0"]]}
{"instId":"BTC-USDT","action":"update","ts":"1776816042770","asks":[],"bids":[["76311.7","0.09773365","1"],["76184.4","0","0"]]}
{"instId":"BTC-USDT","action":"update","ts":"1776816042830","asks":[["76365.6","1.00748379","2"]],"bids":[]}
{"instId":"BTC-USDT","action":"update","ts":"1776816042860","asks":[["76353.9","0.21213892","3"]],"bids":[["76307.9","0.15686142","3"]]}
{"instId":"BTC-USDT","action":"update","ts":"1776816042870","asks":[["76338.6","0.05303473","1"],["76457.9","0","0"]],"bids":[["76292.6","0.1047113","2"]]}
{"instId":"BTC-USDT","action":"update","ts":"1776816042890","asks":[],"bids":[["76321.8","0.00655821","2"],["76320.3","0","0"],["76315.7","0.32741986","1"],["76311.6","0","0"],["76184.4","1.00603555","1"]]}
{"instId":"BTC-USDT","action":"update","ts":"1776816042900","asks":[],"bids":[["76321.8","0.00001033","1"],["76320.4","0.00654787","1"],["76315.7","0","0"],["76311.8","0.32743138","2"],["76311.7","0","0"],["76184.1","0.47151308","1"]]}
{"instId":"BTC-USDT","action":"update","ts":"1776816042910","asks":[],"bids":[["76311.9","0.09773827","1"],["76214.1","0.00514643","1"],["76184.4","0","0"],["76184.1","0","0"]]}
{"instId":"BTC-USDT","action":"update","ts":"1776816042930","asks":[["76380.2","1.90674513","1"],["76382.7","0.0008","1"],["76457.8","0","0"]],"bids":[]}
{"instId":"BTC-USDT","action":"update","ts":"1776816042940","asks":[],"bids":[["76315.5","0.45792333","2"],["76311.8","0.00001155","1"]]}
{"instId":"BTC-USDT","action":"update","ts":"1776816042950","asks":[["76338.6","0","0"],["76457.8","0.00026388","1"]],"bids":[["76311.9","0","0"],["76292.6","0","0"],["76184.4","1.00603555","1"],["76184.1","0.47151308","1"]]}
{"instId":"BTC-USDT","action":"update","ts":"1776816042960","asks":[],"bids":[["76315.5","0.1305","1"],["76311.6","0.32742313","1"],["76184.1","0","0"]]}
{"instId":"BTC-USDT","action":"update","ts":"1776816042970","asks":[],"bids":[["76311.7","0.0977358","1"],["76184.4","0","0"]]}
{"instId":"BTC-USDT","action":"update","ts":"1776816042980","asks":[],"bids":[["76307.9","0.20853799","4"]]}
{"instId":"BTC-USDT","action":"update","ts":"1776816043010","asks":[],"bids":[["76313.4","0.01585128","1"],["76184.8","0","0"]]}
{"instId":"BTC-USDT","action":"update","ts":"1776816043030","asks":[],"bids":[["76286.6","0.11655072","1"],["76260.6","0.00001316","1"]]}
{"instId":"BTC-USDT","action":"update","ts":"1776816043040","asks":[["76353.9","0.26517365","4"]],"bids":[["76292.6","0.05303473","1"],["76185.3","0","0"]]}
{"instId":"BTC-USDT","action":"update","ts":"1776816043070","asks":[["76341.1","0.00654788","1"],["76348.2","0.00654836","1"],["76349.6","0","0"]],"bids":[["76320.4","0","0"],["76320.3","0.00654788","1"],["76312.7","0.00654836","1"],["76312.6","0","0"]]}
{"instId":"BTC-USDT","action":"update","ts":"1776816043090","asks":[],"bids":[["76260.6","0.00324706","2"]]}
{"instId":"BTC-USDT","action":"update","ts":"1776816043120","asks":[],"bids":[["76292.6","0","0"],["76185.3","0.00002512","1"]]}
{"instId":"BTC-USDT","action":"update","ts":"1776816043130","asks":[],"bids":[["76307.9","0.26157272","5"]]}
{"instId":"BTC-USDT","action":"update","ts":"1776816043160","asks":[],"bids":[["76307.9","0.20853799","4"]]}
{"instId":"BTC-USDT","action":"update","ts":"1776816043170","asks":[],"bids":[["76292.6","0.05303473","1"],["76185.3","0","0"]]}
{"instId":"BTC-USDT","action":"update","ts":"1776816043180","asks":[],"bids":[["76286.7","0.12025172","2"]]}
{"instId":"BTC-USDT","action":"update","ts":"1776816043190","asks":[["76338.8","0.16","1"],["76457.8","0","0"]],"bids":[["76321.8","0.16001033","2"],["76321.6","0.0262","1"]]}
{"instId":"BTC-USDT","action":"update","ts":"1776816043200","asks":[],"bids":[["76321.7","0.11074376","2"]]}
{"instId":"BTC-USDT","action":"update","ts":"1776816043210","asks":[],"bids":[["76282.3","0","0"],["76185.3","0.00002512","1"]]}
{"instId":"BTC-USDT","action":"update","ts":"1776816043290","asks":[["76348.2","0","0"],["76349.4","0.00654837","1"]],"bids":[["76321.8","0.16655822","3"],["76320.3","0","0"],["76315.7","0.32742192","1"],["76313.5","0.00654837","1"],["76312.7","0","0"],["76311.6","0","0"],["76184.8","0.01614584","1"]]}
{"instId":"BTC-USDT","action":"update","ts":"1776816043300","asks":[["76345.8","0.3274219","1"],["76346.8","0","0"]],"bids":[["76321.8","0.16001033","2"],["76320.3","0.00654789","1"],["76315.7","0","0"],["76311.8","0.32743345","2"],["76311.7","0","0"],["76184.4","1.00603555","1"]]}
{"instId":"BTC-USDT","action":"update","ts":"1776816043310","asks":[["76348.2","0.00654837","1"],["76349.4","0","0"]],"bids":[["76313.5","0","0"],["76312.6","0.00654837","1"],["76311.9","0.09773888","1"],["76184.4","0","0"]]}
{"instId":"BTC-USDT","action":"update","ts":"1776816043350","asks":[["76345.8","0","0"],["76346.8","0.32742176","1"]],"bids":[["76320.3","0.00654787","1"],["76312","0.32742176","1"],["76311.8","0.00001155","1"],["76184.8","0","0"]]}
{"instId":"BTC-USDT","action":"update","ts":"1776816043360","asks":[],"bids":[["76312.1","0.09773884","1"],["76311.9","0","0"]]}
{"instId":"BTC-USDT","action":"update","ts":"1776816043370","asks":[["76323.3","0","0"],["76327.9","0","0"],["76331.3","0","0"],["76334.6","0","0"],["76336","0.34715183","7"],["76338","0","0"],["76338.8","0","0"],["76338.9","0.27220885","1"],["76339","0","0"],["76339.1","0","0"],["76341.1","0","0"],["76341.2","0","0"],["76341.5","0.00654793","1"],["76341.6","0","0"],["76342.6","0","0"],["76345.1","0.03","2"],["76346.8","0","0"],["76346.9","0","0"],["76347.2","0","0"],["76348.2","0","0"],["76348.3","0","0"],["76349.4","0.47806145","2"],["76349.5","0","0"],["76349.7","0","0"],["76350.3","0","0"],["76353.8","0","0"],["76353.9","0","0"],["76355.5","0","0"],["76358.4","0","0"],["76358.5","1.00624645","1"],["76358.7","0","0"],["76364.4","0","0"],["76365.2","1.00624645","1"],["76365.6","0.00133225","1"],["76371.6","0.00001316","1"],["76380.2","0","0"],["76384.5","0","0"],["76395.7","1.90339437","1"],["76457.8","0.00026388","1"],["76457.9","0.00003026","1"],["76458.1","0.00001883","1"],["76458.3","0.00035006","7"],["76458.4","0.0000711","2"],["76458.7","0.01614584","1"],["76458.8","0.00001501","1"],["76459.1","0.00006716","3"],["76459.2","0.08410468","3"],["76459.3","0.00319921","2"],["76459.6","0.00072458","2"],["76459.7","0.0000534","1"],["76459.8","0.00203787","4"],["76459.9","1.5419822","2"],["76460","0.03539391","5"],["76460.1","0.0022005","4"],["76460.2","0.00162671","12"],["76460.6","0.00002799","2"],["76460.7","0.00167279","1"],["76460.9","0.00030148","3"],["76461.1","0.00003024","1"],["76461.3","0.00027039","1"]],"bids":[["76335.9","0.80984497","13"],["76331.2","0.0062","1"],["76327.9","0.31926078","3"],["76327.8","0.36176734","4"],["76323.4","0.1305","1"],["76323.3","0.28603167","1"],["76323.2","0.50555451","11"],["76321.9","0.47807602","3"],["76321.8","0.00001033","1"],["76321.6","0","0"],["76321.3","0.11469624","3"],["76320.3","0","0"],["76319","1.33390558","7"],["76318.9","0.51184888","1"],["76316.5","0.00001086","1"],["76315.8","0","0"],["76313.5","0.00654837","1"],["76312.6","0","0"],["76312","0","0"],["76307.9","0.00001316","1"],["76292.6","0","0"],["76290.1","0.06540031","2"],["76285","0","0"],["76277.7","0","0"],["76274.2","0","0"],["76258.8","0.02331696","1"],["76227.3","0","0"],["76227.1","0","0"],["76184.8","0.01614584","1"],["76184.1","0.47151308","1"],["76183.9","0.00003806","1"],["76183.7","0.00001319","1"]]}
{"instId":"BTC-USDT","action":"update","ts":"1776816043380","asks":[["76336","0.37208721","10"],["76338.9","0","0"],["76341.5","0","0"],["76342.5","0.03646207","1"],["76342.7","0.01218437","1"],["76345","0.00654793","1"],["76345.1","0","0"],["76345.9","0.1417183","2"],["76349.3","0.12725024","1"],["76349.4","0.47151308","1"],["76349.9","0","0"],["76353.6","0.0065483","1"],["76353.7","0","0"],["76354.6","0.12725024","1"],["76354.9","0.07869","1"],["76358.3","0.08378297","1"],["76358.6","0","0"],["76360.3","0","0"],["76362.4","0","0"],["76365.5","0","0"],["76366.6","0.26517365","4"],["76368.9","0.1192971","1"],["76374.3","0.15098019","5"],["76380","0.25094478","2"],["76384.5","0.11664605","1"],["76393.9","0.11420777","1"],["76416","0","0"],["76420.5","0","0"]],"bids":[["76335.9","0.7174963","13"],["76330.1","0.01565521","1"],["76328","0.20330005","3"],["76327.9","0.15751631","1"],["76327.8","0.24669867","3"],["76323.5","0.00654793","1"],["76323.3","0","0"],["76323.2","0.52257027","11"],["76321.9","0.57152809","3"],["76321.5","0.05896264","1"],["76321.3","0.10001316","2"],["76320.6","0.05167657","1"],["76319","1.00648389","6"],["76318.7","0","0"],["76318.2","0.00305","1"],["76315.7","0.45061601","3"],["76315.4","0","0"],["76313.5","0","0"],["76313.4","0","0"],["76312.4","0","0"],["76312.1","0","0"],["76305.3","0.20988299","3"],["76304.9","0.00305","1"],["76295.1","0","0"],["76286.7","0.00002863","1"],["76284.9","0.11664605","1"],["76271","0","0"],["76266.2","0.02331696","1"],["76184","0.1305","1"],["76183.9","0","0"],["76183.7","0","0"]]}
{"instId":"BTC-USDT","action":"update","ts":"1776816043390","asks":[["76345","0","0"],["76345.8","0.00654735","1"],["76346.3","0.47151308","1"],["76354.5","0.10356038","1"],["76365","0.12194814","1"],["76372.1","0","0"],["76375.5","0","0"],["76375.6","0","0"],["76379.8","0.00130924","1"],["76391.3","0.1192971","1"],["76391.5","0.06541544","1"],["76395.7","0","0"],["76403.5","1.92309296","2"],["76415.9","0","0"],["76461.3","0","0"]],"bids":[["76330.1","0","0"],["76328.1","0.18134324","1"],["76328","0.00001316","1"],["76323.2","0.5029351","10"],["76321.7","0.21074376","3"],["76321.1","0.0067388","1"],["76315.8","0.32739166","1"],["76315.7","0.12319435","2"],["76305.3","0.15910419","2"],["76304.9","0.12499814","2"],["76304.6","0","0"],["76283.1","0.03399526","2"],["76269.2","0.16589954","1"],["76184","0","0"]]}
{"instId":"BTC-USDT","action":"update","ts":"1776816043400","asks":[["76336","0.40797667","11"],["76345.8","0.14440199","2"],["76345.9","0.30145777","3"],["76354.9","0.15732","2"],["76362.4","0.06550532","1"],["76365.1","0.65208714","2"],["76403.1","0.83923856","2"],["76461.1","0","0"]],"bids":[["76332.4","0.01565474","1"],["76328.1","0.1206621","1"],["76327.9","0","0"],["76323.5","0.19563176","2"],["76322","0.2859527","1"],["76321.7","0.100015","2"],["76321.5","0.15896264","2"],["76321.3","0.00001316","1"],["76315.9","0.32739035","1"],["76315.8","0","0"],["76315.6","0.47152341","2"],["76299.5","0.06480091","1"],["76293.6","0","0"],["76222.6","0.000655","1"],["76184.1","0","0"]]}
{"instId":"BTC-USDT","action":"update","ts":"1776816043410","asks":[["76342.5","0","0"],["76343.4","0.07715214","2"],["76345.8","0.13785443","1"]],"bids":[["76328.1","0.07364348","1"],["76323.5","0.19563139","2"],["76323.2","0.2629351","8"],["76322","0.3859527","2"],["76321.4","0","0"],["76320.8","0.0000935","2"],["76260.6","0.00337819","3"],["76256","0","0"],["76184.1","0.47151308","1"],["76183.9","0.00003806","1"]]}
{"instId":"BTC-USDT","action":"update","ts":"1776816043420","asks":[["76336","0.41097216","12"],["76343.4","0.07060458","1"],["76345.7","0.0065476","1"],["76346.3","0.50151308","3"],["76354.4","0.41117631","2"],["76364.6","0.01576061","1"],["76377","0","0"],["76380.3","0","0"],["76385.6","0.00130914","1"],["76399.5","0","0"],["76460.9","0","0"]],"bids":[["76323.6","0.0065476","1"],["76323.5","0.11744383","1"],["76323.2","0.26085707","7"],["76319.1","0.32741014","2"],["76317","0.01593082","1"],["76315.9","0","0"],["76290.2","0.00135708","2"],["76282","0","0"],["76277.8","0.00325289","1"],["76273.2","1.00616208","1"],["76252","0.00054216","1"],["76247.4","0.00001316","1"],["76184.1","0","0"],["76183.9","0","0"]]}
{"instId":"BTC-USDT","action":"update","ts":"1776816043430","asks":[["76336","0.41471745","13"],["76345.7","0.14175262","2"],["76354.3","0.24976756","1"],["76354.5","0","0"],["76393.9","0","0"],["76396.9","0","0"],["76425","0.67712762","11"],["76429.6","0.65793148","2"],["76460.9","0.00030148","3"],["76461.1","0.00003024","1"]],"bids":[["76335.9","0.65244728","12"],["76318.9","0","0"],["76285.5","0.00325285","1"],["76282.7","0.00233657","1"],["76280","0.6592912","2"],["76277.8","0","0"],["76275.2","0.660765","1"],["76269.4","0","0"]]}
{"instId":"BTC-USDT","action":"update","ts":"1776816043440","asks":[["76343.4","0.10193663","2"],["76364.6","0","0"],["76366.6","0.15910419","3"],["76401","1.90339437","1"],["76403.5","0.01969859","1"]],"bids":[["76319.1","0.85685632","3"]]}
{"instId":"BTC-USDT","action":"update","ts":"1776816043450","asks":[["76354.6","0.18621288","2"],["76403.1","0.31081204","1"]],"bids":[["76327.9","0.03","2"],["76327.6","0.05896264","1"],["76321.5","0.1","1"],["76185.3","0","0"],["76184.8","0","0"]]}
{"instId":"BTC-USDT","action":"update","ts":"1776816043460","asks":[["76336","0.47754745","14"],["76351.3","0.10606946","1"],["76366.6","0.10606946","2"],["76461.1","0","0"]],"bids":[["76320.6","0.0507788","1"]]}
{"instId":"BTC-USDT","action":"update","ts":"1776816043470","asks":[["76349.3","0","0"],["76349.9","0.04062514","1"],["76351.2","0.32738732","1"],["76351.3","0.15910419","2"],["76354.4","0.08378297","1"],["76460.9","0","0"]],"bids":[["76326.8","0.0262","1"],["76319.2","0.32738732","1"],["76319.1","0.52946298","2"],["76305.3","0.21078076","3"],["76186.1","0","0"],["76186","0","0"]]}
{"instId":"BTC-USDT","action":"update","ts":"1776816043480","asks":[["76349.3","1.00624645","1"],["76349.9","0.14898728","2"],["76354.3","0","0"],["76386.8","0","0"],["76460.9","0.00030148","3"]],"bids":[["76332.4","0","0"],["76319.3","0.10894591","2"],["76304.7","0.00001086","1"],["76273.4","0.00323371","1"],["76260.6","0.00014429","2"]]}
{"instId":"BTC-USDT","action":"update","ts":"1776816043490","asks":[["76338.6","0.00001299","1"],["76342.8","0.16","1"],["76345.9","0.55237076","2"],["76377.2","0.06493305","1"],["76460.6","0","0"],["76460.7","0","0"],["76460.9","0","0"]],"bids":[["76330","0.01565524","1"],["76320.8","0.0000463","1"],["76299.3","0.11969861","2"],["76186.4","0","0"]]}
{"instId":"BTC-USDT","action":"update","ts":"1776816043500","asks":[["76342.7","0.19198961","2"],["76343.4","0","0"],["76353.6","0","0"],["76354.3","0.00654774","1"],["76460.6","0.00002799","2"]],"bids":[["76318.3","0.00655808","2"],["76315.7","0.11664605","1"]]}
{"instId":"BTC-USDT","action":"update","ts":"1776816043510","asks":[["76342.6","0.47151308","1"],["76393","0.1","1"],["76460.2","0","0"],["76460.6","0","0"]],"bids":[["76333.3","0.00003389","1"],["76277.1","0.42386124","3"],["76270.8","0","0"],["76267.4","0.00019775","1"],["76261","0","0"],["76252","0.00054218","1"]]}
{"instId":"BTC-USDT","action":"update","ts":"1776816043520","asks":[["76342.5","0.30311346","1"],["76342.7","0.01218437","1"],["76385.3","1.90339437","1"],["76401","0","0"],["76409.3","0.00093709","1"],["76460","0","0"],["76460.1","0","0"]],"bids":[]}
{"instId":"BTC-USDT","action":"update","ts":"1776816043540","asks":[["76379.8","0","0"],["76387.6","0.00130911","1"],["76412.7","0.00002082","1"],["76459.9","0","0"]],"bids":[]}
{"instId":"BTC-USDT","action":"update","ts":"1776816043580","asks":[["76349.3","1.09002942","2"]],"bids":[]}
{"instId":"BTC-USDT","action":"update","ts":"1776816043590","asks":[["76351.9","0.01614584","1"],["76459.8","0","0"]],"bids":[["76286.7","0","0"],["76186.4","0.00022771","1"]]}
{"instId":"BTC-USDT","action":"update","ts":"1776816043620","asks":[["76399.2","0.00004008","1"],["76459.7","0","0"]],"bids":[]}
{"instId":"BTC-USDT","action":"update","ts":"1776816043660","asks":[["76365","0.13796485","2"]],"bids":[["76317","0","0"],["76186.1","6.4292","1"]]}
{"instId":"BTC-USDT","action":"update","ts":"1776816043670","asks":[["76342.7","0","0"],["76354.5","0.14463178","1"],["76366.6","0","0"],["76459.7","0.0000534","1"]],"bids":[["76331.2","0","0"],["76320.6","0","0"],["76299.4","0.00002863","1"],["76186","0.00170529","1"]]}
{"instId":"BTC-USDT","action":"update","ts":"1776816043680","asks":[["76336","0.48374745","15"],["76339.2","0.01218493","1"],["76351.3","0.21213892","3"],["76459.7","0","0"]],"bids":[["76335.9","0.52105681","11"],["76327.8","0.21069867","2"],["76305.3","0.26155956","4"],["76303.4","0.12194963","1"],["76296.4","0","0"]]}
{"instId":"BTC-USDT","action":"update","ts":"1776816043710","asks":[["76351.2","0","0"],["76354.3","0.33394125","2"],["76459.7","0.0000534","1"]],"bids":[["76319.4","0.32739351","1"],["76319.2","0","0"]]}
{"instId":"BTC-USDT","action":"update","ts":"1776816043720","asks":[["76349.9","0.07191257","1"]],"bids":[]}
{"instId":"BTC-USDT","action":"update","ts":"1776816043740","asks":[["76351.2","0.32739378","1"],["76354.3","0.00654774","1"],["76459.7","0","0"]],"bids":[]}
{"instId":"BTC-USDT","action":"update","ts":"1776816043750","asks":[["76349.9","0.16563957","2"]],"bids":[["76299.6","0.11906735","1"],["76299.2","0","0"]]}
{"instId":"BTC-USDT","action":"update","ts":"1776816043760","asks":[["76351.3","0.26517365","4"]],"bids":[]}
{"instId":"BTC-USDT","action":"update","ts":"1776816043800","asks":[["76351.2","0","0"],["76354.3","0.33394564","2"],["76459.7","0.0000534","1"]],"bids":[]}
{"instId":"BTC-USDT","action":"update","ts":"1776816043810","asks":[["76349.9","0.07191257","1"]],"bids":[["76190.9","0.02066065","5"]]}
{"instId":"BTC-USDT","action":"update","ts":"1776816043820","asks":[["76351.2","0.32739739","1"],["76354.3","0.00654774","1"],["76459.7","0","0"]],"bids":[]}
{"instId":"BTC-USDT","action":"update","ts":"1776816043830","asks":[["76349.9","0.18147152","2"]],"bids":[]}
{"instId":"BTC-USDT","action":"update","ts":"1776816043850","asks":[],"bids":[["76319.2","0.01569221","1"],["76186","0","0"]]}
{"instId":"BTC-USDT","action":"update","ts":"1776816044000","asks":[["76336","0.50648745","17"]],"bids":[]}
{"instId":"BTC-USDT","action":"update","ts":"1776816044010","asks":[["76345.6","0.00654746","1"],["76345.7","0.13520502","1"],["76459.6","0","0"]],"bids":[["76335.9","0.5210568","10"],["76318.3","0.00001034","1"],["76318","0.00654791","1"],["76186.1","0","0"]]}
{"instId":"BTC-USDT","action":"update","ts":"1776816044020","asks":[["76345.6","0.11625472","2"],["76345.8","0","0"],["76354.3","0.12321462","2"],["76358.1","0.00001316","1"],["76459.6","0.00072458","2"]],"bids":[]}
{"instId":"BTC-USDT","action":"update","ts":"1776816044040","asks":[["76345.5","0.00654748","1"],["76345.6","0.10970726","1"],["76459.6","0","0"]],"bids":[["76283.2","0.00233655","1"],["76282.7","0","0"]]}
{"instId":"BTC-USDT","action":"update","ts":"1776816044050","asks":[["76345.7","0","0"],["76459.6","0.00072458","2"]],"bids":[]}
{"instId":"BTC-USDT","action":"update","ts":"1776816044060","asks":[["76427","0.13645429","1"],["76459.6","0","0"]],"bids":[]}
{"instId":"BTC-USDT","action":"update","ts":"1776816044070","asks":[["76336","0","0"],["76337.2","0","0"],["76338.6","0","0"],["76339.2","0","0"],["76339.3","0","0"],["76340.6","0","0"],["76341","0","0"],["76342.5","0","0"],["76342.6","0","0"],["76342.8","0","0"],["76344.8","0","0"],["76345.5","0","0"],["76345.6","0","0"],["76345.9","0.000084","1"],["76346.3","0","0"],["76349.3","0","0"],["76349.4","0","0"],["76349.9","0","0"],["76351.2","0","0"],["76351.3","0","0"],["76351.9","0","0"],["76354.3","0","0"],["76354.4","0","0"],["76354.6","0","0"],["76354.7","0","0"],["76354.9","0","0"],["76356.9","0.07866","1"],["76358.3","0","0"],["76358.5","0","0"],["76359.6","0","0"],["76362.3","0","0"],["76362.4","0.47151308","1"],["76362.7","0","0"],["76365","0","0"],["76365.1","0.56830417","1"],["76365.2","0","0"],["76365.3","0","0"],["76365.6","0.47284533","2"],["76365.8","0.00649862","1"],["76368.7","0.47151308","1"],["76368.9","0","0"],["76369","0","0"],["76369.3","0","0"],["76369.6","0","0"],["76371.1","0","0"],["76372.6","0.47151308","1"],["76374.3","0.01047472","4"],["76375.8","1.56137509","3"],["76376","0","0"],["76376.2","0.15073632","1"],["76379.9","0","0"],["76382.1","0","0"],["76384.4","1.00607904","1"],["76384.5","0.58815913","2"],["76384.7","0","0"],["76385.2","0","0"],["76385.3","0","0"],["76385.4","0.00076482","1"],["76385.6","0","0"],["76388.7","0","0"],["76391.3","0","0"],["76395.4","1.00607904","1"],["76395.9","0.12771188","2"],["76396","0","0"],["76397.4","0.47151308","1"],["76397.9","0.00130893","1"],["76398.8","0.01309214","1"],["76401.3","0.15596914","2"],["76406.8","0.10623115","1"],["76459.6","0.00072458","2"],["76459.7","0.0000534","1"],["76459.8","0.00203787","4"],["76459.9","1.5419822","2"],["76460","0.03539391","5"],["76460.1","0.0022005","4"],["76460.2","0.00162671","12"],["76460.6","0.00002799","2"],["76460.7","0.00167279","1"],["76460.9","0.00030148","3"],["76461.1","0.00003024","1"],["76461.3","0.00027039","1"],["76461.4","0.0312605","1"],["76461.5","0.01228943","9"],["76461.6","0.00332668","1"],["76461.7","0.00001025","1"],["76462","0.00002228","1"],["76462.2","0.00551437","1"],["76462.3","0.00027227","4"],["76462.5","0.00001257","1"],["76462.6","0.47226231","9"],["76463","0.00004357","1"],["76463.1","0.00001427","1"],["76463.2","0.00059244","1"],["76463.3","0.08378297","1"],["76463.4","0.00010604","1"],["76463.9","0.00088649","6"],["76464.1","0.00005359","1"],["76464.2","0.0025747","2"],["76464.4","0.00019338","3"],["76464.6","0.00012165","3"],["76464.7","0.00497942","3"],["76465","0.00044","2"],["76465.1","0.00002105","1"],["76465.5","0.00119834","3"],["76465.7","0.00001316","1"],["76465.8","0.00071318","6"],["76466","0.0059052","2"],["76466.2","0.00014238","2"],["76466.5","0.00028078","2"]],"bids":[["76340.5","0.424793","5"],["76339.3","0.34507866","3"],["76339.2","0.69691384","11"],["76339.1","0.11507142","2"],["76338.5","0.036","1"],["76337.1","0.31496472","3"],["76336","0.12","1"],["76335.9","0.23163","3"],["76330.1","0.00654744","1"],["76330","0.11565524","2"],["76328.2","0.79891404","2"],["76327","0.06550532","1"],["76326.8","0","0"],["76323.6","0","0"],["76321.7","0.000015","1"],["76321.5","0","0"],["76319.5","0.08378297","1"],["76319.4","0","0"],["76319.3","0.00694802","2"],["76318","0","0"],["76308.8","0","0"],["76305.3","0","0"],["76300.1","0.01309214","1"],["76299.3","0.00040006","1"],["76294.1","0.00131071","1"],["76291","0","0"],["76290.2","0.0000463","1"],["76286.6","0","0"],["76286.4","0.0000463","1"],["76284.9","0","0"],["76284.7","0.47152988","2"],["76275.3","0.00131104","1"],["76275","0","0"],["76235.5","0","0"],["76231","0.08378297","1"],["76211.3","0","0"],["76186.4","0","0"]]}
{"instId":"BTC-USDT","action":"update","ts":"1776816044080","asks":[["76341.3","0","0"],["76341.4","0","0"],["76343.5","0","0"],["76344.7","0","0"],["76354.5","0.02661298","1"],["76359","0.11198459","2"],["76361.5","0.12197517","2"],["76365","0.11665931","1"],["76365.1","0","0"],["76365.5","0.092085","1"],["76366.9","0","0"],["76369.2","0.07952187","1"],["76369.9","0","0"],["76371.6","0.15114","2"],["76372","0.15910419","2"],["76372.5","0.1305","1"],["76375.7","0.12196201","1"],["76376.3","0.00019343","1"],["76380","0.0000812","1"],["76381.1","0.12998121","2"],["76381.9","0.10759348","1"],["76384.6","0","0"],["76387.6","0","0"],["76387.8","0","0"],["76388.5","0","0"],["76389.4","0.10739424","1"],["76391.3","0.11931066","1"],["76395.6","0.00130897","1"],["76396.8","0.345751","1"],["76397.3","0","0"],["76400","0.0144791","3"],["76402.8","1.00607904","1"],["76403.5","0","0"],["76417.5","0.20397616","3"],["76421.8","1.90339437","1"],["76425","0.01765762","10"],["76429.6","0.00001048","1"],["76459.9","0.0000212","1"],["76461.5","0.14278943","10"],["76466.6","0.00546094","15"]],"bids":[["76341.6","0.57049132","14"],["76341.3","0.51122291","5"],["76341.2","0.00411183","2"],["76340.5","0.15962024","3"],["76339.4","0.00654664","1"],["76339.3","0","0"],["76339.2","0.036","1"],["76339.1","0","0"],["76337.2","0.3273976","1"],["76337.1","0.22211856","2"],["76336","0","0"],["76335.9","0.34022781","7"],["76330.4","1.00607904","1"],["76330.2","0.00654761","1"],["76330.1","0.15932396","1"],["76330","0.25266365","2"],["76329.5","0.00001501","1"],["76328.8","0.01614584","1"],["76328.2","0.47151308","1"],["76328.1","0.07669348","2"],["76327.9","0","0"],["76327.8","0.09563","1"],["76327.6","0","0"],["76326","0.26155956","4"],["76324.9","0.00261926","1"],["76323.6","0.08378297","1"],["76322","0.1","1"],["76321.9","0.47152809","2"],["76319.3","0.00040006","1"],["76318.2","0","0"],["76317.1","0","0"],["76315.8","0.1182628","1"],["76315.7","0","0"],["76309.6","0.00523852","1"],["76307.9","0.1441033","2"],["76307","0.06545485","1"],["76306.6","0.05239641","1"],["76301.8","0","0"],["76299.6","0","0"],["76296.3","0.61732655","1"],["76293.7","0","0"],["76290.1","0.00001086","1"],["76284.8","1.66095437","3"],["76280","0.0000812","1"],["76279.1","0.01047704","1"],["76263.8","0.0130963","1"],["76263.5","0","0"],["76254.6","0","0"],["76244.9","0.12","1"],["76243.1","0","0"],["76227.6","0","0"],["76193.4","0.00002624","1"],["76187.1","0","0"],["76187","0","0"],["76186.6","0","0"]]}
{"instId":"BTC-USDT","action":"update","ts":"1776816044090","asks":[["76356.7","0.01314216","1"],["76358.9","0.03357554","1"],["76373.5","0.06550532","1"],["76375.8","1.47759212","2"],["76376.2","0","0"],["76377.2","0","0"],["76396.6","0.19257336","1"],["76397","0","0"],["76403.2","0.02331962","1"],["76404.5","0.02572474","1"],["76431.7","1.00761","1"],["76466.2","0","0"],["76466.5","0","0"],["76466.6","0","0"]],"bids":[["76341.6","0.58114915","17"],["76341.4","0.22492023","1"],["76341.3","0.036","1"],["76341.2","0","0"],["76340.5","0.17498949","4"],["76339.4","0.1","1"],["76338.6","0.32735894","1"],["76337.2","0","0"],["76336","0.00654711","1"],["76335.9","0.32059264","6"],["76335.1","0.00305","1"],["76330.8","0.00261906","1"],["76330.5","0.18028989","1"],["76330.2","0","0"],["76330.1","0","0"],["76330","0.1","1"],["76329.6","0.00305","1"],["76328.1","0","0"],["76324.9","0","0"],["76323.2","0.14615168","6"],["76322.1","0.12461213","1"],["76322","0","0"],["76319.2","0.11665816","1"],["76318.5","0.01615","2"],["76315.5","0.13573812","2"],["76310.3","0","0"],["76309.6","0","0"],["76308.2","0","0"],["76305.6","0.02572474","1"],["76304.9","0.12194814","1"],["76300.2","0.00785718","1"],["76299.5","0","0"],["76296.4","0.12461213","1"],["76286.5","0","0"],["76280","0.01055812","2"],["76279.1","0","0"],["76276.2","0.04982072","1"],["76275.2","0","0"],["76264.7","0.01309615","1"],["76263.8","0","0"],["76254.9","0.06736618","3"],["76221","0","0"],["76187.1","0.00001197","1"],["76187","0.00011911","5"],["76186.6","0.00683192","1"]]}
{"instId":"BTC-USDT","action":"update","ts":"1776816044100","asks":[["76358.9","0.1502337","2"],["76362.3","0.22835712","1"],["76365.4","0.17249886","1"],["76368.6","0.23335455","1"],["76369.2","0","0"],["76381.9","0","0"],["76384.3","0.56331321","1"],["76396.6","0","0"],["76403.1","0","0"],["76406.7","0.10526836","1"],["76406.8","0","0"],["76408","0.0134511","1"]],"bids":[["76341.6","0.68114915","18"],["76338.6","0","0"],["76337.2","0.1474505","1"],["76337.1","0.1305","1"],["76336","0.33390605","2"],["76330.8","0.16965234","2"],["76330.5","0.7050384","2"],["76328.3","0.08378297","1"],["76326.1","0.18566872","1"],["76323.6","0.14274561","2"],["76323.5","0","0"],["76323.2","0.04615168","5"],["76322","0.07588488","1"],["76314.8","0.05239603","1"],["76306.6","0","0"],["76296.7","0.12461213","1"],["76296.4","0","0"],["76283.1","0.01697538","1"],["76273.9","0","0"],["76238","0","0"],["76235.3","0.08378297","1"]]}
{"instId":"BTC-USDT","action":"update","ts":"1776816044110","asks":[["76358.8","0.53991108","2"],["76358.9","0.11665816","1"],["76377.9","0.0720415","1"],["76380.4","0.13994625","1"],["76391.5","0","0"],["76395.3","0.62388191","1"],["76395.6","0","0"],["76396.6","0.19398469","1"],["76403.7","0.00130883","1"],["76406.9","0.74037081","3"],["76408","0","0"],["76422.3","0","0"],["76438.8","0.00044174","3"],["76444.1","0.00034519","4"],["76449.9","0.00005654","1"],["76450.4","0","0"],["76454.2","0.0000119","1"],["76456.7","0.00135308","2"],["76465.8","0","0"],["76466","0","0"]],"bids":[["76341.4","0","0"],["76337.8","0.01614584","1"],["76337.3","0.32735022","1"],["76337.2","0.15399757","2"],["76336","0","0"],["76335.9","0.29059264","4"],["76333.3","0","0"],["76283.1","0","0"],["76279.6","0.00019775","1"],["76267.4","0","0"],["76265.8","0.03927764","1"],["76254.9","0.04235696","2"],["76249.9","0.02481496","3"],["76245.7","0.20472245","1"],["76240.2","0","0"],["76203","0.09847197","2"],["76187.1","0","0"],["76186.4","0.00022771","1"],["76186.1","6.4292","1"],["76186","0.00170529","1"]]}
{"instId":"BTC-USDT","action":"update","ts":"1776816044120","asks":[["76341.7","0","0"],["76347.4","0.00709","1"],["76358.7","0.22956145","1"],["76358.8","0.47151308","1"],["76360.3","0.01","1"],["76361.8","0.02","1"],["76365.7","0.07876","1"],["76393","0","0"],["76396.6","0","0"],["76397.9","0","0"],["76406.9","0.74167959","4"],["76413.7","0.01979102","1"],["76465.5","0","0"],["76465.7","0","0"]],"bids":[["76342.8","0.143348","3"],["76341.3","0.136","2"],["76337.4","0.10397086","1"],["76337.3","0","0"],["76337.2","0","0"],["76336.1","0.47151308","1"],["76336","0.32734921","1"],["76335.2","0.00654694","1"],["76330","0","0"],["76323.9","0.0131","1"],["76318.5","0.00305","1"],["76306.3","0.30279","1"],["76296.8","0.1068999","1"],["76296.7","0","0"],["76296","0.0002805","9"],["76291.8","0.2822","1"],["76282.5","0","0"],["76281.5","0","0"],["76186.4","0","0"],["76186.1","0","0"],["76186","0","0"]]}
{"instId":"BTC-USDT","action":"update","ts":"1776816044130","asks":[["76342.9","0","0"],["76344.4","0","0"],["76345.9","0","0"],["76347.4","0.03945511","4"],["76348.1","0","0"],["76351.4","0","0"],["76354.5","0","0"],["76356.9","0","0"],["76358.8","0","0"],["76359","0.00041663","1"],["76360.3","0","0"],["76361.5","0.00001316","1"],["76372","0","0"],["76381.2","0.01515321","1"],["76382","0","0"],["76389.3","0.09551952","1"],["76405.1","0.19883972","1"],["76409.3","0","0"],["76412.7","0","0"],["76413.7","0","0"],["76431.6","0.47151308","1"],["76465.5","0.00119834","3"],["76465.7","0.00001316","1"],["76465.8","0.00071318","6"],["76466","0.0059052","2"],["76466.2","0.00014238","2"],["76466.5","0.00028078","2"],["76466.6","0.00546094","15"],["76466.7","0.00025453","6"],["76467.1","0.00181702","1"],["76467.2","0.00011781","1"]],"bids":[["76347.3","0.94009669","17"],["76342.8","0.27247606","8"],["76341.6","0.1","1"],["76338.6","0.32733205","1"],["76337.8","0","0"],["76337.5","0.00654654","1"],["76337.4","0","0"],["76336","0","0"],["76335.9","0.3264763","4"],["76335.2","0","0"],["76330.9","0.12096737","1"],["76330.8","0.00261906","1"],["76330.5","0.52474851","1"],["76326.2","0.10510624","1"],["76326","0","0"],["76322.2","0.11664945","1"],["76322.1","0","0"],["76303.4","0","0"],["76299.2","0.11664945","1"],["76296.8","0","0"],["76296.4","0.10853733","1"],["76290.3","0.00325228","1"],["76288.5","0.00233595","1"],["76285.5","0","0"],["76283.2","0","0"],["76243.9","0","0"],["76186.4","0.00022771","1"]]}
{"instId":"BTC-USDT","action":"update","ts":"1776816044140","asks":[["76347.4","0.04021314","5"],["76358.7","0.03509496","1"],["76364.9","0.01201316","2"],["76380.4","0","0"],["76382.4","0.08378297","1"],["76405.1","0","0"],["76467.3","0.00050101","1"]],"bids":[["76347.3","0.94428214","19"],["76346.6","0.015368","1"],["76342.8","0.2486553","5"],["76340.5","0.15962024","3"],["76339.3","0.0065462","1"],["76337.5","0","0"],["76331","0.17497418","1"],["76330.9","0","0"],["76328.9","0.01590145","1"],["76326.2","0.12460283","1"],["76326.1","0","0"],["76322.2","0","0"],["76322.1","0.11664945","1"],["76299.3","0.11704951","2"],["76299.2","0","0"],["76296.7","0.10810926","1"],["76296.4","0","0"],["76268.3","0.01598","1"],["76186.4","0","0"]]}
{"instId":"BTC-USDT","action":"update","ts":"1776816044150","asks":[["76347.4","0.0333","4"],["76361.8","0","0"],["76364.5","0","0"],["76364.7","0.00691314","1"],["76375.6","0.08378297","1"],["76379","0","0"],["76380.4","0.11235283","1"],["76385.3","0.29343","1"],["76399.8","0.18783","1"],["76405.1","0.19323793","1"],["76467.1","0","0"],["76467.2","0","0"],["76467.3","0","0"]],"bids":[["76347.3","1.05082768","21"],["76342.8","0.24210924","4"],["76341.6","0.22","3"],["76341.4","0.32731355","1"],["76340.4","0.00305","1"],["76339.4","0","0"],["76338.6","0","0"],["76338","0.0131","1"],["76337.2","0.10483922","1"],["76335.1","0","0"],["76332","0.10245537","2"],["76323.9","0","0"],["76320.4","0.30279","1"],["76306.3","0","0"],["76305.9","0.2822","1"],["76291.8","0","0"],["76186.6","0","0"]]}
{"instId":"BTC-USDT","action":"update","ts":"1776816044160","asks":[["76362.3","0.14283184","1"],["76373.7","0.05896264","1"],["76377.9","0","0"],["76378","0.31759231","6"],["76400","0.07344174","4"],["76405.1","0","0"],["76467.1","0.00181702","1"]],"bids":[["76347.3","1.04428214","20"],["76346.7","0.00654569","1"],["76332","0.26155956","4"],["76187","0","0"]]}
{"instId":"BTC-USDT","action":"update","ts":"1776816044170","asks":[["76361.8","0.01","1"],["76363.5","0","0"],["76364.8","0.00139625","2"],["76365","0.11717641","2"],["76367.9","0.00073763","1"],["76368.5","1.00607904","1"],["76369.5","0.07866","1"],["76371.5","0.08378297","1"],["76372.4","0.32731087","1"],["76377.9","0.09512858","1"],["76405.1","0.19974301","1"],["76409.1","0","0"],["76465.8","0","0"],["76466","0","0"],["76466.2","0","0"],["76466.5","0","0"],["76466.6","0","0"],["76466.7","0","0"],["76467.1","0","0"]],"bids":[["76347.3","1.05082805","21"],["76346.7","0","0"],["76341.6","0.1","1"],["76332.1","0.47151308","1"],["76328.3","0","0"],["76328.2","0.50451308","2"],["76322.8","0","0"],["76319","1.00624645","1"],["76318.3","0","0"],["76315.1","0","0"],["76313","0","0"],["76311.3","1.00624645","1"],["76307.7","0.00001681","1"],["76307.5","0","0"],["76303.7","0","0"],["76302.4","0","0"],["76299.9","0","0"],["76296","0.00003273","3"],["76292.2","0","0"],["76290.7","0","0"],["76288.4","0","0"],["76285.4","0.05896264","1"],["76284.6","0","0"],["76280.8","0","0"],["76280.1","0","0"],["76276.9","0","0"],["76274.8","0.08378297","1"],["76273.1","0","0"],["76269.5","0.00001681","1"],["76269.3","0.071281","1"],["76265.5","0","0"],["76264.2","0.00001316","1"],["76261.7","0","0"],["76187","0.00011911","5"],["76186.6","0.00683192","1"],["76186.4","0.00022771","1"],["76186.1","6.4292","1"],["76186","0.00170529","1"],["76185.3","0.00002512","1"],["76184.8","0.01614584","1"],["76184.1","0.47151308","1"],["76183.9","0.00003806","1"],["76183.7","0.00001319","1"],["76183.4","0.00005866","1"],["76183.3","0.00009283","1"],["76182.7","0.00002401","2"],["76182.2","0.00875","1"],["76181.6","0.00073364","2"],["76181.4","0.001571","1"],["76180","0.0000812","1"],["76179.9","0.47151308","1"],["76179.3","0.00040006","1"]]}
{"instId":"BTC-USDT","action":"update","ts":"1776816044180","asks":[["76347.4","0.027069","3"],["76365.4","0.47448986","2"],["76366.9","0.00654597","1"],["76374.2","0.0065463","1"],["76399.2","0","0"],["76405.1","0","0"],["76406.7","0.10530844","2"]],"bids":[["76345.2","0.05896264","1"],["76342.3","0.02619","1"],["76335.9","0.13163","2"],["76321.8","0","0"],["76315.6","0.47151308","1"],["76309.4","0","0"],["76303.2","1.09810255","2"],["76296","0.0000224","2"],["76294.2","0.00325225","1"],["76292.8","0.00233595","1"],["76290.3","0","0"],["76289.8","0","0"],["76288.5","0","0"],["76283.6","0","0"],["76278.4","0.00323302","1"],["76277.4","0","0"],["76273.4","0","0"],["76271.2","0","0"],["76265","0","0"],["76184","0.1305","1"],["76178.9","0.0008637","1"],["76177.9","0.00004571","1"],["76177.8","0.00105547","4"],["76175.4","0.00003868","3"]]}
{"instId":"BTC-USDT","action":"update","ts":"1776816044190","asks":[["76354.4","0.01314255","1"],["76356.7","0","0"],["76361.8","0.03","2"],["76401.4","0.50913709","3"],["76405.1","0.19442494","1"],["76465.7","0","0"]],"bids":[["76345.3","0.09768767","1"],["76296.9","0.00325226","1"],["76294.2","0","0"],["76175.4","0","0"]]}
{"instId":"BTC-USDT","action":"update","ts":"1776816044200","asks":[["76402.8","1.11810797","2"],["76405.1","0","0"],["76465.7","0.00001316","1"]],"bids":[["76341.5","0.2103022","1"],["76340.2","0.00004297","1"],["76177.9","0","0"],["76177.8","0","0"]]}
{"instId":"BTC-USDT","action":"update","ts":"1776816044210","asks":[["76347.4","0.025869","2"],["76402.8","1.06007213","2"],["76405.1","0.1914511","1"],["76465.7","0","0"]],"bids":[["76344.7","0.00003372","1"],["76343.4","0.03","2"],["76337.2","0.30641815","2"],["76274.3","0.0001443","2"],["76265.7","0.00054219","1"],["76260.6","0.00001316","1"],["76252","0","0"],["76179.3","0","0"],["76178.9","0","0"]]}
{"instId":"BTC-USDT","action":"update","ts":"1776816044220","asks":[["76397.9","0.1","1"],["76402.8","1.11031737","3"],["76405.1","0","0"],["76419.1","1.90466427","1"],["76421.8","0","0"]],"bids":[["76347.3","1.04428214","20"],["76346.7","0.00654606","1"],["76339.3","0","0"],["76338.6","0.00654653","1"],["76337.1","0.13051501","2"],["76332.2","0.27183377","1"],["76322.9","0","0"],["76322.4","0","0"],["76319.1","0.52944618","1"],["76316.5","0","0"],["76315.3","0","0"],["76311.5","0.12429748","1"],["76310.6","0","0"],["76307.7","0","0"],["76304.7","0","0"],["76303.8","0","0"],["76300","0.00358153","3"],["76296.2","1.47767516","2"],["76296","0.00001154","1"],["76295.2","0.18378297","2"],["76292.4","0","0"],["76290.1","0","0"],["76288.6","0","0"],["76284.7","0.47151308","1"],["76284.2","0","0"],["76280.9","0","0"],["76278.3","0.00346789","4"],["76277.1","0.42384443","2"],["76273.3","0.76659385","1"],["76272.4","0","0"],["76269.5","0","0"],["76266.5","0","0"],["76179.3","0.00040006","1"],["76178.9","0.0008637","1"],["76177.9","0.00004571","1"],["76177.8","0.00105547","4"],["76175.4","0.00003868","3"],["76175.1","0.47151308","1"],["76175","0.00029601","2"],["76173.7","0.00070045","3"],["76173.6","0.00002308","1"],["76173.2","0.00001006","1"],["76173","0.00001059","1"],["76171.1","0.00001024","1"],["76170.8","0.00003094","3"],["76170.6","0.0001094","1"]]}
{"instId":"BTC-USDT","action":"update","ts":"1776816044230","asks":[["76367","0.00630842","1"],["76402.8","1.06007213","2"],["76407.5","0.19668307","1"],["76408.7","1.90466427","1"],["76419","1.24815709","2"],["76419.1","0","0"],["76419.6","0","0"]],"bids":[["76346.7","0","0"],["76345.4","0.00654602","1"],["76323","0","0"],["76322","0.28826842","2"],["76321.1","0","0"],["76319.2","0","0"],["76317.4","0","0"],["76311.8","0","0"],["76306.2","0","0"],["76303.4","0.12223212","1"],["76296.7","0","0"],["76296","0","0"],["76295.4","0","0"],["76290.4","0","0"],["76284.8","1.66094282","2"],["76279.2","0","0"],["76273.6","0","0"],["76268","0","0"],["76176.3","0.1305","1"],["76170.2","0.00001385","1"],["76168.9","0.000015","1"],["76168.4","0.00011049","4"],["76167","0.00001319","1"],["76166.6","0.00248493","6"],["76166.2","0.00026145","4"],["76165.9","0.47151308","1"],["76165.8","0.01614584","1"],["76165.2","0.00091086","3"],["76165.1","0.00001015","1"],["76164.3","0.00046091","2"]]}
{"instId":"BTC-USDT","action":"update","ts":"1776816044240","asks":[["76371.4","0.32733071","1"],["76372.4","0","0"],["76378","0.21152285","5"],["76406.7","0.10526836","1"],["76407.5","0","0"],["76411.1","0.00004008","1"],["76416.1","0.54092717","1"],["76419","0.345809","1"],["76465.5","0","0"]],"bids":[["76346.6","0.115368","2"],["76341.4","0","0"],["76340.5","0.05962024","2"],["76339.3","0.32733071","1"],["76332","0.10245537","2"],["76326.3","0.13253404","1"],["76284.8","1.66417594","3"],["76278.4","0","0"],["76168.6","0.1305","1"],["76164.3","0","0"]]}
{"instId":"BTC-USDT","action":"update","ts":"1776816044250","asks":[["76347.4","0.0009","1"],["76362.7","0.10606946","1"],["76364.9","0.00001316","1"],["76377.9","0.06346685","1"],["76403.5","1.90466427","1"],["76407.5","0.19716665","1"],["76408.7","0","0"],["76411.1","0","0"],["76465.1","0","0"]],"bids":[["76345.4","0.10654602","2"],["76341.3","0.036","1"],["76316.7","0.15910419","2"],["76314.9","0.02051357","1"],["76165.2","0","0"],["76165.1","0","0"]]}
{"instId":"BTC-USDT","action":"update","ts":"1776816044260","asks":[["76347.4","0.0307","2"],["76362.7","0","0"],["76364.8","0.0005858","1"],["76402.8","1.6217115","3"],["76407.5","0","0"],["76465.1","0.00002105","1"],["76465.5","0.00119834","3"]],"bids":[["76341.5","0.15062025","1"],["76316.7","0.10606946","1"],["76310.5","0.11118788","1"],["76307.9","0.00001316","1"],["76165.8","0","0"]]}
{"instId":"BTC-USDT","action":"update","ts":"1776816044270","asks":[["76364.8","0","0"],["76366.8","0.00007241","1"],["76372.8","0.00654657","1"],["76374.2","0","0"],["76407.5","0.19642538","1"],["76422.4","0.60264703","2"],["76465.5","0","0"]],"bids":[["76338.6","0","0"],["76338.1","0.00654657","1"],["76332","0.1554901","3"],["76299.4","0.0999244","2"],["76187.7","0.47151308","1"]]}
{"instId":"BTC-USDT","action":"update","ts":"1776816044280","asks":[["76358.6","0.47151308","1"],["76365","0.11665931","1"],["76372.8","0","0"],["76373.4","0.00654658","1"],["76418.9","0.49663434","2"],["76465.1","0","0"]],"bids":[["76285.5","0.04260956","1"],["76165.9","0","0"]]}
{"instId":"BTC-USDT","action":"update","ts":"1776816044290","asks":[["76358.5","0.17584162","1"],["76358.7","0","0"],["76364.9","0.00655923","2"],["76366.9","0","0"],["76367.9","0","0"],["76465.1","0.00002105","1"],["76465.5","0.00119834","3"]],"bids":[["76345.5","0.00654607","1"],["76345.4","0.1","1"],["76332","0.10245537","2"],["76303.9","0.00002863","1"],["76299.4","0.09989577","1"],["76285.4","0","0"],["76255.1","0.07489484","2"],["76166.2","0","0"]]}
{"instId":"BTC-USDT","action":"update","ts":"1776816044300","asks":[["76372.4","0.00654659","1"],["76373.4","0","0"],["76431.5","0.50625924","1"],["76465.5","0","0"]],"bids":[["76340.2","0","0"],["76338.1","0","0"],["76337.3","0.00654659","1"],["76305","0.00002863","1"],["76303.9","0","0"],["76285.5","0.02500922","1"],["76166.2","0.00026145","4"]]}
{"instId":"BTC-USDT","action":"update","ts":"1776816044310","asks":[["76364.6","0.00654607","1"],["76364.9","0.00001316","1"],["76397.9","0","0"],["76440.6","0.65960789","2"],["76442.2","0.58002835","3"],["76445.1","0.65931113","6"]],"bids":[["76345.5","0","0"],["76343.5","0.00654607","1"],["76334.2","0.00014036","4"],["76330.4","1.00620907","4"],["76328","0.00002349","2"],["76326.6","0.00013003","3"],["76322.8","0.00013004","3"],["76321.8","0.00001033","1"],["76319","1.00637649","4"],["76315.6","0.47152341","2"],["76315.1","0.00013004","3"],["76311.3","1.00637649","4"],["76309.4","0.00001033","1"],["76307.5","0.00013006","3"],["76305","0.11960353","2"],["76303.7","0.00013006","3"],["76303.4","0","0"],["76303.2","1.09811288","3"],["76299.9","0.00013006","3"],["76295.5","0.659076","1"],["76290.7","0.66063","1"],["76277.3","0.0001311","1"],["76274.3","0.00001319","1"],["76268.8","0.00054218","1"],["76265.7","0","0"],["76254.2","1.54613116","2"],["76235.3","0.64142828","2"],["76173","0","0"],["76171.1","0","0"],["76170.8","0","0"],["76170.6","0","0"],["76170.2","0","0"],["76168.9","0","0"],["76168.6","0","0"],["76168.4","0","0"],["76167","0","0"],["76166.6","0","0"],["76166.2","0","0"]]}
{"instId":"BTC-USDT","action":"update","ts":"1776816044320","asks":[["76362.7","0.10606946","1"],["76434.7","0.48331491","7"],["76465.1","0","0"]],"bids":[["76334.2","0.00024776","6"],["76330.4","1.00631647","6"],["76326.6","0.00023743","5"],["76322.8","0.00023744","5"],["76319","1.00648389","6"],["76316.7","0.15910419","2"],["76315.1","0.00023744","5"],["76311.3","1.00648389","6"],["76307.5","0.00023747","5"],["76303.7","0.00023748","5"],["76299.9","0.00023748","5"],["76290.8","0.33740722","2"]]}
{"instId":"BTC-USDT","action":"update","ts":"1776816044330","asks":[["76369.4","0.00006929","1"],["76437.4","0.36669523","2"],["76465","0","0"]],"bids":[["76334.2","0.0002581","7"],["76328.9","0.01591179","2"],["76323.6","0.14275595","3"],["76318.3","0.00001034","1"],["76313","0.00001035","1"],["76307.7","0.00001035","1"],["76306.8","0.31786656","2"],["76302.4","0.00001035","1"],["76273.3","0.77329028","2"],["76247.6","0.00703125","1"],["76175.1","0","0"],["76175","0","0"],["76173.7","0","0"],["76173.6","0","0"],["76173.2","0","0"]]}
{"instId":"BTC-USDT","action":"update","ts":"1776816044340","asks":[["76347.4","0.03240402","4"],["76442.2","0.11274873","3"]],"bids":[["76337.3","0","0"],["76336.2","0.00654664","1"],["76253.5","0.000015","1"],["76235.3","0.08378297","1"]]}
{"instId":"BTC-USDT","action":"update","ts":"1776816044350","asks":[["76378","0.15848812","4"]],"bids":[["76332","0.0507788","1"],["76308.1","0.00002863","1"],["76305","0.1195749","1"],["76175.4","0","0"]]}
{"instId":"BTC-USDT","action":"update","ts":"1776816044360","asks":[],"bids":[["76310.7","0.00002863","1"],["76308.1","0","0"]]}
{"instId":"BTC-USDT","action":"update","ts":"1776816044370","asks":[["76362.7","0.15910419","2"],["76366.8","0","0"],["76465","0.00044","2"]],"bids":[["76316.7","0.21078076","3"]]}
{"instId":"BTC-USDT","action":"update","ts":"1776816044380","asks":[],"bids":[["76334.7","0.00001316","1"],["76176.3","0","0"]]}
{"instId":"BTC-USDT","action":"update","ts":"1776816044390","asks":[["76381.4","0.01566129","1"],["76465","0","0"]],"bids":[["76331.4","0.00001316","1"],["76328.9","0.00001034","1"],["76177.8","0","0"]]}
{"instId":"BTC-USDT","action":"update","ts":"1776816044400","asks":[["76411.1","0.00004008","1"],["76464.7","0","0"]],"bids":[["76344.7","0.00004804","2"],["76214.1","0","0"],["76177.8","0.00105547","4"]]}
{"instId":"BTC-USDT","action":"update","ts":"1776816044410","asks":[["76404.4","0.1","1"],["76464.6","0","0"]],"bids":[]}
{"instId":"BTC-USDT","action":"update","ts":"1776816044420","asks":[],"bids":[["76342","0.0000168","1"],["76338.2","0.0000168","1"],["76334.4","0.0000168","1"],["76334.2","0.0002805","9"],["76330.6","0.0000168","1"],["76328.6","0.00001155","1"],["76328.3","0.00001086","1"],["76326.8","0.0000168","1"],["76323","0.00001155","1"],["76322.9","0.0000168","1"],["76322.4","0.00001086","1"],["76319.1","0.52946298","2"],["76317.4","0.00001155","1"],["76316.5","0.00001086","1"],["76315.3","0.00001681","1"],["76311.8","0.00001155","1"],["76311.5","0.12431429","2"],["76310.6","0.00001086","1"],["76307.7","0.00002716","2"],["76306.2","0.00001155","1"],["76304.7","0.00001086","1"],["76184.8","0","0"],["76184.1","0","0"],["76184","0","0"],["76183.9","0","0"],["76183.7","0","0"],["76183.4","0","0"],["76183.3","0","0"],["76182.7","0","0"],["76182.2","0","0"],["76181.6","0","0"],["76181.4","0","0"],["76180","0","0"],["76179.9","0","0"],["76179.3","0","0"],["76178.9","0","0"],["76177.9","0","0"],["76177.8","0","0"]]}
{"instId":"BTC-USDT","action":"update","ts":"1776816044430","asks":[["76369.4","0","0"],["76464.6","0.00012165","3"]],"bids":[]}
{"instId":"BTC-USDT","action":"update","ts":"1776816044450","asks":[],"bids":[["76310.7","0","0"],["76309.6","0.00002863","1"]]}
{"instId":"BTC-USDT","action":"update","ts":"1776816044480","asks":[["76358.4","0.16","1"],["76464.6","0","0"]],"bids":[]}
{"instId":"BTC-USDT","action":"update","ts":"1776816044500","asks":[],"bids":[["76292.4","0.033392","2"],["76187.6","0.00303","1"],["76186","0","0"],["76185.3","0","0"]]}
{"instId":"BTC-USDT","action":"update","ts":"1776816044530","asks":[["76362.7","0","0"],["76464.6","0.00012165","3"]],"bids":[["76316.7","0.15910419","2"]]}
{"instId":"BTC-USDT","action":"update","ts":"1776816044540","asks":[],"bids":[["76338.2","0.10657753","2"]]}
{"instId":"BTC-USDT","action":"update","ts":"1776816044550","asks":[["76378","0.31759231","6"]],"bids":[["76332","0.10245537","2"]]}
{"instId":"BTC-USDT","action":"update","ts":"1776816044560","asks":[["76378","0.10545339","3"],["76381.2","0","0"],["76464.7","0.00497942","3"]],"bids":[["76332","0.0507788","1"]]}
{"instId":"BTC-USDT","action":"update","ts":"1776816044570","asks":[["76377.9","0.03180511","1"],["76442.2","0.14441047","4"]],"bids":[["76332","0","0"],["76254.3","0.98869034","1"]]}
{"instId":"BTC-USDT","action":"update","ts":"1776816044580","asks":[["76362.7","0.21213892","3"],["76464.7","0","0"]],"bids":[["76332.2","0","0"],["76254.3","0","0"],["76250.1","0","0"],["76245.7","0","0"],["76186","0.00170529","1"],["76185.3","0.00002512","1"],["76184.8","0.01614584","1"],["76184.1","0.47151308","1"]]}
{"instId":"BTC-USDT","action":"update","ts":"1776816044590","asks":[],"bids":[["76316.7","0.20988299","3"],["76304.9","0","0"],["76183.9","0.00003806","1"]]}
{"instId":"BTC-USDT","action":"update","ts":"1776816044600","asks":[],"bids":[["76184","0.1305","1"],["76183.9","0","0"]]}
{"instId":"BTC-USDT","action":"update","ts":"1776816044610","asks":[["76416.4","0.01908052","1"],["76464.6","0","0"]],"bids":[["76298.5","0.01915971","1"],["76207.9","0.01445819","1"],["76184.1","0","0"],["76184","0","0"]]}
{"instId":"BTC-USDT","action":"update","ts":"1776816044620","asks":[],"bids":[["76332.2","0.19376718","1"],["76184.8","0","0"]]}
{"instId":"BTC-USDT","action":"update","ts":"1776816044630","asks":[["76378","0.05241866","2"]],"bids":[["76316.7","0.26155956","4"],["76300.4","0.12488934","1"],["76254.3","0.98869034","1"],["76186","0","0"],["76185.3","0","0"]]}
{"instId":"BTC-USDT","action":"update","ts":"1776816044640","asks":[["76377.9","0.01597425","1"],["76381.2","0.01523777","1"],["76464.4","0","0"]],"bids":[["76330.4","1.02184349","7"],["76245.7","0.37864832","1"],["76186.1","0","0"]]}
{"instId":"BTC-USDT","action":"update","ts":"1776816044650","asks":[["76362.7","0.26517365","4"]],"bids":[["76235.4","0.00514499","1"],["76186.4","0","0"]]}
{"instId":"BTC-USDT","action":"update","ts":"1776816044660","asks":[["76362.3","0.20565779","2"]],"bids":[]}
{"instId":"BTC-USDT","action":"update","ts":"1776816044720","asks":[],"bids":[["76320.7","0.092085","1"],["76303.2","1.00604588","2"],["76186.6","0","0"]]}
{"instId":"BTC-USDT","action":"update","ts":"1776816044730","asks":[["76362.7","0.10606946","2"]],"bids":[["76346.6","0.1","1"],["76316.7","0.1047113","2"],["76250.1","0.26527569","1"],["76187","0","0"]]}
{"instId":"BTC-USDT","action":"update","ts":"1776816044740","asks":[["76378","0.21152285","4"],["76381.4","0","0"],["76464.4","0.00019338","3"]],"bids":[["76344.2","0.0153685","1"],["76332.2","0.20990243","2"],["76332","0.15684826","2"],["76187.6","0","0"],["76187.5","0","0"]]}
{"instId":"BTC-USDT","action":"update","ts":"1776816044750","asks":[["76377.9","0.06142457","2"]],"bids":[]}
{"instId":"BTC-USDT","action":"update","ts":"1776816044810","asks":[],"bids":[["76332","0","0"],["76187.6","0.00303","1"]]}
{"instId":"BTC-USDT","action":"update","ts":"1776816044820","asks":[],"bids":[["76198.5","0","0"],["76187.5","0.00032499","3"]]}
{"instId":"BTC-USDT","action":"update","ts":"1776816044830","asks":[],"bids":[["76316.7","0.26155956","4"]]}
{"instId":"BTC-USDT","action":"update","ts":"1776816044880","asks":[["76458.3","0.02085311","8"]],"bids":[]}
{"instId":"BTC-USDT","action":"update","ts":"1776816044900","asks":[],"bids":[["76314.7","0.06319536","1"],["76187.5","0","0"]]}
{"instId":"BTC-USDT","action":"update","ts":"1776816044910","asks":[],"bids":[["76314.9","0.0367613","2"]]}
{"instId":"BTC-USDT","action":"update","ts":"1776816044930","asks":[["76378","0.10545339","3"]],"bids":[]}
{"instId":"BTC-USDT","action":"update","ts":"1776816044940","asks":[["76362.7","0.21213892","3"],["76377.9","0.02976284","1"]],"bids":[]}
{"instId":"BTC-USDT","action":"update","ts":"1776816044950","asks":[["76358.5","0.33584162","2"]],"bids":[]}
{"instId":"BTC-USDT","action":"update","ts":"1776816045010","asks":[["76369.4","0.32733943","1"],["76371.3","0.00654673","1"],["76371.4","0","0"],["76372.4","0","0"]],"bids":[["76339.3","0","0"],["76338.3","0.32733943","1"]]}
{"instId":"BTC-USDT","action":"update","ts":"1776816045020","asks":[],"bids":[["76338.3","0","0"],["76337.3","0.32733942","1"]]}
{"instId":"BTC-USDT","action":"update","ts":"1776816045030","asks":[],"bids":[["76341.5","0.08275846","1"]]}
{"instId":"BTC-USDT","action":"update","ts":"1776816045040","asks":[["76378","0.05241866","2"]],"bids":[]}
{"instId":"BTC-USDT","action":"update","ts":"1776816045050","asks":[["76377.9","0.01597425","1"]],"bids":[]}
{"instId":"BTC-USDT","action":"update","ts":"1776816045060","asks":[["76362.7","0.26517365","4"]],"bids":[]}
{"instId":"BTC-USDT","action":"update","ts":"1776816045070","asks":[],"bids":[["76310.2","0.00131044","1"],["76306.7","0.00132551","2"],["76294.1","0","0"],["76275.3","0","0"],["76257.4","0.12","1"]]}
{"instId":"BTC-USDT","action":"update","ts":"1776816045080","asks":[],"bids":[["76337.2","0.10483922","1"],["76306","0.12225037","1"],["76299.3","0.00040006","1"],["76187.6","0","0"]]}
{"instId":"BTC-USDT","action":"update","ts":"1776816045090","asks":[],"bids":[["76337.4","0.34996538","1"],["76299.4","0","0"]]}
{"instId":"BTC-USDT","action":"update","ts":"1776816045100","asks":[["76358.1","0.10994392","2"],["76362.6","0.0065462","1"],["76364.6","0","0"],["76368.4","0.32733942","1"],["76369.4","0","0"],["76371.3","0","0"],["76371.4","0.00654673","1"]],"bids":[["76347.3","0.93042373","19"],["76343.5","0","0"],["76342.9","0.0065462","1"],["76337.3","0","0"],["76336.2","0.32733942","1"],["76334.3","0.00654673","1"],["76299.2","0.07067567","1"],["76187.7","0","0"]]}
{"instId":"BTC-USDT","action":"update","ts":"1776816045110","asks":[["76347.4","0.03241402","5"],["76358.3","0.27136162","1"],["76358.5","0.16","1"],["76362.6","0","0"],["76364.6","0.0065462","1"],["76368.3","0.11693514","1"],["76368.4","0","0"],["76369.4","0.32733951","1"],["76375.7","0","0"],["76380.3","0.12225037","1"],["76384.5","0.47151308","1"],["76406.7","0","0"],["76464.4","0","0"]],"bids":[["76343.5","0.0065462","1"],["76342.9","0","0"],["76340.5","0.036","1"],["76337.5","0.32733951","1"],["76336.2","0","0"],["76257.5","0.09451576","1"],["76255.1","0.02332185","1"],["76187.9","0","0"]]}
{"instId":"BTC-USDT","action":"update","ts":"1776816045120","asks":[["76371.6","0.00001316","1"],["76381.1","0.00006516","1"],["76384.2","0.11959275","1"],["76402.7","0.15966785","2"],["76464.2","0","0"]],"bids":[["76337.4","0","0"],["76336.2","0.00654673","1"],["76334.3","0","0"],["76187.9","0.00001002","1"]]}
{"instId":"BTC-USDT","action":"update","ts":"1776816045130","asks":[["76374.7","0.13579701","1"],["76380.4","0.07359813","1"],["76464.1","0","0"]],"bids":[]}
{"instId":"BTC-USDT","action":"update","ts":"1776816045160","asks":[["76347.4","0.50509047","9"],["76354.4","0","0"],["76362.2","0.00654621","1"],["76364.6","0","0"],["76368.2","0.32735357","2"],["76369.4","0","0"],["76464.1","0.00005359","1"],["76464.2","0.0025747","2"]],"bids":[["76347.3","0.84792373","18"],["76343.5","0","0"],["76342.8","0.20610924","3"],["76342.4","0.00654621","1"],["76341.3","0","0"],["76337.5","0","0"],["76336.2","0","0"],["76336.1","0","0"],["76334.3","0.00654686","1"],["76332.3","0.32734041","1"],["76332.2","0.19376718","1"],["76330.4","0.01576445","6"],["76187.7","0.47151308","1"],["76187.6","0.00303","1"]]}
{"instId":"BTC-USDT","action":"update","ts":"1776816045170","asks":[["76349","0.01314349","1"],["76361.7","0.0065463","1"],["76362.2","0","0"],["76365.3","0.16243297","2"],["76366","0.01614584","1"],["76369.4","0.00654696","1"],["76371.4","0","0"],["76380.9","0.01592054","1"],["76382","0.01","1"],["76463.3","0","0"],["76463.4","0","0"],["76463.9","0","0"],["76464.1","0","0"],["76464.2","0","0"]],"bids":[["76347.3","0.56296531","13"],["76344.2","0","0"],["76342.4","0","0"],["76340.6","0.0065463","1"],["76339.2","0.05136949","2"],["76334.3","0","0"],["76332.4","0.00654713","1"],["76332.3","0.32734545","1"],["76332.2","0","0"],["76330.5","0","0"],["76326","1.00592882","1"],["76296.4","0.1037508","1"],["76187.5","0.00032499","3"]]}
{"instId":"BTC-USDT","action":"update","ts":"1776816045180","asks":[["76380.2","0.11782715","1"],["76380.4","0","0"],["76381.2","0","0"],["76416.4","0","0"],["76463.3","0.08378297","1"],["76463.4","0.00010604","1"]],"bids":[["76298.5","0","0"],["76292.4","0","0"],["76207.9","0","0"],["76187","0.00011911","5"],["76186.6","0.00683192","1"],["76186.4","0.00022771","1"]]}
{"instId":"BTC-USDT","action":"update","ts":"1776816045190","asks":[],"bids":[["76337.3","0.10955374","1"],["76334.3","0.00654716","1"],["76332.4","0.32736072","1"],["76332.3","0","0"],["76186.4","0","0"]]}
{"instId":"BTC-USDT","action":"update","ts":"1776816045200","asks":[["76347.4","0.40693876","5"],["76362.7","0.21213892","3"],["76368.1","0.33393683","3"],["76368.2","0.00001316","1"],["76369.4","0","0"],["76463.9","0.00088649","6"]],"bids":[["76347.3","0.62456531","14"],["76340.6","0","0"],["76339.3","0.0065464","1"],["76334.3","0","0"],["76332.5","0.62539207","3"],["76332.4","0","0"],["76295.2","0.08378297","1"],["76186.4","0.00022771","1"]]}
{"instId":"BTC-USDT","action":"update","ts":"1776816045210","asks":[["76362.7","0.26517365","4"]],"bids":[["76341.5","0.08359149","2"],["76340.7","0.00654639","1"],["76339.3","0","0"],["76332.6","1.38637553","2"],["76332.5","0.33390772","2"],["76200","0.01335597","51"],["76186.4","0","0"]]}
{"instId":"BTC-USDT","action":"update","ts":"1776816045220","asks":[["76362.7","0.21213892","3"],["76368.1","0.00657627","2"],["76368.2","0.327373","2"]],"bids":[["76340.7","0","0"],["76340.6","0.00654638","1"],["76332.7","0.32735984","1"],["76332.6","1.00592882","1"],["76332.5","0.00654716","1"],["76186.6","0","0"]]}
{"instId":"BTC-USDT","action":"update","ts":"1776816045230","asks":[["76378","0.10545339","3"]],"bids":[["76332.7","0.8233511","2"],["76273.3","0.76659385","1"],["76247.6","0","0"],["76186.6","0.00683192","1"]]}
{"instId":"BTC-USDT","action":"update","ts":"1776816045240","asks":[["76368","0.00654721","1"],["76368.1","0.00002911","1"],["76377.9","0.02976284","2"],["76463.9","0","0"]],"bids":[["76332.8","0.33391405","2"],["76332.7","0.49599126","1"],["76332.5","0","0"],["76328.3","0.19871893","2"]]}
{"instId":"BTC-USDT","action":"update","ts":"1776816045250","asks":[["76365.6","0.80020321","3"],["76368.2","0.00001316","1"]],"bids":[["76340.6","0","0"],["76339.3","0.00654639","1"]]}
{"instId":"BTC-USDT","action":"update","ts":"1776816045270","asks":[["76369.5","0","0"],["76380.9","0","0"],["76463.9","0.00088649","6"],["76464.1","0.00005359","1"]],"bids":[["76341.5","0.09896052","3"],["76339.2","0.036","1"],["76328.3","0.21482237","3"]]}
{"instId":"BTC-USDT","action":"update","ts":"1776816045280","asks":[["76368.6","0.1657598","1"]],"bids":[]}
{"instId":"BTC-USDT","action":"update","ts":"1776816045290","asks":[["76349.9","0.00001137","1"],["76464.1","0","0"]],"bids":[["76344.7","0.00003372","1"],["76300.2","0.10785718","2"]]}
{"instId":"BTC-USDT","action":"update","ts":"1776816045300","asks":[],"bids":[["76347.3","0.56296531","13"],["76326.3","0.41586611","2"]]}
{"instId":"BTC-USDT","action":"update","ts":"1776816045310","asks":[["76365.6","0.47284533","2"],["76368.2","0.32737603","2"]],"bids":[["76347.3","0.62546531","14"],["76268.8","0.00054217","1"]]}
{"instId":"BTC-USDT","action":"update","ts":"1776816045320","asks":[],"bids":[["76332.2","0.00671921","1"],["76306.5","0.00705517","1"],["76187","0","0"],["76186.6","0","0"]]}
{"instId":"BTC-USDT","action":"update","ts":"1776816045330","asks":[["76366.3","0.05896264","1"],["76373.7","0","0"]],"bids":[["76345.2","0","0"],["76338.8","0.05896264","1"],["76323.6","0.08379331","2"],["76309.6","0","0"],["76285.4","0.05896264","1"],["76284.8","1.66094282","2"]]}
{"instId":"BTC-USDT","action":"update","ts":"1776816045340","asks":[],"bids":[["76285.5","0.03941219","2"]]}
{"instId":"BTC-USDT","action":"update","ts":"1776816045350","asks":[["76365.6","0.80021118","3"],["76368.2","0.00001316","1"]],"bids":[["76346.6","0","0"],["76187","0.00011911","5"]]}
{"instId":"BTC-USDT","action":"update","ts":"1776816045360","asks":[["76391.1","0.0642835","1"],["76400.9","1.90839315","1"],["76403.5","0","0"],["76463.9","0","0"]],"bids":[]}
{"instId":"BTC-USDT","action":"update","ts":"1776816045370","asks":[["76400.8","1.26282823","2"],["76401.4","0.08378297","1"],["76402.7","0.02331962","1"],["76402.8","1.06007213","2"],["76463.4","0","0"]],"bids":[]}
{"instId":"BTC-USDT","action":"update","ts":"1776816045380","asks":[["76378","0.05241866","2"],["76402.8","1.08301922","3"]],"bids":[]}
{"instId":"BTC-USDT","action":"update","ts":"1776816045390","asks":[["76362.7","0.15910419","2"],["76377.9","0.01597425","1"]],"bids":[["76347.3","0.56296531","13"],["76338.1","0.00001316","1"],["76284.8","1.66417597","3"],["76187","0","0"]]}
{"instId":"BTC-USDT","action":"update","ts":"1776816045400","asks":[["76347.4","0.46943876","6"],["76378","0.10545339","3"]],"bids":[["76324.6","0.00001316","1"],["76187.5","0","0"]]}
{"instId":"BTC-USDT","action":"update","ts":"1776816045410","asks":[["76362.7","0.21213892","3"],["76377.9","0.02976284","2"]],"bids":[["76314.8","0","0"],["76307.1","0.05239212","1"]]}
{"instId":"BTC-USDT","action":"update","ts":"1776816045420","asks":[],"bids":[["76314.9","0.02051357","1"]]}
{"instId":"BTC-USDT","action":"update","ts":"1776816045430","asks":[["76366.9","0.00654721","1"],["76368","0","0"]],"bids":[["76332.8","0.32736684","1"],["76331.1","0.00654721","1"],["76310.7","0.00002864","1"],["76187.7","0","0"],["76187.6","0","0"]]}
{"instId":"BTC-USDT","action":"update","ts":"1776816045470","asks":[["76347.4","0.62943876","7"],["76358","0.16","1"],["76378","0.05241866","2"],["76463.3","0","0"]],"bids":[["76340.5","0","0"],["76187.7","0.47151308","1"]]}
{"instId":"BTC-USDT","action":"update","ts":"1776816045480","asks":[["76357.9","0.14882654","1"],["76358.8","0.00654653","1"],["76361.7","0","0"],["76362.7","0.26517365","4"],["76377.9","0.01597425","1"],["76463.2","0","0"]],"bids":[]}
{"instId":"BTC-USDT","action":"update","ts":"1776816045500","asks":[["76355.5","0.47151308","1"],["76463.1","0","0"]],"bids":[["76339.2","0","0"],["76338.5","0","0"],["76187.6","0.00303","1"],["76187.5","0.00032499","3"]]}
{"instId":"BTC-USDT","action":"update","ts":"1776816045510","asks":[["76355.4","0.14074665","1"],["76358.8","0","0"],["76361.7","0.00654661","1"],["76463","0","0"]],"bids":[["76345.4","0","0"],["76341.7","0.08696458","1"],["76341.5","0.00083303","1"],["76339.3","0","0"],["76338.9","0.00654661","1"]]}
{"instId":"BTC-USDT","action":"update","ts":"1776816045520","asks":[],"bids":[["76338.6","0.01536962","1"],["76187.5","0","0"]]}
{"instId":"BTC-USDT","action":"update","ts":"1776816045540","asks":[["76358.8","0.0065466","1"],["76361.7","0","0"],["76401.3","0.02331962","1"]],"bids":[["76347.3","0.5615653","11"],["76337.1","0.00001501","1"]]}
{"instId":"BTC-USDT","action":"update","ts":"1776816045550","asks":[],"bids":[["76337.3","0.07059949","1"]]}
{"instId":"BTC-USDT","action":"update","ts":"1776816045560","asks":[["76347.4","0.65216876","8"]],"bids":[["76347.3","0.5388453","10"]]}
{"instId":"BTC-USDT","action":"update","ts":"1776816045580","asks":[],"bids":[["76342.3","0","0"],["76187.5","0.00032499","3"]]}
{"instId":"BTC-USDT","action":"update","ts":"1776816045590","asks":[["76398.4","1.92202352","1"],["76400.9","0","0"]],"bids":[["76345.3","0.07049369","1"],["76305.6","0","0"],["76297.8","0.02141567","3"],["76187","0.00011911","5"]]}
{"instId":"BTC-USDT","action":"update","ts":"1776816045600","asks":[["76400.7","0.83194122","1"],["76400.8","0.13288084","1"],["76462.6","0","0"]],"bids":[]}
{"instId":"BTC-USDT","action":"update","ts":"1776816045610","asks":[["76398.3","0.12756561","1"],["76400.7","0.49465192","1"],["76400.8","0","0"]],"bids":[]}
{"instId":"BTC-USDT","action":"update","ts":"1776816045620","asks":[["76347.4","0.65836876","9"],["76395.3","1.15514075","2"]],"bids":[["76347.3","0.5090453","9"]]}
{"instId":"BTC-USDT","action":"update","ts":"1776816045630","asks":[],"bids":[["76347.3","0.38144751","8"],["76330.8","0","0"],["76327.4","0.00261917","1"]]}
{"instId":"BTC-USDT","action":"update","ts":"1776816045640","asks":[["76352.4","0.13289585","2"],["76355","0.00654669","1"],["76356.1","0.01614584","1"],["76358","0.48737508","2"],["76358.5","0.24378297","2"],["76358.8","0","0"],["76362.2","1.01247627","2"],["76362.8","0.1305","1"],["76365.6","0.47284533","2"],["76366.9","0","0"],["76379","0.01614002","1"],["76396.3","0.02141818","1"],["76398.3","0","0"],["76399.1","0.00130891","1"],["76404.5","0","0"],["76406.9","0.74037081","3"],["76420.4","0.01977615","1"],["76462","0","0"],["76462.2","0","0"],["76462.3","0","0"],["76462.5","0","0"]],"bids":[["76347.3","0.00156712","1"],["76345.3","0","0"],["76343.4","0","0"],["76341.7","0","0"],["76340.5","0.01","1"],["76340","0.02","1"],["76338.9","0","0"],["76338.6","0","0"],["76337.2","0","0"],["76335.9","0.09563","1"],["76332.9","0.00654669","1"],["76332.8","0","0"],["76332.6","0","0"],["76332.1","0","0"],["76331.1","0","0"],["76330.4","0.00023743","5"],["76328.8","0","0"],["76328.3","0.19871893","2"],["76328.2","0.033","1"],["76327.5","0.00654745","1"],["76327.1","0.32737508","1"],["76326","0","0"],["76323.6","0.00001034","1"],["76321.9","0.00001501","1"],["76319.5","0","0"],["76319.2","1.4774419","2"],["76319","0.00023744","5"],["76318.8","0","0"],["76315.6","0.00001033","1"],["76311.6","1.4774419","2"],["76311.3","0.00023744","5"],["76309.5","0","0"],["76305","0","0"],["76292.5","0.01956793","1"],["76221","0.08378297","1"],["76211.3","0.08378297","1"],["76200","1.01928479","52"],["76193.3","1.00592882","1"],["76186.6","0.00683192","1"],["76186.4","0.00022771","1"],["76186.1","6.4292","1"],["76186","0.00170529","1"],["76185.3","0.00002512","1"]]}
{"instId":"BTC-USDT","action":"update","ts":"1776816045650","asks":[["76342.9","0.86066482","15"],["76344.4","0.14783769","3"],["76344.7","0.23795605","2"],["76344.8","0.07154861","2"],["76344.9","0.47151308","1"],["76347.3","0.20044641","1"],["76347.4","0.036","1"],["76349","0","0"],["76352.3","0.1627616","3"],["76352.4","0.00001501","1"],["76355","0","0"],["76357.8","0.47355691","2"],["76357.9","0","0"],["76358","0","0"],["76358.1","0.00001316","1"],["76358.4","0","0"],["76358.5","0.08378297","1"],["76358.9","0","0"],["76359.9","0.00654752","1"],["76362.2","1.00592882","1"],["76362.7","0","0"],["76368.3","0","0"],["76381.2","0.01528694","1"],["76391.3","0.17290359","2"],["76394.7","0.00130899","1"],["76395.2","0.1082931","1"],["76395.9","0.02331962","1"],["76396.3","0","0"],["76403.7","0","0"],["76406.9","0.67597148","2"],["76461.6","0","0"],["76461.7","0","0"]],"bids":[["76347.3","0","0"],["76344.7","0","0"],["76342.8","0.11392436","4"],["76341.5","0","0"],["76341.4","0.00084957","1"],["76340.5","0","0"],["76340.4","0","0"],["76340","0","0"],["76338.8","0","0"],["76338.2","0.0000168","1"],["76337.3","0.02855898","1"],["76332.9","0","0"],["76332.8","0.00654669","1"],["76332.7","0","0"],["76332.6","0.05896264","1"],["76331.1","0.01537113","1"],["76327.5","0","0"],["76327.1","0","0"],["76326.4","0.32737937","1"],["76326.3","0","0"],["76326.2","0.12765283","2"],["76323.5","0.00654752","1"],["76319.3","0.47191314","2"],["76319.2","1.00592882","1"],["76319.1","0.0000168","1"],["76316.7","0","0"],["76311.4","0.08378297","1"],["76310.2","0","0"],["76307.2","0.08378297","1"],["76307.1","0.16933124","2"],["76307","0","0"],["76303.4","0.10564037","1"],["76300.4","0.12619994","2"],["76297.8","0.00005945","2"],["76292.5","0","0"],["76291","0.0535966","1"],["76289.7","0.02144183","1"],["76287.7","0.10422817","2"],["76184.8","0.01614584","1"],["76184.1","0.47151308","1"],["76183.9","0.00003806","1"],["76183.7","0.00001319","1"],["76183.4","0.00005866","1"],["76183.3","0.00009283","1"]]}
{"instId":"BTC-USDT","action":"update","ts":"1776816045660","asks":[["76342.9","0.88706486","17"],["76344.6","0.2331338","1"],["76344.7","0","0"],["76344.8","0","0"],["76347.3","0","0"],["76349.9","0.00655829","2"],["76352.3","0.1165455","1"],["76355.3","0.32738354","1"],["76357.7","0.15158484","2"],["76357.8","0","0"],["76358.2","0.26517365","4"],["76358.3","0","0"],["76359.1","0.05896264","1"],["76359.9","0","0"],["76366.3","0","0"],["76370.6","0.01001887","1"],["76371.4","0.10467584","1"],["76381.4","0.14408259","1"],["76388.5","0.02145091","1"],["76389.4","0","0"],["76440.6","0.00027189","1"],["76445.1","0.00152413","5"],["76461.5","0","0"]],"bids":[["76342.8","0.04147924","3"],["76335.4","0.0262","1"],["76332.8","0","0"],["76332.7","0.07643305","1"],["76330.6","0.0030668","2"],["76329.7","0.00654692","1"],["76328.3","0.00001086","1"],["76326.4","0","0"],["76326.2","0.12460283","1"],["76323.5","0.47151308","1"],["76322.2","0.33393116","2"],["76312.2","0.26155956","4"],["76306.7","0.00001501","1"],["76298.2","0.00131064","1"],["76295.5","0","0"],["76290.7","0","0"],["76184","0.1305","1"],["76183.7","0","0"],["76183.4","0","0"],["76183.3","0","0"]]}
{"instId":"BTC-USDT","action":"update","ts":"1776816045670","asks":[["76342.9","0.90020938","18"],["76344.6","0.14074665","1"],["76357.6","0.00654774","1"],["76357.7","0.14503722","1"],["76360.8","0.07868","1"],["76362.1","0.11694203","1"],["76380.1","0.11694203","1"],["76395.2","0","0"],["76395.7","1.92202352","1"],["76398.4","0","0"],["76437.4","0.00196024","1"],["76461.1","0","0"],["76461.3","0","0"],["76461.4","0","0"]],"bids":[["76342.8","0.01047924","1"],["76330.6","0.0000168","1"],["76329.7","0","0"],["76329.6","0","0"],["76328.3","0.06530108","3"],["76322.7","0.00305","1"],["76322.2","0.32738354","1"],["76320.8","0.00659404","2"],["76318.5","0","0"],["76316.1","0.00305","1"],["76302.8","0.00305","1"],["76290.8","0.2034312","1"]]}
{"instId":"BTC-USDT","action":"update","ts":"1776816045680","asks":[["76344.4","0.11498845","2"],["76349.9","0.0503066","3"],["76355.2","0.24329017","1"],["76355.4","0.00654767","1"],["76357.6","0.14086199","1"],["76358.1","0.28628219","2"],["76362.1","0","0"],["76374.6","0.11694203","1"],["76374.7","0","0"],["76384.2","0","0"],["76390.4","0.14353477","2"],["76461.1","0.00003024","1"]],"bids":[["76342.8","0.04027924","2"],["76341.6","0","0"],["76335.4","0","0"],["76327.1","0.00305","1"],["76323.6","0.19349097","2"],["76322.7","0","0"],["76322","0.52898711","1"],["76314.9","0.54021302","2"],["76313.9","0.00305","1"],["76310.7","0","0"],["76302.8","0","0"],["76290.9","0.10509414","1"],["76284.8","1.66094282","2"],["76183.7","0.00001319","1"],["76183.4","0.00005866","1"]]}
{"instId":"BTC-USDT","action":"update","ts":"1776816045690","asks":[["76355.3","0","0"],["76355.4","0","0"],["76357.5","0.33393647","2"],["76360.8","0.15744","2"],["76362.1","0.48203423","1"],["76362.3","0","0"],["76381.1","0.11300117","2"],["76381.4","0","0"],["76419.9","0.0221","1"],["76434.7","0.0008618","6"],["76461.3","0.00027039","1"]],"bids":[["76336.5","0.03","2"],["76335.9","0","0"],["76331.1","0","0"],["76323.7","0.32738875","1"],["76322.3","0.00654772","1"],["76322.2","0","0"],["76320.8","0.0000463","1"],["76315.9","0.07582236","1"],["76183.4","0","0"]]}
{"instId":"BTC-USDT","action":"update","ts":"1776816045700","asks":[["76349.9","0.04375968","2"],["76352.2","0.00654716","1"],["76355.2","0.14556619","1"],["76357.4","0.13820422","1"],["76357.7","0","0"],["76391.3","0.05359293","1"],["76395.1","0.12098261","2"],["76461.3","0","0"]],"bids":[["76337.3","0","0"],["76328.6","0.01538319","2"],["76328.4","0.00654716","1"],["76328.3","0.0587541","2"],["76323.8","0.29120926","1"],["76323.6","0.00001034","1"],["76306","0","0"],["76300.2","0.00785718","1"],["76296.9","0","0"],["76292.8","0.00325243","1"],["76290.9","0.10743027","2"],["76284.9","0.1062944","1"]]}
{"instId":"BTC-USDT","action":"update","ts":"1776816045710","asks":[["76352.2","0.11414514","2"],["76357.4","0.45151016","1"],["76358.1","0.00001316","1"],["76391.1","0","0"],["76393.1","1.92202352","1"],["76395.7","0","0"],["76433.7","0.659395","1"],["76438.3","0.65789759","4"]],"bids":[["76340.3","0.0000324","1"],["76328.7","0.00654705","1"],["76328.4","0","0"],["76314.7","0","0"],["76311.6","1.54784252","3"],["76290.9","0.10509414","1"],["76289.7","0.02377796","2"],["76288.7","0.659135","1"],["76283.8","0.66069","1"],["76277.3","0","0"],["76272.8","0.00013111","1"],["76268.8","0","0"],["76264.2","0.00055534","2"],["76183.7","0","0"]]}
{"instId":"BTC-USDT","action":"update","ts":"1776816045720","asks":[["76349.9","0.07223887","3"],["76352.1","0.00654716","1"],["76352.2","0.10759798","1"],["76395.3","0.62388191","1"],["76461.1","0","0"]],"bids":[["76342.8","0.01047924","1"],["76331.1","0.00654716","1"],["76328.7","0","0"],["76288.8","0.27266452","1"],["76285.5","0","0"]]}
{"instId":"BTC-USDT","action":"update","ts":"1776816045730","asks":[["76352.1","0.11476887","2"],["76357.5","0.32738875","1"],["76358.9","0.00654792","1"],["76392.5","0.81208552","3"],["76395.1","0.00001316","1"],["76460.9","0","0"]],"bids":[["76342.8","0.04027924","2"],["76323.9","0.00654792","1"],["76322.3","0","0"],["76288.2","0.01941164","1"],["76198.5","0.0144315","1"],["76184","0","0"],["76183.9","0","0"]]}
{"instId":"BTC-USDT","action":"update","ts":"1776816045740","asks":[["76349.9","0.10090204","2"],["76365.7","0","0"],["76460.9","0.00030148","3"]],"bids":[["76342.8","0.01047924","1"],["76284.8","0.96677354","2"]]}
{"instId":"BTC-USDT","action":"update","ts":"1776816045750","asks":[["76408.9","0.00003983","1"],["76411.1","0","0"]],"bids":[["76284.8","1.77968924","2"],["76281.7","0.00323353","1"],["76184.1","0","0"]]}
{"instId":"BTC-USDT","action":"update","ts":"1776816045760","asks":[["76406.8","0.00003983","1"],["76408.9","0","0"]],"bids":[["76334.8","0.0262","1"],["76281.7","0","0"],["76280.1","0.00323355","1"],["76184.8","0","0"]]}
{"instId":"BTC-USDT","action":"update","ts":"1776816045770","asks":[["76365.3","0.08378297","1"]],"bids":[["76336.6","0.01678464","1"],["76250.1","0","0"],["76245.7","0","0"],["76184.8","0.01614584","1"]]}
{"instId":"BTC-USDT","action":"update","ts":"1776816045780","asks":[],"bids":[["76328.6","0.00001155","1"],["76250.1","0.24879073","1"],["76214","0.0396362","2"],["76184.8","0","0"]]}
{"instId":"BTC-USDT","action":"update","ts":"1776816045790","asks":[["76344.4","0.00003373","1"],["76357.6","0","0"],["76392.4","0.12491535","1"]],"bids":[["76332.8","0.11203529","1"],["76331","0.19034532","2"],["76302.1","0.1","1"],["76284.9","0","0"],["76185.3","0","0"]]}
{"instId":"BTC-USDT","action":"update","ts":"1776816045800","asks":[["76349.9","0.10089067","1"],["76357.5","0","0"],["76358.1","0.32741752","2"],["76379","0","0"],["76461.1","0.00003024","1"],["76461.3","0.00027039","1"]],"bids":[["76327.1","0.33045436","2"],["76323.7","0","0"],["76318.6","0.01628317","1"],["76316","0.08378297","1"],["76211.3","0","0"],["76193.4","1.00595506","2"],["76193.3","0","0"],["76185.3","0.00002512","1"]]}
{"instId":"BTC-USDT","action":"update","ts":"1776816045810","asks":[["76358.5","0","0"],["76358.9","0","0"],["76359.9","0.00654797","1"],["76461.4","0.0312605","1"]],"bids":[["76328.4","1.00592882","1"],["76328.3","0.14988452","3"],["76323.8","0","0"],["76272.8","0","0"],["76269.7","0.00013111","1"],["76264.2","0.00001316","1"],["76261.1","0.00055718","2"],["76250.1","0","0"],["76193.4","0.00002624","1"],["76184.8","0.01614584","1"]]}
{"instId":"BTC-USDT","action":"update","ts":"1776816045820","asks":[],"bids":[["76328.5","0.47519172","1"],["76328.3","0.00001086","1"],["76280.1","0","0"]]}
{"instId":"BTC-USDT","action":"update","ts":"1776816045830","asks":[],"bids":[["76323.6","0.1235673","2"]]}
{"instId":"BTC-USDT","action":"update","ts":"1776816045840","asks":[],"bids":[["76323.6","0.17769445","3"],["76257.5","0","0"],["76254.3","0","0"],["76222.6","0","0"],["76184.1","0.47151308","1"],["76183.9","0.00003806","1"],["76183.7","0.00001319","1"]]}
{"instId":"BTC-USDT","action":"update","ts":"1776816045850","asks":[],"bids":[["76254.3","0.98869034","1"],["76187.6","0","0"],["76184","0.1305","1"],["76183.7","0","0"]]}
{"instId":"BTC-USDT","action":"update","ts":"1776816045860","asks":[["76361.8","0.13666704","3"],["76362.8","0.1425","2"],["76370.6","0","0"],["76461.5","0.01228943","9"]],"bids":[["76250.1","0.26317686","1"],["76183.9","0","0"]]}
{"instId":"BTC-USDT","action":"update","ts":"1776816045870","asks":[["76461.5","0.14278943","10"]],"bids":[["76306.3","0.00002864","1"],["76280.1","0.00323362","1"],["76257.5","0.09451576","1"],["76184.8","0","0"],["76184.1","0","0"],["76184","0","0"]]}
{"instId":"BTC-USDT","action":"update","ts":"1776816045880","asks":[],"bids":[["76245.7","0.38392377","1"],["76185.3","0","0"]]}
{"instId":"BTC-USDT","action":"update","ts":"1776816045900","asks":[["76345.4","0.00001389","1"],["76461.5","0","0"]],"bids":[["76306.3","0","0"],["76185.3","0.00002512","1"]]}
{"instId":"BTC-USDT","action":"update","ts":"1776816045910","asks":[["76369.4","0.00006929","1"],["76461.4","0","0"]],"bids":[["76342.8","0.10397924","4"],["76303.8","0.0000168","1"],["76300","0.00359833","4"],["76296.2","1.47769196","3"],["76296","0.00001154","1"],["76292.4","0.0000168","1"],["76290.4","0.00001155","1"],["76288.6","0.0000168","1"],["76284.8","1.77970079","3"],["76284.7","0.47152988","2"],["76280.9","0.0000168","1"],["76279.2","0.00001155","1"],["76277.1","0.42386124","3"],["76273.6","0.00001155","1"],["76273.3","0.76661066","2"],["76269.5","0.00001681","1"],["76268","0.00001155","1"],["76188.3","0","0"],["76187.9","0","0"],["76187.7","0","0"],["76187.5","0","0"],["76187","0","0"],["76186.6","0","0"],["76186.4","0","0"],["76186.1","0","0"],["76186","0","0"],["76185.3","0","0"]]}
{"instId":"BTC-USDT","action":"update","ts":"1776816045920","asks":[],"bids":[["76342.8","0.0935","3"],["76296","0.0000224","2"],["76290.1","0.00001086","1"],["76284.2","0.00001086","1"],["76278.3","0.00347875","5"],["76272.4","0.00001086","1"],["76266.5","0.00001086","1"],["76190.4","0","0"],["76190","0","0"],["76188.9","0","0"],["76188.7","0","0"]]}
{"instId":"BTC-USDT","action":"update","ts":"1776816045960","asks":[],"bids":[["76306.3","0.00002864","1"],["76190.9","0","0"]]}
{"instId":"BTC-USDT","action":"update","ts":"1776816045970","asks":[],"bids":[["76327.2","0.47151308","1"],["76316.1","0.47456308","2"],["76191","0","0"]]}
{"instId":"BTC-USDT","action":"update","ts":"1776816045980","asks":[],"bids":[["76316.2","0.24248865","1"],["76315.9","0","0"]]}
{"instId":"BTC-USDT","action":"update","ts":"1776816045990","asks":[["76357.3","0.32739556","1"],["76358.1","0.00001316","1"],["76461.3","0","0"]],"bids":[["76327.1","0.00305","1"],["76323.7","0.32739556","1"],["76191.2","0","0"]]}
{"instId":"BTC-USDT","action":"update","ts":"1776816046000","asks":[["76357.4","0.28672817","1"]],"bids":[["76323.8","0.29121129","1"],["76323.6","0.00001034","1"],["76191.7","0","0"]]}
{"instId":"BTC-USDT","action":"update","ts":"1776816046010","asks":[["76352","0.00654748","1"],["76352.1","0.10822171","1"],["76357.2","0.47004411","1"],["76357.4","0","0"],["76358.9","0.00654788","1"],["76359.9","0","0"],["76461.1","0","0"]],"bids":[["76323.9","0.33394347","2"],["76323.7","0","0"],["76191.2","0.0000842","4"]]}
{"instId":"BTC-USDT","action":"update","ts":"1776816046020","asks":[["76352","0.12880506","2"],["76352.3","0","0"],["76357.1","0.32739653","1"],["76357.3","0","0"],["76358.5","0.00654791","1"],["76358.9","0","0"],["76461.1","0.00003024","1"]],"bids":[["76342.8","0.031","2"],["76324","0.29316275","1"],["76323.8","0","0"],["76191.7","0.1305","1"],["76191.2","0","0"]]}
