{"instId":"BTC-USDT","action":"update","ts":"1776816046030","asks":[["76355.2","0.2246837","2"],["76357.2","0","0"],["76358.1","0.00656107","2"],["76358.5","0","0"],["76361.5","0.11695519","2"],["76392.3","0.11605433","1"],["76392.4","0","0"],["76461.3","0.00027039","1"],["76461.4","0.0312605","1"]],"bids":[["76336.6","0.13678464","2"],["76323.9","0.32739555","1"],["76323.6","0.00655825","2"]]}
{"instId":"BTC-USDT","action":"update","ts":"1776816046040","asks":[["76357","0.32739774","1"],["76357.1","0","0"],["76358.1","0.28478284","2"],["76358.5","0.0065479","1"],["76360.7","0.08378297","1"],["76461.3","0","0"],["76461.4","0","0"]],"bids":[["76336.7","0.05260464","1"],["76336.6","0","0"],["76324.1","0.32739782","1"],["76323.9","0","0"]]}
{"instId":"BTC-USDT","action":"update","ts":"1776816046050","asks":[["76356.9","0.32739759","1"],["76357","0","0"]],"bids":[["76336.7","0.01678464","1"],["76324","0","0"],["76191.2","0.0000842","4"]]}
{"instId":"BTC-USDT","action":"update","ts":"1776816046060","asks":[["76356.8","0.32739793","1"],["76356.9","0","0"]],"bids":[["76324.2","0.61860681","2"],["76324.1","0","0"]]}
{"instId":"BTC-USDT","action":"update","ts":"1776816046070","asks":[["76356.7","0.32739783","1"],["76356.8","0","0"]],"bids":[["76324.3","0.70553268","2"],["76324.2","0","0"]]}
{"instId":"BTC-USDT","action":"update","ts":"1776816046080","asks":[["76356.6","0.32739767","1"],["76356.7","0","0"]],"bids":[["76324.4","0.73147988","2"],["76324.3","0","0"],["76217.7","1.61171399","2"]]}
{"instId":"BTC-USDT","action":"update","ts":"1776816046090","asks":[["76356.5","0.32739755","1"],["76356.6","0","0"]],"bids":[["76324.5","0.73922492","2"],["76324.4","0","0"]]}
{"instId":"BTC-USDT","action":"update","ts":"1776816046100","asks":[["76356.4","0.3273974","1"],["76356.5","0","0"]],"bids":[["76324.6","0.74154991","3"],["76324.5","0","0"],["76191","0.00014147","1"]]}
{"instId":"BTC-USDT","action":"update","ts":"1776816046110","asks":[["76351.9","0.0065476","1"],["76352","0.12225758","1"],["76356.3","0.32739734","1"],["76356.4","0","0"],["76358","0.0065479","1"],["76358.5","0","0"],["76360.6","0.11694203","1"],["76365","0","0"],["76371.4","0","0"],["76392.3","0","0"],["76392.4","0.12491535","1"]],"bids":[["76342.8","0.0298","1"],["76331.1","0.0065476","1"],["76324.7","0.74223062","2"],["76324.6","0.00001316","1"],["76323.6","0.00001034","1"],["76322.9","0.0065647","2"],["76191","0","0"]]}
{"instId":"BTC-USDT","action":"update","ts":"1776816046120","asks":[["76338.1","0.74729628","12"],["76338.2","0.00370166","1"],["76339","0.0062","1"],["76340.4","0.47151308","1"],["76342","0.26257866","2"],["76342.1","0.40819626","3"],["76342.9","0.01681456","2"],["76344.4","0","0"],["76344.6","0","0"],["76349.8","0.0065476","1"],["76351.9","0.1195998","1"],["76352.1","0","0"],["76352.2","0","0"],["76355.1","0.33787975","5"],["76356","0.07868","1"],["76356.3","0","0"],["76358","0.43624167","2"],["76358.1","0.00001316","1"],["76358.2","0","0"],["76361.8","0.03","2"],["76371.4","0.16479232","1"],["76380.3","0","0"],["76384.2","0.15416055","1"],["76390.4","0.000015","1"],["76391.3","0.17054231","2"],["76392.4","0","0"],["76460.9","0","0"],["76461.1","0","0"]],"bids":[["76342.8","0","0"],["76342","0","0"],["76341.4","0","0"],["76340.3","0","0"],["76338.2","0","0"],["76338.1","0","0"],["76338","0.25989895","8"],["76334.7","0","0"],["76331.1","0","0"],["76328.6","0.00655915","2"],["76326.2","0","0"],["76324.8","0.4150404","1"],["76324.7","0","0"],["76322.9","0.0000168","1"],["76322.2","0.3339451","2"],["76312.2","0","0"],["76311.5","0.00001681","1"],["76300.4","0.0013106","1"],["76191","0.00014147","1"],["76190.9","0.02066065","5"],["76190.4","0.00001319","1"],["76190","0.00001428","1"],["76188.9","0.00002109","2"],["76188.7","0.00047516","7"],["76188.3","0.00001061","1"],["76187.9","0.00001002","1"],["76187.7","0.47151308","1"]]}
{"instId":"BTC-USDT","action":"update","ts":"1776816046130","asks":[["76338.1","0.75099793","13"],["76338.2","0","0"],["76342.9","0.01314452","1"],["76353.4","0.26517365","4"],["76358","0.27208358","2"],["76361.5","0.00001316","1"],["76365.2","0.12226527","1"],["76390.4","0.14354379","2"],["76460.7","0","0"]],"bids":[["76338","0.34663444","11"],["76324.8","0.19348456","1"],["76318.6","0","0"],["76307.4","0.26155956","4"],["76284.9","0.10874406","1"],["76187.7","0","0"]]}
{"instId":"BTC-USDT","action":"update","ts":"1776816046140","asks":[["76342","0","0"],["76342.1","0.1456176","1"],["76349.9","0.14740957","2"],["76356","0.15738","2"],["76373.8","0.01611935","1"]],"bids":[["76334.8","0","0"],["76328.4","0","0"],["76327.2","0","0"],["76320.8","0.08382927","2"],["76291.7","0.03318391","2"],["76221","0","0"],["76193.3","1.00598811","1"],["76187.7","0.47151308","1"],["76187.5","0.00335499","4"]]}
{"instId":"BTC-USDT","action":"update","ts":"1776816046150","asks":[["76340.3","0.14074665","1"],["76340.6","0.01243145","1"],["76342.9","0","0"],["76387.9","1.92202352","1"],["76393.1","0","0"],["76404.4","0","0"]],"bids":[["76336.7","0","0"],["76328.5","0.05965691","1"],["76323.6","0.12493355","2"],["76323.5","0","0"],["76319.3","0.00040006","1"],["76319.2","0","0"],["76187","0.00011911","5"],["76186.6","0.00683192","1"],["76186.4","0.00022771","1"]]}
{"instId":"BTC-USDT","action":"update","ts":"1776816046160","asks":[["76340.4","0","0"],["76349.8","0.12099555","2"],["76358.5","0.11960733","1"],["76387.8","1.17324245","2"],["76389.3","0","0"],["76391.3","0.05359293","1"],["76392.5","0.22803367","2"],["76402.8","1.06007213","2"]],"bids":[["76324.8","0.0527379","1"],["76323.6","1.13092166","3"],["76322","0","0"],["76320.9","0.47151308","1"],["76311.7","0.13821291","1"],["76186.4","0","0"]]}
{"instId":"BTC-USDT","action":"update","ts":"1776816046170","asks":[["76340.3","0","0"],["76360.8","0.07876","1"],["76460.7","0.00167279","1"]],"bids":[["76324.8","0.33053687","2"],["76292.8","0","0"],["76291.1","0.0032658","2"],["76289.7","0.02144183","1"],["76288.9","0.00233647","1"]]}
{"instId":"BTC-USDT","action":"update","ts":"1776816046180","asks":[["76353.4","0.10606946","1"]],"bids":[["76334.8","0.0262","1"],["76324.9","0.47151308","1"],["76322.3","0.42312909","1"],["76291.1","0.00001316","1"],["76288.9","0","0"],["76287.8","0.00325265","1"],["76285.3","0.00233647","1"],["76187.7","0","0"],["76187.5","0","0"],["76187","0","0"],["76186.6","0","0"]]}
{"instId":"BTC-USDT","action":"update","ts":"1776816046190","asks":[],"bids":[["76336.6","0.01678071","1"],["76334.8","0","0"],["76318.6","0.01613048","1"],["76187.9","0","0"]]}
{"instId":"BTC-USDT","action":"update","ts":"1776816046200","asks":[["76342.9","0.00001","1"],["76345.4","0","0"]],"bids":[["76336.6","0","0"],["76335.5","0.00004575","1"]]}
{"instId":"BTC-USDT","action":"update","ts":"1776816046210","asks":[["76345.9","0.0000168","1"],["76353.4","0.15910419","2"],["76360.6","0","0"],["76368.7","0.57758254","3"],["76417.5","0.20378297","2"]],"bids":[["76335.6","0.00003133","1"],["76188.3","0","0"]]}
{"instId":"BTC-USDT","action":"update","ts":"1776816046220","asks":[],"bids":[["76280.1","0","0"],["76279.4","0.00323376","1"]]}
{"instId":"BTC-USDT","action":"update","ts":"1776816046230","asks":[["76401.2","0.00003983","1"],["76406.8","0","0"]],"bids":[["76279.4","0","0"],["76275","0.00323376","1"]]}
{"instId":"BTC-USDT","action":"update","ts":"1776816046240","asks":[["76399.9","0.12331962","2"]],"bids":[]}
{"instId":"BTC-USDT","action":"update","ts":"1776816046250","asks":[["76338.1","0.75156793","14"],["76339","0","0"],["76359.9","0.00691314","1"],["76360.8","0","0"],["76364.7","0","0"],["76460.9","0.00030148","3"],["76461.1","0.00003024","1"]],"bids":[["76338","0.33353444","10"],["76333.1","0.0131","1"],["76188.7","0","0"]]}
{"instId":"BTC-USDT","action":"update","ts":"1776816046260","asks":[["76382","0","0"],["76461.3","0.00027039","1"]],"bids":[["76331","0.01537114","1"]]}
{"instId":"BTC-USDT","action":"update","ts":"1776816046270","asks":[["76368.7","0.52454781","2"]],"bids":[["76332.9","0.05764579","1"],["76332.7","0","0"]]}
{"instId":"BTC-USDT","action":"update","ts":"1776816046280","asks":[["76353.4","0.21213892","3"]],"bids":[]}
{"instId":"BTC-USDT","action":"update","ts":"1776816046290","asks":[],"bids":[["76306.3","0","0"],["76188.7","0.00047516","7"]]}
{"instId":"BTC-USDT","action":"update","ts":"1776816046310","asks":[["76357.9","0.00654797","1"],["76358","0.26553568","1"],["76461.3","0","0"]],"bids":[["76322.9","0.00656477","2"],["76322.2","0.3273972","1"]]}
{"instId":"BTC-USDT","action":"update","ts":"1776816046320","asks":[],"bids":[["76325","0.53106467","1"],["76324.8","0","0"]]}
{"instId":"BTC-USDT","action":"update","ts":"1776816046330","asks":[["76338.1","0.68755636","12"],["76355.1","0.01048255","4"],["76355.9","0.32740096","1"],["76461.1","0","0"]],"bids":[["76323.7","0.32740096","1"],["76322.2","0","0"]]}
{"instId":"BTC-USDT","action":"update","ts":"1776816046340","asks":[],"bids":[["76338","0.33403846","11"],["76325.1","0.13024728","1"],["76322.1","0","0"],["76302.1","0","0"],["76296.7","0.11961485","1"]]}
{"instId":"BTC-USDT","action":"update","ts":"1776816046350","asks":[],"bids":[["76322.3","0.28862662","1"]]}
{"instId":"BTC-USDT","action":"update","ts":"1776816046360","asks":[["76338.1","0.68385471","11"],["76347.4","0.15560319","2"],["76349.8","0.11444795","1"],["76351.8","0.00654772","1"],["76355.9","0.3274007","1"],["76460.9","0","0"]],"bids":[["76328.6","0.00655927","2"],["76325.2","0.32740076","1"],["76323.7","0","0"]]}
{"instId":"BTC-USDT","action":"update","ts":"1776816046370","asks":[["76338.1","0.70658471","12"],["76347.3","0.04644755","1"],["76349.7","0.00654767","1"],["76351.8","0","0"],["76355.4","0.32740064","1"],["76355.9","0","0"],["76368.7","0.47151308","1"],["76460.7","0","0"]],"bids":[["76325.2","0","0"],["76323.8","0.32740064","1"],["76323.6","1.00599845","2"],["76322.9","0.0000168","1"],["76322.4","0.00655883","2"]]}
{"instId":"BTC-USDT","action":"update","ts":"1776816046380","asks":[["76347.3","0.16340429","2"],["76351.9","0","0"],["76368.7","0.52454781","2"],["76387.7","0.14353782","1"],["76390.4","0.000015","1"]],"bids":[["76301.2","0.00002864","1"],["76188.7","0","0"]]}
{"instId":"BTC-USDT","action":"update","ts":"1776816046390","asks":[["76347.2","0.08135914","1"],["76347.3","0.11695674","1"],["76349.7","0","0"],["76349.8","0.1209956","2"],["76349.9","0.10089067","1"],["76352","0","0"],["76355.4","0","0"],["76355.9","0.32739862","1"],["76357.9","0.16337633","2"],["76368.7","0.47151308","1"],["76387.6","0.14353782","1"],["76387.7","0","0"],["76432.1","0.00001316","1"]],"bids":[["76328.6","0.0065592","2"],["76323.8","0","0"],["76323.7","0.32739862","1"],["76299.2","0.12201582","2"]]}
{"instId":"BTC-USDT","action":"update","ts":"1776816046400","asks":[["76349.9","0.07228295","1"],["76351.4","0.00001316","1"],["76353.4","0.26517365","4"],["76460.6","0","0"]],"bids":[]}
{"instId":"BTC-USDT","action":"update","ts":"1776816046410","asks":[["76349.7","0.12423493","1"],["76349.9","0","0"]],"bids":[]}
{"instId":"BTC-USDT","action":"update","ts":"1776816046430","asks":[],"bids":[["76338","0.25145841","10"],["76297.3","0.1","1"],["76188.9","0","0"]]}
{"instId":"BTC-USDT","action":"update","ts":"1776816046440","asks":[],"bids":[["76307.3","0.0645016","1"],["76190","0","0"]]}
{"instId":"BTC-USDT","action":"update","ts":"1776816046460","asks":[["76349.6","0.16","1"],["76460.2","0","0"]],"bids":[]}
{"instId":"BTC-USDT","action":"update","ts":"1776816046470","asks":[["76347.2","0.11871753","2"],["76349.8","0.11444795","1"],["76353.3","0.00654771","1"],["76367.8","0.00040631","1"],["76367.9","0.00118825","2"],["76459.9","0","0"],["76460","0","0"],["76460.1","0","0"]],"bids":[["76331.1","0.00654771","1"],["76328.6","0.00001155","1"],["76323.3","0.00654799","1"],["76322.4","0.00001086","1"],["76296","0.00020782","7"],["76292.2","0.00023743","5"],["76289.8","0.00001033","1"],["76288.4","0.00017509","4"],["76284.6","0.0001751","4"],["76283.6","0.00001033","1"],["76280.8","0.0001751","4"],["76277.4","0.00001033","1"],["76276.9","0.0001751","4"],["76273.1","0.0001751","4"],["76271.2","0.00001033","1"],["76269.3","0.07145612","5"],["76265.5","0.00023748","5"],["76265","0.00001033","1"],["76261.7","0.00017513","4"],["76194.3","0","0"],["76193.9","0","0"],["76193.7","0","0"],["76193.4","0","0"],["76193.3","0","0"],["76193.2","0","0"],["76193.1","0","0"],["76192.7","0","0"],["76192.3","0","0"],["76192.2","0","0"],["76191.7","0","0"],["76191.2","0","0"],["76191","0","0"],["76190.9","0","0"],["76190.4","0","0"]]}
{"instId":"BTC-USDT","action":"update","ts":"1776816046480","asks":[["76349.9","0.00654771","1"],["76353.3","0","0"],["76357.8","0.00654799","1"],["76357.9","0.15682836","1"],["76366.8","0.00007241","1"],["76367.9","0.00181168","3"],["76459.7","0","0"],["76459.8","0","0"]],"bids":[["76331.1","0","0"],["76328.6","0.00655926","2"],["76323.3","0","0"],["76322.4","0.00655885","2"],["76296","0.0002805","9"],["76290.7","0.00001034","1"],["76288.4","0.00023743","5"],["76285.4","0.05897298","2"],["76284.6","0.00023744","5"],["76280.8","0.00023744","5"],["76280.1","0.00001034","1"],["76276.9","0.00023744","5"],["76274.8","0.08379332","2"],["76273.1","0.00023744","5"],["76269.5","0.00002716","2"],["76269.3","0.07151847","6"],["76264.2","0.00002351","2"],["76261.7","0.00023748","5"]]}
{"instId":"BTC-USDT","action":"update","ts":"1776816046490","asks":[["76357.8","0.15008581","2"],["76358.5","0","0"],["76384.2","0","0"],["76459.7","0.0000534","1"],["76459.8","0.00203787","4"]],"bids":[]}
{"instId":"BTC-USDT","action":"update","ts":"1776816046500","asks":[["76358","0.18569622","1"],["76384.2","0.12758917","1"],["76459.8","0","0"]],"bids":[]}
{"instId":"BTC-USDT","action":"update","ts":"1776816046510","asks":[["76373.8","0","0"],["76459.8","0.00203787","4"]],"bids":[]}
{"instId":"BTC-USDT","action":"update","ts":"1776816046520","asks":[["76454.1","0.00005044","1"]],"bids":[]}
{"instId":"BTC-USDT","action":"update","ts":"1776816046550","asks":[["76439.1","0.01576034","2"],["76457.2","0.00001568","1"]],"bids":[]}
{"instId":"BTC-USDT","action":"update","ts":"1776816046590","asks":[],"bids":[["76291.7","0","0"],["76194.3","0.0018792","9"]]}
{"instId":"BTC-USDT","action":"update","ts":"1776816046640","asks":[["76391.3","0.05490197","2"],["76399.1","0","0"],["76459.9","0.0000212","1"]],"bids":[["76319.3","0.1173568","2"]]}
{"instId":"BTC-USDT","action":"update","ts":"1776816046650","asks":[],"bids":[["76338","0.33403846","11"]]}
{"instId":"BTC-USDT","action":"update","ts":"1776816046660","asks":[],"bids":[["76334.8","0.0262","1"],["76284.9","0","0"]]}
{"instId":"BTC-USDT","action":"update","ts":"1776816046670","asks":[["76349.9","0","0"],["76353.3","0.00654757","1"]],"bids":[["76336.6","0.01680372","1"],["76194.3","0","0"]]}
{"instId":"BTC-USDT","action":"update","ts":"1776816046690","asks":[["76355.9","0","0"],["76357.7","0.32739962","1"]],"bids":[["76325.2","0.32739962","1"],["76323.7","0","0"]]}
{"instId":"BTC-USDT","action":"update","ts":"1776816046700","asks":[["76349.6","0","0"],["76357.6","0.5159186","2"],["76357.8","0.14353782","1"],["76357.9","0","0"],["76358","0","0"],["76358.5","0.00654795","1"],["76365.2","0","0"],["76460","0.03539391","5"],["76460.1","0.0022005","4"]],"bids":[["76338","0.40143846","12"],["76331.1","0.00654756","1"],["76328.6","0.00001155","1"],["76323.5","0.00654795","1"],["76322.4","0.00001086","1"],["76195.4","0","0"],["76195.1","0","0"]]}
{"instId":"BTC-USDT","action":"update","ts":"1776816046710","asks":[["76347.2","0.08135914","1"]],"bids":[]}
{"instId":"BTC-USDT","action":"update","ts":"1776816046750","asks":[["76338.1","0.64231471","9"],["76353.4","0.10606946","2"],["76387.9","0","0"],["76400.9","1.92157371","1"]],"bids":[["76338","0.40763846","13"]]}
{"instId":"BTC-USDT","action":"update","ts":"1776816046760","asks":[["76338.1","0.55088471","8"],["76349.7","0.07674231","1"],["76387.7","0.19139002","1"],["76387.8","0.47151308","1"],["76395.1","0.12494422","2"],["76460.1","0","0"]],"bids":[["76338","0.50763846","14"]]}
{"instId":"BTC-USDT","action":"update","ts":"1776816046770","asks":[["76353.4","0.21213892","3"],["76358.5","0","0"],["76359.8","0.00654796","1"],["76368.7","0.52454781","2"],["76400.7","0.99035757","2"]],"bids":[["76332.3","0.00654756","1"],["76331.1","0","0"],["76323.7","0.00654795","1"],["76323.5","0","0"]]}
{"instId":"BTC-USDT","action":"update","ts":"1776816046790","asks":[],"bids":[["76333.1","0.1382474","2"],["76332.3","0","0"],["76331.1","0.00654752","1"]]}
{"instId":"BTC-USDT","action":"update","ts":"1776816046800","asks":[["76338.1","0.52815471","7"],["76370.5","0.0162943","1"],["76460","0","0"]],"bids":[["76335.5","0","0"],["76333.2","0.10086708","1"],["76332.9","0","0"],["76318.6","0","0"],["76195.4","0.00098504","2"],["76195.1","0.01457366","1"]]}
{"instId":"BTC-USDT","action":"update","ts":"1776816046810","asks":[],"bids":[["76332.9","0.00654742","1"],["76332.8","0","0"],["76331.1","0","0"],["76325.3","0.0065479","1"],["76323.7","0","0"],["76194.3","0.0018792","9"]]}
{"instId":"BTC-USDT","action":"update","ts":"1776816046820","asks":[],"bids":[["76333.2","0.06742451","1"]]}
{"instId":"BTC-USDT","action":"update","ts":"1776816046830","asks":[["76368.7","0.47151308","1"]],"bids":[]}
{"instId":"BTC-USDT","action":"update","ts":"1776816046840","asks":[["76338.1","0.49835471","6"],["76353.4","0.26517365","4"]],"bids":[["76331","0","0"],["76193.9","0.01496","1"]]}
{"instId":"BTC-USDT","action":"update","ts":"1776816046850","asks":[["76349.7","0.11442355","2"]],"bids":[["76333.3","0.01486122","1"],["76193.9","0","0"]]}
{"instId":"BTC-USDT","action":"update","ts":"1776816046860","asks":[["76338.1","0.44182871","5"],["76356.1","0","0"],["76384","0.06424646","1"]],"bids":[]}
{"instId":"BTC-USDT","action":"update","ts":"1776816046910","asks":[],"bids":[["76301.2","0","0"],["76193.9","0.01496","1"]]}
{"instId":"BTC-USDT","action":"update","ts":"1776816046930","asks":[["76387.9","1.92109385","1"],["76400.9","0","0"]],"bids":[]}
{"instId":"BTC-USDT","action":"update","ts":"1776816046940","asks":[["76387.7","0.7403677","2"],["76400.7","0.49465192","1"]],"bids":[["76332.9","0","0"],["76332.3","0.00654739","1"]]}
{"instId":"BTC-USDT","action":"update","ts":"1776816046950","asks":[],"bids":[["76325.3","0","0"],["76323.7","0.00654783","1"]]}
{"instId":"BTC-USDT","action":"update","ts":"1776816046980","asks":[],"bids":[["76325.3","0.00654783","1"],["76323.7","0","0"]]}
{"instId":"BTC-USDT","action":"update","ts":"1776816046990","asks":[],"bids":[["76301.2","0.00002864","1"],["76193.9","0","0"]]}
{"instId":"BTC-USDT","action":"update","ts":"1776816047040","asks":[],"bids":[["76325.3","0","0"],["76323.7","0.00654783","1"]]}
{"instId":"BTC-USDT","action":"update","ts":"1776816047050","asks":[["76359.8","0","0"],["76360.6","0.00654783","1"]],"bids":[["76333.2","0.07397191","2"],["76332.3","0","0"],["76325.3","0.00654783","1"],["76323.7","0","0"],["76322.2","0.01597939","1"]]}
{"instId":"BTC-USDT","action":"update","ts":"1776816047060","asks":[],"bids":[["76333.2","0.06742451","1"],["76332.7","0.00654742","1"],["76194.3","0","0"]]}
{"instId":"BTC-USDT","action":"update","ts":"1776816047100","asks":[],"bids":[["76335.6","0.00005525","2"]]}
{"instId":"BTC-USDT","action":"update","ts":"1776816047110","asks":[["76387.9","0","0"],["76393.1","1.92109385","1"]],"bids":[]}
{"instId":"BTC-USDT","action":"update","ts":"1776816047120","asks":[["76387.7","0.19139002","1"]],"bids":[]}
{"instId":"BTC-USDT","action":"update","ts":"1776816047150","asks":[["76370.5","0","0"],["76460","0.03539391","5"]],"bids":[["76322.2","0","0"],["76194.3","0.0018792","9"]]}
{"instId":"BTC-USDT","action":"update","ts":"1776816047160","asks":[["76390.5","1.92109478","1"],["76393.1","0","0"],["76433.6","0.27963349","1"],["76460","0","0"]],"bids":[["76332.7","0","0"],["76332.3","0.00654743","1"]]}
{"instId":"BTC-USDT","action":"update","ts":"1776816047170","asks":[["76359.8","0.00654791","1"],["76360.6","0","0"]],"bids":[["76325.3","0","0"],["76323.7","0.00654791","1"]]}
{"instId":"BTC-USDT","action":"update","ts":"1776816047180","asks":[],"bids":[["76332.3","0","0"],["76328.6","0.00655892","2"],["76193.9","0.01496","1"]]}
{"instId":"BTC-USDT","action":"update","ts":"1776816047200","asks":[["76353.4","0.21213892","3"],["76399.9","0.02331962","1"]],"bids":[["76219.3","0.00134151","3"]]}
{"instId":"BTC-USDT","action":"update","ts":"1776816047220","asks":[["76368.7","0.52454781","2"]],"bids":[]}
{"instId":"BTC-USDT","action":"update","ts":"1776816047260","asks":[["76368.7","0.47151308","1"]],"bids":[]}
{"instId":"BTC-USDT","action":"update","ts":"1776816047270","asks":[["76353.4","0.26517365","4"]],"bids":[]}
{"instId":"BTC-USDT","action":"update","ts":"1776816047290","asks":[["76358.5","0.00654781","1"],["76359.8","0","0"],["76395.1","0.22494422","3"]],"bids":[]}
{"instId":"BTC-USDT","action":"update","ts":"1776816047310","asks":[["76342.9","0","0"],["76460","0.03539391","5"]],"bids":[]}
{"instId":"BTC-USDT","action":"update","ts":"1776816047320","asks":[["76357.8","0","0"],["76359.1","0","0"],["76362","0.14884467","1"],["76365.1","0.05896264","1"],["76368.4","0.11960733","1"],["76387.6","0","0"],["76395.1","0.10001316","2"]],"bids":[]}
{"instId":"BTC-USDT","action":"update","ts":"1776816047330","asks":[["76357.6","0.40865889","2"]],"bids":[]}
{"instId":"BTC-USDT","action":"update","ts":"1776816047350","asks":[],"bids":[["76325.1","0.14618127","2"]]}
{"instId":"BTC-USDT","action":"update","ts":"1776816047400","asks":[["76348.1","0.00001316","1"],["76435.4","0.00001316","1"],["76459.9","0","0"],["76460","0","0"]],"bids":[]}
{"instId":"BTC-USDT","action":"update","ts":"1776816047420","asks":[],"bids":[["76291.8","0.01692073","1"],["76291.7","0.01691038","1"],["76194.3","0","0"],["76193.9","0","0"]]}
{"instId":"BTC-USDT","action":"update","ts":"1776816047450","asks":[],"bids":[["76333.3","0.17486122","2"]]}
{"instId":"BTC-USDT","action":"update","ts":"1776816047460","asks":[],"bids":[["76333.4","0.1130779","1"],["76333.2","0","0"]]}
{"instId":"BTC-USDT","action":"update","ts":"1776816047490","asks":[],"bids":[["76333.3","0.01486122","1"]]}
{"instId":"BTC-USDT","action":"update","ts":"1776816047500","asks":[],"bids":[["76333.4","0.0653179","1"]]}
{"instId":"BTC-USDT","action":"update","ts":"1776816047550","asks":[],"bids":[["76320.4","0.31892562","2"]]}
{"instId":"BTC-USDT","action":"update","ts":"1776816047560","asks":[["76370.9","0.01565851","1"],["76459.8","0","0"]],"bids":[]}
{"instId":"BTC-USDT","action":"update","ts":"1776816047720","asks":[],"bids":[["76301.2","0","0"],["76194.3","0.0018792","9"]]}
{"instId":"BTC-USDT","action":"update","ts":"1776816047830","asks":[],"bids":[["76301.2","0.00002864","1"],["76194.3","0","0"]]}
{"instId":"BTC-USDT","action":"update","ts":"1776816047890","asks":[["76340.5","0.00001334","1"],["76459.7","0","0"]],"bids":[["76335.6","0.00003133","1"]]}
{"instId":"BTC-USDT","action":"update","ts":"1776816047910","asks":[["76390.4","0.11696438","2"]],"bids":[["76320.4","0.30279","1"]]}
{"instId":"BTC-USDT","action":"update","ts":"1776816047940","asks":[["76450.8","0.000655","1"],["76459.6","0","0"]],"bids":[]}
{"instId":"BTC-USDT","action":"update","ts":"1776816047980","asks":[["76353.4","0.21213892","3"]],"bids":[]}
{"instId":"BTC-USDT","action":"update","ts":"1776816047990","asks":[["76368.7","0.52454781","2"]],"bids":[]}
{"instId":"BTC-USDT","action":"update","ts":"1776816048010","asks":[["76357.5","0.32738956","1"],["76357.7","0","0"]],"bids":[["76325.1","0.13024728","1"]]}
{"instId":"BTC-USDT","action":"update","ts":"1776816048020","asks":[["76357.6","0.14087971","1"]],"bids":[["76288.2","0","0"],["76198.5","0","0"],["76194.3","0.0018792","9"],["76193.9","0.01496","1"]]}
{"instId":"BTC-USDT","action":"update","ts":"1776816048030","asks":[["76368.7","0.47151308","1"]],"bids":[]}
{"instId":"BTC-USDT","action":"update","ts":"1776816048050","asks":[["76353.4","0.26517365","4"]],"bids":[]}
{"instId":"BTC-USDT","action":"update","ts":"1776816048150","asks":[],"bids":[["76320.1","0.01588116","1"],["76193.9","0","0"]]}
{"instId":"BTC-USDT","action":"update","ts":"1776816048190","asks":[["76340.5","0","0"],["76459.6","0.00072458","2"]],"bids":[]}
{"instId":"BTC-USDT","action":"update","ts":"1776816048200","asks":[["76387.7","0.77527737","2"]],"bids":[]}
{"instId":"BTC-USDT","action":"update","ts":"1776816048210","asks":[],"bids":[["76338","0.50680487","13"]]}
{"instId":"BTC-USDT","action":"update","ts":"1776816048300","asks":[["76340.5","0.00001383","1"],["76459.6","0","0"]],"bids":[["76288","0.01983004","1"],["76198.3","0.01437429","1"],["76195.1","0","0"],["76194.3","0","0"]]}
{"instId":"BTC-USDT","action":"update","ts":"1776816048380","asks":[["76353.4","0.21213892","3"]],"bids":[]}
{"instId":"BTC-USDT","action":"update","ts":"1776816048390","asks":[["76387.9","1.92109478","1"],["76390.5","0","0"]],"bids":[["76333.5","0.16","1"],["76195.4","0","0"]]}
{"instId":"BTC-USDT","action":"update","ts":"1776816048400","asks":[["76338.1","0.44183871","6"],["76344.7","0.00001316","1"],["76368.7","0.52454781","2"],["76445.3","0.00038686","6"],["76459.3","0","0"]],"bids":[["76333.6","0.1130779","1"],["76333.5","0","0"],["76333.4","0","0"],["76195.4","0.00098504","2"]]}
{"instId":"BTC-USDT","action":"update","ts":"1776816048410","asks":[],"bids":[["76333.6","0.0653179","1"]]}
{"instId":"BTC-USDT","action":"update","ts":"1776816048420","asks":[],"bids":[["76291.8","0","0"],["76291.7","0","0"],["76195.1","0.01457366","1"],["76194.3","0.0018792","9"]]}
{"instId":"BTC-USDT","action":"update","ts":"1776816048430","asks":[["76368.7","0.47151308","1"]],"bids":[["76320.1","0","0"],["76193.9","0.01496","1"]]}
{"instId":"BTC-USDT","action":"update","ts":"1776816048440","asks":[["76353.4","0.15910419","2"]],"bids":[["76307.4","0.20988299","3"]]}
{"instId":"BTC-USDT","action":"update","ts":"1776816048460","asks":[["76368.7","0.52454781","2"]],"bids":[]}
{"instId":"BTC-USDT","action":"update","ts":"1776816048480","asks":[["76370.9","0","0"],["76459.3","0.00319921","2"]],"bids":[["76323.1","0.01579051","1"],["76322.7","0.05167657","1"],["76194.3","0","0"],["76193.9","0","0"]]}
{"instId":"BTC-USDT","action":"update","ts":"1776816048490","asks":[["76358.5","0","0"],["76358.9","0.00654774","1"]],"bids":[]}
{"instId":"BTC-USDT","action":"update","ts":"1776816048520","asks":[["76340.6","0","0"],["76368.7","0.57758254","3"],["76459.6","0.00072458","2"]],"bids":[]}
{"instId":"BTC-USDT","action":"update","ts":"1776816048530","asks":[["76343.9","0.01131326","1"],["76459.6","0","0"]],"bids":[]}
{"instId":"BTC-USDT","action":"update","ts":"1776816048540","asks":[["76368.7","0.47151308","1"]],"bids":[["76322.7","0","0"],["76194.3","0.0018792","9"]]}
{"instId":"BTC-USDT","action":"update","ts":"1776816048550","asks":[["76353.4","0.26517365","4"]],"bids":[]}
{"instId":"BTC-USDT","action":"update","ts":"1776816048560","asks":[["76401.2","0","0"],["76459.6","0.00072458","2"]],"bids":[]}
{"instId":"BTC-USDT","action":"update","ts":"1776816048590","asks":[],"bids":[["76307.4","0.26155956","4"]]}
{"instId":"BTC-USDT","action":"update","ts":"1776816048660","asks":[["76401.2","0.00003983","1"],["76459.6","0","0"]],"bids":[]}
{"instId":"BTC-USDT","action":"update","ts":"1776816048670","asks":[["76358.5","0.00654775","1"],["76358.9","0","0"]],"bids":[["76323.7","0","0"],["76323.5","0.00654775","1"],["76300.4","0","0"],["76298.2","0","0"],["76290.5","0.00131077","1"],["76289.4","0.00131079","1"]]}
{"instId":"BTC-USDT","action":"update","ts":"1776816048700","asks":[["76355.9","0.32739008","1"],["76357.5","0","0"]],"bids":[["76323.5","0","0"],["76323.3","0.00654776","1"],["76323.1","0","0"],["76284.9","0.10417975","1"]]}
{"instId":"BTC-USDT","action":"update","ts":"1776816048710","asks":[["76349.9","0.00654743","1"],["76353.3","0","0"],["76355.4","0.32739002","1"],["76355.9","0","0"],["76357.5","0.00654777","1"],["76358.5","0","0"],["76368.5","1.02167712","2"]],"bids":[["76325.2","0","0"],["76323.7","0.32739006","1"],["76323.3","0","0"],["76322.9","0.00656457","2"],["76193.9","0.01496","1"]]}
{"instId":"BTC-USDT","action":"update","ts":"1776816048720","asks":[["76349.7","0.12097098","3"],["76349.9","0","0"],["76459.6","0.00072458","2"]],"bids":[]}
{"instId":"BTC-USDT","action":"update","ts":"1776816048730","asks":[],"bids":[["76322.9","0.0000168","1"],["76322.4","0.00655862","2"]]}
{"instId":"BTC-USDT","action":"update","ts":"1776816048740","asks":[["76338.1","0.44569871","7"],["76343.9","0","0"],["76459.7","0.0000534","1"]],"bids":[["76338","0.41802482","11"],["76334.8","0","0"],["76193.7","0.00009338","1"]]}
{"instId":"BTC-USDT","action":"update","ts":"1776816048750","asks":[["76341.2","0.01131366","1"],["76459.7","0","0"]],"bids":[["76338","0.31802482","10"],["76336.6","0","0"],["76333.3","0","0"],["76330.3","0.01407136","1"],["76322.4","0.00001086","1"],["76321","0.00654781","1"]]}
{"instId":"BTC-USDT","action":"update","ts":"1776816048760","asks":[["76341.2","0","0"],["76459.7","0.0000534","1"]],"bids":[["76319.8","0.01574916","1"],["76193.7","0","0"]]}
{"instId":"BTC-USDT","action":"update","ts":"1776816048770","asks":[["76338.8","0.01131402","1"],["76459.7","0","0"]],"bids":[]}
{"instId":"BTC-USDT","action":"update","ts":"1776816048780","asks":[["76349.7","0.12097121","3"],["76355.4","0","0"],["76355.9","0.3273934","1"]],"bids":[["76330.4","0.00678509","6"],["76328.6","0.00001155","1"],["76322.9","0.00656466","2"],["76321","0","0"],["76193.7","0.00009338","1"]]}
{"instId":"BTC-USDT","action":"update","ts":"1776816048790","asks":[["76349.7","0.11442355","2"],["76349.9","0.00654766","1"],["76459.6","0","0"]],"bids":[]}
{"instId":"BTC-USDT","action":"update","ts":"1776816048800","asks":[["76338.1","0.50819871","8"],["76344.7","0.13373267","2"],["76349.9","0","0"],["76353.3","0.00654769","1"],["76353.6","0.03","2"],["76355.9","0","0"],["76357.5","0.3339424","2"],["76361.8","0","0"],["76390.4","0.000015","1"],["76459.6","0.00072458","2"]],"bids":[["76338","0.09212482","6"],["76336.5","0","0"],["76333.1","0.0131","1"],["76332.7","0.00654769","1"],["76332.2","0.01671921","2"],["76330.4","0.00023743","5"],["76325.2","0.32739463","1"],["76324.9","0","0"],["76323.8","1.00605137","1"],["76323.7","0","0"],["76323.6","0.00001034","1"]]}
{"instId":"BTC-USDT","action":"update","ts":"1776816048810","asks":[["76338.1","0.53256871","9"],["76347.1","0.00654768","1"],["76353.3","0.32739463","1"],["76355","0.00654776","1"],["76355.1","1.10031689","6"],["76357.5","0","0"],["76459.6","0","0"]],"bids":[["76338","0.12312482","8"],["76333.6","0.02846481","1"],["76332.7","0","0"],["76332.2","0.03671921","3"],["76330.3","0","0"],["76327.6","0.01407186","1"],["76327.5","0.00654768","1"],["76327","0","0"],["76325.2","0","0"],["76325","0","0"],["76322.9","0.0000168","1"],["76321","0.32739463","1"],["76320.8","0.0000463","1"],["76319.9","0.00654776","1"],["76316","0","0"],["76221","0.08378297","1"],["76193.4","0.00002624","1"]]}
{"instId":"BTC-USDT","action":"update","ts":"1776816048820","asks":[["76349.7","0.20537893","1"]],"bids":[["76338","0.20570487","9"],["76323.9","0.35304339","1"],["76193.4","0","0"]]}
{"instId":"BTC-USDT","action":"update","ts":"1776816048830","asks":[],"bids":[["76338","0.18298487","8"]]}
{"instId":"BTC-USDT","action":"update","ts":"1776816048840","asks":[],"bids":[["76323.2","0.111657","6"]]}
{"instId":"BTC-USDT","action":"update","ts":"1776816048850","asks":[["76355","0.52271694","2"],["76355.2","0","0"],["76433.6","0","0"],["76459.6","0.00072458","2"],["76459.7","0.0000534","1"]],"bids":[["76315.6","0.0837933","2"]]}
{"instId":"BTC-USDT","action":"update","ts":"1776816048860","asks":[],"bids":[["76324","0.47151308","1"],["76193.7","0","0"]]}
{"instId":"BTC-USDT","action":"update","ts":"1776816048870","asks":[["76347","0.00654777","1"],["76347.1","0","0"],["76353.3","0.32740517","1"]],"bids":[["76328.9","0.10393088","2"],["76327.7","0.00654777","1"],["76327.5","0","0"],["76321","0.32740517","1"]]}
{"instId":"BTC-USDT","action":"update","ts":"1776816048880","asks":[["76347","0","0"],["76349.6","0.00654777","1"],["76353.3","0","0"],["76354.9","0.32740478","1"],["76355","0.51616918","1"],["76355.4","0.00654806","1"],["76459.7","0","0"]],"bids":[["76328.3","0.00655863","2"],["76327.7","0","0"],["76322.4","0.32741564","2"],["76321","0","0"],["76320.8","0.00659436","2"],["76319.9","0","0"],["76193.7","0.00009338","1"],["76193.4","0.00002624","1"],["76193.3","1.00598811","1"]]}
{"instId":"BTC-USDT","action":"update","ts":"1776816048890","asks":[["76349.7","0.12228046","1"],["76387.9","0","0"],["76393.1","1.92109478","1"]],"bids":[]}
{"instId":"BTC-USDT","action":"update","ts":"1776816048900","asks":[["76387.7","0.19139002","1"]],"bids":[]}
{"instId":"BTC-USDT","action":"update","ts":"1776816048910","asks":[],"bids":[["76331","0.0262","1"],["76269.7","0","0"],["76265.1","0.00013112","1"],["76261.1","0.00001501","1"],["76256.6","0.00054219","1"],["76193.4","0","0"],["76193.3","0","0"]]}
{"instId":"BTC-USDT","action":"update","ts":"1776816048930","asks":[["76390.5","1.92109478","1"],["76393.1","0","0"]],"bids":[["76332.2","0.03","2"],["76306.5","0","0"],["76193.4","0.00002624","1"]]}
{"instId":"BTC-USDT","action":"update","ts":"1776816048940","asks":[["76355.4","0","0"],["76355.9","0.00654803","1"]],"bids":[["76321","0.00654803","1"],["76320.8","0.0000463","1"],["76193.4","0","0"]]}
{"instId":"BTC-USDT","action":"update","ts":"1776816048980","asks":[["76354.9","0","0"],["76357.5","0.3274028","1"]],"bids":[["76325.2","0.3274028","1"],["76322.4","0.00001086","1"],["76301.2","0","0"]]}
{"instId":"BTC-USDT","action":"update","ts":"1776816048990","asks":[["76349.6","0","0"],["76353.3","0.00654761","1"],["76355.9","0","0"],["76358.9","0.00654801","1"],["76390.5","0","0"],["76393.1","1.92109478","1"]],"bids":[["76331.1","0.00654761","1"],["76328.3","0.00001086","1"],["76325.2","0.87962893","2"],["76324.1","0.00654801","1"],["76323.9","0","0"],["76321","0","0"]]}
{"instId":"BTC-USDT","action":"update","ts":"1776816049000","asks":[["76401.2","0","0"],["76459.7","0.0000534","1"]],"bids":[["76329","0.07533084","1"],["76328.5","0","0"]]}
{"instId":"BTC-USDT","action":"update","ts":"1776816049010","asks":[["76358.5","0.00654801","1"],["76358.9","0","0"],["76433.6","0.35565079","1"],["76459.7","0","0"]],"bids":[["76329.1","0.10900087","1"],["76325.1","0","0"],["76324.1","0.11694938","1"],["76323.5","0.00654801","1"],["76315.8","0","0"],["76297.8","0.12232472","3"],["76284.9","0","0"],["76193.4","0.00002624","1"]]}
{"instId":"BTC-USDT","action":"update","ts":"1776816049020","asks":[["76355.9","0.32740221","1"],["76357.5","0","0"],["76454.2","0.00570866","2"]],"bids":[["76331.1","0","0"],["76329.2","0.00654764","1"],["76325.2","0.55222613","1"],["76324.2","0.32740221","1"],["76299.2","0.18140704","1"],["76296.7","0.12667043","2"],["76193.4","0","0"]]}
{"instId":"BTC-USDT","action":"update","ts":"1776816049030","asks":[],"bids":[["76329.2","0.12349702","2"],["76323.5","0","0"],["76322.9","0.00656479","2"],["76322.4","0.00673046","2"],["76193.4","0.00002624","1"]]}
{"instId":"BTC-USDT","action":"update","ts":"1776816049040","asks":[],"bids":[["76329.3","0.14473146","1"],["76329","0","0"],["76327.6","0","0"],["76301.2","0.00002864","1"]]}
{"instId":"BTC-USDT","action":"update","ts":"1776816049050","asks":[["76349.9","0.00654741","1"],["76353.3","0","0"]],"bids":[["76330.3","0.01407135","1"],["76329.4","0.00654741","1"],["76329.2","0.11694938","1"],["76193.7","0","0"],["76193.4","0","0"]]}
{"instId":"BTC-USDT","action":"update","ts":"1776816049060","asks":[],"bids":[["76338","0.31048487","9"]]}
{"instId":"BTC-USDT","action":"update","ts":"1776816049070","asks":[["76349.9","0","0"],["76353.3","0.0065474","1"]],"bids":[["76330.4","0.00678483","6"],["76329.4","0","0"],["76193.7","0.00009338","1"]]}
{"instId":"BTC-USDT","action":"update","ts":"1776816049080","asks":[["76349.9","0.0065474","1"],["76353.3","0","0"]],"bids":[]}
{"instId":"BTC-USDT","action":"update","ts":"1776816049110","asks":[["76338.1","0.47006871","8"],["76368.5","1.00607904","1"],["76401.2","0.00003983","1"],["76459.6","0","0"]],"bids":[]}
{"instId":"BTC-USDT","action":"update","ts":"1776816049130","asks":[["76380","0.06506706","2"],["76384","0","0"],["76459.6","0.00072458","2"]],"bids":[]}
{"instId":"BTC-USDT","action":"update","ts":"1776816049140","asks":[],"bids":[["76338","0.40658487","10"]]}
{"instId":"BTC-USDT","action":"update","ts":"1776816049150","asks":[["76338.1","0.11965","3"],["76344.9","0","0"],["76347.4","0.11960319","1"],["76354.9","0.47151308","1"],["76355.1","0.09426552","5"],["76355.5","0","0"],["76358.6","0","0"],["76362.2","0","0"],["76368.5","0","0"],["76371.4","0","0"],["76375.8","0.47151308","1"],["76459.7","0.0000534","1"],["76459.8","0.00203787","4"],["76459.9","0.0000212","1"],["76460","0.03539391","5"],["76460.1","0.0022005","4"]],"bids":[["76338","0.44878487","12"],["76327.9","0.47151308","1"],["76193.7","0","0"]]}
{"instId":"BTC-USDT","action":"update","ts":"1776816049160","asks":[["76338.1","0","0"],["76338.8","0","0"],["76340.5","0","0"],["76342.1","0","0"],["76344.7","0","0"],["76345.9","0","0"],["76347.2","0.031","2"],["76347.3","0","0"],["76347.4","0","0"],["76348.1","0","0"],["76349.7","0","0"],["76349.8","0","0"],["76349.9","0","0"],["76353.4","0","0"],["76353.6","0","0"],["76354.8","0.31360556","2"],["76354.9","0","0"],["76355","0","0"],["76355.1","0.01048255","4"],["76355.9","0","0"],["76358.5","0","0"],["76360.7","0","0"],["76361.9","0.47151308","1"],["76362.1","0","0"],["76362.4","0","0"],["76362.8","0.012","1"],["76365.1","0","0"],["76365.2","0.12757229","1"],["76365.3","0","0"],["76365.4","0.17249886","1"],["76366","0","0"],["76371.5","0","0"],["76374.3","0.14071381","5"],["76374.6","0","0"],["76374.8","0","0"],["76375.6","0","0"],["76388.5","0","0"],["76391.3","0.17184768","3"],["76392.4","0.12226527","1"],["76393.1","0","0"],["76396.8","0.36998226","2"],["76400.6","0.12757714","1"],["76411.3","2.39260786","2"],["76445.5","0.00001146","1"],["76460.2","0.00162671","12"],["76460.6","0.00002799","2"],["76460.7","0.00167279","1"],["76460.9","0.00030148","3"],["76461.1","0.00003024","1"],["76461.3","0.00027039","1"],["76461.4","0.0312605","1"],["76461.5","0.01228943","9"],["76461.6","0.00332668","1"],["76461.7","0.00001025","1"],["76462","0.00002228","1"],["76462.2","0.00551437","1"],["76462.3","0.00027227","4"],["76462.5","0.00001257","1"],["76462.6","0.47226231","9"],["76463","0.00004357","1"],["76463.1","0.00001427","1"],["76463.2","0.00059244","1"],["76463.3","0.08378297","1"],["76463.4","0.00010604","1"],["76463.9","0.00088649","6"],["76464.1","0.00005359","1"],["76464.2","0.0025747","2"],["76464.4","0.00019338","3"],["76464.6","0.00012165","3"],["76464.7","0.00497942","3"]],"bids":[["76347.1","0.06847314","5"],["76344.6","0.49338403","6"],["76342","0.50558414","7"],["76340.5","0.18758005","2"],["76340.4","0.47681393","6"],["76338.7","0.15095473","3"],["76338.1","0.21416095","1"],["76338","0.14065946","5"],["76336.8","0.01614584","1"],["76333.6","0.12846481","2"],["76332.7","0.1370473","2"],["76331.2","0.01614584","1"],["76331.1","0.47151308","1"],["76331","0","0"],["76330.4","0.00023743","5"],["76330.3","0","0"],["76329.4","0.32739866","1"],["76329.3","0.26081956","2"],["76329.1","0","0"],["76328.9","0.00001034","1"],["76328.3","0.00655832","2"],["76325.3","0.08378297","1"],["76324.2","0","0"],["76322.9","0.0000168","1"],["76321","0.08378297","1"],["76313","0.11695606","2"],["76311.7","0","0"],["76307.4","0","0"],["76307.1","0.05239212","1"],["76297.8","0.14655598","4"],["76296.8","0.13554556","1"],["76296.7","0.00705558","1"],["76296.4","0","0"],["76290.9","0","0"],["76289.7","0","0"],["76287.7","0.00001316","1"],["76245.7","0","0"],["76235.3","0","0"],["76231","0","0"],["76221","0","0"],["76194.3","0","0"],["76193.9","0","0"]]}
{"instId":"BTC-USDT","action":"update","ts":"1776816049170","asks":[["76347.2","0.32666","5"],["76351.4","0","0"],["76353.1","0.0113119","1"],["76354.8","0.05012013","2"],["76356","0","0"],["76362.5","0.26517365","4"],["76378","0.00001","1"],["76388.1","0.05239713","1"],["76411.1","0.08378297","1"],["76411.3","0.47151308","1"],["76416.5","1.92109478","1"],["76417.9","0.00019319","1"],["76461.5","0.14278943","10"],["76464.2","0","0"],["76464.4","0","0"],["76464.6","0","0"],["76464.7","0","0"]],"bids":[["76347.1","0.5901327","14"],["76344.7","0.298192","1"],["76344.6","0","0"],["76342.9","0.01406904","1"],["76342","0.14824401","2"],["76340.5","0","0"],["76340.4","0","0"],["76338.7","0.036","1"],["76338.1","0","0"],["76338","0.15613919","4"],["76333.7","0.00654656","1"],["76333.1","0.1131","2"],["76332.8","0.10573462","1"],["76332.7","0.1305","1"],["76332.6","0","0"],["76331.2","1.02219721","2"],["76330.3","0.00261907","1"],["76329.5","0.44430089","3"],["76329.4","0","0"],["76329.2","0","0"],["76327.4","0","0"],["76323.6","0.05897298","2"],["76316.5","0.26157042","5"],["76316.3","0.11693476","1"],["76307.3","0","0"],["76306","0.12225069","1"],["76303.4","0.16863996","2"],["76296.8","0","0"],["76296.4","0.11693544","1"],["76285.4","0.00001034","1"],["76240","0.0000812","1"],["76194.3","0.0018792","9"],["76193.9","0.01496","1"]]}
{"instId":"BTC-USDT","action":"update","ts":"1776816049180","asks":[["76354.8","0.00001316","1"],["76357.5","0.04439259","1"],["76377.1","1.00605137","1"],["76381.1","0.00006516","1"],["76392.4","0.26306198","2"],["76463.9","0","0"],["76464.1","0","0"]],"bids":[["76347.1","0.6901327","15"],["76344.7","0.04845045","1"],["76342","0.0062","1"],["76338","0.13650402","3"],["76333.7","0.00654658","1"],["76331.3","0.32734877","1"],["76329.5","0.20073342","3"],["76329.3","0.14473146","1"],["76292.6","0.03332601","2"],["76194.3","0","0"],["76193.9","0","0"]]}
{"instId":"BTC-USDT","action":"update","ts":"1776816049190","asks":[["76357.5","0.1799314","2"],["76358.8","0.47151308","1"],["76361.8","0.26791312","1"],["76365.2","0","0"],["76368.3","1.00605137","1"],["76377","0.08378297","1"],["76380.2","0","0"],["76416.5","0","0"],["76419.1","1.92109478","1"],["76463.3","0","0"],["76463.4","0","0"]],"bids":[["76344.7","0","0"],["76338.1","0.04558483","1"],["76338","0.29303662","4"],["76336.9","0.00654676","1"],["76333.7","0","0"],["76333.6","0.75318729","3"],["76331.4","0.32736201","2"],["76331.3","0","0"],["76329.6","0.24849523","2"],["76329.3","0","0"],["76328.3","0.00001086","1"],["76194.3","0.0018792","9"]]}
{"instId":"BTC-USDT","action":"update","ts":"1776816049200","asks":[["76355.7","0.03","2"],["76357.5","0.31500255","3"],["76372.4","0.08378297","1"],["76463.1","0","0"],["76463.2","0","0"]],"bids":[["76342.9","0.11406904","2"],["76338.8","0.00654675","1"],["76338.1","0.08843609","2"],["76336.9","0","0"],["76333.2","0.32735018","1"],["76331.4","0.00001316","1"],["76235.3","0.08378297","1"],["76195.1","0","0"],["76194.3","0","0"]]}
{"instId":"BTC-USDT","action":"update","ts":"1776816049210","asks":[["76347.2","0.33036155","6"],["76358.7","0.00654674","1"],["76365.3","0.32735018","1"],["76365.4","0.48711735","2"],["76366.7","0.00654694","1"],["76380","0.0000812","1"],["76395.1","0.00001316","1"],["76462.5","0","0"],["76462.6","0","0"],["76463","0","0"]],"bids":[["76343","0.03590031","1"],["76342","0.1062","2"],["76338.8","0","0"],["76338.2","0.00654674","1"],["76336.8","0","0"],["76335.6","0","0"],["76333.1","0.0131","1"],["76331.3","0.00654694","1"],["76329.6","0.24194828","1"],["76329.5","0.11695045","2"]]}
{"instId":"BTC-USDT","action":"update","ts":"1776816049220","asks":[["76372.5","0.47365436","2"],["76377.9","0","0"],["76462.5","0.00001257","1"]],"bids":[["76347.1","0.69275139","16"],["76343","0.16116052","3"],["76333.6","0.65318729","2"],["76294.1","0.00325259","1"],["76291.1","0.00234958","2"],["76287.8","0","0"],["76285.3","0","0"],["76195.1","0.01457366","1"]]}
{"instId":"BTC-USDT","action":"update","ts":"1776816049230","asks":[["76365.1","0.15706","2"],["76368.5","0.08378297","1"],["76377.1","1.06501401","2"],["76462.3","0","0"],["76462.5","0","0"]],"bids":[["76343.1","0.10314048","1"],["76343","0.1","1"],["76303.4","0.10564037","1"],["76296.9","0.00325259","1"],["76294.1","0.00233642","1"],["76291.1","0.00001316","1"],["76231","0.08378297","1"],["76196.5","0","0"],["76195.4","0","0"],["76195.1","0","0"]]}
{"instId":"BTC-USDT","action":"update","ts":"1776816049240","asks":[["76347.2","0.32666","5"],["76358.7","0","0"],["76359.8","0.00654659","1"]],"bids":[["76343.1","0.20314048","2"],["76338.8","0.00654659","1"],["76338.2","0","0"],["76338","0.03650402","2"]]}
{"instId":"BTC-USDT","action":"update","ts":"1776816049250","asks":[["76368.2","0.08379613","2"],["76368.5","0","0"],["76462.3","0.00027227","4"]],"bids":[["76338.1","0","0"],["76196.5","0.00034725","1"]]}
{"instId":"BTC-USDT","action":"update","ts":"1776816049260","asks":[["76347.2","0.32546","4"],["76366.6","0.00654678","1"],["76366.7","0","0"],["76391.3","0.17053864","2"],["76401.6","0.00130887","1"],["76462.3","0","0"]],"bids":[["76337.1","0.11638101","2"],["76336.3","0.02619","1"],["76334.4","0","0"],["76331.4","0.00655994","2"],["76331.3","0","0"],["76330.6","0","0"],["76326.8","0","0"],["76325.3","0","0"],["76322.9","0","0"],["76319.1","0","0"],["76315.3","0","0"],["76311.5","0","0"],["76307.7","0.00001035","1"],["76303.8","0","0"],["76300","0.00358153","3"],["76296.2","1.47767516","2"],["76292.4","0","0"],["76288.6","0","0"],["76284.7","0.47151308","1"],["76280.9","0","0"],["76277.1","0.42384443","2"],["76273.3","0.76659385","1"],["76269.5","0.00001035","1"],["76195.4","0.00098504","2"],["76195.1","0.01457366","1"],["76194.3","0.0018792","9"],["76193.9","0.01496","1"],["76193.7","0.00009338","1"],["76193.4","0.00002624","1"],["76193.2","0.47151308","1"],["76193.1","0.00004445","1"],["76192.7","0.00013126","1"],["76192.3","2.54203491","4"],["76192.2","0.00007834","2"],["76191.2","0.0000842","4"]]}
{"instId":"BTC-USDT","action":"update","ts":"1776816049270","asks":[["76401.2","0","0"],["76411.1","0.0838228","2"],["76462.3","0.00027227","4"]],"bids":[["76338.1","0.0534539","1"],["76284.2","0.00324453","2"],["76275","0","0"],["76191.7","0.1305","1"],["76191.2","0","0"]]}
{"instId":"BTC-USDT","action":"update","ts":"1776816049280","asks":[["76347.2","0.40804005","5"],["76358.7","0.00654651","1"],["76359.8","0","0"],["76365.5","0.09863178","2"],["76366.6","0","0"],["76462.5","0.00001257","1"]],"bids":[["76338.8","0","0"],["76338.2","0.00654651","1"],["76331.4","0.00001316","1"],["76330.5","0.00654678","1"],["76191.7","0","0"]]}
{"instId":"BTC-USDT","action":"update","ts":"1776816049290","asks":[["76362.8","0","0"],["76462.6","0.47226231","9"]],"bids":[["76346.5","0.01015168","4"],["76323.2","0.10150532","2"],["76192.2","0","0"]]}
{"instId":"BTC-USDT","action":"update","ts":"1776816049300","asks":[["76347.2","0.40794706","5"],["76349.6","0.00004181","1"],["76365.5","0.092085","1"],["76366.7","0.00654682","1"],["76368.1","1.00608048","2"],["76368.3","0","0"],["76404.2","0.1","1"],["76462.5","0","0"],["76462.6","0","0"]],"bids":[["76331.3","0.00654682","1"],["76330.5","0","0"]]}
{"instId":"BTC-USDT","action":"update","ts":"1776816049310","asks":[["76347.2","0.34478706","4"]],"bids":[["76344.8","0.00003075","1"],["76271.2","0.00014144","2"],["76265.1","0","0"],["76262.7","0.02385915","2"],["76256.6","0","0"],["76192.2","0.00007834","2"]]}
{"instId":"BTC-USDT","action":"update","ts":"1776816049320","asks":[["76374.9","0.01564782","2"],["76413.9","1.92109478","1"],["76419.1","0","0"]],"bids":[["76319.8","0","0"],["76191.2","0.0000842","4"]]}
{"instId":"BTC-USDT","action":"update","ts":"1776816049330","asks":[["76411.1","0.08378297","1"],["76411.2","0.70141494","2"]],"bids":[["76191.7","0.1305","1"],["76191.2","0","0"]]}
{"instId":"BTC-USDT","action":"update","ts":"1776816049340","asks":[["76400.9","1.92109478","1"],["76413.9","0","0"]],"bids":[]}
{"instId":"BTC-USDT","action":"update","ts":"1776816049350","asks":[["76365","0.32733637","1"],["76365.3","0","0"],["76411.2","0.13771388","1"]],"bids":[["76333.2","0","0"],["76331.3","0.33388319","2"],["76191.2","0.0000842","4"]]}
{"instId":"BTC-USDT","action":"update","ts":"1776816049360","asks":[["76365.2","0.00654669","1"],["76366","0.01614584","1"],["76366.7","0","0"],["76462.3","0","0"]],"bids":[["76331.3","0.32733637","1"],["76330.5","0.00654669","1"],["76191.2","0","0"]]}
{"instId":"BTC-USDT","action":"update","ts":"1776816049370","asks":[],"bids":[["76338.7","0","0"],["76338","0.00050402","1"],["76191.2","0.0000842","4"]]}
{"instId":"BTC-USDT","action":"update","ts":"1776816049380","asks":[],"bids":[["76332.9","0.32733617","1"],["76331.3","0","0"],["76309.5","0.00002864","1"],["76301.2","0","0"]]}
{"instId":"BTC-USDT","action":"update","ts":"1776816049400","asks":[["76395.7","1.90845271","1"],["76400.9","0","0"]],"bids":[["76341.4","0.00001316","1"],["76338.1","0.05346706","2"],["76191.2","0","0"]]}
{"instId":"BTC-USDT","action":"update","ts":"1776816049410","asks":[["76411","0.00004004","1"],["76462.2","0","0"]],"bids":[]}
{"instId":"BTC-USDT","action":"update","ts":"1776816049420","asks":[["76411","0","0"],["76462.2","0.00551437","1"]],"bids":[["76342","0.1062168","3"],["76338.2","0.00656331","2"],["76334.4","0.0000168","1"],["76330.6","0.0000168","1"],["76326.8","0.0000168","1"],["76322.9","0.0000168","1"],["76319.1","0.0000168","1"],["76315.3","0.00001681","1"],["76311.5","0.00001681","1"],["76307.7","0.00002716","2"],["76193.4","0","0"],["76193.2","0","0"],["76193.1","0","0"],["76192.7","0","0"],["76192.3","0","0"],["76192.2","0","0"],["76191.7","0","0"]]}
{"instId":"BTC-USDT","action":"update","ts":"1776816049430","asks":[["76357.4","0.16","1"],["76462.2","0","0"]],"bids":[]}
{"instId":"BTC-USDT","action":"update","ts":"1776816049440","asks":[["76357.3","0.13298081","1"],["76357.6","0","0"]],"bids":[]}
{"instId":"BTC-USDT","action":"update","ts":"1776816049450","asks":[],"bids":[["76235.4","0","0"],["76193.4","0.00002624","1"]]}
{"instId":"BTC-USDT","action":"update","ts":"1776816049460","asks":[["76361.7","1.00605137","1"],["76462","0","0"]],"bids":[]}
{"instId":"BTC-USDT","action":"update","ts":"1776816049470","asks":[["76361.6","0.56463746","1"],["76361.8","0","0"],["76411","0.00004004","1"],["76461.7","0","0"]],"bids":[["76343.2","0.08303337","1"],["76343.1","0.1","1"],["76193.4","0","0"]]}
{"instId":"BTC-USDT","action":"update","ts":"1776816049480","asks":[["76362.4","0.012","1"],["76461.6","0","0"]],"bids":[]}
{"instId":"BTC-USDT","action":"update","ts":"1776816049490","asks":[["76349.9","0.01131238","1"],["76353.1","0","0"],["76365.2","0","0"],["76366.7","0.00654671","1"]],"bids":[["76331.3","0.00654671","1"],["76330.5","0","0"]]}
{"instId":"BTC-USDT","action":"update","ts":"1776816049500","asks":[["76347.2","0.34479706","5"]],"bids":[]}
{"instId":"BTC-USDT","action":"update","ts":"1776816049510","asks":[["76367.7","0.01109717","1"],["76461.5","0","0"]],"bids":[]}
{"instId":"BTC-USDT","action":"update","ts":"1776816049520","asks":[],"bids":[["76332.9","0","0"],["76331.3","0.33388443","2"],["76193.4","0.00002624","1"]]}
{"instId":"BTC-USDT","action":"update","ts":"1776816049530","asks":[["76347.2","0.36916706","6"]],"bids":[]}
{"instId":"BTC-USDT","action":"update","ts":"1776816049550","asks":[["76357.3","0.13952727","2"],["76358.7","0","0"],["76461.5","0.01228943","9"]],"bids":[["76338.2","0.0000168","1"],["76337.2","0.00654646","1"],["76193.4","0","0"]]}
{"instId":"BTC-USDT","action":"update","ts":"1776816049560","asks":[["76461.5","0.14278943","10"]],"bids":[["76343.2","0.11483967","2"]]}
{"instId":"BTC-USDT","action":"update","ts":"1776816049610","asks":[],"bids":[["76337.2","0.12637218","2"]]}
{"instId":"BTC-USDT","action":"update","ts":"1776816049620","asks":[],"bids":[["76338.1","0.00001316","1"],["76337.3","0.08028456","1"],["76193.7","0","0"]]}
{"instId":"BTC-USDT","action":"update","ts":"1776816049630","asks":[],"bids":[["76337.4","0.12500196","1"],["76337.1","0.00001501","1"],["76332.8","0","0"]]}
{"instId":"BTC-USDT","action":"update","ts":"1776816049640","asks":[],"bids":[["76337.5","0.08286239","1"],["76337.3","0","0"]]}
{"instId":"BTC-USDT","action":"update","ts":"1776816049650","asks":[],"bids":[["76337.6","0.10904221","1"],["76337.2","0.00654646","1"],["76193.9","0","0"]]}
{"instId":"BTC-USDT","action":"update","ts":"1776816049660","asks":[],"bids":[["76337.7","0.07964351","1"],["76337.5","0","0"]]}
{"instId":"BTC-USDT","action":"update","ts":"1776816049670","asks":[],"bids":[["76303","0.00131056","1"],["76300.6","0.0013106","1"],["76290.5","0","0"],["76289.4","0","0"]]}
{"instId":"BTC-USDT","action":"update","ts":"1776816049680","asks":[["76361.8","0.08378297","1"],["76461.5","0","0"]],"bids":[]}
{"instId":"BTC-USDT","action":"update","ts":"1776816049760","asks":[],"bids":[["76328","0.01595872","3"]]}
{"instId":"BTC-USDT","action":"update","ts":"1776816049780","asks":[["76355.7","0.50151308","3"],["76364.9","0.00655993","2"],["76366.7","0","0"],["76461.5","0.01228943","9"]],"bids":[["76347.1","0.66896139","15"],["76331.3","0.32733772","1"],["76329.7","0.00654677","1"],["76218.5","0.00514613","1"],["76195.1","0","0"],["76194.3","0","0"]]}
{"instId":"BTC-USDT","action":"update","ts":"1776816049790","asks":[["76355.6","0.14970165","1"],["76461.5","0","0"]],"bids":[]}
{"instId":"BTC-USDT","action":"update","ts":"1776816049850","asks":[["76347.2","0.33946005","5"],["76391.4","0","0"],["76395.9","0","0"],["76461.5","0.01228943","9"],["76461.6","0.00332668","1"]],"bids":[]}
{"instId":"BTC-USDT","action":"update","ts":"1776816049860","asks":[["76392.5","0.20471405","1"],["76395.7","0","0"],["76400.9","1.90845271","1"],["76461.5","0.14278943","10"]],"bids":[["76347.1","0.67516139","16"],["76342","0.1000168","2"],["76333.3","0.00261897","1"],["76330.3","0","0"],["76314.8","0.05239226","1"],["76307.1","0","0"]]}
{"instId":"BTC-USDT","action":"update","ts":"1776816049930","asks":[["76357.3","0.13298081","1"],["76358.7","0.00654646","1"],["76461.6","0","0"]],"bids":[["76337.8","0.00654646","1"],["76337.2","0","0"]]}
{"instId":"BTC-USDT","action":"update","ts":"1776816049940","asks":[["76364.9","0.00001316","1"],["76365.9","0.00656847","2"]],"bids":[["76331.3","0.33388449","2"],["76329.7","0","0"],["76195.1","0.01457366","1"]]}
{"instId":"BTC-USDT","action":"update","ts":"1776816049950","asks":[["76364.8","0.00654676","1"],["76365.9","0.0000217","1"],["76461.5","0","0"]],"bids":[["76331.3","0.32733772","1"],["76329.8","0.00654676","1"],["76195.1","0","0"]]}
{"instId":"BTC-USDT","action":"update","ts":"1776816050010","asks":[["76357.2","0.00654648","1"],["76358.7","0","0"],["76364.8","0","0"],["76364.9","0.00655987","2"],["76461.5","0.01228943","9"]],"bids":[["76329.8","0","0"],["76329.7","0.00654671","1"]]}
{"instId":"BTC-USDT","action":"update","ts":"1776816050020","asks":[["76357.2","0.13422328","2"],["76357.5","0.17946374","2"],["76395.7","1.90852886","1"],["76400.9","0","0"],["76461.5","0.14278943","10"]],"bids":[["76329.8","0.00654671","1"],["76329.7","0","0"]]}
{"instId":"BTC-USDT","action":"update","ts":"1776816050030","asks":[["76357.1","0.00654649","1"],["76357.2","0.1276768","1"],["76461.5","0","0"]],"bids":[]}
{"instId":"BTC-USDT","action":"update","ts":"1776816050040","asks":[["76357.1","0.13156336","2"],["76357.3","0","0"],["76461.5","0.01228943","9"]],"bids":[["76296.9","0","0"],["76296.8","0.00325241","1"]]}
{"instId":"BTC-USDT","action":"update","ts":"1776816050050","asks":[["76355.6","0.20794578","2"],["76461.5","0.14278943","10"]],"bids":[]}
{"instId":"BTC-USDT","action":"update","ts":"1776816050070","asks":[["76357.1","0.12501687","1"],["76357.3","0.00654655","1"],["76461.5","0","0"]],"bids":[]}
{"instId":"BTC-USDT","action":"update","ts":"1776816050090","asks":[["76374.9","0.00001316","1"],["76450.7","0.02348858","1"],["76453.7","0.02348858","1"],["76454.9","0.02348858","1"],["76456.6","0.02348858","1"],["76458.7","0.03963442","2"],["76460.9","0","0"],["76461.1","0","0"],["76461.3","0","0"],["76461.4","0","0"]],"bids":[["76328","0.00002349","2"]]}
{"instId":"BTC-USDT","action":"update","ts":"1776816050110","asks":[["76357.2","0.13422338","2"],["76357.3","0","0"],["76460.9","0.00030148","3"]],"bids":[]}
{"instId":"BTC-USDT","action":"update","ts":"1776816050130","asks":[],"bids":[["76330.5","0.0065467","1"],["76329.8","0","0"]]}
{"instId":"BTC-USDT","action":"update","ts":"1776816050140","asks":[["76355.5","0.16","1"],["76460.9","0","0"]],"bids":[]}
{"instId":"BTC-USDT","action":"update","ts":"1776816050160","asks":[["76357.2","0.1276768","1"],["76358.7","0.00654653","1"],["76364.9","0.00001316","1"],["76365.3","0.0065467","1"],["76460.6","0","0"],["76460.7","0","0"]],"bids":[["76332.8","0.32733655","1"],["76331.3","0","0"]]}
{"instId":"BTC-USDT","action":"update","ts":"1776816050200","asks":[],"bids":[["76297.3","0","0"],["76195.1","0.01457366","1"]]}
{"instId":"BTC-USDT","action":"update","ts":"1776816050240","asks":[["76374.1","0.01602429","1"],["76460.2","0","0"]],"bids":[["76328.7","0.01562034","1"],["76195.1","0","0"]]}
{"instId":"BTC-USDT","action":"update","ts":"1776816050250","asks":[["76347.2","0.34192005","6"],["76377","0.40201991","2"]],"bids":[["76347.1","0.66896139","15"]]}
{"instId":"BTC-USDT","action":"update","ts":"1776816050270","asks":[],"bids":[["76292.6","0","0"],["76195.1","0.01457366","1"]]}
{"instId":"BTC-USDT","action":"update","ts":"1776816050300","asks":[],"bids":[["76306.4","0.2305","2"]]}
{"instId":"BTC-USDT","action":"update","ts":"1776816050410","asks":[["76442.2","0.14442363","5"],["76448.9","0.00005808","2"]],"bids":[]}
{"instId":"BTC-USDT","action":"update","ts":"1776816050420","asks":[["76347.2","0.50192005","7"],["76355.6","0.36794578","3"],["76437.4","0.37094139","2"]],"bids":[["76332.8","0","0"],["76331.3","0.3273374","1"]]}
{"instId":"BTC-USDT","action":"update","ts":"1776816050430","asks":[],"bids":[["76328.7","0","0"],["76194.3","0.0018792","9"]]}
{"instId":"BTC-USDT","action":"update","ts":"1776816050450","asks":[["76358.7","0.00654661","1"]],"bids":[]}
{"instId":"BTC-USDT","action":"update","ts":"1776816050490","asks":[["76347.2","0.34192005","6"],["76395.7","0","0"],["76400.9","1.90852884","1"]],"bids":[]}
{"instId":"BTC-USDT","action":"update","ts":"1776816050500","asks":[],"bids":[["76332.8","0.32733806","1"],["76331.3","0","0"]]}
{"instId":"BTC-USDT","action":"update","ts":"1776816050530","asks":[["76365.3","0","0"],["76365.7","0.00654672","1"]],"bids":[]}
{"instId":"BTC-USDT","action":"update","ts":"1776816050540","asks":[],"bids":[["76309.5","0","0"],["76193.9","0.01496","1"]]}
{"instId":"BTC-USDT","action":"update","ts":"1776816050590","asks":[],"bids":[["76292.6","0.01675821","1"],["76292.5","0.01661397","1"],["76194.3","0","0"],["76193.9","0","0"]]}
{"instId":"BTC-USDT","action":"update","ts":"1776816050600","asks":[["76395.7","1.90852884","1"],["76400.9","0","0"]],"bids":[]}
{"instId":"BTC-USDT","action":"update","ts":"1776816050620","asks":[],"bids":[["76328.7","0.01627079","1"],["76195.1","0","0"]]}
{"instId":"BTC-USDT","action":"update","ts":"1776816050630","asks":[["76384.7","0.06524427","1"],["76460.1","0","0"]],"bids":[["76328.7","0","0"],["76195.1","0.01457366","1"]]}
{"instId":"BTC-USDT","action":"update","ts":"1776816050650","asks":[],"bids":[["76347.1","0.58630129","13"],["76332.8","0","0"],["76331.3","0.32734082","1"]]}
{"instId":"BTC-USDT","action":"update","ts":"1776816050660","asks":[["76357.4","0.16654653","2"],["76358.7","0","0"],["76460.1","0.0022005","4"]],"bids":[["76331.2","0.01614584","1"]]}
{"instId":"BTC-USDT","action":"update","ts":"1776816050670","asks":[["76349.9","0","0"],["76357.4","0.16","1"],["76358.7","0.00654659","1"],["76411","0","0"],["76460.2","0.00162671","12"]],"bids":[["76342.9","0.1","1"],["76333.6","0.29224856","1"],["76308.2","0.06504333","1"],["76195.1","0","0"]]}
{"instId":"BTC-USDT","action":"update","ts":"1776816050680","asks":[["76347.7","0.01062572","1"],["76358.6","0.00654659","1"],["76358.7","0","0"],["76460.2","0","0"]],"bids":[["76340.4","0.01487595","1"],["76332.8","0.32734169","1"],["76331.3","0","0"],["76309.5","0.00002864","1"],["76196.5","0","0"],["76195.4","0","0"]]}
{"instId":"BTC-USDT","action":"update","ts":"1776816050690","asks":[],"bids":[["76340.4","0","0"],["76336.6","0.0148767","1"]]}
{"instId":"BTC-USDT","action":"update","ts":"1776816050700","asks":[["76365.7","0","0"],["76365.9","0.00656853","2"],["76460.2","0.00162671","12"]],"bids":[["76331.3","0.00654683","1"],["76330.5","0","0"]]}
{"instId":"BTC-USDT","action":"update","ts":"1776816050710","asks":[["76365.9","0.0000217","1"],["76366.7","0.00654683","1"],["76460.2","0","0"]],"bids":[["76333.7","0.32734298","1"],["76332.8","0","0"]]}
{"instId":"BTC-USDT","action":"update","ts":"1776816050720","asks":[["76358.6","0","0"],["76359.8","0.00654654","1"]],"bids":[["76333.7","0","0"],["76333.6","0.20013072","1"],["76332.8","0.32734297","1"]]}
{"instId":"BTC-USDT","action":"update","ts":"1776816050730","asks":[["76365.7","0.00654687","1"],["76366.7","0","0"]],"bids":[["76331.3","0","0"],["76331.2","0.02269271","2"],["76196.5","0.00034725","1"]]}
{"instId":"BTC-USDT","action":"update","ts":"1776816050740","asks":[],"bids":[["76331.2","0.01614584","1"],["76330.5","0.00654689","1"],["76196.5","0","0"]]}
{"instId":"BTC-USDT","action":"update","ts":"1776816050750","asks":[["76347.2","0.40442005","7"]],"bids":[["76347.1","0.52240129","11"]]}
{"instId":"BTC-USDT","action":"update","ts":"1776816050760","asks":[["76357.3","0.00654657","1"],["76359.8","0","0"]],"bids":[["76332.8","0","0"],["76331.2","0.34349617","2"],["76196.5","0.00034725","1"]]}
{"instId":"BTC-USDT","action":"update","ts":"1776816050780","asks":[["76364.9","0.00656018","2"],["76365.7","0","0"],["76460.2","0.00162671","12"]],"bids":[["76330.5","0","0"],["76329.7","0.00654702","1"]]}
{"instId":"BTC-USDT","action":"update","ts":"1776816050790","asks":[["76357","0.00654657","1"],["76357.3","0","0"],["76362.4","0.33935262","2"],["76365","0","0"],["76460.6","0.00002799","2"]],"bids":[["76347.1","0.49260129","10"],["76337.8","0","0"],["76336.7","0.00654657","1"]]}
{"instId":"BTC-USDT","action":"update","ts":"1776816050800","asks":[["76355.4","0.12235693","1"],["76357.2","0","0"]],"bids":[["76347.1","0.38760129","9"],["76333.3","0","0"],["76327.5","0.00261917","1"]]}
{"instId":"BTC-USDT","action":"update","ts":"1776816050810","asks":[["76364.9","0.00001316","1"],["76365","0.00654704","1"],["76460.6","0","0"]],"bids":[["76347.1","0.4474826","9"],["76329.7","0","0"],["76328.3","0.0065579","2"],["76195.4","0.00098504","2"]]}
{"instId":"BTC-USDT","action":"update","ts":"1776816050820","asks":[["76362.4","0.012","1"],["76365","0.33390076","2"],["76411","0.00004004","1"],["76460.2","0","0"]],"bids":[["76329.7","0.00654704","1"],["76328.3","0.00001086","1"],["76195.4","0","0"]]}
{"instId":"BTC-USDT","action":"update","ts":"1776816050840","asks":[["76362.4","0.33935384","2"],["76365","0.00654704","1"]],"bids":[]}
{"instId":"BTC-USDT","action":"update","ts":"1776816050850","asks":[["76362.4","0.012","1"],["76365","0.33390044","2"]],"bids":[]}
{"instId":"BTC-USDT","action":"update","ts":"1776816050890","asks":[["76362.4","0.33936015","2"],["76365","0.00654704","1"],["76394.6","0.00130899","1"],["76394.7","0","0"]],"bids":[]}
{"instId":"BTC-USDT","action":"update","ts":"1776816050940","asks":[],"bids":[["76329.7","0","0"],["76328.3","0.00655798","2"],["76195.4","0.00098504","2"]]}
{"instId":"BTC-USDT","action":"update","ts":"1776816051020","asks":[["76384.2","0.25728917","2"],["76392.4","0.12226527","1"]],"bids":[["76329.6","0.24849541","2"],["76328.3","0.00001086","1"]]}
{"instId":"BTC-USDT","action":"update","ts":"1776816051040","asks":[],"bids":[["76329.6","0.24194828","1"],["76328.3","0.00655799","2"]]}
{"instId":"BTC-USDT","action":"update","ts":"1776816051060","asks":[["76361.6","0.89199517","2"],["76362.4","0.012","1"]],"bids":[["76336.7","0","0"],["76336.4","0.0065465","1"],["76331.2","0.01614584","1"],["76329.7","0.32735771","1"],["76195.4","0","0"]]}
{"instId":"BTC-USDT","action":"update","ts":"1776816051070","asks":[["76361.6","0.56463746","1"],["76361.8","0.41114067","2"]],"bids":[["76329.8","0.3273577","1"],["76329.7","0","0"]]}
{"instId":"BTC-USDT","action":"update","ts":"1776816051080","asks":[],"bids":[["76331.2","0.34350357","2"],["76329.8","0","0"],["76195.4","0.00098504","2"]]}
{"instId":"BTC-USDT","action":"update","ts":"1776816051090","asks":[],"bids":[["76331.2","0.34350209","2"]]}
{"instId":"BTC-USDT","action":"update","ts":"1776816051170","asks":[],"bids":[["76325.1","0.01535195","1"],["76195.4","0","0"]]}
{"instId":"BTC-USDT","action":"update","ts":"1776816051210","asks":[],"bids":[["76341.8","0.00054698","1"],["76327.3","0.01582236","1"],["76198.2","0","0"],["76196.5","0","0"]]}
{"instId":"BTC-USDT","action":"update","ts":"1776816051240","asks":[["76361.8","0.08378297","1"],["76362.4","0.33935254","2"]],"bids":[["76338","0.00053678","2"],["76307.2","0.08414354","2"]]}
{"instId":"BTC-USDT","action":"update","ts":"1776816051300","asks":[["76404.2","0","0"],["76460.2","0.00162671","12"]],"bids":[]}
{"instId":"BTC-USDT","action":"update","ts":"1776816051310","asks":[["76380","0.1086012","2"]],"bids":[]}
{"instId":"BTC-USDT","action":"update","ts":"1776816051350","asks":[],"bids":[["76278.2","0.345742","1"],["76260.3","0.00065564","1"],["76198.3","0","0"]]}
{"instId":"BTC-USDT","action":"update","ts":"1776816051360","asks":[],"bids":[["76280.7","0.36608968","3"],["76260.4","0.14500978","1"]]}
{"instId":"BTC-USDT","action":"update","ts":"1776816051400","asks":[["76347.2","0.56442005","8"],["76404.3","0.1","1"],["76460.2","0","0"]],"bids":[]}
{"instId":"BTC-USDT","action":"update","ts":"1776816051410","asks":[["76355.3","0.16","1"],["76361.7","1.33340408","2"],["76362.4","0.012","1"],["76453.7","0.02350174","2"],["76460.1","0","0"]],"bids":[["76334.7","0.00001316","1"],["76331.2","0.01614584","1"],["76329.7","0.32735271","1"],["76218.5","0","0"],["76199.3","0","0"]]}
{"instId":"BTC-USDT","action":"update","ts":"1776816051420","asks":[["76355.3","0.48101688","2"],["76355.6","0.16","1"]],"bids":[["76325.1","0","0"],["76292.6","0","0"],["76292.5","0","0"],["76199.3","0.00040006","1"],["76198.3","0.01437429","1"],["76198.2","0.04493904","1"]]}
{"instId":"BTC-USDT","action":"update","ts":"1776816051440","asks":[["76361.7","1.00605137","1"],["76361.8","0.41113568","2"]],"bids":[["76331.2","0.34349855","2"],["76329.7","0","0"],["76196.5","0.00034725","1"]]}
{"instId":"BTC-USDT","action":"update","ts":"1776816051540","asks":[["76361.8","0.08378297","1"],["76362.4","0.33935181","2"]],"bids":[]}
{"instId":"BTC-USDT","action":"update","ts":"1776816051590","asks":[["76357","0.09032954","2"],["76361.8","0.41113502","2"],["76362.4","0.012","1"]],"bids":[["76331.2","0.01614584","1"],["76331.1","0","0"],["76329.7","0.32735205","1"],["76327.9","0","0"],["76324","0","0"],["76323.8","0","0"],["76321","0","0"],["76315.6","0.00001033","1"],["76289.7","0.11117268","1"],["76221","0.08378297","1"],["76211.3","0.08378297","1"],["76201.3","0.08378297","1"]]}
{"instId":"BTC-USDT","action":"update","ts":"1776816051600","asks":[["76352.4","0.1118313","2"],["76355.6","0.16654652","2"],["76357","0.08378297","1"],["76362.6","0.1305","1"],["76460","0","0"]],"bids":[["76347.1","0.30799996","5"],["76343.2","0","0"],["76336.4","0.00654652","1"],["76333.6","0.05664808","1"],["76329.6","0","0"],["76325.2","0","0"],["76195.4","0.00098504","2"],["76195.1","0.01457366","1"],["76194.3","0.0018792","9"]]}
{"instId":"BTC-USDT","action":"update","ts":"1776816051610","asks":[["76346.6","1.35868352","21"],["76347.1","0.33166364","2"],["76347.2","0.06251","2"],["76349.9","0.04233664","1"],["76355.4","0.12890349","2"],["76355.6","0.16","1"],["76358.7","0.32735914","1"],["76361.8","0.08378297","1"],["76361.9","0.47806028","2"],["76362.5","0","0"],["76365","0","0"],["76370.4","0.05896264","1"],["76377.1","1.00605137","1"],["76400.6","0","0"],["76453.7","0.02348858","1"],["76459.8","0","0"],["76459.9","0","0"]],"bids":[["76347.1","0","0"],["76336.6","0","0"],["76336.4","0","0"],["76333.7","0.00654656","1"],["76329.8","0.17941169","1"],["76329.7","0","0"],["76328.3","0.00001086","1"],["76327.9","0.32735914","1"],["76327.4","0.0065472","1"],["76324.2","0.47151308","1"],["76321","1.00593145","1"],["76316.5","0.00001086","1"],["76316.4","0.08378297","1"],["76201.3","0","0"],["76195.1","0","0"],["76194.3","0","0"]]}
{"instId":"BTC-USDT","action":"update","ts":"1776816051620","asks":[["76346.6","1.3623848","22"],["76347","0.12084509","1"],["76347.1","0","0"],["76347.2","0.00001","1"],["76354.3","0.10606946","1"],["76355","0.00654664","1"],["76355.4","0.12235693","1"],["76361.5","0.00656036","2"],["76361.9","0.63061727","4"],["76392.4","0","0"],["76437.4","0.00196024","1"],["76459.7","0","0"]],"bids":[["76337.4","0","0"],["76334.2","0.01515766","10"],["76333.7","0","0"],["76333.2","0.00654664","1"],["76331.2","0","0"],["76327.9","0","0"],["76327.4","0","0"],["76324.3","1.18497597","5"],["76324.2","0","0"],["76321.1","1.47744453","2"],["76321","0","0"],["76320.9","0","0"],["76319.3","0.00040006","1"],["76315.9","0.15774603","2"],["76284.9","0.12121249","1"],["76195.1","0.01457366","1"],["76194.3","0.0018792","9"],["76193.9","0.01496","1"]]}
{"instId":"BTC-USDT","action":"update","ts":"1776816051630","asks":[["76347","0","0"],["76352.3","0.00654664","1"],["76355","0","0"],["76359.8","0.0065472","1"],["76361.5","0.00001316","1"]],"bids":[["76337.7","0.04038024","1"],["76333.2","0","0"],["76332.3","0.00654664","1"],["76329.8","0","0"],["76324.4","0.0065472","1"],["76324.3","0.91591226","3"],["76321.2","0.1277032","3"],["76315.9","0.26155956","4"]]}
{"instId":"BTC-USDT","action":"update","ts":"1776816051640","asks":[["76358.6","0.32736127","1"],["76358.7","0","0"]],"bids":[["76324.4","0.33390849","2"],["76324.3","0.58855106","2"]]}
{"instId":"BTC-USDT","action":"update","ts":"1776816051650","asks":[["76390.1","0.00130907","1"],["76401.6","0","0"]],"bids":[["76332.7","0","0"],["76329.6","0.07974279","1"],["76324.5","0.39712404","1"],["76193.9","0","0"]]}
{"instId":"BTC-USDT","action":"update","ts":"1776816051660","asks":[["76361.9","0.57758254","3"]],"bids":[["76333.6","0.01482847","1"],["76306.4","0.1305","1"]]}
{"instId":"BTC-USDT","action":"update","ts":"1776816051670","asks":[["76352.3","0.15816403","2"],["76355.8","0.01614584","1"],["76356.9","0.32736164","1"],["76358.6","0","0"],["76361.9","0.47151308","1"],["76389.1","0.02618757","1"],["76396.8","0.345751","1"],["76459.3","0","0"],["76459.6","0","0"]],"bids":[["76337.6","0","0"],["76336.3","0","0"],["76332.3","0","0"],["76329.7","0.00654675","1"],["76327.3","0","0"],["76324.6","0.3273748","2"],["76324.4","0.0065472","1"],["76324.3","0.11703798","1"],["76322.3","0.56509942","2"],["76321.1","0","0"],["76294.1","0","0"],["76292.8","0.00233631","1"],["76193.9","0.01496","1"],["76193.7","0.00009338","1"],["76193.4","0.00002624","1"],["76193.2","0.47151308","1"]]}
{"instId":"BTC-USDT","action":"update","ts":"1776816051680","asks":[["76349.9","0.08413595","2"],["76352.2","0.09032972","2"],["76352.3","0.15161739","1"],["76355.2","1.00593145","1"],["76356.9","0","0"],["76358.7","0.32736786","1"],["76379.3","0.10573227","2"],["76391.3","0.05359293","1"],["76459.1","0","0"],["76459.2","0","0"]],"bids":[["76340.6","0.05896264","1"],["76337.7","0","0"],["76334.2","0.0002805","9"],["76329.8","0.00654692","1"],["76329.7","0","0"],["76327.1","0","0"],["76325.1","0.01551087","1"],["76324.7","0.58374927","2"],["76324.6","0.00001316","1"],["76324.5","0","0"],["76324.1","0","0"],["76323.6","0.00001034","1"],["76322.3","0","0"],["76318.8","0.00305","1"],["76316.4","0","0"],["76313.9","0","0"],["76303","0","0"],["76300.6","0","0"],["76298.9","0.00305","1"],["76297.8","0.12232472","3"],["76295.2","0.08509366","2"],["76290.9","0.11703798","1"],["76290.5","0.00131077","1"],["76289.8","0.02619813","2"],["76285.4","0.05897298","2"],["76285","0.1276778","1"],["76284.9","0","0"],["76201.3","0.08378297","1"],["76193.1","0.00004445","1"]]}
{"instId":"BTC-USDT","action":"update","ts":"1776816051690","asks":[["76342.1","1.02883029","14"],["76343","0.2305054","2"],["76343.2","0.47151308","1"],["76344.9","0.00370155","1"],["76346.3","0.47151308","1"],["76346.5","0.31757866","2"],["76346.6","0.33815645","5"],["76347.7","0","0"],["76349.6","0","0"],["76352.1","0.15551354","2"],["76352.2","0.08378297","1"],["76352.3","0","0"],["76352.4","0.00001501","1"],["76354.3","0","0"],["76355.1","0.7873299","6"],["76355.3","0","0"],["76355.4","0","0"],["76355.5","0","0"],["76355.6","0","0"],["76356.9","0.32739183","1"],["76357.1","0","0"],["76357.4","0","0"],["76358.7","0","0"],["76361.5","0.11971815","2"],["76362","0","0"],["76363.4","0.05896264","1"],["76365.3","0.11704488","1"],["76368.4","0","0"],["76370.4","0","0"],["76459.1","0.00006716","3"],["76459.2","0.08410468","3"],["76459.3","0.00319921","2"],["76459.6","0.00072458","2"]],"bids":[["76346.5","0","0"],["76344.8","0","0"],["76343.1","0","0"],["76343","0","0"],["76342.9","0","0"],["76329.9","0.00654732","1"],["76329.8","0","0"],["76324.8","0.28040338","1"],["76324.7","0","0"],["76320.5","0.47151308","1"],["76315.9","0","0"],["76311.4","0","0"],["76310","0.00305","1"],["76298.9","0","0"],["76192.7","0.00013126","1"],["76192.3","2.54203491","4"],["76192.2","0.00007834","2"],["76191.2","0.0000842","4"],["76191","0.00014147","1"],["76190.9","0.02066065","5"]]}
{"instId":"BTC-USDT","action":"update","ts":"1776816051700","asks":[["76342.1","1.12780184","16"],["76342.9","0.21065743","1"],["76343.2","0.48213941","2"],["76343.7","0.00262043","1"],["76344.9","0","0"],["76346.5","0.16","1"],["76346.6","0.036","1"],["76349.8","0.10606946","2"],["76352","0.00654731","1"],["76352.1","0.14896622","1"],["76355","0.12768533","1"],["76355.1","0.65964457","5"],["76356.9","0.33393983","2"],["76357.4","0.15910419","2"],["76359.8","0","0"],["76361.4","0.12236511","1"],["76361.5","0.00001316","1"],["76365","0.11552615","1"],["76365.3","0","0"],["76368","0.11970499","1"],["76374.1","0","0"],["76391.3","0.17063781","2"],["76433.6","0","0"],["76459.1","0","0"],["76459.2","0","0"],["76459.3","0","0"],["76459.6","0","0"]],"bids":[["76342","0.10263573","3"],["76330","0.0065473","1"],["76329.9","0","0"],["76326.9","0.01487859","1"],["76325.1","0","0"],["76324.8","0.10615423","1"],["76324.4","0","0"],["76321.3","0.00656116","2"],["76320.5","0","0"],["76316.1","0.00305","1"],["76311.4","0.26155956","4"],["76295.2","0.08378297","1"],["76287.5","0.00131083","1"],["76191.7","0.1305","1"],["76190.9","0","0"]]}
{"instId":"BTC-USDT","action":"update","ts":"1776816051710","asks":[["76342.1","1.28453026","16"],["76346.2","0.19925564","1"],["76349.8","0.05303473","1"],["76352","0.14630611","1"],["76355","0.00654733","1"],["76356.9","0.32738633","1"],["76358.7","0.00654804","1"],["76360","0.07869621","3"],["76384.1","0.10792766","2"],["76384.2","0.1297","1"],["76391.3","0.05359293","1"],["76431.5","0","0"],["76458.8","0","0"]],"bids":[["76342","0.00263573","2"],["76339.8","0.00002944","1"],["76333.7","0.00654733","1"],["76330","0","0"],["76326.9","0","0"],["76324.4","0.01487908","1"],["76323.3","0.00959804","2"],["76321.3","0.16097976","2"],["76318.8","0","0"],["76316.4","0.47151308","1"],["76316.2","0","0"],["76271.2","0.00001033","1"],["76266.7","0.00013112","1"],["76262.7","0.02331696","1"],["76258.1","0.00054221","1"],["76191.7","0","0"],["76191.2","0","0"],["76191","0","0"]]}
{"instId":"BTC-USDT","action":"update","ts":"1776816051720","asks":[["76340.7","1.33211145","18"],["76341.5","0.00370157","1"],["76342","0.59693896","1"],["76342.1","0.19642997","2"],["76342.9","0","0"],["76343","0","0"],["76343.2","0.47151308","1"],["76346.5","0","0"],["76349.8","0","0"],["76351.9","0.16083663","2"],["76352","0","0"],["76355","0","0"],["76356.9","0","0"],["76357.4","0","0"],["76358.7","0.33394491","2"],["76409.8","0.00003981","1"],["76411","0","0"],["76442.2","0.0838237","3"],["76458.8","0.00001501","1"],["76459.1","0.00006716","3"],["76459.2","0.08410468","3"],["76459.3","0.00319921","2"]],"bids":[["76342","0","0"],["76341.8","0","0"],["76341.4","0","0"],["76338.1","0","0"],["76333.7","0","0"],["76329.7","0.00654736","1"],["76321.2","0.0000254","2"],["76316.5","0.21709388","2"],["76311.4","0","0"],["76306.9","0.11704703","1"],["76303.4","0","0"],["76289.7","0","0"],["76284.2","0.00001086","1"],["76283.9","0.00324868","2"],["76279.3","0.12276741","2"],["76221.3","0.00556056","2"],["76191.2","0.0000842","4"],["76191","0.00014147","1"],["76190.9","0.02066065","5"],["76190.4","0.00001319","1"],["76190","0.00001428","1"],["76188.9","0.00002109","2"]]}
{"instId":"BTC-USDT","action":"update","ts":"1776816051730","asks":[["76340.7","1.33581296","19"],["76341.5","0","0"],["76341.7","0.01062654","1"],["76342","0.2001632","1"],["76349.8","0.00654727","1"],["76351.9","0.15428927","1"],["76355.1","0.01048255","4"],["76356.9","0.32740409","1"],["76357.4","0.00654804","1"],["76358.6","0.07867","1"],["76358.7","0","0"],["76361.4","0.13436511","2"],["76367.7","0","0"],["76459.2","0","0"],["76459.3","0","0"]],"bids":[["76340.6","0.06211995","3"],["76323.3","0.00305","1"],["76322.5","0.00654804","1"],["76316.4","0","0"],["76315","0.47151308","1"],["76191.7","0.1305","1"],["76190","0","0"],["76188.9","0","0"]]}
{"instId":"BTC-USDT","action":"update","ts":"1776816051740","asks":[["76355.1","0.58801361","5"],["76356.9","0.33395212","2"],["76357.4","0","0"],["76393.1","1.92276558","1"],["76395.7","0","0"],["76459.2","0.08410468","3"]],"bids":[["76329.7","0","0"],["76328.3","0.00655813","2"],["76323.3","0.33045376","2"],["76322.5","0","0"],["76321.4","0.00654803","1"],["76316.5","0.07634722","2"],["76292.1","0.0336338","2"]]}
{"instId":"BTC-USDT","action":"update","ts":"1776816051750","asks":[["76355.1","0.91541527","6"],["76356.9","0.00654803","1"]],"bids":[["76340.6","0.05950107","2"],["76324.8","0.19371013","2"],["76323.3","0.00305","1"],["76321.4","0.33394969","2"],["76305.8","0.1","1"],["76296.8","0","0"],["76292.8","0","0"],["76291.1","0.00326584","2"],["76288.9","0.00233651","1"]]}
{"instId":"BTC-USDT","action":"update","ts":"1776816051760","asks":[["76354.4","0.00691314","1"],["76359.9","0","0"],["76368.4","0.01619446","1"],["76375","0.29343","1"],["76379.6","0.0524587","2"],["76385.3","0","0"],["76388.1","0","0"],["76389.5","0.18783","1"],["76399.8","0","0"]],"bids":[["76333.1","0","0"],["76328.5","0.0131","1"],["76328.2","0","0"],["76324.8","0.10615423","1"],["76321.5","0.27059122","1"],["76321.3","0.00001316","1"],["76320.4","0","0"],["76314.2","0.01614039","1"],["76311","0.30279","1"],["76190.4","0","0"]]}
{"instId":"BTC-USDT","action":"update","ts":"1776816051770","asks":[],"bids":[["76333.6","0","0"],["76321.5","0.13215988","1"],["76288.9","0","0"],["76287.6","0.00233647","1"],["76190.4","0.00001319","1"]]}
{"instId":"BTC-USDT","action":"update","ts":"1776816051780","asks":[["76348.4","0.10606946","2"],["76355.1","0.92196356","7"],["76356","0.15910419","2"],["76356.9","0","0"],["76365.1","0.07852","1"],["76411.9","0.0221","1"],["76419.9","0","0"],["76459.2","0","0"]],"bids":[["76321.4","0.32740166","1"],["76320.3","0.00654829","1"],["76310","0.26460956","5"],["76190.4","0","0"]]}
{"instId":"BTC-USDT","action":"update","ts":"1776816051790","asks":[["76342.9","0.00002654","1"],["76348.4","0","0"]],"bids":[["76340.6","0.06070107","3"]]}
{"instId":"BTC-USDT","action":"update","ts":"1776816051800","asks":[["76406.8","0.00003981","1"],["76409.8","0","0"]],"bids":[["76340.6","0.12320107","4"],["76283.9","0.000015","1"],["76279.4","0.00323368","1"],["76190.9","0","0"]]}
{"instId":"BTC-USDT","action":"update","ts":"1776816051810","asks":[["76347.2","0.0000268","2"],["76365.1","0","0"],["76459.2","0.08410468","3"]],"bids":[["76340.6","0.15251107","5"],["76330.8","0.0262","1"],["76311.1","0.08378297","1"],["76268.3","0","0"],["76266.7","0","0"],["76265.1","0.00013112","1"],["76258.1","0","0"],["76256.6","0.00054218","1"],["76191","0","0"]]}
{"instId":"BTC-USDT","action":"update","ts":"1776816051820","asks":[["76339.9","0.23271","3"],["76340.7","1.33843184","20"],["76346.6","0.03862043","2"],["76404.2","0.00003981","1"],["76406.8","0","0"],["76459.2","0","0"]],"bids":[["76340.6","0","0"],["76332.3","0.01678464","1"],["76330.8","0","0"],["76321.6","1.00593145","1"],["76279.4","0","0"],["76278.6","0.00323369","1"]]}
{"instId":"BTC-USDT","action":"update","ts":"1776816051830","asks":[["76339.9","0.79779186","14"],["76340.6","0.40269393","1"],["76340.7","0.2468827","3"],["76341.7","0","0"],["76356","0","0"],["76384.7","0","0"],["76445.3","0.0003737","5"],["76459.2","0.08410468","3"],["76459.3","0.00319921","2"]],"bids":[["76339.8","0.06363162","3"],["76332.3","0","0"],["76332.2","0.13","3"],["76321.7","0.43244549","2"],["76321.5","0","0"],["76310","0.00305","1"],["76278.6","0","0"],["76277.2","0.00323369","1"],["76191","0.00014147","1"],["76190.9","0.02066065","5"]]}
{"instId":"BTC-USDT","action":"update","ts":"1776816051840","asks":[["76340.6","0.07369449","1"],["76342.1","0.036","1"]],"bids":[["76339.8","0.10173018","3"],["76332.3","0.03881394","1"],["76314.2","0","0"]]}
{"instId":"BTC-USDT","action":"update","ts":"1776816051850","asks":[["76339.9","0.80841865","15"],["76349.8","0.00654732","1"],["76354.3","0.00654822","1"],["76355.1","0.91541527","6"],["76404.3","0","0"]],"bids":[["76339.8","0.13153018","4"],["76332.3","0.13881394","2"],["76329.7","0.12717648","1"],["76328.3","0.00001086","1"],["76327.6","0.00654732","1"],["76320.3","0","0"],["76319.4","0.00654822","1"],["76309.5","0","0"],["76305.8","0","0"],["76277.2","0","0"],["76190.4","0.00001319","1"]]}
{"instId":"BTC-USDT","action":"update","ts":"1776816051860","asks":[["76355.2","1.2711051","5"],["76357.8","0.07858","1"],["76459.3","0","0"]],"bids":[["76332.4","0.06866394","1"],["76332.3","0.1","1"],["76329.7","0.22717648","2"],["76309.2","0.26155956","4"],["76190.9","0","0"],["76190.4","0","0"]]}
{"instId":"BTC-USDT","action":"update","ts":"1776816051870","asks":[],"bids":[["76329.8","0.13793579","1"],["76329.6","0","0"],["76308.2","0","0"],["76190.9","0.02066065","5"]]}
{"instId":"BTC-USDT","action":"update","ts":"1776816051880","asks":[],"bids":[["76339.8","0.19403018","5"],["76329.9","0.1098441","1"],["76291.1","0.00001316","1"],["76289.7","0.00325266","1"],["76287.6","0","0"],["76286.5","0.00233649","1"],["76279.3","0.00040006","1"],["76191","0","0"],["76190.9","0","0"]]}
{"instId":"BTC-USDT","action":"update","ts":"1776816051900","asks":[["76342.9","0","0"],["76459.3","0.00319921","2"]],"bids":[["76334.4","0.05897944","2"]]}
{"instId":"BTC-USDT","action":"update","ts":"1776816051910","asks":[["76360","0.00009621","2"],["76368.4","0","0"],["76459.6","0.00072458","2"]],"bids":[["76337.6","0.00002852","1"],["76334.5","0.01760536","1"],["76330.8","0.0262","1"],["76313.6","0.01585257","1"],["76256.6","0.00054217","1"],["76192.3","0","0"],["76192.2","0","0"],["76191.7","0","0"],["76191.2","0","0"]]}
{"instId":"BTC-USDT","action":"update","ts":"1776816051920","asks":[["76346.2","0.14075465","1"]],"bids":[["76303.8","0.0000168","1"],["76300","0.00359833","4"],["76296.2","1.47769196","3"],["76292.4","0.0000168","1"],["76288.6","0.0000168","1"],["76284.7","0.47152988","2"],["76280.9","0.0000168","1"],["76277.1","0.42386124","3"],["76273.3","0.76661066","2"],["76269.5","0.00002716","2"],["76193.4","0","0"],["76193.2","0","0"],["76193.1","0","0"],["76192.7","0","0"]]}
{"instId":"BTC-USDT","action":"update","ts":"1776816051930","asks":[],"bids":[["76324.8","0.07461588","1"]]}
{"instId":"BTC-USDT","action":"update","ts":"1776816051940","asks":[["76346.6","0.04124086","3"],["76403.7","0.1","1"],["76459.6","0","0"]],"bids":[["76327.6","0","0"],["76324.9","0.00654735","1"],["76299.9","0.10023748","6"],["76277.2","0.00323371","1"],["76193.7","0","0"]]}
{"instId":"BTC-USDT","action":"update","ts":"1776816051960","asks":[],"bids":[["76330.8","0","0"],["76327.6","0.00654733","1"],["76324.9","0","0"],["76193.7","0.00009338","1"]]}
{"instId":"BTC-USDT","action":"update","ts":"1776816051970","asks":[],"bids":[["76327.6","0","0"],["76324.9","0.00654735","1"]]}
{"instId":"BTC-USDT","action":"update","ts":"1776816051980","asks":[],"bids":[["76338","0.00050402","1"],["76307.2","0.08378297","1"]]}
{"instId":"BTC-USDT","action":"update","ts":"1776816051990","asks":[["76352.2","0","0"],["76459.6","0.00072458","2"]],"bids":[["76303.8","0.00004544","2"]]}
{"instId":"BTC-USDT","action":"update","ts":"1776816052000","asks":[["76342","0.14152885","1"],["76342.1","0.03601996","2"]],"bids":[]}
{"instId":"BTC-USDT","action":"update","ts":"1776816052010","asks":[["76355","0.32740765","1"],["76355.1","0.58801361","5"],["76459.6","0","0"]],"bids":[["76330.8","0.0262","1"],["76321.8","0.32741798","2"],["76321.4","0","0"],["76256.6","0.00054216","1"]]}
{"instId":"BTC-USDT","action":"update","ts":"1776816052020","asks":[["76354.3","0","0"],["76354.9","0.00654812","1"]],"bids":[["76327.6","0.00654731","1"],["76324.9","0","0"]]}
{"instId":"BTC-USDT","action":"update","ts":"1776816052030","asks":[["76340.6","0","0"],["76402.7","0.02335943","2"],["76404.2","0","0"],["76459.6","0.00072458","2"],["76459.7","0.0000534","1"]],"bids":[]}
{"instId":"BTC-USDT","action":"update","ts":"1776816052040","asks":[["76365.3","0.01569832","1"],["76459.7","0","0"]],"bids":[["76339.8","0.19406301","6"],["76313.6","0","0"],["76309.2","0.26188799","5"],["76303.8","0.0000168","1"],["76303.3","0.66188378","3"],["76299.9","0.00023748","5"],["76193.4","0.00002624","1"]]}
{"instId":"BTC-USDT","action":"update","ts":"1776816052050","asks":[["76346.5","0.00654738","1"],["76349.8","0","0"],["76354.3","0.00654812","1"],["76354.9","0","0"],["76356.7","0.012","1"],["76459.6","0","0"]],"bids":[["76327.6","0","0"],["76324.9","0.00654738","1"],["76321.8","0.00001033","1"],["76320.8","0.32745377","2"]]}
{"instId":"BTC-USDT","action":"update","ts":"1776816052060","asks":[["76346.6","0.04386129","4"]],"bids":[]}
{"instId":"BTC-USDT","action":"update","ts":"1776816052090","asks":[],"bids":[["76315","0.55529605","2"],["76201.3","0","0"],["76193.2","0.47151308","1"]]}
{"instId":"BTC-USDT","action":"update","ts":"1776816052100","asks":[["76342.1","0.036","1"]],"bids":[["76324.4","0","0"],["76316.8","0.0156697","1"]]}
{"instId":"BTC-USDT","action":"update","ts":"1776816052110","asks":[],"bids":[["76328.1","0.01387548","1"],["76193.2","0","0"]]}
{"instId":"BTC-USDT","action":"update","ts":"1776816052120","asks":[["76346.5","0","0"],["76349.8","0.00654737","1"]],"bids":[["76320.9","0.32740548","1"],["76320.8","0.0000463","1"],["76193.4","0","0"]]}
{"instId":"BTC-USDT","action":"update","ts":"1776816052130","asks":[["76380.3","0.06389382","1"],["76459.3","0","0"]],"bids":[["76299.1","0.18379798","3"]]}
{"instId":"BTC-USDT","action":"update","ts":"1776816052140","asks":[["76340.6","0.07369449","1"],["76459.2","0","0"]],"bids":[["76278.5","0.47154593","2"]]}
{"instId":"BTC-USDT","action":"update","ts":"1776816052150","asks":[["76355","0.3274054","1"]],"bids":[["76339.8","0.09406301","5"],["76320.9","0","0"],["76320.8","0.3274517","2"],["76193.4","0.00002624","1"]]}
{"instId":"BTC-USDT","action":"update","ts":"1776816052160","asks":[["76346.5","0.00654737","1"],["76349.8","0","0"]],"bids":[]}
{"instId":"BTC-USDT","action":"update","ts":"1776816052180","asks":[],"bids":[["76303.9","0.06489904","1"],["76193.4","0","0"]]}
{"instId":"BTC-USDT","action":"update","ts":"1776816052190","asks":[["76352","0.32740529","1"],["76355","0","0"]],"bids":[]}
{"instId":"BTC-USDT","action":"update","ts":"1776816052200","asks":[["76349.9","0.18645511","1"]],"bids":[]}
{"instId":"BTC-USDT","action":"update","ts":"1776816052210","asks":[],"bids":[["76292.1","0.01696037","1"]]}
{"instId":"BTC-USDT","action":"update","ts":"1776816052220","asks":[],"bids":[["76292.1","0","0"],["76193.4","0.00002624","1"]]}
{"instId":"BTC-USDT","action":"update","ts":"1776816052230","asks":[["76403.7","0","0"],["76459.2","0.08410468","3"]],"bids":[]}
{"instId":"BTC-USDT","action":"update","ts":"1776816052290","asks":[["76365.3","0","0"],["76459.3","0.00319921","2"]],"bids":[]}
{"instId":"BTC-USDT","action":"update","ts":"1776816052300","asks":[["76391.3","0.17064241","2"]],"bids":[]}
{"instId":"BTC-USDT","action":"update","ts":"1776816052320","asks":[["76397.7","0.1","1"],["76459.3","0","0"]],"bids":[]}
{"instId":"BTC-USDT","action":"update","ts":"1776816052330","asks":[["76392.5","0.75287802","2"],["76427","0","0"],["76459.3","0.00319921","2"]],"bids":[]}
{"instId":"BTC-USDT","action":"update","ts":"1776816052340","asks":[["76346.2","0.14730198","2"],["76346.5","0","0"],["76365.2","0.01569832","1"]],"bids":[]}
{"instId":"BTC-USDT","action":"update","ts":"1776816052390","asks":[],"bids":[["76332.5","0.16","1"],["76193.4","0","0"]]}
{"instId":"BTC-USDT","action":"update","ts":"1776816052400","asks":[],"bids":[["76332.6","0.12424464","1"],["76332.4","0","0"]]}
{"instId":"BTC-USDT","action":"update","ts":"1776816052450","asks":[["76344.7","0.00001316","1"],["76348.1","0.00001316","1"],["76459.2","0","0"],["76459.3","0","0"]],"bids":[]}
{"instId":"BTC-USDT","action":"update","ts":"1776816052460","asks":[["76352.1","0","0"],["76355","0.1197097","1"]],"bids":[]}
{"instId":"BTC-USDT","action":"update","ts":"1776816052470","asks":[["76349.8","0.13353301","1"],["76351.9","0.48169438","2"],["76352","0","0"]],"bids":[]}
{"instId":"BTC-USDT","action":"update","ts":"1776816052480","asks":[["76351.9","0.15428927","1"],["76354.9","0.3274051","1"],["76459.1","0","0"]],"bids":[]}
{"instId":"BTC-USDT","action":"update","ts":"1776816052490","asks":[["76349.7","0.1254167","1"],["76349.9","0","0"]],"bids":[]}
{"instId":"BTC-USDT","action":"update","ts":"1776816052500","asks":[["76351.9","0","0"],["76459.1","0.00006716","3"]],"bids":[]}
{"instId":"BTC-USDT","action":"update","ts":"1776816052510","asks":[["76349.7","0.04881908","1"]],"bids":[]}
{"instId":"BTC-USDT","action":"update","ts":"1776816052600","asks":[["76342.1","0.03601411","2"]],"bids":[]}
{"instId":"BTC-USDT","action":"update","ts":"1776816052610","asks":[["76346.2","0.14075465","1"],["76346.5","0.0065473","1"],["76459.1","0","0"]],"bids":[]}
{"instId":"BTC-USDT","action":"update","ts":"1776816052640","asks":[["76340.7","0.1512527","2"],["76365.2","0","0"],["76459.1","0.00006716","3"]],"bids":[["76316.8","0","0"],["76193.4","0.00002624","1"]]}
{"instId":"BTC-USDT","action":"update","ts":"1776816052650","asks":[["76340.6","0","0"],["76459.2","0.08410468","3"]],"bids":[]}
{"instId":"BTC-USDT","action":"update","ts":"1776816052680","asks":[],"bids":[["76319.4","0","0"],["76319.1","0.00656487","2"],["76193.2","0.47151308","1"]]}
{"instId":"BTC-USDT","action":"update","ts":"1776816052740","asks":[["76386.9","0.20965643","2"],["76394.6","0","0"],["76459.3","0.00319921","2"]],"bids":[]}
{"instId":"BTC-USDT","action":"update","ts":"1776816052750","asks":[],"bids":[["76330.8","0.1262","2"]]}
{"instId":"BTC-USDT","action":"update","ts":"1776816052760","asks":[],"bids":[["76329.9","0.2098441","2"]]}
{"instId":"BTC-USDT","action":"update","ts":"1776816052770","asks":[["76340.6","0.04514893","1"],["76459.3","0","0"]],"bids":[]}
{"instId":"BTC-USDT","action":"update","ts":"1776816052800","asks":[["76347.2","0.0000168","1"]],"bids":[]}
{"instId":"BTC-USDT","action":"update","ts":"1776816052820","asks":[],"bids":[["76292.1","0.0336338","2"],["76193.2","0","0"]]}
{"instId":"BTC-USDT","action":"update","ts":"1776816052860","asks":[],"bids":[["76319.1","0.0000168","1"],["76318","0.00654795","1"],["76193.4","0","0"]]}
{"instId":"BTC-USDT","action":"update","ts":"1776816052870","asks":[],"bids":[["76319.1","0.00656476","2"],["76318","0","0"],["76193.4","0.00002624","1"]]}
{"instId":"BTC-USDT","action":"update","ts":"1776816052890","asks":[["76365.6","0.48895074","3"]],"bids":[["76339.8","0.09399752","5"],["76332.5","0","0"],["76318.3","0.01572774","2"],["76193.2","0.47151308","1"]]}
{"instId":"BTC-USDT","action":"update","ts":"1776816052900","asks":[["76361.4","0.12236511","1"]],"bids":[["76311.6","1.69621516","4"]]}
{"instId":"BTC-USDT","action":"update","ts":"1776816053010","asks":[],"bids":[["76321.8","0.47152341","2"]]}
{"instId":"BTC-USDT","action":"update","ts":"1776816053070","asks":[["76346.1","0.00654726","1"],["76346.5","0","0"]],"bids":[]}
{"instId":"BTC-USDT","action":"update","ts":"1776816053080","asks":[["76346.1","0","0"],["76346.5","0.00654726","1"]],"bids":[]}
{"instId":"BTC-USDT","action":"update","ts":"1776816053210","asks":[["76397.7","0","0"],["76459.3","0.00319921","2"]],"bids":[]}
{"instId":"BTC-USDT","action":"update","ts":"1776816053300","asks":[["76346.1","0.00654725","1"],["76346.5","0","0"],["76396.9","0.1","1"],["76459.3","0","0"]],"bids":[]}
{"instId":"BTC-USDT","action":"update","ts":"1776816053340","asks":[["76420.4","0","0"],["76459.3","0.00319921","2"]],"bids":[]}
{"instId":"BTC-USDT","action":"update","ts":"1776816053350","asks":[["76346.1","0","0"],["76346.5","0.00654726","1"]],"bids":[]}
{"instId":"BTC-USDT","action":"update","ts":"1776816053380","asks":[],"bids":[["76332.7","0.16","1"],["76193.2","0","0"]]}
{"instId":"BTC-USDT","action":"update","ts":"1776816053390","asks":[["76340.7","0.036","1"],["76343.2","0","0"],["76346.3","0","0"],["76355.2","0.26517365","4"],["76361.7","0","0"],["76459.6","0.00072458","2"],["76459.7","0.0000534","1"],["76459.8","0.00203787","4"]],"bids":[["76339.8","0.30407757","7"]]}
{"instId":"BTC-USDT","action":"update","ts":"1776816053400","asks":[["76339.9","0.47732515","10"],["76340.6","0","0"],["76340.7","0","0"],["76342","0","0"],["76342.1","0.00001411","1"],["76346.2","0.0150559","1"],["76346.5","0","0"],["76346.6","0.00786129","3"],["76349.6","0.00654727","1"],["76352.2","0.47151308","1"],["76354.3","0","0"],["76354.9","0","0"],["76355.1","0.01048255","4"],["76356.6","0.00654777","1"],["76356.9","0.3273984","1"],["76361.6","0","0"],["76365.3","1.00602765","1"],["76365.6","0.47284533","2"],["76368.1","0.00002911","1"],["76392.4","0.14631033","1"],["76459.9","0.0000212","1"]],"bids":[["76339.8","0.44241355","11"],["76328.2","0.00654727","1"],["76328.1","0","0"],["76324.9","0.79891148","2"],["76320.9","0.00654777","1"],["76320.8","0.0000463","1"],["76319.1","0.0000168","1"],["76193.4","0","0"]]}
{"instId":"BTC-USDT","action":"update","ts":"1776816053410","asks":[["76339.9","0.47112515","9"],["76343.6","0.01561751","1"],["76354.9","0.3273984","1"],["76356.6","0.00654758","1"],["76356.9","0","0"],["76357","0","0"]],"bids":[["76339.8","0.54861355","13"],["76335.8","0.01387408","1"],["76329.7","0.12717648","1"],["76329.6","0.00654722","1"],["76328.2","0","0"],["76324.9","0.47151308","1"],["76323.5","0.3273984","1"],["76321.9","0.00656259","2"],["76320.9","0","0"],["76318.3","0.00001034","1"],["76193.7","0","0"]]}
{"instId":"BTC-USDT","action":"update","ts":"1776816053420","asks":[["76346.2","0","0"],["76349.7","0.18332432","2"],["76356.6","0","0"],["76357.4","0.00654758","1"],["76460","0.03539391","5"]],"bids":[["76339.8","0.57240355","14"],["76335.8","0.11387408","2"],["76329.9","0.1098441","1"],["76325","0.34358539","1"],["76324.8","0","0"]]}
{"instId":"BTC-USDT","action":"update","ts":"1776816053430","asks":[["76339.9","0.37670064","7"],["76349.6","0","0"],["76352.1","0.00654714","1"],["76354.8","0.37386149","2"],["76354.9","0","0"],["76357.4","0.32738032","1"],["76358.5","0.00654758","1"],["76365.4","0.17249886","1"]],"bids":[["76339.8","0.5750224","15"],["76335.9","0.0516007","1"],["76334.5","0.1","1"],["76330.9","0.00654714","1"],["76330.8","0.0262","1"],["76329.6","0","0"],["76325","0.67096571","2"],["76323.6","0.00655792","2"],["76323.5","0","0"],["76321.9","0.00001501","1"]]}
{"instId":"BTC-USDT","action":"update","ts":"1776816053440","asks":[["76354.8","0.27613307","2"],["76355.8","0","0"],["76460.1","0.0022005","4"]],"bids":[["76335.9","0.1516007","2"],["76332.8","0.12619896","1"],["76332.6","0","0"],["76332.2","0.03","2"],["76325","0.32738032","1"]]}
{"instId":"BTC-USDT","action":"update","ts":"1776816053450","asks":[["76351.4","0.00001316","1"],["76357.3","0.28763969","1"],["76357.5","0","0"],["76460.1","0","0"]],"bids":[["76336","0.1060455","1"],["76335.9","0.1","1"],["76240.7","0.00001316","1"],["76194.3","0","0"],["76193.9","0","0"]]}
{"instId":"BTC-USDT","action":"update","ts":"1776816053460","asks":[["76339.9","0.35233064","6"],["76365.2","0.53902181","1"],["76365.4","0","0"]],"bids":[["76336","0.2060455","2"],["76332.3","0","0"],["76325.1","0.34553445","1"]]}
{"instId":"BTC-USDT","action":"update","ts":"1776816053470","asks":[],"bids":[["76332.8","0.06649896","1"],["76329.5","0.00001501","1"],["76307.3","0.12236864","1"],["76285","0","0"]]}
{"instId":"BTC-USDT","action":"update","ts":"1776816053480","asks":[],"bids":[["76329.8","0.07122619","1"]]}
{"instId":"BTC-USDT","action":"update","ts":"1776816053500","asks":[["76342.1","0","0"],["76460.1","0.0022005","4"]],"bids":[["76337.7","0.00001298","1"],["76195.1","0","0"]]}
{"instId":"BTC-USDT","action":"update","ts":"1776816053510","asks":[["76433.6","0.69937809","1"],["76460.1","0","0"]],"bids":[["76256.6","0.00054218","1"]]}
{"instId":"BTC-USDT","action":"update","ts":"1776816053540","asks":[["76339.9","0.25706064","5"],["76358.5","0","0"],["76358.9","0.00654764","1"],["76393.1","0","0"],["76460.1","0.0022005","4"]],"bids":[["76323.6","0.00001034","1"],["76323.5","0.00654764","1"],["76195.4","0","0"]]}
{"instId":"BTC-USDT","action":"update","ts":"1776816053550","asks":[["76392.5","0.20471405","1"],["76395.7","1.92203586","1"],["76460.1","0","0"]],"bids":[["76332.3","0.00654697","1"],["76330.9","0","0"]]}
{"instId":"BTC-USDT","action":"update","ts":"1776816053560","asks":[["76395.3","1.1087941","2"]],"bids":[["76332.3","0","0"],["76330.9","0.0065469","1"]]}
{"instId":"BTC-USDT","action":"update","ts":"1776816053570","asks":[],"bids":[["76332.3","0.00654689","1"],["76330.9","0","0"]]}
{"instId":"BTC-USDT","action":"update","ts":"1776816053600","asks":[["76358.7","1.00602765","1"],["76460","0","0"]],"bids":[]}
{"instId":"BTC-USDT","action":"update","ts":"1776816053610","asks":[["76357.3","0.55116479","2"]],"bids":[["76332.3","0","0"],["76330.9","0.00654683","1"],["76314.8","0","0"],["76303.3","0.71428105","4"],["76195.4","0.00098504","2"]]}
{"instId":"BTC-USDT","action":"update","ts":"1776816053640","asks":[],"bids":[["76295.2","0.08509366","2"],["76287.5","0","0"],["76195.1","0.01457366","1"]]}
{"instId":"BTC-USDT","action":"update","ts":"1776816053650","asks":[["76369.2","0.01593049","1"],["76459.9","0","0"]],"bids":[["76320.9","0.01601477","1"],["76292.1","0","0"]]}
{"instId":"BTC-USDT","action":"update","ts":"1776816053720","asks":[["76402.7","0.02331962","1"]],"bids":[]}
{"instId":"BTC-USDT","action":"update","ts":"1776816053730","asks":[],"bids":[["76332.3","0.00654674","1"],["76330.9","0","0"]]}
{"instId":"BTC-USDT","action":"update","ts":"1776816053740","asks":[],"bids":[["76332.3","0","0"],["76330.9","0.00654672","1"]]}
{"instId":"BTC-USDT","action":"update","ts":"1776816053750","asks":[["76358.9","0","0"],["76359.9","0.00654772","1"],["76393.1","1.92203586","1"],["76395.7","0","0"]],"bids":[["76325","0.33392804","2"],["76323.5","0","0"],["76194.3","0.0018792","9"]]}
{"instId":"BTC-USDT","action":"update","ts":"1776816053760","asks":[["76395.3","0.62388191","1"]],"bids":[["76325","0.32738032","1"],["76324.4","0.00654773","1"],["76194.3","0","0"]]}
{"instId":"BTC-USDT","action":"update","ts":"1776816053790","asks":[["76339.9","0.15206064","4"],["76349.5","0.03274025","1"],["76353.4","0.04911037","1"],["76357.4","0","0"],["76358.5","0.32738794","1"],["76459.7","0","0"],["76459.8","0","0"]],"bids":[["76325.2","0.32738794","1"],["76325","0","0"],["76321.9","0.08379798","2"],["76211.3","0","0"],["76194.3","0.0018792","9"]]}
{"instId":"BTC-USDT","action":"update","ts":"1776816053800","asks":[["76339.9","0.14944166","3"],["76349.5","0","0"],["76352.1","0","0"],["76353.3","0.00654661","1"],["76353.4","0","0"],["76459.7","0.0000534","1"],["76459.8","0.00203787","4"]],"bids":[["76332.9","0.00654661","1"],["76330.9","0","0"],["76325.1","0.24781146","1"]]}
{"instId":"BTC-USDT","action":"update","ts":"1776816053810","asks":[["76353.3","0","0"],["76354.3","0.00654661","1"],["76359.9","0","0"],["76361.3","0.00654773","1"]],"bids":[["76325.3","0.00654773","1"],["76324.4","0","0"]]}
{"instId":"BTC-USDT","action":"update","ts":"1776816053820","asks":[["76339.9","0.14574005","2"]],"bids":[["76316.6","0.11704826","1"],["76194.3","0","0"]]}
{"instId":"BTC-USDT","action":"update","ts":"1776816053830","asks":[["76393.1","0","0"],["76459.9","0.0000212","1"]],"bids":[["76334.7","0.10838955","2"],["76290.9","0","0"],["76289.7","0.11210951","2"],["76194.3","0.0018792","9"]]}
{"instId":"BTC-USDT","action":"update","ts":"1776816053840","asks":[["76358.5","0","0"],["76358.6","0.40605822","2"],["76395.7","1.92203594","1"]],"bids":[["76327.9","0.32738822","1"],["76325.2","0","0"],["76292.1","0.03288519","2"],["76194.3","0","0"]]}
{"instId":"BTC-USDT","action":"update","ts":"1776816053850","asks":[["76355.2","0.05303473","1"],["76405","0.01895548","1"],["76459.9","0","0"]],"bids":[["76329.8","0.15984545","2"],["76328","0.47153657","3"],["76309.2","0.05336316","2"]]}
{"instId":"BTC-USDT","action":"update","ts":"1776816053860","asks":[],"bids":[["76329.8","0.2892623","1"]]}
{"instId":"BTC-USDT","action":"update","ts":"1776816053870","asks":[["76370.5","0.21213892","3"],["76402.7","0.02335943","2"],["76459.8","0","0"]],"bids":[["76324.5","0.20852483","3"],["76195.1","0","0"]]}
{"instId":"BTC-USDT","action":"update","ts":"1776816053880","asks":[["76358.6","0.07867","1"],["76361.3","0.333936","2"]],"bids":[["76328.1","0.32738827","1"],["76327.9","0","0"]]}
{"instId":"BTC-USDT","action":"update","ts":"1776816053890","asks":[["76356.7","0","0"],["76369.2","0","0"],["76459.8","0.00203787","4"],["76459.9","0.0000212","1"]],"bids":[["76320.9","0","0"],["76195.1","0.01457366","1"]]}
{"instId":"BTC-USDT","action":"update","ts":"1776816053900","asks":[["76354.8","0.20440807","2"],["76358.6","0.40605837","2"],["76361.2","0.00654774","1"],["76361.3","0","0"]],"bids":[["76328.1","0","0"],["76327.9","0.32738837","1"],["76325.4","0.00654774","1"],["76325.3","0","0"]]}
{"instId":"BTC-USDT","action":"update","ts":"1776816053910","asks":[["76339.9","0.14575005","3"],["76352.1","0.0065465","1"],["76354.3","0","0"],["76358.5","0.32738836","1"],["76358.6","0.07867","1"],["76359.9","0.00654774","1"],["76361.2","0","0"],["76370.5","0.10606946","2"],["76459.9","0","0"]],"bids":[["76332.9","0","0"],["76332.3","0.0065465","1"],["76327.9","0","0"],["76325.4","0","0"],["76325.2","0.3339361","2"],["76324.5","0.10245537","2"],["76205.6","0.02050468","1"]]}
{"instId":"BTC-USDT","action":"update","ts":"1776816053920","asks":[["76352.1","0","0"],["76354.3","0.00654651","1"],["76358.7","0","0"],["76359.9","0","0"],["76361.3","0.00654774","1"],["76365.5","0.104085","2"],["76459.9","0.0000212","1"]],"bids":[["76332.9","0.00654651","1"],["76332.3","0","0"],["76329.8","0.21197284","1"],["76325.3","0.00654774","1"],["76325.2","0.32738836","1"],["76195.1","0","0"]]}
{"instId":"BTC-USDT","action":"update","ts":"1776816053930","asks":[["76357.3","0.28763969","1"],["76358.5","1.33341601","2"]],"bids":[["76325.3","0.38071306","2"],["76325.1","0","0"],["76195.1","0.01457366","1"]]}
{"instId":"BTC-USDT","action":"update","ts":"1776816053940","asks":[["76357.3","0.54921272","2"]],"bids":[["76264.2","0.01192351","3"]]}
{"instId":"BTC-USDT","action":"update","ts":"1776816053950","asks":[["76355.2","0.15910419","2"]],"bids":[["76309.2","0.15943262","3"]]}
{"instId":"BTC-USDT","action":"update","ts":"1776816054010","asks":[["76358.4","0.32737996","1"],["76358.5","1.00602765","1"],["76459.9","0","0"]],"bids":[["76325.4","0.33392753","2"],["76325.3","0.37416532","1"],["76325.2","0","0"]]}
{"instId":"BTC-USDT","action":"update","ts":"1776816054020","asks":[["76358.4","0","0"],["76358.5","1.33340744","2"],["76459.9","0.0000212","1"]],"bids":[["76325.3","0.27643989","1"]]}
{"instId":"BTC-USDT","action":"update","ts":"1776816054030","asks":[["76358.5","1.00602765","1"],["76358.7","0.3273797","1"],["76459.9","0","0"]],"bids":[["76327.9","0.3273797","1"],["76325.4","0.00654757","1"],["76289.8","0.02945075","3"],["76289.7","0.10885685","1"],["76219.3","0.00068651","2"],["76195.1","0","0"]]}
{"instId":"BTC-USDT","action":"update","ts":"1776816054040","asks":[["76355.2","0.05303473","1"]],"bids":[]}
{"instId":"BTC-USDT","action":"update","ts":"1776816054050","asks":[["76370.5","0.21213892","3"]],"bids":[["76309.2","0.05336316","2"]]}
{"instId":"BTC-USDT","action":"update","ts":"1776816054060","asks":[["76393.1","1.92203594","1"],["76395.7","0","0"]],"bids":[]}
{"instId":"BTC-USDT","action":"update","ts":"1776816054070","asks":[],"bids":[["76324.5","0.20852483","3"]]}
{"instId":"BTC-USDT","action":"update","ts":"1776816054080","asks":[["76358.5","1.33340699","2"],["76358.7","0","0"],["76370.5","0.10606946","2"],["76459.9","0.0000212","1"]],"bids":[["76339.8","0.60776264","16"],["76327.9","0.32737934","1"],["76324.5","0.10245537","2"],["76205.6","0","0"],["76195.1","0.01457366","1"]]}
{"instId":"BTC-USDT","action":"update","ts":"1776816054090","asks":[["76358.5","1.00602765","1"],["76358.7","0.32737928","1"],["76459.9","0","0"]],"bids":[["76335.9","0.14911036","2"],["76328","0.79891585","4"],["76327.9","0","0"],["76194.3","0.0018792","9"]]}
{"instId":"BTC-USDT","action":"update","ts":"1776816054110","asks":[["76358.7","0","0"],["76361.3","0.33392694","2"],["76459.9","0.0000212","1"]],"bids":[["76328.1","0.3273792","1"],["76328","0.47153657","3"],["76194.3","0","0"]]}
{"instId":"BTC-USDT","action":"update","ts":"1776816054120","asks":[["76358.7","0.32737915","1"],["76361.3","0.00654774","1"],["76459.9","0","0"]],"bids":[]}
{"instId":"BTC-USDT","action":"update","ts":"1776816054140","asks":[["76355.2","0.15910419","2"]],"bids":[]}
{"instId":"BTC-USDT","action":"update","ts":"1776816054150","asks":[],"bids":[["76309.2","0.15943262","3"]]}
{"instId":"BTC-USDT","action":"update","ts":"1776816054180","asks":[],"bids":[["76324.5","0.0507788","1"]]}
{"instId":"BTC-USDT","action":"update","ts":"1776816054190","asks":[["76358.7","0.32737956","1"]],"bids":[["76309.2","0.21110919","4"]]}
{"instId":"BTC-USDT","action":"update","ts":"1776816054210","asks":[],"bids":[["76309.2","0.15943262","3"]]}
{"instId":"BTC-USDT","action":"update","ts":"1776816054220","asks":[],"bids":[["76309.2","0.21110919","4"]]}
{"instId":"BTC-USDT","action":"update","ts":"1776816054230","asks":[],"bids":[["76309.2","0.15943262","3"]]}
{"instId":"BTC-USDT","action":"update","ts":"1776816054240","asks":[["76358.7","0","0"],["76361.3","0.33392729","2"],["76459.9","0.0000212","1"]],"bids":[]}
{"instId":"BTC-USDT","action":"update","ts":"1776816054260","asks":[["76358.7","0.32737947","1"],["76361.3","0.00654774","1"],["76459.9","0","0"]],"bids":[["76328.1","0.32737947","1"]]}
{"instId":"BTC-USDT","action":"update","ts":"1776816054270","asks":[],"bids":[["76309.2","0.21110919","4"]]}
{"instId":"BTC-USDT","action":"update","ts":"1776816054280","asks":[["76358.7","0","0"],["76361.3","0.33392727","2"],["76459.9","0.0000212","1"]],"bids":[]}
{"instId":"BTC-USDT","action":"update","ts":"1776816054370","asks":[["76349.6","0.16","1"],["76459.9","0","0"]],"bids":[["76332.7","0","0"],["76194.3","0.0018792","9"]]}
{"instId":"BTC-USDT","action":"update","ts":"1776816054380","asks":[["76349.5","0.04776","1"],["76459.8","0","0"]],"bids":[["76332.8","0.01678464","1"]]}
{"instId":"BTC-USDT","action":"update","ts":"1776816054430","asks":[["76361.2","0.00654755","1"],["76361.3","0.32737953","1"],["76459.7","0","0"]],"bids":[["76326.7","0.00654755","1"],["76325.4","0","0"]]}
{"instId":"BTC-USDT","action":"update","ts":"1776816054460","asks":[],"bids":[["76326.7","0","0"],["76325.4","0.00654755","1"]]}
{"instId":"BTC-USDT","action":"update","ts":"1776816054610","asks":[["76355.2","0.10606946","1"]],"bids":[["76309.2","0.15943262","3"]]}
{"instId":"BTC-USDT","action":"update","ts":"1776816054620","asks":[["76393.1","0","0"],["76395.7","1.92203594","1"]],"bids":[]}
{"instId":"BTC-USDT","action":"update","ts":"1776816054630","asks":[["76370.5","0.15910419","3"]],"bids":[["76324.5","0.10245537","2"]]}
{"instId":"BTC-USDT","action":"update","ts":"1776816054660","asks":[],"bids":[["76303.3","0.71425241","3"]]}
{"instId":"BTC-USDT","action":"update","ts":"1776816054670","asks":[["76358.7","0.32738167","1"],["76361.3","0","0"]],"bids":[["76328.1","0","0"],["76327.9","0.32738167","1"]]}
{"instId":"BTC-USDT","action":"update","ts":"1776816054690","asks":[["76370.5","0.10606946","2"]],"bids":[]}
{"instId":"BTC-USDT","action":"update","ts":"1776816054720","asks":[["76355.2","0.15910419","2"]],"bids":[]}
{"instId":"BTC-USDT","action":"update","ts":"1776816054730","asks":[["76370.5","0.05303473","1"]],"bids":[["76324.5","0.0507788","1"]]}
{"instId":"BTC-USDT","action":"update","ts":"1776816054740","asks":[["76355.2","0.21213892","3"]],"bids":[["76309.2","0.21110919","4"]]}
{"instId":"BTC-USDT","action":"update","ts":"1776816054750","asks":[],"bids":[["76324.5","0","0"],["76193.9","0.01496","1"]]}
{"instId":"BTC-USDT","action":"update","ts":"1776816054760","asks":[["76450.8","0","0"],["76459.7","0.0000534","1"]],"bids":[["76309.2","0.26188799","5"]]}
{"instId":"BTC-USDT","action":"update","ts":"1776816054770","asks":[["76358.7","0","0"],["76361.3","0.32738232","1"],["76393.1","1.92203594","1"],["76395.7","0","0"]],"bids":[["76328.1","0.32738232","1"],["76327.9","0","0"]]}
{"instId":"BTC-USDT","action":"update","ts":"1776816054780","asks":[["76355.2","0.15910419","2"]],"bids":[["76309.2","0.15943262","3"]]}
{"instId":"BTC-USDT","action":"update","ts":"1776816054790","asks":[["76402.7","0.02331962","1"]],"bids":[["76303.3","0.71428105","4"]]}
{"instId":"BTC-USDT","action":"update","ts":"1776816054830","asks":[["76355.2","0.21213892","3"]],"bids":[["76309.2","0.21110919","4"]]}
{"instId":"BTC-USDT","action":"update","ts":"1776816054840","asks":[],"bids":[["76309.2","0.26188799","5"]]}
{"instId":"BTC-USDT","action":"update","ts":"1776816054850","asks":[["76405","0","0"],["76459.8","0.00203787","4"]],"bids":[]}
{"instId":"BTC-USDT","action":"update","ts":"1776816054890","asks":[["76369.4","0.01574114","2"]],"bids":[["76326.5","0.01585951","1"],["76221.3","0.00041462","1"],["76193.9","0","0"]]}
{"instId":"BTC-USDT","action":"update","ts":"1776816054900","asks":[],"bids":[["76326.6","0.00678504","6"],["76325.4","0","0"],["76193.9","0.01496","1"]]}
{"instId":"BTC-USDT","action":"update","ts":"1776816054910","asks":[["76458.3","0.00035006","7"]],"bids":[["76326.6","0.00023743","5"],["76325.5","0.00654761","1"],["76193.9","0","0"]]}
{"instId":"BTC-USDT","action":"update","ts":"1776816054920","asks":[["76402.7","0.02335943","2"]],"bids":[]}
{"instId":"BTC-USDT","action":"update","ts":"1776816054970","asks":[["76444.3","0.02050395","1"],["76459.8","0","0"]],"bids":[]}
{"instId":"BTC-USDT","action":"update","ts":"1776816055020","asks":[["76370.5","0","0"],["76459.8","0.00203787","4"]],"bids":[]}
{"instId":"BTC-USDT","action":"update","ts":"1776816055040","asks":[["76355.2","0.26517365","4"]],"bids":[]}
{"instId":"BTC-USDT","action":"update","ts":"1776816055140","asks":[["76444.3","0","0"],["76459.9","0.0000212","1"]],"bids":[["76222.6","0.00514585","1"],["76194.3","0","0"]]}
{"instId":"BTC-USDT","action":"update","ts":"1776816055220","asks":[],"bids":[["76292.1","0","0"],["76194.3","0.0018792","9"]]}
{"instId":"BTC-USDT","action":"update","ts":"1776816055270","asks":[["76339.9","0.00001","1"],["76349.6","0","0"],["76352.2","0","0"],["76355.2","0.15910419","3"],["76355.7","0.03","2"],["76358.4","0.47151308","1"],["76358.5","0","0"],["76358.8","0","0"],["76361.8","0","0"],["76361.9","0","0"],["76364.9","0.47152624","2"],["76365.3","0","0"],["76365.6","0.00133225","1"],["76368.7","0","0"],["76371.2","1.00602765","1"],["76377.1","0","0"],["76389.1","0","0"],["76397.3","0.02284338","1"],["76460","0.03539391","5"],["76460.1","0.0022005","4"],["76460.2","0.00162671","12"],["76460.6","0.00002799","2"],["76460.7","0.00167279","1"],["76460.9","0.00030148","3"],["76461.1","0.00003024","1"]],"bids":[["76332.1","0.1305","1"],["76309.2","0.15581853","4"],["76298.2","0.02284338","1"],["76289.8","0.00326295","2"],["76195.1","0","0"],["76194.3","0","0"]]}
{"instId":"BTC-USDT","action":"update","ts":"1776816055280","asks":[["76339.9","0","0"],["76343.6","0","0"],["76349.5","0","0"],["76349.7","0","0"],["76352.2","0.01309772","1"],["76354.3","0","0"],["76354.8","0.09532315","2"],["76355.2","0","0"],["76357.2","0.00654664","1"],["76357.3","0","0"],["76358.9","0.10606946","1"],["76361.2","0","0"],["76361.3","0","0"],["76362.6","0","0"],["76363.3","0.32738198","1"],["76363.4","0","0"],["76364.8","0.00654768","1"],["76365.2","0","0"],["76368.2","0.00001316","1"],["76369.4","0.00006929","1"],["76372.3","0.08378297","1"],["76372.4","0","0"],["76377","0.08378297","1"],["76393.1","0","0"],["76400.6","0.1190802","1"],["76400.9","1.92203594","1"],["76445.3","0.00038686","6"],["76461.3","0.00027039","1"],["76461.4","0.0312605","1"],["76461.5","0.01228943","9"],["76461.6","0.00332668","1"],["76461.7","0.00001025","1"],["76462","0.00002228","1"]],"bids":[["76343.6","0.97805369","16"],["76343.5","0.49088111","7"],["76343.4","0.01075402","1"],["76339.8","0.13585661","5"],["76336.1","0.00654664","1"],["76335.8","0.1","1"],["76332.9","0","0"],["76332.8","0.05359301","2"],["76332.3","0.47151308","1"],["76332.2","0.35738198","3"],["76330.8","0.01614584","1"],["76330","0.08378297","1"],["76329.7","0","0"],["76328.6","0.00655923","2"],["76328.2","1.00602765","1"],["76328.1","0","0"],["76325.5","0","0"],["76322","0.11970265","1"],["76316.3","0","0"],["76312.9","0.10606946","1"],["76309.2","0.00032843","1"],["76306.9","0","0"],["76306","0","0"],["76303.4","0.11704244","1"],["76297.8","0.00005945","2"],["76296.7","0.12409802","2"],["76296.5","0.10886126","1"],["76296.4","0","0"],["76289.7","0","0"],["76243.9","0.00001316","1"],["76240.2","0.08378297","1"],["76237.4","0","0"],["76231","0","0"],["76221","0","0"],["76195.4","0","0"]]}
{"instId":"BTC-USDT","action":"update","ts":"1776816055290","asks":[["76354.8","0.04978472","2"],["76357.2","0","0"],["76357.7","0.00654628","1"],["76358.9","0.26517365","4"],["76363.3","0","0"],["76364.8","0.32736897","1"],["76365.4","0.00654708","1"],["76370.1","0.05896264","1"],["76461.5","0.14278943","10"],["76462","0","0"]],"bids":[["76343.6","1.05030922","20"],["76343.5","0.37054411","6"],["76341.4","0.00094028","1"],["76339.8","0.13277307","3"],["76336.1","0.10654628","2"],["76334.5","0","0"],["76334.4","0.0000168","1"],["76332.8","0.28435614","1"],["76332.4","0.32736897","1"],["76332.2","0.03","2"],["76330.8","0.0187649","2"],["76330.5","0.00654708","1"],["76328.6","0.00001155","1"],["76327.5","0","0"],["76323.6","0.05897298","2"],["76316.5","0.00001086","1"],["76313.1","0.05244229","2"],["76312.9","0.26155956","4"],["76311.6","1.54784252","3"],["76303.3","0.66188378","3"],["76292.1","0.03371018","2"],["76198.2","0","0"],["76196.5","0","0"]]}
{"instId":"BTC-USDT","action":"update","ts":"1776816055300","asks":[["76357.7","0","0"],["76358.3","0.25020269","2"],["76365.4","0","0"],["76365.5","0.092085","1"],["76365.7","0.00654709","1"],["76386.9","0.20834731","1"],["76392.4","0","0"],["76395.2","0.11970249","1"],["76395.5","0.00130897","1"],["76400.5","0.11704244","1"],["76400.6","0","0"],["76400.9","0","0"],["76403.5","1.92203594","1"],["76461.7","0","0"]],"bids":[["76343.6","1.15030922","21"],["76339.8","0.28039752","4"],["76336.2","0.00654621","1"],["76336.1","0.1","1"],["76335.8","0","0"],["76330.9","0.00654709","1"],["76330.5","0","0"],["76329.8","0.44642779","2"],["76301.3","0.00131059","1"],["76290.5","0","0"]]}
{"instId":"BTC-USDT","action":"update","ts":"1776816055310","asks":[["76358.9","0.15910419","3"],["76361.3","0.13783155","1"],["76364.8","0.5775251","2"],["76365.7","0","0"],["76366.7","0.0065471","1"],["76384.1","0.00011763","1"],["76389.4","0.14285134","1"],["76400.5","0","0"],["76402.7","0.14040187","3"],["76403.5","0","0"],["76408.7","1.92203594","1"],["76461.6","0","0"]],"bids":[["76343.5","0.52097998","8"],["76337.6","0","0"],["76336.2","0.14311495","2"],["76336","0.1","1"],["76335.9","0.04911036","1"],["76331","0.0065471","1"],["76330.9","0","0"],["76328.8","0.00305","1"],["76326.6","0.00328743","6"],["76323.3","0","0"],["76316.1","0","0"],["76198.2","0.04493904","1"],["76196.5","0.00034725","1"]]}
{"instId":"BTC-USDT","action":"update","ts":"1776816055320","asks":[["76349.8","0","0"],["76358.3","0.24365648","1"],["76361.2","0.00654623","1"],["76364.7","1.00602765","1"],["76380.3","0","0"],["76390.1","0","0"],["76397.9","0.00130893","1"],["76402.6","0.11704244","1"],["76402.7","0.02335943","2"],["76461.5","0","0"]],"bids":[["76343.4","0.11075402","2"],["76339.9","0.00654623","1"],["76336.2","0.13656874","1"],["76336","0","0"],["76332.2","0.03654707","3"],["76331","0","0"],["76316.7","0.07637348","1"],["76303.9","0","0"],["76195.4","0.00098504","2"]]}
{"instId":"BTC-USDT","action":"update","ts":"1776816055330","asks":[["76361.3","0.42050931","2"],["76385.2","0.06494722","1"],["76396.9","0","0"]],"bids":[["76339.9","0.10654623","2"],["76336.2","0.07686874","1"],["76336.1","0","0"],["76308.8","0.06529868","1"],["76290.9","0.00233628","1"],["76286.5","0","0"]]}
{"instId":"BTC-USDT","action":"update","ts":"1776816055340","asks":[["76354.7","0.47151308","1"],["76373.3","0.01625393","1"],["76461.3","0","0"],["76461.4","0","0"]],"bids":[["76343.5","0.5761859","7"],["76339.9","0.1","1"],["76336.3","0.00654609","1"],["76336.2","0","0"],["76332.2","0.03","2"],["76330.9","0.00654709","1"],["76326.5","0","0"],["76312.9","0.1554901","3"],["76292.8","0.00325245","1"],["76289.8","0.00001033","1"],["76195.4","0","0"]]}
{"instId":"BTC-USDT","action":"update","ts":"1776816055350","asks":[["76354.6","0.18856404","1"],["76354.8","0.00001316","1"],["76461.1","0","0"]],"bids":[["76339.8","0.13277307","3"],["76336.9","0.0131","1"],["76336.4","0.00654612","1"],["76336.3","0","0"],["76336","0.04701874","1"],["76328.5","0","0"],["76319.2","0.30279","1"],["76311","0","0"],["76196.5","0","0"]]}
{"instId":"BTC-USDT","action":"update","ts":"1776816055360","asks":[["76354.3","0.16","1"],["76358.9","0.26517365","4"],["76460.9","0","0"]],"bids":[["76343.5","0.54078087","7"],["76312.9","0.26155956","4"]]}
{"instId":"BTC-USDT","action":"update","ts":"1776816055380","asks":[["76408.7","0","0"],["76411.3","2.39354902","2"],["76460.9","0.00030148","3"]],"bids":[["76334.7","0.13458955","3"]]}
{"instId":"BTC-USDT","action":"update","ts":"1776816055390","asks":[["76358.8","0.00654623","1"],["76361.2","0","0"],["76368.6","0.32174137","2"],["76402.7","0.02331962","1"],["76406.8","0.00003981","1"],["76460.9","0","0"]],"bids":[["76337","0.00654623","1"],["76336.4","0","0"],["76280.9","0.00325031","2"],["76277.2","0","0"],["76196.5","0.00034725","1"]]}
{"instId":"BTC-USDT","action":"update","ts":"1776816055400","asks":[["76365.5","0","0"],["76396.8","0","0"],["76411.2","0.70829273","2"],["76419","0","0"],["76460.9","0.00030148","3"],["76461.1","0.00003024","1"],["76461.3","0.00027039","1"]],"bids":[["76337.7","0","0"],["76195.4","0.00098504","2"]]}
{"instId":"BTC-USDT","action":"update","ts":"1776816055410","asks":[["76437.4","0.37094139","2"]],"bids":[["76341.5","0.00002798","1"],["76269.7","0.00013111","1"],["76265.1","0","0"],["76261.1","0.00055719","2"],["76256.6","0","0"]]}
{"instId":"BTC-USDT","action":"update","ts":"1776816055420","asks":[["76352.2","0","0"],["76400.7","0.59465192","2"],["76400.9","1.92203594","1"],["76405.1","0.345737","1"],["76411.3","0.47151308","1"],["76461.3","0","0"]],"bids":[["76231.4","0.000655","1"],["76195.4","0","0"]]}
{"instId":"BTC-USDT","action":"update","ts":"1776816055430","asks":[["76349.9","0.01309812","1"],["76379.9","0.01","1"],["76411.2","0.13771388","1"],["76460.9","0","0"],["76461.1","0","0"]],"bids":[]}
{"instId":"BTC-USDT","action":"update","ts":"1776816055440","asks":[],"bids":[["76304.2","0.00131054","1"],["76295.2","0.08378297","1"],["76196.5","0","0"]]}
{"instId":"BTC-USDT","action":"update","ts":"1776816055450","asks":[["76406.8","0","0"],["76460.9","0.00030148","3"]],"bids":[]}
{"instId":"BTC-USDT","action":"update","ts":"1776816055460","asks":[],"bids":[["76309.2","0","0"],["76278.5","0.47151308","1"],["76196.5","0.00034725","1"]]}
{"instId":"BTC-USDT","action":"update","ts":"1776816055490","asks":[["76343.7","0.03242043","2"]],"bids":[["76341.5","0.00006202","2"]]}
{"instId":"BTC-USDT","action":"update","ts":"1776816055500","asks":[["76343.7","0.00262043","1"],["76361.8","0.092082","1"],["76392.8","0.42951997","2"],["76393.1","1.92203594","1"],["76400.9","0","0"],["76460.9","0","0"]],"bids":[["76304.8","0.00002864","1"],["76303.3","0.66185514","2"],["76196.5","0","0"]]}
{"instId":"BTC-USDT","action":"update","ts":"1776816055510","asks":[],"bids":[["76306.9","0.00002864","1"],["76304.8","0","0"]]}
{"instId":"BTC-USDT","action":"update","ts":"1776816055520","asks":[["76406.8","0.00003981","1"],["76460.7","0","0"]],"bids":[]}
{"instId":"BTC-USDT","action":"update","ts":"1776816055540","asks":[["76343.7","0.03242043","2"]],"bids":[]}
{"instId":"BTC-USDT","action":"update","ts":"1776816055550","asks":[["76343.7","0.00262043","1"],["76358.9","0.15910419","3"],["76393.1","0","0"],["76395.7","1.92203594","1"]],"bids":[]}
{"instId":"BTC-USDT","action":"update","ts":"1776816055560","asks":[["76358.9","0.26517365","4"]],"bids":[["76339.9","0.10003326","2"],["76339.8","0.13274024","2"]]}
{"instId":"BTC-USDT","action":"update","ts":"1776816055620","asks":[],"bids":[["76309.3","0.00041232","2"]]}
{"instId":"BTC-USDT","action":"update","ts":"1776816055700","asks":[["76358.9","0.15910419","3"]],"bids":[["76312.9","0.1554901","3"]]}
{"instId":"BTC-USDT","action":"update","ts":"1776816055710","asks":[],"bids":[["76312.9","0.26155956","4"]]}
{"instId":"BTC-USDT","action":"update","ts":"1776816055740","asks":[],"bids":[["76327.9","0.01615056","1"],["76198.2","0","0"]]}
{"instId":"BTC-USDT","action":"update","ts":"1776816055780","asks":[],"bids":[["76327.9","0","0"],["76198.2","0.04493904","1"]]}
{"instId":"BTC-USDT","action":"update","ts":"1776816055790","asks":[["76358.9","0.26517365","4"]],"bids":[]}
{"instId":"BTC-USDT","action":"update","ts":"1776816055820","asks":[["76407.6","0.01899737","1"],["76460.6","0","0"]],"bids":[]}
{"instId":"BTC-USDT","action":"update","ts":"1776816055890","asks":[["76343.7","0.03242043","2"],["76393.1","1.92203594","1"],["76395.7","0","0"]],"bids":[["76343.6","1.08756771","18"]]}
{"instId":"BTC-USDT","action":"update","ts":"1776816055900","asks":[["76343.7","0.12889043","4"],["76354.2","0.13207751","1"],["76357.7","0.0065464","1"],["76358.8","0","0"],["76365.5","0.00654715","1"],["76366.7","0","0"],["76460.2","0","0"]],"bids":[["76343.5","0.42555878","6"],["76343.4","0.1","1"]]}
{"instId":"BTC-USDT","action":"update","ts":"1776816055910","asks":[["76343.7","0.12949043","5"],["76364.6","0.08378297","1"],["76460.1","0","0"]],"bids":[["76340.8","0.01075438","1"],["76330","0","0"]]}
{"instId":"BTC-USDT","action":"update","ts":"1776816055920","asks":[["76364.9","0.47807354","3"],["76365.5","0","0"],["76460.1","0.0022005","4"]],"bids":[["76332.3","0","0"],["76330.9","0","0"],["76330","0.0065473","1"],["76328.2","0","0"],["76326.9","0.016044","1"],["76292.1","0.01701775","1"],["76196.5","0.00034725","1"]]}
{"instId":"BTC-USDT","action":"update","ts":"1776816055930","asks":[["76364.9","0.47152624","2"],["76365.5","0.00654729","1"],["76460.1","0","0"]],"bids":[["76332.8","0.15123915","1"],["76330.5","0.00654729","1"],["76330","0","0"],["76329.8","0.21197284","1"],["76292.1","0","0"],["76195.4","0.00098504","2"]]}
{"instId":"BTC-USDT","action":"update","ts":"1776816055940","asks":[["76364.5","0.33391359","2"],["76364.8","0.25015613","1"],["76365.5","0","0"]],"bids":[["76343.5","0.29845853","4"],["76332.4","0","0"],["76330.5","0","0"],["76330","0.32736629","1"],["76328.9","0.00655764","2"],["76195.1","0.01457366","1"]]}
{"instId":"BTC-USDT","action":"update","ts":"1776816055950","asks":[["76343.7","0.28706909","6"]],"bids":[["76342.1","0.05896264","1"],["76332.8","0.05351952","1"],["76323.6","0.00001034","1"],["76289.7","0.10831921","1"],["76195.4","0","0"],["76195.1","0","0"]]}
{"instId":"BTC-USDT","action":"update","ts":"1776816055960","asks":[["76347.5","0.01309854","1"],["76349.9","0","0"]],"bids":[["76343.5","0.29845852","3"],["76340.8","0","0"],["76337.6","0.01075484","1"]]}
{"instId":"BTC-USDT","action":"update","ts":"1776816055970","asks":[],"bids":[["76326.9","0","0"],["76195.4","0.00098504","2"]]}
{"instId":"BTC-USDT","action":"update","ts":"1776816056010","asks":[["76364.4","0.00654726","1"],["76364.5","0.32736629","1"],["76460","0","0"]],"bids":[]}
{"instId":"BTC-USDT","action":"update","ts":"1776816056050","asks":[["76400.7","0.49465192","1"]],"bids":[["76299.1","0.08379798","2"]]}
{"instId":"BTC-USDT","action":"update","ts":"1776816056070","asks":[],"bids":[["76306.9","0","0"],["76280.9","0.0000168","1"],["76195.1","0.01457366","1"]]}
{"instId":"BTC-USDT","action":"update","ts":"1776816056090","asks":[["76343.7","0.44884914","8"],["76361.7","0.32736347","1"],["76364.5","0","0"]],"bids":[]}
{"instId":"BTC-USDT","action":"update","ts":"1776816056100","asks":[["76343.7","0.44885914","9"],["76364.4","0","0"],["76364.5","0.00654722","1"],["76379.9","0","0"],["76460","0.03539391","5"]],"bids":[["76337","0","0"],["76336.1","0.0065467","1"]]}
{"instId":"BTC-USDT","action":"update","ts":"1776816056110","asks":[],"bids":[["76292.5","0.03371018","2"],["76195.1","0","0"]]}
{"instId":"BTC-USDT","action":"update","ts":"1776816056120","asks":[],"bids":[["76280.9","0.00325038","2"]]}
{"instId":"BTC-USDT","action":"update","ts":"1776816056140","asks":[],"bids":[["76306.9","0.00002864","1"],["76195.4","0","0"]]}
{"instId":"BTC-USDT","action":"update","ts":"1776816056210","asks":[],"bids":[["76341.5","0.00095559","3"],["76341.4","0","0"],["76195.4","0.00098504","2"]]}
{"instId":"BTC-USDT","action":"update","ts":"1776816056290","asks":[],"bids":[["76338.1","0.00001316","1"],["76195.4","0","0"]]}
{"instId":"BTC-USDT","action":"update","ts":"1776816056320","asks":[],"bids":[["76323.3","0.01586994","1"],["76196.5","0","0"]]}
{"instId":"BTC-USDT","action":"update","ts":"1776816056340","asks":[["76355.6","0.00654668","1"],["76357.7","0","0"]],"bids":[]}
{"instId":"BTC-USDT","action":"update","ts":"1776816056350","asks":[["76354.1","0.16","1"],["76460","0","0"]],"bids":[["76328.9","0.00001034","1"],["76328.1","0.00654719","1"],["76198.2","0","0"]]}
{"instId":"BTC-USDT","action":"update","ts":"1776816056360","asks":[["76354","0.15960333","1"],["76355","0","0"],["76402.6","0","0"],["76460","0.03539391","5"]],"bids":[]}
{"instId":"BTC-USDT","action":"update","ts":"1776816056370","asks":[["76354","0.45140085","2"],["76354.6","0","0"],["76355.6","0","0"],["76357.7","0.00654669","1"],["76460.1","0.0022005","4"]],"bids":[]}
{"instId":"BTC-USDT","action":"update","ts":"1776816056380","asks":[],"bids":[["76328.9","0.00655753","2"],["76328.1","0","0"],["76198.2","0.04493904","1"]]}
{"instId":"BTC-USDT","action":"update","ts":"1776816056420","asks":[],"bids":[["76328.9","0.00001034","1"],["76328.1","0.00654719","1"],["76198.2","0","0"]]}
{"instId":"BTC-USDT","action":"update","ts":"1776816056430","asks":[],"bids":[["76328.9","0.00655753","2"],["76328.1","0","0"],["76198.2","0.04493904","1"]]}
{"instId":"BTC-USDT","action":"update","ts":"1776816056440","asks":[],"bids":[["76328.9","0.00001034","1"],["76328.2","0.00654719","1"],["76198.2","0","0"]]}
{"instId":"BTC-USDT","action":"update","ts":"1776816056460","asks":[["76373.3","0","0"],["76460.2","0.00162671","12"]],"bids":[["76323.5","0.01582612","1"],["76198.3","0","0"]]}
{"instId":"BTC-USDT","action":"update","ts":"1776816056470","asks":[["76376.9","0.07242156","1"],["76460.2","0","0"]],"bids":[]}
{"instId":"BTC-USDT","action":"update","ts":"1776816056480","asks":[["76402.8","1.14830219","3"]],"bids":[]}
{"instId":"BTC-USDT","action":"update","ts":"1776816056510","asks":[["76357.6","0.00654669","1"],["76357.7","0","0"],["76361.7","0","0"],["76364.5","0.33391114","2"],["76460.2","0.00162671","12"]],"bids":[]}
{"instId":"BTC-USDT","action":"update","ts":"1776816056520","asks":[["76357.6","0","0"],["76357.7","0.00654669","1"],["76431.5","0.50626317","1"],["76460.2","0","0"]],"bids":[["76336.2","0.00654669","1"],["76336.1","0","0"]]}
{"instId":"BTC-USDT","action":"update","ts":"1776816056540","asks":[["76361.7","0.32736426","1"],["76364.5","0.00654722","1"],["76460.1","0","0"]],"bids":[]}
{"instId":"BTC-USDT","action":"update","ts":"1776816056550","asks":[["76361.7","0.32736428","1"]],"bids":[["76343.6","0.98756771","17"]]}
{"instId":"BTC-USDT","action":"update","ts":"1776816056560","asks":[],"bids":[["76343.6","0.97842936","16"]]}
{"instId":"BTC-USDT","action":"update","ts":"1776816056580","asks":[["76343.7","0.49105914","11"],["76350.7","0.47151308","1"],["76355.6","0.00654672","1"],["76357.7","0.08378297","1"],["76358.2","1.00597757","1"],["76361.2","0.32736917","1"],["76361.7","0","0"],["76459.8","0","0"],["76459.9","0","0"],["76460","0","0"]],"bids":[["76343.6","0.26754365","5"],["76336.2","0","0"],["76336.1","0.00654672","1"],["76330","0","0"],["76328.1","0.32736917","1"],["76328","0.00002349","2"],["76325.4","0.47151308","1"],["76324.9","0","0"],["76322.1","1.47749065","2"],["76321.9","0.00001501","1"],["76321.8","0.00001033","1"],["76321.6","0","0"],["76315.1","1.47772809","7"],["76315","0.08378297","1"],["76311.7","0.47151308","1"],["76311.6","0.07040062","1"],["76231","0.08378297","1"],["76221","0.08378297","1"],["76200","0","0"],["76199.4","0","0"],["76199.3","0","0"]]}
{"instId":"BTC-USDT","action":"update","ts":"1776816056590","asks":[["76347.5","0","0"],["76350.6","0.14075506","1"],["76354.1","0.16654673","2"],["76355.6","0","0"],["76361.7","0.00654744","1"],["76364.5","0","0"],["76372.6","0.48713562","2"],["76459.8","0.00203787","4"]],"bids":[["76343.6","0.14112865","3"],["76343.5","0.09563","1"],["76343.4","0","0"],["76337.6","0","0"],["76336.1","0","0"],["76334.8","0.00654673","1"],["76332.1","0","0"],["76330.8","0","0"],["76329.8","0.1291563","1"],["76328.2","0","0"],["76328.1","0.32998832","2"],["76326.7","0.00654744","1"],["76325.3","0","0"],["76321.7","0.000015","1"],["76315.6","0.0837933","2"],["76315","0","0"],["76314.9","0.02051357","1"],["76200","1.01928479","52"],["76199.3","0.00040006","1"],["76198.3","0.01437429","1"],["76198.2","0.04493904","1"],["76196.5","0.00034725","1"],["76195.4","0.00098504","2"]]}
{"instId":"BTC-USDT","action":"update","ts":"1776816056600","asks":[["76344.1","0.0140678","1"],["76353.9","0.00654682","1"],["76354.1","0.16","1"],["76358.1","0.54395395","2"],["76358.3","0","0"],["76361.1","0.32738032","1"],["76361.2","0","0"],["76437.4","0.00196024","1"],["76459.8","0","0"]],"bids":[["76343.6","0.11990865","5"],["76342.2","0.0873735","1"],["76334.8","0","0"],["76332.9","0.00654682","1"],["76332.8","0","0"],["76332.6","0.01058159","1"],["76328.2","0.32738032","1"],["76328.1","0.00261915","1"],["76199.4","0.1305","1"],["76198.2","0","0"],["76196.5","0","0"],["76195.4","0","0"]]}
{"instId":"BTC-USDT","action":"update","ts":"1776816056610","asks":[["76343.7","0.49367786","12"],["76353.9","0.16083003","2"],["76354.2","0","0"],["76361","0.00654757","1"],["76361.7","0","0"],["76395.2","0","0"],["76459.8","0.00203787","4"],["76459.9","0.0000212","1"]],"bids":[["76326.7","0","0"],["76325.5","0.26095539","2"]]}
{"instId":"BTC-USDT","action":"update","ts":"1776816056620","asks":[["76358","0.32737988","1"],["76361.1","0","0"]],"bids":[["76328.2","0","0"],["76325.6","0.32737988","1"]]}
{"instId":"BTC-USDT","action":"update","ts":"1776816056630","asks":[["76343.7","0.51804786","13"],["76353.8","0.00654676","1"],["76353.9","0.15428321","1"],["76359.9","0.00654757","1"],["76361","0","0"],["76459.9","0","0"]],"bids":[["76342.2","0","0"],["76332.9","0","0"],["76332.3","0.00654676","1"],["76330","0.06305254","1"],["76329.8","0","0"],["76325.5","0.25440782","1"],["76324.4","0.00654757","1"]]}
{"instId":"BTC-USDT","action":"update","ts":"1776816056640","asks":[["76353.8","0.15816992","2"],["76354","0.29179752","1"]],"bids":[["76343.6","0.09611865","4"],["76332.7","0.01407676","1"],["76328.8","0","0"],["76322","0.12275265","2"]]}
{"instId":"BTC-USDT","action":"update","ts":"1776816056650","asks":[],"bids":[["76326.4","0.00305","1"],["76325.7","0.43002589","1"],["76325.5","0","0"],["76322","0.11970265","1"],["76292.5","0","0"]]}
{"instId":"BTC-USDT","action":"update","ts":"1776816056700","asks":[["76345.7","0.00001697","1"],["76459.8","0","0"]],"bids":[["76341.5","0.00092155","2"]]}
{"instId":"BTC-USDT","action":"update","ts":"1776816056780","asks":[["76369.9","0.01","1"],["76459.7","0","0"]],"bids":[]}
{"instId":"BTC-USDT","action":"update","ts":"1776816056910","asks":[],"bids":[["76222.6","0","0"],["76198.2","0.04493904","1"]]}
{"instId":"BTC-USDT","action":"update","ts":"1776816056920","asks":[["76348.1","0.1170556","2"]],"bids":[["76343.6","0.00261865","1"],["76343.5","0","0"],["76334.7","0.10838955","2"],["76325.4","0","0"],["76284.9","0.10841267","1"],["76196.5","0.00034725","1"]]}
{"instId":"BTC-USDT","action":"update","ts":"1776816056930","asks":[["76340","1.4277802","19"],["76341.5","0.63265871","5"],["76341.6","0.67730889","5"],["76342.2","0.62273517","3"],["76343.7","0.04124915","4"],["76344.1","0","0"],["76346.6","0.11264529","4"],["76348","0.0349411","1"],["76348.1","0.00001316","1"],["76349.9","0.00654704","1"],["76353.7","0.41116475","2"],["76353.8","0.15162316","1"],["76353.9","0","0"],["76357.9","0.11970829","1"],["76358","0","0"],["76358.8","0.00654761","1"],["76358.9","0","0"],["76359.1","0.1305","1"],["76359.9","0","0"],["76363.5","0.05896264","1"],["76370.1","0","0"],["76380.1","0","0"],["76384.1","0.11982248","2"],["76384.2","0.23962117","2"],["76388.9","0.02396779","1"],["76389.4","0","0"],["76391.3","0.05359293","1"],["76397.3","0","0"],["76445.3","0.0003737","5"],["76459.2","0","0"],["76459.3","0","0"],["76459.6","0","0"]],"bids":[["76343.6","0","0"],["76342.1","0","0"],["76341.5","0","0"],["76339.9","0.00003326","1"],["76339.8","0.03274024","1"],["76335.9","0.108073","2"],["76334.7","0.00001316","1"],["76332.6","0","0"],["76332.3","0","0"],["76328.2","0.00654704","1"],["76326.6","0.00023743","5"],["76326.4","0","0"],["76325.7","0.21333851","1"],["76325.6","0","0"],["76324.4","0","0"],["76323.6","0.00655795","2"],["76323.5","0","0"],["76323.2","0.06550532","1"],["76322.2","0.32738178","1"],["76322.1","0","0"],["76322","0","0"],["76318.9","0.00305","1"],["76316.8","0.11970829","1"],["76315.6","0.00001033","1"],["76315.1","0.00023744","5"],["76312.9","0","0"],["76312.4","0.00305","1"],["76311.8","0.47152463","2"],["76311.7","0","0"],["76309.7","1.00597757","1"],["76308.7","0.47151308","1"],["76304.6","0.47151308","1"],["76304.5","0.00001316","1"],["76303.2","0.00001033","1"],["76300.3","0","0"],["76298.2","0","0"],["76297.8","0.12242793","3"],["76290","0.02396779","1"],["76240.7","0","0"],["76235.5","0.00001316","1"],["76195.4","0.00098504","2"],["76195.1","0.01457366","1"],["76194.3","0.0018792","9"],["76193.9","0.01496","1"],["76193.7","0.00009338","1"],["76193.4","0.00002624","1"]]}
{"instId":"BTC-USDT","action":"update","ts":"1776816056940","asks":[["76339.9","1.52032563","21"],["76340","0.57373904","9"],["76341.5","0","0"],["76341.6","0.036","1"],["76342.2","0.50751308","2"],["76343.7","0.03863043","3"],["76344.6","0.00649862","1"],["76346.6","0.00786129","3"],["76347.9","0.00654725","1"],["76348","0","0"],["76349.9","0","0"],["76352.7","0.01614584","1"],["76353.6","0.43957688","2"],["76353.7","0.08378297","1"],["76353.8","0","0"],["76354.1","0","0"],["76354.3","0","0"],["76355.3","0.26517365","4"],["76357.6","0.00654768","1"],["76358.8","0","0"],["76368","0","0"],["76371.1","0.11704811","1"],["76380","0.0000812","1"],["76384.2","0.1297","1"],["76387.6","0.00130911","1"],["76388.4","0.00132225","2"],["76395.5","0","0"],["76397.9","0","0"],["76433.6","0","0"],["76459.2","0.08410468","3"],["76459.3","0.00319921","2"]],"bids":[["76339.9","0","0"],["76339.8","0.03361691","2"],["76336","0.03226873","1"],["76332.7","0","0"],["76332.2","0","0"],["76331.1","0.03","2"],["76328.3","0.00655811","2"],["76328.2","0","0"],["76325.7","0","0"],["76323.6","0.00001034","1"],["76323.3","0.00305","1"],["76323.2","0","0"],["76322.3","0.32739228","1"],["76322.2","0","0"],["76320.8","0.00659396","2"],["76318.9","0","0"],["76311.9","1.47749065","2"],["76311.8","0.00001155","1"],["76311.1","0","0"],["76309.7","0","0"],["76309.3","0.26197188","6"],["76304.7","1.00598843","2"],["76304.2","0","0"],["76303.3","0.08378297","1"],["76301.3","0","0"],["76296.5","0","0"],["76296.1","0.00131068","1"],["76292.5","0.03435952","3"],["76279.3","0.12276854","2"],["76211.3","0.08378297","1"],["76193.2","0.47151308","1"],["76193.1","0.00004445","1"],["76192.7","0.00013126","1"],["76192.3","2.54203491","4"],["76192.2","0.00007834","2"],["76191.2","0.0000842","4"],["76191","0.00014147","1"]]}
{"instId":"BTC-USDT","action":"update","ts":"1776816056950","asks":[["76339.9","1.52664608","23"],["76340","0.20195659","5"],["76342.1","0.16497267","1"],["76347.8","0.00654749","1"],["76347.9","0","0"],["76350","0.17365014","2"],["76353.6","0.1121846","1"],["76353.9","0.32740377","1"],["76355.3","0.21213892","3"],["76355.6","0.00654829","1"],["76355.9","0.06550532","1"],["76356.8","0.05896264","1"],["76357.6","0","0"],["76363.5","0","0"],["76364.8","0","0"],["76372.6","0.47151308","1"],["76373.5","0","0"],["76376.3","0.14428583","2"],["76380.9","0.02398317","1"],["76384.2","0","0"],["76388.9","0","0"],["76433.7","0","0"],["76438.3","0.00005159","3"],["76459.6","0.00072458","2"]],"bids":[["76339.8","0.03623581","3"],["76335.9","0.04911036","1"],["76329.2","0.05896264","1"],["76328.3","0.00001086","1"],["76328.2","0.00654749","1"],["76324.4","0.07480705","1"],["76322.3","0.32740377","1"],["76321.6","0.01058312","1"],["76320.2","0","0"],["76315.6","0.47152341","2"],["76296.1","0","0"],["76292.5","0.03304878","2"],["76290","0","0"],["76288.7","0","0"],["76286.2","0.00131085","1"],["76284.3","0.00131088","1"],["76283.8","0","0"],["76282","0.02398317","1"],["76198.3","0","0"],["76191.7","0.1305","1"],["76191.2","0","0"],["76191","0","0"]]}
{"instId":"BTC-USDT","action":"update","ts":"1776816056960","asks":[["76347.8","0","0"],["76349.9","0.00654747","1"],["76353.9","0","0"],["76354.6","0.32741483","1"],["76363","0.012","1"],["76374.3","0.01047472","4"],["76384.2","0.13476912","1"],["76459.3","0","0"],["76459.6","0","0"]],"bids":[["76339.8","0.03361691","2"],["76336","0","0"],["76331.1","0.01","1"],["76322.4","0.55504007","4"],["76322.3","0","0"],["76316.7","0.20644552","2"],["76316.6","0","0"],["76306.8","0.52581636","1"],["76288.8","0","0"],["76191.2","0.0000842","4"],["76191","0.00014147","1"],["76190.9","0.0002635","5"],["76190.4","0.00001319","1"]]}
{"instId":"BTC-USDT","action":"update","ts":"1776816056970","asks":[["76349.9","0.14098995","1"],["76352.6","0.00654747","1"],["76353.5","0.32741256","1"],["76353.6","0","0"],["76354.6","0","0"],["76355.5","0.00654823","1"],["76355.6","0","0"]],"bids":[["76331.2","0.00654747","1"],["76331.1","0","0"],["76328.2","0","0"],["76322.5","0.28884421","1"],["76322.4","0.00673046","2"],["76321.6","0","0"],["76320.8","0.33400709","3"],["76317.9","0.06877742","3"],["76274.9","0.15684558","3"],["76190","0.00001428","1"]]}
{"instId":"BTC-USDT","action":"update","ts":"1776816056980","asks":[["76349.9","0.14753742","2"],["76352.6","0","0"],["76353.5","0","0"],["76354.6","0.32741237","1"],["76355.3","0.05303473","1"],["76355.5","0","0"],["76356.7","0.00654823","1"],["76459.3","0.00319921","2"]],"bids":[["76336.9","0","0"],["76331.2","0","0"],["76329.6","0.0131","1"],["76328.2","0.00654747","1"],["76324.3","0.12762072","2"],["76323.5","0.32741237","1"],["76320.9","0.00654823","1"],["76320.8","0.0000463","1"],["76319.3","1.47789071","3"],["76319.2","0","0"],["76312","0.30279","1"],["76190.4","0","0"],["76190","0","0"]]}
{"instId":"BTC-USDT","action":"update","ts":"1776816056990","asks":[["76345.7","0","0"],["76349.8","0.00654739","1"],["76349.9","0.14098995","1"],["76353.6","0.32741212","1"],["76354.6","0","0"]],"bids":[["76328.2","0","0"],["76324.5","0.00654739","1"],["76324.4","0.16613465","2"],["76323.5","0","0"],["76320.8","0.32745842","2"],["76292.8","0","0"],["76290.9","0","0"],["76289.8","0.00326306","2"],["76286.5","0.00233657","1"],["76190.4","0.00001319","1"],["76190","0.00001428","1"]]}
{"instId":"BTC-USDT","action":"update","ts":"1776816057000","asks":[["76346.5","0.00654741","1"],["76349.8","0.13051041","1"],["76350","0.03","1"],["76353.5","0.33257913","1"],["76353.9","0.00654808","1"],["76354","0","0"],["76356.7","0","0"],["76357.6","0.11559576","1"],["76357.9","0","0"],["76459.3","0","0"]],"bids":[["76330.1","0.02","1"],["76324.6","0.00656057","2"],["76324.5","0","0"],["76324.4","0.07480705","1"],["76320.9","0","0"],["76319.4","0.00654808","1"],["76309.3","0.26160585","5"],["76274.9","0.04663392","2"]]}
{"instId":"BTC-USDT","action":"update","ts":"1776816057010","asks":[["76346.5","0.0065473","1"],["76347.7","0.21213892","3"],["76353.4","0.32741168","1"],["76353.6","0","0"],["76459.2","0","0"]],"bids":[["76337.9","0.00002691","1"],["76330.1","0.03","2"],["76324.6","0.00001316","1"],["76324.5","0.00654741","1"],["76320.8","0.0000463","1"],["76319.4","0.33395976","2"],["76261.1","0.00055717","2"],["76190.4","0","0"],["76190","0","0"]]}
{"instId":"BTC-USDT","action":"update","ts":"1776816057020","asks":[["76346.5","0","0"],["76347.6","0.0698747","2"],["76353.5","0","0"],["76353.9","0","0"],["76354.6","0.00654838","1"],["76459.2","0.08410468","3"]],"bids":[["76324.5","0.0065473","1"],["76322.5","0.53346723","2"],["76319.5","0.00654838","1"],["76319.4","0.32741168","1"],["76190.9","0","0"]]}
{"instId":"BTC-USDT","action":"update","ts":"1776816057030","asks":[["76343.6","0.00654734","1"],["76347.6","0.0633274","1"],["76349.7","0.32741697","1"],["76350.6","0.22531173","2"],["76352.6","0.0065485","1"],["76353.4","0","0"],["76354.6","0","0"],["76387.9","1.92241581","1"],["76393.1","0","0"],["76459.2","0","0"]],"bids":[["76324.5","0","0"],["76323.5","0.00654734","1"],["76319.5","0","0"],["76319.4","0","0"],["76318","0.32741697","1"],["76315.7","0.0065485","1"],["76288","0","0"],["76196.4","0.0142092","1"]]}
{"instId":"BTC-USDT","action":"update","ts":"1776816057040","asks":[["76349.6","0.47093748","2"],["76349.9","0","0"],["76350.6","0","0"],["76402.8","1.148342","4"],["76406.8","0","0"],["76459.2","0.08410468","3"],["76459.3","0.00319921","2"]],"bids":[["76323.3","0","0"],["76313.1","0.05549229","3"],["76310","0","0"],["76293.3","0.00305","1"],["76280.9","0.0000168","1"],["76277.2","0.00323376","1"]]}
{"instId":"BTC-USDT","action":"update","ts":"1776816057050","asks":[["76347.6","0.19580595","2"]],"bids":[["76336","0.01466839","1"],["76317.5","0.00305","1"],["76313.1","0.05244229","2"],["76304.3","0.01043407","2"],["76293.3","0","0"],["76279.6","0.1134582","2"],["76191","0","0"]]}
{"instId":"BTC-USDT","action":"update","ts":"1776816057060","asks":[],"bids":[["76336","0","0"],["76318.1","0.33815018","1"],["76316.7","0","0"],["76279.3","0.00040006","1"],["76191","0.00014147","1"]]}
{"instId":"BTC-USDT","action":"update","ts":"1776816057070","asks":[],"bids":[["76308.8","0","0"],["76304.9","0.06324779","1"]]}
{"instId":"BTC-USDT","action":"update","ts":"1776816057080","asks":[],"bids":[["76336","0.01466839","1"],["76329","0.0262","1"],["76326.7","0.01058241","1"],["76324.3","0.11703798","1"],["76191.7","0","0"],["76191.2","0","0"],["76191","0","0"]]}
{"instId":"BTC-USDT","action":"update","ts":"1776816057100","asks":[["76385.2","0","0"],["76459.6","0.00072458","2"]],"bids":[["76306.9","0","0"],["76277.2","0","0"],["76215.2","0.02702705","2"],["76191.2","0.0000842","4"],["76191","0.00014147","1"]]}
{"instId":"BTC-USDT","action":"update","ts":"1776816057110","asks":[["76354.6","0.20581918","1"],["76434","0.00003166","2"],["76444.1","0.00033322","3"],["76459.6","0","0"]],"bids":[["76269.7","0","0"],["76263.6","0.00013112","1"],["76261.1","0.00001501","1"],["76255","0.0471761","3"],["76191.7","0.1305","1"],["76191","0","0"]]}
{"instId":"BTC-USDT","action":"update","ts":"1776816057120","asks":[["76381.1","0.06419537","2"]],"bids":[["76336","0","0"],["76191","0.00014147","1"]]}
{"instId":"BTC-USDT","action":"update","ts":"1776816057160","asks":[],"bids":[["76292.5","0","0"],["76190.9","0.0002635","5"]]}
{"instId":"BTC-USDT","action":"update","ts":"1776816057170","asks":[],"bids":[["76277.2","0.00323381","1"],["76190.9","0","0"]]}
{"instId":"BTC-USDT","action":"update","ts":"1776816057200","asks":[["76341.8","0.00001066","1"],["76343.7","0.03862043","2"],["76459.3","0","0"]],"bids":[]}
{"instId":"BTC-USDT","action":"update","ts":"1776816057210","asks":[["76364.7","1.02188629","2"]],"bids":[["76339","0.00079463","1"],["76314.8","0.01595246","1"],["76303.3","0.08381161","2"],["76191.2","0","0"],["76191","0","0"]]}
{"instId":"BTC-USDT","action":"update","ts":"1776816057220","asks":[["76350.6","0.0065483","1"],["76352.6","0","0"]],"bids":[]}
{"instId":"BTC-USDT","action":"update","ts":"1776816057240","asks":[],"bids":[["76228.1","0.00514548","1"],["76191.7","0","0"]]}
{"instId":"BTC-USDT","action":"update","ts":"1776816057250","asks":[],"bids":[["76303.3","0.08378297","1"]]}
{"instId":"BTC-USDT","action":"update","ts":"1776816057260","asks":[],"bids":[["76329","0","0"],["76319.3","1.00637763","2"],["76191.2","0.0000842","4"]]}
{"instId":"BTC-USDT","action":"update","ts":"1776816057270","asks":[["76348","0.03","2"],["76355.3","0","0"],["76355.7","0","0"],["76384.2","0","0"],["76459.3","0.00319921","2"],["76459.6","0.00072458","2"]],"bids":[["76339","0","0"],["76337.1","0","0"],["76330.1","0","0"],["76329.9","0","0"],["76327.9","0.03","2"],["76327.8","0","0"],["76322.5","0.28884421","1"],["76319.4","1.00602765","1"],["76319.3","0.00040006","1"],["76314.8","0","0"],["76196.4","0","0"],["76191.7","0.1305","1"],["76191","0.00014147","1"],["76190.9","0.0002635","5"],["76190.4","0.00001319","1"],["76190","0.00001428","1"]]}
{"instId":"BTC-USDT","action":"update","ts":"1776816057280","asks":[["76347.7","0.26517365","4"],["76349.7","0.41119994","2"],["76350.6","0","0"],["76352.6","0.00654825","1"],["76364.7","1.00602765","1"]],"bids":[["76330","0.0312738","1"],["76327.9","0.01","1"],["76326.7","0","0"],["76324.2","0.01058275","1"],["76319.5","0.01587764","1"],["76273.6","0.11206202","2"],["76190","0","0"]]}
{"instId":"BTC-USDT","action":"update","ts":"1776816057300","asks":[["76384.2","0.10494534","1"],["76459.6","0","0"]],"bids":[["76324.6","0.10583438","2"],["76319.5","0.48739072","2"]]}
{"instId":"BTC-USDT","action":"update","ts":"1776816057310","asks":[["76343.5","0.0065476","1"],["76343.6","0","0"]],"bids":[["76327.3","0.0262","1"],["76323.6","0.00655794","2"],["76323.5","0","0"],["76322.5","0.43853466","2"]]}
{"instId":"BTC-USDT","action":"update","ts":"1776816057320","asks":[["76350.6","0.0065484","1"],["76352.6","0","0"],["76353.1","0.012","1"],["76363","0","0"]],"bids":[["76328.4","0.02","1"],["76190.4","0","0"]]}
{"instId":"BTC-USDT","action":"update","ts":"1776816057340","asks":[["76363.5","0.01554534","1"],["76459.3","0","0"]],"bids":[["76314.5","0.01602244","1"],["76190.9","0","0"]]}
{"instId":"BTC-USDT","action":"update","ts":"1776816057350","asks":[["76343.5","0","0"],["76343.6","0.00654761","1"],["76347.6","0.12051636","1"],["76376.8","0.12237472","1"],["76459.2","0","0"]],"bids":[["76323.6","0.00001034","1"],["76322.6","0.00654761","1"],["76191","0","0"]]}
{"instId":"BTC-USDT","action":"update","ts":"1776816057390","asks":[],"bids":[["76303.3","0.08381161","2"],["76273.6","0.00001155","1"]]}
{"instId":"BTC-USDT","action":"update","ts":"1776816057410","asks":[],"bids":[["76263.6","0","0"],["76262.1","0.00013113","1"],["76255","0.04663392","2"],["76253.5","0.00055718","2"]]}
{"instId":"BTC-USDT","action":"update","ts":"1776816057430","asks":[["76340","0.05006855","3"],["76363.5","0","0"],["76387.6","0.10922927","2"],["76459.2","0.08410468","3"]],"bids":[["76336","0.01466839","1"],["76326.6","0.01081986","6"],["76324.2","0","0"]]}
{"instId":"BTC-USDT","action":"update","ts":"1776816057440","asks":[["76387.6","0.00130911","1"]],"bids":[["76303.3","0.08378297","1"],["76277.2","0","0"],["76191","0.00014147","1"]]}
{"instId":"BTC-USDT","action":"update","ts":"1776816057460","asks":[],"bids":[["76292.6","0.03304878","2"],["76191","0","0"]]}
{"instId":"BTC-USDT","action":"update","ts":"1776816057480","asks":[["76364.7","1.02225683","2"]],"bids":[["76314.5","0","0"],["76191","0.00014147","1"]]}
{"instId":"BTC-USDT","action":"update","ts":"1776816057510","asks":[["76425.8","0.659464","1"],["76430.5","0.657913","1"],["76459.1","0","0"],["76459.2","0","0"]],"bids":[["76336","0","0"],["76303.3","0.08381161","2"],["76281","0.65921516","2"],["76277.2","0.00323381","1"],["76276","0.660758","1"],["76191","0","0"]]}
{"instId":"BTC-USDT","action":"update","ts":"1776816057520","asks":[["76364.8","0.18498251","1"],["76458.8","0","0"]],"bids":[["76281.1","0.56376322","1"],["76280.7","0.08378297","1"],["76191.2","0","0"]]}
{"instId":"BTC-USDT","action":"update","ts":"1776816057530","asks":[["76387.7","0.76258285","2"],["76431.5","0","0"],["76458.8","0.00001501","1"]],"bids":[]}
{"instId":"BTC-USDT","action":"update","ts":"1776816057540","asks":[],"bids":[["76315.7","0.02247552","2"]]}
{"instId":"BTC-USDT","action":"update","ts":"1776816057550","asks":[],"bids":[["76336","0.01466839","1"],["76191.7","0","0"]]}
{"instId":"BTC-USDT","action":"update","ts":"1776816057560","asks":[["76350.6","0","0"],["76352.6","0.00654823","1"]],"bids":[["76315.8","0.00654823","1"],["76315.7","0.01592702","1"],["76192.2","0","0"]]}
{"instId":"BTC-USDT","action":"update","ts":"1776816057590","asks":[["76347.7","0.21213892","3"]],"bids":[]}
{"instId":"BTC-USDT","action":"update","ts":"1776816057600","asks":[["76355.3","0.05303473","1"],["76458.8","0","0"]],"bids":[]}
{"instId":"BTC-USDT","action":"update","ts":"1776816057680","asks":[["76347.7","0","0"],["76458.8","0.00001501","1"]],"bids":[]}
{"instId":"BTC-USDT","action":"update","ts":"1776816057690","asks":[["76347.6","0.04945831","1"],["76355.3","0.26517365","4"]],"bids":[]}
{"instId":"BTC-USDT","action":"update","ts":"1776816057710","asks":[["76364.7","1.00602765","1"]],"bids":[]}
{"instId":"BTC-USDT","action":"update","ts":"1776816057750","asks":[],"bids":[["76315.7","0","0"],["76192.2","0.00007834","2"]]}
{"instId":"BTC-USDT","action":"update","ts":"1776816057780","asks":[],"bids":[["76285.7","0.01939304","1"],["76195.1","0.02886703","2"],["76192.2","0","0"]]}
{"instId":"BTC-USDT","action":"update","ts":"1776816057920","asks":[["76355.9","0","0"],["76459.1","0.00006716","3"]],"bids":[["76339.8","0.06341691","3"]]}
{"instId":"BTC-USDT","action":"update","ts":"1776816057930","asks":[["76369.9","0","0"],["76459.2","0.08410468","3"]],"bids":[["76339.8","0.12591691","4"]]}
{"instId":"BTC-USDT","action":"update","ts":"1776816057940","asks":[["76340","0.05006854","2"],["76380","0.00139044","2"],["76388.4","0.00001316","1"]],"bids":[["76312","0.38657297","2"]]}
{"instId":"BTC-USDT","action":"update","ts":"1776816057950","asks":[["76361.7","0.06550532","1"],["76459.2","0","0"]],"bids":[["76292.6","0","0"],["76246.2","0","0"],["76231.4","0.01637","2"],["76192.2","0.00007834","2"],["76191.2","0.0000842","4"]]}
{"instId":"BTC-USDT","action":"update","ts":"1776816057960","asks":[],"bids":[["76339.8","0.03361691","2"],["76191.7","0.1305","1"],["76191.2","0","0"]]}
{"instId":"BTC-USDT","action":"update","ts":"1776816057970","asks":[],"bids":[["76314.9","0.61013919","2"]]}
{"instId":"BTC-USDT","action":"update","ts":"1776816057980","asks":[["76340","0.01406854","1"]],"bids":[["76339.8","0.12591691","4"]]}
{"instId":"BTC-USDT","action":"update","ts":"1776816057990","asks":[],"bids":[["76326.6","0.00023743","5"]]}
{"instId":"BTC-USDT","action":"update","ts":"1776816058000","asks":[["76364.2","0.01573618","1"],["76459.1","0","0"]],"bids":[["76331.5","0.01283767","1"],["76322.6","0.47806069","2"],["76316.8","0.13586432","2"],["76191.7","0","0"]]}
{"instId":"BTC-USDT","action":"update","ts":"1776816058010","asks":[["76343.6","0","0"],["76344.5","0.00654744","1"],["76349.6","0.79834705","3"],["76349.7","0.08378297","1"]],"bids":[["76330","0.14132288","2"],["76324.7","0.00654744","1"],["76322.6","0.47151308","1"],["76318.2","0.32740957","1"],["76318","0","0"],["76316.9","0.00659442","2"],["76315.8","0","0"],["76285.5","0.04261265","1"],["76192.2","0","0"]]}
{"instId":"BTC-USDT","action":"update","ts":"1776816058020","asks":[["76343.6","0.00654742","1"],["76344.5","0","0"],["76347.6","0.14086692","2"],["76349.6","0.4630859","2"]],"bids":[["76330.1","0.07194415","1"],["76330","0.11004908","1"],["76324.7","0.14098995","1"],["76323.5","0.00654742","1"],["76318.1","0","0"],["76316.9","0.00004629","1"],["76315.7","0.00654813","1"],["76192.7","0","0"],["76192.3","0","0"]]}
{"instId":"BTC-USDT","action":"update","ts":"1776816058030","asks":[["76349.5","0.32740827","1"],["76349.6","0.13567633","1"],["76349.7","0.28280657","2"],["76402.8","1.14830219","3"],["76458.8","0","0"]],"bids":[["76330.2","0.12236864","1"],["76324.8","0.14952809","1"],["76324.4","0","0"],["76318.3","0.32741861","2"],["76318.2","0","0"],["76284.9","0","0"],["76279.6","0.00019775","1"],["76192.7","0.00013126","1"]]}
{"instId":"BTC-USDT","action":"update","ts":"1776816058040","asks":[["76349.8","0","0"],["76458.8","0.00001501","1"]],"bids":[["76339.8","0.12711691","5"],["76330.3","0.10847119","1"],["76330.1","0","0"],["76324.6","0.00001316","1"],["76324.3","0","0"],["76318.4","0.32740849","1"],["76318.3","0.00001034","1"],["76284.9","0.12502883","1"],["76192.7","0","0"]]}
{"instId":"BTC-USDT","action":"update","ts":"1776816058050","asks":[],"bids":[["76330.4","0.11488874","6"],["76324.8","0.08300462","1"],["76318.4","0","0"],["76318","0.32740854","1"]]}
{"instId":"BTC-USDT","action":"update","ts":"1776816058070","asks":[],"bids":[["76292.4","0.03343349","3"]]}
{"instId":"BTC-USDT","action":"update","ts":"1776816058080","asks":[],"bids":[["76339.8","0.06341691","3"]]}
{"instId":"BTC-USDT","action":"update","ts":"1776816058090","asks":[["76341.8","0","0"],["76459.1","0.00006716","3"]],"bids":[["76337.9","0.00005795","2"]]}
{"instId":"BTC-USDT","action":"update","ts":"1776816058130","asks":[["76343.6","0","0"],["76344.5","0.00654742","1"]],"bids":[["76316.9","0.00659432","2"],["76315.7","0","0"],["76192.7","0.00013126","1"]]}
{"instId":"BTC-USDT","action":"update","ts":"1776816058140","asks":[],"bids":[["76303.3","0.08378297","1"],["76277.2","0","0"],["76192.3","2.54203491","4"]]}
{"instId":"BTC-USDT","action":"update","ts":"1776816058170","asks":[["76442.3","0.49221241","7"]],"bids":[]}
{"instId":"BTC-USDT","action":"update","ts":"1776816058180","asks":[["76339.9","1.43101608","22"],["76402.7","0.0233595","2"]],"bids":[["76339.8","0.12711691","5"]]}
{"instId":"BTC-USDT","action":"update","ts":"1776816058190","asks":[["76349.5","0","0"],["76350.6","0.32740616","1"],["76364.2","0","0"],["76459.2","0.08410468","3"]],"bids":[["76337.9","0.00002691","1"],["76324.8","0.08955205","2"],["76323.5","0","0"],["76316.8","0.11970829","1"],["76192.2","0.00007834","2"]]}
{"instId":"BTC-USDT","action":"update","ts":"1776816058200","asks":[["76347.6","0.04945831","1"]],"bids":[["76277.2","0.00323384","1"],["76192.2","0","0"]]}
{"instId":"BTC-USDT","action":"update","ts":"1776816058210","asks":[],"bids":[["76303.3","0.08381161","2"],["76299.1","0.18379798","3"]]}
{"instId":"BTC-USDT","action":"update","ts":"1776816058220","asks":[["76343.6","0.00654736","1"],["76344.5","0","0"],["76349.5","0.32740336","1"],["76350.6","0","0"]],"bids":[["76324.8","0.08300462","1"],["76323.5","0.00654736","1"],["76316.9","0.00004629","1"],["76315.7","0.00654804","1"],["76192.7","0","0"],["76192.3","0","0"]]}
{"instId":"BTC-USDT","action":"update","ts":"1776816058230","asks":[["76347.6","0.14086507","2"]],"bids":[]}
{"instId":"BTC-USDT","action":"update","ts":"1776816058240","asks":[["76343.6","0","0"],["76344.5","0.00654736","1"]],"bids":[["76316.9","0.00659433","2"],["76315.7","0","0"],["76192.7","0.00013126","1"]]}
{"instId":"BTC-USDT","action":"update","ts":"1776816058250","asks":[["76396.9","0.1","1"],["76459.2","0","0"]],"bids":[["76319.5","0.47151308","1"]]}
{"instId":"BTC-USDT","action":"update","ts":"1776816058270","asks":[],"bids":[["76285.7","0","0"],["76195.1","0.01457366","1"],["76192.3","2.54203491","4"]]}
{"instId":"BTC-USDT","action":"update","ts":"1776816058290","asks":[["76344.5","0","0"],["76346.5","0.00654743","1"],["76349.5","0","0"],["76350.6","0.32739999","1"]],"bids":[["76324.9","0.00654743","1"],["76323.5","0","0"],["76319.6","0.32739999","1"],["76318","0","0"]]}
{"instId":"BTC-USDT","action":"update","ts":"1776816058300","asks":[["76347.6","0.04945831","1"]],"bids":[]}
{"instId":"BTC-USDT","action":"update","ts":"1776816058310","asks":[["76339.9","1.43102608","23"]],"bids":[]}
{"instId":"BTC-USDT","action":"update","ts":"1776816058320","asks":[["76344.5","0.0065474","1"],["76346.5","0","0"]],"bids":[]}
{"instId":"BTC-USDT","action":"update","ts":"1776816058360","asks":[["76402.7","0.02331962","1"]],"bids":[]}
{"instId":"BTC-USDT","action":"update","ts":"1776816058400","asks":[],"bids":[["76319.6","0","0"],["76318","0.32740647","1"]]}
{"instId":"BTC-USDT","action":"update","ts":"1776816058420","asks":[["76354.4","0.11918344","2"]],"bids":[["76339.8","0.06341691","3"]]}
{"instId":"BTC-USDT","action":"update","ts":"1776816058480","asks":[["76402.7","0.0233595","2"]],"bids":[]}
{"instId":"BTC-USDT","action":"update","ts":"1776816058500","asks":[],"bids":[["76339.8","0.06461691","4"]]}
{"instId":"BTC-USDT","action":"update","ts":"1776816058510","asks":[["76364.9","0.48746757","3"]],"bids":[["76318.7","0.01621169","1"],["76192.3","0","0"]]}
{"instId":"BTC-USDT","action":"update","ts":"1776816058620","asks":[["76355.3","0.15910419","3"]],"bids":[["76339.8","0.06341691","3"]]}
{"instId":"BTC-USDT","action":"update","ts":"1776816058630","asks":[["76347.7","0.10606946","1"],["76459.1","0","0"]],"bids":[]}
{"instId":"BTC-USDT","action":"update","ts":"1776816058640","asks":[["76347.6","0.0747969","2"]],"bids":[]}
{"instId":"BTC-USDT","action":"update","ts":"1776816058700","asks":[["76341.8","0.00001338","1"],["76458.8","0","0"]],"bids":[]}
{"instId":"BTC-USDT","action":"update","ts":"1776816058710","asks":[["76425.7","0.20282934","2"]],"bids":[]}
{"instId":"BTC-USDT","action":"update","ts":"1776816058720","asks":[],"bids":[["76339.8","0.03361691","2"]]}
{"instId":"BTC-USDT","action":"update","ts":"1776816058740","asks":[],"bids":[["76339.8","0.06341691","3"]]}
{"instId":"BTC-USDT","action":"update","ts":"1776816058750","asks":[],"bids":[["76330.5","0.00262018","1"],["76192.7","0","0"]]}
{"instId":"BTC-USDT","action":"update","ts":"1776816058770","asks":[],"bids":[["76285.5","0.06162677","2"],["76194.9","0.014399","1"],["76193.1","0","0"]]}
{"instId":"BTC-USDT","action":"update","ts":"1776816058840","asks":[],"bids":[["76304.9","0","0"],["76193.1","0.00004445","1"]]}
{"instId":"BTC-USDT","action":"update","ts":"1776816058920","asks":[],"bids":[["76330.5","0.00524036","2"]]}
{"instId":"BTC-USDT","action":"update","ts":"1776816058930","asks":[],"bids":[["76324.9","0","0"],["76323.5","0.00654745","1"]]}
{"instId":"BTC-USDT","action":"update","ts":"1776816058960","asks":[["76349.6","0.46308473","2"],["76350.6","0","0"],["76458.8","0.00001501","1"]],"bids":[["76339.8","0.03361691","2"]]}
{"instId":"BTC-USDT","action":"update","ts":"1776816058970","asks":[["76347.6","0.16928882","1"]],"bids":[]}
{"instId":"BTC-USDT","action":"update","ts":"1776816058980","asks":[],"bids":[["76292.4","0.0000168","1"]]}
{"instId":"BTC-USDT","action":"update","ts":"1776816058990","asks":[],"bids":[["76318.1","0.3381469","1"],["76193.1","0","0"]]}
{"instId":"BTC-USDT","action":"update","ts":"1776816059030","asks":[["76349.6","0.13567633","1"],["76350.6","0.3274083","1"],["76458.8","0","0"]],"bids":[["76339.8","0.06341691","3"],["76324.9","0.00654751","1"],["76323.5","0","0"],["76318.2","0.3274083","1"],["76318","0","0"]]}
{"instId":"BTC-USDT","action":"update","ts":"1776816059040","asks":[["76347.6","0.08112005","1"],["76347.7","0","0"],["76349.6","0.46308463","2"],["76350.6","0","0"],["76458.8","0.00001501","1"],["76459.1","0.00006716","3"]],"bids":[["76324.9","0","0"],["76323.5","0.00654745","1"],["76318.1","0","0"],["76193.1","0.00004445","1"]]}
{"instId":"BTC-USDT","action":"update","ts":"1776816059050","asks":[["76347.6","0.13681865","2"]],"bids":[]}
{"instId":"BTC-USDT","action":"update","ts":"1776816059060","asks":[["76347.7","0.10606946","1"],["76459.1","0","0"]],"bids":[]}
{"instId":"BTC-USDT","action":"update","ts":"1776816059090","asks":[],"bids":[["76330.5","0.00786054","3"]]}
{"instId":"BTC-USDT","action":"update","ts":"1776816059100","asks":[["76349.6","0.13567633","1"],["76350.6","0.32740836","1"],["76458.8","0","0"]],"bids":[["76339.8","0.12711691","5"],["76324.8","0.08955208","2"],["76323.5","0","0"],["76318.2","0","0"],["76318","0.32740836","1"],["76192.7","0.00013126","1"]]}
{"instId":"BTC-USDT","action":"update","ts":"1776816059110","asks":[["76347.6","0.08112005","1"]],"bids":[]}
{"instId":"BTC-USDT","action":"update","ts":"1776816059120","asks":[["76347.7","0","0"],["76458.8","0.00001501","1"]],"bids":[]}
{"instId":"BTC-USDT","action":"update","ts":"1776816059130","asks":[["76347.6","0.04945831","1"]],"bids":[]}
{"instId":"BTC-USDT","action":"update","ts":"1776816059140","asks":[["76355.3","0.26517365","4"]],"bids":[]}
{"instId":"BTC-USDT","action":"update","ts":"1776816059260","asks":[],"bids":[["76330.5","0.01048072","4"]]}
{"instId":"BTC-USDT","action":"update","ts":"1776816059300","asks":[["76341.8","0","0"],["76459.1","0.00006716","3"]],"bids":[["76337.9","0.00003919","2"]]}
{"instId":"BTC-USDT","action":"update","ts":"1776816059340","asks":[],"bids":[["76339.8","0.12591691","4"]]}
{"instId":"BTC-USDT","action":"update","ts":"1776816059390","asks":[],"bids":[["76339.8","0.12711691","5"]]}
{"instId":"BTC-USDT","action":"update","ts":"1776816059400","asks":[],"bids":[["76339.8","0.09611691","3"]]}
{"instId":"BTC-USDT","action":"update","ts":"1776816059410","asks":[],"bids":[["76339.8","0.03361691","2"]]}
{"instId":"BTC-USDT","action":"update","ts":"1776816059440","asks":[["76349.6","0.46308461","2"],["76350.6","0","0"],["76459.2","0.08410468","3"]],"bids":[["76339.8","0.06341691","3"],["76324.8","0.08300462","1"],["76323.5","0.00654743","1"],["76192.7","0","0"]]}
{"instId":"BTC-USDT","action":"update","ts":"1776816059450","asks":[["76347.6","0.14086654","2"],["76349.6","0.13567633","1"],["76350.5","0.32740828","1"],["76459.2","0","0"]],"bids":[["76324.8","0.08955205","2"],["76323.5","0","0"],["76192.7","0.00013126","1"]]}
{"instId":"BTC-USDT","action":"update","ts":"1776816059460","asks":[["76347.6","0.04945831","1"]],"bids":[]}
{"instId":"BTC-USDT","action":"update","ts":"1776816059500","asks":[],"bids":[["76337.9","0.00002691","1"]]}
{"instId":"BTC-USDT","action":"update","ts":"1776816059620","asks":[["76349.6","0.46308534","2"],["76350.5","0","0"],["76459.2","0.08410468","3"]],"bids":[["76324.8","0.08300462","1"],["76323.5","0.00654745","1"],["76192.7","0","0"]]}
{"instId":"BTC-USDT","action":"update","ts":"1776816059630","asks":[["76347.6","0.14086675","2"],["76349.6","0.13567633","1"],["76350.6","0.32740902","1"],["76459.2","0","0"]],"bids":[["76339.8","0.12711691","5"],["76324.8","0.08955206","2"],["76323.5","0","0"],["76318.7","0","0"],["76192.7","0.00013126","1"],["76192.3","2.54203491","4"]]}
{"instId":"BTC-USDT","action":"update","ts":"1776816059640","asks":[["76347.6","0.04945831","1"],["76364.9","0.47152624","2"],["76376.2","0.15241054","1"],["76376.9","0","0"]],"bids":[]}
{"instId":"BTC-USDT","action":"update","ts":"1776816059650","asks":[["76349.7","0.1990236","1"]],"bids":[["76339.8","0.20969696","6"]]}
{"instId":"BTC-USDT","action":"update","ts":"1776816059660","asks":[],"bids":[["76292.4","0.01702304","2"]]}
{"instId":"BTC-USDT","action":"update","ts":"1776816059670","asks":[],"bids":[["76292.4","0.03373482","3"]]}
{"instId":"BTC-USDT","action":"update","ts":"1776816059790","asks":[["76341.8","0.00001929","1"],["76459.1","0","0"]],"bids":[]}
{"instId":"BTC-USDT","action":"update","ts":"1776816059800","asks":[],"bids":[["76339.8","0.12711691","5"]]}
{"instId":"BTC-USDT","action":"update","ts":"1776816059870","asks":[],"bids":[["76301.1","0.06550228","2"]]}
{"instId":"BTC-USDT","action":"update","ts":"1776816059890","asks":[],"bids":[["76339.8","0.09611691","3"]]}
{"instId":"BTC-USDT","action":"update","ts":"1776816059900","asks":[],"bids":[["76339.8","0.12591691","4"]]}
{"instId":"BTC-USDT","action":"update","ts":"1776816059940","asks":[],"bids":[["76339.8","0.09611691","3"]]}
{"instId":"BTC-USDT","action":"update","ts":"1776816059970","asks":[["76343.6","0.00654737","1"],["76344.5","0","0"],["76349.5","0.32740823","1"],["76350.6","0","0"]],"bids":[["76339.8","0.03361691","2"],["76324.8","0.08300462","1"],["76323.5","0.00654737","1"],["76322.6","0","0"],["76316.9","0.00004629","1"],["76315.7","0.00654813","1"],["76192.3","0","0"]]}
{"instId":"BTC-USDT","action":"update","ts":"1776816059980","asks":[["76347.6","0.14086652","2"],["76349.4","0.1303492","1"],["76349.5","0.4111912","2"],["76354.4","0.00691314","1"],["76458.8","0","0"]],"bids":[["76319.4","0","0"],["76192.3","2.54203491","4"]]}
{"instId":"BTC-USDT","action":"update","ts":"1776816059990","asks":[],"bids":[["76322.5","0.14969045","1"],["76319.6","1.00602765","1"],["76318.1","0.3381475","1"],["76292.4","0.0000168","1"],["76192.7","0","0"],["76192.3","0","0"]]}
