{"instId":"BTC-USDT","action":"update","ts":"1776816023940","asks":[["76355.1","1.97215032","25"],["76355.2","0","0"],["76356.7","0.01082842","1"],["76357.1","0.16405392","2"],["76357.2","0","0"],["76357.3","0.2506719","5"],["76359","0.05896264","1"],["76362.4","0","0"],["76362.8","0.1305","1"],["76363.3","0","0"],["76364.1","0.32733957","1"],["76364.7","0.00654723","1"],["76364.8","0","0"],["76366.3","0","0"],["76366.4","0","0"],["76370.4","0.26517365","4"],["76371","0","0"],["76442.6","0.00022069","3"],["76442.9","0","0"],["76466.6","0.00546094","15"],["76466.7","0.00025453","6"],["76467.1","0.00181702","1"]],"bids":[["76346.8","0","0"],["76344","0","0"],["76342","0.0000168","1"],["76341.9","0.00023748","5"],["76337.9","0.1199112","1"],["76337.8","0","0"],["76337.5","0.00654654","1"],["76334.7","0.00001316","1"],["76334.4","0.07415437","2"],["76334.3","0.07837543","2"],["76331.7","0","0"],["76330.2","0.00654723","1"],["76329.7","0","0"],["76324.4","0.26155956","4"],["76314.5","0.01614584","1"],["76311.2","0.11725967","2"],["76309.9","0","0"],["76308","0.00001456","1"],["76307.1","0","0"],["76305.3","0.00131052","1"],["76303.7","0.00023748","5"],["76301.7","0.13328096","2"],["76296.4","0.13589936","1"],["76176.3","0.1305","1"],["76170.8","0.00003094","3"]]}
{"instId":"BTC-USDT","action":"update","ts":"1776816023950","asks":[["76356.5","0.08729492","2"],["76357.1","0","0"],["76363.2","0.32736499","1"],["76364","0.00654746","1"],["76364.1","0","0"],["76364.7","0","0"],["76364.9","0.00001316","1"],["76401.3","0.1199112","1"],["76467.1","0","0"]],"bids":[["76338","0.03946702","1"],["76337.5","0","0"],["76335.9","0.00654699","1"],["76330.2","0","0"],["76328.7","0.00654746","1"],["76310","0","0"],["76277","0.55966186","3"],["76275.7","0.345672","1"],["76170.8","0","0"]]}
{"instId":"BTC-USDT","action":"update","ts":"1776816023960","asks":[["76355.1","1.9786973","26"],["76356.4","0.05783537","1"],["76356.5","0","0"],["76357.2","0.09242591","1"],["76362.2","0.00654738","1"],["76364","0","0"],["76373","0.07927","1"],["76390.2","0.06375069","1"],["76394.1","0","0"],["76423.5","0.01603351","3"],["76434","0.00001968","1"],["76466.6","0","0"],["76466.7","0","0"]],"bids":[["76335.9","0","0"],["76334.5","0.00654698","1"],["76330.2","0.08827322","1"],["76328.7","0.47151308","1"],["76326.7","0.00654738","1"],["76310.2","0.3642505","1"],["76173.2","0","0"],["76173","0","0"],["76171.1","0","0"]]}
{"instId":"BTC-USDT","action":"update","ts":"1776816023970","asks":[["76356.4","0.03177784","1"]],"bids":[["76339.4","0.00131","1"],["76330.2","0.2157799","2"],["76328.8","1.0057984","1"],["76317.5","0.2822","1"],["76313.6","0.06343835","1"],["76184.3","0","0"],["76173.7","0","0"],["76173.6","0","0"]]}
{"instId":"BTC-USDT","action":"update","ts":"1776816023980","asks":[["76355.1","1.97215032","25"],["76356.3","0.00654686","1"],["76373","0.15875","2"],["76466.5","0","0"]],"bids":[["76340","0.11556108","2"],["76335.9","0.00654686","1"],["76334.5","0","0"],["76330.2","0.49970924","1"],["76328.9","0.32737997","2"],["76316.5","0.00001086","1"]]}
{"instId":"BTC-USDT","action":"update","ts":"1776816023990","asks":[["76355.1","1.85585761","24"],["76356.3","0","0"],["76356.5","0.00654686","1"],["76362.2","0.65553956","1"],["76362.5","0","0"],["76363.1","0.32736829","1"],["76363.2","0","0"],["76365","0.00654734","1"],["76370.4","0.21213892","3"],["76430.8","0","0"],["76466.5","0.00028078","2"]],"bids":[["76340.1","0.03502427","1"],["76339.4","0","0"],["76336","0.00659315","2"],["76335.9","0","0"],["76330.3","0.32736829","1"],["76330.2","0.50625658","2"],["76328.9","0.00001034","1"],["76326.7","0","0"],["76318.1","0","0"],["76307.2","0.47151308","1"],["76304.7","0.00326312","2"],["76304.4","0","0"],["76301.8","0.00233617","1"],["76173.7","0.00070045","3"],["76173.6","0.00002308","1"]]}
{"instId":"BTC-USDT","action":"update","ts":"1776816024000","asks":[["76364.1","0.00654733","1"],["76365","0.03958653","1"],["76466.5","0","0"]],"bids":[["76340.1","0.16026486","2"],["76330.2","0.49970924","1"],["76329","0.00654733","1"],["76314.7","0.22852636","1"],["76300.4","0","0"],["76296.5","0.11224636","1"],["76296.4","0","0"],["76173.6","0","0"]]}
{"instId":"BTC-USDT","action":"update","ts":"1776816024010","asks":[["76356.3","0.00654687","1"],["76356.5","0","0"],["76362.1","0.32736121","1"],["76363.1","0","0"],["76363.8","0.00654726","1"],["76364.1","0","0"],["76387.6","0.25675933","2"],["76443.2","0","0"],["76466.5","0.00028078","2"]],"bids":[["76340.2","0.07201755","1"],["76340.1","0.12524059","1"],["76336.1","0.00654702","1"],["76336","0.00004629","1"],["76331.8","0.05896264","1"],["76329","0","0"],["76328.9","0.0065576","2"],["76310.3","0.47151308","1"],["76281.9","0","0"],["76275.8","0.0001311","1"],["76273.3","0.33238704","1"],["76267.2","0.00054218","1"],["76217.6","0","0"],["76201.5","0.00001197","1"],["76175.1","0","0"],["76175","0","0"],["76173.9","0","0"],["76173.7","0","0"]]}
{"instId":"BTC-USDT","action":"update","ts":"1776816024020","asks":[["76355.1","1.87858761","25"],["76362.1","0","0"],["76362.5","0.32736427","1"],["76363.8","0","0"],["76364.1","0.0065472","1"]],"bids":[["76340.3","0.12257942","1"],["76340","0.0000812","1"],["76337.9","0","0"],["76336.2","0.00654698","1"],["76336.1","0","0"],["76329","0.0065472","1"],["76328.9","0.00001034","1"],["76318.1","0.13678515","1"],["76314.3","0.100015","2"],["76308.7","0","0"],["76304.3","0.12463395","2"],["76296.7","0.11724988","1"],["76296.5","0","0"],["76175.4","0","0"]]}
{"instId":"BTC-USDT","action":"update","ts":"1776816024030","asks":[["76355.1","1.79480464","24"],["76356.3","0.00654695","1"],["76357.3","0.10008376","4"],["76359","0.05900893","2"],["76362.1","0.32736095","1"],["76362.5","0","0"],["76363.8","0.00654764","1"],["76364.1","0","0"],["76376.3","0.12527321","1"],["76378.8","0","0"],["76379","0","0"],["76379.8","0.00001034","1"],["76380.1","0.00018116","3"],["76382.6","0","0"],["76389.2","0.00130908","1"],["76392.8","0.08509199","2"],["76393.5","0","0"],["76398.3","0","0"],["76406.8","0.13018169","1"],["76466.6","0.00546094","15"]],"bids":[["76355","0.07298255","5"],["76340.4","0.07413676","1"],["76340.2","0","0"],["76338","0","0"],["76336.3","0.00654695","1"],["76336.2","0","0"],["76329","0","0"],["76328.9","0.00655798","2"],["76317.6","0.08378297","1"],["76307.4","0","0"],["76305.3","0","0"],["76297.1","0.00131066","1"],["76293.5","0.00131072","1"],["76175.4","0.00003868","3"]]}
{"instId":"BTC-USDT","action":"update","ts":"1776816024040","asks":[["76357.2","0.04748917","1"],["76363.3","0.00654739","1"],["76363.8","0","0"],["76418.3","0.00003967","1"],["76421.3","0","0"]],"bids":[["76355","0.01048255","4"],["76342.1","0.02619","1"],["76340.5","0.11724988","1"],["76340.1","0","0"],["76336.4","0.00654697","1"],["76336.3","0","0"],["76329.1","0.01546255","1"],["76328.9","0.00001034","1"],["76328.8","1.01234579","2"],["76303.9","0.4106207","1"],["76294.1","0","0"],["76292.6","0.00323366","1"],["76177.8","0","0"],["76176.3","0","0"],["76175.4","0","0"]]}
{"instId":"BTC-USDT","action":"update","ts":"1776816024050","asks":[["76355.1","1.86006464","25"],["76357.3","0.03616376","3"],["76363.2","0.00654732","1"],["76363.3","0","0"]],"bids":[["76340.6","0.07176188","2"],["76340.4","0","0"],["76336.4","0","0"],["76335.9","0.00654697","1"],["76328.8","1.0057984","1"],["76326.7","0.00654732","1"],["76320.6","0.11367457","2"]]}
{"instId":"BTC-USDT","action":"update","ts":"1776816024060","asks":[["76357.2","0.02840905","1"],["76363.2","0","0"],["76363.3","0.00654732","1"],["76375.2","0.07967501","2"]],"bids":[["76340.3","0","0"],["76335.9","0.12379685","2"],["76328.7","0.4780604","2"],["76326.7","0","0"],["76177.8","0.00105547","4"],["76175.4","0.00003868","3"]]}
{"instId":"BTC-USDT","action":"update","ts":"1776816024070","asks":[["76424.8","0.01904496","3"]],"bids":[["76340.6","0.03517193","2"],["76310.4","0.11991465","1"],["76175.4","0","0"]]}
{"instId":"BTC-USDT","action":"update","ts":"1776816024080","asks":[["76363.3","0","0"],["76363.8","0.00654733","1"],["76375.2","0.00001501","1"],["76387.9","0.20144125","1"],["76466.6","0","0"]],"bids":[["76336","0.03791902","2"],["76328.9","0.00655767","2"],["76328.7","0.47151308","1"]]}
{"instId":"BTC-USDT","action":"update","ts":"1776816024090","asks":[["76362.8","0.18353473","2"]],"bids":[]}
{"instId":"BTC-USDT","action":"update","ts":"1776816024110","asks":[["76355.1","1.85960626","24"],["76362.8","0.1305","1"]],"bids":[["76320.6","0.11364593","1"],["76292.6","0","0"],["76175.4","0.00003868","3"]]}
{"instId":"BTC-USDT","action":"update","ts":"1776816024120","asks":[["76361.5","0.12097426","3"],["76362","0.10698081","1"],["76370.4","0.26517365","4"],["76376.3","0.12605041","4"],["76380.1","0.00004506","1"],["76432.2","0.00026516","2"],["76466.5","0","0"]],"bids":[["76342.1","0","0"],["76334.3","0.06550532","1"],["76307.3","0.24493811","1"],["76176.3","0.1305","1"],["76175.4","0","0"]]}
{"instId":"BTC-USDT","action":"update","ts":"1776816024130","asks":[["76376.3","0.12646038","6"],["76377.9","0.00022161","1"],["76378.8","0.00004136","1"],["76379.8","0","0"],["76380.1","0","0"],["76382.6","0.00004619","1"],["76466.2","0","0"]],"bids":[["76337","0.01230734","1"],["76277.1","0.42383243","1"],["76277","0.345672","1"],["76177.8","0","0"],["76176.3","0","0"]]}
{"instId":"BTC-USDT","action":"update","ts":"1776816024140","asks":[],"bids":[["76342.1","0.02619","1"],["76245.7","0.2047146","1"],["76178.9","0","0"],["76177.9","0","0"]]}
{"instId":"BTC-USDT","action":"update","ts":"1776816024150","asks":[["76428.4","0.00095181","2"]],"bids":[]}
{"instId":"BTC-USDT","action":"update","ts":"1776816024170","asks":[],"bids":[["76292.6","0.00323366","1"],["76179.3","0","0"]]}
{"instId":"BTC-USDT","action":"update","ts":"1776816024180","asks":[["76414.3","0","0"],["76466.2","0.00014238","2"]],"bids":[["76318.4","0.00002864","1"],["76179.9","0","0"]]}
{"instId":"BTC-USDT","action":"update","ts":"1776816024210","asks":[["76357.3","0.03615376","2"],["76376.3","0.12614868","5"],["76432.2","0.00007195","1"]],"bids":[]}
{"instId":"BTC-USDT","action":"update","ts":"1776816024220","asks":[["76376.3","0.12577988","4"],["76412.1","0.1","1"],["76466.2","0","0"]],"bids":[]}
{"instId":"BTC-USDT","action":"update","ts":"1776816024230","asks":[["76376.3","0.12555458","3"],["76377.9","0","0"],["76378.8","0","0"],["76466.2","0.00014238","2"],["76466.5","0.00028078","2"]],"bids":[]}
{"instId":"BTC-USDT","action":"update","ts":"1776816024300","asks":[],"bids":[["76333.2","0","0"],["76318.4","0","0"],["76179.9","0.47151308","1"],["76179.3","0.00040006","1"]]}
{"instId":"BTC-USDT","action":"update","ts":"1776816024310","asks":[["76361.4","0.32736942","1"],["76362.1","0","0"],["76363.3","0.00654736","1"],["76363.8","0","0"],["76376.3","0.12623508","5"],["76392.9","0.07642146","2"],["76400.7","0","0"],["76406.8","0","0"],["76466.6","0.00546094","15"],["76466.7","0.00025453","6"]],"bids":[["76328.9","0.00001034","1"],["76326.7","0.00654736","1"],["76179.3","0","0"]]}
{"instId":"BTC-USDT","action":"update","ts":"1776816024320","asks":[["76361.3","0.12651718","1"],["76376.3","0.12646038","6"],["76378.8","0.00004136","1"],["76466.6","0","0"],["76466.7","0","0"]],"bids":[]}
{"instId":"BTC-USDT","action":"update","ts":"1776816024330","asks":[["76361.4","0","0"],["76361.9","0.32736925","1"],["76376.3","0.12627571","5"],["76377.9","0.00003694","1"],["76466.5","0","0"]],"bids":[]}
{"instId":"BTC-USDT","action":"update","ts":"1776816024340","asks":[["76363.3","0","0"],["76363.8","0.00654736","1"]],"bids":[["76328.9","0.0065577","2"],["76326.7","0","0"],["76179.3","0.00040006","1"]]}
{"instId":"BTC-USDT","action":"update","ts":"1776816024350","asks":[],"bids":[["76318.4","0.00002864","1"],["76179.3","0","0"]]}
{"instId":"BTC-USDT","action":"update","ts":"1776816024410","asks":[["76361.2","0.32736881","1"],["76361.9","0","0"],["76370.4","0.15910419","3"]],"bids":[["76342.1","0","0"],["76340.6","0.00001035","1"],["76337","0","0"],["76332.1","0","0"],["76331.8","0","0"],["76179.3","0.00040006","1"],["76178.9","0.0008637","1"],["76177.9","0.00004571","1"],["76177.8","0.00105547","4"]]}
{"instId":"BTC-USDT","action":"update","ts":"1776816024420","asks":[["76361.1","0.16254629","1"],["76361.5","0.016159","2"],["76362","0","0"],["76362.8","0.23656946","2"],["76363.3","0.00654741","1"],["76363.8","0","0"],["76369.3","0.12257589","1"],["76369.4","0","0"],["76370.4","0.05303473","1"],["76380.5","0.1305","1"],["76401.3","0","0"],["76466.5","0.00028078","2"]],"bids":[["76340.6","0.03517193","2"],["76334.6","0.01230772","1"],["76334.4","0.0000168","1"],["76328.9","0.00001034","1"],["76326.7","0.00654741","1"],["76317.6","0","0"],["76313.3","0","0"],["76201.3","0.08378297","1"],["76177.8","0","0"]]}
{"instId":"BTC-USDT","action":"update","ts":"1776816024430","asks":[["76362.8","0.34263892","4"]],"bids":[["76334.4","0.05266237","2"]]}
{"instId":"BTC-USDT","action":"update","ts":"1776816024440","asks":[["76376.3","0.12646038","6"],["76400.5","0","0"],["76428.1","0.05973555","1"]],"bids":[["76333.6","0.01563222","1"],["76299.2","0.01985978","1"],["76208.6","0.01448037","1"],["76179.3","0","0"],["76178.9","0","0"],["76177.9","0","0"]]}
{"instId":"BTC-USDT","action":"update","ts":"1776816024450","asks":[["76355.1","1.86615328","25"],["76356.3","0","0"],["76361","0.3273714","1"],["76361.2","0","0"],["76370.4","0","0"],["76425.6","0.5880872","4"],["76466.6","0.00546094","15"],["76466.7","0.00025453","6"]],"bids":[["76335.9","0.11724988","1"],["76334.7","0.00656018","2"],["76330.3","0","0"],["76329.7","0.3273714","1"]]}
{"instId":"BTC-USDT","action":"update","ts":"1776816024460","asks":[["76357.2","0.12249438","2"],["76360.9","0.15721691","1"],["76361.3","0","0"],["76362.8","0.39567365","5"],["76390.6","0.35379393","2"],["76405.9","0","0"],["76440.5","0.00001071","1"],["76467.1","0.00181702","1"]],"bids":[["76334.6","0","0"],["76329.7","0","0"],["76329.1","0","0"],["76328.9","0.3273819","2"],["76328.8","0","0"],["76328.7","0","0"],["76301.2","0","0"],["76293.1","0.02414473","1"],["76184.3","1.00582738","1"],["76179.3","0.00040006","1"],["76178.9","0.0008637","1"],["76177.9","0.00004571","1"],["76177.8","0.00105547","4"]]}
{"instId":"BTC-USDT","action":"update","ts":"1776816024470","asks":[["76356.3","0.08378297","1"],["76372.4","0.01547354","1"],["76409.4","0.05276672","1"],["76438.4","0.79690339","5"],["76442.8","1.25771829","3"],["76445.3","0.0003737","5"],["76449.1","0","0"],["76466.7","0","0"],["76467.1","0","0"]],"bids":[["76334.3","0","0"],["76333.6","0","0"],["76330.4","0.01254583","6"],["76330.2","0.18403921","1"],["76329","1.00582738","1"],["76326.6","0.05920007","6"],["76305.7","0","0"],["76299.5","0","0"],["76299.2","0","0"],["76295.5","0","0"],["76293.2","0.659096","1"],["76289.7","0.1057362","1"],["76289.3","0.06188546","2"],["76289","0.660645","1"],["76208.6","0","0"],["76184.3","0","0"],["76175.4","0.00003868","3"],["76175.1","0.47151308","1"],["76175","0.00029601","2"],["76173.9","0.00399999","1"]]}
{"instId":"BTC-USDT","action":"update","ts":"1776816024480","asks":[["76355.1","1.85960626","24"],["76356.2","0.05678705","1"],["76356.4","0","0"],["76356.6","0.10217727","2"],["76363.3","0","0"],["76364.5","0.00654756","1"],["76446.5","0","0"],["76466.7","0.00025453","6"]],"bids":[["76336.1","0.00654727","1"],["76334.7","0.00001316","1"],["76334.4","0.03310903","2"],["76331.1","0.00219891","1"],["76329.7","0.00654756","1"],["76326.7","0","0"],["76318.4","0","0"],["76299.6","0","0"],["76292.6","0","0"],["76176.3","0.1305","1"]]}
{"instId":"BTC-USDT","action":"update","ts":"1776816024490","asks":[["76355.1","1.867973","25"],["76356.1","0.0065473","1"],["76356.6","0.09563","1"],["76358.9","0.32737893","1"],["76361","0","0"],["76363.3","0.00654754","1"],["76364.5","0","0"],["76437.4","0.34397909","3"],["76466.7","0","0"]],"bids":[["76337.4","0","0"],["76336.1","0.0065473","1"],["76331.7","0.00261902","1"],["76331.1","0","0"],["76330.2","0.46270408","2"],["76329.7","0","0"],["76328.9","0.00001034","1"],["76326.7","0.33392648","2"],["76322.1","0","0"],["76316.4","0.00523804","1"],["76249.1","0","0"],["76173.7","0.00070045","3"],["76173.6","0.00002308","1"]]}
{"instId":"BTC-USDT","action":"update","ts":"1776816024500","asks":[["76343","0.62377088","14"],["76343.8","0.00637275","2"],["76344.7","0.1867","2"],["76345.8","0.1867","2"],["76346.1","0.09527","1"],["76346.3","0.47151308","1"],["76347.3","0.00438","1"],["76347.5","0.1867","2"],["76347.6","0.1867","2"],["76348.7","0.1867","2"],["76349.6","0.28233","3"],["76350.1","0.61207505","2"],["76351.1","0.28750055","2"],["76351.2","0.32097234","4"],["76351.6","0.41928542","4"],["76353.2","0.50426563","4"],["76353.3","0.15250055","2"],["76353.4","0.09563","1"],["76353.9","0.1867","2"],["76354.3","0.16","1"],["76354.4","0.036","1"],["76355","0.907904","3"],["76355.1","0.58751191","6"],["76356.1","0","0"],["76356.2","0","0"],["76356.6","0","0"],["76356.7","0","0"],["76358.9","0","0"],["76360.8","0.13447309","2"],["76360.9","0","0"],["76361.1","0","0"],["76362.1","0.12531579","1"],["76362.8","0.1305","1"],["76363.3","0","0"],["76369.3","0","0"],["76384.9","0.05238684","1"],["76391.7","0.00001316","1"],["76392.9","0.0240386","1"],["76395.1","0.00001316","1"],["76397.2","0.15457671","1"],["76448.9","0.00004492","1"],["76452.3","0.00012963","1"],["76459","0","0"],["76464.1","0","0"],["76464.2","0","0"],["76464.4","0","0"],["76464.5","0","0"],["76464.6","0","0"],["76464.7","0","0"],["76465","0","0"],["76465.1","0","0"],["76465.4","0","0"],["76465.5","0","0"],["76465.7","0","0"],["76465.8","0","0"],["76466","0","0"],["76466.2","0","0"],["76466.5","0","0"],["76466.6","0","0"]],"bids":[["76355","0","0"],["76354.7","0","0"],["76354.4","0","0"],["76353.8","0","0"],["76353.3","0","0"],["76351.5","0","0"],["76351.3","0","0"],["76351.2","0","0"],["76350","0","0"],["76349.5","0","0"],["76348.8","0","0"],["76348.2","0","0"],["76347.6","0","0"],["76347.5","0","0"],["76346.2","0","0"],["76345.9","0","0"],["76345.7","0","0"],["76344.8","0","0"],["76344.7","0","0"],["76344.4","0","0"],["76343.7","0","0"],["76342.9","0.11727306","5"],["76341.1","0.1131","2"],["76340.5","0","0"],["76336.1","0","0"],["76331.8","0.00654729","1"],["76329","0","0"],["76328.5","0.06550532","1"],["76326.8","0.49469781","2"],["76326.7","0","0"],["76326.4","0","0"],["76324.5","0.00654754","1"],["76324.4","0","0"],["76322.6","0.32737844","1"],["76310.4","0","0"],["76304.3","0.00738407","1"],["76304","0.12526044","1"],["76283.6","0","0"],["76266.3","0.03980678","1"],["76184.3","1.00582738","1"],["76173.2","0.00001006","1"],["76173","0.00001059","1"],["76171.1","0.00001024","1"],["76170.8","0.00003094","3"],["76170.2","0.00001385","1"],["76168.9","0.000015","1"],["76168.4","0.00011049","4"],["76167","0.00001319","1"],["76166.6","0.00248493","6"],["76166.2","0.00026145","4"],["76165.9","0.47151308","1"],["76165.8","0.01614584","1"],["76165.2","0.00091086","3"],["76165.1","0.00001015","1"],["76164.3","0.00046091","2"],["76163.9","0.00005592","3"],["76162.2","0.00002057","1"],["76162.1","0.00004159","3"],["76162","0.00001017","1"],["76161.2","0.00007766","2"],["76161.1","0.0000827","1"],["76160.4","0.01614584","1"]]}
{"instId":"BTC-USDT","action":"update","ts":"1776816024510","asks":[["76343","0.66616098","18"],["76343.8","0","0"],["76344.6","0.1114599","1"],["76344.7","0","0"],["76345.8","0","0"],["76346.1","0","0"],["76348.6","0.00654729","1"],["76350.4","0.05896264","1"],["76351.1","0.12750055","1"],["76351.6","0.30299271","3"],["76352.4","0.00001501","1"],["76353.2","0.34426563","3"],["76354.3","0","0"],["76354.9","0.32737805","1"],["76355","0","0"],["76355.1","0.57539371","4"],["76356.2","0.00654753","1"],["76356.3","0","0"],["76357.2","0.02840905","1"],["76358.3","0.26517365","4"],["76359","0.00004629","1"],["76360","0.00001501","1"],["76360.8","0.12792555","1"],["76362.1","0","0"],["76391.6","0","0"],["76419.7","0.02690248","2"]],"bids":[["76342.9","0.21503086","5"],["76341.2","0.03392284","1"],["76340.6","0.00001035","1"],["76331.8","0","0"],["76330.2","0","0"],["76328.7","0.00654729","1"],["76326.8","0.0000168","1"],["76324.5","0","0"],["76324","0.32737805","1"],["76322.6","0","0"],["76320.8","0.00659383","2"],["76314.8","0.08378297","1"],["76312.3","0.20988299","3"],["76285.3","0.1076444","1"],["76275.8","0","0"],["76274.3","0.0001443","2"],["76267.2","0","0"],["76265.7","0.00054219","1"],["76168.6","0.1305","1"],["76161.1","0","0"],["76160.4","0","0"]]}
{"instId":"BTC-USDT","action":"update","ts":"1776816024520","asks":[["76344.6","0","0"],["76346.2","0.39547381","1"],["76351.1","0","0"],["76351.2","0.036","1"],["76351.6","0.1867","2"],["76353.2","0.1867","2"],["76353.3","0.036","1"],["76354.9","0","0"],["76355","0.32737782","1"],["76366.1","0.012","1"],["76369.4","0.12259532","1"],["76372.5","0.00093856","1"],["76444.2","0.01803197","2"],["76454","0.00129878","1"],["76462.4","0.00001191","1"],["76463.4","0","0"],["76463.9","0","0"]],"bids":[["76342.9","0.21623086","6"],["76330.2","0.1078265","1"],["76161.2","0","0"]]}
{"instId":"BTC-USDT","action":"update","ts":"1776816024530","asks":[["76343","0.61767911","16"],["76347.5","0","0"],["76347.6","0","0"],["76348.6","0","0"],["76349.5","0.0065473","1"],["76350","0.36180669","1"],["76354.3","0.23982465","1"],["76355","0","0"],["76357.2","0.45189687","3"],["76442.2","0.0838237","3"],["76463.4","0.00010604","1"]],"bids":[["76342.9","0.34373141","7"],["76340.2","0.02619","1"],["76329.7","0.0065473","1"],["76328.7","0","0"],["76324.7","0.3273786","1"],["76324.1","0.33367788","1"],["76324","0","0"],["76299.2","0.10231828","1"],["76292.6","0.00323375","1"],["76292.5","0.6531926","1"],["76163.9","0","0"],["76162.2","0","0"],["76162.1","0","0"],["76162","0","0"]]}
{"instId":"BTC-USDT","action":"update","ts":"1776816024540","asks":[["76346.2","0.28401391","1"],["76356.2","0","0"],["76358.2","0.00654759","1"]],"bids":[["76340.2","0","0"],["76324.8","0.48111933","2"],["76324.1","0","0"],["76322.9","0.00656439","2"],["76320.8","0.08382927","2"],["76312.3","0.26155956","4"],["76201.3","0","0"],["76163.9","0.00005592","3"],["76162.2","0.00002057","1"],["76162.1","0.00004159","3"]]}
{"instId":"BTC-USDT","action":"update","ts":"1776816024550","asks":[["76349.5","0","0"],["76350.3","0.00654745","1"],["76357.3","0.036","1"],["76416.5","0.0009368","1"],["76428.4","0.00001501","1"],["76463.4","0","0"]],"bids":[["76330.5","0.00654745","1"],["76329.7","0","0"],["76314.3","0.000015","1"],["76304.7","0.00001086","1"],["76301.8","0","0"],["76292.8","0.00325257","1"],["76289.8","0.00233646","1"],["76285.5","0.06929387","2"],["76162.1","0","0"]]}
{"instId":"BTC-USDT","action":"update","ts":"1776816024560","asks":[["76348.7","0.09143","1"],["76350.3","0","0"],["76351.1","0.00654763","1"],["76353.9","0.09143","1"],["76372.4","0","0"],["76373","0.07948","1"],["76391.4","0.10749017","1"]],"bids":[["76322.9","0.02232055","3"],["76319.1","0.0000168","1"],["76318.4","0.00002864","1"],["76311","0.14408665","1"],["76289.8","0.12493178","2"],["76285.3","0","0"],["76237.9","1.20718681","3"],["76162.2","0","0"]]}
{"instId":"BTC-USDT","action":"update","ts":"1776816024570","asks":[["76343","0.61758089","16"],["76348.7","0","0"],["76349.5","0.00654759","1"],["76349.6","0.18706","2"],["76351.1","0","0"],["76357.1","0.32738796","1"],["76357.2","0.12451827","2"],["76358.3","0.21213892","3"]],"bids":[["76330.5","0","0"],["76329.7","0.00654759","1"],["76324.7","0","0"],["76324","0.32738796","1"],["76322.9","0.00656439","2"],["76318","0","0"],["76312.3","0.20988299","3"],["76309.6","0.05239514","1"],["76285.5","0.04260956","1"],["76242.6","0.81483754","2"],["76214.3","0","0"],["76190.2","0.00010937","1"]]}
{"instId":"BTC-USDT","action":"update","ts":"1776816024580","asks":[["76346.2","0.19984595","1"],["76367.6","0.11472773","2"]],"bids":[["76237.9","0.42417808","3"]]}
{"instId":"BTC-USDT","action":"update","ts":"1776816024590","asks":[["76349.5","0","0"],["76349.6","0.09563","1"],["76351.1","0.00654737","1"],["76353.9","0","0"],["76357.1","0.327388","1"],["76358.2","0","0"],["76358.3","0.26517365","4"],["76360.7","0.00654764","1"],["76365","0.07234921","2"],["76373","0","0"],["76376.3","0.12545788","2"],["76378.2","0.00018116","3"],["76381.1","0.12790159","1"],["76463.4","0.00010604","1"]],"bids":[["76335.8","0","0"],["76331.3","0","0"],["76330.5","0.00654737","1"],["76329.7","0","0"],["76326.6","0.06225007","7"],["76324.9","0.327388","1"],["76324","0","0"],["76323.9","0.49420656","3"],["76322.9","0.0000168","1"],["76317.4","0.00306155","2"],["76302.2","0.1","1"],["76162.2","0.00002057","1"]]}
{"instId":"BTC-USDT","action":"update","ts":"1776816024600","asks":[["76343","0.61729274","16"],["76359","0","0"],["76376.3","0.12527321","1"],["76377.9","0","0"],["76378.8","0","0"],["76379.6","0","0"],["76382.6","0","0"],["76384.4","0.11992987","1"],["76463.9","0.00088649","6"],["76464.1","0.00006549","2"],["76464.2","0.0025747","2"],["76464.4","0.00019338","3"],["76464.5","0.02702693","2"]],"bids":[["76325","0.39893699","1"],["76324.8","0.11994243","1"],["76162.2","0","0"]]}
{"instId":"BTC-USDT","action":"update","ts":"1776816024610","asks":[["76343","0.58763216","15"],["76406.8","0.00003967","1"],["76418.3","0","0"]],"bids":[["76340.4","0.00004739","1"],["76292.6","0","0"],["76280.4","0.00323387","1"],["76163.9","0","0"]]}
{"instId":"BTC-USDT","action":"update","ts":"1776816024620","asks":[],"bids":[["76328.7","0.47151308","1"],["76312.3","0.26155956","4"],["76184.3","0","0"]]}
{"instId":"BTC-USDT","action":"update","ts":"1776816024630","asks":[["76355.1","0.57801435","5"],["76357.1","0","0"],["76358.2","0.3273868","1"]],"bids":[["76330.3","1.00582738","1"],["76330.2","0.23283339","2"],["76325.1","0.3273868","1"],["76324.9","0","0"],["76164.3","0","0"]]}
{"instId":"BTC-USDT","action":"update","ts":"1776816024640","asks":[["76354.3","0.16961879","1"]],"bids":[["76330.4","0.5594041","7"],["76330.2","0","0"],["76237.9","0.14664584","2"],["76211.3","0","0"],["76164.3","0.00046091","2"],["76163.9","0.00005592","3"]]}
{"instId":"BTC-USDT","action":"update","ts":"1776816024650","asks":[["76351.1","0","0"],["76353.1","0.0065474","1"]],"bids":[["76331.8","0.0065474","1"],["76330.5","0","0"]]}
{"instId":"BTC-USDT","action":"update","ts":"1776816024660","asks":[["76353.2","0.09143","1"]],"bids":[["76324.9","0.08378297","1"],["76163.9","0","0"]]}
{"instId":"BTC-USDT","action":"update","ts":"1776816024670","asks":[["76358.2","0","0"],["76358.3","0","0"],["76360.7","0.3339339","2"],["76361.5","0.00001316","1"],["76362.3","1.0057984","1"],["76371.9","0.0157593","1"],["76464.6","0.00012165","3"]],"bids":[["76342.9","0.38662087","8"],["76340.2","0.02619","1"],["76330.4","0.5470957","6"],["76326.7","0.32738626","1"],["76325.1","0","0"],["76321.8","0.05144618","3"],["76312.3","0.20988299","3"],["76289.7","0","0"]]}
{"instId":"BTC-USDT","action":"update","ts":"1776816024680","asks":[["76343","0.57434481","14"],["76345.9","0.01328684","1"],["76347.3","0","0"],["76373.6","0.21213892","3"],["76378.2","0.00011882","2"],["76381.1","0.12795589","2"],["76464.6","0","0"]],"bids":[["76342.9","0.39562929","11"],["76333","0.01230799","1"],["76327.6","0.05167657","1"],["76165.1","0","0"],["76164.3","0","0"]]}
{"instId":"BTC-USDT","action":"update","ts":"1776816024690","asks":[["76353.2","0","0"],["76371.9","0","0"],["76376.3","0.12542794","2"],["76378.2","0","0"],["76378.8","0.00006206","1"],["76464.6","0.00012165","3"],["76464.7","0.00497942","3"]],"bids":[["76305.5","0.12799212","2"],["76301.7","0.00004629","1"],["76296.4","0.13860798","1"],["76289.8","0.00233646","1"],["76165.2","0","0"]]}
{"instId":"BTC-USDT","action":"update","ts":"1776816024700","asks":[["76343","0.57418763","14"],["76359","0.00018516","1"],["76373.6","0.26517365","4"],["76376.3","0.12572343","3"],["76379.6","0.00005165","1"],["76382.6","0.00006929","1"],["76384.4","0.11995898","2"],["76401.3","0.11703726","1"],["76412.1","0","0"],["76464.5","0","0"],["76464.6","0","0"],["76464.7","0","0"]],"bids":[]}
{"instId":"BTC-USDT","action":"update","ts":"1776816024710","asks":[],"bids":[["76265.7","0.00054216","1"]]}
{"instId":"BTC-USDT","action":"update","ts":"1776816024720","asks":[],"bids":[["76318.4","0","0"],["76311.9","0.00002864","1"]]}
{"instId":"BTC-USDT","action":"update","ts":"1776816024730","asks":[],"bids":[["76311.9","0","0"],["76306.4","0.13052864","2"],["76165.2","0.00091086","3"]]}
{"instId":"BTC-USDT","action":"update","ts":"1776816024740","asks":[["76400","0.17344174","5"]],"bids":[]}
{"instId":"BTC-USDT","action":"update","ts":"1776816024750","asks":[["76355.1","0.58063499","6"],["76372.4","0.01535735","1"],["76372.5","0","0"],["76373.6","0","0"],["76464.5","0.02702693","2"]],"bids":[["76327.6","0","0"],["76321.8","0.03601033","2"],["76165.1","0.00001015","1"]]}
{"instId":"BTC-USDT","action":"update","ts":"1776816024760","asks":[["76358.3","0.26517365","4"],["76464.5","0","0"]],"bids":[]}
{"instId":"BTC-USDT","action":"update","ts":"1776816024770","asks":[["76357.2","0.21190572","1"]],"bids":[["76342.9","0.41487937","12"],["76333.8","0.01614584","1"],["76312.3","0.26155956","4"],["76303.8","0.47152988","2"],["76300","0.00359833","4"],["76296.2","1.47769196","3"],["76292.4","0.0000168","1"],["76288.6","0.0000168","1"],["76284.7","1.40807988","3"],["76280.9","0.0000168","1"],["76277.1","0.42384924","2"],["76273.3","0.33240385","2"],["76269.5","0.00001681","1"],["76166.2","0","0"],["76165.9","0","0"],["76165.8","0","0"],["76165.2","0","0"],["76165.1","0","0"]]}
{"instId":"BTC-USDT","action":"update","ts":"1776816024780","asks":[],"bids":[["76330.5","0.13061137","1"],["76296","0.00001154","1"],["76290.4","0.00001155","1"],["76284.8","0.69741437","2"],["76283","0.00001455","1"],["76279.2","0.00001155","1"],["76273.6","0.00001155","1"],["76269.8","0.00001456","1"],["76268","0.00001155","1"],["76171.1","0","0"],["76170.8","0","0"],["76170.2","0","0"],["76168.9","0","0"],["76168.6","0","0"],["76168.4","0","0"],["76167","0","0"],["76166.6","0","0"]]}
{"instId":"BTC-USDT","action":"update","ts":"1776816024800","asks":[["76384.4","0.11992987","1"]],"bids":[]}
{"instId":"BTC-USDT","action":"update","ts":"1776816024810","asks":[["76382.6","0","0"],["76464.5","0.02702693","2"]],"bids":[]}
{"instId":"BTC-USDT","action":"update","ts":"1776816024840","asks":[["76391.3","0.1082335","1"],["76406.8","0","0"]],"bids":[]}
{"instId":"BTC-USDT","action":"update","ts":"1776816024850","asks":[["76387.6","0.35750027","1"]],"bids":[["76323.6","0.01540537","2"]]}
{"instId":"BTC-USDT","action":"update","ts":"1776816024870","asks":[["76355.1","0.58325563","7"]],"bids":[]}
{"instId":"BTC-USDT","action":"update","ts":"1776816024890","asks":[["76358.2","0.32737482","1"],["76360.7","0.00654764","1"],["76464.5","0","0"]],"bids":[["76342.9","0.41226041","11"],["76340.2","0","0"],["76171.1","0.00001024","1"]]}
{"instId":"BTC-USDT","action":"update","ts":"1776816024900","asks":[["76368.1","0.00002911","1"],["76464.4","0","0"]],"bids":[]}
{"instId":"BTC-USDT","action":"update","ts":"1776816024910","asks":[["76373.7","0.00006929","1"],["76464.2","0","0"]],"bids":[]}
{"instId":"BTC-USDT","action":"update","ts":"1776816024930","asks":[["76406.8","0.00003967","1"],["76464.1","0","0"]],"bids":[]}
{"instId":"BTC-USDT","action":"update","ts":"1776816024940","asks":[["76351.4","0.00001316","1"],["76354.8","0.00001316","1"],["76463.4","0","0"],["76463.9","0","0"]],"bids":[["76342.9","0.39301033","10"]]}
{"instId":"BTC-USDT","action":"update","ts":"1776816024950","asks":[],"bids":[["76342.9","0.39599784","12"]]}
{"instId":"BTC-USDT","action":"update","ts":"1776816024960","asks":[],"bids":[["76342.9","0.39597167","11"]]}
{"instId":"BTC-USDT","action":"update","ts":"1776816024970","asks":[],"bids":[["76297.7","0.01938804","1"],["76207","0.01421012","1"],["76173","0","0"],["76171.1","0","0"]]}
{"instId":"BTC-USDT","action":"update","ts":"1776816024990","asks":[["76345.9","0","0"],["76463.4","0.00010604","1"]],"bids":[]}
{"instId":"BTC-USDT","action":"update","ts":"1776816025000","asks":[["76343.3","0.01328731","1"],["76346.3","0","0"]],"bids":[["76297.7","0","0"],["76207","0","0"],["76173","0.00001059","1"],["76171.1","0.00001024","1"]]}
{"instId":"BTC-USDT","action":"update","ts":"1776816025010","asks":[["76346.2","0.02854556","1"]],"bids":[["76342.9","0.39335273","10"],["76333","0","0"],["76330","0.01230846","1"]]}
{"instId":"BTC-USDT","action":"update","ts":"1776816025020","asks":[["76343","0.55738763","14"],["76350.3","0.00654746","1"],["76353.1","0","0"],["76357.1","0.32738325","1"],["76358.1","0.12064651","1"],["76358.2","0","0"],["76463.4","0","0"]],"bids":[["76339.8","0.02619","1"],["76331.8","0","0"],["76330.6","0.00656426","2"],["76326.7","0","0"],["76325.1","0.32738325","1"]]}
{"instId":"BTC-USDT","action":"update","ts":"1776816025030","asks":[["76343.3","0","0"],["76346.5","0.01328675","1"],["76350.3","0","0"],["76353.2","0.00654745","1"],["76354.3","0.28697536","2"],["76357.1","0","0"],["76360.7","0.33392755","2"],["76372.4","0","0"],["76463.4","0.00010604","1"],["76463.9","0.00088649","6"]],"bids":[["76342.9","0.41885289","12"],["76332.7","0.01230803","1"],["76331.8","0.00654745","1"],["76330.6","0.0000168","1"],["76330","0","0"],["76326.7","0.32737991","1"],["76325.1","0","0"],["76171.1","0","0"]]}
{"instId":"BTC-USDT","action":"update","ts":"1776816025040","asks":[["76343","0.52758763","13"],["76354.3","0.16961879","1"]],"bids":[["76342.9","0.42147183","13"],["76338.2","0.12529709","2"],["76296.4","0","0"],["76171.1","0.00001024","1"]]}
{"instId":"BTC-USDT","action":"update","ts":"1776816025050","asks":[["76350.1","0.47151308","1"]],"bids":[["76341.2","0.17481699","3"],["76332.7","0","0"],["76170.8","0.00003094","3"]]}
{"instId":"BTC-USDT","action":"update","ts":"1776816025060","asks":[["76350","0.26607733","1"],["76353.2","0","0"],["76354.2","0.00654738","1"],["76360.7","0.32737991","1"],["76362.1","0.00654732","1"],["76381.1","0.12790159","1"],["76463.9","0","0"]],"bids":[["76341.3","0.12121086","1"],["76341.2","0.1","1"],["76339.8","0.12619","2"],["76335.3","0.01230761","1"],["76334.2","0.00682788","10"],["76331.8","0","0"],["76326.8","0.32738456","2"],["76326.7","0","0"],["76325.1","0.00654732","1"],["76323.9","0.48765892","2"],["76170.8","0","0"]]}
{"instId":"BTC-USDT","action":"update","ts":"1776816025070","asks":[],"bids":[["76328.8","0.32736804","1"],["76326.8","0.0000168","1"],["76171.1","0","0"]]}
{"instId":"BTC-USDT","action":"update","ts":"1776816025080","asks":[],"bids":[["76324.8","0","0"],["76171.1","0.00001024","1"]]}
{"instId":"BTC-USDT","action":"update","ts":"1776816025090","asks":[["76343","0.52459248","12"]],"bids":[["76325","0.29305902","1"]]}
{"instId":"BTC-USDT","action":"update","ts":"1776816025100","asks":[],"bids":[["76296.4","0.12914438","1"],["76171.1","0","0"]]}
{"instId":"BTC-USDT","action":"update","ts":"1776816025110","asks":[],"bids":[["76280.4","0.00343162","2"],["76274.1","0","0"],["76265.7","0.00054219","1"],["76171.1","0.00001024","1"]]}
{"instId":"BTC-USDT","action":"update","ts":"1776816025140","asks":[],"bids":[["76328.8","0","0"],["76326.7","0.32737063","1"]]}
{"instId":"BTC-USDT","action":"update","ts":"1776816025150","asks":[["76343","0.58815248","13"],["76355.1","0.51799563","6"],["76381.1","0.12796675","2"]],"bids":[]}
{"instId":"BTC-USDT","action":"update","ts":"1776816025160","asks":[["76353.2","0.00654709","1"],["76354.2","0","0"]],"bids":[["76334.2","0.0002805","9"],["76331.8","0.00654709","1"],["76171.1","0","0"]]}
{"instId":"BTC-USDT","action":"update","ts":"1776816025170","asks":[],"bids":[["76306.4","0.1305","1"],["76280.4","0.00019775","1"]]}
{"instId":"BTC-USDT","action":"update","ts":"1776816025220","asks":[],"bids":[["76280.5","0.00323379","1"],["76173","0","0"]]}
{"instId":"BTC-USDT","action":"update","ts":"1776816025250","asks":[["76353.2","0","0"],["76354.2","0.00654721","1"]],"bids":[["76334.2","0.00682771","10"],["76331.8","0","0"],["76328.6","0.44991966","3"],["76326.7","0","0"],["76173","0.00001059","1"],["76171.1","0.00001024","1"]]}
{"instId":"BTC-USDT","action":"update","ts":"1776816025290","asks":[],"bids":[["76306.4","0.13052864","2"]]}
{"instId":"BTC-USDT","action":"update","ts":"1776816025300","asks":[["76343","0.58816248","14"]],"bids":[]}
{"instId":"BTC-USDT","action":"update","ts":"1776816025320","asks":[["76343","0.56543248","13"]],"bids":[["76328.6","0.44992275","3"]]}
{"instId":"BTC-USDT","action":"update","ts":"1776816025330","asks":[],"bids":[["76328.6","0.12255241","2"],["76326.7","0.32737035","1"],["76171.1","0","0"]]}
{"instId":"BTC-USDT","action":"update","ts":"1776816025370","asks":[["76343","0.56367727","13"],["76353.2","0.0065471","1"],["76354.2","0","0"]],"bids":[["76334.2","0.0002805","9"],["76331.8","0.0065471","1"],["76173","0","0"]]}
{"instId":"BTC-USDT","action":"update","ts":"1776816025380","asks":[["76358.3","0.10606946","2"]],"bids":[]}
{"instId":"BTC-USDT","action":"update","ts":"1776816025390","asks":[["76373.6","0.15910419","2"],["76463.4","0","0"]],"bids":[]}
{"instId":"BTC-USDT","action":"update","ts":"1776816025400","asks":[["76343","0.56107459","13"]],"bids":[["76340.9","0.03","2"],["76173.2","0","0"]]}
{"instId":"BTC-USDT","action":"update","ts":"1776816025410","asks":[["76358.3","0.05303473","1"],["76372.1","0.01546412","1"],["76463.3","0","0"]],"bids":[["76323.6","0.00001034","1"],["76312.3","0.15910419","2"]]}
{"instId":"BTC-USDT","action":"update","ts":"1776816025430","asks":[["76373.6","0.21213892","3"]],"bids":[["76327.6","0.10245537","2"],["76173.6","0","0"]]}
{"instId":"BTC-USDT","action":"update","ts":"1776816025480","asks":[["76373.6","0.10606946","2"]],"bids":[["76327.6","0.0507788","1"]]}
{"instId":"BTC-USDT","action":"update","ts":"1776816025500","asks":[["76343","0.5610484","13"],["76358.3","0.15910419","2"]],"bids":[["76297.4","0.0195863","1"],["76206.7","0.01452558","1"],["76173.9","0","0"],["76173.7","0","0"]]}
{"instId":"BTC-USDT","action":"update","ts":"1776816025510","asks":[],"bids":[["76312.3","0.21078076","3"]]}
{"instId":"BTC-USDT","action":"update","ts":"1776816025590","asks":[],"bids":[["76340.4","0.00006734","2"]]}
{"instId":"BTC-USDT","action":"update","ts":"1776816025610","asks":[["76343","0.56098291","13"]],"bids":[]}
{"instId":"BTC-USDT","action":"update","ts":"1776816025620","asks":[["76373.6","0.05303473","1"]],"bids":[]}
{"instId":"BTC-USDT","action":"update","ts":"1776816025630","asks":[["76358.3","0.21213892","3"]],"bids":[]}
{"instId":"BTC-USDT","action":"update","ts":"1776816025670","asks":[["76343","0.5608575","13"]],"bids":[["76327.7","0.32737056","1"],["76326.7","0","0"]]}
{"instId":"BTC-USDT","action":"update","ts":"1776816025690","asks":[["76349.9","0.16","1"],["76463.2","0","0"]],"bids":[]}
{"instId":"BTC-USDT","action":"update","ts":"1776816025720","asks":[["76350","0.29607733","2"],["76450","0.49655623","29"]],"bids":[]}
{"instId":"BTC-USDT","action":"update","ts":"1776816025750","asks":[["76358","0.32737119","1"],["76360.7","0","0"],["76373.6","0","0"],["76463.2","0.00059244","1"]],"bids":[["76342.9","0.41885289","12"],["76327.7","0","0"],["76327.6","0","0"],["76326.7","0.32737119","1"],["76173.9","0.00399999","1"]]}
{"instId":"BTC-USDT","action":"update","ts":"1776816025760","asks":[["76358","0","0"],["76360.7","0.32736703","1"]],"bids":[["76339.8","0.1","1"]]}
{"instId":"BTC-USDT","action":"update","ts":"1776816025770","asks":[["76358.3","0.26517365","4"]],"bids":[["76312.3","0.26155956","4"]]}
{"instId":"BTC-USDT","action":"update","ts":"1776816025810","asks":[],"bids":[["76265.7","0.00054218","1"]]}
{"instId":"BTC-USDT","action":"update","ts":"1776816025840","asks":[["76358.3","0.21213892","3"],["76359.9","0.03","2"],["76463.2","0","0"]],"bids":[["76312.3","0.20988299","3"]]}
{"instId":"BTC-USDT","action":"update","ts":"1776816025850","asks":[["76358.3","0.26517365","4"]],"bids":[["76339.8","0.12619","2"],["76312.3","0.26155956","4"]]}
{"instId":"BTC-USDT","action":"update","ts":"1776816025860","asks":[],"bids":[["76328.8","0.32737024","1"],["76326.7","0","0"]]}
{"instId":"BTC-USDT","action":"update","ts":"1776816025870","asks":[["76349.9","0","0"],["76353.2","0","0"],["76354.2","0.00654727","1"],["76463.2","0.00059244","1"]],"bids":[["76334.5","0.00654727","1"],["76331.8","0","0"]]}
{"instId":"BTC-USDT","action":"update","ts":"1776816025930","asks":[["76343","0.2804985","8"],["76346.2","0","0"],["76350","0.03","1"],["76350.1","0","0"],["76355.1","0.04648255","5"],["76362.3","0","0"],["76363.4","0","0"],["76369.6","0","0"],["76371.2","0","0"],["76374.3","0.01047472","4"],["76376.6","0","0"],["76377.8","0","0"],["76385.1","0","0"],["76463.3","0.08378297","1"],["76463.4","0.00010604","1"],["76463.9","0.00088649","6"],["76464.1","0.00006549","2"],["76464.2","0.0025747","2"],["76464.4","0.00019338","3"],["76464.5","0.02702693","2"],["76464.6","0.00012165","3"],["76464.7","0.00497942","3"]],"bids":[["76328.8","0","0"],["76328.5","0.08151741","2"],["76326.7","0.32737503","1"]]}
{"instId":"BTC-USDT","action":"update","ts":"1776816025940","asks":[["76343","0.06357","2"],["76346.5","0","0"],["76348.1","0.00001316","1"],["76349","0.00025286","1"],["76349.6","0","0"],["76350.4","0","0"],["76351.2","0","0"],["76353.3","0","0"],["76354.2","0","0"],["76354.3","0","0"],["76354.4","0","0"],["76355.1","0.01048255","4"],["76357.1","0.0065473","1"],["76357.9","0.05896264","1"],["76358.1","0.12065967","2"],["76358.3","0.15910419","3"],["76360.7","0","0"],["76362.1","0.79888813","2"],["76362.2","0","0"],["76362.8","0","0"],["76363.8","0.00654742","1"],["76366.2","0","0"],["76369.3","0.47151308","1"],["76369.5","0","0"],["76372.1","0","0"],["76372.7","0","0"],["76374","1.0059868","1"],["76376.2","0.47151308","1"],["76376.5","0","0"],["76384.7","1.0059868","1"],["76385","0.00001316","1"],["76406.8","0.1066623","2"],["76465","0.00044","2"],["76465.1","0.00002105","1"],["76465.4","0.00574024","1"],["76465.5","0.00119834","3"],["76465.7","0.00001316","1"],["76465.8","0.00071318","6"],["76466","0.0059052","2"]],"bids":[["76342.9","0.42147181","13"],["76341.3","0.22121086","2"],["76336.1","0.0065473","1"],["76335.3","0","0"],["76334.5","0","0"],["76330.6","0.32739185","2"],["76328.8","0.00654742","1"],["76326.7","0","0"],["76326.6","0.00328743","6"],["76325.1","0","0"],["76221","0","0"],["76173.7","0.00070045","3"],["76173.6","0.00002308","1"],["76173.2","0.00001006","1"]]}
{"instId":"BTC-USDT","action":"update","ts":"1776816025950","asks":[["76357.5","0.01328483","1"],["76360.8","0","0"],["76362","0.29330268","1"],["76362.1","0.47151308","1"],["76364.1","0.32735321","1"],["76365","0.03958653","1"],["76367","0.12357351","2"],["76371.1","0","0"],["76376.1","0.12259532","1"],["76381.1","0.00006516","1"],["76406.7","0.10521442","1"],["76406.8","0.00003967","1"],["76465.7","0","0"],["76465.8","0","0"],["76466","0","0"]],"bids":[["76342.9","0.43377821","14"],["76334.4","0.13129059","3"],["76333.1","0.05896264","1"],["76328.8","0.09033039","2"],["76318","0.05239514","1"],["76309.6","0","0"],["76173.2","0","0"]]}
{"instId":"BTC-USDT","action":"update","ts":"1776816025960","asks":[["76353.4","0","0"],["76357.2","0.12483613","1"],["76358.3","0.10606946","2"],["76363.8","0","0"],["76364.1","0","0"],["76364.5","0.32734672","1"],["76366.9","0.0065469","1"],["76373.6","0.10606946","1"],["76389.8","0.13325578","1"],["76406.7","0","0"]],"bids":[["76335.2","0.0026189","1"],["76334.5","0.47151308","1"],["76333.2","0.32734672","1"],["76331.7","0","0"],["76330.7","0.0065469","1"],["76330.6","0.0000168","1"],["76328.8","0.08378297","1"],["76313.7","0.11279029","1"],["76312.3","0.21078076","3"],["76311","0","0"],["76173.9","0","0"],["76173.7","0","0"],["76173.6","0","0"]]}
{"instId":"BTC-USDT","action":"update","ts":"1776816025970","asks":[["76357.1","0","0"],["76359.8","0.00654726","1"],["76364.1","0.32734672","1"],["76364.4","0.12259532","1"],["76364.5","0","0"],["76365","0.08430657","2"],["76376.3","0.00045022","2"],["76381.9","0.11726509","1"],["76391.3","0","0"],["76391.5","0","0"],["76397.1","0.15724183","1"],["76397.2","0","0"]],"bids":[["76338.3","0.00654726","1"],["76336.1","0","0"],["76336","0.17174076","3"],["76333.2","0","0"],["76330.6","0.32736352","2"],["76173.9","0.00399999","1"]]}
{"instId":"BTC-USDT","action":"update","ts":"1776816025980","asks":[["76364","0.11726509","1"],["76367.6","0.00001501","1"],["76369.2","0.18216482","1"],["76373.6","0.15910419","2"],["76391.4","0","0"],["76406.8","0.10448729","2"],["76465.5","0","0"]],"bids":[["76338.3","0.12914258","2"],["76335.9","0","0"],["76334.1","0","0"],["76327.6","0.0507788","1"],["76173.7","0.00070045","3"]]}
{"instId":"BTC-USDT","action":"update","ts":"1776816025990","asks":[["76365","0.03958653","1"],["76384.6","0.5441043","1"],["76465.4","0","0"]],"bids":[["76341.3","0.2708674","3"],["76242.6","0.0051445","1"]]}
{"instId":"BTC-USDT","action":"update","ts":"1776816026000","asks":[["76373.9","0.48082061","1"],["76465.1","0","0"]],"bids":[["76242.6","0.35250803","2"],["76176","0.00984862","1"],["76173.7","0","0"]]}
{"instId":"BTC-USDT","action":"update","ts":"1776816026010","asks":[["76349","0","0"],["76349.9","0.00025286","1"],["76358","0.00654697","1"],["76359.8","0","0"],["76363.9","0.34043608","2"],["76364.1","0","0"],["76365.7","0.00654693","1"],["76366.9","0","0"],["76377","0.04490851","1"]],"bids":[["76338.4","0.00654697","1"],["76338.3","0.12259532","1"],["76173.9","0","0"]]}
{"instId":"BTC-USDT","action":"update","ts":"1776816026020","asks":[["76357.9","0","0"],["76364.4","0","0"],["76465.1","0.00002105","1"],["76465.4","0.00574024","1"]],"bids":[["76338.2","0.0000168","1"]]}
{"instId":"BTC-USDT","action":"update","ts":"1776816026030","asks":[["76357.2","0.09335919","1"],["76364.1","0.05896264","1"],["76465.4","0","0"]],"bids":[["76312.3","0.1047113","2"],["76306.4","0.1305","1"],["76289.8","0","0"],["76289.7","0.00233636","1"],["76280.5","0","0"],["76271.8","0.01292","1"]]}
{"instId":"BTC-USDT","action":"update","ts":"1776816026040","asks":[["76392.7","0.07448323","1"],["76465.1","0","0"]],"bids":[["76338.4","0.12647718","2"],["76327.6","0.15684826","2"]]}
{"instId":"BTC-USDT","action":"update","ts":"1776816026050","asks":[["76343","0.00001","1"],["76354.2","0.01469056","1"],["76357.5","0","0"],["76400","0.07344174","4"],["76442.2","0.7763969","4"]],"bids":[["76338.5","0.00654681","1"],["76338.4","0.11993021","1"],["76302.2","0","0"]]}
{"instId":"BTC-USDT","action":"update","ts":"1776816026060","asks":[["76343","0","0"],["76348.1","0","0"],["76349.9","0.06309762","6"],["76351.6","0","0"],["76357.3","0","0"],["76358","0","0"],["76358.3","0","0"],["76359.8","0.0065468","1"],["76363.8","0.13059067","1"],["76363.9","0.01309","1"],["76364","0","0"],["76365.7","0","0"],["76366.9","0.33388785","2"],["76373.6","0","0"],["76406.7","0.00003967","1"],["76406.8","0.10444762","1"],["76425.8","0.00019321","1"],["76465.1","0.00002105","1"],["76465.4","0.00574024","1"],["76465.5","0.00119834","3"],["76465.7","0.00001316","1"]],"bids":[["76349.8","0.61144063","11"],["76348.1","0.50712611","5"],["76348","0.39973592","4"],["76343","0.08","1"],["76342.9","0.4014349","8"],["76338.5","0.1238119","2"],["76338.3","0","0"],["76334.6","0.32734106","1"],["76330.6","0.0000168","1"],["76327.6","0","0"],["76312.3","0","0"],["76296.4","0","0"],["76175","0","0"]]}
{"instId":"BTC-USDT","action":"update","ts":"1776816026070","asks":[["76357.2","0.04698588","1"],["76359.8","0","0"],["76361.9","0.00654678","1"],["76365.2","0.26517365","4"],["76366.1","0","0"],["76366.8","1.0059868","1"],["76366.9","0.32734106","1"],["76369.1","0.09032976","2"],["76375","0.01123792","1"],["76377.7","0.01546569","1"],["76406.7","0.13861316","2"],["76465.1","0","0"],["76465.4","0","0"],["76465.5","0","0"],["76465.7","0","0"]],"bids":[["76349.8","0.62778839","12"],["76348.2","0.27069832","1"],["76348.1","0.49018584","4"],["76348","0.39018584","3"],["76343","0","0"],["76342.9","0.37918081","6"],["76341","0.00654678","1"],["76339.8","0.02619","1"],["76338.5","0","0"],["76334.4","0.0000168","1"],["76333.2","0.00654679","1"],["76330.7","0","0"],["76328.5","0.06550532","1"],["76319.2","0.1554901","3"],["76301.3","0.02529544","1"],["76293.1","0","0"],["76175.1","0","0"]]}
{"instId":"BTC-USDT","action":"update","ts":"1776816026080","asks":[["76365","0.52168127","2"]],"bids":[["76349.8","0.72778839","13"],["76348.1","0.38509638","3"],["76348","0.28509638","2"],["76343","0.11319049","1"],["76341.3","0.22121086","2"],["76341.1","0.0131","1"],["76334.7","0.1225974","2"],["76175.4","0","0"]]}
{"instId":"BTC-USDT","action":"update","ts":"1776816026090","asks":[],"bids":[["76348.2","0.30005254","2"],["76341.4","0.11834562","3"],["76341.3","0.1","1"],["76341.2","0","0"],["76338.4","0","0"],["76280.5","0.00323373","1"],["76175.4","0.00003868","3"]]}
{"instId":"BTC-USDT","action":"update","ts":"1776816026100","asks":[["76367.8","0.07943","1"],["76465","0","0"]],"bids":[["76348.1","0.25759583","2"],["76348","0.25759583","2"],["76341.4","0.05269645","3"],["76341.3","0","0"],["76341.2","0.00654674","1"],["76341","0","0"],["76306.4","0.13052864","2"],["76175.1","0.47151308","1"]]}
{"instId":"BTC-USDT","action":"update","ts":"1776816026110","asks":[["76349.9","0.0620417","6"],["76361.9","0.00654672","1"],["76367.7","0.00654679","1"],["76367.8","0.15868","2"],["76369.1","0.08378297","1"],["76464.7","0","0"]],"bids":[["76341.4","0.02284644","3"],["76341.2","0","0"],["76340.4","0.00001995","1"],["76339.9","0.00659302","2"],["76333.2","0","0"],["76330.6","0.00656359","2"],["76175","0.00029601","2"],["76173.9","0.00399999","1"]]}
{"instId":"BTC-USDT","action":"update","ts":"1776816026120","asks":[["76367.7","0","0"],["76369","0.00654677","1"],["76416.5","0","0"],["76423.2","0.00151581","8"],["76464.7","0.00497942","3"]],"bids":[["76341","0.00654671","1"],["76339.9","0.00004629","1"],["76336","0.25393052","2"],["76333.3","0.00654677","1"],["76330.6","0.0000168","1"],["76319.2","0.26155956","4"],["76299.4","0.00325245","1"],["76296.8","0.00233635","1"],["76292.8","0","0"],["76289.7","0","0"],["76175","0","0"],["76173.9","0","0"]]}
{"instId":"BTC-USDT","action":"update","ts":"1776816026130","asks":[],"bids":[["76333.9","0.02439685","1"],["76175.1","0","0"]]}
{"instId":"BTC-USDT","action":"update","ts":"1776816026140","asks":[["76389.2","0","0"],["76397.7","0.00130893","1"]],"bids":[["76302","0.00131058","1"],["76293.5","0","0"]]}
{"instId":"BTC-USDT","action":"update","ts":"1776816026160","asks":[["76377.7","0","0"],["76465","0.00044","2"]],"bids":[]}
{"instId":"BTC-USDT","action":"update","ts":"1776816026170","asks":[["76349.9","0.06116418","6"],["76354.2","0","0"],["76406.7","0.13857349","1"],["76412.7","0.00003967","1"]],"bids":[["76348.1","0.1","1"],["76348","0.1","1"],["76287.4","0.0032337","1"],["76280.5","0","0"]]}
{"instId":"BTC-USDT","action":"update","ts":"1776816026180","asks":[["76351.9","0.01469099","1"],["76465","0","0"]],"bids":[["76348.2","0.1597","2"]]}
{"instId":"BTC-USDT","action":"update","ts":"1776816026200","asks":[["76349.9","0.02836893","4"],["76366.9","0","0"],["76367.7","0.32733518","1"]],"bids":[["76343.1","0.10634138","1"],["76340.4","0","0"],["76336.1","0.32733518","1"],["76334.6","0","0"],["76333.9","0.03094352","2"],["76333.3","0","0"],["76175.1","0.47151308","1"]]}
{"instId":"BTC-USDT","action":"update","ts":"1776816026210","asks":[["76349.9","0.05620431","4"],["76365.2","0.15910419","3"],["76367.6","0.32735007","2"],["76367.7","0","0"],["76465","0.00044","2"]],"bids":[["76347.3","0.00004665","1"],["76336.2","0.30038073","1"],["76336","0.00004629","1"],["76319.2","0.1554901","3"],["76175.4","0","0"],["76175.1","0","0"]]}
{"instId":"BTC-USDT","action":"update","ts":"1776816026220","asks":[["76365.2","0.10606946","2"],["76380.5","0.23656946","2"],["76392.9","0","0"],["76401","0.02540525","1"]],"bids":[["76334.5","0.57758254","2"],["76319.2","0.1047113","2"]]}
{"instId":"BTC-USDT","action":"update","ts":"1776816026230","asks":[["76349.9","0.12058431","5"],["76366.9","0.32733518","1"],["76367.6","0.00001501","1"],["76380.5","0.28960419","3"],["76465","0","0"]],"bids":[["76336.1","0","0"],["76334.8","0.32733518","1"],["76334.5","0.47151308","1"],["76319.2","0.1554901","3"]]}
{"instId":"BTC-USDT","action":"update","ts":"1776816026260","asks":[],"bids":[["76187.9","0.00001002","1"]]}
{"instId":"BTC-USDT","action":"update","ts":"1776816026270","asks":[["76349.9","0.12171621","6"]],"bids":[]}
{"instId":"BTC-USDT","action":"update","ts":"1776816026280","asks":[],"bids":[["76309.5","0.00002864","1"],["76306.4","0.1305","1"],["76176","0","0"]]}
{"instId":"BTC-USDT","action":"update","ts":"1776816026290","asks":[],"bids":[["76347.3","0.00005839","2"],["76313.2","0.00002864","1"],["76309.5","0","0"]]}
{"instId":"BTC-USDT","action":"update","ts":"1776816026300","asks":[["76349.9","0.12163764","6"],["76380.5","0.18353473","2"]],"bids":[["76319.2","0.26155956","4"]]}
{"instId":"BTC-USDT","action":"update","ts":"1776816026310","asks":[["76349.9","0.12157216","6"]],"bids":[]}
{"instId":"BTC-USDT","action":"update","ts":"1776816026320","asks":[["76365.2","0.21213892","3"]],"bids":[]}
{"instId":"BTC-USDT","action":"update","ts":"1776816026360","asks":[["76359","0.47169824","2"]],"bids":[]}
{"instId":"BTC-USDT","action":"update","ts":"1776816026370","asks":[["76357.2","0.17977126","2"],["76365.2","0","0"],["76465","0.00044","2"]],"bids":[["76339.2","0.00261988","1"],["76319.2","0.15910419","2"],["76176.3","0","0"]]}
{"instId":"BTC-USDT","action":"update","ts":"1776816026380","asks":[["76380.5","0.39567365","5"]],"bids":[["76334.5","0.57396845","3"]]}
{"instId":"BTC-USDT","action":"update","ts":"1776816026390","asks":[["76380.3","0.29713215","2"]],"bids":[]}
{"instId":"BTC-USDT","action":"update","ts":"1776816026400","asks":[],"bids":[["76347.3","0.00004665","1"]]}
{"instId":"BTC-USDT","action":"update","ts":"1776816026410","asks":[["76349.9","0.12158216","7"]],"bids":[]}
{"instId":"BTC-USDT","action":"update","ts":"1776816026420","asks":[["76349.9","0.11826408","6"],["76378.4","0.01547354","1"],["76380.5","0.28960419","3"],["76465","0","0"]],"bids":[["76336.3","0.32733607","1"],["76334.8","0","0"],["76334.5","0.52229188","2"],["76330.9","0.01575145","1"],["76177.8","0","0"]]}
{"instId":"BTC-USDT","action":"update","ts":"1776816026430","asks":[["76380.5","0.34263892","4"]],"bids":[["76336.4","0.29099602","1"],["76336.3","0","0"],["76336.2","0","0"],["76334.9","0.32733609","1"]]}
{"instId":"BTC-USDT","action":"update","ts":"1776816026450","asks":[],"bids":[["76333.9","0.02439685","1"],["76333.2","0.00654666","1"],["76177.9","0","0"]]}
{"instId":"BTC-USDT","action":"update","ts":"1776816026460","asks":[["76380.5","0.39567365","5"]],"bids":[["76334.5","0.57396845","3"]]}
{"instId":"BTC-USDT","action":"update","ts":"1776816026470","asks":[],"bids":[["76187.8","0.00303","1"],["76178.9","0","0"]]}
{"instId":"BTC-USDT","action":"update","ts":"1776816026480","asks":[["76380.5","0.28960419","3"]],"bids":[["76334.5","0.47151308","1"]]}
{"instId":"BTC-USDT","action":"update","ts":"1776816026490","asks":[["76365.2","0.05303473","1"],["76464.7","0","0"]],"bids":[["76348.3","0.08956393","1"],["76348.2","0.1","1"],["76319.2","0.20988299","3"],["76179.3","0","0"]]}
{"instId":"BTC-USDT","action":"update","ts":"1776816026510","asks":[["76349.9","0.11760921","6"],["76366.9","0","0"],["76367.7","0.32732877","1"]],"bids":[["76336.5","0.32732877","1"],["76334.9","0","0"],["76334.6","0.00654654","1"],["76333.2","0","0"]]}
{"instId":"BTC-USDT","action":"update","ts":"1776816026520","asks":[],"bids":[["76336.6","0.27780433","1"],["76336.4","0","0"],["76319.2","0.05303473","1"]]}
{"instId":"BTC-USDT","action":"update","ts":"1776816026530","asks":[],"bids":[["76339.2","0.00523976","2"],["76336.5","0","0"],["76334.8","0.32732866","1"],["76334.5","0.62836134","3"]]}
{"instId":"BTC-USDT","action":"update","ts":"1776816026540","asks":[["76365.2","0.10606946","2"]],"bids":[["76319.2","0.1047113","2"]]}
{"instId":"BTC-USDT","action":"update","ts":"1776816026550","asks":[],"bids":[["76330.9","0","0"],["76179.3","0.00040006","1"]]}
{"instId":"BTC-USDT","action":"update","ts":"1776816026570","asks":[["76349.9","0.11640921","5"]],"bids":[]}
{"instId":"BTC-USDT","action":"update","ts":"1776816026600","asks":[["76412.7","0","0"],["76464.7","0.00497942","3"]],"bids":[]}
{"instId":"BTC-USDT","action":"update","ts":"1776816026610","asks":[["76349.9","0.11638302","5"]],"bids":[]}
{"instId":"BTC-USDT","action":"update","ts":"1776816026630","asks":[],"bids":[["76334.5","0.52229188","2"]]}
{"instId":"BTC-USDT","action":"update","ts":"1776816026650","asks":[],"bids":[["76327.7","0.00305","1"],["76319.2","0.21078076","3"],["76317.4","0.00001155","1"],["76179.3","0","0"]]}
{"instId":"BTC-USDT","action":"update","ts":"1776816026660","asks":[],"bids":[["76313.2","0","0"],["76179.3","0.00040006","1"]]}
{"instId":"BTC-USDT","action":"update","ts":"1776816026670","asks":[["76412.7","0.00003967","1"],["76464.7","0","0"]],"bids":[["76332.2","0.00309629","2"],["76326.6","0.00023743","5"]]}
{"instId":"BTC-USDT","action":"update","ts":"1776816026680","asks":[["76358.9","0.16","1"],["76464.6","0","0"]],"bids":[]}
{"instId":"BTC-USDT","action":"update","ts":"1776816026700","asks":[],"bids":[["76339.2","0.00785964","3"]]}
{"instId":"BTC-USDT","action":"update","ts":"1776816026750","asks":[["76349.9","0.11758302","6"]],"bids":[]}
{"instId":"BTC-USDT","action":"update","ts":"1776816026770","asks":[["76380.5","0.1305","1"]],"bids":[["76334.5","0.47151308","1"]]}
{"instId":"BTC-USDT","action":"update","ts":"1776816026780","asks":[["76365.2","0.26517365","4"]],"bids":[["76319.2","0.26155956","4"]]}
{"instId":"BTC-USDT","action":"update","ts":"1776816026810","asks":[],"bids":[["76313.2","0.00002864","1"],["76179.3","0","0"]]}
{"instId":"BTC-USDT","action":"update","ts":"1776816026870","asks":[],"bids":[["76339.2","0.01047952","4"]]}
{"instId":"BTC-USDT","action":"update","ts":"1776816026910","asks":[["76366.7","0.3273364","1"],["76367.7","0","0"]],"bids":[["76334.6","0","0"],["76333.9","0.03094354","2"],["76179.3","0.00040006","1"]]}
{"instId":"BTC-USDT","action":"update","ts":"1776816026940","asks":[["76453.7","0.00001316","1"],["76464.5","0","0"]],"bids":[["76344.8","0.00001316","1"],["76179.3","0","0"]]}
{"instId":"BTC-USDT","action":"update","ts":"1776816026950","asks":[["76365.2","0.15910419","2"]],"bids":[["76342.9","0.26392789","5"],["76335.2","0.12996471","2"],["76311.5","0.11940351","2"],["76304","0","0"],["76297.4","0.14162603","2"],["76296.7","0","0"],["76179.3","0.00040006","1"],["76178.9","0.0008637","1"]]}
{"instId":"BTC-USDT","action":"update","ts":"1776816026960","asks":[],"bids":[["76343","0.07878749","1"]]}
{"instId":"BTC-USDT","action":"update","ts":"1776816026970","asks":[["76349.9","0.11730798","6"],["76380.5","0.23656946","3"]],"bids":[["76319.2","0.15910419","2"]]}
{"instId":"BTC-USDT","action":"update","ts":"1776816026980","asks":[["76365.2","0.05303473","1"],["76380.5","0.18353473","2"]],"bids":[["76319.2","0.21078076","3"]]}
{"instId":"BTC-USDT","action":"update","ts":"1776816026990","asks":[["76380.5","0.28960419","3"]],"bids":[["76319.2","0.26155956","4"]]}
{"instId":"BTC-USDT","action":"update","ts":"1776816027000","asks":[["76349.9","0.11712462","6"]],"bids":[]}
{"instId":"BTC-USDT","action":"update","ts":"1776816027010","asks":[["76349.9","0.11709843","6"]],"bids":[["76341.5","0.0065464","1"],["76341","0","0"],["76319.2","0.21078076","3"]]}
{"instId":"BTC-USDT","action":"update","ts":"1776816027020","asks":[],"bids":[["76319.2","0.15910419","2"]]}
{"instId":"BTC-USDT","action":"update","ts":"1776816027050","asks":[["76365.2","0.10606946","2"]],"bids":[["76334.5","0.52229188","2"]]}
{"instId":"BTC-USDT","action":"update","ts":"1776816027060","asks":[],"bids":[["76319.2","0.21078076","3"]]}
{"instId":"BTC-USDT","action":"update","ts":"1776816027110","asks":[["76349.9","0.11707224","6"]],"bids":[]}
{"instId":"BTC-USDT","action":"update","ts":"1776816027170","asks":[["76349.9","0.08607224","4"]],"bids":[["76335.2","0.12734581","1"],["76330.8","0.00261906","1"],["76178.9","0","0"]]}
{"instId":"BTC-USDT","action":"update","ts":"1776816027180","asks":[],"bids":[["76336.2","0.00261887","1"],["76330.8","0","0"]]}
{"instId":"BTC-USDT","action":"update","ts":"1776816027240","asks":[["76349.9","0.11707224","6"]],"bids":[]}
{"instId":"BTC-USDT","action":"update","ts":"1776816027250","asks":[],"bids":[["76334.5","0.47151308","1"]]}
{"instId":"BTC-USDT","action":"update","ts":"1776816027270","asks":[],"bids":[["76319.2","0.26155956","4"]]}
{"instId":"BTC-USDT","action":"update","ts":"1776816027290","asks":[["76365.2","0.05303473","1"]],"bids":[["76319.2","0.1047113","2"]]}
{"instId":"BTC-USDT","action":"update","ts":"1776816027310","asks":[],"bids":[["76334.5","0.62836134","3"],["76319.2","0.05303473","1"]]}
{"instId":"BTC-USDT","action":"update","ts":"1776816027320","asks":[],"bids":[["76334.5","0.68003791","4"]]}
{"instId":"BTC-USDT","action":"update","ts":"1776816027340","asks":[],"bids":[["76334.5","0.62836134","3"]]}
{"instId":"BTC-USDT","action":"update","ts":"1776816027380","asks":[["76365.2","0.10606946","2"]],"bids":[]}
{"instId":"BTC-USDT","action":"update","ts":"1776816027400","asks":[["76363.7","0.008","1"],["76464.4","0","0"]],"bids":[]}
{"instId":"BTC-USDT","action":"update","ts":"1776816027420","asks":[],"bids":[["76334.5","0.52229188","2"],["76319.2","0.1047113","2"]]}
{"instId":"BTC-USDT","action":"update","ts":"1776816027440","asks":[],"bids":[["76319.2","0.21078076","3"]]}
{"instId":"BTC-USDT","action":"update","ts":"1776816027450","asks":[["76349.9","0.11587224","5"]],"bids":[["76341.5","0","0"],["76341.2","0.0065464","1"]]}
{"instId":"BTC-USDT","action":"update","ts":"1776816027460","asks":[["76390.2","0","0"],["76464.4","0.00019338","3"]],"bids":[["76333.9","0.02439685","1"],["76333.2","0.0065466","1"],["76313.6","0","0"]]}
{"instId":"BTC-USDT","action":"update","ts":"1776816027470","asks":[["76349.9","0.08607224","4"],["76358.9","0","0"],["76359","0.00018516","1"],["76362.1","0","0"],["76362.6","0","0"],["76364.1","0","0"],["76364.6","0","0"],["76365.1","0","0"],["76365.2","0","0"],["76366.8","0","0"],["76374","0","0"],["76464.5","0.02702693","2"],["76464.6","0.00012165","3"],["76464.7","0.00497942","3"],["76465","0.00044","2"],["76465.1","0.00002105","1"],["76465.4","0.00574024","1"],["76465.5","0.00119834","3"],["76465.7","0.00001316","1"],["76465.8","0.00071318","6"]],"bids":[["76344.8","0.11431132","2"],["76319.2","0","0"],["76305.2","0.06545754","1"],["76297.4","0.0195863","1"],["76289.3","0.0015","1"]]}
{"instId":"BTC-USDT","action":"update","ts":"1776816027480","asks":[["76349.9","0.06439","2"],["76351.9","0","0"],["76357.2","0","0"],["76358.1","0.00001316","1"],["76359.9","0","0"],["76361.9","0","0"],["76362","0.07275749","1"],["76363.8","0","0"],["76365","0.03958653","1"],["76366.6","0.0065464","1"],["76366.7","0","0"],["76367","0.00630842","1"],["76369","0","0"],["76369.1","0","0"],["76369.4","0","0"],["76371.3","0","0"],["76372.8","0","0"],["76373.6","0.00654665","1"],["76373.7","0.11680295","2"],["76373.9","0","0"],["76376","1.33322902","2"],["76376.1","0","0"],["76377.2","0","0"],["76378.1","0.11727366","2"],["76378.4","0","0"],["76380.5","0.39567365","5"],["76382.8","0.0159323","2"],["76389.8","0","0"],["76390.6","0.29343","1"],["76391.7","0.12735897","2"],["76401","0","0"],["76407","0.53696797","2"],["76409.9","0.02847285","2"],["76416","0.10709677","1"],["76466","0.0059052","2"],["76466.2","0.00014238","2"],["76466.5","0.00028078","2"],["76466.6","0.00546094","15"],["76466.7","0.00025453","6"],["76467.1","0.00181702","1"],["76467.2","0.00011781","1"],["76467.3","0.00050101","1"],["76467.8","0.47151308","1"],["76467.9","0.00001035","1"],["76468","1.00618616","2"],["76468.2","0.00158724","2"],["76468.3","0.01147749","1"]],"bids":[["76349.8","0.98102845","16"],["76348.3","0.18956393","2"],["76344.9","0.15119872","2"],["76343.2","0.32733314","1"],["76343","0.01614584","1"],["76342.9","0.15162149","3"],["76342.1","0.1305","1"],["76341.2","0","0"],["76339.8","0","0"],["76338.2","0.00656345","2"],["76334.8","0","0"],["76334.5","0.68139607","4"],["76333.6","0.01577953","1"],["76333.2","0","0"],["76328.6","0.00001155","1"],["76320.9","0.11673366","1"],["76320.6","0","0"],["76311.2","0.00001316","1"],["76309.4","0.02619192","2"],["76308.1","0.00131047","1"],["76305.5","0.00004629","1"],["76301.3","0","0"],["76299.2","0","0"],["76297.1","0","0"],["76231","0","0"],["76178.9","0.0008637","1"],["76177.9","0.00004571","1"],["76177.8","0.00105547","4"]]}
{"instId":"BTC-USDT","action":"update","ts":"1776816027490","asks":[["76361.1","0.01468923","1"],["76362","0.03377617","1"],["76366.6","0","0"],["76368.9","0.00654618","1"],["76369","0.1105377","1"],["76373.6","0","0"],["76375.9","0.11673366","1"],["76376.9","0.00654639","1"],["76378.1","0.00054","1"],["76382.8","0.000015","1"],["76384.9","0","0"],["76389.9","0","0"],["76391.7","0.00001316","1"],["76392.8","0.08378297","1"],["76394","0.18289041","2"],["76395.3","0.1165","1"],["76401.9","0.00130886","1"],["76416","0","0"],["76468.2","0","0"],["76468.3","0","0"]],"bids":[["76348.4","0.00654618","1"],["76347.8","0.01198693","1"],["76345","0.12999885","1"],["76344.9","0.22929854","2"],["76342.9","0.03636857","2"],["76341.5","0.00654639","1"],["76340.2","0.05896264","1"],["76338.2","0.0000168","1"],["76335.2","0","0"],["76334.9","0.08378297","1"],["76334.7","0.00001316","1"],["76334.5","0.73307264","5"],["76333.6","0.03111647","2"],["76333.1","0","0"],["76330.6","0.12205653","2"],["76310.4","0.1167702","1"],["76179.9","0","0"],["76179.3","0","0"],["76178.9","0","0"],["76177.9","0","0"],["76177.8","0","0"]]}
{"instId":"BTC-USDT","action":"update","ts":"1776816027500","asks":[["76363.7","0","0"],["76368.9","0.00654584","1"],["76375","0","0"],["76375.8","0.32731245","1"],["76375.9","0.65544918","2"],["76376","1.00589588","1"],["76377","0","0"],["76391.6","0.12734581","1"],["76468.2","0.00158724","2"]],"bids":[["76348.4","0.10654584","2"],["76348","0","0"],["76346.2","0.05896264","1"],["76343.2","0.32731245","1"],["76340.2","0","0"],["76338.1","0.00330064","7"],["76333.9","0.04835076","2"],["76332.2","0.00004629","1"],["76331.4","0.12735897","2"],["76330.5","0","0"],["76323.6","0.05897298","2"],["76322.6","0.11673366","1"],["76310.4","0","0"],["76309.7","0.00131044","1"],["76304","0.12469277","1"],["76302","0","0"],["76285.4","0","0"],["76179.9","0.47151308","1"],["76179.3","0.00040006","1"]]}
{"instId":"BTC-USDT","action":"update","ts":"1776816027510","asks":[["76368.9","0","0"],["76369.1","0.00654585","1"],["76376.8","0.0065462","1"],["76376.9","0","0"],["76386","0.06459865","1"],["76391.5","0.12057216","1"],["76392.7","0","0"],["76468.2","0","0"]],"bids":[["76349.8","0.9875743","17"],["76348.5","0.1425463","1"],["76348.4","0.1","1"],["76348.3","0.1","1"],["76342.2","0.0065462","1"],["76341.5","0","0"],["76341.4","0.00002349","2"],["76326.7","0.00305","1"],["76316","0","0"],["76309.5","0.06469242","1"],["76304.1","0.12203973","1"],["76304","0","0"],["76285.5","0","0"],["76265.7","0.00054219","1"],["76179.3","0","0"]]}
{"instId":"BTC-USDT","action":"update","ts":"1776816027520","asks":[["76365.8","0.02649862","2"],["76368.9","0.00654598","1"],["76369.1","0","0"],["76376.8","0","0"],["76377","0.00654623","1"],["76391.4","0.12203973","1"],["76397.1","0","0"]],"bids":[["76349.8","0.98102845","16"],["76348.6","0.00654598","1"],["76342.3","0.00654623","1"],["76342.2","0","0"],["76341.2","0.01615906","1"],["76180","0","0"],["76179.9","0","0"]]}
{"instId":"BTC-USDT","action":"update","ts":"1776816027530","asks":[["76365.8","0.03649862","3"],["76368.9","0.00654555","1"],["76373","0.05896264","1"],["76377","0","0"],["76378","0.00654622","1"],["76468","0","0"]],"bids":[["76348.7","0.00654555","1"],["76348.6","0.1","1"],["76348.1","0","0"],["76343.2","0.32731389","1"],["76343.1","0","0"],["76336.2","0.11318904","2"],["76333.9","0.08239059","1"],["76304.2","0.1193867","1"],["76304.1","0","0"],["76180","0.0000812","1"]]}
{"instId":"BTC-USDT","action":"update","ts":"1776816027540","asks":[["76349.9","0.05614234","2"],["76364.9","0.1179058","2"],["76365","0.05509992","2"],["76368.9","0","0"],["76373.6","0.00654555","1"],["76375.8","0","0"],["76378","0","0"],["76379.9","0.00655714","2"],["76380.2","0.32731393","1"],["76387.9","0","0"],["76397.7","0","0"],["76409.5","0.00130873","1"],["76416","0.10905262","1"],["76418.4","0","0"],["76468","1.00618616","2"],["76468.2","0.00158724","2"]],"bids":[["76349.8","1.147574","18"],["76348.7","0.11614584","2"],["76348.2","0","0"],["76346.3","0.32731492","1"],["76345.1","0.00654629","1"],["76343.3","0.47151308","1"],["76343.2","0","0"],["76342.3","0","0"],["76337.6","0.47151308","1"],["76299.2","0.07347187","1"],["76181.6","0","0"],["76180","0","0"]]}
{"instId":"BTC-USDT","action":"update","ts":"1776816027550","asks":[["76363.9","0","0"],["76364.8","0.09535586","1"],["76365","0","0"],["76369","0.1236277","2"],["76384.2","0.01545784","1"],["76387.6","0","0"],["76413.1","0.19359075","1"]],"bids":[["76348.5","0.2425463","2"],["76348.3","0","0"],["76348.1","0.0131","1"],["76344.8","0.00001316","1"],["76341.1","0","0"],["76337.7","1.4242881","2"],["76336.6","0","0"],["76333.6","0.01577953","1"],["76330.7","0.30279","1"],["76323.8","0","0"],["76193.3","0","0"],["76181.6","0.00073364","2"],["76180","0.0000812","1"]]}
{"instId":"BTC-USDT","action":"update","ts":"1776816027560","asks":[["76352.4","0","0"],["76369","0.01309","1"],["76373.6","0.12327921","2"],["76377","0.32730427","1"],["76380.2","0","0"],["76413.1","0","0"],["76416","0","0"],["76468.3","0.01147749","1"],["76468.4","0.00002034","1"],["76468.5","0.00038944","1"]],"bids":[["76349.8","0.987574","17"],["76346.3","0","0"],["76345.1","0.32730427","1"],["76343.4","0.00654602","1"],["76337.8","0.22281552","1"],["76337.7","1.00589588","1"],["76325","0","0"],["76309.5","0","0"],["76242.6","0.0051445","1"],["76179.9","0.47151308","1"]]}
{"instId":"BTC-USDT","action":"update","ts":"1776816027570","asks":[["76364.7","0.11148482","1"],["76376.9","0.32730449","1"],["76377","0","0"],["76413.1","0.19646479","1"],["76446.5","0.51821089","1"],["76468.3","0","0"],["76468.4","0","0"],["76468.5","0","0"]],"bids":[["76348.8","0.14932225","1"],["76348.5","0.1","1"],["76345.2","0.32730449","1"],["76345.1","0","0"],["76179.9","0","0"]]}
{"instId":"BTC-USDT","action":"update","ts":"1776816027580","asks":[["76362","0.05644081","2"],["76365.8","0.5080117","4"],["76369.1","1.00589588","1"],["76378","0.00654596","1"],["76379.9","0.00001085","1"],["76413.1","0","0"],["76468.2","0","0"]],"bids":[["76345.6","0.02619","1"],["76345.3","0.39747051","1"],["76344.9","0","0"],["76300.4","0.10835641","1"],["76181.6","0","0"],["76180","0","0"]]}
{"instId":"BTC-USDT","action":"update","ts":"1776816027590","asks":[["76364.8","0.22391146","2"],["76375.9","0.53871552","1"],["76386","0","0"],["76413.1","0.19936872","1"]],"bids":[["76347.4","0.00004246","1"],["76337.8","0.48117023","2"],["76182.2","0","0"]]}
{"instId":"BTC-USDT","action":"update","ts":"1776816027600","asks":[["76369","0.4541005","2"],["76369.2","0","0"],["76375.8","0.32729996","1"],["76376.9","0","0"],["76413.1","0","0"],["76468.2","0.00158724","2"],["76468.3","0.01147749","1"]],"bids":[["76345.2","0","0"],["76343.4","0.33384598","2"],["76333.9","0.16384341","2"],["76250.1","0","0"],["76245.7","0","0"],["76182.2","0.00875","1"],["76181.6","0.00073364","2"],["76180","0.0000812","1"]]}
{"instId":"BTC-USDT","action":"update","ts":"1776816027610","asks":[["76413.1","0.19557276","1"],["76468.3","0","0"]],"bids":[["76343.4","0.32729996","1"],["76342.2","0.00654598","1"],["76324.7","0.17788291","1"],["76280.4","0.00032885","2"],["76274.3","0.00001319","1"],["76271.8","0.01346218","2"],["76265.7","0","0"],["76180","0","0"]]}
{"instId":"BTC-USDT","action":"update","ts":"1776816027620","asks":[["76413.1","0","0"],["76468.3","0.01147749","1"]],"bids":[["76334.5","0.68003791","4"]]}
{"instId":"BTC-USDT","action":"update","ts":"1776816027630","asks":[["76413.1","0.20021533","1"],["76468.3","0","0"]],"bids":[["76348.7","0.1","1"],["76319.2","0.05303473","1"],["76181.6","0","0"]]}
{"instId":"BTC-USDT","action":"update","ts":"1776816027640","asks":[["76413.1","0","0"],["76468.3","0.01147749","1"]],"bids":[]}
{"instId":"BTC-USDT","action":"update","ts":"1776816027650","asks":[["76412.7","0","0"],["76413.1","0.19759414","1"]],"bids":[]}
{"instId":"BTC-USDT","action":"update","ts":"1776816027660","asks":[["76369.2","0.00654558","1"],["76373.6","0.11673366","1"],["76413.1","0","0"]],"bids":[]}
{"instId":"BTC-USDT","action":"update","ts":"1776816027670","asks":[["76413.1","0.19159418","1"],["76468.3","0","0"]],"bids":[["76349.8","1.147574","18"],["76348.9","0.16","1"],["76182.2","0","0"]]}
{"instId":"BTC-USDT","action":"update","ts":"1776816027680","asks":[["76413.1","0","0"],["76468.3","0.01147749","1"]],"bids":[]}
{"instId":"BTC-USDT","action":"update","ts":"1776816027690","asks":[["76413.1","0.19764397","1"],["76468.3","0","0"]],"bids":[]}
{"instId":"BTC-USDT","action":"update","ts":"1776816027700","asks":[["76368.9","0.00654556","1"],["76369.2","0","0"],["76413.1","0","0"],["76468.3","0.01147749","1"]],"bids":[["76349.8","1.14102845","17"],["76349","0.00654556","1"],["76182.7","0","0"]]}
{"instId":"BTC-USDT","action":"update","ts":"1776816027710","asks":[["76413.1","0.19227971","1"],["76468.3","0","0"]],"bids":[]}
{"instId":"BTC-USDT","action":"update","ts":"1776816027720","asks":[["76377","0.00654604","1"],["76378","0","0"],["76413.1","0","0"],["76468.3","0.01147749","1"]],"bids":[["76342.2","0","0"],["76341.3","0.00654604","1"]]}
{"instId":"BTC-USDT","action":"update","ts":"1776816027730","asks":[["76413.1","0.19361442","1"],["76468.3","0","0"]],"bids":[]}
{"instId":"BTC-USDT","action":"update","ts":"1776816027740","asks":[["76413.1","0","0"],["76418.6","0.01979709","2"],["76468.3","0.01147749","1"]],"bids":[]}
{"instId":"BTC-USDT","action":"update","ts":"1776816027750","asks":[["76380.5","0.34263892","4"],["76413.1","0.19549844","1"],["76468.3","0","0"]],"bids":[]}
{"instId":"BTC-USDT","action":"update","ts":"1776816027760","asks":[["76365.2","0.05303473","1"],["76377","0.02644533","2"],["76468.2","0","0"]],"bids":[]}
{"instId":"BTC-USDT","action":"update","ts":"1776816027770","asks":[["76349.9","0.05465055","2"]],"bids":[["76334.5","0.62836134","3"]]}
{"instId":"BTC-USDT","action":"update","ts":"1776816027780","asks":[],"bids":[["76334.5","0.68003791","4"]]}
{"instId":"BTC-USDT","action":"update","ts":"1776816027790","asks":[["76412.7","0.00003967","1"],["76468","0","0"]],"bids":[["76349.8","0.98102845","16"],["76334.5","0.62836134","3"]]}
{"instId":"BTC-USDT","action":"update","ts":"1776816027800","asks":[["76349.9","0.05462436","2"],["76373.5","0.32730734","1"],["76375.7","0.00654611","1"],["76375.8","0","0"],["76377","0.01989929","1"],["76467.9","0","0"]],"bids":[["76343.4","0","0"],["76342.2","0.32730734","1"],["76341.3","0","0"],["76340.1","0.00654611","1"],["76319.2","0.1047113","2"]]}
{"instId":"BTC-USDT","action":"update","ts":"1776816027810","asks":[["76349.9","0.05428384","2"],["76373.4","0.11673366","1"],["76467.8","0","0"]],"bids":[["76319.2","0.05303473","1"]]}
{"instId":"BTC-USDT","action":"update","ts":"1776816027830","asks":[["76373.5","0","0"],["76375.8","0.32731016","1"]],"bids":[["76343","0.343456","2"],["76342.2","0","0"],["76182.7","0.00002401","2"]]}
{"instId":"BTC-USDT","action":"update","ts":"1776816027850","asks":[],"bids":[["76348.9","0","0"],["76334.5","0.68003791","4"],["76182.2","0.00875","1"]]}
{"instId":"BTC-USDT","action":"update","ts":"1776816027900","asks":[["76349.9","0.05362897","2"]],"bids":[]}
{"instId":"BTC-USDT","action":"update","ts":"1776816027910","asks":[["76349.9","0.05356349","2"],["76365.2","0","0"],["76467.8","0.47151308","1"]],"bids":[]}
{"instId":"BTC-USDT","action":"update","ts":"1776816027920","asks":[["76380.5","0.39567365","5"]],"bids":[["76343.3","0","0"],["76337.7","0","0"],["76193.3","1.00589588","1"],["76181.6","0.00073364","2"]]}
{"instId":"BTC-USDT","action":"update","ts":"1776816027930","asks":[["76349.9","0.05476349","3"],["76465.4","0","0"],["76467.9","0.00001035","1"]],"bids":[["76345.3","0.19114548","1"],["76287.4","0","0"],["76286.5","0.00323312","1"],["76253","0","0"],["76227.4","0","0"],["76180","0.0000812","1"],["76179.9","0.47151308","1"]]}
{"instId":"BTC-USDT","action":"update","ts":"1776816027940","asks":[["76448.9","0.00005808","2"]],"bids":[]}
{"instId":"BTC-USDT","action":"update","ts":"1776816027950","asks":[["76367.7","0.00654561","1"],["76368.9","0","0"]],"bids":[["76349","0","0"],["76347.9","0.00654561","1"]]}
{"instId":"BTC-USDT","action":"update","ts":"1776816027960","asks":[],"bids":[["76334.5","0.62836134","3"]]}
{"instId":"BTC-USDT","action":"update","ts":"1776816027970","asks":[["76372.9","0.32745066","2"],["76375.8","0","0"],["76468","1.00618616","2"]],"bids":[["76343","0.01614584","1"],["76342.2","0.32731949","1"],["76319.2","0.1047113","2"],["76179.9","0","0"]]}
{"instId":"BTC-USDT","action":"update","ts":"1776816027990","asks":[],"bids":[["76335.6","0.01547261","1"],["76280.3","0.00354807","5"],["76272.5","0.00006018","1"],["76181.6","0","0"],["76180","0","0"]]}
{"instId":"BTC-USDT","action":"update","ts":"1776816028000","asks":[["76349.9","0.05463252","3"],["76362.7","0.47151308","1"],["76468","0","0"]],"bids":[]}
{"instId":"BTC-USDT","action":"update","ts":"1776816028010","asks":[["76362","0.19428983","1"],["76375.6","0.00654638","1"],["76375.7","0","0"],["76375.9","0.62249849","2"]],"bids":[["76319.2","0.05303473","1"],["76280.4","0.00034084","3"],["76277.4","0","0"],["76181.6","0.00073364","2"]]}
{"instId":"BTC-USDT","action":"update","ts":"1776816028020","asks":[["76375.6","0","0"],["76375.8","0.00654638","1"],["76380.5","0.34263892","4"]],"bids":[["76342.2","0","0"],["76337.9","0.32732079","1"],["76334.5","0.68003791","4"],["76273.3","0.33917796","3"],["76247.6","0.00711281","1"],["76181.6","0","0"]]}
{"instId":"BTC-USDT","action":"update","ts":"1776816028030","asks":[["76361.4","0.16","1"],["76365.2","0.05303473","1"],["76366.9","0.00654567","1"],["76367.7","0","0"],["76373.5","0.00654638","1"],["76375.8","0","0"],["76467.8","0","0"],["76467.9","0","0"]],"bids":[["76347.9","0","0"],["76346.3","0.00654566","1"],["76345.3","0.0934434","1"],["76340.1","0","0"],["76338.2","0.00656318","2"],["76181.6","0.00073364","2"]]}
{"instId":"BTC-USDT","action":"update","ts":"1776816028040","asks":[["76365.7","0.00654568","1"],["76366.9","0","0"]],"bids":[["76334.5","0.62836134","3"],["76296.8","0","0"],["76296.7","0.00233598","1"],["76286.6","0.00323312","1"],["76286.5","0","0"]]}
{"instId":"BTC-USDT","action":"update","ts":"1776816028050","asks":[],"bids":[["76319.2","0.1047113","2"]]}
{"instId":"BTC-USDT","action":"update","ts":"1776816028070","asks":[],"bids":[["76346.3","0","0"],["76345.7","0.00654571","1"],["76335.6","0","0"],["76180","0.0000812","1"]]}
{"instId":"BTC-USDT","action":"update","ts":"1776816028080","asks":[["76372.9","0.33399706","3"],["76373.5","0","0"],["76467.8","0.47151308","1"]],"bids":[]}
{"instId":"BTC-USDT","action":"update","ts":"1776816028100","asks":[["76361.1","0","0"],["76364.6","0.00654575","1"],["76365.7","0","0"],["76372.8","0.0065464","1"],["76372.9","0.32745066","2"]],"bids":[["76347.8","0","0"],["76345.7","0","0"],["76345.4","0.00654575","1"],["76338.2","0.0000168","1"],["76337.7","0.0065464","1"]]}
{"instId":"BTC-USDT","action":"update","ts":"1776816028110","asks":[["76349.9","0.08443252","4"],["76357.1","0.01490971","1"],["76364.6","0.12858548","2"],["76406.8","0","0"]],"bids":[["76344.9","0.01515689","1"],["76180","0","0"]]}
{"instId":"BTC-USDT","action":"update","ts":"1776816028120","asks":[["76364.1","0.00654581","1"],["76364.6","0.12203973","1"],["76467.8","0","0"]],"bids":[["76349.8","0.86275298","15"],["76345.4","0","0"],["76343.1","0.00654581","1"],["76337.7","0","0"],["76336.3","0.00654643","1"]]}
{"instId":"BTC-USDT","action":"update","ts":"1776816028130","asks":[["76364.1","0","0"],["76365.1","0.00654589","1"]],"bids":[["76349.8","0.76275298","14"],["76345.7","0.00654589","1"],["76343.1","0","0"],["76338","0.12203973","1"],["76337.9","0.33386731","2"],["76336.3","0","0"],["76323.6","0.00001034","1"],["76285.4","0.05896264","1"],["76181.6","0","0"]]}
{"instId":"BTC-USDT","action":"update","ts":"1776816028140","asks":[["76364.8","0.23045736","3"],["76365.1","0","0"],["76467.8","0.47151308","1"]],"bids":[["76346.2","0","0"],["76345.7","0","0"],["76345.4","0.0065459","1"],["76340.2","0.05896264","1"],["76334","0.0157615","1"],["76182.2","0","0"]]}
{"instId":"BTC-USDT","action":"update","ts":"1776816028150","asks":[["76349.9","0.14693252","5"],["76360","0.10893014","2"],["76369.2","0.32732967","1"],["76372.9","0.00013117","1"],["76406.7","0","0"]],"bids":[["76341.2","0","0"],["76341","0.02984906","1"],["76338.1","0.33063031","8"],["76337.9","0.00654652","1"]]}
{"instId":"BTC-USDT","action":"update","ts":"1776816028160","asks":[["76349.9","0.30452835","6"],["76359.9","0.03251565","1"],["76364.1","0.00654592","1"],["76364.8","0.22391146","2"],["76369","0.78143049","3"],["76369.2","0","0"],["76406.8","0.10504173","1"],["76467.3","0","0"],["76467.8","0","0"]],"bids":[["76349.8","0.65050839","13"],["76345.4","0","0"],["76343.1","0.00654592","1"],["76337.9","0","0"],["76336.3","0.00654656","1"],["76296.4","0.12203973","1"],["76182.7","0","0"]]}
{"instId":"BTC-USDT","action":"update","ts":"1776816028170","asks":[["76354.8","0.01492332","2"],["76357.1","0","0"],["76359.9","0.16782057","2"],["76362.6","0.00654595","1"],["76364.1","0","0"],["76367.7","0.32733139","1"],["76369","0.4541005","2"],["76373.7","0.00006929","1"],["76381.9","0","0"],["76406.7","0.13048069","1"],["76406.8","0","0"],["76467.3","0.00050101","1"]],"bids":[["76344.9","0","0"],["76343.1","0","0"],["76342.2","0.00654595","1"],["76341.8","0.0151575","1"],["76338.1","0.00330064","7"],["76336.3","0.32733139","1"],["76335","0.00654667","1"],["76183.3","0","0"]]}
{"instId":"BTC-USDT","action":"update","ts":"1776816028180","asks":[["76359.8","0.07290417","1"],["76359.9","0.13530492","1"],["76367.7","0","0"],["76368.9","0.32733139","1"],["76406.9","0.77597148","3"],["76467.3","0","0"]],"bids":[["76336.4","0.32733679","1"],["76336.3","0","0"],["76309.1","0.1","1"],["76183.4","0","0"]]}
{"instId":"BTC-USDT","action":"update","ts":"1776816028190","asks":[["76349.9","0.3594289","7"],["76359.7","0.13265189","1"],["76360","0.00001501","1"],["76364.9","0.00001316","1"],["76367.7","0.3273367","1"],["76368.9","0","0"],["76373.3","0.10375372","1"],["76373.4","0","0"],["76380.5","0.28960419","3"],["76381.9","0.11673366","1"],["76406.6","0.12999885","1"],["76406.7","0","0"],["76467.1","0","0"],["76467.2","0","0"]],"bids":[["76336.4","0","0"],["76336.3","0.3273367","1"]]}
{"instId":"BTC-USDT","action":"update","ts":"1776816028200","asks":[["76349.9","0.44436844","9"],["76359.6","0.55150267","2"],["76359.8","0","0"],["76365.2","0.10606946","2"],["76367.6","0.32735166","2"],["76367.7","0","0"],["76467.1","0.00181702","1"]],"bids":[["76349.8","0.49291256","12"],["76348.7","0","0"],["76348.6","0","0"],["76348.5","0","0"],["76348.4","0","0"],["76343","0","0"],["76342.9","0.00036857","1"],["76342.1","0","0"],["76337.6","0","0"],["76334.5","0","0"],["76334","0","0"],["76330.8","0.47151308","1"],["76330.3","0","0"],["76328.7","0","0"],["76193.4","1.00592212","2"],["76193.3","0","0"],["76183.4","0.00005866","1"],["76183.3","0.00009283","1"],["76182.7","0.00002401","2"],["76182.2","0.00875","1"],["76181.6","0.00073364","2"],["76180","0.0000812","1"],["76179.9","0.47151308","1"],["76179.3","0.00040006","1"],["76178.9","0.0008637","1"],["76177.9","0.00004571","1"],["76177.8","0.00105547","4"]]}
{"instId":"BTC-USDT","action":"update","ts":"1776816028210","asks":[["76359.5","0.37195895","2"],["76359.6","0.47151308","1"],["76359.9","0","0"],["76362.6","0.00654604","1"],["76366.7","0.05896264","1"],["76367.6","0.00001501","1"],["76368.9","0.32733576","1"],["76373","0","0"],["76373.6","0","0"],["76375.8","0.1193867","1"],["76380.5","0.18353473","2"],["76384.2","0","0"],["76406.5","0.11083396","1"],["76406.6","0","0"]],"bids":[["76348.8","0","0"],["76345.3","0.04087758","1"],["76342.2","0","0"],["76341.9","0.00678352","6"],["76337.8","0","0"],["76336.3","0.32733576","1"],["76335.1","0.00654683","1"],["76335","0","0"],["76330.4","0.00023743","5"],["76319.2","0.26155956","4"],["76184.3","1.00589588","1"],["76176","0.00984862","1"],["76175.4","0.00003868","3"]]}
{"instId":"BTC-USDT","action":"update","ts":"1776816028220","asks":[["76354.8","0.00001316","1"],["76359.4","0.29137747","1"],["76359.5","0.12734581","1"],["76365.2","0.21213892","3"],["76467.1","0","0"]],"bids":[["76336.4","0.15848286","1"],["76334","0.47151308","1"],["76330.9","1.00589588","1"],["76326.7","0","0"],["76312.5","0.00315586","2"],["76184.3","0","0"],["76176.3","0.1305","1"],["76176","0","0"],["76175.4","0","0"]]}
{"instId":"BTC-USDT","action":"update","ts":"1776816028230","asks":[["76351","0.0149109","1"],["76359.3","0.12203973","1"],["76359.7","0","0"],["76361.9","0.00654604","1"],["76362.6","0","0"],["76367.7","0.32734603","1"],["76368.9","0","0"],["76369.2","0.00654686","1"],["76372.8","0","0"],["76406.4","0.11451407","1"],["76406.5","0","0"],["76466.7","0","0"]],"bids":[["76336.3","0","0"],["76335.1","0","0"],["76335","0.32734603","1"],["76334.3","0.00654686","1"],["76333.9","0.5944364","1"],["76323","0.00306155","2"],["76312.5","0.00010586","1"]]}
{"instId":"BTC-USDT","action":"update","ts":"1776816028240","asks":[["76359.4","0.17876386","1"],["76361.9","0","0"],["76362.6","0.006546","1"],["76367.7","0","0"],["76368.9","0.32734483","1"],["76369.2","0","0"],["76372.8","0.00654698","1"]],"bids":[["76336.5","0.32734483","1"],["76335","0","0"]]}
{"instId":"BTC-USDT","action":"update","ts":"1776816028250","asks":[["76361.3","0.00654599","1"],["76362.6","0","0"],["76367.7","0.32734507","1"],["76368.8","0.00654694","1"],["76368.9","0","0"],["76372.8","0","0"]],"bids":[["76341.9","0.00023748","5"],["76341.1","0.00654599","1"],["76336.6","0.15653134","1"],["76336.5","0","0"],["76336.4","0","0"],["76336.3","0.32734507","1"],["76334.3","0","0"],["76333.7","0.00654694","1"],["76176.3","0","0"]]}
{"instId":"BTC-USDT","action":"update","ts":"1776816028260","asks":[["76364.8","0.35092124","1"],["76367.6","0.32736382","2"],["76367.7","0","0"],["76466.7","0.00025453","6"]],"bids":[["76336.3","0","0"],["76335","0.32734507","1"]]}
{"instId":"BTC-USDT","action":"update","ts":"1776816028270","asks":[["76361.9","0.31699489","1"],["76362","0","0"]],"bids":[]}
{"instId":"BTC-USDT","action":"update","ts":"1776816028300","asks":[["76401.2","0.02618394","1"],["76409.9","0.0022919","1"],["76466.7","0","0"]],"bids":[["76349.8","0.4753648","10"],["76345.6","0","0"],["76176","0.00984862","1"]]}
{"instId":"BTC-USDT","action":"update","ts":"1776816028310","asks":[["76380.5","0.1305","1"]],"bids":[["76345.6","0.02619","1"],["76341.8","0","0"],["76176.3","0.1305","1"],["76176","0","0"]]}
{"instId":"BTC-USDT","action":"update","ts":"1776816028320","asks":[["76365.2","0.26517365","4"]],"bids":[["76338.3","0.01515819","1"],["76176.3","0","0"]]}
{"instId":"BTC-USDT","action":"update","ts":"1776816028340","asks":[["76366.6","0.00654708","1"],["76368.8","0","0"],["76368.9","0.08378297","1"],["76377.5","0.01603782","1"],["76466.5","0","0"],["76466.6","0","0"]],"bids":[["76349.8","0.4691648","9"],["76334.9","0","0"],["76333.7","0","0"],["76331.5","0.00654708","1"],["76176","0.00984862","1"]]}
{"instId":"BTC-USDT","action":"update","ts":"1776816028350","asks":[["76359.2","0.00654633","1"],["76361.3","0","0"],["76364.6","0.44939612","2"],["76367.6","0.00001501","1"]],"bids":[["76341.1","0","0"],["76339.3","0.00694639","2"],["76335","0","0"],["76331.5","0.45859624","3"],["76330.6","0.0000168","1"],["76296.7","0.12437571","2"],["76296.4","0","0"],["76288.9","0.345682","1"],["76275.7","0","0"],["76176.3","0.1305","1"],["76175.4","0.00003868","3"],["76175.1","0.47151308","1"]]}
{"instId":"BTC-USDT","action":"update","ts":"1776816028360","asks":[["76359.2","0.12327999","2"],["76359.5","0","0"],["76378.1","0.01060465","2"],["76406.3","0.11250851","1"],["76406.4","0","0"],["76466.5","0.00028078","2"]],"bids":[["76338.1","0.07354367","8"],["76336.6","0","0"],["76334","0.79886897","2"],["76331.5","0.13123985","2"],["76175","0.00029601","2"]]}
{"instId":"BTC-USDT","action":"update","ts":"1776816028370","asks":[],"bids":[["76334.1","0.98512409","1"],["76333.9","0","0"]]}
{"instId":"BTC-USDT","action":"update","ts":"1776816028380","asks":[],"bids":[["76334","0.47151308","1"],["76331.6","0.32735581","1"],["76175","0","0"]]}
{"instId":"BTC-USDT","action":"update","ts":"1776816028390","asks":[],"bids":[["76340.2","0","0"],["76334.2","0.12232023","10"],["76334.1","1.04408673","2"],["76331.4","0.00001316","1"],["76309.4","0.00001033","1"],["76301.7","0.02623053","2"],["76296.8","0.12203973","1"],["76296.7","0.00233598","1"]]}
{"instId":"BTC-USDT","action":"update","ts":"1776816028400","asks":[],"bids":[["76349.8","0.34166425","8"],["76341","0.01872751","1"]]}
{"instId":"BTC-USDT","action":"update","ts":"1776816028410","asks":[["76349.9","0.47185702","12"],["76354.8","0.11861015","2"],["76356.3","0.47151308","1"],["76359.1","0.00654647","1"],["76359.2","0.11673366","1"],["76361.8","1.00589588","1"],["76364.6","0.53317909","3"],["76365.3","0.1305","1"],["76406.3","0","0"],["76466","0","0"],["76466.2","0","0"],["76466.5","0","0"]],"bids":[["76349.8","0.14054872","3"],["76345.6","0","0"],["76339.3","0.00040006","1"],["76338.4","0.00654647","1"],["76338.3","0","0"],["76334","0","0"],["76330.9","0","0"],["76330.8","0","0"],["76328.8","0","0"],["76231","0.08378297","1"],["76184.3","1.00589588","1"],["76175","0.00029601","2"],["76173.7","0.00070045","3"],["76173.6","0.00002308","1"]]}
{"instId":"BTC-USDT","action":"update","ts":"1776816028420","asks":[["76355","0.1438757","1"],["76359","0.00673193","2"],["76359.1","0","0"],["76359.8","0.05896264","1"],["76361.7","0.32736384","1"],["76364.6","0.2058227","2"],["76366.7","0","0"],["76366.9","0.01614584","1"],["76383.2","0.01555978","1"],["76465.5","0","0"],["76465.7","0","0"],["76465.8","0","0"]],"bids":[["76349.8","0.11521","1"],["76345.3","0","0"],["76345","0","0"],["76338.4","0","0"],["76336.3","0.00654677","1"],["76336.2","0.00261887","1"],["76334.3","0.01515899","1"],["76334.1","0.29578874","2"],["76333.8","0","0"],["76333.6","0","0"],["76331.6","0","0"],["76330.8","0.32736384","1"],["76324.9","0","0"],["76309.7","0","0"],["76308.1","0","0"],["76301.8","0.00131058","1"],["76299.9","0.00154809","6"],["76293.3","0.12734581","1"],["76221","0.08378297","1"],["76173.2","0.00001006","1"],["76173","0.00001059","1"],["76171.1","0.00001024","1"]]}
{"instId":"BTC-USDT","action":"update","ts":"1776816028430","asks":[["76348.2","0.72905959","12"],["76349.8","0.18763954","2"],["76349.9","0.48298702","11"],["76359","0.00018516","1"],["76359.1","0.08378297","1"],["76359.7","0.00654693","1"],["76361.7","0.92847993","2"],["76361.9","0","0"],["76364.1","0.00654723","1"],["76365.2","0.21213892","3"],["76366.6","0","0"],["76372.2","0.01163443","1"],["76387.2","0.14407362","1"],["76393.2","0.02618665","1"],["76395.3","0","0"],["76401.2","0","0"],["76401.3","0","0"],["76446.5","0","0"],["76465","0","0"],["76465.1","0","0"]],"bids":[["76349.8","0","0"],["76341","0","0"],["76339.3","0.00694699","2"],["76338.1","0.04249268","8"],["76336.3","0","0"],["76334.3","0","0"],["76331.5","0","0"],["76327.8","0.00654745","1"],["76324.8","0.14326404","1"],["76319.2","0","0"],["76310.4","0.1193867","1"],["76301.7","0.00004629","1"],["76294","0.02623317","2"],["76293.3","0","0"],["76289.7","0.1074979","1"],["76211.3","0.08378297","1"],["76170.8","0.00003094","3"],["76170.2","0.00001385","1"]]}
{"instId":"BTC-USDT","action":"update","ts":"1776816028440","asks":[["76348.2","1.18275924","19"],["76349.8","0.15425915","1"],["76349.9","0.08943252","3"],["76351","0","0"],["76354.7","0.00654692","1"],["76354.9","0.08378297","1"],["76355.9","0.05303473","1"],["76359","0.32756049","2"],["76359.7","0","0"],["76361.3","0.00654765","1"],["76361.7","0.60111609","1"],["76364.1","0","0"],["76365.2","0","0"],["76385.2","0.05239041","1"],["76391.5","0.18604031","2"],["76394","0.1305","1"],["76407","0.47151308","1"],["76464.7","0","0"]],"bids":[["76341","0.01420297","1"],["76339.3","0.00040006","1"],["76334.1","0.2368261","1"],["76330.9","0.00654692","1"],["76330.8","0","0"],["76330.7","0.31794971","2"],["76328","0.05898613","3"],["76327.8","0.11673626","1"],["76327.7","0.12243936","2"],["76326.7","0.00654765","1"],["76324.9","0.32737533","1"],["76324.8","0","0"],["76320.9","0","0"],["76320.8","0.0000463","1"],["76317.5","0.54375956","5"],["76310.4","0","0"],["76304.7","0.12205331","2"],["76301.8","0","0"],["76300.4","0","0"],["76296.8","0","0"],["76296.4","0.13530794","1"],["76293.9","0.00131072","1"],["76293.4","0.12734865","1"],["76289.8","0.10478697","1"],["76289.7","0","0"],["76243.9","0.00001316","1"],["76170.2","0","0"]]}
{"instId":"BTC-USDT","action":"update","ts":"1776816028450","asks":[["76341","0.287699","3"],["76341.1","1.00513298","15"],["76341.3","0.1867","2"],["76341.5","0.00374496","1"],["76343.3","0.47151308","1"],["76343.6","0.0062","1"],["76346.4","0.47151308","1"],["76347.4","0.47273592","4"],["76347.5","0.83821937","8"],["76348.2","0.17908212","6"],["76349.7","0.08170089","1"],["76349.8","0","0"],["76352.3","0.05896264","1"],["76354.6","0.0065477","1"],["76354.7","0.32738473","1"],["76354.9","0","0"],["76355.9","0","0"],["76359","0.00018516","1"],["76359.3","0","0"],["76359.8","0","0"],["76361.3","0","0"],["76364.6","0.09687297","2"],["76364.7","0","0"],["76364.8","0","0"],["76369","0.4410105","1"],["76373.3","0","0"],["76377.5","0","0"],["76391.4","0","0"],["76391.6","0","0"],["76448.9","0.00004492","1"],["76453.7","0","0"],["76464.7","0.00497942","3"]],"bids":[["76348.1","0","0"],["76347.4","0","0"],["76347.3","0","0"],["76344.8","0","0"],["76342.9","0","0"],["76342","0","0"],["76341.9","0","0"],["76341.7","0","0"],["76341.4","0","0"],["76341","0","0"],["76339.5","0.0131","1"],["76338.1","0.04247952","7"],["76338","0","0"],["76336.2","0","0"],["76334.1","0.096885","1"],["76330.9","0","0"],["76330.7","0.01515971","1"],["76327.7","0.00305","1"],["76327.5","0.00261917","1"],["76326.8","0.00656373","2"],["76326.7","0","0"],["76324.9","0","0"],["76322.7","0.32738473","1"],["76322.3","0.30279","1"],["76319.4","0.0065477","1"],["76318","0","0"],["76317.5","0","0"],["76316.4","0","0"],["76314.8","0","0"],["76308.9","0.00523856","1"],["76307.9","0.05240473","2"],["76307.8","0.2822","1"],["76304.6","0","0"],["76304.2","0","0"],["76300.4","0.11674712","1"],["76299.9","0.00023748","5"],["76293.6","0.00785784","1"],["76292.7","0.47151308","1"],["76291.5","0.00132576","2"],["76278.4","0.01047712","1"],["76201.3","0.08378297","1"],["76170.2","0.00001385","1"],["76168.9","0.000015","1"],["76168.4","0.00011049","4"],["76167","0.00001319","1"],["76166.6","0.00248493","6"],["76166.2","0.00026145","4"],["76165.9","0.47151308","1"],["76165.8","0.01614584","1"],["76165.2","0.00091086","3"],["76165.1","0.00001015","1"]]}
{"instId":"BTC-USDT","action":"update","ts":"1776816028460","asks":[["76341","0.64991772","13"],["76341.1","0.32432881","5"],["76341.3","0","0"],["76341.5","0","0"],["76343.6","0","0"],["76346.3","0.59206974","2"],["76347.4","0.15759583","1"],["76347.5","0.08719583","2"],["76348.2","0.04636482","2"],["76349.7","0","0"],["76349.8","0.05325488","1"],["76352.2","0.32738794","1"],["76354.7","0","0"],["76359.1","0","0"],["76361.6","0.11674727","1"],["76367.8","0.07943","1"],["76368.8","0.11368636","1"],["76373.2","0.11674712","1"],["76375.8","0","0"],["76380.2","0.11940062","1"],["76384.4","0","0"],["76390.4","0.14329574","2"],["76391.5","0.06546815","1"],["76395.1","0.11090619","2"],["76465","0.00044","2"]],"bids":[["76340.9","0.1235","5"],["76338.1","0.00328748","6"],["76334.3","0.04106052","1"],["76334.1","0","0"],["76330.7","0","0"],["76330.2","0.12538632","1"],["76327.2","0.0151604","1"],["76326.8","0.0000168","1"],["76324.8","0.00654692","1"],["76322.7","0","0"],["76320.8","0.32743424","2"],["76318.2","0.11674712","1"],["76318.1","0","0"],["76314.7","0.31230933","2"],["76305.2","0","0"],["76289.9","0.0654707","1"],["76289.8","0","0"],["76289.7","0.11674727","1"],["76168.6","0.1305","1"],["76165.2","0","0"],["76165.1","0","0"]]}
{"instId":"BTC-USDT","action":"update","ts":"1776816028470","asks":[["76341.1","0.16673298","4"],["76343.2","0.14074665","1"],["76346.3","0.00654692","1"],["76347.4","0","0"],["76347.5","0.036","1"],["76348.2","0.036","1"]],"bids":[["76338.1","0.00023748","5"],["76325.3","0.00305","1"],["76323","0.00001155","1"],["76319.4","0","0"],["76318.2","0.12329488","2"],["76304.7","0.12510331","3"]]}
{"instId":"BTC-USDT","action":"update","ts":"1776816028480","asks":[["76346.3","0.16878557","2"],["76349.8","0.14417165","2"],["76352.4","0.00001501","1"],["76358.9","0.07932","1"],["76464.7","0","0"],["76465","0","0"]],"bids":[["76322.3","0.31851539","2"],["76313.2","0","0"],["76309.1","0","0"],["76165.2","0.00091086","3"],["76165.1","0.00001015","1"]]}
{"instId":"BTC-USDT","action":"update","ts":"1776816028490","asks":[["76341.1","0.05147295","3"],["76365.7","0.18207104","1"],["76391","0.00130905","1"],["76401.9","0","0"],["76422.3","0.0009368","1"],["76423.2","0.00057901","7"],["76464.5","0","0"],["76464.6","0","0"]],"bids":[["76299.4","0","0"],["76297.9","0.00325255","1"],["76296.7","0","0"],["76295.3","0.00233645","1"],["76225.9","0.14076811","1"],["76165.1","0","0"]]}
{"instId":"BTC-USDT","action":"update","ts":"1776816028500","asks":[["76350.5","0.00003308","1"],["76464.4","0","0"]],"bids":[["76323.9","0.01614584","1"]]}
{"instId":"BTC-USDT","action":"update","ts":"1776816028510","asks":[["76346.3","0.16223865","1"],["76347.4","0.00654761","1"],["76352.2","0","0"],["76354.7","0.32739413","1"],["76358.9","0.15854","2"],["76359.4","0.11687424","1"],["76416","0.0009368","1"],["76422.3","0","0"],["76425.8","0","0"]],"bids":[["76338.6","0.00004429","1"],["76327.3","0.00654761","1"],["76324.8","0","0"],["76324.7","0.03232492","1"],["76321.2","0.00857482","3"],["76297.9","0","0"],["76295.3","0","0"],["76290.3","0.0032526","1"],["76287.4","0.00233652","1"],["76280.4","0.00020974","2"],["76274.3","0.0001443","2"],["76271.8","0.01292","1"],["76265.7","0.00054217","1"],["76165.8","0","0"],["76165.2","0","0"]]}
{"instId":"BTC-USDT","action":"update","ts":"1776816028520","asks":[["76349.8","0.05325488","1"],["76354.6","0.28355567","2"],["76355","0","0"],["76356.4","0.26517365","4"]],"bids":[["76327.2","0","0"],["76321.2","0.0000254","2"],["76310.4","0.26155956","4"],["76298.6","0.06637434","1"],["76165.9","0","0"]]}
{"instId":"BTC-USDT","action":"update","ts":"1776816028530","asks":[["76351.4","0.10525675","2"],["76367.8","0","0"],["76464.4","0.00019338","3"]],"bids":[["76330.6","0.01517652","2"],["76324.7","0.503838","2"]]}
{"instId":"BTC-USDT","action":"update","ts":"1776816028540","asks":[["76349.8","0.07787592","2"],["76376.3","0.00167516","4"],["76389","0.00130908","1"],["76409.5","0","0"]],"bids":[["76340.9","0.14622","6"],["76324.8","0.12962251","1"],["76324.7","0.47151308","1"],["76298.6","0","0"],["76286.6","0","0"],["76285.5","0.00323359","1"],["76176","0","0"],["76165.9","0.47151308","1"]]}
{"instId":"BTC-USDT","action":"update","ts":"1776816028550","asks":[["76341","0.71424772","14"],["76346.2","0.00654758","1"],["76347.4","0","0"],["76349.9","0.0360268","3"],["76351.3","0.32739716","1"],["76354.7","0","0"],["76358.8","0.22297559","1"],["76359.2","0.12982366","2"],["76359.4","0","0"],["76364.6","0.08378297","1"],["76376.3","0.00163049","3"],["76379.6","0","0"],["76379.9","0","0"],["76380.1","0.29343","1"],["76390.6","0","0"],["76394.6","0.18783","1"],["76407.5","0","0"],["76464.5","0.00652512","1"],["76464.6","0.00012165","3"]],"bids":[["76339.5","0","0"],["76333.7","0.0131","1"],["76327.3","0","0"],["76325.4","0.00654758","1"],["76320.8","0.0000463","1"],["76318.3","0.3274075","2"],["76297.4","0","0"],["76206.7","0","0"],["76165.8","0.01614584","1"],["76165.2","0.00091086","3"]]}
{"instId":"BTC-USDT","action":"update","ts":"1776816028560","asks":[["76341","0.65174772","13"],["76349.8","0.15651461","1"],["76412.7","0","0"],["76442.2","0.0838237","3"],["76464.7","0.00497942","3"]],"bids":[["76313.2","0.00002864","1"],["76285.5","0","0"],["76278.5","0.47474677","2"]]}
{"instId":"BTC-USDT","action":"update","ts":"1776816028570","asks":[["76341","0.65161673","13"],["76362","0.012","1"],["76372.2","0","0"],["76381.7","0.11308582","2"],["76387.2","0","0"],["76465","0.00044","2"]],"bids":[["76307.4","0.1","1"],["76165.2","0","0"]]}
{"instId":"BTC-USDT","action":"update","ts":"1776816028580","asks":[["76346.2","0","0"],["76347.4","0.00654767","1"],["76351.3","0","0"],["76354.5","0.32739552","1"]],"bids":[["76320.8","0.32744182","2"],["76318.3","0.00001034","1"]]}
{"instId":"BTC-USDT","action":"update","ts":"1776816028590","asks":[["76349.8","0.06874284","1"]],"bids":[["76313.2","0","0"],["76278.5","0.47151308","1"],["76165.2","0.00091086","3"]]}
{"instId":"BTC-USDT","action":"update","ts":"1776816028600","asks":[["76341","0.62744584","12"],["76350.5","0","0"],["76465.1","0.00002105","1"]],"bids":[["76338.6","0.00007128","2"]]}
{"instId":"BTC-USDT","action":"update","ts":"1776816028610","asks":[["76341","0.62734368","12"],["76349.9","0.0360168","2"],["76354.6","0.27700797","1"],["76356.2","0.00654785","1"],["76450.2","0.00004711","4"],["76464.1","0.00005359","1"],["76465.1","0","0"]],"bids":[["76320.8","0.33398967","3"],["76318.2","0.11674712","1"]]}
{"instId":"BTC-USDT","action":"update","ts":"1776816028620","asks":[["76354.4","0.00654785","1"],["76356.2","0","0"]],"bids":[["76331","0.01583778","1"],["76320.8","0.32744182","2"],["76319.4","0.00654785","1"],["76165.8","0","0"],["76165.2","0","0"]]}
{"instId":"BTC-USDT","action":"update","ts":"1776816028630","asks":[["76406.8","0.00003978","1"],["76465","0","0"]],"bids":[]}
{"instId":"BTC-USDT","action":"update","ts":"1776816028640","asks":[["76341.1","0.01491282","1"],["76376.3","0.00180457","4"],["76379.9","0.0000217","1"],["76397.2","0.10430241","1"],["76464.6","0","0"],["76464.7","0","0"]],"bids":[["76340.9","0.37881001","8"],["76313.2","0.00002864","1"],["76278.5","0.47474681","2"],["76165.9","0","0"]]}
{"instId":"BTC-USDT","action":"update","ts":"1776816028650","asks":[["76347.4","0","0"],["76348.1","0.0065476","1"],["76354.4","0","0"],["76356.2","0.00654777","1"],["76376.3","0.002137","5"]],"bids":[["76328.6","0.00655915","2"],["76325.4","0","0"],["76320.9","0.00654777","1"],["76319.4","0","0"],["76165.9","0.47151308","1"]]}
{"instId":"BTC-USDT","action":"update","ts":"1776816028660","asks":[["76341","0.62779424","13"],["76348.1","0","0"],["76349.7","0.00654759","1"],["76361.4","0","0"],["76379.6","0.00006198","1"]],"bids":[["76331","0","0"],["76313.2","0","0"],["76311.4","0.00002864","1"],["76165.8","0.01614584","1"]]}
{"instId":"BTC-USDT","action":"update","ts":"1776816028670","asks":[],"bids":[["76311.4","0","0"],["76308","0.0000432","2"],["76307.4","0","0"],["76296.4","0.15468641","2"],["76205.7","0.01465373","2"],["76165.2","0.00091086","3"],["76165.1","0.00001015","1"]]}
{"instId":"BTC-USDT","action":"update","ts":"1776816028680","asks":[],"bids":[["76308","0.00001456","1"],["76304.4","0.00002864","1"],["76296.4","0.13530794","1"],["76205.7","0.00024241","1"],["76165.1","0","0"]]}
{"instId":"BTC-USDT","action":"update","ts":"1776816028690","asks":[["76341","0.62665424","13"]],"bids":[["76320.1","0","0"],["76165.1","0.00001015","1"]]}
{"instId":"BTC-USDT","action":"update","ts":"1776816028700","asks":[["76341","0.62658875","13"]],"bids":[]}
{"instId":"BTC-USDT","action":"update","ts":"1776816028710","asks":[["76341","0.62645776","13"]],"bids":[]}
{"instId":"BTC-USDT","action":"update","ts":"1776816028720","asks":[],"bids":[["76296","0.00002187","2"],["76289.8","0.00001033","1"],["76283.6","0.00001033","1"],["76283","0.0000254","2"],["76277.4","0.00001033","1"],["76271.2","0.00001033","1"],["76265.3","0.00001085","1"],["76265","0.00001033","1"],["76166.6","0","0"],["76166.2","0","0"],["76165.9","0","0"],["76165.8","0","0"],["76165.2","0","0"],["76165.1","0","0"]]}
{"instId":"BTC-USDT","action":"update","ts":"1776816028730","asks":[],"bids":[["76296","0.00003273","3"],["76290.1","0.00001086","1"],["76284.2","0.00001086","1"],["76278.3","0.00001086","1"],["76272.4","0.00001086","1"],["76266.5","0.00001086","1"],["76170.2","0","0"],["76168.9","0","0"],["76168.6","0","0"],["76168.4","0","0"],["76167","0","0"]]}
{"instId":"BTC-USDT","action":"update","ts":"1776816028740","asks":[["76356.2","0","0"],["76358.7","0.00654773","1"],["76379.9","0","0"],["76464.6","0.00012165","3"]],"bids":[["76321.9","0.13706274","3"],["76320.9","0","0"],["76170.2","0.00001385","1"]]}
{"instId":"BTC-USDT","action":"update","ts":"1776816028750","asks":[["76356.3","0.47806079","2"],["76358.7","0","0"],["76371.1","0.01589024","1"]],"bids":[["76322.3","0.30279","1"]]}
{"instId":"BTC-USDT","action":"update","ts":"1776816028760","asks":[["76356.3","0.47151308","1"],["76358.7","0.00654771","1"],["76464.6","0","0"]],"bids":[["76300.2","0.29319633","2"]]}
{"instId":"BTC-USDT","action":"update","ts":"1776816028800","asks":[],"bids":[["76338.6","0.00004429","1"]]}
{"instId":"BTC-USDT","action":"update","ts":"1776816028810","asks":[["76341","0.62632677","13"]],"bids":[]}
{"instId":"BTC-USDT","action":"update","ts":"1776816028840","asks":[["76354.5","0","0"],["76356.2","0.32738656","1"],["76365.9","0.0000217","1"],["76464.5","0","0"]],"bids":[["76322.7","0.32738656","1"],["76320.8","0.0000463","1"],["76170.2","0","0"]]}
{"instId":"BTC-USDT","action":"update","ts":"1776816028870","asks":[["76432.8","0.12002941","2"]],"bids":[]}
{"instId":"BTC-USDT","action":"update","ts":"1776816028900","asks":[],"bids":[["76340.9","0.37884276","9"],["76338.6","0.00007227","2"],["76310.3","0.47187355","2"]]}
{"instId":"BTC-USDT","action":"update","ts":"1776816028950","asks":[["76341","0.51111677","12"],["76445.3","0.00038686","6"]],"bids":[]}
{"instId":"BTC-USDT","action":"update","ts":"1776816028970","asks":[["76388.2","0.06325159","1"],["76454.1","0.00005044","1"],["76464.4","0","0"]],"bids":[["76311.8","0.06495699","2"]]}
{"instId":"BTC-USDT","action":"update","ts":"1776816028980","asks":[["76357.8","0.03","2"],["76365.8","0.4780117","2"],["76464.2","0","0"]],"bids":[["76340.9","0.34884276","7"],["76338.8","0.03","2"],["76170.8","0","0"]]}
{"instId":"BTC-USDT","action":"update","ts":"1776816028990","asks":[],"bids":[["76333","0.01515924","1"],["76330.6","0.0000168","1"],["76294.9","0.0191457","1"],["76204.3","0.01463295","1"],["76173.2","0","0"],["76173","0","0"],["76171.1","0","0"]]}
{"instId":"BTC-USDT","action":"update","ts":"1776816029010","asks":[],"bids":[["76274.3","0.00001319","1"],["76271.2","0.00014144","2"],["76265.7","0","0"],["76262.7","0.00054218","1"]]}
{"instId":"BTC-USDT","action":"update","ts":"1776816029070","asks":[["76352.3","0","0"],["76356.4","0.15910419","3"],["76464.2","0.0025747","2"]],"bids":[["76328.1","1.00601315","1"],["76201.3","0","0"],["76184.3","0","0"],["76173.2","0.00001006","1"]]}
{"instId":"BTC-USDT","action":"update","ts":"1776816029080","asks":[["76341.1","0","0"],["76343.2","0","0"],["76349.8","0.05112964","1"],["76356.4","0.26517365","4"],["76464.4","0.00019338","3"],["76464.5","0.00652512","1"]],"bids":[["76340.9","0.41129284","8"],["76336","0.10415027","2"],["76330.2","0.40965105","2"],["76320.8","0.08382927","2"]]}
{"instId":"BTC-USDT","action":"update","ts":"1776816029090","asks":[["76346.6","0.01491176","1"],["76349.7","0","0"],["76351.3","0.00654749","1"],["76371.1","0","0"]],"bids":[["76337.7","0.02619","1"],["76336.1","0.0310978","1"],["76330.3","0.00654749","1"],["76328.6","0.00001155","1"],["76323.3","0.01574737","1"],["76175","0","0"],["76173.7","0","0"],["76173.6","0","0"],["76173.2","0","0"]]}
{"instId":"BTC-USDT","action":"update","ts":"1776816029100","asks":[["76341","0.51098578","12"]],"bids":[["76310.4","0.82911832","5"],["76310.2","0","0"],["76175","0.00029601","2"]]}
{"instId":"BTC-USDT","action":"update","ts":"1776816029110","asks":[],"bids":[["76340.9","0.41391185","9"],["76336.1","0.13561025","2"],["76289.7","0","0"],["76285.5","0.04260956","1"]]}
{"instId":"BTC-USDT","action":"update","ts":"1776816029120","asks":[],"bids":[["76336.2","0.06229476","1"],["76336.1","0.10451245","1"],["76175","0","0"]]}
{"instId":"BTC-USDT","action":"update","ts":"1776816029130","asks":[],"bids":[["76334.2","0.0002805","9"],["76250.1","0.25979326","1"],["76175.1","0","0"]]}
{"instId":"BTC-USDT","action":"update","ts":"1776816029140","asks":[["76341","0.50599578","11"]],"bids":[["76334.3","0","0"],["76175.1","0.47151308","1"]]}
{"instId":"BTC-USDT","action":"update","ts":"1776816029160","asks":[],"bids":[["76304.4","0","0"],["76175","0.00029601","2"]]}
{"instId":"BTC-USDT","action":"update","ts":"1776816029170","asks":[],"bids":[["76340.9","0.41129284","8"]]}
{"instId":"BTC-USDT","action":"update","ts":"1776816029180","asks":[["76406.9","0.67597148","2"]],"bids":[]}
{"instId":"BTC-USDT","action":"update","ts":"1776816029190","asks":[["76372.7","0.01600956","1"],["76464.5","0","0"]],"bids":[]}
{"instId":"BTC-USDT","action":"update","ts":"1776816029210","asks":[["76355.3","0.05896264","1"],["76464.4","0","0"]],"bids":[]}
{"instId":"BTC-USDT","action":"update","ts":"1776816029270","asks":[["76405.2","0.10001316","2"]],"bids":[]}
{"instId":"BTC-USDT","action":"update","ts":"1776816029300","asks":[],"bids":[["76304.4","0.00002864","1"],["76175","0","0"]]}
{"instId":"BTC-USDT","action":"update","ts":"1776816029370","asks":[["76341","0.50485617","11"],["76356.4","0.15910419","3"]],"bids":[]}
{"instId":"BTC-USDT","action":"update","ts":"1776816029380","asks":[["76378.1","0.00054","1"]],"bids":[]}
{"instId":"BTC-USDT","action":"update","ts":"1776816029390","asks":[["76405.1","0.00003978","1"],["76406.8","0","0"]],"bids":[]}
{"instId":"BTC-USDT","action":"update","ts":"1776816029400","asks":[["76341","0.49155112","11"],["76371.7","0.10606946","1"],["76464.2","0","0"]],"bids":[]}
{"instId":"BTC-USDT","action":"update","ts":"1776816029410","asks":[["76341","0.49090928","11"],["76356.4","0.10606946","2"]],"bids":[]}
{"instId":"BTC-USDT","action":"update","ts":"1776816029430","asks":[["76371.7","0.15910419","2"]],"bids":[]}
{"instId":"BTC-USDT","action":"update","ts":"1776816029440","asks":[["76348.1","0.00001316","1"],["76356.4","0.05303473","1"],["76464.1","0","0"]],"bids":[]}
{"instId":"BTC-USDT","action":"update","ts":"1776816029450","asks":[["76371.7","0.21213892","3"]],"bids":[]}
{"instId":"BTC-USDT","action":"update","ts":"1776816029470","asks":[["76405.2","0.00001316","1"]],"bids":[["76310.4","0.72304886","4"]]}
{"instId":"BTC-USDT","action":"update","ts":"1776816029480","asks":[],"bids":[["76336.3","0.10918434","1"],["76310.4","0.82911832","5"],["76175.1","0","0"]]}
{"instId":"BTC-USDT","action":"update","ts":"1776816029490","asks":[["76343.2","0.14074665","1"],["76356.4","0","0"],["76371.7","0.10606946","1"]],"bids":[["76340.9","0.41749284","9"],["76336.4","0.09488629","1"],["76336.2","0","0"],["76310.4","0.56755876","1"]]}
{"instId":"BTC-USDT","action":"update","ts":"1776816029500","asks":[["76341","0.49077829","11"],["76371.6","0.05304789","2"],["76371.7","0.15910419","2"]],"bids":[["76340.9","0.42011181","10"],["76336","0.00004629","1"],["76325.7","0.15684826","2"],["76325.6","0.05167657","1"],["76310.3","0.52490828","3"],["76176.3","0","0"],["76175.4","0","0"]]}
{"instId":"BTC-USDT","action":"update","ts":"1776816029510","asks":[],"bids":[["76336.4","0.06381125","1"]]}
{"instId":"BTC-USDT","action":"update","ts":"1776816029530","asks":[["76371.6","0.10608262","3"]],"bids":[]}
{"instId":"BTC-USDT","action":"update","ts":"1776816029570","asks":[["76371.6","0.05304789","2"],["76398","0.100025","3"]],"bids":[["76340.9","0.41749284","9"],["76325.7","0.10606946","1"],["76325.6","0","0"],["76175.4","0.00003868","3"]]}
{"instId":"BTC-USDT","action":"update","ts":"1776816029580","asks":[["76356.3","0.52454781","2"],["76371.7","0.05303473","1"],["76388.6","0.18430194","1"],["76405.1","0","0"],["76406.8","0.00003978","1"],["76463.9","0","0"]],"bids":[["76327.9","0.47151308","1"],["76325.7","0","0"],["76310.4","0.61833756","2"],["76310.3","0.57658485","4"],["76176.3","0.1305","1"],["76175.4","0","0"]]}
{"instId":"BTC-USDT","action":"update","ts":"1776816029590","asks":[["76356.4","0.10606946","1"],["76411.5","0.15259347","2"],["76463.4","0","0"]],"bids":[["76310.4","0.72440702","3"]]}
{"instId":"BTC-USDT","action":"update","ts":"1776816029600","asks":[["76356.3","0.47151308","1"],["76356.4","0","0"],["76463.4","0.00010604","1"]],"bids":[["76310.3","0.52490828","3"]]}
{"instId":"BTC-USDT","action":"update","ts":"1776816029610","asks":[["76371.6","0.10608262","3"]],"bids":[["76325.6","0.05167657","1"],["76176.3","0","0"]]}
{"instId":"BTC-USDT","action":"update","ts":"1776816029630","asks":[["76343.2","0","0"],["76463.9","0.00088649","6"]],"bids":[]}
{"instId":"BTC-USDT","action":"update","ts":"1776816029650","asks":[["76356.2","0","0"],["76358.7","0.33392641","2"],["76464.1","0.00005359","1"]],"bids":[["76325.7","0.3273787","1"],["76324","0.00654753","1"],["76322.7","0","0"],["76321.9","0.13051501","2"],["76239.2","0","0"]]}
{"instId":"BTC-USDT","action":"update","ts":"1776816029660","asks":[["76354.6","0.19688117","1"],["76371.6","0.05304789","2"]],"bids":[["76325.8","0.29378503","1"],["76325.6","0","0"],["76324.8","0","0"],["76175.4","0.00003868","3"]]}
{"instId":"BTC-USDT","action":"update","ts":"1776816029670","asks":[["76356.3","0.52454781","2"],["76356.4","0.10606946","1"],["76371.6","0.00001316","1"],["76372.7","0","0"]],"bids":[["76310.3","0.57658485","4"],["76176.3","0.1305","1"],["76175.4","0","0"]]}
{"instId":"BTC-USDT","action":"update","ts":"1776816029680","asks":[["76356.3","0.57758254","3"]],"bids":[]}
{"instId":"BTC-USDT","action":"update","ts":"1776816029700","asks":[["76356.3","0.47151308","1"],["76356.4","0","0"],["76464.2","0.0025747","2"]],"bids":[["76310.3","0.52490828","3"]]}
{"instId":"BTC-USDT","action":"update","ts":"1776816029710","asks":[["76341","0.48816847","12"],["76371.6","0.05304789","2"],["76371.7","0.15910419","2"]],"bids":[["76340.9","0.51749284","10"],["76310.4","0.61833756","2"]]}
{"instId":"BTC-USDT","action":"update","ts":"1776816029720","asks":[],"bids":[["76340.9","0.52011176","11"]]}
{"instId":"BTC-USDT","action":"update","ts":"1776816029730","asks":[["76371.6","0.00001316","1"]],"bids":[]}
{"instId":"BTC-USDT","action":"update","ts":"1776816029740","asks":[["76351.3","0","0"],["76354.5","0.00654729","1"],["76356.3","0.52454781","2"]],"bids":[["76325.7","0.43344816","2"],["76310.3","0.57658485","4"]]}
{"instId":"BTC-USDT","action":"update","ts":"1776816029750","asks":[],"bids":[["76325.7","0.3273787","1"]]}
{"instId":"BTC-USDT","action":"update","ts":"1776816029760","asks":[],"bids":[["76310.3","0.52490828","3"]]}
{"instId":"BTC-USDT","action":"update","ts":"1776816029770","asks":[["76371.6","0.05304789","2"],["76406.8","0","0"],["76464.4","0.00019338","3"]],"bids":[]}
{"instId":"BTC-USDT","action":"update","ts":"1776816029800","asks":[["76371.7","0.05303473","1"]],"bids":[["76310.4","0.72440702","3"]]}
{"instId":"BTC-USDT","action":"update","ts":"1776816029830","asks":[["76356.4","0.10606946","1"],["76406.8","0.00003978","1"],["76464.2","0","0"],["76464.4","0","0"]],"bids":[["76310.3","0.57658485","4"]]}
{"instId":"BTC-USDT","action":"update","ts":"1776816029900","asks":[["76341","0.48785803","12"]],"bids":[]}
{"instId":"BTC-USDT","action":"update","ts":"1776816029950","asks":[["76373.1","0.01537527","1"],["76464.1","0","0"]],"bids":[["76323.3","0","0"],["76175.4","0.00003868","3"]]}
{"instId":"BTC-USDT","action":"update","ts":"1776816029960","asks":[["76356.3","0.47151308","1"],["76356.4","0","0"],["76464.1","0.00005359","1"]],"bids":[["76310.4","0.56755876","1"],["76310.3","0.52490828","3"],["76244.1","0.00001316","1"],["76175.4","0","0"]]}
{"instId":"BTC-USDT","action":"update","ts":"1776816029970","asks":[["76371.6","0.10608262","3"],["76371.7","0.10606946","1"]],"bids":[["76325.7","0.43344816","2"],["76325.6","0.05167657","1"],["76310.3","0.47187355","2"],["76176.3","0","0"]]}
{"instId":"BTC-USDT","action":"update","ts":"1776816029990","asks":[],"bids":[["76338.2","0.1600168","2"],["76325.6","0.1554901","3"]]}
{"instId":"BTC-USDT","action":"update","ts":"1776816030000","asks":[],"bids":[["76338.9","0.05674159","1"],["76325.7","0.3273787","1"],["76177.8","0","0"]]}
{"instId":"BTC-USDT","action":"update","ts":"1776816030010","asks":[["76351.3","0.0065473","1"],["76354.5","0","0"]],"bids":[["76325.9","0.32737887","1"],["76325.7","0","0"],["76325.6","0.10245537","2"]]}
{"instId":"BTC-USDT","action":"update","ts":"1776816030020","asks":[],"bids":[["76338.2","0.0000168","1"],["76325.8","0.20651937","1"]]}
{"instId":"BTC-USDT","action":"update","ts":"1776816030030","asks":[],"bids":[["76338.9","0","0"],["76177.8","0.00105547","4"]]}
{"instId":"BTC-USDT","action":"update","ts":"1776816030050","asks":[["76358.6","0.00654754","1"],["76358.7","0.3273787","1"],["76371.6","0.15911735","4"],["76464.1","0","0"]],"bids":[["76310.4","0.67362822","2"],["76310.3","0.52490828","3"]]}
{"instId":"BTC-USDT","action":"update","ts":"1776816030070","asks":[["76358.6","0","0"],["76358.7","0.33392624","2"],["76464.1","0.00005359","1"]],"bids":[["76310.4","0.56755876","1"],["76310.3","0.47187355","2"]]}
{"instId":"BTC-USDT","action":"update","ts":"1776816030080","asks":[],"bids":[["76325.7","0.10606946","1"],["76325.6","0.1554901","3"],["76177.8","0","0"]]}
{"instId":"BTC-USDT","action":"update","ts":"1776816030090","asks":[],"bids":[["76326","0.35173456","1"],["76325.8","0","0"]]}
{"instId":"BTC-USDT","action":"update","ts":"1776816030100","asks":[],"bids":[["76326.1","0.32737822","1"],["76325.9","0","0"]]}
{"instId":"BTC-USDT","action":"update","ts":"1776816030110","asks":[],"bids":[["76326","0.25401197","1"]]}
{"instId":"BTC-USDT","action":"update","ts":"1776816030120","asks":[],"bids":[["76325.7","0","0"],["76325.6","0.10245537","2"],["76177.8","0.00105547","4"]]}
{"instId":"BTC-USDT","action":"update","ts":"1776816030130","asks":[],"bids":[["76318.3","0.07086036","2"]]}
{"instId":"BTC-USDT","action":"update","ts":"1776816030140","asks":[],"bids":[["76310.4","0.67362822","2"],["76310.3","0.52490828","3"]]}
{"instId":"BTC-USDT","action":"update","ts":"1776816030200","asks":[],"bids":[["76326.1","0","0"],["76325.7","0.32737829","1"]]}
{"instId":"BTC-USDT","action":"update","ts":"1776816030230","asks":[],"bids":[["76310.3","0.47187355","2"]]}
{"instId":"BTC-USDT","action":"update","ts":"1776816030240","asks":[],"bids":[["76310.3","0.52490828","3"]]}
{"instId":"BTC-USDT","action":"update","ts":"1776816030250","asks":[["76358.6","0.00654754","1"],["76358.7","0.3273787","1"],["76464.1","0","0"]],"bids":[["76324","0","0"],["76322.9","0.00656434","2"],["76175.4","0.00003868","3"]]}
{"instId":"BTC-USDT","action":"update","ts":"1776816030260","asks":[],"bids":[["76324","0.00654754","1"],["76322.9","0.0000168","1"],["76245.7","0.20472245","1"],["76177.8","0","0"],["76175.4","0","0"]]}
{"instId":"BTC-USDT","action":"update","ts":"1776816030330","asks":[["76371.6","0.10608262","3"]],"bids":[]}
{"instId":"BTC-USDT","action":"update","ts":"1776816030350","asks":[["76356.2","0.32737846","1"],["76356.3","0.52454781","2"],["76357.7","0.00654753","1"],["76358.6","0","0"],["76358.7","0","0"]],"bids":[["76325.7","0","0"],["76324.8","0.32737846","1"],["76324","0","0"],["76322.9","0.00656433","2"],["76177.8","0.00105547","4"]]}
{"instId":"BTC-USDT","action":"update","ts":"1776816030360","asks":[["76351.3","0.00654725","1"],["76354.6","0.28526364","2"]],"bids":[["76340.9","0.51749284","10"]]}
{"instId":"BTC-USDT","action":"update","ts":"1776816030380","asks":[["76371.7","0","0"],["76464.1","0.00005359","1"]],"bids":[["76325.6","0.0507788","1"]]}
{"instId":"BTC-USDT","action":"update","ts":"1776816030390","asks":[["76356.4","0.10606946","1"],["76357.7","0","0"],["76358.7","0.00654757","1"],["76464.1","0","0"]],"bids":[["76310.3","0.57658485","4"]]}
{"instId":"BTC-USDT","action":"update","ts":"1776816030410","asks":[["76357.7","0.0065476","1"],["76358.7","0","0"]],"bids":[]}
{"instId":"BTC-USDT","action":"update","ts":"1776816030440","asks":[["76349.9","0.04256409","3"],["76351.3","0","0"],["76464.1","0.00005359","1"]],"bids":[]}
{"instId":"BTC-USDT","action":"update","ts":"1776816030450","asks":[["76341","0.52385803","13"],["76349.9","0.0360168","2"],["76351.3","0.00654736","1"],["76371.6","0.00001316","1"],["76464.1","0","0"]],"bids":[["76340.9","0.3487533","7"],["76329.6","0","0"],["76328.1","0","0"],["76328","0.00002349","2"],["76327.9","0","0"],["76325.6","0","0"],["76324.7","0","0"],["76320.7","0","0"],["76314.6","0.00001316","1"],["76310.3","0.10507177","3"],["76240.1","0.47151308","1"],["76175.4","0.00003868","3"],["76175.1","0.47151308","1"],["76175","0.00029601","2"],["76173.7","0.00070045","3"],["76173.6","0.00002308","1"]]}
{"instId":"BTC-USDT","action":"update","ts":"1776816030460","asks":[["76341","0.53005803","14"],["76343.2","0.14074665","1"],["76346.2","0.14062739","1"],["76346.6","0","0"],["76348.1","0.00656052","2"],["76351.3","0.13266735","1"],["76354.5","1.41717808","3"],["76356.1","0.0065476","1"],["76356.2","0","0"],["76356.3","0.63061727","4"],["76357.7","0","0"],["76359.1","0.08378297","1"],["76397.2","0","0"],["76438.4","0.13754939","4"],["76463.9","0","0"]],"bids":[["76340.9","0.2127533","4"],["76338.8","0","0"],["76337.7","0","0"],["76336.3","0","0"],["76336.1","0","0"],["76335","0.03","2"],["76333.9","0.0262","1"],["76333","0","0"],["76330.3","0","0"],["76330.2","0.12538632","1"],["76328.6","0.00655891","2"],["76326","0.13095782","1"],["76324.8","0","0"],["76322.9","0.0000168","1"],["76322.5","0.17948596","1"],["76321.9","0.45789697","3"],["76320.9","1.48407383","3"],["76320.8","0.0000463","1"],["76314.8","0.47151308","1"],["76314.7","0","0"],["76310.5","0.47151308","1"],["76310.3","0.15585057","4"],["76294.9","0","0"],["76293.9","0","0"],["76289.7","0.12341449","1"],["76289","0","0"],["76285.8","0.00131085","1"],["76284.9","0.1187014","1"],["76268.4","0","0"],["76245","0.316599","1"],["76242.5","0","0"],["76217.7","1.610636","1"],["76204.3","0","0"],["76184.3","1.00601315","1"],["76176.3","0.1305","1"],["76173.2","0.00001006","1"],["76173","0.00001059","1"]]}
{"instId":"BTC-USDT","action":"update","ts":"1776816030470","asks":[["76341","0.5652488","16"],["76349.8","0.08419402","2"],["76355.2","0.00654778","1"],["76356.1","0","0"],["76383.4","0.06317051","1"],["76388.2","0","0"],["76437.4","0.17965236","2"]],"bids":[["76340.9","0.06253275","2"],["76336.4","0","0"],["76335","0","0"],["76333.9","0","0"],["76330.1","0","0"],["76328.6","0.01297545","2"],["76327.9","0.00654736","1"],["76326","0.03323535","1"],["76321.6","0.01572382","1"],["76320.9","1.47752623","2"],["76320.1","0.00654778","1"],["76311.8","0.00001155","1"],["76306.9","0.06310052","1"],["76269.2","0.16589954","1"]]}
{"instId":"BTC-USDT","action":"update","ts":"1776816030480","asks":[["76343.3","0","0"],["76346.1","0.0065479","1"],["76348.1","0.00001316","1"],["76351.2","0.32740328","1"],["76354.4","0.70756574","2"],["76354.5","0.08378297","1"],["76354.6","0","0"],["76355.2","0","0"],["76356.4","0.23656946","2"],["76359.8","0.06550532","1"],["76377.1","0","0"]],"bids":[["76330.2","0.06195557","1"],["76327.9","0","0"],["76325.4","0.0065479","1"],["76324.6","0.00005946","2"],["76323.9","0","0"],["76321.9","0.13051501","2"],["76321","1.47753623","3"],["76320.9","0","0"],["76320.1","0","0"],["76318.4","0.32740328","1"],["76318","0.00654806","1"],["76252.9","0","0"],["76171.1","0.00001024","1"],["76170.8","0.00003094","3"]]}
{"instId":"BTC-USDT","action":"update","ts":"1776816030490","asks":[["76343.2","0","0"],["76346.1","0.12667804","2"],["76349.8","0.17769668","1"],["76354.3","1.00601315","1"],["76354.4","0.00654806","1"],["76354.8","0.00001316","1"],["76377","0","0"],["76385.2","0.07857981","2"],["76393.2","0","0"],["76463.9","0.00088649","6"],["76464.1","0.00005359","1"]],"bids":[["76327.7","0","0"],["76326.1","0.00654797","1"],["76326","0","0"],["76325.4","0","0"],["76325.3","0","0"],["76322.5","0.56305853","2"],["76318.1","0.0061","2"],["76313.7","0","0"],["76306","0.14409042","1"],["76303.2","0.09207733","2"],["76253.5","0.000015","1"],["76170.2","0.00001385","1"],["76168.9","0.000015","1"]]}
{"instId":"BTC-USDT","action":"update","ts":"1776816030500","asks":[["76341","0.55220834","16"],["76346","0.00654792","1"],["76346.1","0.12013014","1"],["76354.2","0.60684729","1"],["76463.9","0","0"],["76464.1","0","0"]],"bids":[["76326.1","0","0"],["76322.7","0.00654792","1"],["76237.1","0","0"],["76168.4","0.00011049","4"]]}
{"instId":"BTC-USDT","action":"update","ts":"1776816030510","asks":[["76346","0.12865501","2"],["76346.2","0","0"],["76351.2","0.32740667","1"],["76395.1","0.00001316","1"],["76418.9","0.21113","2"],["76463.9","0.00088649","6"]],"bids":[["76340.9","0.09233275","3"],["76322.6","0.11978366","2"],["76318.4","0.32740667","1"],["76318.1","0.00305","1"],["76306","0","0"],["76305.4","0.11599999","1"],["76293.2","0","0"],["76262.7","0.00054217","1"],["76168.6","0.1305","1"]]}
{"instId":"BTC-USDT","action":"update","ts":"1776816030520","asks":[["76346","0.12210709","1"],["76347.4","0.00654784","1"],["76351.2","0","0"],["76354.1","0.32740667","1"],["76354.4","0","0"],["76355","0.00654793","1"],["76442.8","0.59991129","2"],["76463.9","0","0"]],"bids":[["76333.9","0.03","2"],["76327.6","0.00654784","1"],["76323.4","0.05896264","1"],["76322.7","0","0"],["76321.1","0.32740667","1"],["76320.1","0.00654793","1"],["76318.4","0","0"],["76318","0","0"],["76261.1","0.00001501","1"],["76168.6","0","0"],["76168.4","0","0"]]}
{"instId":"BTC-USDT","action":"update","ts":"1776816030530","asks":[["76346.3","0.1687864","2"],["76347.4","0","0"],["76349.8","0.09073084","1"],["76351.2","0.32739833","1"],["76354","0.00654793","1"],["76354.1","0","0"],["76355","0","0"],["76463.9","0.00088649","6"]],"bids":[["76327.6","0","0"],["76323.5","0.0176038","1"],["76322.8","0.00678519","6"],["76321.1","0","0"],["76320.1","0","0"],["76318.4","0.33394626","2"],["76261.2","0","0"],["76168.4","0.00011049","4"],["76167","0.00001319","1"]]}
{"instId":"BTC-USDT","action":"update","ts":"1776816030540","asks":[["76349.8","0.17685948","2"]],"bids":[["76168.6","0.1305","1"],["76167","0","0"]]}
{"instId":"BTC-USDT","action":"update","ts":"1776816030550","asks":[["76353.1","0.01309","1"],["76359.2","0.11673366","1"],["76463.9","0","0"]],"bids":[["76322.3","0","0"],["76314.4","0.30279","1"]]}
{"instId":"BTC-USDT","action":"update","ts":"1776816030560","asks":[["76341","0.51620834","15"]],"bids":[["76332.8","0.0262","1"],["76168.4","0","0"]]}
{"instId":"BTC-USDT","action":"update","ts":"1776816030570","asks":[],"bids":[["76334","0.02070881","1"],["76168.6","0","0"]]}
{"instId":"BTC-USDT","action":"update","ts":"1776816030590","asks":[],"bids":[["76340.9","0.06253275","2"]]}
{"instId":"BTC-USDT","action":"update","ts":"1776816030610","asks":[],"bids":[["76271.2","0.00001033","1"],["76266.7","0.00013112","1"],["76262.7","0","0"],["76258.1","0.00054219","1"],["76168.9","0","0"]]}
{"instId":"BTC-USDT","action":"update","ts":"1776816030630","asks":[],"bids":[["76304.4","0","0"],["76278.5","0.47151308","1"],["76168.9","0.000015","1"]]}
{"instId":"BTC-USDT","action":"update","ts":"1776816030640","asks":[["76349.7","0.16","1"],["76351.2","0","0"],["76354.1","0.32740245","1"],["76463.4","0","0"]],"bids":[]}
{"instId":"BTC-USDT","action":"update","ts":"1776816030650","asks":[["76349.6","0.14434944","1"],["76349.8","0","0"]],"bids":[]}
{"instId":"BTC-USDT","action":"update","ts":"1776816030670","asks":[["76356.3","0.52454781","2"],["76406.8","0","0"],["76432","0.12","1"]],"bids":[["76340.9","0.09353275","4"],["76321.1","0.32740165","1"],["76318.4","0.00654793","1"],["76168.9","0","0"]]}
{"instId":"BTC-USDT","action":"update","ts":"1776816030680","asks":[["76346.3","0.16223865","1"],["76347.4","0.00654788","1"],["76371.6","0.10608262","3"],["76395.1","0.10508174","2"],["76430.8","0.65942","1"],["76435.1","0.65788553","2"],["76463.2","0","0"],["76463.3","0","0"]],"bids":[["76323.6","0.00655822","2"],["76322.8","0.00023744","5"],["76310.3","0.104174","3"],["76285.6","0.659162","1"],["76281","0.66072816","2"],["76244.2","2.01783308","2"],["76235.2","1.55371529","2"],["76170.2","0","0"]]}
{"instId":"BTC-USDT","action":"update","ts":"1776816030690","asks":[["76373.1","0","0"],["76463.2","0.00059244","1"]],"bids":[["76325.6","0.05167657","1"],["76285.7","0.23936942","1"],["76285.5","0","0"],["76278.5","0.47474703","2"],["76170.8","0","0"]]}
{"instId":"BTC-USDT","action":"update","ts":"1776816030700","asks":[],"bids":[["76325.7","0.04155252","2"],["76323.6","0.00001034","1"],["76323.5","0","0"]]}
{"instId":"BTC-USDT","action":"update","ts":"1776816030710","asks":[],"bids":[["76321.6","0","0"],["76304.4","0.00002864","1"]]}
{"instId":"BTC-USDT","action":"update","ts":"1776816030730","asks":[],"bids":[["76273.3","0.33240385","2"],["76247.6","0","0"],["76170.8","0.00003094","3"]]}
{"instId":"BTC-USDT","action":"update","ts":"1776816030740","asks":[["76371.6","0.00001316","1"]],"bids":[["76325.6","0","0"],["76170.2","0.00001385","1"]]}
{"instId":"BTC-USDT","action":"update","ts":"1776816030750","asks":[["76356.3","0.63061727","4"]],"bids":[["76331.4","0.11101784","2"],["76327.6","0.00654766","1"],["76325.8","0.03002806","1"],["76325.7","0","0"],["76170.2","0","0"]]}
{"instId":"BTC-USDT","action":"update","ts":"1776816030760","asks":[],"bids":[["76334","0.05119613","2"],["76325.8","0","0"],["76170.2","0.00001385","1"]]}
{"instId":"BTC-USDT","action":"update","ts":"1776816030770","asks":[["76447.5","0.00002945","1"]],"bids":[["76323.5","0.0176038","1"],["76310.3","0.15585057","4"],["76170.2","0","0"]]}
{"instId":"BTC-USDT","action":"update","ts":"1776816030780","asks":[["76406.8","0.00003978","1"],["76463.2","0","0"]],"bids":[["76327.6","0","0"],["76323.6","0.00655805","2"],["76214","0.01722383","2"],["76170.2","0.00001385","1"]]}
{"instId":"BTC-USDT","action":"update","ts":"1776816030790","asks":[["76368.7","0.01583215","1"],["76463.1","0","0"]],"bids":[["76321.4","0.01605195","1"],["76170.2","0","0"]]}
{"instId":"BTC-USDT","action":"update","ts":"1776816030800","asks":[],"bids":[["76340.9","0.09233275","3"],["76338.6","0.00004429","1"]]}
{"instId":"BTC-USDT","action":"update","ts":"1776816030820","asks":[],"bids":[["76321.1","0.33414045","2"],["76295.4","0.00707574","1"],["76170.8","0","0"]]}
{"instId":"BTC-USDT","action":"update","ts":"1776816030980","asks":[],"bids":[["76290.5","0.01917789","1"],["76199.9","0.01466708","1"],["76173","0","0"],["76171.1","0","0"]]}
{"instId":"BTC-USDT","action":"update","ts":"1776816030990","asks":[["76343.3","0.00001763","1"],["76463","0","0"]],"bids":[]}
{"instId":"BTC-USDT","action":"update","ts":"1776816031000","asks":[],"bids":[["76332.8","0","0"],["76324.8","0.01521585","1"]]}
{"instId":"BTC-USDT","action":"update","ts":"1776816031010","asks":[["76346.2","0.00654794","1"],["76347.4","0","0"],["76383.2","0.01686896","2"],["76391","0","0"],["76463","0.00004357","1"]],"bids":[["76324.9","0.00654794","1"],["76323.6","0.00001034","1"],["76321.1","0.33413935","2"],["76235.3","0.08378297","1"],["76173.6","0","0"],["76173.2","0","0"]]}
{"instId":"BTC-USDT","action":"update","ts":"1776816031030","asks":[["76339.3","1.72692101","21"],["76339.4","0.00374539","1"],["76340","0.1867","2"],["76340.1","0.1867","2"],["76340.9","0.64548036","5"],["76341","0.11961506","7"],["76344.7","0.00001316","1"],["76351.2","0.32740234","1"],["76351.3","0","0"],["76351.4","0.00001316","1"],["76354","0.12813638","2"],["76354.1","0","0"],["76356.3","0.47151308","1"],["76356.4","0.1305","1"],["76359.3","0.00040006","1"],["76395.1","0.00001316","1"],["76445.3","0.0003737","5"],["76462.2","0","0"],["76462.3","0","0"],["76462.4","0","0"],["76462.5","0","0"],["76462.6","0","0"],["76463","0","0"]],"bids":[["76340.9","0","0"],["76340.6","0","0"],["76340","0","0"],["76339.9","0","0"],["76339.3","0","0"],["76339.2","0.07297952","5"],["76321.1","0.0067388","1"],["76319.3","0.00569792","2"],["76318.4","0.33395027","2"],["76316.8","0","0"],["76310.6","0.11941414","2"],["76310.4","0.56755876","1"],["76310.3","0.00036047","1"],["76293.4","0","0"],["76289.7","0","0"],["76173.6","0.00002308","1"],["76173.2","0.00001006","1"],["76173","0.00001059","1"],["76171.1","0.00001024","1"],["76170.8","0.00003094","3"],["76170.2","0.00001385","1"],["76168.9","0.000015","1"],["76168.4","0.00011049","4"]]}
{"instId":"BTC-USDT","action":"update","ts":"1776816031040","asks":[["76339.3","1.7332856","23"],["76339.4","0","0"],["76340","0.28411093","1"],["76340.1","0","0"],["76340.9","0.15759583","1"],["76341","0.11325133","5"],["76351.1","0.32740204","1"],["76351.2","0","0"],["76360","0.00009621","2"],["76381.9","0","0"],["76462.2","0.00551437","1"],["76462.3","0.00027227","4"],["76462.4","0.00001191","1"]],"bids":[["76318.3","0.00001034","1"],["76314.9","0.27496361","1"],["76289.8","0.13533404","2"],["76168.4","0","0"]]}
{"instId":"BTC-USDT","action":"update","ts":"1776816031050","asks":[["76339.9","0.16565499","1"],["76340","0","0"],["76351","0.32740189","1"],["76351.1","0","0"],["76354.6","0.26517365","4"],["76462.4","0","0"]],"bids":[["76318.5","0.46384888","2"],["76318.4","0.00654793","1"],["76308.6","0.34534253","5"],["76278.5","0.47151308","1"],["76277.6","0.00324714","2"],["76233","0.000655","1"],["76170.2","0","0"],["76168.9","0","0"]]}
{"instId":"BTC-USDT","action":"update","ts":"1776816031060","asks":[["76339.9","0.08084788","1"],["76350.9","0.32740164","1"],["76351","0","0"],["76392.7","0.12298422","1"],["76462.3","0","0"]],"bids":[["76318.6","0.50457793","2"],["76318.5","0","0"],["76281.1","0.37226861","1"],["76278.6","0","0"]]}
{"instId":"BTC-USDT","action":"update","ts":"1776816031070","asks":[["76350.8","0.32740146","1"],["76350.9","0","0"],["76429.5","0.30589807","2"],["76437.4","0.00196024","1"]],"bids":[["76318.7","0.51673542","2"],["76318.6","0","0"]]}
{"instId":"BTC-USDT","action":"update","ts":"1776816031080","asks":[["76350.8","0","0"],["76353.9","0.32740134","1"]],"bids":[["76318.8","0.52036426","2"],["76318.7","0","0"],["76300.2","0.19319633","1"]]}
{"instId":"BTC-USDT","action":"update","ts":"1776816031090","asks":[["76339.3","1.6180315","22"],["76343.3","0","0"],["76349.6","0.07138179","1"],["76384.5","0.11674987","1"],["76416","0","0"],["76462.3","0.00027227","4"]],"bids":[["76339.2","0.10397952","7"],["76318.9","0.19404613","1"],["76318.8","0.32740134","1"],["76310.3","0","0"],["76290.3","0","0"],["76289","0.00325274","1"],["76287.4","0","0"],["76286.5","0.00233659","1"]]}
{"instId":"BTC-USDT","action":"update","ts":"1776816031100","asks":[["76340.9","0","0"],["76354.6","0.21213892","3"],["76358.7","0.1273635","1"],["76375.8","0.10432483","1"],["76378","0.00001","1"],["76390.4","0.000015","1"],["76398","0.100015","2"],["76462.2","0","0"],["76462.3","0","0"]],"bids":[["76339.2","0.07297952","5"],["76328.5","0","0"],["76322.7","0.32740087","1"],["76321","1.00601315","1"],["76318.9","0.1364467","1"],["76318.8","0","0"],["76301","0.00001","1"]]}
{"instId":"BTC-USDT","action":"update","ts":"1776816031110","asks":[["76339.9","0.03380552","1"],["76345.9","0.00654784","1"],["76346.2","0","0"],["76347.4","0.32740087","1"],["76347.9","0.05896264","1"],["76349.5","0.08378297","1"],["76353","0.00654797","1"],["76353.5","0.01614584","1"],["76353.9","0","0"],["76354","0.12158845","1"],["76354.6","0.10606946","2"],["76355.3","0","0"],["76375.4","0.05239768","1"],["76385.2","0.0261894","1"],["76461.5","0","0"],["76461.6","0","0"],["76461.7","0","0"],["76462","0","0"]],"bids":[["76330.2","0.03953742","1"],["76327.5","0","0"],["76324.9","0","0"],["76323.6","0.00655818","2"],["76322.7","0","0"],["76322.5","0.17948596","1"],["76321.4","0.01867133","2"],["76321","0","0"],["76319.3","0.00040006","1"],["76318.9","0","0"],["76318.4","0","0"],["76315.2","0.00654797","1"],["76315","0.32740087","1"],["76314.8","0","0"],["76306.5","0","0"],["76306.3","0","0"],["76294","0.00004629","1"],["76285.9","0.02618969","1"],["76277.5","0","0"],["76260.3","0.61365254","3"],["76173.1","1.00601315","1"],["76170.2","0.00001385","1"],["76168.9","0.000015","1"],["76168.4","0.00011049","4"],["76167","0.00001319","1"],["76166.6","0.00248493","6"],["76166.2","0.00026145","4"]]}
{"instId":"BTC-USDT","action":"update","ts":"1776816031120","asks":[["76346.3","0.28183942","2"],["76347","0.05303473","1"],["76349.4","0.00654797","1"],["76353","0","0"],["76354.6","0.21213892","3"],["76359","0","0"]],"bids":[["76328.6","0.00001155","1"],["76323.6","0.00001034","1"],["76322.7","0.09322487","1"],["76322.5","0","0"],["76322","0.00654784","1"],["76315.2","0","0"],["76315","0.79891395","2"],["76314.9","0","0"],["76314.6","0.00656113","2"],["76168.6","0.1305","1"]]}
{"instId":"BTC-USDT","action":"update","ts":"1776816031130","asks":[["76346.1","0","0"],["76368.7","0.13523543","2"],["76373.2","0","0"],["76378.8","0","0"],["76384.4","0.11674987","1"],["76384.5","0","0"],["76461.5","0.01228943","9"],["76461.6","0.00332668","1"],["76461.7","0.00001025","1"]],"bids":[["76325.9","0.01296437","1"],["76322","0.07205316","2"],["76318.3","0.50828317","3"],["76166.2","0","0"]]}
{"instId":"BTC-USDT","action":"update","ts":"1776816031140","asks":[["76402.7","0.00003978","1"],["76406.8","0","0"],["76461.5","0.14278943","10"]],"bids":[["76318.4","1.19449543","2"],["76318.3","0.47152342","2"],["76277.6","0.00001316","1"],["76276.3","0.003249","2"],["76173.1","0","0"]]}
{"instId":"BTC-USDT","action":"update","ts":"1776816031150","asks":[],"bids":[["76318.5","0.53406638","1"],["76318.4","1.00601315","1"],["76166.6","0","0"]]}
{"instId":"BTC-USDT","action":"update","ts":"1776816031160","asks":[["76347.4","0","0"],["76349.3","0.00654798","1"],["76349.4","0.32740108","1"]],"bids":[["76322.1","0.00654826","1"],["76322","0.06550532","1"],["76315.1","0.70228586","7"],["76315","0.47151308","1"],["76314.7","0.00654798","1"],["76314.6","0.00001316","1"],["76168.4","0","0"],["76167","0","0"]]}
{"instId":"BTC-USDT","action":"update","ts":"1776816031170","asks":[],"bids":[["76315.2","0.48655051","1"],["76315.1","0.32763852","6"],["76298.5","0.1","1"],["76168.9","0","0"],["76168.6","0","0"]]}
{"instId":"BTC-USDT","action":"update","ts":"1776816031180","asks":[["76339.3","1.6834015","23"],["76341","0.04892133","4"]],"bids":[["76299.2","0.12777415","2"]]}
{"instId":"BTC-USDT","action":"update","ts":"1776816031190","asks":[["76339.9","0.01460302","1"],["76349.3","0","0"],["76353","0.00654798","1"]],"bids":[["76315.3","0.00656479","2"],["76314.7","0","0"],["76168.9","0.000015","1"]]}
{"instId":"BTC-USDT","action":"update","ts":"1776816031200","asks":[["76408","0.02671766","2"],["76461.7","0","0"]],"bids":[["76323.5","0.0241519","2"],["76322.1","0","0"],["76281.4","0.03349534","2"],["76245.7","0.73463041","2"]]}
{"instId":"BTC-USDT","action":"update","ts":"1776816031210","asks":[["76339.3","1.66806532","22"]],"bids":[["76260.4","0.32407993","1"],["76168.9","0","0"]]}
{"instId":"BTC-USDT","action":"update","ts":"1776816031220","asks":[["76359","0.00023145","1"],["76378.8","0.00007241","1"],["76461.5","0","0"],["76461.6","0","0"]],"bids":[["76333.9","0","0"],["76332","0.03","2"],["76324.8","0","0"],["76318.3","0.79892296","3"],["76315.1","0.00023744","5"],["76253.5","0.49933734","2"],["76168.9","0.000015","1"]]}
{"instId":"BTC-USDT","action":"update","ts":"1776816031230","asks":[["76347","0","0"],["76368.7","0.11940328","1"],["76461.5","0.01228943","9"]],"bids":[["76318.3","0.47152342","2"],["76315.3","0.33396416","3"],["76315.2","0.27503449","1"],["76291.5","0.000015","1"],["76290.5","0","0"],["76283.6","0.00132122","2"],["76199.9","0","0"],["76168.4","0.00011049","4"],["76167","0.00001319","1"]]}
{"instId":"BTC-USDT","action":"update","ts":"1776816031240","asks":[["76383.4","0","0"],["76391.4","0.10527543","1"],["76461.5","0.14278943","10"]],"bids":[["76318.3","0.79892468","3"],["76315.3","0.00656479","2"],["76240.2","0.46589223","1"],["76168.6","0.1305","1"],["76168.4","0","0"],["76167","0","0"]]}
{"instId":"BTC-USDT","action":"update","ts":"1776816031250","asks":[["76354.6","0.26517365","4"]],"bids":[["76304.4","0","0"],["76303.4","0.00002864","1"],["76237.9","0.94565919","3"]]}
{"instId":"BTC-USDT","action":"update","ts":"1776816031260","asks":[],"bids":[["76303.4","0","0"],["76302.5","0.00002864","1"]]}
{"instId":"BTC-USDT","action":"update","ts":"1776816031270","asks":[["76398","0.000015","1"]],"bids":[]}
{"instId":"BTC-USDT","action":"update","ts":"1776816031300","asks":[],"bids":[["76296","0.00004307","4"],["76290.7","0.00001034","1"],["76285.4","0.05897298","2"],["76280.1","0.00001034","1"],["76274.8","0.08379332","2"],["76269.5","0.00002716","2"],["76264.2","0.00002351","2"],["76168.9","0","0"],["76168.6","0","0"]]}
{"instId":"BTC-USDT","action":"update","ts":"1776816031310","asks":[],"bids":[["76291.1","0.0335085","3"],["76266.7","0","0"],["76265.1","0.00013112","1"],["76258.1","0","0"],["76256.6","0.00054219","1"]]}
{"instId":"BTC-USDT","action":"update","ts":"1776816031320","asks":[["76378.8","0","0"],["76461.6","0.00332668","1"]],"bids":[]}
{"instId":"BTC-USDT","action":"update","ts":"1776816031330","asks":[["76349.4","0","0"],["76353.9","0.32740067","1"]],"bids":[["76318.6","0.32740067","1"],["76318.3","0.47152342","2"],["76170.2","0","0"]]}
{"instId":"BTC-USDT","action":"update","ts":"1776816031340","asks":[["76346.3","0.16223865","1"],["76353.8","0.11675247","1"],["76358.7","0","0"]],"bids":[]}
{"instId":"BTC-USDT","action":"update","ts":"1776816031350","asks":[],"bids":[["76330.9","0.0262","1"],["76170.8","0","0"]]}
{"instId":"BTC-USDT","action":"update","ts":"1776816031360","asks":[["76396.3","0.1","1"],["76461.6","0","0"]],"bids":[]}
{"instId":"BTC-USDT","action":"update","ts":"1776816031370","asks":[],"bids":[["76330.9","0","0"],["76170.8","0.00003094","3"]]}
{"instId":"BTC-USDT","action":"update","ts":"1776816031380","asks":[["76349.7","0","0"],["76461.6","0.00332668","1"]],"bids":[]}
{"instId":"BTC-USDT","action":"update","ts":"1776816031390","asks":[["76349.6","0.02557636","1"]],"bids":[]}
{"instId":"BTC-USDT","action":"update","ts":"1776816031400","asks":[["76341.6","0.00001134","1"],["76461.6","0","0"]],"bids":[["76302.5","0","0"],["76170.2","0.00001385","1"]]}
{"instId":"BTC-USDT","action":"update","ts":"1776816031420","asks":[["76371.8","0.00007241","1"],["76461.5","0","0"]],"bids":[]}
{"instId":"BTC-USDT","action":"update","ts":"1776816031450","asks":[],"bids":[["76330.9","0.0262","1"],["76318","0.00654792","1"],["76315.3","0.00001681","1"],["76170.8","0","0"],["76170.2","0","0"]]}
{"instId":"BTC-USDT","action":"update","ts":"1776816031460","asks":[],"bids":[["76302.5","0.00002864","1"],["76260.3","0.01375254","2"],["76171.1","0","0"]]}
{"instId":"BTC-USDT","action":"update","ts":"1776816031470","asks":[],"bids":[["76260.4","0.14500978","1"]]}
{"instId":"BTC-USDT","action":"update","ts":"1776816031500","asks":[],"bids":[["76228.4","0.60080772","2"]]}
{"instId":"BTC-USDT","action":"update","ts":"1776816031510","asks":[],"bids":[["76237.9","1.12472934","4"]]}
{"instId":"BTC-USDT","action":"update","ts":"1776816031520","asks":[],"bids":[["76330.9","0","0"],["76171.1","0.00001024","1"]]}
{"instId":"BTC-USDT","action":"update","ts":"1776816031530","asks":[["76344.7","0.11914903","2"]],"bids":[["76332","0.01","1"],["76331.4","0.00001316","1"],["76331","0.02","1"],["76171.1","0","0"]]}
{"instId":"BTC-USDT","action":"update","ts":"1776816031540","asks":[["76344.6","0.03556599","1"],["76345.9","0","0"],["76346.2","0.00654794","1"],["76353.7","0.32740012","1"],["76353.9","0","0"],["76363.5","0.01546879","1"],["76461.3","0","0"],["76461.4","0","0"]],"bids":[["76339.2","0.01047952","4"],["76334","0","0"],["76326","0.00654794","1"],["76323.5","0.0176038","1"],["76321.4","0.00261938","1"],["76318.6","0.33394864","2"],["76318","0","0"],["76288.9","0.3648702","2"],["76237.9","0.14664584","2"],["76198.3","0.01470225","1"]]}
{"instId":"BTC-USDT","action":"update","ts":"1776816031550","asks":[["76354","0","0"],["76358.7","0.12736634","1"],["76368.1","0.12055099","2"],["76368.8","0","0"],["76384.4","0","0"],["76391.4","0","0"],["76461.3","0.00027039","1"],["76461.4","0.0312605","1"],["76461.5","0.01228943","9"]],"bids":[["76339.2","0.07297952","5"],["76237.9","0.85976749","3"]]}
{"instId":"BTC-USDT","action":"update","ts":"1776816031560","asks":[["76391.4","0.10714474","1"],["76461.5","0","0"]],"bids":[["76271.8","0","0"],["76225.9","0","0"],["76171.1","0.00001024","1"],["76170.8","0.00003094","3"]]}
{"instId":"BTC-USDT","action":"update","ts":"1776816031570","asks":[["76353","0","0"],["76354.1","0.00654807","1"]],"bids":[["76319.4","0.00654807","1"],["76318.6","0.32740067","1"],["76170.8","0","0"]]}
{"instId":"BTC-USDT","action":"update","ts":"1776816031580","asks":[],"bids":[["76242.6","0","0"],["76170.8","0.00003094","3"]]}
{"instId":"BTC-USDT","action":"update","ts":"1776816031590","asks":[],"bids":[["76339.2","0.10277952","6"]]}
{"instId":"BTC-USDT","action":"update","ts":"1776816031600","asks":[["76339.3","1.65502457","21"]],"bids":[["76339.2","0.10397952","7"]]}
{"instId":"BTC-USDT","action":"update","ts":"1776816031610","asks":[],"bids":[["76256.6","0.00054218","1"]]}
{"instId":"BTC-USDT","action":"update","ts":"1776816031630","asks":[["76345.9","0.16","1"],["76461.4","0","0"]],"bids":[["76339.2","0.10277952","6"],["76272.5","0","0"],["76170.2","0.00001385","1"]]}
{"instId":"BTC-USDT","action":"update","ts":"1776816031670","asks":[],"bids":[["76330.8","0.0262","1"],["76170.2","0","0"]]}
{"instId":"BTC-USDT","action":"update","ts":"1776816031680","asks":[],"bids":[["76332.1","0.01678464","1"],["76170.8","0","0"]]}
{"instId":"BTC-USDT","action":"update","ts":"1776816031690","asks":[["76457.9","0.02053416","2"]],"bids":[["76237.9","1.15914083","4"]]}
{"instId":"BTC-USDT","action":"update","ts":"1776816031750","asks":[["76363.5","0","0"],["76461.4","0.0312605","1"]],"bids":[["76315.2","0.29093511","2"]]}
{"instId":"BTC-USDT","action":"update","ts":"1776816031760","asks":[["76368.7","0","0"],["76461.5","0.01228943","9"]],"bids":[]}
{"instId":"BTC-USDT","action":"update","ts":"1776816031770","asks":[["76461.5","0.14278943","10"]],"bids":[]}
{"instId":"BTC-USDT","action":"update","ts":"1776816031780","asks":[["76402.7","0","0"],["76461.6","0.00332668","1"]],"bids":[]}
{"instId":"BTC-USDT","action":"update","ts":"1776816031790","asks":[],"bids":[["76315.2","0.27503449","1"]]}
{"instId":"BTC-USDT","action":"update","ts":"1776816031810","asks":[["76384.5","0.11674988","1"],["76461.6","0","0"]],"bids":[["76339.2","0.07297952","5"],["76331","0","0"],["76330.8","0","0"],["76330.3","0.02","1"],["76170.8","0.00003094","3"]]}
{"instId":"BTC-USDT","action":"update","ts":"1776816031820","asks":[["76345.8","0.0065479","1"],["76346.2","0","0"],["76353","0.00654813","1"],["76354.1","0","0"],["76363","0.01600426","1"],["76461.5","0","0"]],"bids":[["76332.1","0","0"],["76326","0","0"],["76323.6","0.00655824","2"],["76319.4","0","0"],["76318.2","0.12329525","2"],["76312.5","0.11685574","2"],["76310.6","0.00001086","1"],["76290","0.11940328","1"],["76237.9","1.17592547","3"],["76170.2","0.00001385","1"],["76168.9","0.000015","1"]]}
{"instId":"BTC-USDT","action":"update","ts":"1776816031830","asks":[],"bids":[["76231","0.08892826","2"]]}
{"instId":"BTC-USDT","action":"update","ts":"1776816031840","asks":[],"bids":[["76339.2","0.10277952","6"],["76330.8","0.0262","1"],["76168.9","0","0"]]}
{"instId":"BTC-USDT","action":"update","ts":"1776816031850","asks":[],"bids":[["76339.2","0.07297952","5"],["76333.8","0.01473881","1"],["76326","0.006548","1"],["76323.6","0.00001034","1"],["76170.8","0","0"],["76170.2","0","0"]]}
{"instId":"BTC-USDT","action":"update","ts":"1776816031860","asks":[],"bids":[["76326","0","0"],["76323.6","0.00655835","2"],["76170.8","0.00003094","3"]]}
{"instId":"BTC-USDT","action":"update","ts":"1776816031880","asks":[["76402.7","0.00003978","1"],["76461.4","0","0"]],"bids":[]}
{"instId":"BTC-USDT","action":"update","ts":"1776816031910","asks":[["76341","0.04891133","3"]],"bids":[]}
{"instId":"BTC-USDT","action":"update","ts":"1776816031930","asks":[],"bids":[["76330.8","0","0"],["76170.2","0.00001385","1"]]}
{"instId":"BTC-USDT","action":"update","ts":"1776816031940","asks":[],"bids":[["76333.8","0","0"],["76168.9","0.000015","1"]]}
{"instId":"BTC-USDT","action":"update","ts":"1776816031950","asks":[],"bids":[["76323.7","0.00654804","1"],["76323.6","0.00001034","1"],["76168.9","0","0"]]}
{"instId":"BTC-USDT","action":"update","ts":"1776816031970","asks":[["76373.7","0.10611446","2"],["76379.5","0.0634439","1"],["76461.3","0","0"]],"bids":[["76318.2","0.11674712","1"],["76315.3","0.006565","2"]]}
{"instId":"BTC-USDT","action":"update","ts":"1776816031980","asks":[["76379.4","0.01898074","1"],["76461.1","0","0"]],"bids":[]}
{"instId":"BTC-USDT","action":"update","ts":"1776816031990","asks":[],"bids":[["76302.5","0","0"],["76276.3","0.00001501","1"],["76168.9","0.000015","1"]]}
{"instId":"BTC-USDT","action":"update","ts":"1776816032010","asks":[["76344.5","0.00654817","1"],["76345.8","0","0"]],"bids":[["76323.8","0.00654813","1"],["76323.7","0","0"]]}
{"instId":"BTC-USDT","action":"update","ts":"1776816032020","asks":[],"bids":[["76323.9","0.00654823","1"],["76323.8","0","0"]]}
{"instId":"BTC-USDT","action":"update","ts":"1776816032030","asks":[["76344.5","0","0"],["76344.6","0.04211423","2"],["76461.1","0.00003024","1"]],"bids":[["76324","0.00654824","1"],["76323.9","0","0"]]}
{"instId":"BTC-USDT","action":"update","ts":"1776816032040","asks":[["76344.6","0.03556599","1"],["76345.8","0.00654824","1"],["76461.1","0","0"]],"bids":[["76324","0","0"],["76323.6","0.00655858","2"],["76318","0.00654817","1"],["76315.3","0.00001681","1"]]}
{"instId":"BTC-USDT","action":"update","ts":"1776816032050","asks":[],"bids":[["76302.5","0.00002863","1"],["76276.3","0.00324899","2"],["76168.9","0","0"]]}
{"instId":"BTC-USDT","action":"update","ts":"1776816032060","asks":[],"bids":[["76318","0","0"],["76315.3","0.00656498","2"],["76168.9","0.000015","1"]]}
{"instId":"BTC-USDT","action":"update","ts":"1776816032080","asks":[],"bids":[["76318","0.00654816","1"],["76315.3","0.00001681","1"],["76168.9","0","0"]]}
{"instId":"BTC-USDT","action":"update","ts":"1776816032100","asks":[],"bids":[["76324.8","0.01531169","1"],["76170.2","0","0"]]}
{"instId":"BTC-USDT","action":"update","ts":"1776816032110","asks":[],"bids":[["76324.9","0.00654821","1"],["76323.6","0.00001034","1"],["76170.8","0","0"]]}
{"instId":"BTC-USDT","action":"update","ts":"1776816032120","asks":[],"bids":[["76324.8","0","0"],["76170.8","0.00003094","3"]]}
{"instId":"BTC-USDT","action":"update","ts":"1776816032130","asks":[],"bids":[["76325","0.00654806","1"],["76324.9","0","0"],["76315.4","0.0156745","1"],["76170.8","0","0"]]}
{"instId":"BTC-USDT","action":"update","ts":"1776816032140","asks":[],"bids":[["76325.1","0.00654806","1"],["76325","0","0"]]}
{"instId":"BTC-USDT","action":"update","ts":"1776816032150","asks":[],"bids":[["76325.2","0.00654806","1"],["76325.1","0","0"]]}
{"instId":"BTC-USDT","action":"update","ts":"1776816032160","asks":[],"bids":[["76325.3","0.00654807","1"],["76325.2","0","0"]]}
{"instId":"BTC-USDT","action":"update","ts":"1776816032170","asks":[],"bids":[["76325.4","0.00654811","1"],["76325.3","0","0"]]}
{"instId":"BTC-USDT","action":"update","ts":"1776816032180","asks":[],"bids":[["76325.4","0","0"],["76323.6","0.00655844","2"],["76170.8","0.00003094","3"]]}
{"instId":"BTC-USDT","action":"update","ts":"1776816032250","asks":[["76363","0","0"],["76461.1","0.00003024","1"]],"bids":[]}
{"instId":"BTC-USDT","action":"update","ts":"1776816032260","asks":[["76345.8","0","0"],["76346.2","0.00654798","1"]],"bids":[["76326","0.00654798","1"],["76323.6","0.00001034","1"],["76170.8","0","0"]]}
{"instId":"BTC-USDT","action":"update","ts":"1776816032270","asks":[["76345.7","0.00654804","1"],["76346.2","0","0"]],"bids":[["76326","0.00654804","1"],["76318.6","0.33394899","2"],["76318","0","0"],["76264.9","0","0"],["76170.8","0.00003094","3"],["76170.2","0.00001385","1"]]}
{"instId":"BTC-USDT","action":"update","ts":"1776816032280","asks":[["76353","0","0"],["76353.4","0.0065482","1"]],"bids":[["76339.2","0.01047952","4"],["76337.1","0","0"],["76318.7","0.0065482","1"],["76318.6","0.32740067","1"],["76308.6","0.26155956","4"],["76201.3","0.08378297","1"],["76170.2","0","0"]]}
{"instId":"BTC-USDT","action":"update","ts":"1776816032300","asks":[["76372.9","0.1442248","2"],["76381.7","0.00001316","1"]],"bids":[]}
{"instId":"BTC-USDT","action":"update","ts":"1776816032310","asks":[["76380","0.33814283","2"],["76380.3","0","0"],["76461.3","0.00027039","1"]],"bids":[["76280.4","0.00001199","1"],["76270","0.00019775","1"],["76170.8","0","0"]]}
{"instId":"BTC-USDT","action":"update","ts":"1776816032320","asks":[],"bids":[["76307.3","0.32872108","2"]]}
{"instId":"BTC-USDT","action":"update","ts":"1776816032330","asks":[["76345.7","0","0"],["76345.8","0.00654798","1"],["76353","0.00654825","1"],["76353.4","0","0"]],"bids":[["76326","0","0"],["76323.6","0.00655832","2"],["76318.7","0","0"],["76318","0.00654822","1"],["76170.8","0.00003094","3"]]}
{"instId":"BTC-USDT","action":"update","ts":"1776816032380","asks":[["76413.1","0","0"],["76461.4","0.0312605","1"]],"bids":[["76326","0.00654817","1"],["76323.6","0.00001034","1"],["76170.8","0","0"]]}
{"instId":"BTC-USDT","action":"update","ts":"1776816032390","asks":[["76375.6","0.20084096","1"],["76411.5","0.10805133","1"],["76461.4","0","0"]],"bids":[]}
{"instId":"BTC-USDT","action":"update","ts":"1776816032400","asks":[],"bids":[["76326","0","0"],["76323.6","0.00655852","2"],["76170.8","0.00003094","3"]]}
{"instId":"BTC-USDT","action":"update","ts":"1776816032410","asks":[],"bids":[["76326","0.00654819","1"],["76323.6","0.00001034","1"],["76256.6","0.00054216","1"],["76170.8","0","0"]]}
{"instId":"BTC-USDT","action":"update","ts":"1776816032420","asks":[],"bids":[["76326","0","0"],["76323.6","0.00655853","2"],["76170.8","0.00003094","3"]]}
{"instId":"BTC-USDT","action":"update","ts":"1776816032430","asks":[["76402.7","0","0"],["76461.4","0.0312605","1"]],"bids":[]}
{"instId":"BTC-USDT","action":"update","ts":"1776816032470","asks":[["76428","0.12","1"],["76461.4","0","0"]],"bids":[["76244.9","0.12","1"],["76170.8","0","0"]]}
{"instId":"BTC-USDT","action":"update","ts":"1776816032480","asks":[["76402.7","0.00003978","1"],["76461.3","0","0"]],"bids":[]}
{"instId":"BTC-USDT","action":"update","ts":"1776816032570","asks":[["76441.1","0.00016","2"]],"bids":[]}
{"instId":"BTC-USDT","action":"update","ts":"1776816032620","asks":[["76345.7","0.16","1"],["76461.1","0","0"]],"bids":[]}
{"instId":"BTC-USDT","action":"update","ts":"1776816032630","asks":[["76344.6","0.08073352","2"],["76390.5","1.92417942","1"],["76460.9","0","0"]],"bids":[]}
{"instId":"BTC-USDT","action":"update","ts":"1776816032640","asks":[["76388.6","0.72392951","2"],["76434.8","0.47151308","1"]],"bids":[]}
{"instId":"BTC-USDT","action":"update","ts":"1776816032650","asks":[],"bids":[["76339.2","0.07297952","5"]]}
{"instId":"BTC-USDT","action":"update","ts":"1776816032660","asks":[],"bids":[["76339.2","0.01047952","4"]]}
{"instId":"BTC-USDT","action":"update","ts":"1776816032700","asks":[["76339.3","1.64198382","21"]],"bids":[["76339.2","0.10277952","6"]]}
{"instId":"BTC-USDT","action":"update","ts":"1776816032710","asks":[],"bids":[["76339.2","0.07297952","5"],["76277.2","0.00019775","1"],["76270","0","0"]]}
{"instId":"BTC-USDT","action":"update","ts":"1776816032760","asks":[["76421.3","0.99511","1"],["76452","0.00005546","1"],["76460.7","0","0"]],"bids":[]}
{"instId":"BTC-USDT","action":"update","ts":"1776816032770","asks":[["76418.9","0.47726211","3"]],"bids":[]}
{"instId":"BTC-USDT","action":"update","ts":"1776816032880","asks":[],"bids":[["76339.2","0.01047952","4"]]}
{"instId":"BTC-USDT","action":"update","ts":"1776816032890","asks":[],"bids":[["76339.2","0.07297952","5"]]}
{"instId":"BTC-USDT","action":"update","ts":"1776816032900","asks":[],"bids":[["76339.2","0.01047952","4"],["76318","0.00654813","1"]]}
{"instId":"BTC-USDT","action":"update","ts":"1776816032910","asks":[],"bids":[["76318","0","0"],["76315.5","0.00654811","1"],["76277.2","0","0"],["76270","0.00019775","1"]]}
{"instId":"BTC-USDT","action":"update","ts":"1776816032940","asks":[["76362.7","0.48753147","2"]],"bids":[["76318","0.0065481","1"],["76315.5","0","0"],["76315.4","0","0"],["76170.8","0.00003094","3"]]}
{"instId":"BTC-USDT","action":"update","ts":"1776816033000","asks":[["76339.3","1.64199382","22"]],"bids":[]}
{"instId":"BTC-USDT","action":"update","ts":"1776816033030","asks":[],"bids":[["76318","0","0"],["76315.3","0.00656491","2"],["76170.2","0.00001385","1"]]}
{"instId":"BTC-USDT","action":"update","ts":"1776816033040","asks":[],"bids":[["76318","0.0065481","1"],["76315.3","0.00001681","1"],["76170.2","0","0"]]}
{"instId":"BTC-USDT","action":"update","ts":"1776816033090","asks":[],"bids":[["76318","0","0"],["76315.3","0.00656493","2"],["76170.2","0.00001385","1"]]}
{"instId":"BTC-USDT","action":"update","ts":"1776816033110","asks":[],"bids":[["76318","0.00654812","1"],["76315.3","0.00001681","1"],["76170.2","0","0"]]}
{"instId":"BTC-USDT","action":"update","ts":"1776816033120","asks":[["76344.5","0.23096158","3"],["76345.8","0","0"],["76349.3","0.02","1"],["76350","0.04","2"],["76357.8","0","0"],["76380.3","0.00130923","1"],["76389","0","0"],["76391.4","0","0"],["76460.7","0.00167279","1"]],"bids":[["76332","0","0"],["76330.3","0","0"],["76329","0.01","1"],["76328.9","0.02001034","2"],["76323.6","0.00655842","2"],["76321.9","0.00001501","1"],["76321.8","0.01545997","2"],["76318.4","0","0"],["76318.3","0.00001034","1"],["76318","0","0"],["76315.3","0.00656495","2"],["76307.3","0.24493811","1"],["76288.9","0.345682","1"],["76284.9","0","0"],["76198.3","0","0"],["76173.1","1.00603555","1"],["76170.2","0.00001385","1"],["76168.9","0.000015","1"],["76168.4","0.00011049","4"],["76167","0.00001319","1"]]}
{"instId":"BTC-USDT","action":"update","ts":"1776816033130","asks":[["76344.4","0.1588161","2"],["76344.5","0.2244135","2"],["76344.6","0","0"],["76348.1","0.32742501","2"],["76349.3","0","0"],["76349.9","0.04256511","3"],["76353","0","0"],["76353.6","0.11674988","1"],["76353.7","0","0"],["76359.2","0","0"],["76361.6","0","0"],["76367.6","0.11007353","2"],["76375.8","0","0"],["76384.4","0.11674988","1"],["76384.5","0","0"],["76429.5","0.04964509","1"],["76460.9","0.00030148","3"],["76461.1","0.00003024","1"],["76461.3","0.00027039","1"],["76461.4","0.0312605","1"],["76461.5","0.01228943","9"]],"bids":[["76325.9","0","0"],["76323.6","0.00001034","1"],["76323","0.01496564","2"],["76322.8","0.00678552","6"],["76322.7","0.06289816","1"],["76321.8","0.00001033","1"],["76318.6","0","0"],["76318.5","0","0"],["76315.3","0.3339768","3"],["76315","0","0"],["76311.5","0.00001681","1"],["76310.6","0.11557361","2"],["76310.2","1.00603555","1"],["76310.1","0","0"],["76307.4","0.47151308","1"],["76307.2","0","0"],["76303.3","0","0"],["76289.8","0.00001033","1"],["76288.9","0","0"],["76193.5","0.08378297","1"],["76168.6","0.1305","1"],["76166.6","0.00248493","6"],["76166.2","0.00026145","4"],["76165.9","0.47151308","1"],["76165.8","0.01614584","1"]]}
{"instId":"BTC-USDT","action":"update","ts":"1776816033140","asks":[["76344.3","0.13532372","1"],["76344.7","0.00001316","1"],["76346","0","0"],["76346.3","0.28184269","2"],["76353.8","0","0"],["76361.6","0.11187103","1"],["76368.1","0.00002911","1"],["76375.5","0.11674988","1"],["76429.5","0","0"],["76461.5","0.14278943","10"]],"bids":[["76323.4","0","0"],["76323","0.00001155","1"],["76322.6","0.11673366","1"],["76318.3","0.03677009","2"],["76316.5","0.0589735","2"],["76315.2","0","0"],["76314.1","0.13355","2"],["76307.3","0","0"],["76306.9","0","0"],["76285.8","0.12945811","2"],["76260.3","0.35944954","3"],["76165.2","0.00091086","3"],["76165.1","0.00001015","1"],["76164.3","0.00046091","2"],["76163.9","0.00005592","3"]]}
{"instId":"BTC-USDT","action":"update","ts":"1776816033150","asks":[["76348.1","0.00001316","1"],["76349.4","0.32742174","1"],["76350.2","0.01309","1"],["76353.1","0","0"],["76371.3","0.29343","1"],["76380.1","0","0"],["76461.5","0","0"]],"bids":[["76333.7","0","0"],["76325.7","0.0131","1"],["76323.5","0","0"],["76320","0.01503588","2"],["76316.6","0.32742174","1"],["76315.4","0.26974017","1"],["76315.3","0.00656495","2"],["76314.2","0.47151308","1"],["76307.8","0","0"],["76294.1","0.2822","1"],["76164.3","0","0"],["76163.9","0","0"]]}
{"instId":"BTC-USDT","action":"update","ts":"1776816033160","asks":[["76348.1","0.32743445","2"],["76349.4","0","0"],["76349.9","0.04256517","3"],["76380","0.25094478","2"],["76461.5","0.01228943","9"]],"bids":[["76318.3","0.14740617","3"],["76315.4","0.27628854","2"],["76315.3","0.00001681","1"],["76310.4","0","0"],["76284.9","0.11674988","1"]]}
{"instId":"BTC-USDT","action":"update","ts":"1776816033170","asks":[["76347.7","0.02","1"],["76387.9","1.92417942","1"],["76390.5","0","0"],["76409.1","0.01598","1"],["76423.5","0.00005351","2"],["76461.4","0","0"],["76461.5","0","0"]],"bids":[["76318.6","0.00305","1"],["76314.1","0.1305","1"],["76310.6","0.65192517","3"],["76165.1","0","0"]]}
{"instId":"BTC-USDT","action":"update","ts":"1776816033180","asks":[["76349.5","0.09033133","2"],["76349.9","0.0360168","2"],["76354.6","0.21213892","3"],["76387.8","0.71512262","1"],["76388.6","0","0"]],"bids":[["76315.4","0.26974017","1"],["76314.6","0.00656152","2"],["76307.5","0.25413753","6"],["76289.5","0.47151308","1"]]}
{"instId":"BTC-USDT","action":"update","ts":"1776816033190","asks":[["76347","0.05303473","1"],["76461.3","0","0"]],"bids":[["76292.5","0.23239791","1"]]}
{"instId":"BTC-USDT","action":"update","ts":"1776816033200","asks":[["76344.2","0.00654817","1"],["76344.4","0.15226802","1"],["76354.6","0.15910419","2"],["76461.1","0","0"]],"bids":[["76322.8","0.00023744","5"],["76322.1","0.00654817","1"],["76289","0","0"],["76287.4","0.00325294","1"],["76165.2","0","0"]]}
{"instId":"BTC-USDT","action":"update","ts":"1776816033210","asks":[["76340.9","0.00654817","1"],["76344.2","0.13001691","1"],["76344.5","0.08378297","1"],["76344.8","0.01614584","1"],["76347","0.10606946","2"],["76347.4","0.32742091","1"],["76348.1","0.00001316","1"],["76349.4","0.0065484","1"],["76349.5","0.08378297","1"],["76354.6","0.05303473","1"],["76433.4","0.00001198","1"],["76444.2","0.01802","1"],["76460.1","0","0"],["76460.2","0","0"],["76460.6","0","0"],["76460.7","0","0"],["76460.9","0","0"]],"bids":[["76322.1","0","0"],["76322","0","0"],["76321.5","0.00654817","1"],["76316.6","0","0"],["76315.5","0.32742091","1"],["76314.6","0.00001316","1"],["76312.6","0.0065484","1"],["76265.1","0","0"],["76262.1","0.00013113","1"],["76260.4","0.22966112","2"],["76256.6","0","0"],["76253.5","0.49987951","3"],["76165.2","0.00091086","3"]]}
{"instId":"BTC-USDT","action":"update","ts":"1776816033220","asks":[["76344.2","0.29345572","2"],["76344.4","0","0"],["76347","0.21213892","3"],["76460.1","0.0022005","4"]],"bids":[["76330.2","0","0"],["76322.7","0.04424128","1"],["76165.1","0.00001015","1"]]}
{"instId":"BTC-USDT","action":"update","ts":"1776816033230","asks":[["76332.3","1.10386157","16"],["76334.3","0.47525855","2"],["76338.6","0.31751631","2"],["76338.7","0.76183173","5"],["76339.1","0.16","1"],["76339.2","0.036","1"],["76339.3","0.63243028","6"],["76339.9","0","0"],["76340.8","0.00654823","1"],["76340.9","0","0"],["76341","0.03645056","2"],["76341.3","0.00001316","1"],["76344.2","0.24800372","2"],["76344.4","0.32742262","1"],["76345.7","0","0"],["76345.9","0","0"],["76346.2","1.00603555","1"],["76347","0","0"],["76347.4","0","0"],["76347.7","0.1505","2"],["76354.6","0","0"],["76430.8","0","0"],["76435.1","0.00001253","1"],["76436.9","0","0"],["76460.1","0","0"]],"bids":[["76339.2","0","0"],["76338.6","0","0"],["76338.2","0","0"],["76338.1","0","0"],["76336","0","0"],["76334.7","0","0"],["76334.4","0","0"],["76334.2","0","0"],["76332.2","0.09458884","4"],["76331.4","0","0"],["76329","0.0408514","1"],["76328.9","0.00001034","1"],["76327.8","0","0"],["76326.3","0.01","1"],["76326.2","0.02","1"],["76315.5","0.06550532","1"],["76314.5","0","0"],["76314.2","0.47806148","2"],["76312.6","0.32742262","1"],["76308.6","0","0"],["76290.7","0.12473187","2"],["76285.6","0","0"],["76284.9","0","0"],["76281","0.00001316","1"],["76235.5","0.00001316","1"],["76234","0","0"],["76164.3","0.00046091","2"],["76163.9","0.00005592","3"],["76162.2","0.00002057","1"],["76162.1","0.00004159","3"],["76162","0.00001017","1"],["76161.2","0.00007766","2"],["76161.1","0.0000827","1"],["76160.4","0.01614584","1"],["76160.2","0.00705391","1"],["76160","0.00187493","7"],["76159.3","0.00040006","1"],["76159.1","0.00002078","1"]]}
{"instId":"BTC-USDT","action":"update","ts":"1776816033240","asks":[["76332.3","1.1249615","19"],["76334.2","0.14186468","1"],["76334.3","0.47151308","1"],["76338.6","0","0"],["76338.7","0.53541577","4"],["76339.1","0.00654834","1"],["76339.3","0.53689308","3"],["76340","0.05303473","1"],["76340.8","0","0"],["76344.2","0.11798681","1"],["76344.4","0","0"],["76346.1","0.32742595","1"],["76346.3","0.28839115","3"],["76347.6","0.21213892","3"],["76349.4","0","0"],["76350.2","0.09215","2"],["76377.5","0.026192","1"],["76385.2","0","0"],["76418.6","0.00001316","1"],["76422.4","0.46189407","2"],["76425.6","0.47153419","3"]],"bids":[["76332.2","0.00004629","1"],["76329","0","0"],["76326.3","0","0"],["76326.2","0","0"],["76321.5","0","0"],["76318.7","0.00654834","1"],["76318.3","0.06922412","2"],["76317.1","0.01575842","1"],["76314.5","0.12737518","1"],["76314.2","0","0"],["76312.6","0.32742595","1"],["76311.4","0.00654846","1"],["76310.5","0","0"],["76310.2","0","0"],["76307.4","0","0"],["76303.8","0.0000168","1"],["76301.6","0.05167657","1"],["76290","0","0"],["76285.9","0.13281862","2"],["76285.8","0.00131085","1"],["76285.7","0","0"],["76284.9","0.10421991","1"],["76281.1","0","0"],["76273.4","0.10474668","1"],["76160.9","0.1305","1"],["76158.5","0.0002223","1"],["76157.8","0.00003012","1"],["76157.7","0.00011366","1"]]}
{"instId":"BTC-USDT","action":"update","ts":"1776816033250","asks":[["76338.5","0.13042212","1"],["76338.7","0.34984075","3"],["76339.1","0","0"],["76340.9","0.00654838","1"],["76344.1","0.14595073","1"],["76344.2","0.07022681","1"],["76344.8","0.01616085","2"],["76346.1","0","0"],["76346.3","0.60927826","3"],["76349.4","0.00654866","1"],["76357.4","0.012","1"],["76362","0","0"],["76362.7","0.47151308","1"],["76384.4","0","0"],["76403.2","0.9982","1"],["76435.9","0","0"],["76460","0","0"]],"bids":[["76330.4","0.09253743","7"],["76322.7","0.07044128","2"],["76321.2","0.00657378","3"],["76320","0.0000812","1"],["76318.7","0","0"],["76317.1","0","0"],["76315.6","0.3274459","2"],["76314.5","1.13995939","3"],["76312.6","0","0"],["76311.4","0","0"],["76311.3","0.00700101","6"],["76310.7","0.52323957","2"],["76310.6","0.11557361","2"],["76310.2","0.01555045","1"],["76307.6","1.47754863","2"],["76307.5","0.00023747","5"],["76304","0.47151308","1"],["76303.9","0","0"],["76296.4","0","0"],["76284.7","0.47152988","2"],["76277.2","0.12472153","1"],["76273.5","0.13533613","1"],["76273.4","0","0"],["76254.6","0.96359","1"],["76173.1","0","0"],["76160","0.01221613","8"],["76157.6","0.47151308","1"]]}
{"instId":"BTC-USDT","action":"update","ts":"1776816033260","asks":[["76330.5","1.00094236","17"],["76330.7","0.45240077","3"],["76332.2","0.4726564","4"],["76332.3","0.34986728","7"],["76334.2","0","0"],["76338.4","0.00654835","1"],["76340","0","0"],["76340.9","0","0"],["76344","0.44123682","2"],["76344.2","0","0"],["76346.1","0.71964436","2"],["76346.3","0","0"],["76347.6","0","0"],["76349.4","0","0"],["76349.6","0.04693631","2"],["76351.1","0.012","1"],["76361.8","1.06485852","2"],["76380.1","1.92417942","1"],["76387.9","0","0"],["76418.9","0.05960455","1"],["76422.4","0.00015119","1"]],"bids":[["76332.2","0","0"],["76330.6","0","0"],["76330.4","0.09373743","8"],["76321.2","0.0000254","2"],["76318.6","0","0"],["76318.3","0.16281445","3"],["76318.1","0","0"],["76318","0.00654835","1"],["76317.3","0.01495521","1"],["76315.6","0.00001033","1"],["76315.4","0.47011529","2"],["76314.5","1.13341073","2"],["76312.6","0.32743924","1"],["76312.5","0.00010586","1"],["76311.1","0.00305","1"],["76311","0.00654859","1"],["76310.8","0.21255531","1"],["76310.7","0.47151308","1"],["76304.7","0.12205331","2"],["76304.2","0.00305","1"],["76301.9","0.00305","1"],["76301.6","0","0"],["76299.8","0.06692464","2"],["76296.4","0.10516375","1"],["76287.4","0.00325299","1"],["76273.6","0.1070685","2"],["76273.5","0","0"],["76157.8","0","0"],["76157.7","0","0"],["76157.6","0","0"]]}
{"instId":"BTC-USDT","action":"update","ts":"1776816033270","asks":[["76330.5","1.00730722","19"],["76330.7","0.44865524","2"],["76332.2","0.15751631","1"],["76332.3","0.17225147","2"],["76338.6","0.25212046","1"],["76338.7","0.13163","2"],["76343.9","0.32743608","1"],["76344","0.11379758","1"],["76344.3","0","0"],["76380.1","0","0"],["76387.8","0","0"],["76387.9","1.92417942","1"]],"bids":[["76318.3","0.06922412","2"],["76315.7","0.00305","1"],["76312.6","0","0"],["76311.1","0","0"],["76310.9","0.35251608","2"],["76307.7","0.69504637","3"],["76157.8","0.00003012","1"]]}
{"instId":"BTC-USDT","action":"update","ts":"1776816033280","asks":[["76330.6","0.37310593","1"],["76330.7","0","0"],["76338.6","0","0"],["76344","0","0"],["76460","0.03539391","5"],["76460.1","0.0022005","4"]],"bids":[["76323.8","0.03","2"],["76300.5","0.23326477","1"],["76298.5","0","0"],["76157.8","0","0"]]}
{"instId":"BTC-USDT","action":"update","ts":"1776816033290","asks":[["76330.6","0.23918234","1"],["76338.6","0.18698455","1"],["76345.8","0.15910419","2"],["76358.9","0.07922","1"],["76460","0","0"],["76460.1","0","0"]],"bids":[["76322.7","0.04424128","1"],["76287.4","0","0"],["76286.5","0","0"],["76286","0.0826503","1"],["76281.7","0.00325299","1"],["76279.4","0.00233684","1"],["76278.6","0.14388433","1"],["76159.1","0","0"],["76158.5","0","0"]]}
{"instId":"BTC-USDT","action":"update","ts":"1776816033300","asks":[["76332.2","0","0"],["76332.3","0.01473516","1"],["76341.6","0","0"],["76343.8","0.21863572","1"],["76460","0.03539391","5"]],"bids":[["76302.5","0","0"],["76254.9","0.32848345","3"],["76159.1","0.00002078","1"]]}
{"instId":"BTC-USDT","action":"update","ts":"1776816033310","asks":[["76330.6","0.1451451","1"],["76338.4","0","0"],["76343.7","0.00654864","1"],["76343.9","0","0"],["76346.1","1.0405332","2"],["76348.4","0.07899","1"],["76349.4","0.00654866","1"],["76353.5","0.15679259","2"],["76361.6","0","0"],["76449.9","0.00006845","2"]],"bids":[["76330.4","0.09253743","7"],["76328.1","0.00004124","1"],["76321.5","0.00654864","1"],["76318","0","0"],["76314.6","0.32745059","2"],["76314.5","0.12737518","1"],["76314.2","0.00654866","1"],["76311.3","0.00023744","5"],["76311","0","0"],["76310.9","0.02508","1"],["76304.1","0.08378297","1"],["76292.4","0.066386","2"],["76279.4","0","0"],["76277.3","0.0023369","1"],["76253.5","0.49933734","2"],["76248.9","0.00054217","1"],["76237.9","1.92928236","4"],["76173.1","1.00603555","1"],["76160.2","0","0"],["76160","0","0"],["76159.3","0","0"],["76159.1","0","0"]]}
{"instId":"BTC-USDT","action":"update","ts":"1776816033320","asks":[["76330.5","0.91068803","18"],["76339.2","0.04254852","2"],["76339.3","0.53696684","4"],["76342.9","0.00001086","1"],["76343.7","0","0"],["76343.8","0.12089605","1"],["76345.8","0.26517365","4"],["76347.4","0.00654865","1"],["76349.4","0","0"],["76359","0","0"],["76376.3","0.00147314","4"],["76384.5","0.10478166","1"],["76420.8","0.659522","2"],["76425.1","0.657959","1"],["76460","0","0"]],"bids":[["76330.4","0.09373743","8"],["76321.5","0","0"],["76318.4","0.00654852","1"],["76315.4","0.26974017","1"],["76314.2","0","0"],["76311.4","0.00654865","1"],["76299.8","0.2777054","5"],["76275.6","0.659248","1"],["76270.9","0.66081516","2"],["76262.1","0","0"],["76257.5","0.00013113","1"],["76235.3","0.4258517","2"],["76184.4","1.00603555","1"],["76184.3","0","0"],["76173.2","1.00604561","2"],["76173.1","0","0"]]}
{"instId":"BTC-USDT","action":"update","ts":"1776816033330","asks":[["76339.3","0.53713051","8"],["76340.6","0.00001034","1"],["76341.4","0.00001033","1"],["76344.4","0.00001154","1"],["76349.9","0.036","1"],["76352.4","0.13270062","2"],["76353.6","0","0"],["76371.8","0","0"],["76373.7","0.10604517","1"],["76376.3","0","0"],["76387.8","0.71512262","1"],["76459.9","0","0"]],"bids":[["76273.3","0.46000372","3"]]}
{"instId":"BTC-USDT","action":"update","ts":"1776816033340","asks":[["76342.9","0.10630566","2"],["76349.6","0.08738912","1"],["76379.5","0","0"],["76396.2","0.00003978","1"],["76402.7","0","0"],["76459.9","0.0000212","1"]],"bids":[["76276.3","0.00001501","1"],["76269.4","0.00323409","1"],["76160.4","0","0"]]}
{"instId":"BTC-USDT","action":"update","ts":"1776816033350","asks":[["76330.5","0.91067122","17"],["76339.2","0.036","1"],["76340.9","0.00654851","1"],["76379.4","0","0"],["76387.9","0","0"],["76402.8","0.33194406","2"],["76408.7","1.92417942","1"]],"bids":[["76330.4","0.37875429","10"],["76318.4","0.00654851","1"]]}
{"instId":"BTC-USDT","action":"update","ts":"1776816033360","asks":[["76358.9","0","0"],["76387.8","0.14075506","1"],["76460","0.03539391","5"]],"bids":[]}
{"instId":"BTC-USDT","action":"update","ts":"1776816033370","asks":[["76344.5","0","0"],["76393.9","0.00003978","1"],["76396.2","0","0"],["76406.9","1.05271061","3"],["76460.1","0.0022005","4"]],"bids":[["76302.5","0.00002863","1"],["76291.5","0.100015","2"],["76269.4","0","0"],["76266.4","0.00323413","1"],["76160.9","0","0"]]}
{"instId":"BTC-USDT","action":"update","ts":"1776816033380","asks":[],"bids":[["76330.4","0.37755429","9"]]}
{"instId":"BTC-USDT","action":"update","ts":"1776816033390","asks":[["76330.5","0.97371122","18"],["76339.3","0.47176051","7"]],"bids":[["76330.4","0.38017365","10"],["76314.5","1.13341073","2"],["76173.2","0.00001006","1"]]}
{"instId":"BTC-USDT","action":"update","ts":"1776816033400","asks":[],"bids":[["76322.7","0.07044128","2"],["76315.4","0.53105074","2"]]}
{"instId":"BTC-USDT","action":"update","ts":"1776816033410","asks":[],"bids":[["76302.5","0","0"],["76160.4","0.01614584","1"]]}
{"instId":"BTC-USDT","action":"update","ts":"1776816033420","asks":[["76340.6","0","0"],["76345.9","0.0000672","1"],["76359","0.00032403","1"],["76369","0.44108291","2"],["76376.3","0.00181168","3"],["76460","0","0"],["76460.1","0","0"]],"bids":[["76266.4","0","0"],["76160.9","0.1305","1"]]}
{"instId":"BTC-USDT","action":"update","ts":"1776816033430","asks":[["76344.4","0","0"],["76370.3","0.00006929","1"],["76376.3","0.00237448","5"]],"bids":[]}
{"instId":"BTC-USDT","action":"update","ts":"1776816033450","asks":[],"bids":[["76330.4","0.37755429","9"]]}
{"instId":"BTC-USDT","action":"update","ts":"1776816033470","asks":[["76371.7","0.06390608","1"],["76459.9","0","0"]],"bids":[["76291.5","0.000015","1"]]}
{"instId":"BTC-USDT","action":"update","ts":"1776816033480","asks":[["76344.8","0.00001501","1"]],"bids":[["76294.5","0.00002864","1"],["76266.4","0.00323413","1"],["76160.9","0","0"],["76160.4","0","0"]]}
{"instId":"BTC-USDT","action":"update","ts":"1776816033490","asks":[],"bids":[["76328.1","0.00005478","2"],["76294.5","0","0"],["76293.7","0.00002864","1"]]}
{"instId":"BTC-USDT","action":"update","ts":"1776816033530","asks":[["76340.6","0.00001034","1"],["76344.4","0.00001154","1"],["76459.7","0","0"],["76459.8","0","0"]],"bids":[]}
{"instId":"BTC-USDT","action":"update","ts":"1776816033540","asks":[],"bids":[["76322.7","0.04424128","1"],["76317.3","0","0"],["76160.4","0.01614584","1"]]}
{"instId":"BTC-USDT","action":"update","ts":"1776816033550","asks":[],"bids":[["76319.7","0.01495474","1"],["76231","0.08378297","1"],["76160.4","0","0"]]}
{"instId":"BTC-USDT","action":"update","ts":"1776816033560","asks":[],"bids":[["76293.7","0","0"],["76289.7","0.1","1"]]}
{"instId":"BTC-USDT","action":"update","ts":"1776816033570","asks":[["76368.5","0.00003694","1"],["76376.3","0.00081686","2"],["76459.6","0","0"]],"bids":[["76296","0.00021816","8"],["76292.2","0.00017509","4"],["76288.4","0.00017509","4"],["76284.6","0.0001751","4"],["76280.8","0.0001751","4"],["76276.9","0.0001751","4"],["76273.1","0.0001751","4"],["76269.3","0.07145612","5"],["76265.5","0.00017513","4"],["76261.7","0.00017513","4"],["76165.1","0","0"],["76164.3","0","0"],["76163.9","0","0"],["76162.2","0","0"],["76162.1","0","0"],["76162","0","0"],["76161.2","0","0"],["76161.1","0","0"]]}
{"instId":"BTC-USDT","action":"update","ts":"1776816033580","asks":[["76376.3","0.00019343","1"]],"bids":[["76296","0.0002805","9"],["76292.2","0.00023743","5"],["76288.4","0.00023743","5"],["76284.6","0.00023744","5"],["76280.8","0.00023744","5"],["76276.9","0.00023744","5"],["76273.1","0.00023744","5"],["76269.3","0.07151847","6"],["76265.5","0.00023748","5"],["76261.7","0.00023748","5"]]}
{"instId":"BTC-USDT","action":"update","ts":"1776816033610","asks":[["76385.3","1.92417942","1"],["76408.7","0","0"]],"bids":[]}
{"instId":"BTC-USDT","action":"update","ts":"1776816033620","asks":[["76384.6","1.03327172","2"],["76406.9","0.67597148","2"]],"bids":[]}
{"instId":"BTC-USDT","action":"update","ts":"1776816033630","asks":[],"bids":[["76295.2","0.14741558","2"]]}
{"instId":"BTC-USDT","action":"update","ts":"1776816033660","asks":[["76368.7","0.00073763","1"],["76459.3","0","0"]],"bids":[["76293.7","0.00002864","1"],["76165.2","0","0"]]}
{"instId":"BTC-USDT","action":"update","ts":"1776816033670","asks":[["76368.7","0.00118825","2"]],"bids":[]}
{"instId":"BTC-USDT","action":"update","ts":"1776816033680","asks":[["76368.5","0","0"],["76368.7","0.00181168","3"],["76459.3","0.00319921","2"]],"bids":[]}
{"instId":"BTC-USDT","action":"update","ts":"1776816033710","asks":[["76396.3","0","0"],["76459.6","0.00072458","2"]],"bids":[]}
{"instId":"BTC-USDT","action":"update","ts":"1776816033750","asks":[["76400.2","0.01925245","1"],["76459.6","0","0"]],"bids":[["76281.4","0.05283311","3"],["76190.8","0.0147312","1"],["76165.8","0","0"]]}
{"instId":"BTC-USDT","action":"update","ts":"1776816033780","asks":[["76339.3","0.47172358","6"],["76368.5","0.00040631","1"],["76459.3","0","0"]],"bids":[]}
{"instId":"BTC-USDT","action":"update","ts":"1776816033800","asks":[["76330.5","0.96066896","18"],["76389.3","0.1","1"],["76459.2","0","0"]],"bids":[["76328.1","0.00004124","1"]]}
{"instId":"BTC-USDT","action":"update","ts":"1776816033810","asks":[],"bids":[["76330.4","0.38017359","10"]]}
{"instId":"BTC-USDT","action":"update","ts":"1776816033830","asks":[["76382.7","1.92409955","2"],["76385.3","0","0"],["76459.2","0.08410468","3"]],"bids":[]}
{"instId":"BTC-USDT","action":"update","ts":"1776816033840","asks":[["76380","0.79297729","3"],["76384.6","0.5441043","1"]],"bids":[]}
{"instId":"BTC-USDT","action":"update","ts":"1776816033850","asks":[["76382.7","0.0008","1"],["76385.3","1.92329955","1"],["76459.2","0","0"]],"bids":[]}
{"instId":"BTC-USDT","action":"update","ts":"1776816033860","asks":[["76380","0.25094478","2"],["76384.6","1.03300908","2"]],"bids":[]}
{"instId":"BTC-USDT","action":"update","ts":"1776816033870","asks":[],"bids":[["76211.3","0.08892959","2"]]}
{"instId":"BTC-USDT","action":"update","ts":"1776816033890","asks":[["76338.1","0.00003693","1"],["76459.1","0","0"]],"bids":[]}
{"instId":"BTC-USDT","action":"update","ts":"1776816033900","asks":[["76342.9","0.00001086","1"],["76360.5","0.01562739","1"],["76458.8","0","0"]],"bids":[["76328","0.00003609","3"]]}
{"instId":"BTC-USDT","action":"update","ts":"1776816033920","asks":[["76338.1","0.15930682","2"],["76340.9","0.00654827","1"],["76345.7","0.32741947","1"],["76346.1","0.71309577","1"],["76366.9","0.13657409","2"],["76382.7","1.92409955","2"],["76385.3","0","0"]],"bids":[["76330.4","0.16015728","8"],["76319.8","0.00654827","1"],["76318.4","0","0"],["76314.7","0.32741947","1"],["76314.6","0.00001316","1"],["76310.2","0","0"],["76285.8","0","0"],["76281.4","0.03349534","2"],["76277.6","0.00132416","2"],["76190.8","0","0"],["76165.8","0.01614584","1"],["76165.2","0.00091086","3"]]}
{"instId":"BTC-USDT","action":"update","ts":"1776816033930","asks":[["76338","0.04755309","1"],["76345.6","0.08378297","1"],["76382.7","0.0008","1"],["76384.6","0.5441043","1"],["76385.3","1.92329955","1"],["76458.3","0","0"],["76458.4","0","0"],["76458.7","0","0"]],"bids":[["76330.4","0.22003798","8"]]}
{"instId":"BTC-USDT","action":"update","ts":"1776816033940","asks":[["76338.5","0","0"],["76343.8","0.23002009","2"],["76458.3","0.00035006","7"]],"bids":[]}
{"instId":"BTC-USDT","action":"update","ts":"1776816033950","asks":[["76384.6","1.03300908","2"]],"bids":[]}
{"instId":"BTC-USDT","action":"update","ts":"1776816033960","asks":[["76339.1","0.00654846","1"],["76340.9","0","0"],["76345.5","0.32743036","1"],["76345.7","0","0"]],"bids":[["76319.8","0","0"],["76318.4","0.00654846","1"],["76314.7","0","0"],["76310.9","0.35251036","2"],["76165.1","0.00001015","1"]]}
{"instId":"BTC-USDT","action":"update","ts":"1776816033970","asks":[],"bids":[["76310.9","0.35251039","2"]]}
{"instId":"BTC-USDT","action":"update","ts":"1776816033980","asks":[["76338","0.15684304","2"]],"bids":[]}
{"instId":"BTC-USDT","action":"update","ts":"1776816033990","asks":[["76337.9","0.08017614","1"],["76338","0.10928995","1"],["76458.3","0","0"]],"bids":[["76328","0.00002349","2"]]}
{"instId":"BTC-USDT","action":"update","ts":"1776816034000","asks":[["76338.1","0.00003693","1"],["76360.5","0","0"],["76382.7","1.92409975","2"],["76385.3","0","0"],["76458.3","0.00035006","7"],["76458.4","0.0000711","2"]],"bids":[["76309","0.01591789","1"],["76165.1","0","0"]]}
{"instId":"BTC-USDT","action":"update","ts":"1776816034010","asks":[["76337.9","0.03263407","1"],["76345.6","0","0"],["76384.6","0.5441043","1"],["76458.7","0.01614584","1"]],"bids":[["76330.4","0.09253743","7"],["76314.5","1.60492381","3"],["76308","0.08379753","2"],["76193.5","0","0"],["76165.1","0.00001015","1"]]}
{"instId":"BTC-USDT","action":"update","ts":"1776816034020","asks":[["76337.8","0.14160511","1"],["76338.5","0.00654838","1"],["76339.1","0","0"],["76344","0.3274358","1"],["76345.5","0","0"],["76346.1","0.71964443","2"],["76347.4","0","0"],["76380","0.79297735","3"]],"bids":[["76330.4","0.03003743","6"],["76310.8","0","0"],["76235.3","0.08378297","1"],["76164.3","0.00046091","2"]]}
{"instId":"BTC-USDT","action":"update","ts":"1776816034030","asks":[["76337.7","0.0749032","1"],["76337.9","0","0"],["76345.8","0.27172231","5"],["76346.1","0.71309577","1"]],"bids":[["76311","0.3274582","1"],["76281.7","0","0"],["76280.4","0.00326515","2"],["76277.7","0.00233701","1"],["76277.3","0","0"]]}
{"instId":"BTC-USDT","action":"update","ts":"1776816034040","asks":[["76337.6","0.16051331","1"],["76338","0","0"],["76384.5","0","0"],["76458.8","0.00001501","1"]],"bids":[]}
{"instId":"BTC-USDT","action":"update","ts":"1776816034050","asks":[["76337.5","0.09019337","1"],["76337.7","0","0"],["76416.1","0","0"],["76459.1","0.00006716","3"]],"bids":[["76311.4","0","0"],["76311.1","0.00654866","1"]]}
{"instId":"BTC-USDT","action":"update","ts":"1776816034060","asks":[["76337.4","0.11509193","1"],["76337.8","0","0"],["76380.2","0","0"],["76459.2","0.08410468","3"]],"bids":[]}
{"instId":"BTC-USDT","action":"update","ts":"1776816034070","asks":[["76337.3","0.08227919","1"],["76337.5","0","0"]],"bids":[]}
{"instId":"BTC-USDT","action":"update","ts":"1776816034080","asks":[["76337.2","0.11376257","1"],["76337.6","0","0"],["76343.7","0.32743588","1"],["76344","0","0"]],"bids":[["76311.1","0.33398454","2"],["76310.9","0.02508","1"]]}
{"instId":"BTC-USDT","action":"update","ts":"1776816034090","asks":[["76337.1","0.06832409","1"],["76337.3","0","0"],["76343.7","0","0"],["76343.8","0.12089605","1"],["76344","0.32743594","1"],["76417.4","1.00616208","1"]],"bids":[["76330.4","0.09253743","7"],["76311","0.22972023","1"],["76266.4","0","0"],["76163.9","0.00005592","3"]]}
{"instId":"BTC-USDT","action":"update","ts":"1776816034100","asks":[["76343.8","0.20697056","2"]],"bids":[["76293.7","0","0"],["76162.2","0.00002057","1"]]}
{"instId":"BTC-USDT","action":"update","ts":"1776816034110","asks":[["76339.3","0.47171358","5"]],"bids":[]}
{"instId":"BTC-USDT","action":"update","ts":"1776816034130","asks":[["76356.4","0.14620905","2"]],"bids":[]}
{"instId":"BTC-USDT","action":"update","ts":"1776816034150","asks":[],"bids":[["76266.4","0.00323427","1"],["76162.2","0","0"]]}
{"instId":"BTC-USDT","action":"update","ts":"1776816034170","asks":[["76345.7","0.00654867","1"],["76345.8","0.26517365","4"],["76459.2","0","0"]],"bids":[["76318.4","0","0"],["76318.3","0.07577264","3"],["76311.1","0.32743588","1"],["76310.7","0.47806175","2"],["76293.7","0.00002864","1"]]}
{"instId":"BTC-USDT","action":"update","ts":"1776816034180","asks":[],"bids":[["76330.4","0.03003743","6"]]}
{"instId":"BTC-USDT","action":"update","ts":"1776816034190","asks":[["76337.3","0.00654852","1"],["76338.5","0","0"],["76389.3","0","0"],["76459.2","0.08410468","3"]],"bids":[["76328","0.00003398","3"],["76318.3","0.06922412","2"],["76318","0.00654852","1"],["76310.7","0.47151308","1"],["76309.1","0.0065486","1"],["76164.3","0","0"],["76163.9","0","0"]]}
{"instId":"BTC-USDT","action":"update","ts":"1776816034210","asks":[["76337.3","0","0"],["76338.5","0.00654853","1"]],"bids":[]}
{"instId":"BTC-USDT","action":"update","ts":"1776816034230","asks":[["76337","0.10778858","1"],["76338","0.00001316","1"],["76339.3","0.47433346","6"],["76459.1","0","0"],["76459.2","0","0"]],"bids":[["76227.1","0.00001316","1"],["76165.1","0","0"]]}
{"instId":"BTC-USDT","action":"update","ts":"1776816034240","asks":[["76353.5","0.01614584","1"],["76361.6","0.12991065","1"],["76367.6","0.00001501","1"],["76458.8","0","0"]],"bids":[]}
{"instId":"BTC-USDT","action":"update","ts":"1776816034270","asks":[["76417.5","0.20378297","2"]],"bids":[]}
{"instId":"BTC-USDT","action":"update","ts":"1776816034280","asks":[["76381.9","0.10556059","1"],["76387.5","0.1","1"],["76458.4","0","0"],["76458.7","0","0"]],"bids":[]}
{"instId":"BTC-USDT","action":"update","ts":"1776816034290","asks":[],"bids":[["76281","0.01941303","2"],["76190.3","0.01477601","1"],["76165.2","0","0"]]}
{"instId":"BTC-USDT","action":"update","ts":"1776816034300","asks":[["76332.9","0.00001358","1"],["76458.3","0","0"]],"bids":[["76328","0.00002349","2"],["76318.3","0.0757727","3"],["76318","0","0"],["76165.2","0.00091086","3"]]}
{"instId":"BTC-USDT","action":"update","ts":"1776816034310","asks":[["76357.4","0","0"],["76458.3","0.00035006","7"]],"bids":[]}
{"instId":"BTC-USDT","action":"update","ts":"1776816034330","asks":[["76342","0.01","1"],["76346","0.11665446","1"],["76350","0.03","1"],["76458.1","0","0"],["76458.3","0","0"]],"bids":[["76318.3","0.06922412","2"],["76318","0.00654859","1"],["76310.7","0.47806167","2"],["76309.1","0","0"],["76281","0.00001316","1"],["76190.3","0","0"],["76165.1","0.00001015","1"]]}
{"instId":"BTC-USDT","action":"update","ts":"1776816034340","asks":[["76325.8","0.20840624","3"],["76329","0.154415","2"],["76329.6","0.269135","3"],["76330.5","1.02316896","19"],["76338.5","0","0"],["76340.9","0.0065486","1"],["76345.8","0","0"],["76383.2","0.00130918","1"],["76457.8","0","0"],["76457.9","0","0"]],"bids":[["76330.4","0","0"],["76329.5","0","0"],["76328.9","0","0"],["76328.6","0","0"],["76328.4","0","0"],["76328.3","0","0"],["76328.1","0","0"],["76328","0","0"],["76326.8","0","0"],["76326.6","0","0"],["76322.6","0","0"],["76319.8","0.0065486","1"],["76318","0","0"],["76314.5","1.13341073","2"],["76314.2","0.01567179","1"],["76310.7","0.47151308","1"],["76309.2","0.00654841","1"],["76309","0","0"],["76164.3","0.00046091","2"],["76163.9","0.00005592","3"],["76162.2","0.00002057","1"],["76162.1","0.00004159","3"],["76162","0.00001017","1"],["76161.2","0.00007766","2"],["76161.1","0.0000827","1"],["76160.4","0.01614584","1"],["76160.2","0.00705391","1"],["76160","0.00187493","7"]]}
{"instId":"BTC-USDT","action":"update","ts":"1776816034350","asks":[["76325.8","0.90407397","13"],["76328.2","0.47151308","1"],["76328.3","0.09527","1"],["76329","0.00085","1"],["76329.6","0","0"],["76330.4","0.39183584","2"],["76330.5","0.19431","3"],["76330.6","0","0"],["76332.3","0","0"],["76334.2","0.14729527","2"],["76337","0","0"],["76337.2","0.11377757","2"],["76337.4","0","0"],["76339.3","0.47695334","7"],["76340.9","0.32743339","1"],["76341.1","0.26517365","4"],["76341.9","0.00654861","1"],["76343.8","0.12089605","1"],["76344","0","0"],["76344.1","0","0"],["76345.7","0","0"],["76345.9","0.11938024","2"],["76373.6","0.10455299","1"],["76373.7","0","0"],["76375.4","0.16905932","2"],["76375.5","0","0"],["76381.9","0","0"],["76432.1","0","0"],["76435.4","0","0"],["76457.8","0.00026388","1"],["76457.9","0.02053416","2"],["76458.1","0.00001883","1"],["76458.3","0.00035006","7"],["76458.4","0.0000711","2"],["76458.7","0.01614584","1"]],"bids":[["76325.7","0.13567551","8"],["76324.6","0.0000463","1"],["76322.7","0","0"],["76322.2","0.0262","1"],["76321.4","0","0"],["76319.8","0","0"],["76318.2","0","0"],["76315.4","0.53367032","3"],["76314.6","0.00656178","2"],["76314.5","0.12737518","1"],["76311.1","0","0"],["76310.6","0.00001086","1"],["76309.2","0","0"],["76308.9","0","0"],["76308.1","0.44674643","2"],["76307.9","0.00001316","1"],["76307.8","0.10814765","1"],["76306.5","0.00654861","1"],["76304.7","0.00001086","1"],["76300.1","0.00523916","1"],["76299.8","0.01614584","1"],["76298.5","0.04430272","1"],["76293.6","0","0"],["76284.8","0.70527311","3"],["76266.5","0.12052138","2"],["76266.3","0","0"],["76249.9","0.0412546","2"],["76196.8","0.00652851","1"],["76173.2","1.0061616","2"],["76160.9","0.1305","1"],["76160","0.0118714","8"],["76159.3","0.00040006","1"]]}
{"instId":"BTC-USDT","action":"update","ts":"1776816034360","asks":[["76329.3","0.0126887","1"],["76330.4","0.15751631","1"],["76334.2","0.14074665","1"],["76337","0.00654862","1"],["76337.1","0.03397756","1"],["76341.5","0.05896264","1"],["76341.9","0","0"],["76343.7","0.00654857","1"],["76343.8","0","0"],["76346","0","0"],["76347.9","0","0"],["76351.1","0.13661584","2"]],"bids":[["76325.7","0.23567551","9"],["76322.3","0.01447725","1"],["76318.3","0.00001034","1"],["76318.2","0.00261949","1"],["76316.9","0.10797557","2"],["76315.6","0.00655895","2"],["76315.4","0","0"],["76314.6","0.00001316","1"],["76307.9","0.00656173","2"],["76306.5","0","0"],["76295.1","0.26155956","4"],["76160","0.00187493","7"],["76159.3","0","0"]]}
{"instId":"BTC-USDT","action":"update","ts":"1776816034370","asks":[["76325.8","0.7482364","10"],["76328.3","0","0"],["76329","0","0"],["76330.5","0.09904","2"],["76338.6","0.37687166","2"],["76340.9","0","0"],["76343.7","0","0"],["76345.8","0.33397964","2"],["76348.4","0","0"],["76432.8","0.00002941","1"],["76458.8","0.00001501","1"],["76459.1","0.00006716","3"],["76459.2","0.08410468","3"],["76459.3","0.00319921","2"]],"bids":[["76325.7","0.24187551","10"],["76317","0.0788044","2"],["76315.6","0.00001033","1"],["76311.1","0.32743138","1"],["76308.2","0.00654856","1"],["76308.1","0.11931304","1"],["76307.9","0.00001316","1"],["76266.5","0.00001086","1"],["76160.4","0","0"],["76160.2","0","0"],["76160","0","0"]]}
{"instId":"BTC-USDT","action":"update","ts":"1776816034380","asks":[["76345.7","0.21635456","2"],["76346.1","0","0"],["76352.4","0.00001501","1"],["76381.9","0.11931304","1"],["76382.7","0.0008","1"],["76385.3","1.92329975","1"],["76459.2","0","0"],["76459.3","0","0"]],"bids":[["76325.7","0.36017606","11"],["76322.2","0","0"],["76317","0.07225591","1"],["76316.6","0.00654849","1"],["76314.6","0.64361926","3"]]}
{"instId":"BTC-USDT","action":"update","ts":"1776816034390","asks":[["76345.6","0.16427476","1"],["76345.7","0.11666164","1"],["76380","0.25094478","2"],["76459.1","0","0"]],"bids":[["76322.3","0","0"],["76314.7","0.36421337","1"],["76314.6","0.47152624","2"],["76289.7","0","0"],["76160.4","0.01614584","1"]]}
{"instId":"BTC-USDT","action":"update","ts":"1776816034400","asks":[["76332.9","0","0"],["76343.7","0.07901","1"]],"bids":[["76323.3","0.00003373","1"],["76312.5","0.0162517","2"],["76280.4","0.00001199","1"],["76277.7","0","0"],["76275.7","0.00325324","1"],["76271","0.00233708","1"],["76160.9","0","0"],["76160.4","0","0"]]}
{"instId":"BTC-USDT","action":"update","ts":"1776816034410","asks":[["76343.6","0.32743407","1"],["76345.8","0.00654856","1"],["76458.8","0","0"]],"bids":[["76323.3","0.00007339","2"],["76280.4","0","0"],["76273.5","0.000012","1"],["76270","0","0"],["76263.7","0.00019775","1"],["76201.5","0","0"],["76187.1","0.00001197","1"]]}
{"instId":"BTC-USDT","action":"update","ts":"1776816034420","asks":[["76343.5","0.15811365","1"],["76343.7","0.15795","2"],["76345.6","0","0"]],"bids":[]}
{"instId":"BTC-USDT","action":"update","ts":"1776816034430","asks":[["76330.4","0","0"],["76458.8","0.00001501","1"]],"bids":[]}
{"instId":"BTC-USDT","action":"update","ts":"1776816034440","asks":[["76339.3","0.47675284","3"],["76340.6","0","0"],["76342.9","0","0"],["76344.4","0","0"],["76345.9","0.11931304","1"],["76359","0","0"],["76368.7","0","0"],["76369","0.4410105","1"],["76370.3","0","0"],["76382.7","1.92409975","2"],["76385.3","0","0"],["76459.1","0.00006716","3"],["76459.2","0.08410468","3"],["76459.3","0.00319921","2"],["76459.6","0.00072458","2"],["76459.7","0.0000534","1"],["76459.8","0.00203787","4"],["76459.9","0.0000212","1"]],"bids":[]}
{"instId":"BTC-USDT","action":"update","ts":"1776816034450","asks":[["76338.1","0","0"],["76341.4","0","0"],["76364.2","0","0"],["76368.5","0","0"],["76460","0.03539391","5"],["76460.1","0.0022005","4"],["76460.2","0.00162671","12"],["76460.6","0.00002799","2"]],"bids":[["76325.7","0.39812614","12"],["76322.2","0.0262","1"],["76161.1","0","0"]]}
{"instId":"BTC-USDT","action":"update","ts":"1776816034460","asks":[["76337","0","0"],["76338.5","0.00654848","1"],["76343.4","0.092072","1"],["76345.9","0","0"],["76354.1","0.13788134","1"],["76388.6","0.00003978","1"],["76393.9","0","0"],["76460.6","0","0"]],"bids":[["76322.3","0.01447725","1"],["76318","0.00654848","1"],["76316.6","0","0"],["76266.4","0","0"],["76263.2","0.00323432","1"],["76161.2","0","0"]]}
{"instId":"BTC-USDT","action":"update","ts":"1776816034470","asks":[["76325.8","0","0"],["76328.2","0","0"],["76334.2","0","0"],["76334.3","0","0"],["76337.1","0","0"],["76337.2","0.000015","1"],["76338.5","0","0"],["76338.6","0","0"],["76338.7","0.036","1"],["76339.3","0.00785964","3"],["76340.9","0.00654855","1"],["76341.1","0","0"],["76341.5","0","0"],["76343.6","0","0"],["76345.7","0","0"],["76346.2","0","0"],["76346.3","0.32742949","1"],["76346.4","0","0"],["76347.7","0.02","1"],["76349.5","0","0"],["76354.5","0","0"],["76361.8","1.00589588","1"],["76366.9","0.01614584","1"],["76382.7","0.0008","1"],["76416.5","1.92329975","1"],["76460.6","0.00002799","2"],["76460.7","0.00167279","1"],["76460.9","0.00030148","3"],["76461.1","0.00003024","1"],["76461.3","0.00027039","1"],["76461.4","0.0312605","1"],["76461.5","0.01228943","9"],["76461.6","0.00332668","1"],["76461.7","0.00001025","1"],["76462","0.00002228","1"],["76462.2","0.00551437","1"],["76462.3","0.00027227","4"]],"bids":[["76328.1","0.22979576","2"],["76325.7","1.10974375","15"],["76323.8","0.13","3"],["76321.6","0.01614584","1"],["76321.3","0.11668199","2"],["76319.8","0.00654855","1"],["76318","0","0"],["76317.1","1.00615154","1"],["76315.6","0.32743982","2"],["76311.1","0","0"],["76295.1","0","0"],["76277.2","0","0"],["76273.6","0.00001155","1"],["76201.3","0","0"],["76173.2","0.00001006","1"],["76161.2","0.00007766","2"]]}
{"instId":"BTC-USDT","action":"update","ts":"1776816034480","asks":[["76329.3","0","0"],["76330.5","0.06304","1"],["76338.7","0","0"],["76339.2","0","0"],["76340.9","0","0"],["76343","0.47151308","1"],["76343.5","0","0"],["76345.8","0","0"],["76346.2","0.00654854","1"],["76346.3","0","0"],["76351.1","0.12461584","1"],["76352.2","0.47151308","1"],["76354","0.00654855","1"],["76354.3","0","0"],["76355.6","0.05896264","1"],["76356.2","0.32743015","1"],["76359.1","0","0"],["76359.9","0.26517365","4"],["76361.6","0","0"],["76367.6","0.12993664","2"],["76368.8","0.14052748","1"],["76375.6","0","0"],["76384.5","0.12166594","1"],["76391.4","0.12196724","1"],["76397.2","0.14312491","1"],["76401.4","0.26111823","2"],["76461.5","0.14278943","10"]],"bids":[["76330.4","0.45874728","5"],["76329.2","0.76378746","16"],["76328.2","0.17368349","2"],["76328.1","0.48178068","6"],["76326.4","0.00261921","1"],["76325.8","0.34815318","3"],["76325.7","0.75495246","5"],["76323.9","0.32743015","1"],["76323.1","0.05896264","1"],["76321.3","0.00001316","1"],["76320","0.11003766","2"],["76319.8","0","0"],["76319.1","0.00656535","2"],["76318.2","0","0"],["76317.1","1.08993451","2"],["76316.5","0.00001086","1"],["76315.6","0.00001033","1"],["76313.9","0.26155956","4"],["76311.1","0.00523842","1"],["76308.2","0","0"],["76307.8","0","0"],["76306.9","0.05240492","1"],["76300.1","0","0"],["76298.5","0","0"],["76295.8","0.00785763","1"],["76285.9","0.0327182","2"],["76285","0.21594192","2"],["76284.9","0","0"],["76284.8","0.69741437","2"],["76258.8","0.00652089","1"],["76215.2","0.00652277","1"],["76196.8","0","0"],["76164.3","0","0"],["76163.9","0","0"],["76162.2","0","0"],["76162.1","0","0"],["76162","0","0"],["76161.2","0","0"]]}
{"instId":"BTC-USDT","action":"update","ts":"1776816034490","asks":[["76330.5","0.0026","2"],["76331.8","0.01268829","1"],["76346.2","0","0"],["76347.4","0.02746593","1"],["76349.5","0.00654853","1"],["76354","1.33358406","2"],["76354.2","0","0"],["76356","0.012","1"],["76356.2","0","0"],["76358.6","0.00654859","1"],["76359.9","0","0"],["76396","0.19936062","1"],["76462.2","0","0"],["76462.3","0","0"]],"bids":[["76330.4","5.60775601","20"],["76329.3","0.69323944","5"],["76329.2","0.20071946","2"],["76328.2","0","0"],["76328.1","0.1465397","3"],["76325.8","0.34160464","2"],["76325.7","0.63665191","4"],["76323.9","0","0"],["76322.3","0.1502679","3"],["76321.7","0.00656359","2"],["76320.1","0.32743252","1"],["76320","0.0000812","1"],["76319.1","0.0000168","1"],["76317.2","0.11666164","1"],["76317","0","0"],["76316.9","0.00004629","1"],["76314.5","0","0"],["76313.9","0","0"],["76307.8","0.11666164","1"],["76301.9","0.11371296","2"],["76300.4","0","0"],["76285","0.1","1"],["76237.9","1.17592547","3"],["76164.3","0.00046091","2"],["76163.9","0.00005592","3"]]}
{"instId":"BTC-USDT","action":"update","ts":"1776816034500","asks":[["76348.1","0.00656168","2"],["76349.5","0","0"],["76349.6","0.21398814","2"],["76353.9","0.32743247","1"],["76354","1.00615154","1"],["76355.5","0.00654858","1"],["76358.6","0","0"],["76358.8","0","0"],["76397.2","0","0"],["76462.2","0.00551437","1"],["76462.3","0.00027227","4"]],"bids":[["76329.4","0.31058883","1"],["76329.3","0.39010632","3"],["76329.2","0.30071946","3"],["76328.2","0.00654852","1"],["76325.8","0.11867486","1"],["76322.4","0.32744333","2"],["76322.3","0.0502679","2"],["76322.2","0","0"],["76321.7","0.000015","1"],["76320.2","0.00654858","1"],["76320.1","0","0"],["76163.9","0","0"]]}
